Workbook

Sheet 1.0SASA
A1: List of District and Taluka in Gujarat state
A2: Sr. No. | B2: District | C2: Sr. No. | D2: Taluka | E2: Gross Crop Area 2016-17 (in Hectares) | F2: Gross Crop Area 2017-18 (in Hectares) | G2: Gross Crop Area 2018-19 (in Hectares)
A3: 1 | B3: Kachchh | C3: 1 | D3: Lakhapat | E3: 22682 | F3: 21032 | G3: 21032
C4: 2 | D4: Rapar | E4: 174644 | F4: 194934 | G4: 67656
C5: 3 | D5: Bhachau | E5: 111111 | F5: 127520 | G5: 102044
C6: 4 | D6: Anjar | E6: 82467 | F6: 78802 | G6: 58328
C7: 5 | D7: Bhuj | E7: 103270 | F7: 93569 | G7: 78272
C8: 6 | D8: Nakhatrana | E8: 69524 | F8: 67528 | G8: 55626
C9: 7 | D9: Abdasa | E9: 114126 | F9: 106646 | G9: 27093
C10: 8 | D10: Mandvi | E10: 79264 | F10: 72705 | G10: 61584
C11: 9 | D11: Mundra | E11: 45111 | F11: 41931 | G11: 21175
C12: 10 | D12: Gandhidham | E12: 3192 | F12: 4719 | G12: 1200
A13: District Total Area | E13: =SUM(E3:E12) -> 805391 | F13: =SUM(F3:F12) -> 809386 | G13: =SUM(G3:G12) -> 494010
A14: 2 | B14: Banaskantha | C14: 1 | D14: Vav | E14: 85996 | F14: 101664 | G14: 62788
C15: 2 | D15: Tharad | E15: 198431 | F15: 193187 | G15: 175991
C16: 3 | D16: Dhanera | E16: 112226 | F16: 126084 | G16: 128484
C17: 4 | D17: Dantiwada | E17: 58340 | F17: 61342 | G17: 52275
C18: 5 | D18: Amirgadh | E18: 30996 | F18: 28814 | G18: 27693
C19: 6 | D19: Danta | E19: 42911 | F19: 38253 | G19: 32466
C20: 7 | D20: Vadgam | E20: 51422 | F20: 59894 | G20: 53928
C21: 8 | D21: Palanpur | E21: 112634 | F21: 125217 | G21: 109607
C22: 9 | D22: Deesa | E22: 181334 | F22: 187821 | G22: 211026
C23: 10 | D23: Deodar | E23: 74672 | F23: 75007 | G23: 79771
C24: 11 | D24: Bhabhar | E24: 65649 | F24: 59263 | G24: 64844
C25: 12 | D25: Kankrej | E25: 127213 | F25: 114719 | G25: 122477
C26: 13 | D26: Lakhani | E26: 89591 | F26: 75129 | G26: 97119
C27: 14 | D27: Suigam | E27: 47156 | F27: 32114 | G27: 22367
A28: District Total Area | E28: =SUM(E14:E27) -> 1278571 | F28: =SUM(F14:F27) -> 1278508 | G28: =SUM(G14:G27) -> 1240836
A29: 3 | B29: Patan | C29: 1 | D29: Santalpur | E29: 89989 | F29: 103445 | G29: 102847
C30: 2 | D30: Radhanpur | E30: 55949 | F30: 63649 | G30: 32721
C31: 3 | D31: Sidhpur | E31: 41623 | F31: 43927 | G31: 42008
C32: 4 | D32: Patan | E32: 50103 | F32: 50696 | G32: 53311
C33: 5 | D33: Harij | E33: 48218 | F33: 48699 | G33: 41028
C34: 6 | D34: Sami | E34: 64529 | F34: 81583 | G34: 49014
C35: 7 | D35: Chanasma | E35: 46377 | F35: 45408 | G35: 44738
C36: 8 | D36: Shankheshwar | E36: 52884 | F36: 52166 | G36: 50204
C37: 9 | D37: Saraswati | E37: 55764 | F37: 54291 | G37: 55462
A38: District Total Area | E38: =SUM(E29:E37) -> 505436 | F38: =SUM(F29:F37) -> 543864 | G38: =SUM(G29:G37) -> 471333
A39: 4 | B39: Mehsana | C39: 1 | D39: Satlasana | E39: 37097 | F39: 35983 | G39: 31655
C40: 2 | D40: Kheralu | E40: 44208 | F40: 46829 | G40: 45145
...

Sheet 1.0WS
A1: WORKING SHEET OF PLAN OF WORK UNDER ICS SCHEME FOR THE CROP AREA ENUMERATION 1.0
A2: STATE: GUJARAT | K2: YEAR: 2026-27
A3: REGION | B3: SRO | C3: DISTT. | D3: Stratum | E3: TEHSIL | F3: AREA IN HECTARE | I3: AVG | J3: PLAN | K3: ADJ
F4: 2016-17 | G4: 2017-18 | H4: 2018-19
A5: AHMEDABAD | B5: S.Nagar | C5: Kutch | D5: 1 | E5: Abdasa | F5: 114126 | G5: 106646 | H5: 27093 | I5: =IF(AND(F5="NA",G5="NA",H5="NA"),0,ROUND(AVERAGE(F5:H5),0)) -> 82622 | J5: =ROUND(I5*340/I$299,2) -> 2.2 | K5: =IF(J5>=2,ROUND(J5,0),IF(J5>1.1,2,"")) -> 2
D6: 2 | E6: Lakhapat | F6: 22682 | G6: 21032 | H6: 21032 | I6: =IF(AND(F6="NA",G6="NA",H6="NA"),0,ROUND(AVERAGE(F6:H6),0)) -> 21582 | J6: =ROUND(I6*340/I$299,2) -> 0.57 | K6: =IF(J6>=2,ROUND(J6,0),IF(J6>1.1,2,""))
E7: Nakhatrana | F7: 69524 | G7: 67528 | H7: 55626 | I7: =IF(AND(F7="NA",G7="NA",H7="NA"),0,ROUND(AVERAGE(F7:H7),0)) -> 64226 | J7: =ROUND(I7*340/I$299,2) -> 1.71 | K7: =IF(J7>=2,ROUND(J7,0),IF(J7>1.1,2,"")) -> 2
D8: 3 | E8: Bhuj | F8: 103270 | G8: 93569 | H8: 78272 | I8: =IF(AND(F8="NA",G8="NA",H8="NA"),0,ROUND(AVERAGE(F8:H8),0)) -> 91704 | J8: =ROUND(I8*340/I$299,2) -> 2.44 | K8: =IF(J8>=2,ROUND(J8,0),IF(J8>1.1,2,"")) -> 2
D9: 4 | E9: Mundra | F9: 45111 | G9: 41931 | H9: 21175 | I9: =IF(AND(F9="NA",G9="NA",H9="NA"),0,ROUND(AVERAGE(F9:H9),0)) -> 36072 | J9: =ROUND(I9*340/I$299,2) -> 0.96 | K9: =IF(J9>=2,ROUND(J9,0),IF(J9>1.1,2,""))
E10: Mandvi | F10: 79264 | G10: 72705 | H10: 61584 | I10: =IF(AND(F10="NA",G10="NA",H10="NA"),0,ROUND(AVERAGE(F10:H10),0)) -> 71184 | J10: =ROUND(I10*340/I$299,2) -> 1.9 | K10: =IF(J10>=2,ROUND(J10,0),IF(J10>1.1,2,"")) -> 2
D11: 5 | E11: Anjar | F11: 82467 | G11: 78802 | H11: 58328 | I11: =IF(AND(F11="NA",G11="NA",H11="NA"),0,ROUND(AVERAGE(F11:H11),0)) -> 73199 | J11: =ROUND(I11*340/I$299,2) -> 1.95 | K11: =IF(J11>=2,ROUND(J11,0),IF(J11>1.1,2,"")) -> 2
D12: 6 | E12: Gandhidham | F12: 3192 | G12: 4719 | H12: 1200 | I12: =IF(AND(F12="NA",G12="NA",H12="NA"),0,ROUND(AVERAGE(F12:H12),0)) -> 3037 | J12: =ROUND(I12*340/I$299,2) -> 0.08 | K12: =IF(J12>=2,ROUND(J12,0),IF(J12>1.1,2,""))
E13: Bhachau | F13: 111111 | G13: 127520 | H13: 102044 | I13: =IF(AND(F13="NA",G13="NA",H13="NA"),0,ROUND(AVERAGE(F13:H13),0)) -> 113558 | J13: =ROUND(I13*340/I$299,2) -> 3.03 | K13: =IF(J13>=2,ROUND(J13,0),IF(J13>1.1,2,"")) -> 3
D14: 7 | E14: Rapar | F14: 174644 | G14: 194934 | H14: 67656 | I14: =IF(AND(F14="NA",G14="NA",H14="NA"),0,ROUND(AVERAGE(F14:H14),0)) -> 145745 | J14: =ROUND(I14*340/I$299,2) -> 3.88 | K14: =IF(J14>=2,ROUND(J14,0),IF(J14>1.1,2,"")) -> 4
E15: DISTRICT TOTAL | F15: =SUM(F5:F14) -> 805391 | G15: =SUM(G5:G14) -> 809386 | H15: =SUM(H5:H14) -> 494010 | I15: =SUM(I5:I14) -> 702929 | J15: =SUM(J5:J14) -> 18.72 | K15: =SUM(K5:K14) -> 17
C16: S.Nagar | D16: 1 | E16: Dhrangadhra | F16: 173282 | G16: 161596 | H16: 159700 | I16: =IF(AND(F16="NA",G16="NA",H16="NA"),0,ROUND(AVERAGE(F16:H16),0)) -> 164859 | J16: =ROUND(I16*340/I$299,2) -> 4.39 | K16: 3
D17: 2 | E17: Dasada | F17: 135107 | G17: 108097 | H17: 137249 | I17: =IF(AND(F17="NA",G17="NA",H17="NA"),0,ROUND(AVERAGE(F17:H17),0)) -> 126818 | J17: =ROUND(I17*340/I$299,2) -> 3.38 | K17: =IF(J17>=2,ROUND(J17,0),IF(J17>1.1,2,"")) -> 3
D18: 3 | E18: Lakhtar | F18: 81611 | G18: 71978 | H18: 68629 | I18: =IF(AND(F18="NA",G18="NA",H18="NA"),0,ROUND(AVERAGE(F18:H18),0)) -> 74073 | J18: =ROUND(I18*340/I$299,2) -> 1.97 | K18: =IF(J18>=2,ROUND(J18,0),IF(J18>1.1,2,"")) -> 2
D19: 4 | E19: Wadhwan | F19: 71045 | G19: 66639 | H19: 65576 | I19: =IF(AND(F19="NA",G19="NA",H19="NA"),0,ROUND(AVERAGE(F19:H19),0)) -> 67753 | J19: =ROUND(I19*340/I$299,2) -> 1.8 | K19: =IF(J19>=2,ROUND(J19,0),IF(J19>1.1,2,"")) -> 2
D20: 5 | E20: Limbdi | F20: 94903 | G20: 91988 | H20: 89725 | I20: =IF(AND(F20="NA",G20="NA",H20="NA"),0,ROUND(AVERAGE(F20:H20),0)) -> 92205 | J20: =ROUND(I20*340/I$299,2) -> 2.46 | K20: =IF(J20>=2,ROUND(J20,0),IF(J20>1.1,2,"")) -> 2
D21: 6 | E21: Muli | F21: 62921 | G21: 76311 | H21: 87551 | I21: =IF(AND(F21="NA",G21="NA",H21="NA"),0,ROUND(AVERAGE(F21:H21),0)) -> 75594 | J21: =ROUND(I21*340/I$299,2) -> 2.01 | K21: =IF(J21>=2,ROUND(J21,0),IF(J21>1.1,2,"")) -> 2
D22: 7 | E22: Sayla | F22: 47512 | G22: 56396 | H22: 55655 | I22: =IF(AND(F22="NA",G22="NA",H22="NA"),0,ROUND(AVERAGE(F22:H22),0)) -> 53188 | J22: =ROUND(I22*340/I$299,2) -> 1.42 | K22: =IF(J22>=2,ROUND(J22,0),IF(J22>1.1,2,"")) -> 2
D23: 8 | E23: Chotila | F23: 47658 | G23: 55718 | H23: 48058 | I23: =IF(AND(F23="NA",G23="NA",H23="NA"),0,ROUND(AVERAGE(F23:H23),0)) -> 50478 | J23: =ROUND(I23*340/I$299,2) -> 1.34 | K23: =IF(J23>=2,ROUND(J23,0),IF(J23>1.1,2,"")) -> 2
D24: 9 | E24: Chuda | F24: 48352 | G24: 48210 | H24: 49845 | I24: =IF(AND(F24="NA",G24="NA",H24="NA"),0,ROUND(AVERAGE(F24:H24),0)) -> 48802 | J24: =ROUND(I24*340/I$299,2) -> 1.3 | K24: =IF(J24>=2,ROUND(J24,0),IF(J24>1.1,2,"")) -> 2
E25: Thangadh | F25: 15801 | G25: 18763 | H25: 16513 | I25: =IF(AND(F25="NA",G25="NA",H25="NA"),0,ROUND(AVERAGE(F25:H25),0)) -> 17026 | J25: =ROUND(I25*340/I$299,2) -> 0.45 | K25: =IF(J25>=2,ROUND(J25,0),IF(J25>1.1,2,""))
E26: DISTRICT TOTAL | F26: =SUM(F16:F25) -> 778192 | G26: =SUM(G16:G25) -> 755696 | H26: =SUM(H16:H25) -> 778501 | I26: =SUM(I16:I25) -> 770796 | J26: =SUM(J16:J25) -> 20.52 | K26: =SUM(K16:K25) -> 20
E27: SRO TOTAL | F27: =SUM(F15,F26) -> 1583583 | G27: =SUM(G15,G26) -> 1565082 | H27: =SUM(H15,H26) -> 1272511 | I27: =SUM(I15,I26) -> 1473725 | J27: =SUM(J15,J26) -> 39.24 | K27: =SUM(K15,K26) -> 37
B28: Ahmedabad | C28: Gandhinagar | D28: 1 | E28: Mansa | F28: 56003 | G28: 58650 | H28: 52556 | I28: =IF(AND(F28="NA",G28="NA",H28="NA"),0,ROUND(AVERAGE(F28:H28),0)) -> 55736 | J28: =ROUND(I28*340/I$299,2) -> 1.48 | K28: =IF(J28>=2,ROUND(J28,0),IF(J28>1.1,2,"")) -> 2
D29: 2 | E29: Gandhinagar | F29: 68585 | G29: 62003 | H29: 64538 | I29: =IF(AND(F29="NA",G29="NA",H29="NA"),0,ROUND(AVERAGE(F29:H29),0)) -> 65042 | J29: =ROUND(I29*340/I$299,2) -> 1.73 | K29: =IF(J29>=2,ROUND(J29,0),IF(J29>1.1,2,"")) -> 2
D30: 3 | E30: Dehgam | F30: 62058 | G30: 74707 | H30: 70195 | I30: =IF(AND(F30="NA",G30="NA",H30="NA"),0,ROUND(AVERAGE(F30:H30),0)) -> 68987 | J30: =ROUND(I30*340/I$299,2) -> 1.84 | K30: =IF(J30>=2,ROUND(J30,0),IF(J30>1.1,2,"")) -> 2
D31: 4 | E31: Kalol | F31: 57524 | G31: 53086 | H31: 54390 | I31: =IF(AND(F31="NA",G31="NA",H31="NA"),0,ROUND(AVERAGE(F31:H31),0)) -> 55000 | J31: =ROUND(I31*340/I$299,2) -> 1.47 | K31: =IF(J31>=2,ROUND(J31,0),IF(J31>1.1,2,"")) -> 2
E32: DISTRICT TOTAL | F32: =SUM(F28:F31) -> 244170 | G32: =SUM(G28:G31) -> 248446 | H32: =SUM(H28:H31) -> 241679 | I32: =SUM(I28:I31) -> 244765 | J32: =SUM(J28:J31) -> 6.52 | K32: =SUM(K28:K31) -> 8
C33: Ahmedabad | D33: 1 | E33: Mandal | F33: 48144 | G33: 46951 | H33: 51208 | I33: =IF(AND(F33="NA",G33="NA",H33="NA"),0,ROUND(AVERAGE(F33:H33),0)) -> 48768 | J33: =ROUND(I33*340/I$299,2) -> 1.3 | K33: =IF(J33>=2,ROUND(J33,0),IF(J33>1.1,2,"")) -> 2
E34: Detroj-Rampura | F34: 38514 | G34: 34672 | H34: 35901 | I34: =IF(AND(F34="NA",G34="NA",H34="NA"),0,ROUND(AVERAGE(F34:H34),0)) -> 36362 | J34: =ROUND(I34*340/I$299,2) -> 0.97 | K34: =IF(J34>=2,ROUND(J34,0),IF(J34>1.1,2,""))
D35: 2 | E35: Viramgam | F35: 88033 | G35: 83683 | H35: 91866 | I35: =IF(AND(F35="NA",G35="NA",H35="NA"),0,ROUND(AVERAGE(F35:H35),0)) -> 87861 | J35: =ROUND(I35*340/I$299,2) -> 2.34 | K35: =IF(J35>=2,ROUND(J35,0),IF(J35>1.1,2,"")) -> 2
D36: 3 | E36: Sanand | F36: 94770 | G36: 84250 | H36: 76213 | I36: =IF(AND(F36="NA",G36="NA",H36="NA"),0,ROUND(AVERAGE(F36:H36),0)) -> 85078 | J36: =ROUND(I36*340/I$299,2) -> 2.27 | K36: =IF(J36>=2,ROUND(J36,0),IF(J36>1.1,2,"")) -> 2
D37: 4 | E37: Bavla | F37: 70812 | G37: 73302 | H37: 67149 | I37: =IF(AND(F37="NA",G37="NA",H37="NA"),0,ROUND(AVERAGE(F37:H37),0)) -> 70421 | J37: =ROUND(I37*340/I$299,2) -> 1.88 | K37: =IF(J37>=2,ROUND(J37,0),IF(J37>1.1,2,"")) -> 2
D38: 5 | E38: Daskroi | F38: 62820 | G38: 69363 | H38: 55418 | I38: =IF(AND(F38="NA",G38="NA",H38="NA"),0,ROUND(AVERAGE(F38:H38),0)) -> 62534 | J38: =ROUND(I38*340/I$299,2) -> 1.67 | K38: =IF(J38>=2,ROUND(J38,0),IF(J38>1.1,2,"")) -> 2
D39: 6 | E39: Dholka | F39: 103733 | G39: 119122 | H39: 115699 | I39: =IF(AND(F39="NA",G39="NA",H39="NA"),0,ROUND(AVERAGE(F39:H39),0)) -> 112851 | J39: =ROUND(I39*340/I$299,2) -> 3.01 | K39: 2
D40: 7 | E40: Dhandhuka | F40: 62703 | G40: 88821 | H40: 74328 | I40: =IF(AND(F40="NA",G40="NA",H40="NA"),0,ROUND(AVERAGE(F40:H40),0)) -> 75284 | J40: =ROUND(I40*340/I$299,2) -> 2.01 | K40: =IF(J40>=2,ROUND(J40,0),IF(J40>1.1,2,"")) -> 2
...

Sheet 1.0WP
A1: Plan of Work for undertaking Sample Check on Area Enumeration (A.S.1.0) and Aggregation of area (A.S.1.1) under ICS scheme
A3: ='1.0WS'!A2 -> STATE: GUJARAT | D3: Season : Kharif, Rabi & Summer | G3: ='1.0WS'!K2 -> YEAR: 2026-27
A5: Region | B5: SRO | C5: District | D5: District Code | E5: Stratum | F5: Tehsil | G5: No. of Vill. | H5: No. of Sample Villages for each season
H6: Central | I6: State*
A7: Ahmedabad | B7: S.Nagar | C7: Kutch | D7: 01 | E7: =IF('1.0WS'!D5="","",'1.0WS'!D5) -> 1 | F7: ='1.0WS'!E5 -> Abdasa | G7: =IF('1.0WS'!K5="","",'1.0WS'!K5) -> 2
E8: =IF('1.0WS'!D6="","",'1.0WS'!D6) -> 2 | F8: ='1.0WS'!E6 -> Lakhapat | G8: =IF('1.0WS'!K6="","",'1.0WS'!K6)
E9: =IF('1.0WS'!D7="","",'1.0WS'!D7) | F9: ='1.0WS'!E7 -> Nakhatrana | G9: =IF('1.0WS'!K7="","",'1.0WS'!K7) -> 2
E10: =IF('1.0WS'!D8="","",'1.0WS'!D8) -> 3 | F10: ='1.0WS'!E8 -> Bhuj | G10: =IF('1.0WS'!K8="","",'1.0WS'!K8) -> 2
E11: =IF('1.0WS'!D9="","",'1.0WS'!D9) -> 4 | F11: ='1.0WS'!E9 -> Mundra | G11: =IF('1.0WS'!K9="","",'1.0WS'!K9)
E12: =IF('1.0WS'!D10="","",'1.0WS'!D10) | F12: ='1.0WS'!E10 -> Mandvi | G12: =IF('1.0WS'!K10="","",'1.0WS'!K10) -> 2
E13: =IF('1.0WS'!D11="","",'1.0WS'!D11) -> 5 | F13: ='1.0WS'!E11 -> Anjar | G13: =IF('1.0WS'!K11="","",'1.0WS'!K11) -> 2
E14: =IF('1.0WS'!D12="","",'1.0WS'!D12) -> 6 | F14: ='1.0WS'!E12 -> Gandhidham | G14: =IF('1.0WS'!K12="","",'1.0WS'!K12)
E15: =IF('1.0WS'!D13="","",'1.0WS'!D13) | F15: ='1.0WS'!E13 -> Bhachau | G15: =IF('1.0WS'!K13="","",'1.0WS'!K13) -> 3
E16: =IF('1.0WS'!D14="","",'1.0WS'!D14) -> 7 | F16: ='1.0WS'!E14 -> Rapar | G16: =IF('1.0WS'!K14="","",'1.0WS'!K14) -> 4
E17: DISTRICT TOTAL | H17: =SUM(H7:H16) -> 0 | I17: =SUM(I7:I16) -> 0
C18: S.Nagar | D18: 08 | E18: =IF('1.0WS'!D16="","",'1.0WS'!D16) -> 1 | F18: ='1.0WS'!E16 -> Dhrangadhra | G18: =IF('1.0WS'!K16="","",'1.0WS'!K16) -> 3
E19: =IF('1.0WS'!D17="","",'1.0WS'!D17) -> 2 | F19: ='1.0WS'!E17 -> Dasada | G19: =IF('1.0WS'!K17="","",'1.0WS'!K17) -> 3
E20: =IF('1.0WS'!D18="","",'1.0WS'!D18) -> 3 | F20: ='1.0WS'!E18 -> Lakhtar | G20: =IF('1.0WS'!K18="","",'1.0WS'!K18) -> 2
E21: =IF('1.0WS'!D19="","",'1.0WS'!D19) -> 4 | F21: ='1.0WS'!E19 -> Wadhwan | G21: =IF('1.0WS'!K19="","",'1.0WS'!K19) -> 2
E22: =IF('1.0WS'!D20="","",'1.0WS'!D20) -> 5 | F22: ='1.0WS'!E20 -> Limbdi | G22: =IF('1.0WS'!K20="","",'1.0WS'!K20) -> 2
E23: =IF('1.0WS'!D21="","",'1.0WS'!D21) -> 6 | F23: ='1.0WS'!E21 -> Muli | G23: =IF('1.0WS'!K21="","",'1.0WS'!K21) -> 2
E24: =IF('1.0WS'!D22="","",'1.0WS'!D22) -> 7 | F24: ='1.0WS'!E22 -> Sayla | G24: =IF('1.0WS'!K22="","",'1.0WS'!K22) -> 2
E25: =IF('1.0WS'!D23="","",'1.0WS'!D23) -> 8 | F25: ='1.0WS'!E23 -> Chotila | G25: =IF('1.0WS'!K23="","",'1.0WS'!K23) -> 2
E26: =IF('1.0WS'!D24="","",'1.0WS'!D24) -> 9 | F26: ='1.0WS'!E24 -> Chuda | G26: =IF('1.0WS'!K24="","",'1.0WS'!K24) -> 2
E27: =IF('1.0WS'!D25="","",'1.0WS'!D25) | F27: ='1.0WS'!E25 -> Thangadh | G27: =IF('1.0WS'!K25="","",'1.0WS'!K25)
E28: DISTRICT TOTAL | H28: =SUM(H18:H27) -> 0 | I28: =SUM(I18:I27) -> 0
C29: SRO TOTAL | H29: =SUM(H17,H28) -> 0 | I29: =SUM(I17,I28) -> 0
B30: Ahmedabad | C30: Gandhinagar | D30: 06 | E30: =IF('1.0WS'!D28="","",'1.0WS'!D28) -> 1 | F30: ='1.0WS'!E28 -> Mansa | G30: =IF('1.0WS'!K28="","",'1.0WS'!K28) -> 2
E31: =IF('1.0WS'!D29="","",'1.0WS'!D29) -> 2 | F31: ='1.0WS'!E29 -> Gandhinagar | G31: =IF('1.0WS'!K29="","",'1.0WS'!K29) -> 2
E32: =IF('1.0WS'!D30="","",'1.0WS'!D30) -> 3 | F32: ='1.0WS'!E30 -> Dehgam | G32: =IF('1.0WS'!K30="","",'1.0WS'!K30) -> 2
E33: =IF('1.0WS'!D31="","",'1.0WS'!D31) -> 4 | F33: ='1.0WS'!E31 -> Kalol | G33: =IF('1.0WS'!K31="","",'1.0WS'!K31) -> 2
E34: DISTRICT TOTAL | H34: =SUM(H30:H33) -> 0 | I34: =SUM(I30:I33) -> 0
C35: Ahmedabad | D35: 07 | E35: =IF('1.0WS'!D33="","",'1.0WS'!D33) -> 1 | F35: ='1.0WS'!E33 -> Mandal | G35: =IF('1.0WS'!K33="","",'1.0WS'!K33) -> 2
E36: =IF('1.0WS'!D34="","",'1.0WS'!D34) | F36: ='1.0WS'!E34 -> Detroj-Rampura | G36: =IF('1.0WS'!K34="","",'1.0WS'!K34)
E37: =IF('1.0WS'!D35="","",'1.0WS'!D35) -> 2 | F37: ='1.0WS'!E35 -> Viramgam | G37: =IF('1.0WS'!K35="","",'1.0WS'!K35) -> 2
E38: =IF('1.0WS'!D36="","",'1.0WS'!D36) -> 3 | F38: ='1.0WS'!E36 -> Sanand | G38: =IF('1.0WS'!K36="","",'1.0WS'!K36) -> 2
E39: =IF('1.0WS'!D37="","",'1.0WS'!D37) -> 4 | F39: ='1.0WS'!E37 -> Bavla | G39: =IF('1.0WS'!K37="","",'1.0WS'!K37) -> 2
E40: =IF('1.0WS'!D38="","",'1.0WS'!D38) -> 5 | F40: ='1.0WS'!E38 -> Daskroi | G40: =IF('1.0WS'!K38="","",'1.0WS'!K38) -> 2
E41: =IF('1.0WS'!D39="","",'1.0WS'!D39) -> 6 | F41: ='1.0WS'!E39 -> Dholka | G41: =IF('1.0WS'!K39="","",'1.0WS'!K39) -> 2
E42: =IF('1.0WS'!D40="","",'1.0WS'!D40) -> 7 | F42: ='1.0WS'!E40 -> Dhandhuka | G42: =IF('1.0WS'!K40="","",'1.0WS'!K40) -> 2
...

Sheet 1.0WP (P)
A1: Plan of Work for undertaking Sample Check on Area Enumeration (A.S.1.0) and Aggregation of area (A.S.1.1) under ICS scheme
A4: STATE: GUJARAT | D4: Season : Kharif, Rabi & Summer | G4: YEAR: 2022-23
A6: Region | B6: SRO | C6: District | D6: District Code | E6: Stratum | F6: Tehsil | G6: No. of Vill. | H6: No. of Sample Villages for each season
H7: Central | I7: State*
A8: Ahmedabad | B8: S.Nagar | C8: Kutch | D8: 01 | E8: 1 | F8: Abdasa | G8: 2 | H8: =G8 -> 2 | I8: =H8 -> 2
E9: 2 | F9: Lakhapat | H9: =SUM(G9:G10) -> 2 | I9: =H9 -> 2
F10: Nakhatrana | G10: 2
E11: 3 | F11: Bhuj | G11: 2 | H11: =G11 -> 2 | I11: =H11 -> 2
E12: 4 | F12: Mundra | H12: =SUM(G12:G13) -> 2 | I12: =H12 -> 2
F13: Mandvi | G13: 2
E14: 5 | F14: Anjar | G14: 2 | H14: =G14 -> 2 | I14: =H14 -> 2
E15: 6 | F15: Gandhidham | H15: =SUM(G15:G16) -> 3 | I15: =H15 -> 3
F16: Bhachau | G16: 3
E17: 7 | F17: Rapar | G17: 4 | H17: =G17 -> 4 | I17: =H17 -> 4
E18: DISTRICT TOTAL | G18: =SUM(G8:G17) -> 17 | H18: =SUM(H8:H17) -> 17 | I18: =SUM(I8:I17) -> 17
C19: S.Nagar | D19: 08 | E19: 1 | F19: Dhrangadhra | G19: 3 | H19: =G19 -> 3 | I19: =H19 -> 3
E20: 2 | F20: Dasada | G20: 3 | H20: =G20 -> 3 | I20: =H20 -> 3
E21: 3 | F21: Lakhtar | G21: 2 | H21: =G21 -> 2 | I21: =H21 -> 2
E22: 4 | F22: Wadhwan | G22: 2 | H22: =G22 -> 2 | I22: =H22 -> 2
E23: 5 | F23: Limbdi | G23: 2 | H23: =G23 -> 2 | I23: =H23 -> 2
E24: 6 | F24: Muli | G24: 2 | H24: =G24 -> 2 | I24: =H24 -> 2
E25: 7 | F25: Sayla | G25: 2 | H25: =G25 -> 2 | I25: =H25 -> 2
E26: 8 | F26: Chotila | G26: 2 | H26: =G26 -> 2 | I26: =H26 -> 2
E27: 9 | F27: Chuda | G27: 2 | H27: =SUM(G27:G28) -> 2 | I27: =H27 -> 2
F28: Thangadh
E29: DISTRICT TOTAL | G29: =SUM(G19:G28) -> 20 | H29: =SUM(H19:H28) -> 20 | I29: =SUM(I19:I28) -> 20
C30: SRO TOTAL | G30: =SUM(G18,G29) -> 37 | H30: =SUM(H18,H29) -> 37 | I30: =SUM(I18,I29) -> 37
B31: Ahmedabad | C31: Gandhinagar | D31: 06 | E31: 1 | F31: Mansa | G31: 2 | H31: =G31 -> 2 | I31: =H31 -> 2
E32: 2 | F32: Gandhinagar | G32: 2 | H32: =G32 -> 2 | I32: =H32 -> 2
E33: 3 | F33: Dehgam | G33: 2 | H33: =G33 -> 2 | I33: =H33 -> 2
E34: 4 | F34: Kalol | G34: 2 | H34: =G34 -> 2 | I34: =H34 -> 2
E35: DISTRICT TOTAL | G35: =SUM(G31:G34) -> 8 | H35: =SUM(H31:H34) -> 8 | I35: =SUM(I31:I34) -> 8
C36: Ahmedabad | D36: 07 | E36: 1 | F36: Mandal | G36: 2 | H36: =SUM(G36:G37) -> 2 | I36: =H36 -> 2
F37: Detroj-Rampura
E38: 2 | F38: Viramgam | G38: 2 | H38: =G38 -> 2 | I38: =H38 -> 2
E39: 3 | F39: Sanand | G39: 2 | H39: =G39 -> 2 | I39: =H39 -> 2
E40: 4 | F40: Bavla | G40: 2 | H40: =G40 -> 2 | I40: =H40 -> 2
E41: 5 | F41: Daskroi | G41: 2 | H41: =G41 -> 2 | I41: =H41 -> 2
E42: 6 | F42: Dholka | G42: 2 | H42: =G42 -> 2 | I42: =H42 -> 2
E43: 7 | F43: Dhandhuka | G43: 2 | H43: =G43 -> 2 | I43: =H43 -> 2
...

Sheet 2.0SASA
A1: District | B1: Kharif Groundnut | C1: Maize | D1: Cotton (Irri) | E1: Cotton (Unirri) | F1: Castor | G1: Sesamum | H1: Tur | I1: Kh. Bajara | J1: Paddy (Irri) | K1: Paddy (Unirri) | L1: Kh. Juwar | M1: Ragi | N1: Soyabean | O1: Kh. Tobacco | Q1: Wheat I | R1: Wheat UI | S1: Rabi Jowar | T1: Rabi Maize | U1: Gram | V1: Rapeseed& Mustard | W1: Sugarcane | X1: Isabgul | Y1: Cumin | Z1: Fennel | AA1: Tobacco | AB1: Potato | AC1: Summer Groundnut | AD1: Summer Bajara | AE1: Summer Paddy | AF1: Summer Sesamum
A2: Kachchh | B2: 90 | C2: 0 | D2: 90 | E2: 20 | F2: 90 | G2: 90 | H2: 0 | I2: 30 | J2: 0 | K2: 0 | L2: 0 | M2: 0 | N2: 0 | O2: 0 | Q2: 90 | R2: 0 | S2: 0 | T2: 0 | U2: 0 | V2: 90 | W2: 0 | X2: 50 | Y2: 30 | Z2: 30 | AA2: 0 | AB2: 0 | AC2: 20 | AD2: 40 | AE2: 0 | AF2: 10
A3: Banaskantha | B3: 120 | C3: 30 | D3: 60 | E3: 0 | F3: 140 | G3: 0 | H3: 0 | I3: 80 | J3: 0 | K3: 0 | L3: 10 | M3: 0 | N3: 0 | O3: 0 | Q3: 140 | R3: 0 | S3: 0 | T3: 0 | U3: 0 | V3: 120 | W3: 0 | X3: 30 | Y3: 60 | Z3: 20 | AA3: 40 | AB3: 90 | AC3: 60 | AD3: 140 | AE3: 0 | AF3: 0
A4: Patan | B4: 10 | C4: 0 | D4: 70 | E4: 20 | F4: 90 | G4: 10 | H4: 0 | I4: 40 | J4: 0 | K4: 0 | L4: 0 | M4: 0 | N4: 0 | O4: 0 | Q4: 90 | R4: 0 | S4: 0 | T4: 0 | U4: 50 | V4: 80 | W4: 0 | X4: 30 | Y4: 40 | Z4: 30 | AA4: 40 | AB4: 10 | AC4: 0 | AD4: 40 | AE4: 0 | AF4: 0
A5: Mahesana | B5: 40 | C5: 0 | D5: 100 | E5: 0 | F5: 100 | G5: 10 | H5: 0 | I5: 20 | J5: 10 | K5: 0 | L5: 0 | M5: 0 | N5: 0 | O5: 0 | Q5: 100 | R5: 0 | S5: 0 | T5: 0 | U5: 10 | V5: 90 | W5: 0 | X5: 0 | Y5: 0 | Z5: 20 | AA5: 60 | AB5: 10 | AC5: 10 | AD5: 70 | AE5: 0 | AF5: 0
A6: Sabarkantha | B6: 60 | C6: 40 | D6: 70 | E6: 0 | F6: 60 | G6: 0 | H6: 40 | I6: 0 | J6: 10 | K6: 10 | L6: 0 | M6: 0 | N6: 50 | O6: 0 | Q6: 80 | R6: 0 | S6: 0 | T6: 10 | U6: 50 | V6: 20 | W6: 0 | X6: 0 | Y6: 0 | Z6: 20 | AA6: 30 | AB6: 60 | AC6: 10 | AD6: 20 | AE6: 0 | AF6: 0
A7: Arvalli | B7: 60 | C7: 60 | D7: 50 | E7: 0 | F7: 50 | G7: 0 | H7: 30 | I7: 10 | J7: 10 | K7: 0 | L7: 0 | M7: 0 | N7: 60 | O7: 0 | Q7: 60 | R7: 0 | S7: 0 | T7: 50 | U7: 60 | V7: 20 | W7: 0 | X7: 0 | Y7: 0 | Z7: 10 | AA7: 10 | AB7: 30 | AC7: 0 | AD7: 20 | AE7: 0 | AF7: 0
A8: Gandhinagar | B8: 30 | C8: 0 | D8: 40 | E8: 0 | F8: 40 | G8: 0 | H8: 0 | I8: 10 | J8: 30 | K8: 0 | L8: 0 | M8: 0 | N8: 0 | O8: 0 | Q8: 40 | R8: 0 | S8: 0 | T8: 0 | U8: 10 | V8: 30 | W8: 0 | X8: 0 | Y8: 0 | Z8: 10 | AA8: 10 | AB8: 30 | AC8: 0 | AD8: 30 | AE8: 0 | AF8: 0
A9: Ahmedabad | B9: 0 | C9: 0 | D9: 40 | E9: 60 | F9: 60 | G9: 0 | H9: 20 | I9: 0 | J9: 52 | K9: 0 | L9: 0 | M9: 0 | N9: 0 | O9: 0 | Q9: 90 | R9: 35 | S9: 0 | T9: 0 | U9: 60 | V9: 40 | W9: 0 | X9: 10 | Y9: 50 | Z9: 0 | AA9: 0 | AB9: 0 | AC9: 0 | AD9: 10 | AE9: 40 | AF9: 10
A10: Surendranagar | B10: 60 | C10: 0 | D10: 100 | E10: 60 | F10: 70 | G10: 60 | H10: 10 | I10: 10 | J10: 10 | K10: 10 | L10: 0 | M10: 0 | N10: 0 | O10: 0 | Q10: 100 | R10: 10 | S10: 0 | T10: 0 | U10: 90 | V10: 40 | W10: 0 | X10: 10 | Y10: 100 | Z10: 60 | AA10: 0 | AB10: 0 | AC10: 0 | AD10: 0 | AE10: 0 | AF10: 60
A11: Morbi | B11: 50 | C11: 0 | D11: 50 | E11: 30 | F11: 30 | G11: 30 | H11: 10 | I11: 0 | J11: 0 | K11: 0 | L11: 0 | M11: 0 | N11: 10 | O11: 0 | Q11: 50 | R11: 0 | S11: 0 | T11: 0 | U11: 50 | V11: 20 | W11: 0 | X11: 0 | Y11: 50 | Z11: 30 | AA11: 0 | AB11: 0 | AC11: 10 | AD11: 10 | AE11: 0 | AF11: 30
A12: Rajkot | B12: 110 | C12: 0 | D12: 110 | E12: 0 | F12: 20 | G12: 0 | H12: 20 | I12: 0 | J12: 0 | K12: 0 | L12: 0 | M12: 0 | N12: 50 | O12: 0 | Q12: 110 | R12: 0 | S12: 0 | T12: 0 | U12: 110 | V12: 0 | W12: 0 | X12: 0 | Y12: 90 | Z12: 0 | AA12: 0 | AB12: 0 | AC12: 0 | AD12: 0 | AE12: 0 | AF12: 50
A13: Jamnagar | B13: 60 | C13: 0 | D13: 60 | E13: 0 | F13: 30 | G13: 10 | H13: 20 | I13: 0 | J13: 0 | K13: 0 | L13: 0 | M13: 0 | N13: 10 | O13: 0 | Q13: 60 | R13: 0 | S13: 0 | T13: 0 | U13: 60 | V13: 30 | W13: 0 | X13: 0 | Y13: 60 | Z13: 0 | AA13: 0 | AB13: 0 | AC13: 10 | AD13: 0 | AE13: 0 | AF13: 50
... A34: Tapi | B34: 10 | C34: 10 | D34: 20 | E34: 20 | F34: 0 | G34: 0 | H34: 50 | I34: 0 | J34: 50 | K34: 40 | L34: 30 | M34: 0 | N34: 40 | O34: 0 | Q34: 20 | R34: 0 | S34: 10 | T34: 0 | U34: 40 | V34: 0 | W34: 70 | X34: 0 | Y34: 0 | Z34: 0 | AA34: 0 | AB34: 0 | AC34: 20 | AD34: 0 | AE34: 10 | AF34: 0
A35: Grand Total

Sheet 2.0WS(S)
A1: ="WORKING SHEET FOR A1SCHEDULE 2.0 OF GUJARAT BASED ON CES DATA 2024-25" -> WORKING SHEET FOR A1SCHEDULE 2.0 OF GUJARAT BASED ON CES DATA 2024-25
B2: KHARIF | AF2: RABI | AO2: SUMMER
B3: MAIZE | E3: GR NUT | H3: Paddy(I) | K3: Paddy(UI) | N3: SEASMUM | Q3: BAJRA | T3: CASTOR | W3: TUR | Z3: COTTON(I) | AC3: COTTON(UI) | AF3: R & MUSTARD | AI3: GRAM | AL3: WHEAT(I) | AO3: BAJRA
A4: District | B4: CES | C4: ICS | D4: ADJ. | E4: CES | F4: ICS | G4: ADJ. | H4: CES | I4: ICS | J4: ADJ. | K4: CES | L4: ICS | M4: ADJ. | N4: CES | O4: ICS | P4: ADJ. | Q4: CES | R4: ICS | S4: ADJ. | T4: CES | U4: ICS | V4: ADJ. | W4: CES | X4: ICS | Y4: ADJ. | Z4: CES | AA4: ICS | AB4: ADJ. | AC4: CES | AD4: ICS | AE4: ADJ. | AF4: CES | AG4: ICS | AH4: ADJ. | AI4: CES | AJ4: ICS | AK4: ADJ. | AL4: CES | AM4: ICS | AN4: ADJ. | AO4: CES | AP4: ICS | AQ4: ADJ.
A5: Kachchh | B5: =_xlfn.XLOOKUP(A5,'2.0SASA'!$A:$A,'2.0SASA'!$C:$C,"",0) -> 0 | C5: =B5*C$50/B$50 -> 0 | D5: =IF(C5>4,ROUND(C5/2,0)*2,IF(C5>2.2,4,0)) -> 0 | E5: =_xlfn.XLOOKUP(A5,'2.0SASA'!$A:$A,'2.0SASA'!$B:$B,"",0) -> 90 | F5: =E5*F$50/E$50 -> 9 | G5: =IF(F5>4,ROUND(F5/2,0)*2,IF(F5>2.2,4,0)) -> 10 | H5: =_xlfn.XLOOKUP(A5,'2.0SASA'!$A:$A,'2.0SASA'!$J:$J,"",0) -> 0 | I5: =H5*I$50/H$50 -> 0 | J5: =IF(I5>4,ROUND(I5/2,0)*2,IF(I5>2,4,0)) -> 0 | K5: =_xlfn.XLOOKUP(A5,'2.0SASA'!$A:$A,'2.0SASA'!$K:$K,"",0) -> 0 | L5: =K5*L$50/K$50 -> 0 | M5: =IF(L5>4,ROUND(L5/2,0)*2,IF(L5>2.2,4,0)) -> 0 | N5: =_xlfn.XLOOKUP(A5,'2.0SASA'!$A:$A,'2.0SASA'!$G:$G,"",0) -> 90 | O5: =N5*O$50/N$50 -> 12 | P5: 14 | Q5: =_xlfn.XLOOKUP(A5,'2.0SASA'!$A:$A,'2.0SASA'!$I:$I,"",0) -> 30 | R5: =Q5*R$50/Q$50 -> 3.4285714 | S5: =IF(R5>4,ROUND(R5/2,0)*2,IF(R5>2.2,4,0)) -> 4 | T5: =_xlfn.XLOOKUP(A5,'2.0SASA'!$A:$A,'2.0SASA'!$F:$F,"",0) -> 90 | U5: =T5*U$50/T$50 -> 9 | V5: 8 | W5: =_xlfn.XLOOKUP(A5,'2.0SASA'!$A:$A,'2.0SASA'!$H:$H,"",0) -> 0 | X5: =W5*X$50/W$50 -> 0 | Y5: =IF(X5>4,ROUND(X5/2,0)*2,IF(X5>2.2,4,0)) -> 0 | Z5: =_xlfn.XLOOKUP(A5,'2.0SASA'!$A:$A,'2.0SASA'!$D:$D,"",0) -> 90 | AA5: =Z5*AA$50/Z$50 -> 8.7272727 | AB5: =IF(AA5>4,ROUND(AA5/2,0)*2,IF(AA5>2.2,4,0)) -> 8 | AC5: =_xlfn.XLOOKUP(A5,'2.0SASA'!$A:$A,'2.0SASA'!$E:$E,"",0) -> 20 | AD5: =AC5*AD$50/AC$50 -> 1.9354839 | AE5: =IF(AD5>4,ROUND(AD5/2,0)*2,IF(AD5>2.2,4,0)) -> 0 | AF5: =_xlfn.XLOOKUP(A5,'2.0SASA'!$A:$A,'2.0SASA'!$V:$V,"",0) -> 90 | AG5: =AF5*AG$50/AF$50 -> 6 | AH5: 6 | AI5: =_xlfn.XLOOKUP(A5,'2.0SASA'!$A:$A,'2.0SASA'!$U:$U,"",0) -> 0 | AJ5: =AI5*AJ$50/AI$50 -> 0 | AK5: =IF(AJ5>4,ROUND(AJ5/2,0)*2,IF(AJ5>2,4,0)) -> 0 | AL5: =_xlfn.XLOOKUP(A5,'2.0SASA'!$A:$A,'2.0SASA'!$Q:$Q,"",0) -> 90 | AM5: =AL5*AM$50/AL$50 -> 4.3478261 | AN5: =IF(AM5>4,ROUND(AM5/2,0)*2,IF(AM5>2.2,4,0)) -> 4 | AO5: =_xlfn.XLOOKUP(A5,'2.0SASA'!$A:$A,'2.0SASA'!$AD:$AD,"",0) -> 40 | AP5: =AO5*AP$50/AO$50 -> 2.0779221 | AQ5: 4
A6: Surendranagar | B6: =_xlfn.XLOOKUP(A6,'2.0SASA'!$A:$A,'2.0SASA'!$C:$C,"",0) -> 0 | C6: =B6*C$50/B$50 -> 0 | D6: =IF(C6>4,ROUND(C6/2,0)*2,IF(C6>2.2,4,0)) -> 0 | E6: =_xlfn.XLOOKUP(A6,'2.0SASA'!$A:$A,'2.0SASA'!$B:$B,"",0) -> 60 | F6: =E6*F$50/E$50 -> 6 | G6: =IF(F6>4,ROUND(F6/2,0)*2,IF(F6>2.2,4,0)) -> 6 | H6: =_xlfn.XLOOKUP(A6,'2.0SASA'!$A:$A,'2.0SASA'!$J:$J,"",0) -> 10 | I6: =H6*I$50/H$50 -> 0.91743119 | J6: =IF(I6>4,ROUND(I6/2,0)*2,IF(I6>2,4,0)) -> 0 | K6: =_xlfn.XLOOKUP(A6,'2.0SASA'!$A:$A,'2.0SASA'!$K:$K,"",0) -> 10 | L6: =K6*L$50/K$50 -> 1.025641 | M6: =IF(L6>4,ROUND(L6/2,0)*2,IF(L6>2.2,4,0)) -> 0 | N6: =_xlfn.XLOOKUP(A6,'2.0SASA'!$A:$A,'2.0SASA'!$G:$G,"",0) -> 60 | O6: =N6*O$50/N$50 -> 8 | P6: 10 | Q6: =_xlfn.XLOOKUP(A6,'2.0SASA'!$A:$A,'2.0SASA'!$I:$I,"",0) -> 10 | R6: =Q6*R$50/Q$50 -> 1.1428571 | S6: =IF(R6>4,ROUND(R6/2,0)*2,IF(R6>2.2,4,0)) -> 0 | T6: =_xlfn.XLOOKUP(A6,'2.0SASA'!$A:$A,'2.0SASA'!$F:$F,"",0) -> 70 | U6: =T6*U$50/T$50 -> 7 | V6: =IF(U6>4,ROUND(U6/2,0)*2,IF(U6>2.2,4,0)) -> 8 | W6: =_xlfn.XLOOKUP(A6,'2.0SASA'!$A:$A,'2.0SASA'!$H:$H,"",0) -> 10 | X6: =W6*X$50/W$50 -> 0.875 | Y6: =IF(X6>4,ROUND(X6/2,0)*2,IF(X6>2.2,4,0)) -> 0 | Z6: =_xlfn.XLOOKUP(A6,'2.0SASA'!$A:$A,'2.0SASA'!$D:$D,"",0) -> 100 | AA6: =Z6*AA$50/Z$50 -> 9.6969697 | AB6: =IF(AA6>4,ROUND(AA6/2,0)*2,IF(AA6>2.2,4,0)) -> 10 | AC6: =_xlfn.XLOOKUP(A6,'2.0SASA'!$A:$A,'2.0SASA'!$E:$E,"",0) -> 60 | AD6: =AC6*AD$50/AC$50 -> 5.8064516 | AE6: =IF(AD6>4,ROUND(AD6/2,0)*2,IF(AD6>2.2,4,0)) -> 6 | AF6: =_xlfn.XLOOKUP(A6,'2.0SASA'!$A:$A,'2.0SASA'!$V:$V,"",0) -> 40 | AG6: =AF6*AG$50/AF$50 -> 2.6666667 | AH6: =IF(AG6>4,ROUND(AG6/2,0)*2,IF(AG6>2.2,4,0)) -> 4 | AI6: =_xlfn.XLOOKUP(A6,'2.0SASA'!$A:$A,'2.0SASA'!$U:$U,"",0) -> 90 | AJ6: =AI6*AJ$50/AI$50 -> 4.0601504 | AK6: =IF(AJ6>4,ROUND(AJ6/2,0)*2,IF(AJ6>2,4,0)) -> 4 | AL6: =_xlfn.XLOOKUP(A6,'2.0SASA'!$A:$A,'2.0SASA'!$Q:$Q,"",0) -> 100 | AM6: =AL6*AM$50/AL$50 -> 4.8309179 | AN6: 6 | AO6: =_xlfn.XLOOKUP(A6,'2.0SASA'!$A:$A,'2.0SASA'!$AD:$AD,"",0) -> 0 | AP6: =AO6*AP$50/AO$50 -> 0 | AQ6: =IF(AP6>4,ROUND(AP6/2,0)*2,IF(AP6>2.2,4,0)) -> 0
A7: SRO S.NAGAR TOTAL | B7: =SUM(B5:B6) -> 0 | C7: =SUM(C5:C6) -> 0 | D7: =SUM(D5:D6) -> 0 | E7: =SUM(E5:E6) -> 150 | F7: =SUM(F5:F6) -> 15 | G7: =SUM(G5:G6) -> 16 | H7: =SUM(H5:H6) -> 10 | I7: =SUM(I5:I6) -> 0.91743119 | ... AQ7: =SUM(AQ5:AQ6) -> 4
A8: Gandhinagar | B8: =_xlfn.XLOOKUP(A8,'2.0SASA'!$A:$A,'2.0SASA'!$C:$C,"",0) -> 0 | C8: =B8*C$50/B$50 -> 0 | D8: =IF(C8>4,ROUND(C8/2,0)*2,IF(C8>2.2,4,0)) -> 0 | E8: =_xlfn.XLOOKUP(A8,'2.0SASA'!$A:$A,'2.0SASA'!$B:$B,"",0) -> 30 | F8: =E8*F$50/E$50 -> 3 | G8: =IF(F8>4,ROUND(F8/2,0)*2,IF(F8>2.2,4,0)) -> 4 | H8: =_xlfn.XLOOKUP(A8,'2.0SASA'!$A:$A,'2.0SASA'!$J:$J,"",0) -> 30 | I8: =H8*I$50/H$50 -> 2.7522936 | J8: =IF(I8>4,ROUND(I8/2,0)*2,IF(I8>2,4,0)) -> 4 | K8: =_xlfn.XLOOKUP(A8,'2.0SASA'!$A:$A,'2.0SASA'!$K:$K,"",0) -> 0 | L8: =K8*L$50/K$50 -> 0 | M8: =IF(L8>4,ROUND(L8/2,0)*2,IF(L8>2.2,4,0)) -> 0 | N8: =_xlfn.XLOOKUP(A8,'2.0SASA'!$A:$A,'2.0SASA'!$G:$G,"",0) -> 0 | O8: =N8*O$50/N$50 -> 0 | P8: =IF(O8>4,ROUND(O8/2,0)*2,IF(O8>2.2,4,0)) -> 0 | Q8: =_xlfn.XLOOKUP(A8,'2.0SASA'!$A:$A,'2.0SASA'!$I:$I,"",0) -> 10 | R8: =Q8*R$50/Q$50 -> 1.1428571 | S8: =IF(R8>4,ROUND(R8/2,0)*2,IF(R8>2.2,4,0)) -> 0 | T8: =_xlfn.XLOOKUP(A8,'2.0SASA'!$A:$A,'2.0SASA'!$F:$F,"",0) -> 40 | U8: =T8*U$50/T$50 -> 4 | V8: =IF(U8>4,ROUND(U8/2,0)*2,IF(U8>2.2,4,0)) -> 4 | W8: =_xlfn.XLOOKUP(A8,'2.0SASA'!$A:$A,'2.0SASA'!$H:$H,"",0) -> 0 | X8: =W8*X$50/W$50 -> 0 | Y8: =IF(X8>4,ROUND(X8/2,0)*2,IF(X8>2.2,4,0)) -> 0 | Z8: =_xlfn.XLOOKUP(A8,'2.0SASA'!$A:$A,'2.0SASA'!$D:$D,"",0) -> 40 | AA8: =Z8*AA$50/Z$50 -> 3.8787879 | AB8: =IF(AA8>4,ROUND(AA8/2,0)*2,IF(AA8>2.2,4,0)) -> 4 | AC8: =_xlfn.XLOOKUP(A8,'2.0SASA'!$A:$A,'2.0SASA'!$E:$E,"",0) -> 0 | AD8: =AC8*AD$50/AC$50 -> 0 | AE8: =IF(AD8>4,ROUND(AD8/2,0)*2,IF(AD8>2.2,4,0)) -> 0 | AF8: =_xlfn.XLOOKUP(A8,'2.0SASA'!$A:$A,'2.0SASA'!$V:$V,"",0) -> 30 | AG8: =AF8*AG$50/AF$50 -> 2 | AH8: 4 | AI8: =_xlfn.XLOOKUP(A8,'2.0SASA'!$A:$A,'2.0SASA'!$U:$U,"",0) -> 10 | AJ8: =AI8*AJ$50/AI$50 -> 0.45112782 | AK8: =IF(AJ8>4,ROUND(AJ8/2,0)*2,IF(AJ8>2,4,0)) -> 0 | AL8: =_xlfn.XLOOKUP(A8,'2.0SASA'!$A:$A,'2.0SASA'!$Q:$Q,"",0) -> 40 | AM8: =AL8*AM$50/AL$50 -> 1.9323671 | AN8: =IF(AM8>4,ROUND(AM8/2,0)*2,IF(AM8>2.2,4,0)) -> 0 | AO8: =_xlfn.XLOOKUP(A8,'2.0SASA'!$A:$A,'2.0SASA'!$AD:$AD,"",0) -> 30 | AP8: =AO8*AP$50/AO$50 -> 1.5584416 | AQ8: =IF(AP8>4,ROUND(AP8/2,0)*2,IF(AP8>2.2,4,0)) -> 0
A9: Ahmedabad | B9: =_xlfn.XLOOKUP(A9,'2.0SASA'!$A:$A,'2.0SASA'!$C:$C,"",0) -> 0 | C9: =B9*C$50/B$50 -> 0 | D9: =IF(C9>4,ROUND(C9/2,0)*2,IF(C9>2.2,4,0)) -> 0 | E9: =_xlfn.XLOOKUP(A9,'2.0SASA'!$A:$A,'2.0SASA'!$B:$B,"",0) -> 0 | F9: =E9*F$50/E$50 -> 0 | G9: =IF(F9>4,ROUND(F9/2,0)*2,IF(F9>2.2,4,0)) -> 0 | H9: =_xlfn.XLOOKUP(A9,'2.0SASA'!$A:$A,'2.0SASA'!$J:$J,"",0) -> 52 | I9: =H9*I$50/H$50 -> 4.7706422 | J9: =IF(I9>4,ROUND(I9/2,0)*2,IF(I9>2,4,0)) -> 4 | K9: =_xlfn.XLOOKUP(A9,'2.0SASA'!$A:$A,'2.0SASA'!$K:$K,"",0) -> 0 | L9: =K9*L$50/K$50 -> 0 | M9: =IF(L9>4,ROUND(L9/2,0)*2,IF(L9>2.2,4,0)) -> 0 | N9: =_xlfn.XLOOKUP(A9,'2.0SASA'!$A:$A,'2.0SASA'!$G:$G,"",0) -> 0 | O9: =N9*O$50/N$50 -> 0 | P9: =IF(O9>4,ROUND(O9/2,0)*2,IF(O9>2.2,4,0)) -> 0 | Q9: =_xlfn.XLOOKUP(A9,'2.0SASA'!$A:$A,'2.0SASA'!$I:$I,"",0) -> 0 | R9: =Q9*R$50/Q$50 -> 0 | S9: =IF(R9>4,ROUND(R9/2,0)*2,IF(R9>2.2,4,0)) -> 0 | T9: =_xlfn.XLOOKUP(A9,'2.0SASA'!$A:$A,'2.0SASA'!$F:$F,"",0) -> 60 | U9: =T9*U$50/T$50 -> 6 | V9: =IF(U9>4,ROUND(U9/2,0)*2,IF(U9>2.2,4,0)) -> 6 | W9: =_xlfn.XLOOKUP(A9,'2.0SASA'!$A:$A,'2.0SASA'!$H:$H,"",0) -> 20 | X9: =W9*X$50/W$50 -> 1.75 | Y9: =IF(X9>4,ROUND(X9/2,0)*2,IF(X9>2.2,4,0)) -> 0 | Z9: =_xlfn.XLOOKUP(A9,'2.0SASA'!$A:$A,'2.0SASA'!$D:$D,"",0) -> 40 | AA9: =Z9*AA$50/Z$50 -> 3.8787879 | AB9: =IF(AA9>4,ROUND(AA9/2,0)*2,IF(AA9>2.2,4,0)) -> 4 | AC9: =_xlfn.XLOOKUP(A9,'2.0SASA'!$A:$A,'2.0SASA'!$E:$E,"",0) -> 60 | AD9: =AC9*AD$50/AC$50 -> 5.8064516 | AE9: =IF(AD9>4,ROUND(AD9/2,0)*2,IF(AD9>2.2,4,0)) -> 6 | AF9: =_xlfn.XLOOKUP(A9,'2.0SASA'!$A:$A,'2.0SASA'!$V:$V,"",0) -> 40 | AG9: =AF9*AG$50/AF$50 -> 2.6666667 | AH9: =IF(AG9>4,ROUND(AG9/2,0)*2,IF(AG9>2.2,4,0)) -> 4 | AI9: =_xlfn.XLOOKUP(A9,'2.0SASA'!$A:$A,'2.0SASA'!$U:$U,"",0) -> 60 | AJ9: =AI9*AJ$50/AI$50 -> 2.7067669 | AK9: =IF(AJ9>4,ROUND(AJ9/2,0)*2,IF(AJ9>2,4,0)) -> 4 | AL9: =_xlfn.XLOOKUP(A9,'2.0SASA'!$A:$A,'2.0SASA'!$Q:$Q,"",0) -> 90 | AM9: =AL9*AM$50/AL$50 -> 4.3478261 | AN9: =IF(AM9>4,ROUND(AM9/2,0)*2,IF(AM9>2.2,4,0)) -> 4 | AO9: =_xlfn.XLOOKUP(A9,'2.0SASA'!$A:$A,'2.0SASA'!$AD:$AD,"",0) -> 10 | AP9: =AO9*AP$50/AO$50 -> 0.51948052 | AQ9: =IF(AP9>4,ROUND(AP9/2,0)*2,IF(AP9>2.2,4,0)) -> 0
A10: SRO AHEMDABAD TOTAL | B10: =SUM(B8:B9) -> 0 | C10: =SUM(C8:C9) -> 0 | D10: =SUM(D8:D9) -> 0 | E10: =SUM(E8:E9) -> 30 | F10: =SUM(F8:F9) -> 3 | G10: =SUM(G8:G9) -> 4 | H10: =SUM(H8:H9) -> 82 | I10: =SUM(I8:I9) -> 7.5229358 | ... AQ10: =SUM(AQ8:AQ9) -> 0
A11: Rajkot | B11: =_xlfn.XLOOKUP(A11,'2.0SASA'!$A:$A,'2.0SASA'!$C:$C,"",0) -> 0 | C11: =B11*C$50/B$50 -> 0 | D11: =IF(C11>4,ROUND(C11/2,0)*2,IF(C11>2.2,4,0)) -> 0 | E11: =_xlfn.XLOOKUP(A11,'2.0SASA'!$A:$A,'2.0SASA'!$B:$B,"",0) -> 110 | F11: =E11*F$50/E$50 -> 11 | G11: 10 | H11: =_xlfn.XLOOKUP(A11,'2.0SASA'!$A:$A,'2.0SASA'!$J:$J,"",0) -> 0 | I11: =H11*I$50/H$50 -> 0 | J11: =IF(I11>4,ROUND(I11/2,0)*2,IF(I11>2,4,0)) -> 0 | K11: =_xlfn.XLOOKUP(A11,'2.0SASA'!$A:$A,'2.0SASA'!$K:$K,"",0) -> 0 | L11: =K11*L$50/K$50 -> 0 | M11: =IF(L11>4,ROUND(L11/2,0)*2,IF(L11>2.2,4,0)) -> 0 | N11: =_xlfn.XLOOKUP(A11,'2.0SASA'!$A:$A,'2.0SASA'!$G:$G,"",0) -> 0 | O11: =N11*O$50/N$50 -> 0 | P11: =IF(O11>4,ROUND(O11/2,0)*2,IF(O11>2.2,4,0)) -> 0 | Q11: =_xlfn.XLOOKUP(A11,'2.0SASA'!$A:$A,'2.0SASA'!$I:$I,"",0) -> 0 | R11: =Q11*R$50/Q$50 -> 0 | S11: =IF(R11>4,ROUND(R11/2,0)*2,IF(R11>2.2,4,0)) -> 0 | T11: =_xlfn.XLOOKUP(A11,'2.0SASA'!$A:$A,'2.0SASA'!$F:$F,"",0) -> 20 | U11: =T11*U$50/T$50 -> 2 | V11: =IF(U11>4,ROUND(U11/2,0)*2,IF(U11>2.2,4,0)) -> 0 | W11: =_xlfn.XLOOKUP(A11,'2.0SASA'!$A:$A,'2.0SASA'!$H:$H,"",0) -> 20 | X11: =W11*X$50/W$50 -> 1.75 | Y11: =IF(X11>4,ROUND(X11/2,0)*2,IF(X11>2.2,4,0)) -> 0 | Z11: =_xlfn.XLOOKUP(A11,'2.0SASA'!$A:$A,'2.0SASA'!$D:$D,"",0) -> 110 | AA11: =Z11*AA$50/Z$50 -> 10.666667 | AB11: =IF(AA11>4,ROUND(AA11/2,0)*2,IF(AA11>2.2,4,0)) -> 10 | AC11: =_xlfn.XLOOKUP(A11,'2.0SASA'!$A:$A,'2.0SASA'!$E:$E,"",0) -> 0 | AD11: =AC11*AD$50/AC$50 -> 0 | AE11: =IF(AD11>4,ROUND(AD11/2,0)*2,IF(AD11>2.2,4,0)) -> 0 | AF11: =_xlfn.XLOOKUP(A11,'2.0SASA'!$A:$A,'2.0SASA'!$V:$V,"",0) -> 0 | AG11: =AF11*AG$50/AF$50 -> 0 | AH11: =IF(AG11>4,ROUND(AG11/2,0)*2,IF(AG11>2.2,4,0)) -> 0 | AI11: =_xlfn.XLOOKUP(A11,'2.0SASA'!$A:$A,'2.0SASA'!$U:$U,"",0) -> 110 | AJ11: =AI11*AJ$50/AI$50 -> 4.962406 | AK11: 6 | AL11: =_xlfn.XLOOKUP(A11,'2.0SASA'!$A:$A,'2.0SASA'!$Q:$Q,"",0) -> 110 | AM11: =AL11*AM$50/AL$50 -> 5.3140097 | AN11: =IF(AM11>4,ROUND(AM11/2,0)*2,IF(AM11>2.2,4,0)) -> 6 | AO11: =_xlfn.XLOOKUP(A11,'2.0SASA'!$A:$A,'2.0SASA'!$AD:$AD,"",0) -> 0 | AP11: =AO11*AP$50/AO$50 -> 0 | AQ11: =IF(AP11>4,ROUND(AP11/2,0)*2,IF(AP11>2.2,4,0)) -> 0
A12: Morbi | B12: =_xlfn.XLOOKUP(A12,'2.0SASA'!$A:$A,'2.0SASA'!$C:$C,"",0) -> 0 | C12: =B12*C$50/B$50 -> 0 | D12: =IF(C12>4,ROUND(C12/2,0)*2,IF(C12>2.2,4,0)) -> 0 | E12: =_xlfn.XLOOKUP(A12,'2.0SASA'!$A:$A,'2.0SASA'!$B:$B,"",0) -> 50 | F12: =E12*F$50/E$50 -> 5 | G12: =IF(F12>4,ROUND(F12/2,0)*2,IF(F12>2.2,4,0)) -> 6 | H12: =_xlfn.XLOOKUP(A12,'2.0SASA'!$A:$A,'2.0SASA'!$J:$J,"",0) -> 0 | I12: =H12*I$50/H$50 -> 0 | J12: =IF(I12>4,ROUND(I12/2,0)*2,IF(I12>2,4,0)) -> 0 | K12: =_xlfn.XLOOKUP(A12,'2.0SASA'!$A:$A,'2.0SASA'!$K:$K,"",0) -> 0 | L12: =K12*L$50/K$50 -> 0 | M12: =IF(L12>4,ROUND(L12/2,0)*2,IF(L12>2.2,4,0)) -> 0 | N12: =_xlfn.XLOOKUP(A12,'2.0SASA'!$A:$A,'2.0SASA'!$G:$G,"",0) -> 30 | O12: =N12*O$50/N$50 -> 4 | P12: =IF(O12>4,ROUND(O12/2,0)*2,IF(O12>2.2,4,0)) -> 4 | Q12: =_xlfn.XLOOKUP(A12,'2.0SASA'!$A:$A,'2.0SASA'!$I:$I,"",0) -> 0 | R12: =Q12*R$50/Q$50 -> 0 | S12: =IF(R12>4,ROUND(R12/2,0)*2,IF(R12>2.2,4,0)) -> 0 | T12: =_xlfn.XLOOKUP(A12,'2.0SASA'!$A:$A,'2.0SASA'!$F:$F,"",0) -> 30 | U12: =T12*U$50/T$50 -> 3 | V12: =IF(U12>4,ROUND(U12/2,0)*2,IF(U12>2.2,4,0)) -> 4 | W12: =_xlfn.XLOOKUP(A12,'2.0SASA'!$A:$A,'2.0SASA'!$H:$H,"",0) -> 10 | X12: =W12*X$50/W$50 -> 0.875 | Y12: =IF(X12>4,ROUND(X12/2,0)*2,IF(X12>2.2,4,0)) -> 0 | Z12: =_xlfn.XLOOKUP(A12,'2.0SASA'!$A:$A,'2.0SASA'!$D:$D,"",0) -> 50 | AA12: =Z12*AA$50/Z$50 -> 4.8484848 | AB12: =IF(AA12>4,ROUND(AA12/2,0)*2,IF(AA12>2.2,4,0)) -> 4 | AC12: =_xlfn.XLOOKUP(A12,'2.0SASA'!$A:$A,'2.0SASA'!$E:$E,"",0) -> 30 | AD12: =AC12*AD$50/AC$50 -> 2.9032258 | AE12: =IF(AD12>4,ROUND(AD12/2,0)*2,IF(AD12>2.2,4,0)) -> 4 | AF12: =_xlfn.XLOOKUP(A12,'2.0SASA'!$A:$A,'2.0SASA'!$V:$V,"",0) -> 20 | AG12: =AF12*AG$50/AF$50 -> 1.3333333 | AH12: =IF(AG12>4,ROUND(AG12/2,0)*2,IF(AG12>2.2,4,0)) -> 0 | AI12: =_xlfn.XLOOKUP(A12,'2.0SASA'!$A:$A,'2.0SASA'!$U:$U,"",0) -> 50 | AJ12: =AI12*AJ$50/AI$50 -> 2.2556391 | AK12: =IF(AJ12>4,ROUND(AJ12/2,0)*2,IF(AJ12>2,4,0)) -> 4 | AL12: =_xlfn.XLOOKUP(A12,'2.0SASA'!$A:$A,'2.0SASA'!$Q:$Q,"",0) -> 50 | AM12: =AL12*AM$50/AL$50 -> 2.4154589 | AN12: =IF(AM12>4,ROUND(AM12/2,0)*2,IF(AM12>2.2,4,0)) -> 4 | AO12: =_xlfn.XLOOKUP(A12,'2.0SASA'!$A:$A,'2.0SASA'!$AD:$AD,"",0) -> 10 | AP12: =AO12*AP$50/AO$50 -> 0.51948052 | AQ12: =IF(AP12>4,ROUND(AP12/2,0)*2,IF(AP12>2.2,4,0)) -> 0
A13: Junagadh | B13: =_xlfn.XLOOKUP(A13,'2.0SASA'!$A:$A,'2.0SASA'!$C:$C,"",0) -> 0 | C13: =B13*C$50/B$50 -> 0 | D13: =IF(C13>4,ROUND(C13/2,0)*2,IF(C13>2.2,4,0)) -> 0 | E13: =_xlfn.XLOOKUP(A13,'2.0SASA'!$A:$A,'2.0SASA'!$B:$B,"",0) -> 90 | F13: =E13*F$50/E$50 -> 9 | G13: =IF(F13>4,ROUND(F13/2,0)*2,IF(F13>2.2,4,0)) -> 10 | H13: =_xlfn.XLOOKUP(A13,'2.0SASA'!$A:$A,'2.0SASA'!$J:$J,"",0) -> 0 | I13: =H13*I$50/H$50 -> 0 | J13: =IF(I13>4,ROUND(I13/2,0)*2,IF(I13>2,4,0)) -> 0 | K13: =_xlfn.XLOOKUP(A13,'2.0SASA'!$A:$A,'2.0SASA'!$K:$K,"",0) -> 0 | L13: =K13*L$50/K$50 -> 0 | M13: =IF(L13>4,ROUND(L13/2,0)*2,IF(L13>2.2,4,0)) -> 0 | N13: =_xlfn.XLOOKUP(A13,'2.0SASA'!$A:$A,'2.0SASA'!$G:$G,"",0) -> 0 | O13: =N13*O$50/N$50 -> 0 | P13: =IF(O13>4,ROUND(O13/2,0)*2,IF(O13>2.2,4,0)) -> 0 | Q13: =_xlfn.XLOOKUP(A13,'2.0SASA'!$A:$A,'2.0SASA'!$I:$I,"",0) -> 0 | R13: =Q13*R$50/Q$50 -> 0 | S13: =IF(R13>4,ROUND(R13/2,0)*2,IF(R13>2.2,4,0)) -> 0 | T13: =_xlfn.XLOOKUP(A13,'2.0SASA'!$A:$A,'2.0SASA'!$F:$F,"",0) -> 0 | U13: =T13*U$50/T$50 -> 0 | V13: =IF(U13>4,ROUND(U13/2,0)*2,IF(U13>2.2,4,0)) -> 0 | W13: =_xlfn.XLOOKUP(A13,'2.0SASA'!$A:$A,'2.0SASA'!$H:$H,"",0) -> 60 | X13: =W13*X$50/W$50 -> 5.25 | Y13: =IF(X13>4,ROUND(X13/2,0)*2,IF(X13>2.2,4,0)) -> 6 | Z13: =_xlfn.XLOOKUP(A13,'2.0SASA'!$A:$A,'2.0SASA'!$D:$D,"",0) -> 50 | AA13: =Z13*AA$50/Z$50 -> 4.8484848 | AB13: =IF(AA13>4,ROUND(AA13/2,0)*2,IF(AA13>2.2,4,0)) -> 4 | AC13: =_xlfn.XLOOKUP(A13,'2.0SASA'!$A:$A,'2.0SASA'!$E:$E,"",0) -> 0 | AD13: =AC13*AD$50/AC$50 -> 0 | AE13: =IF(AD13>4,ROUND(AD13/2,0)*2,IF(AD13>2.2,4,0)) -> 0 | AF13: =_xlfn.XLOOKUP(A13,'2.0SASA'!$A:$A,'2.0SASA'!$V:$V,"",0) -> 0 | AG13: =AF13*AG$50/AF$50 -> 0 | AH13: =IF(AG13>4,ROUND(AG13/2,0)*2,IF(AG13>2.2,4,0)) -> 0 | AI13: =_xlfn.XLOOKUP(A13,'2.0SASA'!$A:$A,'2.0SASA'!$U:$U,"",0) -> 90 | AJ13: =AI13*AJ$50/AI$50 -> 4.0601504 | AK13: =IF(AJ13>4,ROUND(AJ13/2,0)*2,IF(AJ13>2,4,0)) -> 4 | AL13: =_xlfn.XLOOKUP(A13,'2.0SASA'!$A:$A,'2.0SASA'!$Q:$Q,"",0) -> 90 | AM13: =AL13*AM$50/AL$50 -> 4.3478261 | AN13: =IF(AM13>4,ROUND(AM13/2,0)*2,IF(AM13>2.2,4,0)) -> 4 | AO13: =_xlfn.XLOOKUP(A13,'2.0SASA'!$A:$A,'2.0SASA'!$AD:$AD,"",0) -> 10 | AP13: =AO13*AP$50/AO$50 -> 0.51948052 | AQ13: =IF(AP13>4,ROUND(AP13/2,0)*2,IF(AP13>2.2,4,0)) -> 0
A14: Gir Somnath | B14: =_xlfn.XLOOKUP(A14,'2.0SASA'!$A:$A,'2.0SASA'!$C:$C,"",0) -> 0 | C14: =B14*C$50/B$50 -> 0 | D14: =IF(C14>4,ROUND(C14/2,0)*2,IF(C14>2.2,4,0)) -> 0 | E14: =_xlfn.XLOOKUP(A14,'2.0SASA'!$A:$A,'2.0SASA'!$B:$B,"",0) -> 60 | F14: =E14*F$50/E$50 -> 6 | G14: =IF(F14>4,ROUND(F14/2,0)*2,IF(F14>2.2,4,0)) -> 6 | H14: =_xlfn.XLOOKUP(A14,'2.0SASA'!$A:$A,'2.0SASA'!$J:$J,"",0) -> 0 | I14: =H14*I$50/H$50 -> 0 | J14: =IF(I14>4,ROUND(I14/2,0)*2,IF(I14>2,4,0)) -> 0 | K14: =_xlfn.XLOOKUP(A14,'2.0SASA'!$A:$A,'2.0SASA'!$K:$K,"",0) -> 0 | L14: =K14*L$50/K$50 -> 0 | M14: =IF(L14>4,ROUND(L14/2,0)*2,IF(L14>2.2,4,0)) -> 0 | N14: =_xlfn.XLOOKUP(A14,'2.0SASA'!$A:$A,'2.0SASA'!$G:$G,"",0) -> 0 | O14: =N14*O$50/N$50 -> 0 | P14: =IF(O14>4,ROUND(O14/2,0)*2,IF(O14>2.2,4,0)) -> 0 | Q14: =_xlfn.XLOOKUP(A14,'2.0SASA'!$A:$A,'2.0SASA'!$I:$I,"",0) -> 20 | R14: =Q14*R$50/Q$50 -> 2.2857143 | S14: =IF(R14>4,ROUND(R14/2,0)*2,IF(R14>2.2,4,0)) -> 4 | T14: =_xlfn.XLOOKUP(A14,'2.0SASA'!$A:$A,'2.0SASA'!$F:$F,"",0) -> 0 | U14: =T14*U$50/T$50 -> 0 | V14: =IF(U14>4,ROUND(U14/2,0)*2,IF(U14>2.2,4,0)) -> 0 | W14: =_xlfn.XLOOKUP(A14,'2.0SASA'!$A:$A,'2.0SASA'!$H:$H,"",0) -> 10 | X14: =W14*X$50/W$50 -> 0.875 | Y14: =IF(X14>4,ROUND(X14/2,0)*2,IF(X14>2.2,4,0)) -> 0 | Z14: =_xlfn.XLOOKUP(A14,'2.0SASA'!$A:$A,'2.0SASA'!$D:$D,"",0) -> 30 | AA14: =Z14*AA$50/Z$50 -> 2.9090909 | AB14: =IF(AA14>4,ROUND(AA14/2,0)*2,IF(AA14>2.2,4,0)) -> 4 | AC14: =_xlfn.XLOOKUP(A14,'2.0SASA'!$A:$A,'2.0SASA'!$E:$E,"",0) -> 0 | AD14: =AC14*AD$50/AC$50 -> 0 | AE14: =IF(AD14>4,ROUND(AD14/2,0)*2,IF(AD14>2.2,4,0)) -> 0 | AF14: =_xlfn.XLOOKUP(A14,'2.0SASA'!$A:$A,'2.0SASA'!$V:$V,"",0) -> 0 | AG14: =AF14*AG$50/AF$50 -> 0 | AH14: =IF(AG14>4,ROUND(AG14/2,0)*2,IF(AG14>2.2,4,0)) -> 0 | AI14: =_xlfn.XLOOKUP(A14,'2.0SASA'!$A:$A,'2.0SASA'!$U:$U,"",0) -> 60 | AJ14: =AI14*AJ$50/AI$50 -> 2.7067669 | AK14: =IF(AJ14>4,ROUND(AJ14/2,0)*2,IF(AJ14>2,4,0)) -> 4 | AL14: =_xlfn.XLOOKUP(A14,'2.0SASA'!$A:$A,'2.0SASA'!$Q:$Q,"",0) -> 60 | AM14: =AL14*AM$50/AL$50 -> 2.8985507 | AN14: =IF(AM14>4,ROUND(AM14/2,0)*2,IF(AM14>2.2,4,0)) -> 4 | AO14: =_xlfn.XLOOKUP(A14,'2.0SASA'!$A:$A,'2.0SASA'!$AD:$AD,"",0) -> 50 | AP14: =AO14*AP$50/AO$50 -> 2.5974026 | AQ14: =IF(AP14>4,ROUND(AP14/2,0)*2,IF(AP14>2.2,4,0)) -> 4
A15: SRO RAJKOT TOTAL | B15: =SUM(B11:B14) -> 0 | C15: =SUM(C11:C14) -> 0 | D15: =SUM(D11:D14) -> 0 | E15: =SUM(E11:E14) -> 310 | F15: =SUM(F11:F14) -> 31 | G15: =SUM(G11:G14) -> 32 | H15: =SUM(H11:H14) -> 0 | I15: =SUM(I11:I14) -> 0 | ... AQ15: =SUM(AQ11:AQ14) -> 4
A16: Jamnagar | B16: =_xlfn.XLOOKUP(A16,'2.0SASA'!$A:$A,'2.0SASA'!$C:$C,"",0) -> 0 | C16: =B16*C$50/B$50 -> 0 | D16: =IF(C16>4,ROUND(C16/2,0)*2,IF(C16>2.2,4,0)) -> 0 | E16: =_xlfn.XLOOKUP(A16,'2.0SASA'!$A:$A,'2.0SASA'!$B:$B,"",0) -> 60 | F16: =E16*F$50/E$50 -> 6 | G16: =IF(F16>4,ROUND(F16/2,0)*2,IF(F16>2.2,4,0)) -> 6 | H16: =_xlfn.XLOOKUP(A16,'2.0SASA'!$A:$A,'2.0SASA'!$J:$J,"",0) -> 0 | I16: =H16*I$50/H$50 -> 0 | J16: =IF(I16>4,ROUND(I16/2,0)*2,IF(I16>2,4,0)) -> 0 | K16: =_xlfn.XLOOKUP(A16,'2.0SASA'!$A:$A,'2.0SASA'!$K:$K,"",0) -> 0 | L16: =K16*L$50/K$50 -> 0 | M16: =IF(L16>4,ROUND(L16/2,0)*2,IF(L16>2.2,4,0)) -> 0 | N16: =_xlfn.XLOOKUP(A16,'2.0SASA'!$A:$A,'2.0SASA'!$G:$G,"",0) -> 10 | O16: =N16*O$50/N$50 -> 1.3333333 | P16: =IF(O16>4,ROUND(O16/2,0)*2,IF(O16>2.2,4,0)) -> 0 | Q16: =_xlfn.XLOOKUP(A16,'2.0SASA'!$A:$A,'2.0SASA'!$I:$I,"",0) -> 0 | R16: =Q16*R$50/Q$50 -> 0 | S16: =IF(R16>4,ROUND(R16/2,0)*2,IF(R16>2.2,4,0)) -> 0 | T16: =_xlfn.XLOOKUP(A16,'2.0SASA'!$A:$A,'2.0SASA'!$F:$F,"",0) -> 30 | U16: =T16*U$50/T$50 -> 3 | V16: =IF(U16>4,ROUND(U16/2,0)*2,IF(U16>2.2,4,0)) -> 4 | W16: =_xlfn.XLOOKUP(A16,'2.0SASA'!$A:$A,'2.0SASA'!$H:$H,"",0) -> 20 | X16: =W16*X$50/W$50 -> 1.75 | Y16: =IF(X16>4,ROUND(X16/2,0)*2,IF(X16>2.2,4,0)) -> 0 | Z16: =_xlfn.XLOOKUP(A16,'2.0SASA'!$A:$A,'2.0SASA'!$D:$D,"",0) -> 60 | AA16: =Z16*AA$50/Z$50 -> 5.8181818 | AB16: =IF(AA16>4,ROUND(AA16/2,0)*2,IF(AA16>2.2,4,0)) -> 6 | AC16: =_xlfn.XLOOKUP(A16,'2.0SASA'!$A:$A,'2.0SASA'!$E:$E,"",0) -> 0 | AD16: =AC16*AD$50/AC$50 -> 0 | AE16: =IF(AD16>4,ROUND(AD16/2,0)*2,IF(AD16>2.2,4,0)) -> 0 | AF16: =_xlfn.XLOOKUP(A16,'2.0SASA'!$A:$A,'2.0SASA'!$V:$V,"",0) -> 30 | AG16: =AF16*AG$50/AF$50 -> 2 | AH16: =IF(AG16>4,ROUND(AG16/2,0)*2,IF(AG16>2.2,4,0)) -> 0 | AI16: =_xlfn.XLOOKUP(A16,'2.0SASA'!$A:$A,'2.0SASA'!$U:$U,"",0) -> 60 | AJ16: =AI16*AJ$50/AI$50 -> 2.7067669 | AK16: =IF(AJ16>4,ROUND(AJ16/2,0)*2,IF(AJ16>2,4,0)) -> 4 | AL16: =_xlfn.XLOOKUP(A16,'2.0SASA'!$A:$A,'2.0SASA'!$Q:$Q,"",0) -> 60 | AM16: =AL16*AM$50/AL$50 -> 2.8985507 | AN16: =IF(AM16>4,ROUND(AM16/2,0)*2,IF(AM16>2.2,4,0)) -> 4 | AO16: =_xlfn.XLOOKUP(A16,'2.0SASA'!$A:$A,'2.0SASA'!$AD:$AD,"",0) -> 0 | AP16: =AO16*AP$50/AO$50 -> 0 | AQ16: =IF(AP16>4,ROUND(AP16/2,0)*2,IF(AP16>2.2,4,0)) -> 0
A17: Devbhumi Dwarka | B17: =_xlfn.XLOOKUP(A17,'2.0SASA'!$A:$A,'2.0SASA'!$C:$C,"",0) -> 0 | C17: =B17*C$50/B$50 -> 0 | D17: =IF(C17>4,ROUND(C17/2,0)*2,IF(C17>2.2,4,0)) -> 0 | E17: =_xlfn.XLOOKUP(A17,'2.0SASA'!$A:$A,'2.0SASA'!$B:$B,"",0) -> 50 | F17: =E17*F$50/E$50 -> 5 | G17: 4 | H17: =_xlfn.XLOOKUP(A17,'2.0SASA'!$A:$A,'2.0SASA'!$J:$J,"",0) -> 0 | I17: =H17*I$50/H$50 -> 0 | J17: =IF(I17>4,ROUND(I17/2,0)*2,IF(I17>2,4,0)) -> 0 | K17: =_xlfn.XLOOKUP(A17,'2.0SASA'!$A:$A,'2.0SASA'!$K:$K,"",0) -> 0 | L17: =K17*L$50/K$50 -> 0 | M17: =IF(L17>4,ROUND(L17/2,0)*2,IF(L17>2.2,4,0)) -> 0 | N17: =_xlfn.XLOOKUP(A17,'2.0SASA'!$A:$A,'2.0SASA'!$G:$G,"",0) -> 10 | O17: =N17*O$50/N$50 -> 1.3333333 | P17: =IF(O17>4,ROUND(O17/2,0)*2,IF(O17>2.2,4,0)) -> 0 | Q17: =_xlfn.XLOOKUP(A17,'2.0SASA'!$A:$A,'2.0SASA'!$I:$I,"",0) -> 0 | R17: =Q17*R$50/Q$50 -> 0 | S17: =IF(R17>4,ROUND(R17/2,0)*2,IF(R17>2.2,4,0)) -> 0 | T17: =_xlfn.XLOOKUP(A17,'2.0SASA'!$A:$A,'2.0SASA'!$F:$F,"",0) -> 0 | U17: =T17*U$50/T$50 -> 0 | V17: =IF(U17>4,ROUND(U17/2,0)*2,IF(U17>2.2,4,0)) -> 0 | W17: =_xlfn.XLOOKUP(A17,'2.0SASA'!$A:$A,'2.0SASA'!$H:$H,"",0) -> 0 | X17: =W17*X$50/W$50 -> 0 | Y17: =IF(X17>4,ROUND(X17/2,0)*2,IF(X17>2.2,4,0)) -> 0 | Z17: =_xlfn.XLOOKUP(A17,'2.0SASA'!$A:$A,'2.0SASA'!$D:$D,"",0) -> 30 | AA17: =Z17*AA$50/Z$50 -> 2.9090909 | AB17: =IF(AA17>4,ROUND(AA17/2,0)*2,IF(AA17>2.2,4,0)) -> 4 | AC17: =_xlfn.XLOOKUP(A17,'2.0SASA'!$A:$A,'2.0SASA'!$E:$E,"",0) -> 0 | AD17: =AC17*AD$50/AC$50 -> 0 | AE17: =IF(AD17>4,ROUND(AD17/2,0)*2,IF(AD17>2.2,4,0)) -> 0 | AF17: =_xlfn.XLOOKUP(A17,'2.0SASA'!$A:$A,'2.0SASA'!$V:$V,"",0) -> 10 | AG17: =AF17*AG$50/AF$50 -> 0.66666667 | AH17: =IF(AG17>4,ROUND(AG17/2,0)*2,IF(AG17>2.2,4,0)) -> 0 | AI17: =_xlfn.XLOOKUP(A17,'2.0SASA'!$A:$A,'2.0SASA'!$U:$U,"",0) -> 40 | AJ17: =AI17*AJ$50/AI$50 -> 1.8045113 | AK17: 0 | AL17: =_xlfn.XLOOKUP(A17,'2.0SASA'!$A:$A,'2.0SASA'!$Q:$Q,"",0) -> 30 | AM17: =AL17*AM$50/AL$50 -> 1.4492754 | AN17: =IF(AM17>4,ROUND(AM17/2,0)*2,IF(AM17>2.2,4,0)) -> 0 | AO17: =_xlfn.XLOOKUP(A17,'2.0SASA'!$A:$A,'2.0SASA'!$AD:$AD,"",0) -> 0 | AP17: =AO17*AP$50/AO$50 -> 0 | AQ17: =IF(AP17>4,ROUND(AP17/2,0)*2,IF(AP17>2.2,4,0)) -> 0
A18: Porbandar | B18: =_xlfn.XLOOKUP(A18,'2.0SASA'!$A:$A,'2.0SASA'!$C:$C,"",0) -> 0 | C18: =B18*C$50/B$50 -> 0 | D18: =IF(C18>4,ROUND(C18/2,0)*2,IF(C18>2.2,4,0)) -> 0 | E18: =_xlfn.XLOOKUP(A18,'2.0SASA'!$A:$A,'2.0SASA'!$B:$B,"",0) -> 30 | F18: =E18*F$50/E$50 -> 3 | G18: =IF(F18>4,ROUND(F18/2,0)*2,IF(F18>2.2,4,0)) -> 4 | H18: =_xlfn.XLOOKUP(A18,'2.0SASA'!$A:$A,'2.0SASA'!$J:$J,"",0) -> 0 | I18: =H18*I$50/H$50 -> 0 | J18: =IF(I18>4,ROUND(I18/2,0)*2,IF(I18>2,4,0)) -> 0 | K18: =_xlfn.XLOOKUP(A18,'2.0SASA'!$A:$A,'2.0SASA'!$K:$K,"",0) -> 0 | L18: =K18*L$50/K$50 -> 0 | M18: =IF(L18>4,ROUND(L18/2,0)*2,IF(L18>2.2,4,0)) -> 0 | N18: =_xlfn.XLOOKUP(A18,'2.0SASA'!$A:$A,'2.0SASA'!$G:$G,"",0) -> 0 | O18: =N18*O$50/N$50 -> 0 | P18: =IF(O18>4,ROUND(O18/2,0)*2,IF(O18>2.2,4,0)) -> 0 | Q18: =_xlfn.XLOOKUP(A18,'2.0SASA'!$A:$A,'2.0SASA'!$I:$I,"",0) -> 0 | R18: =Q18*R$50/Q$50 -> 0 | S18: =IF(R18>4,ROUND(R18/2,0)*2,IF(R18>2.2,4,0)) -> 0 | T18: =_xlfn.XLOOKUP(A18,'2.0SASA'!$A:$A,'2.0SASA'!$F:$F,"",0) -> 0 | U18: =T18*U$50/T$50 -> 0 | V18: =IF(U18>4,ROUND(U18/2,0)*2,IF(U18>2.2,4,0)) -> 0 | W18: =_xlfn.XLOOKUP(A18,'2.0SASA'!$A:$A,'2.0SASA'!$H:$H,"",0) -> 0 | X18: =W18*X$50/W$50 -> 0 | Y18: =IF(X18>4,ROUND(X18/2,0)*2,IF(X18>2.2,4,0)) -> 0 | Z18: =_xlfn.XLOOKUP(A18,'2.0SASA'!$A:$A,'2.0SASA'!$D:$D,"",0) -> 10 | AA18: =Z18*AA$50/Z$50 -> 0.96969697 | AB18: =IF(AA18>4,ROUND(AA18/2,0)*2,IF(AA18>2.2,4,0)) -> 0 | AC18: =_xlfn.XLOOKUP(A18,'2.0SASA'!$A:$A,'2.0SASA'!$E:$E,"",0) -> 10 | AD18: =AC18*AD$50/AC$50 -> 0.96774194 | AE18: =IF(AD18>4,ROUND(AD18/2,0)*2,IF(AD18>2.2,4,0)) -> 0 | AF18: =_xlfn.XLOOKUP(A18,'2.0SASA'!$A:$A,'2.0SASA'!$V:$V,"",0) -> 0 | AG18: =AF18*AG$50/AF$50 -> 0 | AH18: =IF(AG18>4,ROUND(AG18/2,0)*2,IF(AG18>2.2,4,0)) -> 0 | AI18: =_xlfn.XLOOKUP(A18,'2.0SASA'!$A:$A,'2.0SASA'!$U:$U,"",0) -> 30 | AJ18: =AI18*AJ$50/AI$50 -> 1.3533835 | AK18: =IF(AJ18>4,ROUND(AJ18/2,0)*2,IF(AJ18>2,4,0)) -> 0 | AL18: =_xlfn.XLOOKUP(A18,'2.0SASA'!$A:$A,'2.0SASA'!$Q:$Q,"",0) -> 30 | AM18: =AL18*AM$50/AL$50 -> 1.4492754 | AN18: =IF(AM18>4,ROUND(AM18/2,0)*2,IF(AM18>2.2,4,0)) -> 0 | AO18: =_xlfn.XLOOKUP(A18,'2.0SASA'!$A:$A,'2.0SASA'!$AD:$AD,"",0) -> 0 | AP18: =AO18*AP$50/AO$50 -> 0 | AQ18: =IF(AP18>4,ROUND(AP18/2,0)*2,IF(AP18>2.2,4,0)) -> 0
A19: SRO JAMNAGAR TOTAL | B19: =SUM(B16:B18) -> 0 | C19: =SUM(C16:C18) -> 0 | D19: =SUM(D16:D18) -> 0 | E19: =SUM(E16:E18) -> 140 | F19: =SUM(F16:F18) -> 14 | G19: =SUM(G16:G18) -> 14 | H19: =SUM(H16:H18) -> 0 | I19: =SUM(I16:I18) -> 0 | ... AQ19: =SUM(AQ16:AQ18) -> 0
A20: Amreli | B20: =_xlfn.XLOOKUP(A20,'2.0SASA'!$A:$A,'2.0SASA'!$C:$C,"",0) -> 0 | C20: =B20*C$50/B$50 -> 0 | D20: =IF(C20>4,ROUND(C20/2,0)*2,IF(C20>2.2,4,0)) -> 0 | E20: =_xlfn.XLOOKUP(A20,'2.0SASA'!$A:$A,'2.0SASA'!$B:$B,"",0) -> 110 | F20: =E20*F$50/E$50 -> 11 | G20: 10 | H20: =_xlfn.XLOOKUP(A20,'2.0SASA'!$A:$A,'2.0SASA'!$J:$J,"",0) -> 0 | I20: =H20*I$50/H$50 -> 0 | J20: =IF(I20>4,ROUND(I20/2,0)*2,IF(I20>2,4,0)) -> 0 | K20: =_xlfn.XLOOKUP(A20,'2.0SASA'!$A:$A,'2.0SASA'!$K:$K,"",0) -> 0 | L20: =K20*L$50/K$50 -> 0 | M20: =IF(L20>4,ROUND(L20/2,0)*2,IF(L20>2.2,4,0)) -> 0 | N20: =_xlfn.XLOOKUP(A20,'2.0SASA'!$A:$A,'2.0SASA'!$G:$G,"",0) -> 30 | O20: =N20*O$50/N$50 -> 4 | P20: =IF(O20>4,ROUND(O20/2,0)*2,IF(O20>2.2,4,0)) -> 4 | Q20: =_xlfn.XLOOKUP(A20,'2.0SASA'!$A:$A,'2.0SASA'!$I:$I,"",0) -> 10 | R20: =Q20*R$50/Q$50 -> 1.1428571 | S20: =IF(R20>4,ROUND(R20/2,0)*2,IF(R20>2.2,4,0)) -> 0 | T20: =_xlfn.XLOOKUP(A20,'2.0SASA'!$A:$A,'2.0SASA'!$F:$F,"",0) -> 0 | U20: =T20*U$50/T$50 -> 0 | V20: =IF(U20>4,ROUND(U20/2,0)*2,IF(U20>2.2,4,0)) -> 0 | W20: =_xlfn.XLOOKUP(A20,'2.0SASA'!$A:$A,'2.0SASA'!$H:$H,"",0) -> 10 | X20: =W20*X$50/W$50 -> 0.875 | Y20: =IF(X20>4,ROUND(X20/2,0)*2,IF(X20>2.2,4,0)) -> 0 | Z20: =_xlfn.XLOOKUP(A20,'2.0SASA'!$A:$A,'2.0SASA'!$D:$D,"",0) -> 110 | AA20: =Z20*AA$50/Z$50 -> 10.666667 | AB20: 12 | AC20: =_xlfn.XLOOKUP(A20,'2.0SASA'!$A:$A,'2.0SASA'!$E:$E,"",0) -> 110 | AD20: =AC20*AD$50/AC$50 -> 10.645161 | AE20: 14 | AF20: =_xlfn.XLOOKUP(A20,'2.0SASA'!$A:$A,'2.0SASA'!$V:$V,"",0) -> 0 | AG20: =AF20*AG$50/AF$50 -> 0 | AH20: =IF(AG20>4,ROUND(AG20/2,0)*2,IF(AG20>2.2,4,0)) -> 0 | AI20: =_xlfn.XLOOKUP(A20,'2.0SASA'!$A:$A,'2.0SASA'!$U:$U,"",0) -> 110 | AJ20: =AI20*AJ$50/AI$50 -> 4.962406 | AK20: 8 | AL20: =_xlfn.XLOOKUP(A20,'2.0SASA'!$A:$A,'2.0SASA'!$Q:$Q,"",0) -> 110 | AM20: =AL20*AM$50/AL$50 -> 5.3140097 | AN20: =IF(AM20>4,ROUND(AM20/2,0)*2,IF(AM20>2.2,4,0)) -> 6 | AO20: =_xlfn.XLOOKUP(A20,'2.0SASA'!$A:$A,'2.0SASA'!$AD:$AD,"",0) -> 40 | AP20: =AO20*AP$50/AO$50 -> 2.0779221 | AQ20: 4
A21: Bhavnagar | B21: =_xlfn.XLOOKUP(A21,'2.0SASA'!$A:$A,'2.0SASA'!$C:$C,"",0) -> 0 | C21: =B21*C$50/B$50 -> 0 | D21: =IF(C21>4,ROUND(C21/2,0)*2,IF(C21>2.2,4,0)) -> 0 | E21: =_xlfn.XLOOKUP(A21,'2.0SASA'!$A:$A,'2.0SASA'!$B:$B,"",0) -> 80 | F21: =E21*F$50/E$50 -> 8 | G21: =IF(F21>4,ROUND(F21/2,0)*2,IF(F21>2.2,4,0)) -> 8 | H21: =_xlfn.XLOOKUP(A21,'2.0SASA'!$A:$A,'2.0SASA'!$J:$J,"",0) -> 0 | I21: =H21*I$50/H$50 -> 0 | J21: =IF(I21>4,ROUND(I21/2,0)*2,IF(I21>2,4,0)) -> 0 | K21: =_xlfn.XLOOKUP(A21,'2.0SASA'!$A:$A,'2.0SASA'!$K:$K,"",0) -> 0 | L21: =K21*L$50/K$50 -> 0 | M21: =IF(L21>4,ROUND(L21/2,0)*2,IF(L21>2.2,4,0)) -> 0 | N21: =_xlfn.XLOOKUP(A21,'2.0SASA'!$A:$A,'2.0SASA'!$G:$G,"",0) -> 20 | O21: =N21*O$50/N$50 -> 2.6666667 | P21: =IF(O21>4,ROUND(O21/2,0)*2,IF(O21>2.2,4,0)) -> 4 | Q21: =_xlfn.XLOOKUP(A21,'2.0SASA'!$A:$A,'2.0SASA'!$I:$I,"",0) -> 70 | R21: =Q21*R$50/Q$50 -> 8 | S21: =IF(R21>4,ROUND(R21/2,0)*2,IF(R21>2.2,4,0)) -> 8 | T21: =_xlfn.XLOOKUP(A21,'2.0SASA'!$A:$A,'2.0SASA'!$F:$F,"",0) -> 0 | U21: =T21*U$50/T$50 -> 0 | V21: =IF(U21>4,ROUND(U21/2,0)*2,IF(U21>2.2,4,0)) -> 0 | W21: =_xlfn.XLOOKUP(A21,'2.0SASA'!$A:$A,'2.0SASA'!$H:$H,"",0) -> 0 | X21: =W21*X$50/W$50 -> 0 | Y21: =IF(X21>4,ROUND(X21/2,0)*2,IF(X21>2.2,4,0)) -> 0 | Z21: =_xlfn.XLOOKUP(A21,'2.0SASA'!$A:$A,'2.0SASA'!$D:$D,"",0) -> 100 | AA21: =Z21*AA$50/Z$50 -> 9.6969697 | AB21: =IF(AA21>4,ROUND(AA21/2,0)*2,IF(AA21>2.2,4,0)) -> 10 | AC21: =_xlfn.XLOOKUP(A21,'2.0SASA'!$A:$A,'2.0SASA'!$E:$E,"",0) -> 80 | AD21: =AC21*AD$50/AC$50 -> 7.7419355 | AE21: 10 | AF21: =_xlfn.XLOOKUP(A21,'2.0SASA'!$A:$A,'2.0SASA'!$V:$V,"",0) -> 0 | AG21: =AF21*AG$50/AF$50 -> 0 | AH21: =IF(AG21>4,ROUND(AG21/2,0)*2,IF(AG21>2.2,4,0)) -> 0 | AI21: =_xlfn.XLOOKUP(A21,'2.0SASA'!$A:$A,'2.0SASA'!$U:$U,"",0) -> 100 | AJ21: =AI21*AJ$50/AI$50 -> 4.5112782 | AK21: 6 | AL21: =_xlfn.XLOOKUP(A21,'2.0SASA'!$A:$A,'2.0SASA'!$Q:$Q,"",0) -> 100 | AM21: =AL21*AM$50/AL$50 -> 4.8309179 | AN21: 6 | AO21: =_xlfn.XLOOKUP(A21,'2.0SASA'!$A:$A,'2.0SASA'!$AD:$AD,"",0) -> 30 | AP21: =AO21*AP$50/AO$50 -> 1.5584416 | AQ21: =IF(AP21>4,ROUND(AP21/2,0)*2,IF(AP21>2.2,4,0)) -> 0
A22: Botad | B22: =_xlfn.XLOOKUP(A22,'2.0SASA'!$A:$A,'2.0SASA'!$C:$C,"",0) -> 0 | C22: =B22*C$50/B$50 -> 0 | D22: =IF(C22>4,ROUND(C22/2,0)*2,IF(C22>2.2,4,0)) -> 0 | E22: =_xlfn.XLOOKUP(A22,'2.0SASA'!$A:$A,'2.0SASA'!$B:$B,"",0) -> 30 | F22: =E22*F$50/E$50 -> 3 | G22: =IF(F22>4,ROUND(F22/2,0)*2,IF(F22>2.2,4,0)) -> 4 | H22: =_xlfn.XLOOKUP(A22,'2.0SASA'!$A:$A,'2.0SASA'!$J:$J,"",0) -> 0 | I22: =H22*I$50/H$50 -> 0 | J22: =IF(I22>4,ROUND(I22/2,0)*2,IF(I22>2,4,0)) -> 0 | K22: =_xlfn.XLOOKUP(A22,'2.0SASA'!$A:$A,'2.0SASA'!$K:$K,"",0) -> 0 | L22: =K22*L$50/K$50 -> 0 | M22: =IF(L22>4,ROUND(L22/2,0)*2,IF(L22>2.2,4,0)) -> 0 | N22: =_xlfn.XLOOKUP(A22,'2.0SASA'!$A:$A,'2.0SASA'!$G:$G,"",0) -> 30 | O22: =N22*O$50/N$50 -> 4 | P22: =IF(O22>4,ROUND(O22/2,0)*2,IF(O22>2.2,4,0)) -> 4 | Q22: =_xlfn.XLOOKUP(A22,'2.0SASA'!$A:$A,'2.0SASA'!$I:$I,"",0) -> 0 | R22: =Q22*R$50/Q$50 -> 0 | S22: =IF(R22>4,ROUND(R22/2,0)*2,IF(R22>2.2,4,0)) -> 0 | T22: =_xlfn.XLOOKUP(A22,'2.0SASA'!$A:$A,'2.0SASA'!$F:$F,"",0) -> 0 | U22: =T22*U$50/T$50 -> 0 | V22: =IF(U22>4,ROUND(U22/2,0)*2,IF(U22>2.2,4,0)) -> 0 | W22: =_xlfn.XLOOKUP(A22,'2.0SASA'!$A:$A,'2.0SASA'!$H:$H,"",0) -> 0 | X22: =W22*X$50/W$50 -> 0 | Y22: =IF(X22>4,ROUND(X22/2,0)*2,IF(X22>2.2,4,0)) -> 0 | Z22: =_xlfn.XLOOKUP(A22,'2.0SASA'!$A:$A,'2.0SASA'!$D:$D,"",0) -> 40 | AA22: =Z22*AA$50/Z$50 -> 3.8787879 | AB22: =IF(AA22>4,ROUND(AA22/2,0)*2,IF(AA22>2.2,4,0)) -> 4 | AC22: =_xlfn.XLOOKUP(A22,'2.0SASA'!$A:$A,'2.0SASA'!$E:$E,"",0) -> 10 | AD22: =AC22*AD$50/AC$50 -> 0.96774194 | AE22: =IF(AD22>4,ROUND(AD22/2,0)*2,IF(AD22>2.2,4,0)) -> 0 | AF22: =_xlfn.XLOOKUP(A22,'2.0SASA'!$A:$A,'2.0SASA'!$V:$V,"",0) -> 0 | AG22: =AF22*AG$50/AF$50 -> 0 | AH22: =IF(AG22>4,ROUND(AG22/2,0)*2,IF(AG22>2.2,4,0)) -> 0 | AI22: =_xlfn.XLOOKUP(A22,'2.0SASA'!$A:$A,'2.0SASA'!$U:$U,"",0) -> 40 | AJ22: =AI22*AJ$50/AI$50 -> 1.8045113 | AK22: =IF(AJ22>4,ROUND(AJ22/2,0)*2,IF(AJ22>2,4,0)) -> 0 | AL22: =_xlfn.XLOOKUP(A22,'2.0SASA'!$A:$A,'2.0SASA'!$Q:$Q,"",0) -> 40 | AM22: =AL22*AM$50/AL$50 -> 1.9323671 | AN22: =IF(AM22>4,ROUND(AM22/2,0)*2,IF(AM22>2.2,4,0)) -> 0 | AO22: =_xlfn.XLOOKUP(A22,'2.0SASA'!$A:$A,'2.0SASA'!$AD:$AD,"",0) -> 0 | AP22: =AO22*AP$50/AO$50 -> 0 | AQ22: =IF(AP22>4,ROUND(AP22/2,0)*2,IF(AP22>2.2,4,0)) -> 0
A23: SRO BHAVNAGAR TOTAL | B23: =SUM(B20:B22) -> 0 | C23: =SUM(C20:C22) -> 0 | D23: =SUM(D20:D22) -> 0 | E23: =SUM(E20:E22) -> 220 | F23: =SUM(F20:F22) -> 22 | G23: =SUM(G20:G22) -> 22 | H23: =SUM(H20:H22) -> 0 | I23: =SUM(I20:I22) -> 0 | ... AQ23: =SUM(AQ20:AQ22) -> 4
A24: RO AHMEDABAD TOTAL | B24: =SUM(B7,B10,B15,B19,B23) -> 0 | C24: =SUM(C7,C10,C15,C19,C23) -> 0 | D24: =SUM(D7,D10,D15,D19,D23) -> 0 | E24: =SUM(E7,E10,E15,E19,E23) -> 850 | F24: =SUM(F7,F10,F15,F19,F23) -> 85 | G24: =SUM(G7,G10,G15,G19,G23) -> 88 | H24: =SUM(H7,H10,H15,H19,H23) -> 92 | I24: =SUM(I7,I10,I15,I19,I23) -> 8.440367 | ... AQ24: =SUM(AQ7,AQ10,AQ15,AQ19,AQ23) -> 12
A25: Banaskantha | B25: =_xlfn.XLOOKUP(A25,'2.0SASA'!$A:$A,'2.0SASA'!$C:$C,"",0) -> 30 | C25: =B25*C$50/B$50 -> 2.7713626 | D25: =IF(C25>4,ROUND(C25/2,0)*2,IF(C25>2.2,4,0)) -> 4 | E25: =_xlfn.XLOOKUP(A25,'2.0SASA'!$A:$A,'2.0SASA'!$B:$B,"",0) -> 120 | F25: =E25*F$50/E$50 -> 12 | G25: =IF(F25>4,ROUND(F25/2,0)*2,IF(F25>2.2,4,0)) -> 12 | H25: =_xlfn.XLOOKUP(A25,'2.0SASA'!$A:$A,'2.0SASA'!$J:$J,"",0) -> 0 | I25: =H25*I$50/H$50 -> 0 | J25: =IF(I25>4,ROUND(I25/2,0)*2,IF(I25>2,4,0)) -> 0 | K25: =_xlfn.XLOOKUP(A25,'2.0SASA'!$A:$A,'2.0SASA'!$K:$K,"",0) -> 0 | L25: =K25*L$50/K$50 -> 0 | M25: =IF(L25>4,ROUND(L25/2,0)*2,IF(L25>2.2,4,0)) -> 0 | N25: =_xlfn.XLOOKUP(A25,'2.0SASA'!$A:$A,'2.0SASA'!$G:$G,"",0) -> 0 | O25: =N25*O$50/N$50 -> 0 | P25: =IF(O25>4,ROUND(O25/2,0)*2,IF(O25>2.2,4,0)) -> 0 | Q25: =_xlfn.XLOOKUP(A25,'2.0SASA'!$A:$A,'2.0SASA'!$I:$I,"",0) -> 80 | R25: =Q25*R$50/Q$50 -> 9.1428571 | S25: 8 | T25: =_xlfn.XLOOKUP(A25,'2.0SASA'!$A:$A,'2.0SASA'!$F:$F,"",0) -> 140 | U25: =T25*U$50/T$50 -> 14 | V25: =IF(U25>4,ROUND(U25/2,0)*2,IF(U25>2.2,4,0)) -> 14 | W25: =_xlfn.XLOOKUP(A25,'2.0SASA'!$A:$A,'2.0SASA'!$H:$H,"",0) -> 0 | X25: =W25*X$50/W$50 -> 0 | Y25: =IF(X25>4,ROUND(X25/2,0)*2,IF(X25>2.2,4,0)) -> 0 | Z25: =_xlfn.XLOOKUP(A25,'2.0SASA'!$A:$A,'2.0SASA'!$D:$D,"",0) -> 60 | AA25: =Z25*AA$50/Z$50 -> 5.8181818 | AB25: =IF(AA25>4,ROUND(AA25/2,0)*2,IF(AA25>2.2,4,0)) -> 6 | AC25: =_xlfn.XLOOKUP(A25,'2.0SASA'!$A:$A,'2.0SASA'!$E:$E,"",0) -> 0 | AD25: =AC25*AD$50/AC$50 -> 0 | AE25: =IF(AD25>4,ROUND(AD25/2,0)*2,IF(AD25>2.2,4,0)) -> 0 | AF25: =_xlfn.XLOOKUP(A25,'2.0SASA'!$A:$A,'2.0SASA'!$V:$V,"",0) -> 120 | AG25: =AF25*AG$50/AF$50 -> 8 | AH25: 10 | AI25: =_xlfn.XLOOKUP(A25,'2.0SASA'!$A:$A,'2.0SASA'!$U:$U,"",0) -> 0 | AJ25: =AI25*AJ$50/AI$50 -> 0 | AK25: =IF(AJ25>4,ROUND(AJ25/2,0)*2,IF(AJ25>2,4,0)) -> 0 | AL25: =_xlfn.XLOOKUP(A25,'2.0SASA'!$A:$A,'2.0SASA'!$Q:$Q,"",0) -> 140 | AM25: =AL25*AM$50/AL$50 -> 6.763285 | AN25: 8 | AO25: =_xlfn.XLOOKUP(A25,'2.0SASA'!$A:$A,'2.0SASA'!$AD:$AD,"",0) -> 140 | AP25: =AO25*AP$50/AO$50 -> 7.2727273 | AQ25: 10
