Workbook

Sheet info
B2: =[2]year!$B$2 -> STATE | C2: ='[3]Crops CY'!$A$2 -> GUJARAT | E2: =_xlfn.CONCAT(B2,": ",C2) -> STATE: GUJARAT

Sheet RC1-A1
A1: T-1
A2: TABLE A-1: DISTRICTWISE DISTRIBUTION OF SELECTED VILLAGES FOR CHECK ON ENUMERATION OF AREA AND RESPONSE ACHIEVED.
A3: =info!$E$2 -> STATE: GUJARAT | E3: YEAR: | F3: ='[1]Table-1'!E3 -> 2024-25 | G3: SEASON: | H3: ='[1]Table-1'!G3 -> RABI(4) | K3: SAMPLE: CENTRAL
A4: DISTRICT | B4: DISTRICT NAME | C4: NO.OF VILLAGES FOR WHICH SCHEDULE AS 1.0 RECEIVED | D4: NO. OF VILLAGES FOR WHICH SCHEDULE AS 1.0 IS ANALYSED | H4: PERCENTAGE RESPONSE TO COL.(3)
D5: WITH 'a' AND 'b' ENTRIES TOGETHER | E5: WITH 'a' AND 'b' ENTRIES SEPARATELY | F5: WITH 'a' ENTRIES ONLY | G5: TOTAL | H5: WITH 'a' AND 'b' ENTRIES TOGETHER | I5: WITH 'a' AND 'b' ENTRIES SEPARATELY | J5: WITH 'a' ENTRIES ONLY | K5: TOTAL
A10: 1 | B10: 2 | C10: 3 | D10: 4 | E10: 5 | F10: 7 | G10: 8 | H10: 9 | I10: 10 | J10: 11 | K10: 12
A11: ='[1]Table-1'!A11 -> 1 | B11: KACHCHH | C11: ='[1]Table-1'!B11 -> 18 | D11: ='[1]Table-1'!C11 -> 0 | E11: ='[1]Table-1'!D11 -> 0 | F11: ='[1]Table-1'!E11 -> 18 | G11: ='[1]Table-1'!F11 -> 18 | H11: ='[1]Table-1'!G11 -> 0 | I11: ='[1]Table-1'!H11 -> 0 | J11: ='[1]Table-1'!I11 -> 100 | K11: ='[1]Table-1'!J11 -> 100
A12: ='[1]Table-1'!A12 -> 2 | B12: BANASKANTHA | C12: ='[1]Table-1'!B12 -> 30 | D12: ='[1]Table-1'!C12 -> 0 | E12: ='[1]Table-1'!D12 -> 0 | F12: ='[1]Table-1'!E12 -> 30 | G12: ='[1]Table-1'!F12 -> 30 | H12: ='[1]Table-1'!G12 -> 0 | I12: ='[1]Table-1'!H12 -> 0 | J12: ='[1]Table-1'!I12 -> 100 | K12: ='[1]Table-1'!J12 -> 100
A13: ='[1]Table-1'!A13 -> 3 | B13: PATAN | C13: ='[1]Table-1'!B13 -> 13 | D13: ='[1]Table-1'!C13 -> 0 | E13: ='[1]Table-1'!D13 -> 0 | F13: ='[1]Table-1'!E13 -> 13 | G13: ='[1]Table-1'!F13 -> 13 | H13: ='[1]Table-1'!G13 -> 0 | I13: ='[1]Table-1'!H13 -> 0 | J13: ='[1]Table-1'!I13 -> 100 | K13: ='[1]Table-1'!J13 -> 100
A14: ='[1]Table-1'!A14 -> 4 | B14: MEHSANA | C14: ='[1]Table-1'!B14 -> 12 | D14: ='[1]Table-1'!C14 -> 0 | E14: ='[1]Table-1'!D14 -> 0 | F14: ='[1]Table-1'!E14 -> 12 | G14: ='[1]Table-1'!F14 -> 12 | H14: ='[1]Table-1'!G14 -> 0 | I14: ='[1]Table-1'!H14 -> 0 | J14: ='[1]Table-1'!I14 -> 100 | K14: ='[1]Table-1'!J14 -> 100
A15: ='[1]Table-1'!A15 -> 5 | B15: SABARKANTHA | C15: ='[1]Table-1'!B15 -> 9 | D15: ='[1]Table-1'!C15 -> 0 | E15: ='[1]Table-1'!D15 -> 0 | F15: ='[1]Table-1'!E15 -> 9 | G15: ='[1]Table-1'!F15 -> 9 | H15: ='[1]Table-1'!G15 -> 0 | I15: ='[1]Table-1'!H15 -> 0 | J15: ='[1]Table-1'!I15 -> 100 | K15: ='[1]Table-1'!J15 -> 100
A16: ='[1]Table-1'!A16 -> 6 | B16: GANDHINAGAR | C16: ='[1]Table-1'!B16 -> 6 | D16: ='[1]Table-1'!C16 -> 0 | E16: ='[1]Table-1'!D16 -> 0 | F16: ='[1]Table-1'!E16 -> 6 | G16: ='[1]Table-1'!F16 -> 6 | H16: ='[1]Table-1'!G16 -> 0 | I16: ='[1]Table-1'!H16 -> 0 | J16: ='[1]Table-1'!I16 -> 100 | K16: ='[1]Table-1'!J16 -> 100
A17: ='[1]Table-1'!A17 -> 7 | B17: AHMEDABAD | C17: ='[1]Table-1'!B17 -> 16 | D17: ='[1]Table-1'!C17 -> 0 | E17: ='[1]Table-1'!D17 -> 0 | F17: ='[1]Table-1'!E17 -> 16 | G17: ='[1]Table-1'!F17 -> 16 | H17: ='[1]Table-1'!G17 -> 0 | I17: ='[1]Table-1'!H17 -> 0 | J17: ='[1]Table-1'!I17 -> 100 | K17: ='[1]Table-1'!J17 -> 100
A18: ='[1]Table-1'!A18 -> 8 | B18: SURENDRANAGAR | C18: ='[1]Table-1'!B18 -> 21 | D18: ='[1]Table-1'!C18 -> 0 | E18: ='[1]Table-1'!D18 -> 0 | F18: ='[1]Table-1'!E18 -> 21 | G18: ='[1]Table-1'!F18 -> 21 | H18: ='[1]Table-1'!G18 -> 0 | I18: ='[1]Table-1'!H18 -> 0 | J18: ='[1]Table-1'!I18 -> 100 | K18: ='[1]Table-1'!J18 -> 100
A19: ='[1]Table-1'!A19 -> 9 | B19: RAJKOT | C19: ='[1]Table-1'!B19 -> 20 | D19: ='[1]Table-1'!C19 -> 0 | E19: ='[1]Table-1'!D19 -> 0 | F19: ='[1]Table-1'!E19 -> 20 | G19: ='[1]Table-1'!F19 -> 20 | H19: ='[1]Table-1'!G19 -> 0 | I19: ='[1]Table-1'!H19 -> 0 | J19: ='[1]Table-1'!I19 -> 100 | K19: ='[1]Table-1'!J19 -> 100
A20: ='[1]Table-1'!A20 -> 10 | B20: JAMNAGAR | C20: ='[1]Table-1'!B20 -> 12 | D20: ='[1]Table-1'!C20 -> 0 | E20: ='[1]Table-1'!D20 -> 0 | F20: ='[1]Table-1'!E20 -> 12 | G20: ='[1]Table-1'!F20 -> 12 | H20: ='[1]Table-1'!G20 -> 0 | I20: ='[1]Table-1'!H20 -> 0 | J20: ='[1]Table-1'!I20 -> 100 | K20: ='[1]Table-1'!J20 -> 100
A21: ='[1]Table-1'!A21 -> 11 | B21: PORBANDAR | C21: ='[1]Table-1'!B21 -> 5 | D21: ='[1]Table-1'!C21 -> 0 | E21: ='[1]Table-1'!D21 -> 0 | F21: ='[1]Table-1'!E21 -> 5 | G21: ='[1]Table-1'!F21 -> 5 | H21: ='[1]Table-1'!G21 -> 0 | I21: ='[1]Table-1'!H21 -> 0 | J21: ='[1]Table-1'!I21 -> 100 | K21: ='[1]Table-1'!J21 -> 100
A22: ='[1]Table-1'!A22 -> 12 | B22: JUNAGADH | C22: ='[1]Table-1'!B22 -> 16 | D22: ='[1]Table-1'!C22 -> 0 | E22: ='[1]Table-1'!D22 -> 0 | F22: ='[1]Table-1'!E22 -> 16 | G22: ='[1]Table-1'!F22 -> 16 | H22: ='[1]Table-1'!G22 -> 0 | I22: ='[1]Table-1'!H22 -> 0 | J22: ='[1]Table-1'!I22 -> 100 | K22: ='[1]Table-1'!J22 -> 100
... A43: ='[1]Table-1'!A43 -> 33 | B43: MORBI | C43: ='[1]Table-1'!B43 -> 11 | D43: ='[1]Table-1'!C43 -> 0 | E43: ='[1]Table-1'!D43 -> 0 | F43: ='[1]Table-1'!E43 -> 11 | G43: ='[1]Table-1'!F43 -> 11 | H43: ='[1]Table-1'!G43 -> 0 | I43: ='[1]Table-1'!H43 -> 0 | J43: ='[1]Table-1'!I43 -> 100 | K43: ='[1]Table-1'!J43 -> 100
A44: ='[1]Table-1'!A44 | C44: ='[1]Table-1'!B44 | D44: ='[1]Table-1'!C44 | E44: ='[1]Table-1'!D44 | F44: ='[1]Table-1'!E44 | G44: ='[1]Table-1'!F44 | H44: ='[1]Table-1'!G44 | I44: ='[1]Table-1'!H44 | J44: ='[1]Table-1'!I44 | K44: ='[1]Table-1'!J44
A45: ='[1]Table-1'!A45 | C45: ='[1]Table-1'!B45 | D45: ='[1]Table-1'!C45 | E45: ='[1]Table-1'!D45 | F45: ='[1]Table-1'!E45 | G45: ='[1]Table-1'!F45 | H45: ='[1]Table-1'!G45 | I45: ='[1]Table-1'!H45 | J45: ='[1]Table-1'!I45 | K45: ='[1]Table-1'!J45
A46: ='[1]Table-1'!A46 | C46: ='[1]Table-1'!B46 | D46: ='[1]Table-1'!C46 | E46: ='[1]Table-1'!D46 | F46: ='[1]Table-1'!E46 | G46: ='[1]Table-1'!F46 | H46: ='[1]Table-1'!G46 | I46: ='[1]Table-1'!H46 | J46: ='[1]Table-1'!I46 | K46: ='[1]Table-1'!J46
A47: ='[1]Table-1'!A47 | C47: ='[1]Table-1'!B47 | D47: ='[1]Table-1'!C47 | E47: ='[1]Table-1'!D47 | F47: ='[1]Table-1'!E47 | G47: ='[1]Table-1'!F47 | H47: ='[1]Table-1'!G47 | I47: ='[1]Table-1'!H47 | J47: ='[1]Table-1'!I47 | K47: ='[1]Table-1'!J47
A48: ='[1]Table-1'!A48 | C48: ='[1]Table-1'!B48 | D48: ='[1]Table-1'!C48 | E48: ='[1]Table-1'!D48 | F48: ='[1]Table-1'!E48 | G48: ='[1]Table-1'!F48 | H48: ='[1]Table-1'!G48 | I48: ='[1]Table-1'!H48 | J48: ='[1]Table-1'!I48 | K48: ='[1]Table-1'!J48
A49: ='[1]Table-1'!A49 | C49: ='[1]Table-1'!B49 | D49: ='[1]Table-1'!C49 | E49: ='[1]Table-1'!D49 | F49: ='[1]Table-1'!E49 | G49: ='[1]Table-1'!F49 | H49: ='[1]Table-1'!G49 | I49: ='[1]Table-1'!H49 | J49: ='[1]Table-1'!I49 | K49: ='[1]Table-1'!J49
A50: ='[1]Table-1'!A50 | C50: ='[1]Table-1'!B50 | D50: ='[1]Table-1'!C50 | E50: ='[1]Table-1'!D50 | F50: ='[1]Table-1'!E50 | G50: ='[1]Table-1'!F50 | H50: ='[1]Table-1'!G50 | I50: ='[1]Table-1'!H50 | J50: ='[1]Table-1'!I50 | K50: ='[1]Table-1'!J50
A51: ='[1]Table-1'!A51 | C51: ='[1]Table-1'!B51 | D51: ='[1]Table-1'!C51 | E51: ='[1]Table-1'!D51 | F51: ='[1]Table-1'!E51 | G51: ='[1]Table-1'!F51 | H51: ='[1]Table-1'!G51 | I51: ='[1]Table-1'!H51 | J51: ='[1]Table-1'!I51 | K51: ='[1]Table-1'!J51
A52: ='[1]Table-1'!A52 | C52: ='[1]Table-1'!B52 | D52: ='[1]Table-1'!C52 | E52: ='[1]Table-1'!D52 | F52: ='[1]Table-1'!E52 | G52: ='[1]Table-1'!F52 | H52: ='[1]Table-1'!G52 | I52: ='[1]Table-1'!H52 | J52: ='[1]Table-1'!I52 | K52: ='[1]Table-1'!J52
A53: ='[1]Table-1'!A53 | C53: ='[1]Table-1'!B53 | D53: ='[1]Table-1'!C53 | E53: ='[1]Table-1'!D53 | F53: ='[1]Table-1'!E53 | G53: ='[1]Table-1'!F53 | H53: ='[1]Table-1'!G53 | I53: ='[1]Table-1'!H53 | J53: ='[1]Table-1'!I53 | K53: ='[1]Table-1'!J53
A54: ='[1]Table-1'!A54 | C54: ='[1]Table-1'!B54 | D54: ='[1]Table-1'!C54 | E54: ='[1]Table-1'!D54 | F54: ='[1]Table-1'!E54 | G54: ='[1]Table-1'!F54 | H54: ='[1]Table-1'!G54 | I54: ='[1]Table-1'!H54 | J54: ='[1]Table-1'!I54 | K54: ='[1]Table-1'!J54
A55: ='[1]Table-1'!A55 | C55: ='[1]Table-1'!B55 | D55: ='[1]Table-1'!C55 | E55: ='[1]Table-1'!D55 | F55: ='[1]Table-1'!E55 | G55: ='[1]Table-1'!F55 | H55: ='[1]Table-1'!G55 | I55: ='[1]Table-1'!H55 | J55: ='[1]Table-1'!I55 | K55: ='[1]Table-1'!J55
... A98: ='[1]Table-1'!A98 -> STATE: | C98: ='[1]Table-1'!B98 -> 340 | D98: ='[1]Table-1'!C98 -> 0 | E98: ='[1]Table-1'!D98 -> 0 | F98: ='[1]Table-1'!E98 -> 339 | G98: ='[1]Table-1'!F98 -> 339 | H98: ='[1]Table-1'!G98 -> 0 | I98: ='[1]Table-1'!H98 -> 0 | J98: ='[1]Table-1'!I98 -> 99.71 | K98: ='[1]Table-1'!J98 -> 99.71
A99: NOTE: "a" ENTRIES= AS PER SUPERVISOR, "b" ENTRIES= AS PER PATWARI.
A101: T-2
A102: TABLE :A-1 : DISTRICTWISE DISTRIBUTION OF SELECTED VILLAGES FOR CHECK ON ENUMERATION OF AREA AND RESPONSE ACHIEVED.
A103: =A3 -> STATE: GUJARAT | E103: YEAR: | F103: ='[1]Table-1'!P3 -> 2024-25 | G103: SEASON: | H103: ='[1]Table-1'!R3 -> RABI(4) | K103: SAMPLE: STATE
A104: DISTRICT | B104: DISTRICT NAME | C104: NO.OF VILLAGES FOR WHICH SCHEDULE AS 1.0 RECEIVED | D104: NO. OF VILLAGES FOR WHICH SCHEDULE AS 1.0 IS ANALYSED | H104: PERCENTAGE RESPONSE TO COL.(3)
D105: WITH 'a' AND 'b' ENTRIES TOGETHER | E105: WITH 'a' AND 'b' ENTRIES SEPARATELY | F105: WITH 'a' ENTRIES ONLY | G105: TOTAL | H105: WITH 'a' AND 'b' ENTRIES TOGETHER | I105: WITH 'a' AND 'b' ENTRIES SEPARATELY | J105: WITH 'a' ENTRIES ONLY | K105: TOTAL
A110: 1 | B110: 2 | C110: 3 | D110: 4 | E110: 5 | F110: 7 | G110: 8 | H110: 9 | I110: 10 | J110: 11 | K110: 12
A111: ='[1]Table-1'!L11 -> 1 | B111: KACHCHH | C111: ='[1]Table-1'!M11 -> 18 | D111: ='[1]Table-1'!N11 -> 0 | E111: ='[1]Table-1'!O11 -> 0 | F111: ='[1]Table-1'!P11 -> 18 | G111: ='[1]Table-1'!Q11 -> 18 | H111: ='[1]Table-1'!R11 -> 0 | I111: ='[1]Table-1'!S11 -> 0 | J111: ='[1]Table-1'!T11 -> 100 | K111: ='[1]Table-1'!U11 -> 100
...

Sheet RC1-A1 (2)
A1: T-3
A2: TABLE A-1 : DISTRICTWISE DISTRIBUTION OF SELECTED VILLAGES FOR CHECK ON ENUMERATION OF AREA AND RESPONSE ACHIEVED.
A3: =info!$E$2 -> STATE: GUJARAT | E3: YEAR: | F3: ='[4]Table-1'!E3 -> 2024-25 | G3: SEASON: | H3: ='[4]Table-1'!G3 -> SUMMER(5) | K3: ='RC1-A1'!$K$3 -> SAMPLE: CENTRAL
A4: DISTRICT | B4: DISTRICT NAME | C4: NO.OF VILLAGES FOR WHICH SCHEDULE AS 1.0 RECEIVED | D4: NO. OF VILLAGES FOR WHICH SCHEDULE AS 1.0 IS ANALYSED | H4: PERCENTAGE RESPONSE TO COL.(3)
D5: WITH 'a' AND 'b' ENTRIES TOGETHER | E5: WITH 'a' AND 'b' ENTRIES SEPARATELY | F5: WITH 'a' ENTRIES ONLY | G5: TOTAL | H5: WITH 'a' AND 'b' ENTRIES TOGETHER | I5: WITH 'a' AND 'b' ENTRIES SEPARATELY | J5: WITH 'a' ENTRIES ONLY | K5: TOTAL
A10: 1 | B10: 2 | C10: 3 | D10: 4 | E10: 5 | F10: 7 | G10: 8 | H10: 9 | I10: 10 | J10: 11 | K10: 12
A11: ='[4]Table-1'!A11 -> 1 | B11: KACHCHH | C11: ='[4]Table-1'!B11 -> 18 | D11: ='[4]Table-1'!C11 -> 0 | E11: ='[4]Table-1'!D11 -> 0 | F11: ='[4]Table-1'!E11 -> 18 | G11: ='[4]Table-1'!F11 -> 18 | H11: ='[4]Table-1'!G11 -> 0 | I11: ='[4]Table-1'!H11 -> 0 | J11: ='[4]Table-1'!I11 -> 100 | K11: ='[4]Table-1'!J11 -> 100
A12: ='[4]Table-1'!A12 -> 2 | B12: BANASKANTHA | C12: ='[4]Table-1'!B12 -> 30 | D12: ='[4]Table-1'!C12 -> 0 | E12: ='[4]Table-1'!D12 -> 0 | F12: ='[4]Table-1'!E12 -> 30 | G12: ='[4]Table-1'!F12 -> 30 | H12: ='[4]Table-1'!G12 -> 0 | I12: ='[4]Table-1'!H12 -> 0 | J12: ='[4]Table-1'!I12 -> 100 | K12: ='[4]Table-1'!J12 -> 100
A13: ='[4]Table-1'!A13 -> 3 | B13: PATAN | C13: ='[4]Table-1'!B13 -> 13 | D13: ='[4]Table-1'!C13 -> 0 | E13: ='[4]Table-1'!D13 -> 0 | F13: ='[4]Table-1'!E13 -> 13 | G13: ='[4]Table-1'!F13 -> 13 | H13: ='[4]Table-1'!G13 -> 0 | I13: ='[4]Table-1'!H13 -> 0 | J13: ='[4]Table-1'!I13 -> 100 | K13: ='[4]Table-1'!J13 -> 100
A14: ='[4]Table-1'!A14 -> 4 | B14: MEHSANA | C14: ='[4]Table-1'!B14 -> 12 | D14: ='[4]Table-1'!C14 -> 0 | E14: ='[4]Table-1'!D14 -> 0 | F14: ='[4]Table-1'!E14 -> 12 | G14: ='[4]Table-1'!F14 -> 12 | H14: ='[4]Table-1'!G14 -> 0 | I14: ='[4]Table-1'!H14 -> 0 | J14: ='[4]Table-1'!I14 -> 100 | K14: ='[4]Table-1'!J14 -> 100
A15: ='[4]Table-1'!A15 -> 5 | B15: SABARKANTHA | C15: ='[4]Table-1'!B15 -> 9 | D15: ='[4]Table-1'!C15 -> 0 | E15: ='[4]Table-1'!D15 -> 0 | F15: ='[4]Table-1'!E15 -> 9 | G15: ='[4]Table-1'!F15 -> 9 | H15: ='[4]Table-1'!G15 -> 0 | I15: ='[4]Table-1'!H15 -> 0 | J15: ='[4]Table-1'!I15 -> 100 | K15: ='[4]Table-1'!J15 -> 100
A16: ='[4]Table-1'!A16 -> 6 | B16: GANDHINAGAR | C16: ='[4]Table-1'!B16 -> 6 | D16: ='[4]Table-1'!C16 -> 0 | E16: ='[4]Table-1'!D16 -> 0 | F16: ='[4]Table-1'!E16 -> 6 | G16: ='[4]Table-1'!F16 -> 6 | H16: ='[4]Table-1'!G16 -> 0 | I16: ='[4]Table-1'!H16 -> 0 | J16: ='[4]Table-1'!I16 -> 100 | K16: ='[4]Table-1'!J16 -> 100
A17: ='[4]Table-1'!A17 -> 7 | B17: AHMEDABAD | C17: ='[4]Table-1'!B17 -> 16 | D17: ='[4]Table-1'!C17 -> 0 | E17: ='[4]Table-1'!D17 -> 0 | F17: ='[4]Table-1'!E17 -> 16 | G17: ='[4]Table-1'!F17 -> 16 | H17: ='[4]Table-1'!G17 -> 0 | I17: ='[4]Table-1'!H17 -> 0 | J17: ='[4]Table-1'!I17 -> 100 | K17: ='[4]Table-1'!J17 -> 100
A18: ='[4]Table-1'!A18 -> 8 | B18: SURENDRANAGAR | C18: ='[4]Table-1'!B18 -> 21 | D18: ='[4]Table-1'!C18 -> 0 | E18: ='[4]Table-1'!D18 -> 0 | F18: ='[4]Table-1'!E18 -> 21 | G18: ='[4]Table-1'!F18 -> 21 | H18: ='[4]Table-1'!G18 -> 0 | I18: ='[4]Table-1'!H18 -> 0 | J18: ='[4]Table-1'!I18 -> 100 | K18: ='[4]Table-1'!J18 -> 100
A19: ='[4]Table-1'!A19 -> 9 | B19: RAJKOT | C19: ='[4]Table-1'!B19 -> 20 | D19: ='[4]Table-1'!C19 -> 0 | E19: ='[4]Table-1'!D19 -> 0 | F19: ='[4]Table-1'!E19 -> 20 | G19: ='[4]Table-1'!F19 -> 20 | H19: ='[4]Table-1'!G19 -> 0 | I19: ='[4]Table-1'!H19 -> 0 | J19: ='[4]Table-1'!I19 -> 100 | K19: ='[4]Table-1'!J19 -> 100
A20: ='[4]Table-1'!A20 -> 10 | B20: JAMNAGAR | C20: ='[4]Table-1'!B20 -> 12 | D20: ='[4]Table-1'!C20 -> 0 | E20: ='[4]Table-1'!D20 -> 0 | F20: ='[4]Table-1'!E20 -> 12 | G20: ='[4]Table-1'!F20 -> 12 | H20: ='[4]Table-1'!G20 -> 0 | I20: ='[4]Table-1'!H20 -> 0 | J20: ='[4]Table-1'!I20 -> 100 | K20: ='[4]Table-1'!J20 -> 100
A21: ='[4]Table-1'!A21 -> 11 | B21: PORBANDAR | C21: ='[4]Table-1'!B21 -> 5 | D21: ='[4]Table-1'!C21 -> 0 | E21: ='[4]Table-1'!D21 -> 0 | F21: ='[4]Table-1'!E21 -> 5 | G21: ='[4]Table-1'!F21 -> 5 | H21: ='[4]Table-1'!G21 -> 0 | I21: ='[4]Table-1'!H21 -> 0 | J21: ='[4]Table-1'!I21 -> 100 | K21: ='[4]Table-1'!J21 -> 100
A22: ='[4]Table-1'!A22 -> 12 | B22: JUNAGADH | C22: ='[4]Table-1'!B22 -> 16 | D22: ='[4]Table-1'!C22 -> 0 | E22: ='[4]Table-1'!D22 -> 0 | F22: ='[4]Table-1'!E22 -> 16 | G22: ='[4]Table-1'!F22 -> 16 | H22: ='[4]Table-1'!G22 -> 0 | I22: ='[4]Table-1'!H22 -> 0 | J22: ='[4]Table-1'!I22 -> 100 | K22: ='[4]Table-1'!J22 -> 100
... A43: ='[4]Table-1'!A43 -> 33 | B43: MORBI | C43: ='[4]Table-1'!B43 -> 11 | D43: ='[4]Table-1'!C43 -> 0 | E43: ='[4]Table-1'!D43 -> 0 | F43: ='[4]Table-1'!E43 -> 11 | G43: ='[4]Table-1'!F43 -> 11 | H43: ='[4]Table-1'!G43 -> 0 | I43: ='[4]Table-1'!H43 -> 0 | J43: ='[4]Table-1'!I43 -> 100 | K43: ='[4]Table-1'!J43 -> 100
A44: ='[4]Table-1'!A44 | C44: ='[4]Table-1'!B44 | D44: ='[4]Table-1'!C44 | E44: ='[4]Table-1'!D44 | F44: ='[4]Table-1'!E44 | G44: ='[4]Table-1'!F44 | H44: ='[4]Table-1'!G44 | I44: ='[4]Table-1'!H44 | J44: ='[4]Table-1'!I44 | K44: ='[4]Table-1'!J44
A45: ='[4]Table-1'!A45 | C45: ='[4]Table-1'!B45 | D45: ='[4]Table-1'!C45 | E45: ='[4]Table-1'!D45 | F45: ='[4]Table-1'!E45 | G45: ='[4]Table-1'!F45 | H45: ='[4]Table-1'!G45 | I45: ='[4]Table-1'!H45 | J45: ='[4]Table-1'!I45 | K45: ='[4]Table-1'!J45
A46: ='[4]Table-1'!A46 | C46: ='[4]Table-1'!B46 | D46: ='[4]Table-1'!C46 | E46: ='[4]Table-1'!D46 | F46: ='[4]Table-1'!E46 | G46: ='[4]Table-1'!F46 | H46: ='[4]Table-1'!G46 | I46: ='[4]Table-1'!H46 | J46: ='[4]Table-1'!I46 | K46: ='[4]Table-1'!J46
A47: ='[4]Table-1'!A47 | C47: ='[4]Table-1'!B47 | D47: ='[4]Table-1'!C47 | E47: ='[4]Table-1'!D47 | F47: ='[4]Table-1'!E47 | G47: ='[4]Table-1'!F47 | H47: ='[4]Table-1'!G47 | I47: ='[4]Table-1'!H47 | J47: ='[4]Table-1'!I47 | K47: ='[4]Table-1'!J47
A48: ='[4]Table-1'!A48 | C48: ='[4]Table-1'!B48 | D48: ='[4]Table-1'!C48 | E48: ='[4]Table-1'!D48 | F48: ='[4]Table-1'!E48 | G48: ='[4]Table-1'!F48 | H48: ='[4]Table-1'!G48 | I48: ='[4]Table-1'!H48 | J48: ='[4]Table-1'!I48 | K48: ='[4]Table-1'!J48
A49: ='[4]Table-1'!A49 | C49: ='[4]Table-1'!B49 | D49: ='[4]Table-1'!C49 | E49: ='[4]Table-1'!D49 | F49: ='[4]Table-1'!E49 | G49: ='[4]Table-1'!F49 | H49: ='[4]Table-1'!G49 | I49: ='[4]Table-1'!H49 | J49: ='[4]Table-1'!I49 | K49: ='[4]Table-1'!J49
A50: ='[4]Table-1'!A50 | C50: ='[4]Table-1'!B50 | D50: ='[4]Table-1'!C50 | E50: ='[4]Table-1'!D50 | F50: ='[4]Table-1'!E50 | G50: ='[4]Table-1'!F50 | H50: ='[4]Table-1'!G50 | I50: ='[4]Table-1'!H50 | J50: ='[4]Table-1'!I50 | K50: ='[4]Table-1'!J50
A51: ='[4]Table-1'!A51 | C51: ='[4]Table-1'!B51 | D51: ='[4]Table-1'!C51 | E51: ='[4]Table-1'!D51 | F51: ='[4]Table-1'!E51 | G51: ='[4]Table-1'!F51 | H51: ='[4]Table-1'!G51 | I51: ='[4]Table-1'!H51 | J51: ='[4]Table-1'!I51 | K51: ='[4]Table-1'!J51
A52: ='[4]Table-1'!A52 | C52: ='[4]Table-1'!B52 | D52: ='[4]Table-1'!C52 | E52: ='[4]Table-1'!D52 | F52: ='[4]Table-1'!E52 | G52: ='[4]Table-1'!F52 | H52: ='[4]Table-1'!G52 | I52: ='[4]Table-1'!H52 | J52: ='[4]Table-1'!I52 | K52: ='[4]Table-1'!J52
A53: ='[4]Table-1'!A53 | C53: ='[4]Table-1'!B53 | D53: ='[4]Table-1'!C53 | E53: ='[4]Table-1'!D53 | F53: ='[4]Table-1'!E53 | G53: ='[4]Table-1'!F53 | H53: ='[4]Table-1'!G53 | I53: ='[4]Table-1'!H53 | J53: ='[4]Table-1'!I53 | K53: ='[4]Table-1'!J53
A54: ='[4]Table-1'!A54 | C54: ='[4]Table-1'!B54 | D54: ='[4]Table-1'!C54 | E54: ='[4]Table-1'!D54 | F54: ='[4]Table-1'!E54 | G54: ='[4]Table-1'!F54 | H54: ='[4]Table-1'!G54 | I54: ='[4]Table-1'!H54 | J54: ='[4]Table-1'!I54 | K54: ='[4]Table-1'!J54
A55: ='[4]Table-1'!A55 | C55: ='[4]Table-1'!B55 | D55: ='[4]Table-1'!C55 | E55: ='[4]Table-1'!D55 | F55: ='[4]Table-1'!E55 | G55: ='[4]Table-1'!F55 | H55: ='[4]Table-1'!G55 | I55: ='[4]Table-1'!H55 | J55: ='[4]Table-1'!I55 | K55: ='[4]Table-1'!J55
... A98: ='[4]Table-1'!A98 -> STATE: | C98: ='[4]Table-1'!B98 -> 340 | D98: ='[4]Table-1'!C98 -> 0 | E98: ='[4]Table-1'!D98 -> 0 | F98: ='[4]Table-1'!E98 -> 339 | G98: ='[4]Table-1'!F98 -> 339 | H98: ='[4]Table-1'!G98 -> 0 | I98: ='[4]Table-1'!H98 -> 0 | J98: ='[4]Table-1'!I98 -> 99.71 | K98: ='[4]Table-1'!J98 -> 99.71
A99: NOTE: "a" ENTRIES= AS PER SUPERVISOR, "b" ENTRIES= AS PER PATWARI.
A101: T-4
A102: TABLE :A-1 : DISTRICTWISE DISTRIBUTION OF SELECTED VILLAGES FOR CHECK ON ENUMERATION OF AREA AND RESPONSE ACHIEVED.
A103: =A3 -> STATE: GUJARAT | E103: YEAR: | F103: ='[4]Table-1'!P3 -> 2024-25 | G103: SEASON: | H103: ='[4]Table-1'!R3 -> SUMMER(5) | K103: ='RC1-A1'!$K$103 -> SAMPLE: STATE
A104: DISTRICT | B104: DISTRICT NAME | C104: NO.OF VILLAGES FOR WHICH SCHEDULE AS 1.0 RECEIVED | D104: NO. OF VILLAGES FOR WHICH SCHEDULE AS 1.0 IS ANALYSED | H104: PERCENTAGE RESPONSE TO COL.(3)
D105: WITH 'a' AND 'b' ENTRIES TOGETHER | E105: WITH 'a' AND 'b' ENTRIES SEPARATELY | F105: WITH 'a' ENTRIES ONLY | G105: TOTAL | H105: WITH 'a' AND 'b' ENTRIES TOGETHER | I105: WITH 'a' AND 'b' ENTRIES SEPARATELY | J105: WITH 'a' ENTRIES ONLY | K105: TOTAL
A110: 1 | B110: 2 | C110: 3 | D110: 4 | E110: 5 | F110: 7 | G110: 8 | H110: 9 | I110: 10 | J110: 11 | K110: 12
A111: ='[4]Table-1'!L11 -> 1 | B111: KACHCHH | C111: ='[4]Table-1'!M11 -> 18 | D111: ='[4]Table-1'!N11 -> 0 | E111: ='[4]Table-1'!O11 -> 0 | F111: ='[4]Table-1'!P11 -> 18 | G111: ='[4]Table-1'!Q11 -> 18 | H111: ='[4]Table-1'!R11 -> 0 | I111: ='[4]Table-1'!S11 -> 0 | J111: ='[4]Table-1'!T11 -> 100 | K111: ='[4]Table-1'!U11 -> 100
...

Sheet RC1-A5
A1: T-5
A2: TABLE A-5: DISTRICTWISE DISTRIBUTION OF SELECTED VILLAGES ACCORDING TO COMPLETION OR OTHERWISE OF GIRDAWARI BY PATWARI AS PER THE PRESCRIBED TIME SCHEDULE.
A3: =info!$E$2 -> STATE: GUJARAT | H3: YEAR: | I3: ='[1]Table-5'!H3 -> 2024-25 | M3: SEASON: | O3: ='[1]Table-5'!N3 -> RABI(4) | V3: ='RC1-A1'!$K$3 -> SAMPLE: CENTRAL
A4: DISTRICT | B4: DISTRICT NAME | C4: NO. OF VILLAGE ANALYSED | D4: NUMBER OF VILLAGES WHERE GIRDAWARI HAS BEEN | M4: NO. OF VILLAGES IN WHICH | O4: NO. OF VILLAGES IN WHICH GIRDAWARI NOT YET STARTED DUE TO REASON (CODE)* | T4: TOTAL (COL. 7 +12+ 19) | U4: NO. OF VILLAGES FOR WHICH
D5: COMPLETED | H5: PARTIALLY COMPLETED DUE TO REASON (CODE)@ | U5: SYSTEM OF GIRDAWARI DOES NOT EXIST | V5: INFORMATION ABOUT COMPLETION OF GIRDAWARI NOT AVAILABLE
D6: IN TIME | E6: LATE | F6: BUT DATE OF COMPLETION IS NOT KNOWN | G6: SUB TOTAL (COL. 4+5+6) | H6: 1 | I6: 2 | J6: 3 | K6: 4 | L6: SUB TOTAL (COL.8+9+ 10+11) | M6: LATEST FORM FOR GIRDAWARI USED | N6: RECORD OF GIRDAWARI KEPT IN REGULAR FORM | O6: 1 | P6: 2 | Q6: 3 | R6: 4 | S6: SUB TOTAL (COL. 15+ 16+ 17+18)
A7: 1 | B7: 2 | C7: 3 | D7: 4 | E7: 5 | F7: 6 | G7: 7 | H7: 8 | I7: 9 | J7: 10 | K7: 11 | L7: 12 | M7: 13 | N7: 14 | O7: 15 | P7: 16 | Q7: 17 | R7: 18 | S7: 19 | T7: 20 | U7: 21 | V7: 22
A8: ='[1]Table-5'!A8 -> 1 | B8: KACHCHH | C8: ='[1]Table-5'!B8 -> 18 | D8: ='[1]Table-5'!C8 -> 0 | E8: ='[1]Table-5'!D8 -> 0 | F8: ='[1]Table-5'!E8 -> 0 | G8: ='[1]Table-5'!F8 -> 0 | H8: ='[1]Table-5'!G8 -> 0 | I8: ='[1]Table-5'!H8 -> 0 | J8: ='[1]Table-5'!I8 -> 0 | ... V8: ='[1]Table-5'!U8 -> 0
A9: ='[1]Table-5'!A9 -> 2 | B9: BANASKANTHA | C9: ='[1]Table-5'!B9 -> 30 | D9: ='[1]Table-5'!C9 -> 0 | E9: ='[1]Table-5'!D9 -> 0 | F9: ='[1]Table-5'!E9 -> 0 | G9: ='[1]Table-5'!F9 -> 0 | H9: ='[1]Table-5'!G9 -> 0 | I9: ='[1]Table-5'!H9 -> 0 | J9: ='[1]Table-5'!I9 -> 0 | ... V9: ='[1]Table-5'!U9 -> 0
A10: ='[1]Table-5'!A10 -> 3 | B10: PATAN | C10: ='[1]Table-5'!B10 -> 13 | D10: ='[1]Table-5'!C10 -> 0 | E10: ='[1]Table-5'!D10 -> 0 | F10: ='[1]Table-5'!E10 -> 0 | G10: ='[1]Table-5'!F10 -> 0 | H10: ='[1]Table-5'!G10 -> 0 | I10: ='[1]Table-5'!H10 -> 0 | J10: ='[1]Table-5'!I10 -> 0 | ... V10: ='[1]Table-5'!U10 -> 0
A11: ='[1]Table-5'!A11 -> 4 | B11: MEHSANA | C11: ='[1]Table-5'!B11 -> 12 | D11: ='[1]Table-5'!C11 -> 0 | E11: ='[1]Table-5'!D11 -> 0 | F11: ='[1]Table-5'!E11 -> 0 | G11: ='[1]Table-5'!F11 -> 0 | H11: ='[1]Table-5'!G11 -> 0 | I11: ='[1]Table-5'!H11 -> 0 | J11: ='[1]Table-5'!I11 -> 0 | ... V11: ='[1]Table-5'!U11 -> 0
A12: ='[1]Table-5'!A12 -> 5 | B12: SABARKANTHA | C12: ='[1]Table-5'!B12 -> 9 | D12: ='[1]Table-5'!C12 -> 0 | E12: ='[1]Table-5'!D12 -> 0 | F12: ='[1]Table-5'!E12 -> 0 | G12: ='[1]Table-5'!F12 -> 0 | H12: ='[1]Table-5'!G12 -> 0 | I12: ='[1]Table-5'!H12 -> 0 | J12: ='[1]Table-5'!I12 -> 0 | ... V12: ='[1]Table-5'!U12 -> 0
A13: ='[1]Table-5'!A13 -> 6 | B13: GANDHINAGAR | C13: ='[1]Table-5'!B13 -> 6 | D13: ='[1]Table-5'!C13 -> 0 | E13: ='[1]Table-5'!D13 -> 0 | F13: ='[1]Table-5'!E13 -> 0 | G13: ='[1]Table-5'!F13 -> 0 | H13: ='[1]Table-5'!G13 -> 0 | I13: ='[1]Table-5'!H13 -> 0 | J13: ='[1]Table-5'!I13 -> 0 | ... V13: ='[1]Table-5'!U13 -> 0
A14: ='[1]Table-5'!A14 -> 7 | B14: AHMEDABAD | C14: ='[1]Table-5'!B14 -> 16 | D14: ='[1]Table-5'!C14 -> 0 | E14: ='[1]Table-5'!D14 -> 0 | F14: ='[1]Table-5'!E14 -> 0 | G14: ='[1]Table-5'!F14 -> 0 | H14: ='[1]Table-5'!G14 -> 0 | I14: ='[1]Table-5'!H14 -> 0 | J14: ='[1]Table-5'!I14 -> 0 | ... V14: ='[1]Table-5'!U14 -> 0
A15: ='[1]Table-5'!A15 -> 8 | B15: SURENDRANAGAR | C15: ='[1]Table-5'!B15 -> 21 | D15: ='[1]Table-5'!C15 -> 0 | E15: ='[1]Table-5'!D15 -> 0 | F15: ='[1]Table-5'!E15 -> 0 | G15: ='[1]Table-5'!F15 -> 0 | H15: ='[1]Table-5'!G15 -> 0 | I15: ='[1]Table-5'!H15 -> 0 | J15: ='[1]Table-5'!I15 -> 0 | ... V15: ='[1]Table-5'!U15 -> 0
A16: ='[1]Table-5'!A16 -> 9 | B16: RAJKOT | C16: ='[1]Table-5'!B16 -> 20 | D16: ='[1]Table-5'!C16 -> 0 | E16: ='[1]Table-5'!D16 -> 0 | F16: ='[1]Table-5'!E16 -> 0 | G16: ='[1]Table-5'!F16 -> 0 | H16: ='[1]Table-5'!G16 -> 0 | I16: ='[1]Table-5'!H16 -> 0 | J16: ='[1]Table-5'!I16 -> 0 | ... V16: ='[1]Table-5'!U16 -> 0
A17: ='[1]Table-5'!A17 -> 10 | B17: JAMNAGAR | C17: ='[1]Table-5'!B17 -> 12 | D17: ='[1]Table-5'!C17 -> 0 | E17: ='[1]Table-5'!D17 -> 0 | F17: ='[1]Table-5'!E17 -> 0 | G17: ='[1]Table-5'!F17 -> 0 | H17: ='[1]Table-5'!G17 -> 0 | I17: ='[1]Table-5'!H17 -> 0 | J17: ='[1]Table-5'!I17 -> 0 | ... V17: ='[1]Table-5'!U17 -> 0
A18: ='[1]Table-5'!A18 -> 11 | B18: PORBANDAR | C18: ='[1]Table-5'!B18 -> 5 | D18: ='[1]Table-5'!C18 -> 0 | E18: ='[1]Table-5'!D18 -> 0 | F18: ='[1]Table-5'!E18 -> 0 | G18: ='[1]Table-5'!F18 -> 0 | H18: ='[1]Table-5'!G18 -> 0 | I18: ='[1]Table-5'!H18 -> 0 | J18: ='[1]Table-5'!I18 -> 0 | ... V18: ='[1]Table-5'!U18 -> 0
A19: ='[1]Table-5'!A19 -> 12 | B19: JUNAGADH | C19: ='[1]Table-5'!B19 -> 16 | D19: ='[1]Table-5'!C19 -> 0 | E19: ='[1]Table-5'!D19 -> 0 | F19: ='[1]Table-5'!E19 -> 0 | G19: ='[1]Table-5'!F19 -> 0 | H19: ='[1]Table-5'!G19 -> 0 | I19: ='[1]Table-5'!H19 -> 0 | J19: ='[1]Table-5'!I19 -> 0 | ... V19: ='[1]Table-5'!U19 -> 0
... A40: ='[1]Table-5'!A40 -> 33 | B40: MORBI | C40: ='[1]Table-5'!B40 -> 11 | D40: ='[1]Table-5'!C40 -> 0 | E40: ='[1]Table-5'!D40 -> 0 | F40: ='[1]Table-5'!E40 -> 0 | G40: ='[1]Table-5'!F40 -> 0 | H40: ='[1]Table-5'!G40 -> 0 | I40: ='[1]Table-5'!H40 -> 0 | J40: ='[1]Table-5'!I40 -> 0 | ... V40: ='[1]Table-5'!U40 -> 0
A41: ='[1]Table-5'!A41 | C41: ='[1]Table-5'!B41 | D41: ='[1]Table-5'!C41 | E41: ='[1]Table-5'!D41 | F41: ='[1]Table-5'!E41 | G41: ='[1]Table-5'!F41 | H41: ='[1]Table-5'!G41 | I41: ='[1]Table-5'!H41 | J41: ='[1]Table-5'!I41 | ... V41: ='[1]Table-5'!U41
A42: ='[1]Table-5'!A42 | C42: ='[1]Table-5'!B42 | D42: ='[1]Table-5'!C42 | E42: ='[1]Table-5'!D42 | F42: ='[1]Table-5'!E42 | G42: ='[1]Table-5'!F42 | H42: ='[1]Table-5'!G42 | I42: ='[1]Table-5'!H42 | J42: ='[1]Table-5'!I42 | ... V42: ='[1]Table-5'!U42
A43: ='[1]Table-5'!A43 | C43: ='[1]Table-5'!B43 | D43: ='[1]Table-5'!C43 | E43: ='[1]Table-5'!D43 | F43: ='[1]Table-5'!E43 | G43: ='[1]Table-5'!F43 | H43: ='[1]Table-5'!G43 | I43: ='[1]Table-5'!H43 | J43: ='[1]Table-5'!I43 | ... V43: ='[1]Table-5'!U43
A44: ='[1]Table-5'!A44 | C44: ='[1]Table-5'!B44 | D44: ='[1]Table-5'!C44 | E44: ='[1]Table-5'!D44 | F44: ='[1]Table-5'!E44 | G44: ='[1]Table-5'!F44 | H44: ='[1]Table-5'!G44 | I44: ='[1]Table-5'!H44 | J44: ='[1]Table-5'!I44 | ... V44: ='[1]Table-5'!U44
A45: ='[1]Table-5'!A45 | C45: ='[1]Table-5'!B45 | D45: ='[1]Table-5'!C45 | E45: ='[1]Table-5'!D45 | F45: ='[1]Table-5'!E45 | G45: ='[1]Table-5'!F45 | H45: ='[1]Table-5'!G45 | I45: ='[1]Table-5'!H45 | J45: ='[1]Table-5'!I45 | ... V45: ='[1]Table-5'!U45
A46: ='[1]Table-5'!A46 | C46: ='[1]Table-5'!B46 | D46: ='[1]Table-5'!C46 | E46: ='[1]Table-5'!D46 | F46: ='[1]Table-5'!E46 | G46: ='[1]Table-5'!F46 | H46: ='[1]Table-5'!G46 | I46: ='[1]Table-5'!H46 | J46: ='[1]Table-5'!I46 | ... V46: ='[1]Table-5'!U46
A47: ='[1]Table-5'!A47 | C47: ='[1]Table-5'!B47 | D47: ='[1]Table-5'!C47 | E47: ='[1]Table-5'!D47 | F47: ='[1]Table-5'!E47 | G47: ='[1]Table-5'!F47 | H47: ='[1]Table-5'!G47 | I47: ='[1]Table-5'!H47 | J47: ='[1]Table-5'!I47 | ... V47: ='[1]Table-5'!U47
A48: ='[1]Table-5'!A48 | C48: ='[1]Table-5'!B48 | D48: ='[1]Table-5'!C48 | E48: ='[1]Table-5'!D48 | F48: ='[1]Table-5'!E48 | G48: ='[1]Table-5'!F48 | H48: ='[1]Table-5'!G48 | I48: ='[1]Table-5'!H48 | J48: ='[1]Table-5'!I48 | ... V48: ='[1]Table-5'!U48
A49: ='[1]Table-5'!A49 | C49: ='[1]Table-5'!B49 | D49: ='[1]Table-5'!C49 | E49: ='[1]Table-5'!D49 | F49: ='[1]Table-5'!E49 | G49: ='[1]Table-5'!F49 | H49: ='[1]Table-5'!G49 | I49: ='[1]Table-5'!H49 | J49: ='[1]Table-5'!I49 | ... V49: ='[1]Table-5'!U49
A50: ='[1]Table-5'!A50 | C50: ='[1]Table-5'!B50 | D50: ='[1]Table-5'!C50 | E50: ='[1]Table-5'!D50 | F50: ='[1]Table-5'!E50 | G50: ='[1]Table-5'!F50 | H50: ='[1]Table-5'!G50 | I50: ='[1]Table-5'!H50 | J50: ='[1]Table-5'!I50 | ... V50: ='[1]Table-5'!U50
A51: ='[1]Table-5'!A51 | C51: ='[1]Table-5'!B51 | D51: ='[1]Table-5'!C51 | E51: ='[1]Table-5'!D51 | F51: ='[1]Table-5'!E51 | G51: ='[1]Table-5'!F51 | H51: ='[1]Table-5'!G51 | I51: ='[1]Table-5'!H51 | J51: ='[1]Table-5'!I51 | ... V51: ='[1]Table-5'!U51
A52: ='[1]Table-5'!A52 | C52: ='[1]Table-5'!B52 | D52: ='[1]Table-5'!C52 | E52: ='[1]Table-5'!D52 | F52: ='[1]Table-5'!E52 | G52: ='[1]Table-5'!F52 | H52: ='[1]Table-5'!G52 | I52: ='[1]Table-5'!H52 | J52: ='[1]Table-5'!I52 | ... V52: ='[1]Table-5'!U52
... A100: ='[1]Table-5'!A100 -> TOTAL: | C100: ='[1]Table-5'!B100 -> 339 | D100: ='[1]Table-5'!C100 -> 0 | E100: ='[1]Table-5'!D100 -> 0 | F100: ='[1]Table-5'!E100 -> 0 | G100: ='[1]Table-5'!F100 -> 0 | H100: ='[1]Table-5'!G100 -> 0 | I100: ='[1]Table-5'!H100 -> 0 | J100: ='[1]Table-5'!I100 -> 0 | ... V100: ='[1]Table-5'!U100 -> 1
A101: %AGE TO COL.(20) | D101: ='[1]Table-5'!C101 -> 0 | E101: ='[1]Table-5'!D101 -> 0 | F101: ='[1]Table-5'!E101 -> 0 | G101: ='[1]Table-5'!F101 -> 0 | H101: ='[1]Table-5'!G101 -> 0 | I101: ='[1]Table-5'!H101 -> 0 | J101: ='[1]Table-5'!I101 -> 0 | K101: ='[1]Table-5'!J101 -> 0 | ... V101: ='[1]Table-5'!U101 -> 0.29
A102: % TO COL. 13 AND COL. 14 OR WITH RESPECT TO (COL. 7 + COL. 12) | M102: ='[1]Table-5'!L102 -> #DIV/0! | N102: ='[1]Table-5'!M102 -> #DIV/0!
A103: NOTE: (I) COL.3= COL.20+COL.21+COL.22 (II) COL.3 OF TABLE A-2 SHOULD TALLY WITH COL.3 OF TABLE A-5
A104: REASON CODE: OCCUPIED WITH OTHER WORK = 1, TRS PROGRAMME WAS NOT INITIATED IN TIME= 2, OTHER REASON =3, REASON NOT AVAILABLE=4
A105: (THESE CODES CORRESPONDS TO PRE-TABULATION CODING I.E. 4,5,6, AND 7 FOR THE ITEM 10(D) OF SCH. AS 1.0)
A107: T-6
A108: TABLE A-5: DISTRICTWISE DISTRIBUTION OF SELECTED VILLAGES ACCORDING TO COMPLETION OR OTHERWISE OF GIRDAWARI BY PATWARI AS PER THE PRESCRIBED TIME SCHEDULE.
...

Sheet RC1-A5 (2)
A1: T-7
A2: TABLE A-5: DISTRICTWISE DISTRIBUTION OF SELECTED VILLAGES ACCORDING TO COMPLETION OR OTHERWISE OF GIRDAWARI BY PATWARI AS PER THE PRESCRIBED TIME SCHEDULE.
A3: =info!$E$2 -> STATE: GUJARAT | H3: YEAR: | I3: ='[4]Table-5'!H3 -> 2024-25 | M3: SEASON: | O3: ='[4]Table-5'!N3 -> SUMMER(5) | V3: ='RC1-A1'!$K$3 -> SAMPLE: CENTRAL
A4: DISTRICT | B4: DISTRICT NAME | C4: NO. OF VILLAGE ANALYSED | D4: NUMBER OF VILLAGES WHERE GIRDAWARI HAS BEEN | M4: NO. OF VILLAGES IN WHICH | O4: NO. OF VILLAGES IN WHICH GIRDAWARI NOT YET STARTED DUE TO REASON (CODE)* | T4: TOTAL (COL. 7 +12+ 19) | U4: NO. OF VILLAGES FOR WHICH
D5: COMPLETED | H5: PARTIALLY COMPLETED DUE TO REASON (CODE)@ | U5: SYSTEM OF GIRDAWARI DOES NOT EXIST | V5: INFORMATION ABOUT COMPLETION OF GIRDAWARI NOT AVAILABLE
D6: IN TIME | E6: LATE | F6: BUT DATE OF COMPLETION IS NOT KNOWN | G6: SUB TOTAL (COL. 4+5+6) | H6: 1 | I6: 2 | J6: 3 | K6: 4 | L6: SUB TOTAL (COL.8+9+ 10+11) | M6: LATEST FORM FOR GIRDAWARI USED | N6: RECORD OF GIRDAWARI KEPT IN REGULAR FORM | O6: 1 | P6: 2 | Q6: 3 | R6: 4 | S6: SUB TOTAL (COL. 15+ 16+ 17+18)
A7: 1 | B7: 2 | C7: 3 | D7: 4 | E7: 5 | F7: 6 | G7: 7 | H7: 8 | I7: 9 | J7: 10 | K7: 11 | L7: 12 | M7: 13 | N7: 14 | O7: 15 | P7: 16 | Q7: 17 | R7: 18 | S7: 19 | T7: 20 | U7: 21 | V7: 22
A8: ='[4]Table-5'!A8 -> 1 | B8: KACHCHH | C8: ='[4]Table-5'!B8 -> 18 | D8: ='[4]Table-5'!C8 -> 0 | E8: ='[4]Table-5'!D8 -> 0 | F8: ='[4]Table-5'!E8 -> 0 | G8: ='[4]Table-5'!F8 -> 0 | H8: ='[4]Table-5'!G8 -> 0 | I8: ='[4]Table-5'!H8 -> 0 | J8: ='[4]Table-5'!I8 -> 0 | ... V8: ='[4]Table-5'!U8 -> 0
A9: ='[4]Table-5'!A9 -> 2 | B9: BANASKANTHA | C9: ='[4]Table-5'!B9 -> 30 | D9: ='[4]Table-5'!C9 -> 0 | E9: ='[4]Table-5'!D9 -> 0 | F9: ='[4]Table-5'!E9 -> 0 | G9: ='[4]Table-5'!F9 -> 0 | H9: ='[4]Table-5'!G9 -> 0 | I9: ='[4]Table-5'!H9 -> 0 | J9: ='[4]Table-5'!I9 -> 0 | ... V9: ='[4]Table-5'!U9 -> 0
A10: ='[4]Table-5'!A10 -> 3 | B10: PATAN | C10: ='[4]Table-5'!B10 -> 13 | D10: ='[4]Table-5'!C10 -> 0 | E10: ='[4]Table-5'!D10 -> 0 | F10: ='[4]Table-5'!E10 -> 0 | G10: ='[4]Table-5'!F10 -> 0 | H10: ='[4]Table-5'!G10 -> 0 | I10: ='[4]Table-5'!H10 -> 0 | J10: ='[4]Table-5'!I10 -> 0 | ... V10: ='[4]Table-5'!U10 -> 0
A11: ='[4]Table-5'!A11 -> 4 | B11: MEHSANA | C11: ='[4]Table-5'!B11 -> 12 | D11: ='[4]Table-5'!C11 -> 0 | E11: ='[4]Table-5'!D11 -> 0 | F11: ='[4]Table-5'!E11 -> 0 | G11: ='[4]Table-5'!F11 -> 0 | H11: ='[4]Table-5'!G11 -> 0 | I11: ='[4]Table-5'!H11 -> 0 | J11: ='[4]Table-5'!I11 -> 0 | ... V11: ='[4]Table-5'!U11 -> 0
A12: ='[4]Table-5'!A12 -> 5 | B12: SABARKANTHA | C12: ='[4]Table-5'!B12 -> 9 | D12: ='[4]Table-5'!C12 -> 0 | E12: ='[4]Table-5'!D12 -> 0 | F12: ='[4]Table-5'!E12 -> 0 | G12: ='[4]Table-5'!F12 -> 0 | H12: ='[4]Table-5'!G12 -> 0 | I12: ='[4]Table-5'!H12 -> 0 | J12: ='[4]Table-5'!I12 -> 0 | ... V12: ='[4]Table-5'!U12 -> 0
A13: ='[4]Table-5'!A13 -> 6 | B13: GANDHINAGAR | C13: ='[4]Table-5'!B13 -> 6 | D13: ='[4]Table-5'!C13 -> 0 | E13: ='[4]Table-5'!D13 -> 0 | F13: ='[4]Table-5'!E13 -> 0 | G13: ='[4]Table-5'!F13 -> 0 | H13: ='[4]Table-5'!G13 -> 0 | I13: ='[4]Table-5'!H13 -> 0 | J13: ='[4]Table-5'!I13 -> 0 | ... V13: ='[4]Table-5'!U13 -> 0
A14: ='[4]Table-5'!A14 -> 7 | B14: AHMEDABAD | C14: ='[4]Table-5'!B14 -> 16 | D14: ='[4]Table-5'!C14 -> 0 | E14: ='[4]Table-5'!D14 -> 0 | F14: ='[4]Table-5'!E14 -> 0 | G14: ='[4]Table-5'!F14 -> 0 | H14: ='[4]Table-5'!G14 -> 0 | I14: ='[4]Table-5'!H14 -> 0 | J14: ='[4]Table-5'!I14 -> 0 | ... V14: ='[4]Table-5'!U14 -> 0
A15: ='[4]Table-5'!A15 -> 8 | B15: SURENDRANAGAR | C15: ='[4]Table-5'!B15 -> 21 | D15: ='[4]Table-5'!C15 -> 0 | E15: ='[4]Table-5'!D15 -> 0 | F15: ='[4]Table-5'!E15 -> 0 | G15: ='[4]Table-5'!F15 -> 0 | H15: ='[4]Table-5'!G15 -> 0 | I15: ='[4]Table-5'!H15 -> 0 | J15: ='[4]Table-5'!I15 -> 0 | ... V15: ='[4]Table-5'!U15 -> 0
A16: ='[4]Table-5'!A16 -> 9 | B16: RAJKOT | C16: ='[4]Table-5'!B16 -> 20 | D16: ='[4]Table-5'!C16 -> 0 | E16: ='[4]Table-5'!D16 -> 0 | F16: ='[4]Table-5'!E16 -> 0 | G16: ='[4]Table-5'!F16 -> 0 | H16: ='[4]Table-5'!G16 -> 0 | I16: ='[4]Table-5'!H16 -> 0 | J16: ='[4]Table-5'!I16 -> 0 | ... V16: ='[4]Table-5'!U16 -> 0
A17: ='[4]Table-5'!A17 -> 10 | B17: JAMNAGAR | C17: ='[4]Table-5'!B17 -> 12 | D17: ='[4]Table-5'!C17 -> 0 | E17: ='[4]Table-5'!D17 -> 0 | F17: ='[4]Table-5'!E17 -> 0 | G17: ='[4]Table-5'!F17 -> 0 | H17: ='[4]Table-5'!G17 -> 0 | I17: ='[4]Table-5'!H17 -> 0 | J17: ='[4]Table-5'!I17 -> 0 | ... V17: ='[4]Table-5'!U17 -> 0
A18: ='[4]Table-5'!A18 -> 11 | B18: PORBANDAR | C18: ='[4]Table-5'!B18 -> 5 | D18: ='[4]Table-5'!C18 -> 0 | E18: ='[4]Table-5'!D18 -> 0 | F18: ='[4]Table-5'!E18 -> 0 | G18: ='[4]Table-5'!F18 -> 0 | H18: ='[4]Table-5'!G18 -> 0 | I18: ='[4]Table-5'!H18 -> 0 | J18: ='[4]Table-5'!I18 -> 0 | ... V18: ='[4]Table-5'!U18 -> 0
A19: ='[4]Table-5'!A19 -> 12 | B19: JUNAGADH | C19: ='[4]Table-5'!B19 -> 16 | D19: ='[4]Table-5'!C19 -> 0 | E19: ='[4]Table-5'!D19 -> 0 | F19: ='[4]Table-5'!E19 -> 0 | G19: ='[4]Table-5'!F19 -> 0 | H19: ='[4]Table-5'!G19 -> 0 | I19: ='[4]Table-5'!H19 -> 0 | J19: ='[4]Table-5'!I19 -> 0 | ... V19: ='[4]Table-5'!U19 -> 1
... A40: ='[4]Table-5'!A40 -> 33 | B40: MORBI | C40: ='[4]Table-5'!B40 -> 11 | D40: ='[4]Table-5'!C40 -> 0 | E40: ='[4]Table-5'!D40 -> 0 | F40: ='[4]Table-5'!E40 -> 0 | G40: ='[4]Table-5'!F40 -> 0 | H40: ='[4]Table-5'!G40 -> 0 | I40: ='[4]Table-5'!H40 -> 0 | J40: ='[4]Table-5'!I40 -> 0 | ... V40: ='[4]Table-5'!U40 -> 0
A41: ='[4]Table-5'!A41 | C41: ='[4]Table-5'!B41 | D41: ='[4]Table-5'!C41 | E41: ='[4]Table-5'!D41 | F41: ='[4]Table-5'!E41 | G41: ='[4]Table-5'!F41 | H41: ='[4]Table-5'!G41 | I41: ='[4]Table-5'!H41 | J41: ='[4]Table-5'!I41 | ... V41: ='[4]Table-5'!U41
A42: ='[4]Table-5'!A42 | C42: ='[4]Table-5'!B42 | D42: ='[4]Table-5'!C42 | E42: ='[4]Table-5'!D42 | F42: ='[4]Table-5'!E42 | G42: ='[4]Table-5'!F42 | H42: ='[4]Table-5'!G42 | I42: ='[4]Table-5'!H42 | J42: ='[4]Table-5'!I42 | ... V42: ='[4]Table-5'!U42
A43: ='[4]Table-5'!A43 | C43: ='[4]Table-5'!B43 | D43: ='[4]Table-5'!C43 | E43: ='[4]Table-5'!D43 | F43: ='[4]Table-5'!E43 | G43: ='[4]Table-5'!F43 | H43: ='[4]Table-5'!G43 | I43: ='[4]Table-5'!H43 | J43: ='[4]Table-5'!I43 | ... V43: ='[4]Table-5'!U43
A44: ='[4]Table-5'!A44 | C44: ='[4]Table-5'!B44 | D44: ='[4]Table-5'!C44 | E44: ='[4]Table-5'!D44 | F44: ='[4]Table-5'!E44 | G44: ='[4]Table-5'!F44 | H44: ='[4]Table-5'!G44 | I44: ='[4]Table-5'!H44 | J44: ='[4]Table-5'!I44 | ... V44: ='[4]Table-5'!U44
A45: ='[4]Table-5'!A45 | C45: ='[4]Table-5'!B45 | D45: ='[4]Table-5'!C45 | E45: ='[4]Table-5'!D45 | F45: ='[4]Table-5'!E45 | G45: ='[4]Table-5'!F45 | H45: ='[4]Table-5'!G45 | I45: ='[4]Table-5'!H45 | J45: ='[4]Table-5'!I45 | ... V45: ='[4]Table-5'!U45
A46: ='[4]Table-5'!A46 | C46: ='[4]Table-5'!B46 | D46: ='[4]Table-5'!C46 | E46: ='[4]Table-5'!D46 | F46: ='[4]Table-5'!E46 | G46: ='[4]Table-5'!F46 | H46: ='[4]Table-5'!G46 | I46: ='[4]Table-5'!H46 | J46: ='[4]Table-5'!I46 | ... V46: ='[4]Table-5'!U46
A47: ='[4]Table-5'!A47 | C47: ='[4]Table-5'!B47 | D47: ='[4]Table-5'!C47 | E47: ='[4]Table-5'!D47 | F47: ='[4]Table-5'!E47 | G47: ='[4]Table-5'!F47 | H47: ='[4]Table-5'!G47 | I47: ='[4]Table-5'!H47 | J47: ='[4]Table-5'!I47 | ... V47: ='[4]Table-5'!U47
A48: ='[4]Table-5'!A48 | C48: ='[4]Table-5'!B48 | D48: ='[4]Table-5'!C48 | E48: ='[4]Table-5'!D48 | F48: ='[4]Table-5'!E48 | G48: ='[4]Table-5'!F48 | H48: ='[4]Table-5'!G48 | I48: ='[4]Table-5'!H48 | J48: ='[4]Table-5'!I48 | ... V48: ='[4]Table-5'!U48
A49: ='[4]Table-5'!A49 | C49: ='[4]Table-5'!B49 | D49: ='[4]Table-5'!C49 | E49: ='[4]Table-5'!D49 | F49: ='[4]Table-5'!E49 | G49: ='[4]Table-5'!F49 | H49: ='[4]Table-5'!G49 | I49: ='[4]Table-5'!H49 | J49: ='[4]Table-5'!I49 | ... V49: ='[4]Table-5'!U49
A50: ='[4]Table-5'!A50 | C50: ='[4]Table-5'!B50 | D50: ='[4]Table-5'!C50 | E50: ='[4]Table-5'!D50 | F50: ='[4]Table-5'!E50 | G50: ='[4]Table-5'!F50 | H50: ='[4]Table-5'!G50 | I50: ='[4]Table-5'!H50 | J50: ='[4]Table-5'!I50 | ... V50: ='[4]Table-5'!U50
A51: ='[4]Table-5'!A51 | C51: ='[4]Table-5'!B51 | D51: ='[4]Table-5'!C51 | E51: ='[4]Table-5'!D51 | F51: ='[4]Table-5'!E51 | G51: ='[4]Table-5'!F51 | H51: ='[4]Table-5'!G51 | I51: ='[4]Table-5'!H51 | J51: ='[4]Table-5'!I51 | ... V51: ='[4]Table-5'!U51
A52: ='[4]Table-5'!A52 | C52: ='[4]Table-5'!B52 | D52: ='[4]Table-5'!C52 | E52: ='[4]Table-5'!D52 | F52: ='[4]Table-5'!E52 | G52: ='[4]Table-5'!F52 | H52: ='[4]Table-5'!G52 | I52: ='[4]Table-5'!H52 | J52: ='[4]Table-5'!I52 | ... V52: ='[4]Table-5'!U52
... A100: ='[4]Table-5'!A100 -> TOTAL: | C100: ='[4]Table-5'!B100 -> 339 | D100: ='[4]Table-5'!C100 -> 0 | E100: ='[4]Table-5'!D100 -> 0 | F100: ='[4]Table-5'!E100 -> 0 | G100: ='[4]Table-5'!F100 -> 0 | H100: ='[4]Table-5'!G100 -> 0 | I100: ='[4]Table-5'!H100 -> 0 | J100: ='[4]Table-5'!I100 -> 0 | ... V100: ='[4]Table-5'!U100 -> 3
A101: %AGE TO COL.(20) | D101: ='[4]Table-5'!C101 -> 0 | E101: ='[4]Table-5'!D101 -> 0 | F101: ='[4]Table-5'!E101 -> 0 | G101: ='[4]Table-5'!F101 -> 0 | H101: ='[4]Table-5'!G101 -> 0 | I101: ='[4]Table-5'!H101 -> 0 | J101: ='[4]Table-5'!I101 -> 0 | K101: ='[4]Table-5'!J101 -> 0 | ... V101: ='[4]Table-5'!U101 -> 0.88
A102: % TO COL. 13 AND COL. 14 OR WITH RESPECT TO (COL. 7 + COL. 12) | M102: ='[4]Table-5'!L102 -> #DIV/0! | N102: ='[4]Table-5'!M102 -> #DIV/0!
A103: NOTE: (I) COL.3= COL.20+COL.21+COL.22 (II) COL.3 OF TABLE A-2 SHOULD TALLY WITH COL.3 OF TABLE A-5
A104: REASON CODE: OCCUPIED WITH OTHER WORK = 1, TRS PROGRAMME WAS NOT INITIATED IN TIME= 2, OTHER REASON =3, REASON NOT AVAILABLE=4
A105: (THESE CODES CORRESPONDS TO PRE-TABULATION CODING I.E. 4,5,6, AND 7 FOR THE ITEM 10(D) OF SCH. AS 1.0)
A107: T-8
A108: TABLE A-5: DISTRICTWISE DISTRIBUTION OF SELECTED VILLAGES ACCORDING TO COMPLETION OR OTHERWISE OF GIRDAWARI BY PATWARI AS PER THE PRESCRIBED TIME SCHEDULE.
...

Sheet RC1-A7
A1: T-9
A2: TABLE A-7: DISTRICTWISE DISTRIBUTION OF SELECTED VILLAGES ACCORDING TO THE SUBMISSION OF TRS STATEMENT.
A3: =info!$E$2 -> STATE: GUJARAT | H3: YEAR: | I3: ='[1]Table-7'!H2 -> 2024-25 | M3: SEASON: | O3: ='[1]Table-7'!N2 -> RABI(4) | U3: ='RC1-A1'!$K$3 -> SAMPLE: CENTRAL
A4: DISTRICT | B4: DISTRICT NAME | C4: NO. OF VILLAGES ANALYSED | D4: NUMBER OF VILLAGES FOR WHICH
D5: TRS STATEMENT SUBMITTED | N5: OUT OF COL. 12 | P5: TRS STATEMENT NOT SUBMITTED | T5: INFORMATION ABOUT SUBMISSION OR TRS STATEMENT NOT AVAILABLE | U5: TRS STATEMENT NOT TO BE SUBMITTED (A) BEING NON TRS VILLGES (B) AS PER STATE INSTRUCTION
D6: IN TIME | H6: LATE | L6: BUT DATE OF SUBMISSION NOT RECORDED | M6: TOTAL (COL. 7+ 11+ 12) | N6: TRS STATEMENT SUBMITTED IN STANDARD FORM | O6: DUPLICATE COPY OF STATEMENT KEPT | P6: THOUGH GIRDAWARI COMPLETED | R6: AS GIRDAWARI NOT COMPLETED | S6: SUB TOTAL (COL. 16+17+18)
D7: BEFORE GIRDAWARI | E7: AFTER GIRDAWARI | F7: BUT COULD NOT COMPARED WITH GIRDAWARI COMPLETION | G7: SUB TOTAL (COL. 4 +5+6) | H7: BEFORE GIRDAWARI | I7: AFTER GIRDAWARI | J7: BUT COULD NOT COMPARED WITH GIRDAWARI COMPLETION | K7: SUB TOTAL (COL.8+9+10) | P7: AS DUE DATE NOT OVER | Q7: OTHER REASONS
A8: 1 | B8: 2 | C8: 3 | D8: 4 | E8: 5 | F8: 6 | G8: 7 | H8: 8 | I8: 9 | J8: 10 | K8: 11 | L8: 12 | M8: 13 | N8: 14 | O8: 15 | P8: 16 | Q8: 17 | R8: 18 | S8: 19 | T8: 20 | U8: 21
A9: ='[1]Table-7'!A8 -> 1 | B9: KACHCHH | C9: ='[1]Table-7'!B8 -> 18 | D9: ='[1]Table-7'!C8 -> 0 | E9: ='[1]Table-7'!D8 -> 0 | F9: ='[1]Table-7'!E8 -> 0 | G9: ='[1]Table-7'!F8 -> 0 | H9: ='[1]Table-7'!G8 -> 0 | I9: ='[1]Table-7'!H8 -> 0 | J9: ='[1]Table-7'!I8 -> 0 | ... U9: ='[1]Table-7'!T8 -> 0
A10: ='[1]Table-7'!A9 -> 2 | B10: BANASKANTHA | C10: ='[1]Table-7'!B9 -> 30 | D10: ='[1]Table-7'!C9 -> 0 | E10: ='[1]Table-7'!D9 -> 0 | F10: ='[1]Table-7'!E9 -> 0 | G10: ='[1]Table-7'!F9 -> 0 | H10: ='[1]Table-7'!G9 -> 0 | I10: ='[1]Table-7'!H9 -> 0 | J10: ='[1]Table-7'!I9 -> 0 | ... U10: ='[1]Table-7'!T9 -> 0
A11: ='[1]Table-7'!A10 -> 3 | B11: PATAN | C11: ='[1]Table-7'!B10 -> 13 | D11: ='[1]Table-7'!C10 -> 0 | E11: ='[1]Table-7'!D10 -> 0 | F11: ='[1]Table-7'!E10 -> 0 | G11: ='[1]Table-7'!F10 -> 0 | H11: ='[1]Table-7'!G10 -> 0 | I11: ='[1]Table-7'!H10 -> 0 | J11: ='[1]Table-7'!I10 -> 0 | ... U11: ='[1]Table-7'!T10 -> 0
A12: ='[1]Table-7'!A11 -> 4 | B12: MEHSANA | C12: ='[1]Table-7'!B11 -> 12 | D12: ='[1]Table-7'!C11 -> 0 | E12: ='[1]Table-7'!D11 -> 0 | F12: ='[1]Table-7'!E11 -> 0 | G12: ='[1]Table-7'!F11 -> 0 | H12: ='[1]Table-7'!G11 -> 0 | I12: ='[1]Table-7'!H11 -> 0 | J12: ='[1]Table-7'!I11 -> 0 | ... U12: ='[1]Table-7'!T11 -> 0
A13: ='[1]Table-7'!A12 -> 5 | B13: SABARKANTHA | C13: ='[1]Table-7'!B12 -> 9 | D13: ='[1]Table-7'!C12 -> 0 | E13: ='[1]Table-7'!D12 -> 0 | F13: ='[1]Table-7'!E12 -> 0 | G13: ='[1]Table-7'!F12 -> 0 | H13: ='[1]Table-7'!G12 -> 0 | I13: ='[1]Table-7'!H12 -> 0 | J13: ='[1]Table-7'!I12 -> 0 | ... U13: ='[1]Table-7'!T12 -> 0
A14: ='[1]Table-7'!A13 -> 6 | B14: GANDHINAGAR | C14: ='[1]Table-7'!B13 -> 6 | D14: ='[1]Table-7'!C13 -> 0 | E14: ='[1]Table-7'!D13 -> 0 | F14: ='[1]Table-7'!E13 -> 0 | G14: ='[1]Table-7'!F13 -> 0 | H14: ='[1]Table-7'!G13 -> 0 | I14: ='[1]Table-7'!H13 -> 0 | J14: ='[1]Table-7'!I13 -> 0 | ... U14: ='[1]Table-7'!T13 -> 0
A15: ='[1]Table-7'!A14 -> 7 | B15: AHMEDABAD | C15: ='[1]Table-7'!B14 -> 16 | D15: ='[1]Table-7'!C14 -> 0 | E15: ='[1]Table-7'!D14 -> 0 | F15: ='[1]Table-7'!E14 -> 0 | G15: ='[1]Table-7'!F14 -> 0 | H15: ='[1]Table-7'!G14 -> 0 | I15: ='[1]Table-7'!H14 -> 0 | J15: ='[1]Table-7'!I14 -> 0 | ... U15: ='[1]Table-7'!T14 -> 0
A16: ='[1]Table-7'!A15 -> 8 | B16: SURENDRANAGAR | C16: ='[1]Table-7'!B15 -> 21 | D16: ='[1]Table-7'!C15 -> 0 | E16: ='[1]Table-7'!D15 -> 0 | F16: ='[1]Table-7'!E15 -> 0 | G16: ='[1]Table-7'!F15 -> 0 | H16: ='[1]Table-7'!G15 -> 0 | I16: ='[1]Table-7'!H15 -> 0 | J16: ='[1]Table-7'!I15 -> 0 | ... U16: ='[1]Table-7'!T15 -> 0
A17: ='[1]Table-7'!A16 -> 9 | B17: RAJKOT | C17: ='[1]Table-7'!B16 -> 20 | D17: ='[1]Table-7'!C16 -> 0 | E17: ='[1]Table-7'!D16 -> 0 | F17: ='[1]Table-7'!E16 -> 0 | G17: ='[1]Table-7'!F16 -> 0 | H17: ='[1]Table-7'!G16 -> 0 | I17: ='[1]Table-7'!H16 -> 0 | J17: ='[1]Table-7'!I16 -> 0 | ... U17: ='[1]Table-7'!T16 -> 0
A18: ='[1]Table-7'!A17 -> 10 | B18: JAMNAGAR | C18: ='[1]Table-7'!B17 -> 12 | D18: ='[1]Table-7'!C17 -> 0 | E18: ='[1]Table-7'!D17 -> 0 | F18: ='[1]Table-7'!E17 -> 0 | G18: ='[1]Table-7'!F17 -> 0 | H18: ='[1]Table-7'!G17 -> 0 | I18: ='[1]Table-7'!H17 -> 0 | J18: ='[1]Table-7'!I17 -> 0 | ... U18: ='[1]Table-7'!T17 -> 0
A19: ='[1]Table-7'!A18 -> 11 | B19: PORBANDAR | C19: ='[1]Table-7'!B18 -> 5 | D19: ='[1]Table-7'!C18 -> 0 | E19: ='[1]Table-7'!D18 -> 0 | F19: ='[1]Table-7'!E18 -> 0 | G19: ='[1]Table-7'!F18 -> 0 | H19: ='[1]Table-7'!G18 -> 0 | I19: ='[1]Table-7'!H18 -> 0 | J19: ='[1]Table-7'!I18 -> 0 | ... U19: ='[1]Table-7'!T18 -> 0
A20: ='[1]Table-7'!A19 -> 12 | B20: JUNAGADH | C20: ='[1]Table-7'!B19 -> 16 | D20: ='[1]Table-7'!C19 -> 0 | E20: ='[1]Table-7'!D19 -> 0 | F20: ='[1]Table-7'!E19 -> 0 | G20: ='[1]Table-7'!F19 -> 0 | H20: ='[1]Table-7'!G19 -> 0 | I20: ='[1]Table-7'!H19 -> 0 | J20: ='[1]Table-7'!I19 -> 0 | ... U20: ='[1]Table-7'!T19 -> 0
... A41: ='[1]Table-7'!A40 -> 33 | B41: MORBI | C41: ='[1]Table-7'!B40 -> 11 | D41: ='[1]Table-7'!C40 -> 0 | E41: ='[1]Table-7'!D40 -> 0 | F41: ='[1]Table-7'!E40 -> 0 | G41: ='[1]Table-7'!F40 -> 0 | H41: ='[1]Table-7'!G40 -> 0 | I41: ='[1]Table-7'!H40 -> 0 | J41: ='[1]Table-7'!I40 -> 0 | ... U41: ='[1]Table-7'!T40 -> 0
A42: ='[1]Table-7'!A41 | C42: ='[1]Table-7'!B41 | D42: ='[1]Table-7'!C41 | E42: ='[1]Table-7'!D41 | F42: ='[1]Table-7'!E41 | G42: ='[1]Table-7'!F41 | H42: ='[1]Table-7'!G41 | I42: ='[1]Table-7'!H41 | J42: ='[1]Table-7'!I41 | ... U42: ='[1]Table-7'!T41
A43: ='[1]Table-7'!A42 | C43: ='[1]Table-7'!B42 | D43: ='[1]Table-7'!C42 | E43: ='[1]Table-7'!D42 | F43: ='[1]Table-7'!E42 | G43: ='[1]Table-7'!F42 | H43: ='[1]Table-7'!G42 | I43: ='[1]Table-7'!H42 | J43: ='[1]Table-7'!I42 | ... U43: ='[1]Table-7'!T42
A44: ='[1]Table-7'!A43 | C44: ='[1]Table-7'!B43 | D44: ='[1]Table-7'!C43 | E44: ='[1]Table-7'!D43 | F44: ='[1]Table-7'!E43 | G44: ='[1]Table-7'!F43 | H44: ='[1]Table-7'!G43 | I44: ='[1]Table-7'!H43 | J44: ='[1]Table-7'!I43 | ... U44: ='[1]Table-7'!T43
A45: ='[1]Table-7'!A44 | C45: ='[1]Table-7'!B44 | D45: ='[1]Table-7'!C44 | E45: ='[1]Table-7'!D44 | F45: ='[1]Table-7'!E44 | G45: ='[1]Table-7'!F44 | H45: ='[1]Table-7'!G44 | I45: ='[1]Table-7'!H44 | J45: ='[1]Table-7'!I44 | ... U45: ='[1]Table-7'!T44
A46: ='[1]Table-7'!A45 | C46: ='[1]Table-7'!B45 | D46: ='[1]Table-7'!C45 | E46: ='[1]Table-7'!D45 | F46: ='[1]Table-7'!E45 | G46: ='[1]Table-7'!F45 | H46: ='[1]Table-7'!G45 | I46: ='[1]Table-7'!H45 | J46: ='[1]Table-7'!I45 | ... U46: ='[1]Table-7'!T45
A47: ='[1]Table-7'!A46 | C47: ='[1]Table-7'!B46 | D47: ='[1]Table-7'!C46 | E47: ='[1]Table-7'!D46 | F47: ='[1]Table-7'!E46 | G47: ='[1]Table-7'!F46 | H47: ='[1]Table-7'!G46 | I47: ='[1]Table-7'!H46 | J47: ='[1]Table-7'!I46 | ... U47: ='[1]Table-7'!T46
A48: ='[1]Table-7'!A47 | C48: ='[1]Table-7'!B47 | D48: ='[1]Table-7'!C47 | E48: ='[1]Table-7'!D47 | F48: ='[1]Table-7'!E47 | G48: ='[1]Table-7'!F47 | H48: ='[1]Table-7'!G47 | I48: ='[1]Table-7'!H47 | J48: ='[1]Table-7'!I47 | ... U48: ='[1]Table-7'!T47
A49: ='[1]Table-7'!A48 | C49: ='[1]Table-7'!B48 | D49: ='[1]Table-7'!C48 | E49: ='[1]Table-7'!D48 | F49: ='[1]Table-7'!E48 | G49: ='[1]Table-7'!F48 | H49: ='[1]Table-7'!G48 | I49: ='[1]Table-7'!H48 | J49: ='[1]Table-7'!I48 | ... U49: ='[1]Table-7'!T48
A50: ='[1]Table-7'!A49 | C50: ='[1]Table-7'!B49 | D50: ='[1]Table-7'!C49 | E50: ='[1]Table-7'!D49 | F50: ='[1]Table-7'!E49 | G50: ='[1]Table-7'!F49 | H50: ='[1]Table-7'!G49 | I50: ='[1]Table-7'!H49 | J50: ='[1]Table-7'!I49 | ... U50: ='[1]Table-7'!T49
A51: ='[1]Table-7'!A50 | C51: ='[1]Table-7'!B50 | D51: ='[1]Table-7'!C50 | E51: ='[1]Table-7'!D50 | F51: ='[1]Table-7'!E50 | G51: ='[1]Table-7'!F50 | H51: ='[1]Table-7'!G50 | I51: ='[1]Table-7'!H50 | J51: ='[1]Table-7'!I50 | ... U51: ='[1]Table-7'!T50
A52: ='[1]Table-7'!A51 | C52: ='[1]Table-7'!B51 | D52: ='[1]Table-7'!C51 | E52: ='[1]Table-7'!D51 | F52: ='[1]Table-7'!E51 | G52: ='[1]Table-7'!F51 | H52: ='[1]Table-7'!G51 | I52: ='[1]Table-7'!H51 | J52: ='[1]Table-7'!I51 | ... U52: ='[1]Table-7'!T51
A53: ='[1]Table-7'!A52 | C53: ='[1]Table-7'!B52 | D53: ='[1]Table-7'!C52 | E53: ='[1]Table-7'!D52 | F53: ='[1]Table-7'!E52 | G53: ='[1]Table-7'!F52 | H53: ='[1]Table-7'!G52 | I53: ='[1]Table-7'!H52 | J53: ='[1]Table-7'!I52 | ... U53: ='[1]Table-7'!T52
... A100: ='[1]Table-7'!A99 -> TOTAL: | C100: ='[1]Table-7'!B99 -> 339 | D100: ='[1]Table-7'!C99 -> 0 | E100: ='[1]Table-7'!D99 -> 0 | F100: ='[1]Table-7'!E99 -> 0 | G100: ='[1]Table-7'!F99 -> 0 | H100: ='[1]Table-7'!G99 -> 0 | I100: ='[1]Table-7'!H99 -> 0 | J100: ='[1]Table-7'!I99 -> 0 | ... U100: ='[1]Table-7'!T99 -> 0
A101: %AGE TO COL.(3) | D101: ='[1]Table-7'!C100 -> 0 | E101: ='[1]Table-7'!D100 -> 0 | F101: ='[1]Table-7'!E100 -> 0 | G101: ='[1]Table-7'!F100 -> 0 | H101: ='[1]Table-7'!G100 -> 0 | I101: ='[1]Table-7'!H100 -> 0 | J101: ='[1]Table-7'!I100 -> 0 | K101: ='[1]Table-7'!J100 -> 0 | ... U101: ='[1]Table-7'!T100 -> 0
A102: NOTE- (I) PERCENTAGE OF ALL COLUMNS EXCEPT COL.14 AND COL.15 ARE WITH THE REFERENCE TO COL.3
A103: (II) PERCENTAGE OF COL.14 AND COL.15 ARE WITH REFERENCE TO COL.13
A104: T-10
A105: TABLE A-7: DISTRICTWISE DISTRIBUTION OF SELECTED VILLAGES ACCORDING TO THE SUBMISSION OF TRS STATEMENT.
A106: =A3 -> STATE: GUJARAT | H106: YEAR: | I106: ='[1]Table-7'!AC2 -> 2024-25 | M106: SEASON: | O106: ='[1]Table-7'!AI2 -> RABI(4) | U106: ='RC1-A1'!$K$103 -> SAMPLE: STATE
...

Sheet RC1-A7 (2)
A1: T-11
A2: TABLE A-7: DISTRICTWISE DISTRIBUTION OF SELECTED VILLAGES ACCORDING TO THE SUBMISSION OF TRS STATEMENT.
A3: =info!$E$2 -> STATE: GUJARAT | H3: YEAR: | I3: ='[4]Table-7'!H2 -> 2024-25 | M3: SEASON: | O3: ='[4]Table-7'!N2 -> SUMMER(5) | U3: ='RC1-A1'!$K$3 -> SAMPLE: CENTRAL
A4: DISTRICT | B4: DISTRICT NAME | C4: NO. OF VILLAGES ANALYSED | D4: NUMBER OF VILLAGES FOR WHICH
D5: TRS STATEMENT SUBMITTED | N5: OUT OF COL. 12 | P5: TRS STATEMENT NOT SUBMITTED | T5: INFORMATION ABOUT SUBMISSION OR TRS STATEMENT NOT AVAILABLE | U5: TRS STATEMENT NOT TO BE SUBMITTED (A) BEING NON TRS VILLGES (B) AS PER STATE INSTRUCTION
D6: IN TIME | H6: LATE | L6: BUT DATE OF SUBMISSION NOT RECORDED | M6: TOTAL (COL. 7+ 11+ 12) | N6: TRS STATEMENT SUBMITTED IN STANDARD FORM | O6: DUPLICATE COPY OF STATEMENT KEPT | P6: THOUGH GIRDAWARI COMPLETED | R6: AS GIRDAWARI NOT COMPLETED | S6: SUB TOTAL (COL. 16+17+18)
D7: BEFORE GIRDAWARI | E7: AFTER GIRDAWARI | F7: BUT COULD NOT COMPARED WITH GIRDAWARI COMPLETION | G7: SUB TOTAL (COL. 4 +5+6) | H7: BEFORE GIRDAWARI | I7: AFTER GIRDAWARI | J7: BUT COULD NOT COMPARED WITH GIRDAWARI COMPLETION | K7: SUB TOTAL (COL.8+9+10) | P7: AS DUE DATE NOT OVER | Q7: OTHER REASONS
A8: 1 | B8: 2 | C8: 3 | D8: 4 | E8: 5 | F8: 6 | G8: 7 | H8: 8 | I8: 9 | J8: 10 | K8: 11 | L8: 12 | M8: 13 | N8: 14 | O8: 15 | P8: 16 | Q8: 17 | R8: 18 | S8: 19 | T8: 20 | U8: 21
A9: ='[4]Table-7'!A8 -> 1 | B9: KACHCHH | C9: ='[4]Table-7'!B8 -> 18 | D9: ='[4]Table-7'!C8 -> 0 | E9: ='[4]Table-7'!D8 -> 0 | F9: ='[4]Table-7'!E8 -> 0 | G9: ='[4]Table-7'!F8 -> 0 | H9: ='[4]Table-7'!G8 -> 0 | I9: ='[4]Table-7'!H8 -> 0 | J9: ='[4]Table-7'!I8 -> 0 | ... U9: ='[4]Table-7'!T8 -> 0
A10: ='[4]Table-7'!A9 -> 2 | B10: BANASKANTHA | C10: ='[4]Table-7'!B9 -> 30 | D10: ='[4]Table-7'!C9 -> 0 | E10: ='[4]Table-7'!D9 -> 0 | F10: ='[4]Table-7'!E9 -> 0 | G10: ='[4]Table-7'!F9 -> 0 | H10: ='[4]Table-7'!G9 -> 0 | I10: ='[4]Table-7'!H9 -> 0 | J10: ='[4]Table-7'!I9 -> 0 | ... U10: ='[4]Table-7'!T9 -> 0
A11: ='[4]Table-7'!A10 -> 3 | B11: PATAN | C11: ='[4]Table-7'!B10 -> 13 | D11: ='[4]Table-7'!C10 -> 0 | E11: ='[4]Table-7'!D10 -> 0 | F11: ='[4]Table-7'!E10 -> 0 | G11: ='[4]Table-7'!F10 -> 0 | H11: ='[4]Table-7'!G10 -> 0 | I11: ='[4]Table-7'!H10 -> 0 | J11: ='[4]Table-7'!I10 -> 0 | ... U11: ='[4]Table-7'!T10 -> 0
A12: ='[4]Table-7'!A11 -> 4 | B12: MEHSANA | C12: ='[4]Table-7'!B11 -> 12 | D12: ='[4]Table-7'!C11 -> 0 | E12: ='[4]Table-7'!D11 -> 0 | F12: ='[4]Table-7'!E11 -> 0 | G12: ='[4]Table-7'!F11 -> 0 | H12: ='[4]Table-7'!G11 -> 0 | I12: ='[4]Table-7'!H11 -> 0 | J12: ='[4]Table-7'!I11 -> 0 | ... U12: ='[4]Table-7'!T11 -> 0
A13: ='[4]Table-7'!A12 -> 5 | B13: SABARKANTHA | C13: ='[4]Table-7'!B12 -> 9 | D13: ='[4]Table-7'!C12 -> 0 | E13: ='[4]Table-7'!D12 -> 0 | F13: ='[4]Table-7'!E12 -> 0 | G13: ='[4]Table-7'!F12 -> 0 | H13: ='[4]Table-7'!G12 -> 0 | I13: ='[4]Table-7'!H12 -> 0 | J13: ='[4]Table-7'!I12 -> 0 | ... U13: ='[4]Table-7'!T12 -> 0
A14: ='[4]Table-7'!A13 -> 6 | B14: GANDHINAGAR | C14: ='[4]Table-7'!B13 -> 6 | D14: ='[4]Table-7'!C13 -> 0 | E14: ='[4]Table-7'!D13 -> 0 | F14: ='[4]Table-7'!E13 -> 0 | G14: ='[4]Table-7'!F13 -> 0 | H14: ='[4]Table-7'!G13 -> 0 | I14: ='[4]Table-7'!H13 -> 0 | J14: ='[4]Table-7'!I13 -> 0 | ... U14: ='[4]Table-7'!T13 -> 0
A15: ='[4]Table-7'!A14 -> 7 | B15: AHMEDABAD | C15: ='[4]Table-7'!B14 -> 16 | D15: ='[4]Table-7'!C14 -> 0 | E15: ='[4]Table-7'!D14 -> 0 | F15: ='[4]Table-7'!E14 -> 0 | G15: ='[4]Table-7'!F14 -> 0 | H15: ='[4]Table-7'!G14 -> 0 | I15: ='[4]Table-7'!H14 -> 0 | J15: ='[4]Table-7'!I14 -> 0 | ... U15: ='[4]Table-7'!T14 -> 0
A16: ='[4]Table-7'!A15 -> 8 | B16: SURENDRANAGAR | C16: ='[4]Table-7'!B15 -> 21 | D16: ='[4]Table-7'!C15 -> 0 | E16: ='[4]Table-7'!D15 -> 0 | F16: ='[4]Table-7'!E15 -> 0 | G16: ='[4]Table-7'!F15 -> 0 | H16: ='[4]Table-7'!G15 -> 0 | I16: ='[4]Table-7'!H15 -> 0 | J16: ='[4]Table-7'!I15 -> 0 | ... U16: ='[4]Table-7'!T15 -> 0
A17: ='[4]Table-7'!A16 -> 9 | B17: RAJKOT | C17: ='[4]Table-7'!B16 -> 20 | D17: ='[4]Table-7'!C16 -> 0 | E17: ='[4]Table-7'!D16 -> 0 | F17: ='[4]Table-7'!E16 -> 0 | G17: ='[4]Table-7'!F16 -> 0 | H17: ='[4]Table-7'!G16 -> 0 | I17: ='[4]Table-7'!H16 -> 0 | J17: ='[4]Table-7'!I16 -> 0 | ... U17: ='[4]Table-7'!T16 -> 0
A18: ='[4]Table-7'!A17 -> 10 | B18: JAMNAGAR | C18: ='[4]Table-7'!B17 -> 12 | D18: ='[4]Table-7'!C17 -> 0 | E18: ='[4]Table-7'!D17 -> 0 | F18: ='[4]Table-7'!E17 -> 0 | G18: ='[4]Table-7'!F17 -> 0 | H18: ='[4]Table-7'!G17 -> 0 | I18: ='[4]Table-7'!H17 -> 0 | J18: ='[4]Table-7'!I17 -> 0 | ... U18: ='[4]Table-7'!T17 -> 0
A19: ='[4]Table-7'!A18 -> 11 | B19: PORBANDAR | C19: ='[4]Table-7'!B18 -> 5 | D19: ='[4]Table-7'!C18 -> 0 | E19: ='[4]Table-7'!D18 -> 0 | F19: ='[4]Table-7'!E18 -> 0 | G19: ='[4]Table-7'!F18 -> 0 | H19: ='[4]Table-7'!G18 -> 0 | I19: ='[4]Table-7'!H18 -> 0 | J19: ='[4]Table-7'!I18 -> 0 | ... U19: ='[4]Table-7'!T18 -> 0
A20: ='[4]Table-7'!A19 -> 12 | B20: JUNAGADH | C20: ='[4]Table-7'!B19 -> 16 | D20: ='[4]Table-7'!C19 -> 0 | E20: ='[4]Table-7'!D19 -> 0 | F20: ='[4]Table-7'!E19 -> 0 | G20: ='[4]Table-7'!F19 -> 0 | H20: ='[4]Table-7'!G19 -> 0 | I20: ='[4]Table-7'!H19 -> 0 | J20: ='[4]Table-7'!I19 -> 0 | ... U20: ='[4]Table-7'!T19 -> 0
... A41: ='[4]Table-7'!A40 -> 33 | B41: MORBI | C41: ='[4]Table-7'!B40 -> 11 | D41: ='[4]Table-7'!C40 -> 0 | E41: ='[4]Table-7'!D40 -> 0 | F41: ='[4]Table-7'!E40 -> 0 | G41: ='[4]Table-7'!F40 -> 0 | H41: ='[4]Table-7'!G40 -> 0 | I41: ='[4]Table-7'!H40 -> 0 | J41: ='[4]Table-7'!I40 -> 0 | ... U41: ='[4]Table-7'!T40 -> 0
A42: ='[4]Table-7'!A41 | C42: ='[4]Table-7'!B41 | D42: ='[4]Table-7'!C41 | E42: ='[4]Table-7'!D41 | F42: ='[4]Table-7'!E41 | G42: ='[4]Table-7'!F41 | H42: ='[4]Table-7'!G41 | I42: ='[4]Table-7'!H41 | J42: ='[4]Table-7'!I41 | ... U42: ='[4]Table-7'!T41
A43: ='[4]Table-7'!A42 | C43: ='[4]Table-7'!B42 | D43: ='[4]Table-7'!C42 | E43: ='[4]Table-7'!D42 | F43: ='[4]Table-7'!E42 | G43: ='[4]Table-7'!F42 | H43: ='[4]Table-7'!G42 | I43: ='[4]Table-7'!H42 | J43: ='[4]Table-7'!I42 | ... U43: ='[4]Table-7'!T42
A44: ='[4]Table-7'!A43 | C44: ='[4]Table-7'!B43 | D44: ='[4]Table-7'!C43 | E44: ='[4]Table-7'!D43 | F44: ='[4]Table-7'!E43 | G44: ='[4]Table-7'!F43 | H44: ='[4]Table-7'!G43 | I44: ='[4]Table-7'!H43 | J44: ='[4]Table-7'!I43 | ... U44: ='[4]Table-7'!T43
A45: ='[4]Table-7'!A44 | C45: ='[4]Table-7'!B44 | D45: ='[4]Table-7'!C44 | E45: ='[4]Table-7'!D44 | F45: ='[4]Table-7'!E44 | G45: ='[4]Table-7'!F44 | H45: ='[4]Table-7'!G44 | I45: ='[4]Table-7'!H44 | J45: ='[4]Table-7'!I44 | ... U45: ='[4]Table-7'!T44
A46: ='[4]Table-7'!A45 | C46: ='[4]Table-7'!B45 | D46: ='[4]Table-7'!C45 | E46: ='[4]Table-7'!D45 | F46: ='[4]Table-7'!E45 | G46: ='[4]Table-7'!F45 | H46: ='[4]Table-7'!G45 | I46: ='[4]Table-7'!H45 | J46: ='[4]Table-7'!I45 | ... U46: ='[4]Table-7'!T45
A47: ='[4]Table-7'!A46 | C47: ='[4]Table-7'!B46 | D47: ='[4]Table-7'!C46 | E47: ='[4]Table-7'!D46 | F47: ='[4]Table-7'!E46 | G47: ='[4]Table-7'!F46 | H47: ='[4]Table-7'!G46 | I47: ='[4]Table-7'!H46 | J47: ='[4]Table-7'!I46 | ... U47: ='[4]Table-7'!T46
A48: ='[4]Table-7'!A47 | C48: ='[4]Table-7'!B47 | D48: ='[4]Table-7'!C47 | E48: ='[4]Table-7'!D47 | F48: ='[4]Table-7'!E47 | G48: ='[4]Table-7'!F47 | H48: ='[4]Table-7'!G47 | I48: ='[4]Table-7'!H47 | J48: ='[4]Table-7'!I47 | ... U48: ='[4]Table-7'!T47
A49: ='[4]Table-7'!A48 | C49: ='[4]Table-7'!B48 | D49: ='[4]Table-7'!C48 | E49: ='[4]Table-7'!D48 | F49: ='[4]Table-7'!E48 | G49: ='[4]Table-7'!F48 | H49: ='[4]Table-7'!G48 | I49: ='[4]Table-7'!H48 | J49: ='[4]Table-7'!I48 | ... U49: ='[4]Table-7'!T48
A50: ='[4]Table-7'!A49 | C50: ='[4]Table-7'!B49 | D50: ='[4]Table-7'!C49 | E50: ='[4]Table-7'!D49 | F50: ='[4]Table-7'!E49 | G50: ='[4]Table-7'!F49 | H50: ='[4]Table-7'!G49 | I50: ='[4]Table-7'!H49 | J50: ='[4]Table-7'!I49 | ... U50: ='[4]Table-7'!T49
A51: ='[4]Table-7'!A50 | C51: ='[4]Table-7'!B50 | D51: ='[4]Table-7'!C50 | E51: ='[4]Table-7'!D50 | F51: ='[4]Table-7'!E50 | G51: ='[4]Table-7'!F50 | H51: ='[4]Table-7'!G50 | I51: ='[4]Table-7'!H50 | J51: ='[4]Table-7'!I50 | ... U51: ='[4]Table-7'!T50
A52: ='[4]Table-7'!A51 | C52: ='[4]Table-7'!B51 | D52: ='[4]Table-7'!C51 | E52: ='[4]Table-7'!D51 | F52: ='[4]Table-7'!E51 | G52: ='[4]Table-7'!F51 | H52: ='[4]Table-7'!G51 | I52: ='[4]Table-7'!H51 | J52: ='[4]Table-7'!I51 | ... U52: ='[4]Table-7'!T51
A53: ='[4]Table-7'!A52 | C53: ='[4]Table-7'!B52 | D53: ='[4]Table-7'!C52 | E53: ='[4]Table-7'!D52 | F53: ='[4]Table-7'!E52 | G53: ='[4]Table-7'!F52 | H53: ='[4]Table-7'!G52 | I53: ='[4]Table-7'!H52 | J53: ='[4]Table-7'!I52 | ... U53: ='[4]Table-7'!T52
... A100: ='[4]Table-7'!A99 -> TOTAL: | C100: ='[4]Table-7'!B99 -> 339 | D100: ='[4]Table-7'!C99 -> 0 | E100: ='[4]Table-7'!D99 -> 0 | F100: ='[4]Table-7'!E99 -> 0 | G100: ='[4]Table-7'!F99 -> 0 | H100: ='[4]Table-7'!G99 -> 0 | I100: ='[4]Table-7'!H99 -> 0 | J100: ='[4]Table-7'!I99 -> 0 | ... U100: ='[4]Table-7'!T99 -> 0
A101: %AGE TO COL.(3) | D101: ='[4]Table-7'!C100 -> 0 | E101: ='[4]Table-7'!D100 -> 0 | F101: ='[4]Table-7'!E100 -> 0 | G101: ='[4]Table-7'!F100 -> 0 | H101: ='[4]Table-7'!G100 -> 0 | I101: ='[4]Table-7'!H100 -> 0 | J101: ='[4]Table-7'!I100 -> 0 | K101: ='[4]Table-7'!J100 -> 0 | ... U101: ='[4]Table-7'!T100 -> 0
A102: NOTE- (I) PERCENTAGE OF ALL COLUMNS EXCEPT COL.14 AND COL.15 ARE WITH THE REFERENCE TO COL.3
A103: (II) PERCENTAGE OF COL.14 AND COL.15 ARE WITH REFERENCE TO COL.13
A104: T-12
A105: TABLE A-7: DISTRICTWISE DISTRIBUTION OF SELECTED VILLAGES ACCORDING TO THE SUBMISSION OF TRS STATEMENT.
A106: =A3 -> STATE: GUJARAT | H106: YEAR: | I106: ='[4]Table-7'!AC2 -> 2024-25 | M106: SEASON: | O106: ='[4]Table-7'!AI2 -> SUMMER(5) | U106: ='RC1-A1'!$K$103 -> SAMPLE: STATE
...

Sheet RC1-A14
A1: T-13
A2: TABLE A-14: DISTRICTWISE DISTRIBUTION OF SAMPLE VILLAGES FOR WHICH THE AREAS UNDER CROPS ARE NOT AVAILABLE FOR PREVIOUS/CURRENT YEAR.
A3: =info!$E$2 -> STATE: GUJARAT | I3: YEAR: | K3: ='[1]Table-14'!J3 -> 2024-25 | O3: SEASON: | Q3: ='[1]Table-14'!P3 -> RABI(4) | Y3: ='RC1-A1'!$K$3 -> SAMPLE: CENTRAL
A4: DISTRICT | B4: DISTRICT NAME | C4: NO. OF VILLAGE ANALYSED | D4: NO.OF VILLAGES FOR WHICH AREA FIGURES FOR PREVIOUS YEAR ARE NOT AVAILABLE | R4: NO.OF VILLAGES FOR WHICH AREA FIGURES ARE NOT AVAILABLE FOR CURRENT YEAR FOR THE REASONS@
D6: FOR SELECTED CLUSTERS FOR THE REASONS@ | J6: FOR VILLAGES AS A WHOLE FOR THE REASONS@
D8: 0 | E8: 1 | F8: 2 | G8: 4 | H8: 6 | I8: 8 | J8: 0 | K8: 1 | L8: 2 | M8: 3 | N8: 4 | O8: 6 | P8: 7 | Q8: 8 | R8: 0 | S8: 1 | T8: 2 | U8: 3 | V8: 4 | W8: 6 | X8: 7 | Y8: 8
A9: 1 | B9: 2 | C9: 3 | D9: 4 | E9: 5 | F9: 6 | G9: 7 | H9: 8 | I9: 9 | J9: 10 | K9: 11 | L9: 12 | M9: 13 | N9: 14 | O9: 15 | P9: 16 | Q9: 17 | R9: 18 | S9: 19 | T9: 20 | U9: 21 | V9: 22 | W9: 23 | X9: 24 | Y9: 25
A10: ='[1]Table-14'!A10 -> 1 | B10: KACHCHH | C10: ='[1]Table-14'!B10 -> 18 | D10: ='[1]Table-14'!C10 -> 0 | E10: ='[1]Table-14'!D10 -> 0 | F10: ='[1]Table-14'!E10 -> 0 | G10: ='[1]Table-14'!F10 -> 18 | H10: ='[1]Table-14'!G10 -> 0 | I10: ='[1]Table-14'!H10 -> 0 | J10: ='[1]Table-14'!I10 -> 0 | ... Y10: ='[1]Table-14'!X10 -> 0
A11: ='[1]Table-14'!A11 -> 2 | B11: BANASKANTHA | C11: ='[1]Table-14'!B11 -> 30 | D11: ='[1]Table-14'!C11 -> 0 | E11: ='[1]Table-14'!D11 -> 0 | F11: ='[1]Table-14'!E11 -> 0 | G11: ='[1]Table-14'!F11 -> 30 | H11: ='[1]Table-14'!G11 -> 0 | I11: ='[1]Table-14'!H11 -> 0 | J11: ='[1]Table-14'!I11 -> 0 | ... Y11: ='[1]Table-14'!X11 -> 0
