Workbook

Sheet Basicdata
A1: ='[1]RC-1(PY)'!A1 -> RC | B1: ='[1]RC-1(PY)'!B1 -> ST | C1: ='[1]RC-1(PY)'!C1 -> YR | D1: ='[1]RC-1(PY)'!D1 -> SESON | E1: ='[1]RC-1(PY)'!E1 -> NOVP | F1: ='[1]RC-1(PY)'!F1 -> NOVCOD | G1: ='[1]RC-1(PY)'!G1 -> STAT | H1: ='[1]RC-1(PY)'!H1 -> DIST | ... AI1: ='[1]RC-1(PY)'!AI1 -> REJ
A2: ='[1]RC-1(PY)'!A2 -> 1 | B2: ='[1]RC-1(PY)'!B2 -> 1 | C2: ='[1]RC-1(PY)'!C2 -> 2024 | D2: ='[1]RC-1(PY)'!D2 -> 4 | E2: ='[1]RC-1(PY)'!E2 -> 340 | F2: ='[1]RC-1(PY)'!F2 -> 320 | G2: ='[1]RC-1(PY)'!G2 -> 24 | H2: ='[1]RC-1(PY)'!H2 -> 1 | ... AI2: ='[1]RC-1(PY)'!AI2 -> 0
A3: ='[1]RC-1(PY)'!A3 -> 1 | B3: ='[1]RC-1(PY)'!B3 -> 1 | C3: ='[1]RC-1(PY)'!C3 -> 2024 | D3: ='[1]RC-1(PY)'!D3 -> 4 | E3: ='[1]RC-1(PY)'!E3 -> 340 | F3: ='[1]RC-1(PY)'!F3 -> 320 | G3: ='[1]RC-1(PY)'!G3 -> 24 | H3: ='[1]RC-1(PY)'!H3 -> 2 | ... AI3: ='[1]RC-1(PY)'!AI3 -> 0
A4: ='[1]RC-1(PY)'!A4 -> 1 | B4: ='[1]RC-1(PY)'!B4 -> 1 | C4: ='[1]RC-1(PY)'!C4 -> 2024 | D4: ='[1]RC-1(PY)'!D4 -> 4 | E4: ='[1]RC-1(PY)'!E4 -> 340 | F4: ='[1]RC-1(PY)'!F4 -> 320 | G4: ='[1]RC-1(PY)'!G4 -> 24 | H4: ='[1]RC-1(PY)'!H4 -> 3 | ... AI4: ='[1]RC-1(PY)'!AI4 -> 0
A5: ='[1]RC-1(PY)'!A5 -> 1 | B5: ='[1]RC-1(PY)'!B5 -> 1 | C5: ='[1]RC-1(PY)'!C5 -> 2024 | D5: ='[1]RC-1(PY)'!D5 -> 4 | E5: ='[1]RC-1(PY)'!E5 -> 340 | F5: ='[1]RC-1(PY)'!F5 -> 320 | G5: ='[1]RC-1(PY)'!G5 -> 24 | H5: ='[1]RC-1(PY)'!H5 -> 4 | ... AI5: ='[1]RC-1(PY)'!AI5 -> 0
A6: ='[1]RC-1(PY)'!A6 -> 1 | B6: ='[1]RC-1(PY)'!B6 -> 1 | C6: ='[1]RC-1(PY)'!C6 -> 2024 | D6: ='[1]RC-1(PY)'!D6 -> 4 | E6: ='[1]RC-1(PY)'!E6 -> 340 | F6: ='[1]RC-1(PY)'!F6 -> 320 | G6: ='[1]RC-1(PY)'!G6 -> 24 | H6: ='[1]RC-1(PY)'!H6 -> 5 | ... AI6: ='[1]RC-1(PY)'!AI6 -> 0
A7: ='[1]RC-1(PY)'!A7 -> 1 | B7: ='[1]RC-1(PY)'!B7 -> 1 | C7: ='[1]RC-1(PY)'!C7 -> 2024 | D7: ='[1]RC-1(PY)'!D7 -> 4 | E7: ='[1]RC-1(PY)'!E7 -> 340 | F7: ='[1]RC-1(PY)'!F7 -> 320 | G7: ='[1]RC-1(PY)'!G7 -> 24 | H7: ='[1]RC-1(PY)'!H7 -> 7 | ... AI7: ='[1]RC-1(PY)'!AI7 -> 0
A8: ='[1]RC-1(PY)'!A8 -> 1 | B8: ='[1]RC-1(PY)'!B8 -> 1 | C8: ='[1]RC-1(PY)'!C8 -> 2024 | D8: ='[1]RC-1(PY)'!D8 -> 4 | E8: ='[1]RC-1(PY)'!E8 -> 340 | F8: ='[1]RC-1(PY)'!F8 -> 320 | G8: ='[1]RC-1(PY)'!G8 -> 24 | H8: ='[1]RC-1(PY)'!H8 -> 8 | ... AI8: ='[1]RC-1(PY)'!AI8 -> 0
A9: ='[1]RC-1(PY)'!A9 -> 1 | B9: ='[1]RC-1(PY)'!B9 -> 1 | C9: ='[1]RC-1(PY)'!C9 -> 2024 | D9: ='[1]RC-1(PY)'!D9 -> 4 | E9: ='[1]RC-1(PY)'!E9 -> 340 | F9: ='[1]RC-1(PY)'!F9 -> 320 | G9: ='[1]RC-1(PY)'!G9 -> 24 | H9: ='[1]RC-1(PY)'!H9 -> 9 | ... AI9: ='[1]RC-1(PY)'!AI9 -> 0
A10: ='[1]RC-1(PY)'!A10 -> 1 | B10: ='[1]RC-1(PY)'!B10 -> 1 | C10: ='[1]RC-1(PY)'!C10 -> 2024 | D10: ='[1]RC-1(PY)'!D10 -> 4 | E10: ='[1]RC-1(PY)'!E10 -> 340 | F10: ='[1]RC-1(PY)'!F10 -> 320 | G10: ='[1]RC-1(PY)'!G10 -> 24 | H10: ='[1]RC-1(PY)'!H10 -> 10 | ... AI10: ='[1]RC-1(PY)'!AI10 -> 0
A11: ='[1]RC-1(PY)'!A11 -> 1 | B11: ='[1]RC-1(PY)'!B11 -> 1 | C11: ='[1]RC-1(PY)'!C11 -> 2024 | D11: ='[1]RC-1(PY)'!D11 -> 4 | E11: ='[1]RC-1(PY)'!E11 -> 340 | F11: ='[1]RC-1(PY)'!F11 -> 320 | G11: ='[1]RC-1(PY)'!G11 -> 24 | H11: ='[1]RC-1(PY)'!H11 -> 11 | ... AI11: ='[1]RC-1(PY)'!AI11 -> 0
A12: ='[1]RC-1(PY)'!A12 -> 1 | B12: ='[1]RC-1(PY)'!B12 -> 1 | C12: ='[1]RC-1(PY)'!C12 -> 2024 | D12: ='[1]RC-1(PY)'!D12 -> 4 | E12: ='[1]RC-1(PY)'!E12 -> 340 | F12: ='[1]RC-1(PY)'!F12 -> 320 | G12: ='[1]RC-1(PY)'!G12 -> 24 | H12: ='[1]RC-1(PY)'!H12 -> 12 | ... AI12: ='[1]RC-1(PY)'!AI12 -> 0
... A2500: ='[1]RC-1(PY)'!A2500 -> 0 | B2500: ='[1]RC-1(PY)'!B2500 -> 0 | C2500: ='[1]RC-1(PY)'!C2500 -> 0 | D2500: ='[1]RC-1(PY)'!D2500 -> 0 | E2500: ='[1]RC-1(PY)'!E2500 -> 0 | F2500: ='[1]RC-1(PY)'!F2500 -> 0 | G2500: ='[1]RC-1(PY)'!G2500 -> 0 | H2500: ='[1]RC-1(PY)'!H2500 -> 0 | ... AI2500: ='[1]RC-1(PY)'!AI2500 -> 0

Sheet Crops
A1: ='[1]Crops(PY)'!A1 -> STATE | B1: ='[1]Crops(PY)'!B1 -> Code | C1: ='[1]Crops(PY)'!C1 -> Sample Type | D1: ='[1]Crops(PY)'!D1 -> code | M1: =[2]Crops!M1 -> District
A2: ='[1]Crops(PY)'!A2 -> GUJARAT | B2: ='[1]Crops(PY)'!B2 -> 24 | C2: ='[1]Crops(PY)'!C2 -> CENTRAL | D2: ='[1]Crops(PY)'!D2 -> 1 | F2: Don't cut/delete the cell | M2: =[2]Crops!M2 -> 1
A3: ='[1]Crops(PY)'!A3 -> YEAR | B3: ='[1]Crops(PY)'!B3 -> 2023-24 | C3: ='[1]Crops(PY)'!C3 -> STATE | D3: ='[1]Crops(PY)'!D3 -> 2 | M3: =[2]Crops!M3 -> 2
A4: ='[1]Crops(PY)'!A4 -> Season | B4: ='[1]Crops(PY)'!B4 -> code | C4: ='[1]Crops(PY)'!C4 -> Season | D4: ='[1]Crops(PY)'!D4 -> code | M4: =[2]Crops!M4 -> 3
A5: ='[1]Crops(PY)'!A5 -> RABI | B5: ='[1]Crops(PY)'!B5 -> 4 | C5: ='[1]Crops(PY)'!C5 -> SUMMER | D5: ='[1]Crops(PY)'!D5 -> 5 | M5: =[2]Crops!M5 -> 4
A6: ='[1]Crops(PY)'!A6 -> Crop | B6: ='[1]Crops(PY)'!B6 -> Code | C6: ='[1]Crops(PY)'!C6 -> Crop | D6: ='[1]Crops(PY)'!D6 -> Code | M6: =[2]Crops!M6 -> 5
A7: ='[1]Crops(PY)'!A7 -> WHEAT | B7: ='[1]Crops(PY)'!B7 -> 8 | C7: ='[1]Crops(PY)'!C7 -> OTHERS | D7: ='[1]Crops(PY)'!D7 -> 99 | M7: =[2]Crops!M7 -> 6
A8: ='[1]Crops(PY)'!A8 -> GRAM | B8: ='[1]Crops(PY)'!B8 -> 10 | C8: ='[1]Crops(PY)'!C8 -> 0 | D8: ='[1]Crops(PY)'!D8 -> 0 | M8: =[2]Crops!M8 -> 7
A9: ='[1]Crops(PY)'!A9 -> R&M | B9: ='[1]Crops(PY)'!B9 -> 17 | C9: ='[1]Crops(PY)'!C9 -> 0 | D9: ='[1]Crops(PY)'!D9 -> 0 | M9: =[2]Crops!M9 -> 8
A10: ='[1]Crops(PY)'!A10 -> OTHERS | B10: ='[1]Crops(PY)'!B10 -> 99 | C10: ='[1]Crops(PY)'!C10 -> 0 | D10: ='[1]Crops(PY)'!D10 -> 0 | M10: =[2]Crops!M10 -> 9
A11: ='[1]Crops(PY)'!A11 -> 0 | B11: ='[1]Crops(PY)'!B11 -> 0 | C11: ='[1]Crops(PY)'!C11 -> 0 | D11: ='[1]Crops(PY)'!D11 -> 0 | M11: =[2]Crops!M11 -> 10
A12: ='[1]Crops(PY)'!A12 -> 0 | B12: ='[1]Crops(PY)'!B12 -> 0 | C12: ='[1]Crops(PY)'!C12 -> 0 | D12: ='[1]Crops(PY)'!D12 -> 0 | M12: =[2]Crops!M12 -> 11
A13: ='[1]Crops(PY)'!A13 -> 0 | B13: ='[1]Crops(PY)'!B13 -> 0 | C13: ='[1]Crops(PY)'!C13 -> 0 | D13: ='[1]Crops(PY)'!D13 -> 0 | M13: =[2]Crops!M13 -> 12
A14: ='[1]Crops(PY)'!A14 -> 0 | B14: ='[1]Crops(PY)'!B14 -> 0 | C14: ='[1]Crops(PY)'!C14 -> 0 | D14: ='[1]Crops(PY)'!D14 -> 0 | M14: =[2]Crops!M14 -> 13
... A21: ='[1]Crops(PY)'!A21 -> 0 | B21: ='[1]Crops(PY)'!B21 -> 0 | C21: ='[1]Crops(PY)'!C21 -> 0 | D21: ='[1]Crops(PY)'!D21 -> 0 | M21: =[2]Crops!M21 -> 20
M22: =[2]Crops!M22 -> 21
M23: =[2]Crops!M23 -> 22
M24: =[2]Crops!M24 -> 23
M25: =[2]Crops!M25 -> 24
M26: =[2]Crops!M26 -> 25
M27: =[2]Crops!M27 -> 26
M28: =[2]Crops!M28 -> 27
M29: =[2]Crops!M29 -> 28
M30: =[2]Crops!M30 -> 29
M31: =[2]Crops!M31 -> 30
M32: =[2]Crops!M32 -> 31
M33: =[2]Crops!M33 -> 32
... M219: =[2]Crops!M219 -> 218

Sheet Table-1
A2: TABLE :A-1 : DISTRICTWISE DISTRIBUTION OF SELECTED VILLAGES FOR CHECK ON ENUMERATION OF AREA AND RESPONSE ACHIEVED. | L2: TABLE :A-1 : DISTRICTWISE DISTRIBUTION OF SELECTED VILLAGES FOR CHECK ON ENUMERATION OF AREA AND RESPONSE ACHIEVED.
A3: STATE: | B3: =Crops!$A$2&"("&Crops!$B$2&")" -> GUJARAT(24) | D3: YEAR: | E3: =Crops!$B$3 -> 2023-24 | F3: SEASON: | G3: =Crops!$C$5&"("&Crops!$D$5&")" -> SUMMER(5) | H3: SAMPLE: | I3: ="CENTRAL"&"("&1&")" -> CENTRAL(1) | L3: STATE: | M3: =Crops!$A$2&"("&Crops!$B$2&")" -> GUJARAT(24) | O3: YEAR: | P3: =Crops!$B$3 -> 2023-24 | Q3: SEASON: | R3: =Crops!$C$5&"("&Crops!$D$5&")" -> SUMMER(5) | S3: SAMPLE: | T3: ="STATE"&"("&2&")" -> STATE(2)
A4: DISTRICT | B4: NO.OF VILLAGES FOR WHICH SCHEDULE AS 1.0 RECEIVED | C4: NO. OF VILLAGES FOR WHICH SCHEDULE AS 1.0 IS ANALYSED | G4: PERCENTAGE RESPONSE TO COL.(2) | L4: DISTRICT | M4: NO.OF VILLAGES FOR WHICH SCHEDULE AS 1.0 RECEIVED | N4: NO. OF VILLAGES FOR WHICH SCHEDULE AS 1.0 IS ANALYSED | R4: PERCENTAGE RESPONSE TO COL.(2)
C5: WITH 'a' AND 'b' ENTRIES TOGETHER | D5: WITH 'a' AND 'b' ENTRIES SEPARATELY | E5: WITH 'a' ENTRIES ONLY | F5: TOTAL | G5: WITH 'a' AND 'b' ENTRIES TOGETHER | H5: WITH 'a' AND 'b' ENTRIES SEPARATELY | I5: WITH 'a' ENTRIES ONLY | J5: TOTAL | N5: WITH 'a' AND 'b' ENTRIES TOGETHER | O5: WITH 'a' AND 'b' ENTRIES SEPARATELY | P5: WITH 'a' ENTRIES ONLY | Q5: TOTAL | R5: WITH 'a' AND 'b' ENTRIES TOGETHER | S5: WITH 'a' AND 'b' ENTRIES SEPARATELY | T5: WITH 'a' ENTRIES ONLY | U5: TOTAL
A10: 1 | B10: 2 | C10: 3 | D10: 4 | E10: 5 | F10: 7 | G10: 8 | H10: 9 | I10: 10 | J10: 11 | L10: 1 | M10: 2 | N10: 3 | O10: 4 | P10: 5 | Q10: 7 | R10: 8 | S10: 9 | T10: 10 | U10: 11
A11: =IF(COUNTIFS(Basicdata!$B$2:$B$2500,1,Basicdata!$D$2:$D$2500,Crops!$D$5,Basicdata!$H$2:$H$2500,Crops!$M2)>0,Crops!$M2,"") -> 1 | B11: =IF(A11="","",COUNTIFS(Basicdata!$B$2:$B$2500,1,Basicdata!$D$2:$D$2500,Crops!$D$5,Basicdata!$H$2:$H$2500,Crops!$M2)) -> 17 | C11: =IF(A11="","",COUNTIFS(Basicdata!$B$2:$B$2500,1,Basicdata!$D$2:$D$2500,Crops!$D$5,Basicdata!$H$2:$H$2500,Crops!$M2,Basicdata!$K$2:$K$2500,1,Basicdata!$AI$2:$AI$2500,0)) -> 0 | D11: =IF(A11="","",COUNTIFS(Basicdata!$B$2:$B$2500,1,Basicdata!$D$2:$D$2500,Crops!$D$5,Basicdata!$H$2:$H$2500,Crops!$M2,Basicdata!$K$2:$K$2500,2,Basicdata!$AI$2:$AI$2500,0)) -> 0 | E11: =IF(A11="","",COUNTIFS(Basicdata!$B$2:$B$2500,1,Basicdata!$D$2:$D$2500,Crops!$D$5,Basicdata!$H$2:$H$2500,Crops!$M2,Basicdata!$K$2:$K$2500,3,Basicdata!$AI$2:$AI$2500,0)) -> 17 | F11: =IF(A11="","",C11+D11+E11) -> 17 | G11: =IF(OR(F11="",F11=0),"",C11*100/B11) -> 0 | H11: =IF(OR(F11="",F11=0),"",D11*100/B11) -> 0 | I11: =IF(OR(F11="",F11=0),"",J11-G11-H11) -> 100 | J11: =IF(OR(F11="",F11=0),"",F11*100/B11) -> 100 | L11: =IF(COUNTIFS(Basicdata!$B$2:$B$2500,2,Basicdata!$D$2:$D$2500,Crops!$D$5,Basicdata!$H$2:$H$2500,Crops!$M2)>0,Crops!$M2,"") -> 1 | M11: =IF(L11="","",COUNTIFS(Basicdata!$B$2:$B$2500,2,Basicdata!$D$2:$D$2500,Crops!$D$5,Basicdata!$H$2:$H$2500,Crops!$M2)) -> 17 | N11: =IF(L11="","",COUNTIFS(Basicdata!$B$2:$B$2500,2,Basicdata!$D$2:$D$2500,Crops!$D$5,Basicdata!$H$2:$H$2500,Crops!$M2,Basicdata!$K$2:$K$2500,1,Basicdata!$AI$2:$AI$2500,0)) -> 0 | O11: =IF(L11="","",COUNTIFS(Basicdata!$B$2:$B$2500,2,Basicdata!$D$2:$D$2500,Crops!$D$5,Basicdata!$H$2:$H$2500,Crops!$M2,Basicdata!$K$2:$K$2500,2,Basicdata!$AI$2:$AI$2500,0)) -> 0 | P11: =IF(L11="","",COUNTIFS(Basicdata!$B$2:$B$2500,2,Basicdata!$D$2:$D$2500,Crops!$D$5,Basicdata!$H$2:$H$2500,Crops!$M2,Basicdata!$K$2:$K$2500,3,Basicdata!$AI$2:$AI$2500,0)) -> 17 | Q11: =IF(L11="","",N11+O11+P11) -> 17 | R11: =IF(OR(Q11="",Q11=0),"",N11*100/M11) -> 0 | S11: =IF(OR(Q11="",Q11=0),"",O11*100/M11) -> 0 | T11: =IF(OR(Q11="",Q11=0),"",U11-R11-S11) -> 100 | U11: =IF(OR(Q11="",Q11=0),"",Q11*100/M11) -> 100
A12: =IF(COUNTIFS(Basicdata!$B$2:$B$2500,1,Basicdata!$D$2:$D$2500,Crops!$D$5,Basicdata!$H$2:$H$2500,Crops!$M3)>0,Crops!$M3,"") -> 2 | B12: =IF(A12="","",COUNTIFS(Basicdata!$B$2:$B$2500,1,Basicdata!$D$2:$D$2500,Crops!$D$5,Basicdata!$H$2:$H$2500,Crops!$M3)) -> 33 | C12: =IF(A12="","",COUNTIFS(Basicdata!$B$2:$B$2500,1,Basicdata!$D$2:$D$2500,Crops!$D$5,Basicdata!$H$2:$H$2500,Crops!$M3,Basicdata!$K$2:$K$2500,1,Basicdata!$AI$2:$AI$2500,0)) -> 0 | D12: =IF(A12="","",COUNTIFS(Basicdata!$B$2:$B$2500,1,Basicdata!$D$2:$D$2500,Crops!$D$5,Basicdata!$H$2:$H$2500,Crops!$M3,Basicdata!$K$2:$K$2500,2,Basicdata!$AI$2:$AI$2500,0)) -> 0 | E12: =IF(A12="","",COUNTIFS(Basicdata!$B$2:$B$2500,1,Basicdata!$D$2:$D$2500,Crops!$D$5,Basicdata!$H$2:$H$2500,Crops!$M3,Basicdata!$K$2:$K$2500,3,Basicdata!$AI$2:$AI$2500,0)) -> 32 | F12: =IF(A12="","",C12+D12+E12) -> 32 | G12: =IF(OR(F12="",F12=0),"",C12*100/B12) -> 0 | H12: =IF(OR(F12="",F12=0),"",D12*100/B12) -> 0 | I12: =IF(OR(F12="",F12=0),"",J12-G12-H12) -> 96.969697 | J12: =IF(OR(F12="",F12=0),"",F12*100/B12) -> 96.969697 | L12: =IF(COUNTIFS(Basicdata!$B$2:$B$2500,2,Basicdata!$D$2:$D$2500,Crops!$D$5,Basicdata!$H$2:$H$2500,Crops!$M3)>0,Crops!$M3,"") -> 2 | M12: =IF(L12="","",COUNTIFS(Basicdata!$B$2:$B$2500,2,Basicdata!$D$2:$D$2500,Crops!$D$5,Basicdata!$H$2:$H$2500,Crops!$M3)) -> 33 | N12: =IF(L12="","",COUNTIFS(Basicdata!$B$2:$B$2500,2,Basicdata!$D$2:$D$2500,Crops!$D$5,Basicdata!$H$2:$H$2500,Crops!$M3,Basicdata!$K$2:$K$2500,1,Basicdata!$AI$2:$AI$2500,0)) -> 0 | O12: =IF(L12="","",COUNTIFS(Basicdata!$B$2:$B$2500,2,Basicdata!$D$2:$D$2500,Crops!$D$5,Basicdata!$H$2:$H$2500,Crops!$M3,Basicdata!$K$2:$K$2500,2,Basicdata!$AI$2:$AI$2500,0)) -> 0 | P12: =IF(L12="","",COUNTIFS(Basicdata!$B$2:$B$2500,2,Basicdata!$D$2:$D$2500,Crops!$D$5,Basicdata!$H$2:$H$2500,Crops!$M3,Basicdata!$K$2:$K$2500,3,Basicdata!$AI$2:$AI$2500,0)) -> 33 | Q12: =IF(L12="","",N12+O12+P12) -> 33 | R12: =IF(OR(Q12="",Q12=0),"",N12*100/M12) -> 0 | S12: =IF(OR(Q12="",Q12=0),"",O12*100/M12) -> 0 | T12: =IF(OR(Q12="",Q12=0),"",U12-R12-S12) -> 100 | U12: =IF(OR(Q12="",Q12=0),"",Q12*100/M12) -> 100
A13: =IF(COUNTIFS(Basicdata!$B$2:$B$2500,1,Basicdata!$D$2:$D$2500,Crops!$D$5,Basicdata!$H$2:$H$2500,Crops!$M4)>0,Crops!$M4,"") -> 3 | B13: =IF(A13="","",COUNTIFS(Basicdata!$B$2:$B$2500,1,Basicdata!$D$2:$D$2500,Crops!$D$5,Basicdata!$H$2:$H$2500,Crops!$M4)) -> 18 | C13: =IF(A13="","",COUNTIFS(Basicdata!$B$2:$B$2500,1,Basicdata!$D$2:$D$2500,Crops!$D$5,Basicdata!$H$2:$H$2500,Crops!$M4,Basicdata!$K$2:$K$2500,1,Basicdata!$AI$2:$AI$2500,0)) -> 0 | D13: =IF(A13="","",COUNTIFS(Basicdata!$B$2:$B$2500,1,Basicdata!$D$2:$D$2500,Crops!$D$5,Basicdata!$H$2:$H$2500,Crops!$M4,Basicdata!$K$2:$K$2500,2,Basicdata!$AI$2:$AI$2500,0)) -> 0 | E13: =IF(A13="","",COUNTIFS(Basicdata!$B$2:$B$2500,1,Basicdata!$D$2:$D$2500,Crops!$D$5,Basicdata!$H$2:$H$2500,Crops!$M4,Basicdata!$K$2:$K$2500,3,Basicdata!$AI$2:$AI$2500,0)) -> 18 | F13: =IF(A13="","",C13+D13+E13) -> 18 | G13: =IF(OR(F13="",F13=0),"",C13*100/B13) -> 0 | H13: =IF(OR(F13="",F13=0),"",D13*100/B13) -> 0 | I13: =IF(OR(F13="",F13=0),"",J13-G13-H13) -> 100 | J13: =IF(OR(F13="",F13=0),"",F13*100/B13) -> 100 | L13: =IF(COUNTIFS(Basicdata!$B$2:$B$2500,2,Basicdata!$D$2:$D$2500,Crops!$D$5,Basicdata!$H$2:$H$2500,Crops!$M4)>0,Crops!$M4,"") -> 3 | M13: =IF(L13="","",COUNTIFS(Basicdata!$B$2:$B$2500,2,Basicdata!$D$2:$D$2500,Crops!$D$5,Basicdata!$H$2:$H$2500,Crops!$M4)) -> 18 | N13: =IF(L13="","",COUNTIFS(Basicdata!$B$2:$B$2500,2,Basicdata!$D$2:$D$2500,Crops!$D$5,Basicdata!$H$2:$H$2500,Crops!$M4,Basicdata!$K$2:$K$2500,1,Basicdata!$AI$2:$AI$2500,0)) -> 0 | O13: =IF(L13="","",COUNTIFS(Basicdata!$B$2:$B$2500,2,Basicdata!$D$2:$D$2500,Crops!$D$5,Basicdata!$H$2:$H$2500,Crops!$M4,Basicdata!$K$2:$K$2500,2,Basicdata!$AI$2:$AI$2500,0)) -> 0 | P13: =IF(L13="","",COUNTIFS(Basicdata!$B$2:$B$2500,2,Basicdata!$D$2:$D$2500,Crops!$D$5,Basicdata!$H$2:$H$2500,Crops!$M4,Basicdata!$K$2:$K$2500,3,Basicdata!$AI$2:$AI$2500,0)) -> 18 | Q13: =IF(L13="","",N13+O13+P13) -> 18 | R13: =IF(OR(Q13="",Q13=0),"",N13*100/M13) -> 0 | S13: =IF(OR(Q13="",Q13=0),"",O13*100/M13) -> 0 | T13: =IF(OR(Q13="",Q13=0),"",U13-R13-S13) -> 100 | U13: =IF(OR(Q13="",Q13=0),"",Q13*100/M13) -> 100
A14: =IF(COUNTIFS(Basicdata!$B$2:$B$2500,1,Basicdata!$D$2:$D$2500,Crops!$D$5,Basicdata!$H$2:$H$2500,Crops!$M5)>0,Crops!$M5,"") -> 4 | B14: =IF(A14="","",COUNTIFS(Basicdata!$B$2:$B$2500,1,Basicdata!$D$2:$D$2500,Crops!$D$5,Basicdata!$H$2:$H$2500,Crops!$M5)) -> 14 | C14: =IF(A14="","",COUNTIFS(Basicdata!$B$2:$B$2500,1,Basicdata!$D$2:$D$2500,Crops!$D$5,Basicdata!$H$2:$H$2500,Crops!$M5,Basicdata!$K$2:$K$2500,1,Basicdata!$AI$2:$AI$2500,0)) -> 0 | D14: =IF(A14="","",COUNTIFS(Basicdata!$B$2:$B$2500,1,Basicdata!$D$2:$D$2500,Crops!$D$5,Basicdata!$H$2:$H$2500,Crops!$M5,Basicdata!$K$2:$K$2500,2,Basicdata!$AI$2:$AI$2500,0)) -> 0 | E14: =IF(A14="","",COUNTIFS(Basicdata!$B$2:$B$2500,1,Basicdata!$D$2:$D$2500,Crops!$D$5,Basicdata!$H$2:$H$2500,Crops!$M5,Basicdata!$K$2:$K$2500,3,Basicdata!$AI$2:$AI$2500,0)) -> 14 | F14: =IF(A14="","",C14+D14+E14) -> 14 | G14: =IF(OR(F14="",F14=0),"",C14*100/B14) -> 0 | H14: =IF(OR(F14="",F14=0),"",D14*100/B14) -> 0 | I14: =IF(OR(F14="",F14=0),"",J14-G14-H14) -> 100 | J14: =IF(OR(F14="",F14=0),"",F14*100/B14) -> 100 | L14: =IF(COUNTIFS(Basicdata!$B$2:$B$2500,2,Basicdata!$D$2:$D$2500,Crops!$D$5,Basicdata!$H$2:$H$2500,Crops!$M5)>0,Crops!$M5,"") -> 4 | M14: =IF(L14="","",COUNTIFS(Basicdata!$B$2:$B$2500,2,Basicdata!$D$2:$D$2500,Crops!$D$5,Basicdata!$H$2:$H$2500,Crops!$M5)) -> 14 | N14: =IF(L14="","",COUNTIFS(Basicdata!$B$2:$B$2500,2,Basicdata!$D$2:$D$2500,Crops!$D$5,Basicdata!$H$2:$H$2500,Crops!$M5,Basicdata!$K$2:$K$2500,1,Basicdata!$AI$2:$AI$2500,0)) -> 0 | O14: =IF(L14="","",COUNTIFS(Basicdata!$B$2:$B$2500,2,Basicdata!$D$2:$D$2500,Crops!$D$5,Basicdata!$H$2:$H$2500,Crops!$M5,Basicdata!$K$2:$K$2500,2,Basicdata!$AI$2:$AI$2500,0)) -> 0 | P14: =IF(L14="","",COUNTIFS(Basicdata!$B$2:$B$2500,2,Basicdata!$D$2:$D$2500,Crops!$D$5,Basicdata!$H$2:$H$2500,Crops!$M5,Basicdata!$K$2:$K$2500,3,Basicdata!$AI$2:$AI$2500,0)) -> 14 | Q14: =IF(L14="","",N14+O14+P14) -> 14 | R14: =IF(OR(Q14="",Q14=0),"",N14*100/M14) -> 0 | S14: =IF(OR(Q14="",Q14=0),"",O14*100/M14) -> 0 | T14: =IF(OR(Q14="",Q14=0),"",U14-R14-S14) -> 100 | U14: =IF(OR(Q14="",Q14=0),"",Q14*100/M14) -> 100
A15: =IF(COUNTIFS(Basicdata!$B$2:$B$2500,1,Basicdata!$D$2:$D$2500,Crops!$D$5,Basicdata!$H$2:$H$2500,Crops!$M6)>0,Crops!$M6,"") -> 5 | B15: =IF(A15="","",COUNTIFS(Basicdata!$B$2:$B$2500,1,Basicdata!$D$2:$D$2500,Crops!$D$5,Basicdata!$H$2:$H$2500,Crops!$M6)) -> 10 | C15: =IF(A15="","",COUNTIFS(Basicdata!$B$2:$B$2500,1,Basicdata!$D$2:$D$2500,Crops!$D$5,Basicdata!$H$2:$H$2500,Crops!$M6,Basicdata!$K$2:$K$2500,1,Basicdata!$AI$2:$AI$2500,0)) -> 0 | D15: =IF(A15="","",COUNTIFS(Basicdata!$B$2:$B$2500,1,Basicdata!$D$2:$D$2500,Crops!$D$5,Basicdata!$H$2:$H$2500,Crops!$M6,Basicdata!$K$2:$K$2500,2,Basicdata!$AI$2:$AI$2500,0)) -> 0 | E15: =IF(A15="","",COUNTIFS(Basicdata!$B$2:$B$2500,1,Basicdata!$D$2:$D$2500,Crops!$D$5,Basicdata!$H$2:$H$2500,Crops!$M6,Basicdata!$K$2:$K$2500,3,Basicdata!$AI$2:$AI$2500,0)) -> 10 | F15: =IF(A15="","",C15+D15+E15) -> 10 | G15: =IF(OR(F15="",F15=0),"",C15*100/B15) -> 0 | H15: =IF(OR(F15="",F15=0),"",D15*100/B15) -> 0 | I15: =IF(OR(F15="",F15=0),"",J15-G15-H15) -> 100 | J15: =IF(OR(F15="",F15=0),"",F15*100/B15) -> 100 | L15: =IF(COUNTIFS(Basicdata!$B$2:$B$2500,2,Basicdata!$D$2:$D$2500,Crops!$D$5,Basicdata!$H$2:$H$2500,Crops!$M6)>0,Crops!$M6,"") -> 5 | M15: =IF(L15="","",COUNTIFS(Basicdata!$B$2:$B$2500,2,Basicdata!$D$2:$D$2500,Crops!$D$5,Basicdata!$H$2:$H$2500,Crops!$M6)) -> 10 | N15: =IF(L15="","",COUNTIFS(Basicdata!$B$2:$B$2500,2,Basicdata!$D$2:$D$2500,Crops!$D$5,Basicdata!$H$2:$H$2500,Crops!$M6,Basicdata!$K$2:$K$2500,1,Basicdata!$AI$2:$AI$2500,0)) -> 0 | O15: =IF(L15="","",COUNTIFS(Basicdata!$B$2:$B$2500,2,Basicdata!$D$2:$D$2500,Crops!$D$5,Basicdata!$H$2:$H$2500,Crops!$M6,Basicdata!$K$2:$K$2500,2,Basicdata!$AI$2:$AI$2500,0)) -> 0 | P15: =IF(L15="","",COUNTIFS(Basicdata!$B$2:$B$2500,2,Basicdata!$D$2:$D$2500,Crops!$D$5,Basicdata!$H$2:$H$2500,Crops!$M6,Basicdata!$K$2:$K$2500,3,Basicdata!$AI$2:$AI$2500,0)) -> 10 | Q15: =IF(L15="","",N15+O15+P15) -> 10 | R15: =IF(OR(Q15="",Q15=0),"",N15*100/M15) -> 0 | S15: =IF(OR(Q15="",Q15=0),"",O15*100/M15) -> 0 | T15: =IF(OR(Q15="",Q15=0),"",U15-R15-S15) -> 100 | U15: =IF(OR(Q15="",Q15=0),"",Q15*100/M15) -> 100
A16: =IF(COUNTIFS(Basicdata!$B$2:$B$2500,1,Basicdata!$D$2:$D$2500,Crops!$D$5,Basicdata!$H$2:$H$2500,Crops!$M7)>0,Crops!$M7,"") -> 6 | B16: =IF(A16="","",COUNTIFS(Basicdata!$B$2:$B$2500,1,Basicdata!$D$2:$D$2500,Crops!$D$5,Basicdata!$H$2:$H$2500,Crops!$M7)) -> 8 | C16: =IF(A16="","",COUNTIFS(Basicdata!$B$2:$B$2500,1,Basicdata!$D$2:$D$2500,Crops!$D$5,Basicdata!$H$2:$H$2500,Crops!$M7,Basicdata!$K$2:$K$2500,1,Basicdata!$AI$2:$AI$2500,0)) -> 0 | D16: =IF(A16="","",COUNTIFS(Basicdata!$B$2:$B$2500,1,Basicdata!$D$2:$D$2500,Crops!$D$5,Basicdata!$H$2:$H$2500,Crops!$M7,Basicdata!$K$2:$K$2500,2,Basicdata!$AI$2:$AI$2500,0)) -> 0 | E16: =IF(A16="","",COUNTIFS(Basicdata!$B$2:$B$2500,1,Basicdata!$D$2:$D$2500,Crops!$D$5,Basicdata!$H$2:$H$2500,Crops!$M7,Basicdata!$K$2:$K$2500,3,Basicdata!$AI$2:$AI$2500,0)) -> 8 | F16: =IF(A16="","",C16+D16+E16) -> 8 | G16: =IF(OR(F16="",F16=0),"",C16*100/B16) -> 0 | H16: =IF(OR(F16="",F16=0),"",D16*100/B16) -> 0 | I16: =IF(OR(F16="",F16=0),"",J16-G16-H16) -> 100 | J16: =IF(OR(F16="",F16=0),"",F16*100/B16) -> 100 | L16: =IF(COUNTIFS(Basicdata!$B$2:$B$2500,2,Basicdata!$D$2:$D$2500,Crops!$D$5,Basicdata!$H$2:$H$2500,Crops!$M7)>0,Crops!$M7,"") -> 6 | M16: =IF(L16="","",COUNTIFS(Basicdata!$B$2:$B$2500,2,Basicdata!$D$2:$D$2500,Crops!$D$5,Basicdata!$H$2:$H$2500,Crops!$M7)) -> 8 | N16: =IF(L16="","",COUNTIFS(Basicdata!$B$2:$B$2500,2,Basicdata!$D$2:$D$2500,Crops!$D$5,Basicdata!$H$2:$H$2500,Crops!$M7,Basicdata!$K$2:$K$2500,1,Basicdata!$AI$2:$AI$2500,0)) -> 0 | O16: =IF(L16="","",COUNTIFS(Basicdata!$B$2:$B$2500,2,Basicdata!$D$2:$D$2500,Crops!$D$5,Basicdata!$H$2:$H$2500,Crops!$M7,Basicdata!$K$2:$K$2500,2,Basicdata!$AI$2:$AI$2500,0)) -> 0 | P16: =IF(L16="","",COUNTIFS(Basicdata!$B$2:$B$2500,2,Basicdata!$D$2:$D$2500,Crops!$D$5,Basicdata!$H$2:$H$2500,Crops!$M7,Basicdata!$K$2:$K$2500,3,Basicdata!$AI$2:$AI$2500,0)) -> 8 | Q16: =IF(L16="","",N16+O16+P16) -> 8 | R16: =IF(OR(Q16="",Q16=0),"",N16*100/M16) -> 0 | S16: =IF(OR(Q16="",Q16=0),"",O16*100/M16) -> 0 | T16: =IF(OR(Q16="",Q16=0),"",U16-R16-S16) -> 100 | U16: =IF(OR(Q16="",Q16=0),"",Q16*100/M16) -> 100
A17: =IF(COUNTIFS(Basicdata!$B$2:$B$2500,1,Basicdata!$D$2:$D$2500,Crops!$D$5,Basicdata!$H$2:$H$2500,Crops!$M8)>0,Crops!$M8,"") -> 7 | B17: =IF(A17="","",COUNTIFS(Basicdata!$B$2:$B$2500,1,Basicdata!$D$2:$D$2500,Crops!$D$5,Basicdata!$H$2:$H$2500,Crops!$M8)) -> 16 | C17: =IF(A17="","",COUNTIFS(Basicdata!$B$2:$B$2500,1,Basicdata!$D$2:$D$2500,Crops!$D$5,Basicdata!$H$2:$H$2500,Crops!$M8,Basicdata!$K$2:$K$2500,1,Basicdata!$AI$2:$AI$2500,0)) -> 0 | D17: =IF(A17="","",COUNTIFS(Basicdata!$B$2:$B$2500,1,Basicdata!$D$2:$D$2500,Crops!$D$5,Basicdata!$H$2:$H$2500,Crops!$M8,Basicdata!$K$2:$K$2500,2,Basicdata!$AI$2:$AI$2500,0)) -> 0 | E17: =IF(A17="","",COUNTIFS(Basicdata!$B$2:$B$2500,1,Basicdata!$D$2:$D$2500,Crops!$D$5,Basicdata!$H$2:$H$2500,Crops!$M8,Basicdata!$K$2:$K$2500,3,Basicdata!$AI$2:$AI$2500,0)) -> 16 | F17: =IF(A17="","",C17+D17+E17) -> 16 | G17: =IF(OR(F17="",F17=0),"",C17*100/B17) -> 0 | H17: =IF(OR(F17="",F17=0),"",D17*100/B17) -> 0 | I17: =IF(OR(F17="",F17=0),"",J17-G17-H17) -> 100 | J17: =IF(OR(F17="",F17=0),"",F17*100/B17) -> 100 | L17: =IF(COUNTIFS(Basicdata!$B$2:$B$2500,2,Basicdata!$D$2:$D$2500,Crops!$D$5,Basicdata!$H$2:$H$2500,Crops!$M8)>0,Crops!$M8,"") -> 7 | M17: =IF(L17="","",COUNTIFS(Basicdata!$B$2:$B$2500,2,Basicdata!$D$2:$D$2500,Crops!$D$5,Basicdata!$H$2:$H$2500,Crops!$M8)) -> 16 | N17: =IF(L17="","",COUNTIFS(Basicdata!$B$2:$B$2500,2,Basicdata!$D$2:$D$2500,Crops!$D$5,Basicdata!$H$2:$H$2500,Crops!$M8,Basicdata!$K$2:$K$2500,1,Basicdata!$AI$2:$AI$2500,0)) -> 0 | O17: =IF(L17="","",COUNTIFS(Basicdata!$B$2:$B$2500,2,Basicdata!$D$2:$D$2500,Crops!$D$5,Basicdata!$H$2:$H$2500,Crops!$M8,Basicdata!$K$2:$K$2500,2,Basicdata!$AI$2:$AI$2500,0)) -> 0 | P17: =IF(L17="","",COUNTIFS(Basicdata!$B$2:$B$2500,2,Basicdata!$D$2:$D$2500,Crops!$D$5,Basicdata!$H$2:$H$2500,Crops!$M8,Basicdata!$K$2:$K$2500,3,Basicdata!$AI$2:$AI$2500,0)) -> 16 | Q17: =IF(L17="","",N17+O17+P17) -> 16 | R17: =IF(OR(Q17="",Q17=0),"",N17*100/M17) -> 0 | S17: =IF(OR(Q17="",Q17=0),"",O17*100/M17) -> 0 | T17: =IF(OR(Q17="",Q17=0),"",U17-R17-S17) -> 100 | U17: =IF(OR(Q17="",Q17=0),"",Q17*100/M17) -> 100
A18: =IF(COUNTIFS(Basicdata!$B$2:$B$2500,1,Basicdata!$D$2:$D$2500,Crops!$D$5,Basicdata!$H$2:$H$2500,Crops!$M9)>0,Crops!$M9,"") -> 8 | B18: =IF(A18="","",COUNTIFS(Basicdata!$B$2:$B$2500,1,Basicdata!$D$2:$D$2500,Crops!$D$5,Basicdata!$H$2:$H$2500,Crops!$M9)) -> 20 | C18: =IF(A18="","",COUNTIFS(Basicdata!$B$2:$B$2500,1,Basicdata!$D$2:$D$2500,Crops!$D$5,Basicdata!$H$2:$H$2500,Crops!$M9,Basicdata!$K$2:$K$2500,1,Basicdata!$AI$2:$AI$2500,0)) -> 0 | D18: =IF(A18="","",COUNTIFS(Basicdata!$B$2:$B$2500,1,Basicdata!$D$2:$D$2500,Crops!$D$5,Basicdata!$H$2:$H$2500,Crops!$M9,Basicdata!$K$2:$K$2500,2,Basicdata!$AI$2:$AI$2500,0)) -> 0 | E18: =IF(A18="","",COUNTIFS(Basicdata!$B$2:$B$2500,1,Basicdata!$D$2:$D$2500,Crops!$D$5,Basicdata!$H$2:$H$2500,Crops!$M9,Basicdata!$K$2:$K$2500,3,Basicdata!$AI$2:$AI$2500,0)) -> 20 | F18: =IF(A18="","",C18+D18+E18) -> 20 | G18: =IF(OR(F18="",F18=0),"",C18*100/B18) -> 0 | H18: =IF(OR(F18="",F18=0),"",D18*100/B18) -> 0 | I18: =IF(OR(F18="",F18=0),"",J18-G18-H18) -> 100 | J18: =IF(OR(F18="",F18=0),"",F18*100/B18) -> 100 | L18: =IF(COUNTIFS(Basicdata!$B$2:$B$2500,2,Basicdata!$D$2:$D$2500,Crops!$D$5,Basicdata!$H$2:$H$2500,Crops!$M9)>0,Crops!$M9,"") -> 8 | M18: =IF(L18="","",COUNTIFS(Basicdata!$B$2:$B$2500,2,Basicdata!$D$2:$D$2500,Crops!$D$5,Basicdata!$H$2:$H$2500,Crops!$M9)) -> 20 | N18: =IF(L18="","",COUNTIFS(Basicdata!$B$2:$B$2500,2,Basicdata!$D$2:$D$2500,Crops!$D$5,Basicdata!$H$2:$H$2500,Crops!$M9,Basicdata!$K$2:$K$2500,1,Basicdata!$AI$2:$AI$2500,0)) -> 0 | O18: =IF(L18="","",COUNTIFS(Basicdata!$B$2:$B$2500,2,Basicdata!$D$2:$D$2500,Crops!$D$5,Basicdata!$H$2:$H$2500,Crops!$M9,Basicdata!$K$2:$K$2500,2,Basicdata!$AI$2:$AI$2500,0)) -> 0 | P18: =IF(L18="","",COUNTIFS(Basicdata!$B$2:$B$2500,2,Basicdata!$D$2:$D$2500,Crops!$D$5,Basicdata!$H$2:$H$2500,Crops!$M9,Basicdata!$K$2:$K$2500,3,Basicdata!$AI$2:$AI$2500,0)) -> 20 | Q18: =IF(L18="","",N18+O18+P18) -> 20 | R18: =IF(OR(Q18="",Q18=0),"",N18*100/M18) -> 0 | S18: =IF(OR(Q18="",Q18=0),"",O18*100/M18) -> 0 | T18: =IF(OR(Q18="",Q18=0),"",U18-R18-S18) -> 100 | U18: =IF(OR(Q18="",Q18=0),"",Q18*100/M18) -> 100
A19: =IF(COUNTIFS(Basicdata!$B$2:$B$2500,1,Basicdata!$D$2:$D$2500,Crops!$D$5,Basicdata!$H$2:$H$2500,Crops!$M10)>0,Crops!$M10,"") -> 9 | B19: =IF(A19="","",COUNTIFS(Basicdata!$B$2:$B$2500,1,Basicdata!$D$2:$D$2500,Crops!$D$5,Basicdata!$H$2:$H$2500,Crops!$M10)) -> 16 | C19: =IF(A19="","",COUNTIFS(Basicdata!$B$2:$B$2500,1,Basicdata!$D$2:$D$2500,Crops!$D$5,Basicdata!$H$2:$H$2500,Crops!$M10,Basicdata!$K$2:$K$2500,1,Basicdata!$AI$2:$AI$2500,0)) -> 0 | D19: =IF(A19="","",COUNTIFS(Basicdata!$B$2:$B$2500,1,Basicdata!$D$2:$D$2500,Crops!$D$5,Basicdata!$H$2:$H$2500,Crops!$M10,Basicdata!$K$2:$K$2500,2,Basicdata!$AI$2:$AI$2500,0)) -> 0 | E19: =IF(A19="","",COUNTIFS(Basicdata!$B$2:$B$2500,1,Basicdata!$D$2:$D$2500,Crops!$D$5,Basicdata!$H$2:$H$2500,Crops!$M10,Basicdata!$K$2:$K$2500,3,Basicdata!$AI$2:$AI$2500,0)) -> 16 | F19: =IF(A19="","",C19+D19+E19) -> 16 | G19: =IF(OR(F19="",F19=0),"",C19*100/B19) -> 0 | H19: =IF(OR(F19="",F19=0),"",D19*100/B19) -> 0 | I19: =IF(OR(F19="",F19=0),"",J19-G19-H19) -> 100 | J19: =IF(OR(F19="",F19=0),"",F19*100/B19) -> 100 | L19: =IF(COUNTIFS(Basicdata!$B$2:$B$2500,2,Basicdata!$D$2:$D$2500,Crops!$D$5,Basicdata!$H$2:$H$2500,Crops!$M10)>0,Crops!$M10,"") -> 9 | M19: =IF(L19="","",COUNTIFS(Basicdata!$B$2:$B$2500,2,Basicdata!$D$2:$D$2500,Crops!$D$5,Basicdata!$H$2:$H$2500,Crops!$M10)) -> 16 | N19: =IF(L19="","",COUNTIFS(Basicdata!$B$2:$B$2500,2,Basicdata!$D$2:$D$2500,Crops!$D$5,Basicdata!$H$2:$H$2500,Crops!$M10,Basicdata!$K$2:$K$2500,1,Basicdata!$AI$2:$AI$2500,0)) -> 0 | O19: =IF(L19="","",COUNTIFS(Basicdata!$B$2:$B$2500,2,Basicdata!$D$2:$D$2500,Crops!$D$5,Basicdata!$H$2:$H$2500,Crops!$M10,Basicdata!$K$2:$K$2500,2,Basicdata!$AI$2:$AI$2500,0)) -> 0 | P19: =IF(L19="","",COUNTIFS(Basicdata!$B$2:$B$2500,2,Basicdata!$D$2:$D$2500,Crops!$D$5,Basicdata!$H$2:$H$2500,Crops!$M10,Basicdata!$K$2:$K$2500,3,Basicdata!$AI$2:$AI$2500,0)) -> 16 | Q19: =IF(L19="","",N19+O19+P19) -> 16 | R19: =IF(OR(Q19="",Q19=0),"",N19*100/M19) -> 0 | S19: =IF(OR(Q19="",Q19=0),"",O19*100/M19) -> 0 | T19: =IF(OR(Q19="",Q19=0),"",U19-R19-S19) -> 100 | U19: =IF(OR(Q19="",Q19=0),"",Q19*100/M19) -> 100
A20: =IF(COUNTIFS(Basicdata!$B$2:$B$2500,1,Basicdata!$D$2:$D$2500,Crops!$D$5,Basicdata!$H$2:$H$2500,Crops!$M11)>0,Crops!$M11,"") -> 10 | B20: =IF(A20="","",COUNTIFS(Basicdata!$B$2:$B$2500,1,Basicdata!$D$2:$D$2500,Crops!$D$5,Basicdata!$H$2:$H$2500,Crops!$M11)) -> 10 | C20: =IF(A20="","",COUNTIFS(Basicdata!$B$2:$B$2500,1,Basicdata!$D$2:$D$2500,Crops!$D$5,Basicdata!$H$2:$H$2500,Crops!$M11,Basicdata!$K$2:$K$2500,1,Basicdata!$AI$2:$AI$2500,0)) -> 0 | D20: =IF(A20="","",COUNTIFS(Basicdata!$B$2:$B$2500,1,Basicdata!$D$2:$D$2500,Crops!$D$5,Basicdata!$H$2:$H$2500,Crops!$M11,Basicdata!$K$2:$K$2500,2,Basicdata!$AI$2:$AI$2500,0)) -> 0 | E20: =IF(A20="","",COUNTIFS(Basicdata!$B$2:$B$2500,1,Basicdata!$D$2:$D$2500,Crops!$D$5,Basicdata!$H$2:$H$2500,Crops!$M11,Basicdata!$K$2:$K$2500,3,Basicdata!$AI$2:$AI$2500,0)) -> 10 | F20: =IF(A20="","",C20+D20+E20) -> 10 | G20: =IF(OR(F20="",F20=0),"",C20*100/B20) -> 0 | H20: =IF(OR(F20="",F20=0),"",D20*100/B20) -> 0 | I20: =IF(OR(F20="",F20=0),"",J20-G20-H20) -> 100 | J20: =IF(OR(F20="",F20=0),"",F20*100/B20) -> 100 | L20: =IF(COUNTIFS(Basicdata!$B$2:$B$2500,2,Basicdata!$D$2:$D$2500,Crops!$D$5,Basicdata!$H$2:$H$2500,Crops!$M11)>0,Crops!$M11,"") -> 10 | M20: =IF(L20="","",COUNTIFS(Basicdata!$B$2:$B$2500,2,Basicdata!$D$2:$D$2500,Crops!$D$5,Basicdata!$H$2:$H$2500,Crops!$M11)) -> 10 | N20: =IF(L20="","",COUNTIFS(Basicdata!$B$2:$B$2500,2,Basicdata!$D$2:$D$2500,Crops!$D$5,Basicdata!$H$2:$H$2500,Crops!$M11,Basicdata!$K$2:$K$2500,1,Basicdata!$AI$2:$AI$2500,0)) -> 0 | O20: =IF(L20="","",COUNTIFS(Basicdata!$B$2:$B$2500,2,Basicdata!$D$2:$D$2500,Crops!$D$5,Basicdata!$H$2:$H$2500,Crops!$M11,Basicdata!$K$2:$K$2500,2,Basicdata!$AI$2:$AI$2500,0)) -> 0 | P20: =IF(L20="","",COUNTIFS(Basicdata!$B$2:$B$2500,2,Basicdata!$D$2:$D$2500,Crops!$D$5,Basicdata!$H$2:$H$2500,Crops!$M11,Basicdata!$K$2:$K$2500,3,Basicdata!$AI$2:$AI$2500,0)) -> 10 | Q20: =IF(L20="","",N20+O20+P20) -> 10 | R20: =IF(OR(Q20="",Q20=0),"",N20*100/M20) -> 0 | S20: =IF(OR(Q20="",Q20=0),"",O20*100/M20) -> 0 | T20: =IF(OR(Q20="",Q20=0),"",U20-R20-S20) -> 100 | U20: =IF(OR(Q20="",Q20=0),"",Q20*100/M20) -> 100
A21: =IF(COUNTIFS(Basicdata!$B$2:$B$2500,1,Basicdata!$D$2:$D$2500,Crops!$D$5,Basicdata!$H$2:$H$2500,Crops!$M12)>0,Crops!$M12,"") -> 11 | B21: =IF(A21="","",COUNTIFS(Basicdata!$B$2:$B$2500,1,Basicdata!$D$2:$D$2500,Crops!$D$5,Basicdata!$H$2:$H$2500,Crops!$M12)) -> 5 | C21: =IF(A21="","",COUNTIFS(Basicdata!$B$2:$B$2500,1,Basicdata!$D$2:$D$2500,Crops!$D$5,Basicdata!$H$2:$H$2500,Crops!$M12,Basicdata!$K$2:$K$2500,1,Basicdata!$AI$2:$AI$2500,0)) -> 0 | D21: =IF(A21="","",COUNTIFS(Basicdata!$B$2:$B$2500,1,Basicdata!$D$2:$D$2500,Crops!$D$5,Basicdata!$H$2:$H$2500,Crops!$M12,Basicdata!$K$2:$K$2500,2,Basicdata!$AI$2:$AI$2500,0)) -> 0 | E21: =IF(A21="","",COUNTIFS(Basicdata!$B$2:$B$2500,1,Basicdata!$D$2:$D$2500,Crops!$D$5,Basicdata!$H$2:$H$2500,Crops!$M12,Basicdata!$K$2:$K$2500,3,Basicdata!$AI$2:$AI$2500,0)) -> 5 | F21: =IF(A21="","",C21+D21+E21) -> 5 | G21: =IF(OR(F21="",F21=0),"",C21*100/B21) -> 0 | H21: =IF(OR(F21="",F21=0),"",D21*100/B21) -> 0 | I21: =IF(OR(F21="",F21=0),"",J21-G21-H21) -> 100 | J21: =IF(OR(F21="",F21=0),"",F21*100/B21) -> 100 | L21: =IF(COUNTIFS(Basicdata!$B$2:$B$2500,2,Basicdata!$D$2:$D$2500,Crops!$D$5,Basicdata!$H$2:$H$2500,Crops!$M12)>0,Crops!$M12,"") -> 11 | M21: =IF(L21="","",COUNTIFS(Basicdata!$B$2:$B$2500,2,Basicdata!$D$2:$D$2500,Crops!$D$5,Basicdata!$H$2:$H$2500,Crops!$M12)) -> 5 | N21: =IF(L21="","",COUNTIFS(Basicdata!$B$2:$B$2500,2,Basicdata!$D$2:$D$2500,Crops!$D$5,Basicdata!$H$2:$H$2500,Crops!$M12,Basicdata!$K$2:$K$2500,1,Basicdata!$AI$2:$AI$2500,0)) -> 0 | O21: =IF(L21="","",COUNTIFS(Basicdata!$B$2:$B$2500,2,Basicdata!$D$2:$D$2500,Crops!$D$5,Basicdata!$H$2:$H$2500,Crops!$M12,Basicdata!$K$2:$K$2500,2,Basicdata!$AI$2:$AI$2500,0)) -> 0 | P21: =IF(L21="","",COUNTIFS(Basicdata!$B$2:$B$2500,2,Basicdata!$D$2:$D$2500,Crops!$D$5,Basicdata!$H$2:$H$2500,Crops!$M12,Basicdata!$K$2:$K$2500,3,Basicdata!$AI$2:$AI$2500,0)) -> 5 | Q21: =IF(L21="","",N21+O21+P21) -> 5 | R21: =IF(OR(Q21="",Q21=0),"",N21*100/M21) -> 0 | S21: =IF(OR(Q21="",Q21=0),"",O21*100/M21) -> 0 | T21: =IF(OR(Q21="",Q21=0),"",U21-R21-S21) -> 100 | U21: =IF(OR(Q21="",Q21=0),"",Q21*100/M21) -> 100
A22: =IF(COUNTIFS(Basicdata!$B$2:$B$2500,1,Basicdata!$D$2:$D$2500,Crops!$D$5,Basicdata!$H$2:$H$2500,Crops!$M13)>0,Crops!$M13,"") -> 12 | B22: =IF(A22="","",COUNTIFS(Basicdata!$B$2:$B$2500,1,Basicdata!$D$2:$D$2500,Crops!$D$5,Basicdata!$H$2:$H$2500,Crops!$M13)) -> 14 | C22: =IF(A22="","",COUNTIFS(Basicdata!$B$2:$B$2500,1,Basicdata!$D$2:$D$2500,Crops!$D$5,Basicdata!$H$2:$H$2500,Crops!$M13,Basicdata!$K$2:$K$2500,1,Basicdata!$AI$2:$AI$2500,0)) -> 0 | D22: =IF(A22="","",COUNTIFS(Basicdata!$B$2:$B$2500,1,Basicdata!$D$2:$D$2500,Crops!$D$5,Basicdata!$H$2:$H$2500,Crops!$M13,Basicdata!$K$2:$K$2500,2,Basicdata!$AI$2:$AI$2500,0)) -> 0 | E22: =IF(A22="","",COUNTIFS(Basicdata!$B$2:$B$2500,1,Basicdata!$D$2:$D$2500,Crops!$D$5,Basicdata!$H$2:$H$2500,Crops!$M13,Basicdata!$K$2:$K$2500,3,Basicdata!$AI$2:$AI$2500,0)) -> 14 | F22: =IF(A22="","",C22+D22+E22) -> 14 | G22: =IF(OR(F22="",F22=0),"",C22*100/B22) -> 0 | H22: =IF(OR(F22="",F22=0),"",D22*100/B22) -> 0 | I22: =IF(OR(F22="",F22=0),"",J22-G22-H22) -> 100 | J22: =IF(OR(F22="",F22=0),"",F22*100/B22) -> 100 | L22: =IF(COUNTIFS(Basicdata!$B$2:$B$2500,2,Basicdata!$D$2:$D$2500,Crops!$D$5,Basicdata!$H$2:$H$2500,Crops!$M13)>0,Crops!$M13,"") -> 12 | M22: =IF(L22="","",COUNTIFS(Basicdata!$B$2:$B$2500,2,Basicdata!$D$2:$D$2500,Crops!$D$5,Basicdata!$H$2:$H$2500,Crops!$M13)) -> 14 | N22: =IF(L22="","",COUNTIFS(Basicdata!$B$2:$B$2500,2,Basicdata!$D$2:$D$2500,Crops!$D$5,Basicdata!$H$2:$H$2500,Crops!$M13,Basicdata!$K$2:$K$2500,1,Basicdata!$AI$2:$AI$2500,0)) -> 0 | O22: =IF(L22="","",COUNTIFS(Basicdata!$B$2:$B$2500,2,Basicdata!$D$2:$D$2500,Crops!$D$5,Basicdata!$H$2:$H$2500,Crops!$M13,Basicdata!$K$2:$K$2500,2,Basicdata!$AI$2:$AI$2500,0)) -> 0 | P22: =IF(L22="","",COUNTIFS(Basicdata!$B$2:$B$2500,2,Basicdata!$D$2:$D$2500,Crops!$D$5,Basicdata!$H$2:$H$2500,Crops!$M13,Basicdata!$K$2:$K$2500,3,Basicdata!$AI$2:$AI$2500,0)) -> 14 | Q22: =IF(L22="","",N22+O22+P22) -> 14 | R22: =IF(OR(Q22="",Q22=0),"",N22*100/M22) -> 0 | S22: =IF(OR(Q22="",Q22=0),"",O22*100/M22) -> 0 | T22: =IF(OR(Q22="",Q22=0),"",U22-R22-S22) -> 100 | U22: =IF(OR(Q22="",Q22=0),"",Q22*100/M22) -> 100
... A97: =IF(COUNTIFS(Basicdata!$B$2:$B$2500,1,Basicdata!$D$2:$D$2500,Crops!$D$5,Basicdata!$H$2:$H$2500,Crops!$M88)>0,Crops!$M88,"") | B97: =IF(A97="","",COUNTIFS(Basicdata!$B$2:$B$2500,1,Basicdata!$D$2:$D$2500,Crops!$D$5,Basicdata!$H$2:$H$2500,Crops!$M88)) | C97: =IF(A97="","",COUNTIFS(Basicdata!$B$2:$B$2500,1,Basicdata!$D$2:$D$2500,Crops!$D$5,Basicdata!$H$2:$H$2500,Crops!$M88,Basicdata!$K$2:$K$2500,1,Basicdata!$AI$2:$AI$2500,0)) | D97: =IF(A97="","",COUNTIFS(Basicdata!$B$2:$B$2500,1,Basicdata!$D$2:$D$2500,Crops!$D$5,Basicdata!$H$2:$H$2500,Crops!$M88,Basicdata!$K$2:$K$2500,2,Basicdata!$AI$2:$AI$2500,0)) | E97: =IF(A97="","",COUNTIFS(Basicdata!$B$2:$B$2500,1,Basicdata!$D$2:$D$2500,Crops!$D$5,Basicdata!$H$2:$H$2500,Crops!$M88,Basicdata!$K$2:$K$2500,3,Basicdata!$AI$2:$AI$2500,0)) | F97: =IF(A97="","",C97+D97+E97) | G97: =IF(OR(F97="",F97=0),"",C97*100/B97) | H97: =IF(OR(F97="",F97=0),"",D97*100/B97) | I97: =IF(OR(F97="",F97=0),"",J97-G97-H97) | J97: =IF(OR(F97="",F97=0),"",F97*100/B97) | L97: =IF(COUNTIFS(Basicdata!$B$2:$B$2500,2,Basicdata!$D$2:$D$2500,Crops!$D$5,Basicdata!$H$2:$H$2500,Crops!$M88)>0,Crops!$M88,"") | M97: =IF(L97="","",COUNTIFS(Basicdata!$B$2:$B$2500,2,Basicdata!$D$2:$D$2500,Crops!$D$5,Basicdata!$H$2:$H$2500,Crops!$M88)) | N97: =IF(L97="","",COUNTIFS(Basicdata!$B$2:$B$2500,2,Basicdata!$D$2:$D$2500,Crops!$D$5,Basicdata!$H$2:$H$2500,Crops!$M88,Basicdata!$K$2:$K$2500,1,Basicdata!$AI$2:$AI$2500,0)) | O97: =IF(L97="","",COUNTIFS(Basicdata!$B$2:$B$2500,2,Basicdata!$D$2:$D$2500,Crops!$D$5,Basicdata!$H$2:$H$2500,Crops!$M88,Basicdata!$K$2:$K$2500,2,Basicdata!$AI$2:$AI$2500,0)) | P97: =IF(L97="","",COUNTIFS(Basicdata!$B$2:$B$2500,2,Basicdata!$D$2:$D$2500,Crops!$D$5,Basicdata!$H$2:$H$2500,Crops!$M88,Basicdata!$K$2:$K$2500,3,Basicdata!$AI$2:$AI$2500,0)) | Q97: =IF(L97="","",N97+O97+P97) | R97: =IF(OR(Q97="",Q97=0),"",N97*100/M97) | S97: =IF(OR(Q97="",Q97=0),"",O97*100/M97) | T97: =IF(OR(Q97="",Q97=0),"",U97-R97-S97) | U97: =IF(OR(Q97="",Q97=0),"",Q97*100/M97)
A98: STATE: | B98: =SUM(B11:B97) -> 340 | C98: =SUM(C11:C97) -> 0 | D98: =SUM(D11:D97) -> 0 | E98: =SUM(E11:E97) -> 339 | F98: =SUM(F11:F97) -> 339 | G98: =ROUND(C98*100/$B98,2) -> 0 | H98: =ROUND(D98*100/$B98,2) -> 0 | I98: =J98-G98-H98 -> 99.71 | J98: =ROUND(F98*100/$B98,2) -> 99.71 | L98: STATE: | M98: =SUM(M11:M97) -> 340 | N98: =SUM(N11:N97) -> 0 | O98: =SUM(O11:O97) -> 0 | P98: =SUM(P11:P97) -> 339 | Q98: =SUM(Q11:Q97) -> 339 | R98: =ROUND(N98*100/$M98,2) -> 0 | S98: =ROUND(O98*100/$M98,2) -> 0 | T98: =U98-R98-S98 -> 99.71 | U98: =ROUND(Q98*100/$M98,2) -> 99.71
A99: NOTE: "A" ENTRIES= AS PER SUPERVISOR, "B" ENTRIES= AS PER PATWARI. | L99: NOTE: "A" ENTRIES= AS PER SUPERVISOR, "B" ENTRIES= AS PER PATWARI.
A100: Developed by: Deepak Kumar Agrawal, Senior Statistical Officer, NSSO (FOD), Faridabad, Haryana | L100: Developed by: Deepak Kumar Agrawal, Senior Statistical Officer, NSSO (FOD), Faridabad, Haryana

Sheet Table-1(p)
A2: TABLE :A-1 : DISTRICTWISE DISTRIBUTION OF SELECTED VILLAGES FOR CHECK ON ENUMERATION OF AREA AND RESPONSE ACHIEVED.
A3: STATE: | B3: ='Table-1'!B3 -> GUJARAT(24) | D3: YEAR: | E3: ='Table-1'!E3 -> 2023-24 | F3: SEASON: | G3: ='Table-1'!G3 -> SUMMER(5) | H3: SAMPLE: | I3: ='Table-1'!I3 -> CENTRAL(1)
A4: DISTRICT | B4: NO.OF VILLAGES FOR WHICH SCHEDULE AS 1.0 RECEIVED | C4: NO. OF VILLAGES FOR WHICH SCHEDULE AS 1.0 IS ANALYSED | G4: PERCENTAGE RESPONSE TO COL.(2)
C5: WITH 'a' AND 'b' ENTRIES TOGETHER | D5: WITH 'a' AND 'b' ENTRIES SEPARATELY | E5: WITH 'a' ENTRIES ONLY | F5: TOTAL | G5: WITH 'a' AND 'b' ENTRIES TOGETHER | H5: WITH 'a' AND 'b' ENTRIES SEPARATELY | I5: WITH 'a' ENTRIES ONLY | J5: TOTAL
A10: 1 | B10: 2 | C10: 3 | D10: 4 | E10: 5 | F10: 7 | G10: 8 | H10: 9 | I10: 10 | J10: 11
A11: ='Table-1'!A11 -> 1 | B11: ='Table-1'!B11 -> 17 | C11: ='Table-1'!C11 -> 0 | D11: ='Table-1'!D11 -> 0 | E11: ='Table-1'!E11 -> 17 | F11: ='Table-1'!F11 -> 17 | G11: ='Table-1'!G11 -> 0 | H11: ='Table-1'!H11 -> 0 | ... J11: ='Table-1'!J11 -> 100
A12: ='Table-1'!A12 -> 2 | B12: ='Table-1'!B12 -> 33 | C12: ='Table-1'!C12 -> 0 | D12: ='Table-1'!D12 -> 0 | E12: ='Table-1'!E12 -> 32 | F12: ='Table-1'!F12 -> 32 | G12: ='Table-1'!G12 -> 0 | H12: ='Table-1'!H12 -> 0 | ... J12: ='Table-1'!J12 -> 96.969697
A13: ='Table-1'!A13 -> 3 | B13: ='Table-1'!B13 -> 18 | C13: ='Table-1'!C13 -> 0 | D13: ='Table-1'!D13 -> 0 | E13: ='Table-1'!E13 -> 18 | F13: ='Table-1'!F13 -> 18 | G13: ='Table-1'!G13 -> 0 | H13: ='Table-1'!H13 -> 0 | ... J13: ='Table-1'!J13 -> 100
A14: ='Table-1'!A14 -> 4 | B14: ='Table-1'!B14 -> 14 | C14: ='Table-1'!C14 -> 0 | D14: ='Table-1'!D14 -> 0 | E14: ='Table-1'!E14 -> 14 | F14: ='Table-1'!F14 -> 14 | G14: ='Table-1'!G14 -> 0 | H14: ='Table-1'!H14 -> 0 | ... J14: ='Table-1'!J14 -> 100
A15: ='Table-1'!A15 -> 5 | B15: ='Table-1'!B15 -> 10 | C15: ='Table-1'!C15 -> 0 | D15: ='Table-1'!D15 -> 0 | E15: ='Table-1'!E15 -> 10 | F15: ='Table-1'!F15 -> 10 | G15: ='Table-1'!G15 -> 0 | H15: ='Table-1'!H15 -> 0 | ... J15: ='Table-1'!J15 -> 100
A16: ='Table-1'!A16 -> 6 | B16: ='Table-1'!B16 -> 8 | C16: ='Table-1'!C16 -> 0 | D16: ='Table-1'!D16 -> 0 | E16: ='Table-1'!E16 -> 8 | F16: ='Table-1'!F16 -> 8 | G16: ='Table-1'!G16 -> 0 | H16: ='Table-1'!H16 -> 0 | ... J16: ='Table-1'!J16 -> 100
A17: ='Table-1'!A17 -> 7 | B17: ='Table-1'!B17 -> 16 | C17: ='Table-1'!C17 -> 0 | D17: ='Table-1'!D17 -> 0 | E17: ='Table-1'!E17 -> 16 | F17: ='Table-1'!F17 -> 16 | G17: ='Table-1'!G17 -> 0 | H17: ='Table-1'!H17 -> 0 | ... J17: ='Table-1'!J17 -> 100
A18: ='Table-1'!A18 -> 8 | B18: ='Table-1'!B18 -> 20 | C18: ='Table-1'!C18 -> 0 | D18: ='Table-1'!D18 -> 0 | E18: ='Table-1'!E18 -> 20 | F18: ='Table-1'!F18 -> 20 | G18: ='Table-1'!G18 -> 0 | H18: ='Table-1'!H18 -> 0 | ... J18: ='Table-1'!J18 -> 100
A19: ='Table-1'!A19 -> 9 | B19: ='Table-1'!B19 -> 16 | C19: ='Table-1'!C19 -> 0 | D19: ='Table-1'!D19 -> 0 | E19: ='Table-1'!E19 -> 16 | F19: ='Table-1'!F19 -> 16 | G19: ='Table-1'!G19 -> 0 | H19: ='Table-1'!H19 -> 0 | ... J19: ='Table-1'!J19 -> 100
A20: ='Table-1'!A20 -> 10 | B20: ='Table-1'!B20 -> 10 | C20: ='Table-1'!C20 -> 0 | D20: ='Table-1'!D20 -> 0 | E20: ='Table-1'!E20 -> 10 | F20: ='Table-1'!F20 -> 10 | G20: ='Table-1'!G20 -> 0 | H20: ='Table-1'!H20 -> 0 | ... J20: ='Table-1'!J20 -> 100
A21: ='Table-1'!A21 -> 11 | B21: ='Table-1'!B21 -> 5 | C21: ='Table-1'!C21 -> 0 | D21: ='Table-1'!D21 -> 0 | E21: ='Table-1'!E21 -> 5 | F21: ='Table-1'!F21 -> 5 | G21: ='Table-1'!G21 -> 0 | H21: ='Table-1'!H21 -> 0 | ... J21: ='Table-1'!J21 -> 100
A22: ='Table-1'!A22 -> 12 | B22: ='Table-1'!B22 -> 14 | C22: ='Table-1'!C22 -> 0 | D22: ='Table-1'!D22 -> 0 | E22: ='Table-1'!E22 -> 14 | F22: ='Table-1'!F22 -> 14 | G22: ='Table-1'!G22 -> 0 | H22: ='Table-1'!H22 -> 0 | ... J22: ='Table-1'!J22 -> 100
... A98: ='Table-1'!A98 -> STATE: | B98: ='Table-1'!B98 -> 340 | C98: ='Table-1'!C98 -> 0 | D98: ='Table-1'!D98 -> 0 | E98: ='Table-1'!E98 -> 339 | F98: ='Table-1'!F98 -> 339 | G98: ='Table-1'!G98 -> 0 | H98: ='Table-1'!H98 -> 0 | ... J98: ='Table-1'!J98 -> 99.71
A99: NOTE: "A" ENTRIES= AS PER SUPERVISOR, "B" ENTRIES= AS PER PATWARI.
A100: Developed by: Deepak Kumar Agrawal, Senior Statistical Officer, NSSO (FOD), Faridabad, Haryana
A102: TABLE :A-1 : DISTRICTWISE DISTRIBUTION OF SELECTED VILLAGES FOR CHECK ON ENUMERATION OF AREA AND RESPONSE ACHIEVED.
A103: STATE: | B103: ='Table-1'!M3 -> GUJARAT(24) | D103: YEAR: | E103: ='Table-1'!P3 -> 2023-24 | F103: SEASON: | G103: ='Table-1'!R3 -> SUMMER(5) | H103: SAMPLE: | I103: ='Table-1'!T3 -> STATE(2)
A104: DISTRICT | B104: NO.OF VILLAGES FOR WHICH SCHEDULE AS 1.0 RECEIVED | C104: NO. OF VILLAGES FOR WHICH SCHEDULE AS 1.0 IS ANALYSED | G104: PERCENTAGE RESPONSE TO COL.(2)
C105: WITH 'a' AND 'b' ENTRIES TOGETHER | D105: WITH 'a' AND 'b' ENTRIES SEPARATELY | E105: WITH 'a' ENTRIES ONLY | F105: TOTAL | G105: WITH 'a' AND 'b' ENTRIES TOGETHER | H105: WITH 'a' AND 'b' ENTRIES SEPARATELY | I105: WITH 'a' ENTRIES ONLY | J105: TOTAL
A110: 1 | B110: 2 | C110: 3 | D110: 4 | E110: 5 | F110: 7 | G110: 8 | H110: 9 | I110: 10 | J110: 11
A111: ='Table-1'!L11 -> 1 | B111: ='Table-1'!M11 -> 17 | C111: ='Table-1'!N11 -> 0 | D111: ='Table-1'!O11 -> 0 | E111: ='Table-1'!P11 -> 17 | F111: ='Table-1'!Q11 -> 17 | G111: ='Table-1'!R11 -> 0 | H111: ='Table-1'!S11 -> 0 | ... J111: ='Table-1'!U11 -> 100
A112: ='Table-1'!L12 -> 2 | B112: ='Table-1'!M12 -> 33 | C112: ='Table-1'!N12 -> 0 | D112: ='Table-1'!O12 -> 0 | E112: ='Table-1'!P12 -> 33 | F112: ='Table-1'!Q12 -> 33 | G112: ='Table-1'!R12 -> 0 | H112: ='Table-1'!S12 -> 0 | ... J112: ='Table-1'!U12 -> 100
A113: ='Table-1'!L13 -> 3 | B113: ='Table-1'!M13 -> 18 | C113: ='Table-1'!N13 -> 0 | D113: ='Table-1'!O13 -> 0 | E113: ='Table-1'!P13 -> 18 | F113: ='Table-1'!Q13 -> 18 | G113: ='Table-1'!R13 -> 0 | H113: ='Table-1'!S13 -> 0 | ... J113: ='Table-1'!U13 -> 100
A114: ='Table-1'!L14 -> 4 | B114: ='Table-1'!M14 -> 14 | C114: ='Table-1'!N14 -> 0 | D114: ='Table-1'!O14 -> 0 | E114: ='Table-1'!P14 -> 14 | F114: ='Table-1'!Q14 -> 14 | G114: ='Table-1'!R14 -> 0 | H114: ='Table-1'!S14 -> 0 | ... J114: ='Table-1'!U14 -> 100
A115: ='Table-1'!L15 -> 5 | B115: ='Table-1'!M15 -> 10 | C115: ='Table-1'!N15 -> 0 | D115: ='Table-1'!O15 -> 0 | E115: ='Table-1'!P15 -> 10 | F115: ='Table-1'!Q15 -> 10 | G115: ='Table-1'!R15 -> 0 | H115: ='Table-1'!S15 -> 0 | ... J115: ='Table-1'!U15 -> 100
A116: ='Table-1'!L16 -> 6 | B116: ='Table-1'!M16 -> 8 | C116: ='Table-1'!N16 -> 0 | D116: ='Table-1'!O16 -> 0 | E116: ='Table-1'!P16 -> 8 | F116: ='Table-1'!Q16 -> 8 | G116: ='Table-1'!R16 -> 0 | H116: ='Table-1'!S16 -> 0 | ... J116: ='Table-1'!U16 -> 100
A117: ='Table-1'!L17 -> 7 | B117: ='Table-1'!M17 -> 16 | C117: ='Table-1'!N17 -> 0 | D117: ='Table-1'!O17 -> 0 | E117: ='Table-1'!P17 -> 16 | F117: ='Table-1'!Q17 -> 16 | G117: ='Table-1'!R17 -> 0 | H117: ='Table-1'!S17 -> 0 | ... J117: ='Table-1'!U17 -> 100
A118: ='Table-1'!L18 -> 8 | B118: ='Table-1'!M18 -> 20 | C118: ='Table-1'!N18 -> 0 | D118: ='Table-1'!O18 -> 0 | E118: ='Table-1'!P18 -> 20 | F118: ='Table-1'!Q18 -> 20 | G118: ='Table-1'!R18 -> 0 | H118: ='Table-1'!S18 -> 0 | ... J118: ='Table-1'!U18 -> 100
A119: ='Table-1'!L19 -> 9 | B119: ='Table-1'!M19 -> 16 | C119: ='Table-1'!N19 -> 0 | D119: ='Table-1'!O19 -> 0 | E119: ='Table-1'!P19 -> 16 | F119: ='Table-1'!Q19 -> 16 | G119: ='Table-1'!R19 -> 0 | H119: ='Table-1'!S19 -> 0 | ... J119: ='Table-1'!U19 -> 100
A120: ='Table-1'!L20 -> 10 | B120: ='Table-1'!M20 -> 10 | C120: ='Table-1'!N20 -> 0 | D120: ='Table-1'!O20 -> 0 | E120: ='Table-1'!P20 -> 10 | F120: ='Table-1'!Q20 -> 10 | G120: ='Table-1'!R20 -> 0 | H120: ='Table-1'!S20 -> 0 | ... J120: ='Table-1'!U20 -> 100
A121: ='Table-1'!L21 -> 11 | B121: ='Table-1'!M21 -> 5 | C121: ='Table-1'!N21 -> 0 | D121: ='Table-1'!O21 -> 0 | E121: ='Table-1'!P21 -> 5 | F121: ='Table-1'!Q21 -> 5 | G121: ='Table-1'!R21 -> 0 | H121: ='Table-1'!S21 -> 0 | ... J121: ='Table-1'!U21 -> 100
A122: ='Table-1'!L22 -> 12 | B122: ='Table-1'!M22 -> 14 | C122: ='Table-1'!N22 -> 0 | D122: ='Table-1'!O22 -> 0 | E122: ='Table-1'!P22 -> 14 | F122: ='Table-1'!Q22 -> 14 | G122: ='Table-1'!R22 -> 0 | H122: ='Table-1'!S22 -> 0 | ... J122: ='Table-1'!U22 -> 100
... A198: ='Table-1'!L98 -> STATE: | B198: ='Table-1'!M98 -> 340 | C198: ='Table-1'!N98 -> 0 | D198: ='Table-1'!O98 -> 0 | E198: ='Table-1'!P98 -> 339 | F198: ='Table-1'!Q98 -> 339 | G198: ='Table-1'!R98 -> 0 | H198: ='Table-1'!S98 -> 0 | ... J198: ='Table-1'!U98 -> 99.71
A199: NOTE: "A" ENTRIES= AS PER SUPERVISOR, "B" ENTRIES= AS PER PATWARI.
A200: Developed by: Deepak Kumar Agrawal, Senior Statistical Officer, NSSO (FOD), Faridabad, Haryana

Sheet Table-2
A2: Table A-2 : DISTRICTWISE DISTRIBUTION OF SELECTED VILLAGES ACCORDING TO TIME LAG BETWEEN THE YEAR OF SURVEY AND UPDATING OF MAPS. | O2: Table A-2 : DISTRICTWISE DISTRIBUTION OF SELECTED VILLAGES ACCORDING TO TIME LAG BETWEEN THE YEAR OF SURVEY AND UPDATING OF MAPS.
A3: STATE: | B3: =Crops!$A$2&"("&Crops!$B$2&")" -> GUJARAT(24) | E3: YEAR: | F3: =Crops!$B$3 -> 2023-24 | H3: SEASON: | I3: =Crops!$C$5&"("&Crops!$D$5&")" -> SUMMER(5) | K3: SAMPLE: | L3: ="CENTRAL"&"("&1&")" -> CENTRAL(1) | O3: STATE: | P3: =Crops!$A$2&"("&Crops!$B$2&")" -> GUJARAT(24) | S3: YEAR: | T3: =Crops!$B$3 -> 2023-24 | V3: SEASON: | W3: =Crops!$C$5&"("&Crops!$D$5&")" -> SUMMER(5) | Y3: SAMPLE: | Z3: ="STATE"&"("&2&")" -> STATE(2)
A4: DISTRICT | B4: NO. OF VILLAGES ANALYSED | C4: NO. OF VILLAGES ACCORDING TO TIME LAG (YEARS) BETWEEN SURVEY AND UPDATING OF MAP. | H4: NO OF VILLAGES | J4: NO OF VILLAGES FOR WHICH | O4: DISTRICT | P4: NO. OF VILLAGES ANALYSED | Q4: NO. OF VILLAGES ACCORDING TO TIME LAG (YEARS) BETWEEN SURVEY AND UPDATING OF MAP. | V4: NO OF VILLAGES | X4: NO OF VILLAGES FOR WHICH
H5: UNSURVEYED AND INFORMATION NOT APPLICABLE | I5: FOR INFORMATION NOT AVAILABLE | J5: MAPS ARE AVAILABLE WITH PATWARI | M5: MAPS NOT AVAILABLE | V5: UNSURVEYED AND INFORMATION NOT APPLICABLE | W5: FOR INFORMATION NOT AVAILABLE | X5: MAPS ARE AVAILABLE WITH PATWARI | AA5: MAPS NOT AVAILABLE
C6: 1 | D6: 2 TO 5 | E6: 6 TO 10 | F6: 11 TO 20 | G6: ABOVE 20 | J6: USEABLE | K6: UN-USEABLE | L6: TOTAL | Q6: 1 | R6: 2 TO 5 | S6: 6 TO 10 | T6: 11 TO 20 | U6: ABOVE 20 | X6: USEABLE | Y6: UN-USEABLE | Z6: TOTAL
A7: 1 | B7: 2 | C7: 3 | D7: 4 | E7: 5 | F7: 6 | G7: 7 | H7: 8 | I7: 9 | J7: 10 | K7: 11 | L7: 12 | M7: 13 | O7: 1 | P7: 2 | Q7: 3 | R7: 4 | S7: 5 | T7: 6 | U7: 7 | V7: 8 | W7: 9 | X7: 10 | Y7: 11 | Z7: 12 | AA7: 13
A8: =IF(COUNTIFS(Basicdata!$B$2:$B$2500,1,Basicdata!$D$2:$D$2500,Crops!$D$5,Basicdata!$H$2:$H$2500,Crops!$M2,Basicdata!$AI$2:$AI$2500,0)>0,Crops!$M2,"") -> 1 | B8: =IF(A8="","",COUNTIFS(Basicdata!$B$2:$B$2500,1,Basicdata!$D$2:$D$2500,Crops!$D$5,Basicdata!$H$2:$H$2500,Crops!$M2,Basicdata!$AI$2:$AI$2500,0)) -> 17 | C8: =IF(A8="","",COUNTIFS(Basicdata!$B$2:$B$2500,1,Basicdata!$D$2:$D$2500,Crops!$D$5,Basicdata!$H$2:$H$2500,Crops!$M2,Basicdata!$O$2:$O$2500,1,Basicdata!$AI$2:$AI$2500,0)) -> 0 | D8: =IF(A8="","",COUNTIFS(Basicdata!$B$2:$B$2500,1,Basicdata!$D$2:$D$2500,Crops!$D$5,Basicdata!$H$2:$H$2500,Crops!$M2,Basicdata!$O$2:$O$2500,2,Basicdata!$AI$2:$AI$2500,0)) -> 0 | E8: =IF(A8="","",COUNTIFS(Basicdata!$B$2:$B$2500,1,Basicdata!$D$2:$D$2500,Crops!$D$5,Basicdata!$H$2:$H$2500,Crops!$M2,Basicdata!$O$2:$O$2500,3,Basicdata!$AI$2:$AI$2500,0)) -> 4 | F8: =IF(A8="","",COUNTIFS(Basicdata!$B$2:$B$2500,1,Basicdata!$D$2:$D$2500,Crops!$D$5,Basicdata!$H$2:$H$2500,Crops!$M2,Basicdata!$O$2:$O$2500,4,Basicdata!$AI$2:$AI$2500,0)) -> 1 | G8: =IF(A8="","",COUNTIFS(Basicdata!$B$2:$B$2500,1,Basicdata!$D$2:$D$2500,Crops!$D$5,Basicdata!$H$2:$H$2500,Crops!$M2,Basicdata!$O$2:$O$2500,5,Basicdata!$AI$2:$AI$2500,0)) -> 4 | H8: =IF(A8="","",COUNTIFS(Basicdata!$B$2:$B$2500,1,Basicdata!$D$2:$D$2500,Crops!$D$5,Basicdata!$H$2:$H$2500,Crops!$M2,Basicdata!$N$2:$N$2500,3,Basicdata!$AI$2:$AI$2500,0)) -> 4 | I8: =IF(A8="","",B8-C8-D8-E8-F8-G8-H8) -> 4 | J8: =IF(A8="","",COUNTIFS(Basicdata!$B$2:$B$2500,1,Basicdata!$D$2:$D$2500,Crops!$D$5,Basicdata!$H$2:$H$2500,Crops!$M2,Basicdata!$P$2:$P$2500,1,Basicdata!$Q$2:$Q$2500,1,Basicdata!$AI$2:$AI$2500,0)) -> 17 | K8: =IF(A8="","",COUNTIFS(Basicdata!$B$2:$B$2500,1,Basicdata!$D$2:$D$2500,Crops!$D$5,Basicdata!$H$2:$H$2500,Crops!$M2,Basicdata!$P$2:$P$2500,1,Basicdata!$Q$2:$Q$2500,0,Basicdata!$AI$2:$AI$2500,0)) -> 0 | L8: =IF(A8="","",J8+K8) -> 17 | M8: =IF(A8="","",B8-L8) -> 0 | O8: =IF(COUNTIFS(Basicdata!$B$2:$B$2500,2,Basicdata!$D$2:$D$2500,Crops!$D$5,Basicdata!$H$2:$H$2500,Crops!$M2,Basicdata!$AI$2:$AI$2500,0)>0,Crops!$M2,"") -> 1 | P8: =IF(O8="","",COUNTIFS(Basicdata!$B$2:$B$2500,2,Basicdata!$D$2:$D$2500,Crops!$D$5,Basicdata!$H$2:$H$2500,Crops!$M2,Basicdata!$AI$2:$AI$2500,0)) -> 17 | Q8: =IF(O8="","",COUNTIFS(Basicdata!$B$2:$B$2500,2,Basicdata!$D$2:$D$2500,Crops!$D$5,Basicdata!$H$2:$H$2500,Crops!$M2,Basicdata!$O$2:$O$2500,1,Basicdata!$AI$2:$AI$2500,0)) -> 0 | R8: =IF(O8="","",COUNTIFS(Basicdata!$B$2:$B$2500,2,Basicdata!$D$2:$D$2500,Crops!$D$5,Basicdata!$H$2:$H$2500,Crops!$M2,Basicdata!$O$2:$O$2500,2,Basicdata!$AI$2:$AI$2500,0)) -> 0 | S8: =IF(O8="","",COUNTIFS(Basicdata!$B$2:$B$2500,2,Basicdata!$D$2:$D$2500,Crops!$D$5,Basicdata!$H$2:$H$2500,Crops!$M2,Basicdata!$O$2:$O$2500,3,Basicdata!$AI$2:$AI$2500,0)) -> 0 | T8: =IF(O8="","",COUNTIFS(Basicdata!$B$2:$B$2500,2,Basicdata!$D$2:$D$2500,Crops!$D$5,Basicdata!$H$2:$H$2500,Crops!$M2,Basicdata!$O$2:$O$2500,4,Basicdata!$AI$2:$AI$2500,0)) -> 0 | U8: =IF(O8="","",COUNTIFS(Basicdata!$B$2:$B$2500,2,Basicdata!$D$2:$D$2500,Crops!$D$5,Basicdata!$H$2:$H$2500,Crops!$M2,Basicdata!$O$2:$O$2500,5,Basicdata!$AI$2:$AI$2500,0)) -> 17 | V8: =IF(O8="","",COUNTIFS(Basicdata!$B$2:$B$2500,2,Basicdata!$D$2:$D$2500,Crops!$D$5,Basicdata!$H$2:$H$2500,Crops!$M2,Basicdata!$N$2:$N$2500,3,Basicdata!$AI$2:$AI$2500,0)) -> 0 | W8: =IF(O8="","",P8-Q8-R8-S8-T8-U8-V8) -> 0 | X8: =IF(O8="","",COUNTIFS(Basicdata!$B$2:$B$2500,2,Basicdata!$D$2:$D$2500,Crops!$D$5,Basicdata!$H$2:$H$2500,Crops!$M2,Basicdata!$P$2:$P$2500,1,Basicdata!$Q$2:$Q$2500,1,Basicdata!$AI$2:$AI$2500,0)) -> 5 | Y8: =IF(O8="","",COUNTIFS(Basicdata!$B$2:$B$2500,2,Basicdata!$D$2:$D$2500,Crops!$D$5,Basicdata!$H$2:$H$2500,Crops!$M2,Basicdata!$P$2:$P$2500,1,Basicdata!$Q$2:$Q$2500,0,Basicdata!$AI$2:$AI$2500,0)) -> 0 | Z8: =IF(O8="","",X8+Y8) -> 5 | AA8: =IF(O8="","",P8-Z8) -> 12
A9: =IF(COUNTIFS(Basicdata!$B$2:$B$2500,1,Basicdata!$D$2:$D$2500,Crops!$D$5,Basicdata!$H$2:$H$2500,Crops!$M3,Basicdata!$AI$2:$AI$2500,0)>0,Crops!$M3,"") -> 2 | B9: =IF(A9="","",COUNTIFS(Basicdata!$B$2:$B$2500,1,Basicdata!$D$2:$D$2500,Crops!$D$5,Basicdata!$H$2:$H$2500,Crops!$M3,Basicdata!$AI$2:$AI$2500,0)) -> 32 | C9: =IF(A9="","",COUNTIFS(Basicdata!$B$2:$B$2500,1,Basicdata!$D$2:$D$2500,Crops!$D$5,Basicdata!$H$2:$H$2500,Crops!$M3,Basicdata!$O$2:$O$2500,1,Basicdata!$AI$2:$AI$2500,0)) -> 0 | D9: =IF(A9="","",COUNTIFS(Basicdata!$B$2:$B$2500,1,Basicdata!$D$2:$D$2500,Crops!$D$5,Basicdata!$H$2:$H$2500,Crops!$M3,Basicdata!$O$2:$O$2500,2,Basicdata!$AI$2:$AI$2500,0)) -> 25 | E9: =IF(A9="","",COUNTIFS(Basicdata!$B$2:$B$2500,1,Basicdata!$D$2:$D$2500,Crops!$D$5,Basicdata!$H$2:$H$2500,Crops!$M3,Basicdata!$O$2:$O$2500,3,Basicdata!$AI$2:$AI$2500,0)) -> 0 | F9: =IF(A9="","",COUNTIFS(Basicdata!$B$2:$B$2500,1,Basicdata!$D$2:$D$2500,Crops!$D$5,Basicdata!$H$2:$H$2500,Crops!$M3,Basicdata!$O$2:$O$2500,4,Basicdata!$AI$2:$AI$2500,0)) -> 7 | G9: =IF(A9="","",COUNTIFS(Basicdata!$B$2:$B$2500,1,Basicdata!$D$2:$D$2500,Crops!$D$5,Basicdata!$H$2:$H$2500,Crops!$M3,Basicdata!$O$2:$O$2500,5,Basicdata!$AI$2:$AI$2500,0)) -> 0 | H9: =IF(A9="","",COUNTIFS(Basicdata!$B$2:$B$2500,1,Basicdata!$D$2:$D$2500,Crops!$D$5,Basicdata!$H$2:$H$2500,Crops!$M3,Basicdata!$N$2:$N$2500,3,Basicdata!$AI$2:$AI$2500,0)) -> 0 | I9: =IF(A9="","",B9-C9-D9-E9-F9-G9-H9) -> 0 | J9: =IF(A9="","",COUNTIFS(Basicdata!$B$2:$B$2500,1,Basicdata!$D$2:$D$2500,Crops!$D$5,Basicdata!$H$2:$H$2500,Crops!$M3,Basicdata!$P$2:$P$2500,1,Basicdata!$Q$2:$Q$2500,1,Basicdata!$AI$2:$AI$2500,0)) -> 25 | K9: =IF(A9="","",COUNTIFS(Basicdata!$B$2:$B$2500,1,Basicdata!$D$2:$D$2500,Crops!$D$5,Basicdata!$H$2:$H$2500,Crops!$M3,Basicdata!$P$2:$P$2500,1,Basicdata!$Q$2:$Q$2500,0,Basicdata!$AI$2:$AI$2500,0)) -> 7 | L9: =IF(A9="","",J9+K9) -> 32 | M9: =IF(A9="","",B9-L9) -> 0 | O9: =IF(COUNTIFS(Basicdata!$B$2:$B$2500,2,Basicdata!$D$2:$D$2500,Crops!$D$5,Basicdata!$H$2:$H$2500,Crops!$M3,Basicdata!$AI$2:$AI$2500,0)>0,Crops!$M3,"") -> 2 | P9: =IF(O9="","",COUNTIFS(Basicdata!$B$2:$B$2500,2,Basicdata!$D$2:$D$2500,Crops!$D$5,Basicdata!$H$2:$H$2500,Crops!$M3,Basicdata!$AI$2:$AI$2500,0)) -> 33 | Q9: =IF(O9="","",COUNTIFS(Basicdata!$B$2:$B$2500,2,Basicdata!$D$2:$D$2500,Crops!$D$5,Basicdata!$H$2:$H$2500,Crops!$M3,Basicdata!$O$2:$O$2500,1,Basicdata!$AI$2:$AI$2500,0)) -> 0 | R9: =IF(O9="","",COUNTIFS(Basicdata!$B$2:$B$2500,2,Basicdata!$D$2:$D$2500,Crops!$D$5,Basicdata!$H$2:$H$2500,Crops!$M3,Basicdata!$O$2:$O$2500,2,Basicdata!$AI$2:$AI$2500,0)) -> 0 | S9: =IF(O9="","",COUNTIFS(Basicdata!$B$2:$B$2500,2,Basicdata!$D$2:$D$2500,Crops!$D$5,Basicdata!$H$2:$H$2500,Crops!$M3,Basicdata!$O$2:$O$2500,3,Basicdata!$AI$2:$AI$2500,0)) -> 0 | T9: =IF(O9="","",COUNTIFS(Basicdata!$B$2:$B$2500,2,Basicdata!$D$2:$D$2500,Crops!$D$5,Basicdata!$H$2:$H$2500,Crops!$M3,Basicdata!$O$2:$O$2500,4,Basicdata!$AI$2:$AI$2500,0)) -> 0 | U9: =IF(O9="","",COUNTIFS(Basicdata!$B$2:$B$2500,2,Basicdata!$D$2:$D$2500,Crops!$D$5,Basicdata!$H$2:$H$2500,Crops!$M3,Basicdata!$O$2:$O$2500,5,Basicdata!$AI$2:$AI$2500,0)) -> 0 | V9: =IF(O9="","",COUNTIFS(Basicdata!$B$2:$B$2500,2,Basicdata!$D$2:$D$2500,Crops!$D$5,Basicdata!$H$2:$H$2500,Crops!$M3,Basicdata!$N$2:$N$2500,3,Basicdata!$AI$2:$AI$2500,0)) -> 0 | W9: =IF(O9="","",P9-Q9-R9-S9-T9-U9-V9) -> 33 | X9: =IF(O9="","",COUNTIFS(Basicdata!$B$2:$B$2500,2,Basicdata!$D$2:$D$2500,Crops!$D$5,Basicdata!$H$2:$H$2500,Crops!$M3,Basicdata!$P$2:$P$2500,1,Basicdata!$Q$2:$Q$2500,1,Basicdata!$AI$2:$AI$2500,0)) -> 3 | Y9: =IF(O9="","",COUNTIFS(Basicdata!$B$2:$B$2500,2,Basicdata!$D$2:$D$2500,Crops!$D$5,Basicdata!$H$2:$H$2500,Crops!$M3,Basicdata!$P$2:$P$2500,1,Basicdata!$Q$2:$Q$2500,0,Basicdata!$AI$2:$AI$2500,0)) -> 24 | Z9: =IF(O9="","",X9+Y9) -> 27 | AA9: =IF(O9="","",P9-Z9) -> 6
A10: =IF(COUNTIFS(Basicdata!$B$2:$B$2500,1,Basicdata!$D$2:$D$2500,Crops!$D$5,Basicdata!$H$2:$H$2500,Crops!$M4,Basicdata!$AI$2:$AI$2500,0)>0,Crops!$M4,"") -> 3 | B10: =IF(A10="","",COUNTIFS(Basicdata!$B$2:$B$2500,1,Basicdata!$D$2:$D$2500,Crops!$D$5,Basicdata!$H$2:$H$2500,Crops!$M4,Basicdata!$AI$2:$AI$2500,0)) -> 18 | C10: =IF(A10="","",COUNTIFS(Basicdata!$B$2:$B$2500,1,Basicdata!$D$2:$D$2500,Crops!$D$5,Basicdata!$H$2:$H$2500,Crops!$M4,Basicdata!$O$2:$O$2500,1,Basicdata!$AI$2:$AI$2500,0)) -> 12 | D10: =IF(A10="","",COUNTIFS(Basicdata!$B$2:$B$2500,1,Basicdata!$D$2:$D$2500,Crops!$D$5,Basicdata!$H$2:$H$2500,Crops!$M4,Basicdata!$O$2:$O$2500,2,Basicdata!$AI$2:$AI$2500,0)) -> 4 | E10: =IF(A10="","",COUNTIFS(Basicdata!$B$2:$B$2500,1,Basicdata!$D$2:$D$2500,Crops!$D$5,Basicdata!$H$2:$H$2500,Crops!$M4,Basicdata!$O$2:$O$2500,3,Basicdata!$AI$2:$AI$2500,0)) -> 0 | F10: =IF(A10="","",COUNTIFS(Basicdata!$B$2:$B$2500,1,Basicdata!$D$2:$D$2500,Crops!$D$5,Basicdata!$H$2:$H$2500,Crops!$M4,Basicdata!$O$2:$O$2500,4,Basicdata!$AI$2:$AI$2500,0)) -> 2 | G10: =IF(A10="","",COUNTIFS(Basicdata!$B$2:$B$2500,1,Basicdata!$D$2:$D$2500,Crops!$D$5,Basicdata!$H$2:$H$2500,Crops!$M4,Basicdata!$O$2:$O$2500,5,Basicdata!$AI$2:$AI$2500,0)) -> 0 | H10: =IF(A10="","",COUNTIFS(Basicdata!$B$2:$B$2500,1,Basicdata!$D$2:$D$2500,Crops!$D$5,Basicdata!$H$2:$H$2500,Crops!$M4,Basicdata!$N$2:$N$2500,3,Basicdata!$AI$2:$AI$2500,0)) -> 0 | I10: =IF(A10="","",B10-C10-D10-E10-F10-G10-H10) -> 0 | J10: =IF(A10="","",COUNTIFS(Basicdata!$B$2:$B$2500,1,Basicdata!$D$2:$D$2500,Crops!$D$5,Basicdata!$H$2:$H$2500,Crops!$M4,Basicdata!$P$2:$P$2500,1,Basicdata!$Q$2:$Q$2500,1,Basicdata!$AI$2:$AI$2500,0)) -> 16 | K10: =IF(A10="","",COUNTIFS(Basicdata!$B$2:$B$2500,1,Basicdata!$D$2:$D$2500,Crops!$D$5,Basicdata!$H$2:$H$2500,Crops!$M4,Basicdata!$P$2:$P$2500,1,Basicdata!$Q$2:$Q$2500,0,Basicdata!$AI$2:$AI$2500,0)) -> 1 | L10: =IF(A10="","",J10+K10) -> 17 | M10: =IF(A10="","",B10-L10) -> 1 | O10: =IF(COUNTIFS(Basicdata!$B$2:$B$2500,2,Basicdata!$D$2:$D$2500,Crops!$D$5,Basicdata!$H$2:$H$2500,Crops!$M4,Basicdata!$AI$2:$AI$2500,0)>0,Crops!$M4,"") -> 3 | P10: =IF(O10="","",COUNTIFS(Basicdata!$B$2:$B$2500,2,Basicdata!$D$2:$D$2500,Crops!$D$5,Basicdata!$H$2:$H$2500,Crops!$M4,Basicdata!$AI$2:$AI$2500,0)) -> 18 | Q10: =IF(O10="","",COUNTIFS(Basicdata!$B$2:$B$2500,2,Basicdata!$D$2:$D$2500,Crops!$D$5,Basicdata!$H$2:$H$2500,Crops!$M4,Basicdata!$O$2:$O$2500,1,Basicdata!$AI$2:$AI$2500,0)) -> 0 | R10: =IF(O10="","",COUNTIFS(Basicdata!$B$2:$B$2500,2,Basicdata!$D$2:$D$2500,Crops!$D$5,Basicdata!$H$2:$H$2500,Crops!$M4,Basicdata!$O$2:$O$2500,2,Basicdata!$AI$2:$AI$2500,0)) -> 0 | S10: =IF(O10="","",COUNTIFS(Basicdata!$B$2:$B$2500,2,Basicdata!$D$2:$D$2500,Crops!$D$5,Basicdata!$H$2:$H$2500,Crops!$M4,Basicdata!$O$2:$O$2500,3,Basicdata!$AI$2:$AI$2500,0)) -> 0 | T10: =IF(O10="","",COUNTIFS(Basicdata!$B$2:$B$2500,2,Basicdata!$D$2:$D$2500,Crops!$D$5,Basicdata!$H$2:$H$2500,Crops!$M4,Basicdata!$O$2:$O$2500,4,Basicdata!$AI$2:$AI$2500,0)) -> 0 | U10: =IF(O10="","",COUNTIFS(Basicdata!$B$2:$B$2500,2,Basicdata!$D$2:$D$2500,Crops!$D$5,Basicdata!$H$2:$H$2500,Crops!$M4,Basicdata!$O$2:$O$2500,5,Basicdata!$AI$2:$AI$2500,0)) -> 1 | V10: =IF(O10="","",COUNTIFS(Basicdata!$B$2:$B$2500,2,Basicdata!$D$2:$D$2500,Crops!$D$5,Basicdata!$H$2:$H$2500,Crops!$M4,Basicdata!$N$2:$N$2500,3,Basicdata!$AI$2:$AI$2500,0)) -> 0 | W10: =IF(O10="","",P10-Q10-R10-S10-T10-U10-V10) -> 17 | X10: =IF(O10="","",COUNTIFS(Basicdata!$B$2:$B$2500,2,Basicdata!$D$2:$D$2500,Crops!$D$5,Basicdata!$H$2:$H$2500,Crops!$M4,Basicdata!$P$2:$P$2500,1,Basicdata!$Q$2:$Q$2500,1,Basicdata!$AI$2:$AI$2500,0)) -> 1 | Y10: =IF(O10="","",COUNTIFS(Basicdata!$B$2:$B$2500,2,Basicdata!$D$2:$D$2500,Crops!$D$5,Basicdata!$H$2:$H$2500,Crops!$M4,Basicdata!$P$2:$P$2500,1,Basicdata!$Q$2:$Q$2500,0,Basicdata!$AI$2:$AI$2500,0)) -> 0 | Z10: =IF(O10="","",X10+Y10) -> 1 | AA10: =IF(O10="","",P10-Z10) -> 17
