Workbook

Sheet common
B2: UT | C2: ='[1]Crops CY'!$A$2 -> PUDUCHERRY | H2: =CONCATENATE(B2," : ",C2) -> UT : PUDUCHERRY
B3: SEASON | C3: ='[1]Crops CY'!A$5 -> RABI I | D3: ='[1]Crops CY'!B$5 -> 4 | E3: ='[1]Crops CY'!C$5 -> RABI II | F3: ='[1]Crops CY'!D$5 -> 5 | H3: =CONCATENATE(B3," : ",C3) -> SEASON : RABI I | I3: =CONCATENATE(B3," : ",E3) -> SEASON : RABI II
B4: YEAR | C4: ='[1]Crops CY'!$B$3 -> 2024-25 | H4: =CONCATENATE($C$3," ",C4) -> RABI I 2024-25 | I4: =CONCATENATE($E$3," ",C4) -> RABI II 2024-25 | J4: =CONCATENATE($B$4," ",C4) -> YEAR 2024-25
B5: PREV. YEAR | C5: =CONCATENATE(LEFT(C4,4)-1,"-",RIGHT(C4,2)-1) -> 2023-24 | H5: =CONCATENATE($C$3," ",C5) -> RABI I 2023-24 | I5: =CONCATENATE($E$3," ",C5) -> RABI II 2023-24 | J5: =CONCATENATE($B$4," ",C5) -> YEAR 2023-24
C6: =CONCATENATE(LEFT(C5,4)-1,"-",RIGHT(C5,2)-1) -> 2022-23 | H6: =CONCATENATE($C$3," ",C6) -> RABI I 2022-23 | I6: =CONCATENATE($E$3," ",C6) -> RABI II 2022-23 | J6: =CONCATENATE($B$4," ",C6) -> YEAR 2022-23
C7: =CONCATENATE(LEFT(C6,4)-1,"-",RIGHT(C6,2)-1) -> 2021-22 | H7: =CONCATENATE($C$3," ",C7) -> RABI I 2021-22 | I7: =CONCATENATE($E$3," ",C7) -> RABI II 2021-22 | J7: =CONCATENATE($B$4," ",C7) -> YEAR 2021-22
C8: =CONCATENATE(LEFT(C7,4)-1,"-",RIGHT(C7,2)-1) -> 2020-21 | H8: =CONCATENATE($C$3," ",C8) -> RABI I 2020-21 | I8: =CONCATENATE($E$3," ",C8) -> RABI II 2020-21 | J8: =CONCATENATE($B$4," ",C8) -> YEAR 2020-21
B9: CROP | C9: ='[1]Crops CY'!A7 -> PADDY | D9: ='[1]Crops CY'!B7 -> 97 | E9: ='[1]Crops CY'!C7 -> PADDY | F9: ='[1]Crops CY'!D7 -> 98
C10: ='[1]Crops CY'!A8 -> OTHERS | D10: ='[1]Crops CY'!B8 -> 99 | E10: ='[1]Crops CY'!C8 -> OTHERS | F10: ='[1]Crops CY'!D8 -> 99
C11: ='[1]Crops CY'!A9 -> 0 | D11: ='[1]Crops CY'!B9 -> 0 | E11: ='[1]Crops CY'!C9 -> 0 | F11: ='[1]Crops CY'!D9 -> 0
C12: ='[1]Crops CY'!A10 -> 0 | D12: ='[1]Crops CY'!B10 -> 0 | E12: ='[1]Crops CY'!C10 -> 0 | F12: ='[1]Crops CY'!D10 -> 0
C13: ='[1]Crops CY'!A11 -> 0 | D13: ='[1]Crops CY'!B11 -> 0 | E13: ='[1]Crops CY'!C11 -> 0 | F13: ='[1]Crops CY'!D11 -> 0
C14: ='[1]Crops CY'!A12 -> 0 | D14: ='[1]Crops CY'!B12 -> 0 | E14: ='[1]Crops CY'!C12 -> 0 | F14: ='[1]Crops CY'!D12 -> 0
C15: ='[1]Crops CY'!A13 -> 0 | D15: ='[1]Crops CY'!B13 -> 0 | E15: ='[1]Crops CY'!C13 -> 0 | F15: ='[1]Crops CY'!D13 -> 0
C16: ='[1]Crops CY'!A14 -> 0 | D16: ='[1]Crops CY'!B14 -> 0 | E16: ='[1]Crops CY'!C14 -> 0 | F16: ='[1]Crops CY'!D14 -> 0
C17: ='[1]Crops CY'!A15 -> 0 | D17: ='[1]Crops CY'!B15 -> 0 | E17: ='[1]Crops CY'!C15 -> 0 | F17: ='[1]Crops CY'!D15 -> 0
C18: ='[1]Crops CY'!A16 -> 0 | D18: ='[1]Crops CY'!B16 -> 0 | E18: ='[1]Crops CY'!C16 -> 0 | F18: ='[1]Crops CY'!D16 -> 0

Sheet Annex-I
A1: A-1
A2: =common!$H$2 -> UT : PUDUCHERRY | G2: ='[1]Annex-1'!H2 -> ANNEX-I
A3: ='[1]Annex-1'!A3:I3 -> RESPONSE IN SAMPLE CHECK ON ENUMERATION OF AREA DURING 2024-25 AND 2023-24.
A4: YEAR/ SEASON/ AGENCY | B4: NO.OF VILLAGES PLANNED | C4: NO. ( % ) OF VILLAGES FOR WHICH SCHEDULES WERE RECEIVED | E4: NO. ( % ) OF SCHEDULES ANALYSED
E5: TOTAL | F5: WITH 'a' & 'b' ENTRIES TOGETHER | G5: WITH 'a' & 'b' ENTRIES SEPARATELY | H5: WITH 'a' ENTRIES ONLY
C6: TOTAL RECEIVED | D6: BY CUT OFF DATE
A7: (1) | B7: (2) | C7: (3) | D7: (4) | E7: (5) | F7: (6) | G7: (7) | H7: (8)
A8: =common!$H$4 -> RABI I 2024-25
A9: CENTRAL | B9: ='[1]Annex-1'!B9&" " -> 9 | C9: ='[1]Annex-1'!C9 -> 9(100.0) | D9: ='[1]Annex-1'!E9 -> 9(100.0) | E9: ='[1]Annex-1'!F9 -> 9(100.0) | F9: ='[1]Annex-1'!G9 -> 9(100.0) | G9: ='[1]Annex-1'!H9 -> 0( 0.0) | H9: ='[1]Annex-1'!I9 -> 0( 0.0)
A10: STATE | B10: ='[1]Annex-1'!B10&" " -> 9 | C10: ='[1]Annex-1'!C10 -> 9(100.0) | D10: ='[1]Annex-1'!E10 -> 9(100.0) | E10: ='[1]Annex-1'!F10 -> 9(100.0) | F10: ='[1]Annex-1'!G10 -> 9(100.0) | G10: ='[1]Annex-1'!H10 -> 0( 0.0) | H10: ='[1]Annex-1'!I10 -> 0( 0.0)
A11: POOLED | B11: ='[1]Annex-1'!B11&" " -> 18 | C11: ='[1]Annex-1'!C11 -> 18(100.0) | D11: ='[1]Annex-1'!E11 -> 18(100.0) | E11: ='[1]Annex-1'!F11 -> 18(100.0) | F11: ='[1]Annex-1'!G11 -> 18(100.0) | G11: ='[1]Annex-1'!H11 -> 0( 0.0) | H11: ='[1]Annex-1'!I11 -> 0( 0.0)
A12: =common!$I$4 -> RABI II 2024-25
A13: CENTRAL | B13: ='[1]Annex-1'!B13&" " -> 9 | C13: ='[1]Annex-1'!C13 -> 9(100.0) | D13: ='[1]Annex-1'!E13 -> 9(100.0) | E13: ='[1]Annex-1'!F13 -> 9(100.0) | F13: ='[1]Annex-1'!G13 -> 9(100.0) | G13: ='[1]Annex-1'!H13 -> 0( 0.0) | H13: ='[1]Annex-1'!I13 -> 0( 0.0)
A14: STATE | B14: ='[1]Annex-1'!B14&" " -> 9 | C14: ='[1]Annex-1'!C14 -> 9(100.0) | D14: ='[1]Annex-1'!E14 -> 9(100.0) | E14: ='[1]Annex-1'!F14 -> 9(100.0) | F14: ='[1]Annex-1'!G14 -> 9(100.0) | G14: ='[1]Annex-1'!H14 -> 0( 0.0) | H14: ='[1]Annex-1'!I14 -> 0( 0.0)
A15: POOLED | B15: ='[1]Annex-1'!B15&" " -> 18 | C15: ='[1]Annex-1'!C15 -> 18(100.0) | D15: ='[1]Annex-1'!E15 -> 18(100.0) | E15: ='[1]Annex-1'!F15 -> 18(100.0) | F15: ='[1]Annex-1'!G15 -> 18(100.0) | G15: ='[1]Annex-1'!H15 -> 0( 0.0) | H15: ='[1]Annex-1'!I15 -> 0( 0.0)
A16: =common!$H$5 -> RABI I 2023-24
A17: CENTRAL | B17: ='[1]Annex-1'!B18&" " -> 9 | C17: ='[1]Annex-1'!C18 -> 9(100.0) | D17: ='[1]Annex-1'!E18 -> 9(100.0) | E17: ='[1]Annex-1'!F18 -> 9(100.0) | F17: ='[1]Annex-1'!G18 -> 9(100.0) | G17: ='[1]Annex-1'!H18 -> 0( 0.0) | H17: ='[1]Annex-1'!I18 -> 0( 0.0)
A18: STATE | B18: ='[1]Annex-1'!B19&" " -> 9 | C18: ='[1]Annex-1'!C19 -> 9(100.0) | D18: ='[1]Annex-1'!E19 -> 9(100.0) | E18: ='[1]Annex-1'!F19 -> 9(100.0) | F18: ='[1]Annex-1'!G19 -> 9(100.0) | G18: ='[1]Annex-1'!H19 -> 0( 0.0) | H18: ='[1]Annex-1'!I19 -> 0( 0.0)
A19: POOLED | B19: ='[1]Annex-1'!B20&" " -> 18 | C19: ='[1]Annex-1'!C20 -> 18(100.0) | D19: ='[1]Annex-1'!E20 -> 18(100.0) | E19: ='[1]Annex-1'!F20 -> 18(100.0) | F19: ='[1]Annex-1'!G20 -> 18(100.0) | G19: ='[1]Annex-1'!H20 -> 0( 0.0) | H19: ='[1]Annex-1'!I20 -> 0( 0.0)
A20: =common!$I$5 -> RABI II 2023-24
A21: CENTRAL | B21: ='[1]Annex-1'!B22&" " -> 9 | C21: ='[1]Annex-1'!C22 -> 9(100.0) | D21: ='[1]Annex-1'!E22 -> 9(100.0) | E21: ='[1]Annex-1'!F22 -> 9(100.0) | F21: ='[1]Annex-1'!G22 -> 9(100.0) | G21: ='[1]Annex-1'!H22 -> 0( 0.0) | H21: ='[1]Annex-1'!I22 -> 0( 0.0)
A22: STATE | B22: ='[1]Annex-1'!B23&" " -> 9 | C22: ='[1]Annex-1'!C23 -> 9(100.0) | D22: ='[1]Annex-1'!E23 -> 9(100.0) | E22: ='[1]Annex-1'!F23 -> 9(100.0) | F22: ='[1]Annex-1'!G23 -> 9(100.0) | G22: ='[1]Annex-1'!H23 -> 0( 0.0) | H22: ='[1]Annex-1'!I23 -> 0( 0.0)
A23: POOLED | B23: ='[1]Annex-1'!B24&" " -> 18 | C23: ='[1]Annex-1'!C24 -> 18(100.0) | D23: ='[1]Annex-1'!E24 -> 18(100.0) | E23: ='[1]Annex-1'!F24 -> 18(100.0) | F23: ='[1]Annex-1'!G24 -> 18(100.0) | G23: ='[1]Annex-1'!H24 -> 0( 0.0) | H23: ='[1]Annex-1'!I24 -> 0( 0.0)

Sheet Annex-II
A1: A-2
A2: =common!$H$2 -> UT : PUDUCHERRY | C2: ='[1]Annex-2'!C2 -> ANNEX-II
A3: ='[1]Annex-2'!A3 -> INFORMATION REGARDING UPDATING OF VILLAGE MAPS AND THEIR USABILITY DURING 2024-25 AND 2023-24.
A4: NUMBER OF YEARS SINCE UPDATED | B4: NUMBER AND PERCENTAGE OF VILLAGES
B5: =common!$C$4 -> 2024-25 | C5: =common!$C$5 -> 2023-24
A6: (A) 1 TO 5 | B6: ='[1]Annex-2'!B6 -> 0( 0.0) | C6: ='[1]Annex-2'!C6 -> 0( 0.0)
A7: (B) 6 TO 10 | B7: ='[1]Annex-2'!B7 -> 0( 0.0) | C7: ='[1]Annex-2'!C7 -> 0( 0.0)
A8: (C) 11 TO 20 | B8: ='[1]Annex-2'!B8 -> 0( 0.0) | C8: ='[1]Annex-2'!C8 -> 0( 0.0)
A9: (D) MORE THAN 20 YEARS | B9: ='[1]Annex-2'!B9 -> 18(100.0) | C9: ='[1]Annex-2'!C9 -> 17( 94.4)
A10: (E) INFORMATION NOT AVAILABLE | B10: ='[1]Annex-2'!B10 -> 0( 0.0) | C10: ='[1]Annex-2'!C10 -> 1( 5.6)
A11: AVAILABILITY OF MAPS WITH PATWARI
A12: (A) MAPS AVAILABLE | B12: ='[1]Annex-2'!B13 -> 18(100.0) | C12: ='[1]Annex-2'!C13 -> 18(100.0)
A13: (I) USABLE MAPS | B13: ='[1]Annex-2'!B14 -> 18(100.0) | C13: ='[1]Annex-2'!C14 -> 18(100.0)
A14: (II) UNUSABLE MAPS | B14: ='[1]Annex-2'!B15 -> 0( 0.0) | C14: ='[1]Annex-2'!C15 -> 0( 0.0)
A15: (B) MAPS NOT AVAILABLE | B15: ='[1]Annex-2'!B16 -> 0( 0.0) | C15: ='[1]Annex-2'!C16 -> 0( 0.0)
A16: FIGURES IN () INDICATES %AGE TO NO. OF VILLAGES ANALYSED.

Sheet Annex-III
A1: A-3
A2: =common!$H$2 -> UT : PUDUCHERRY | B2: =common!$H$2 -> UT : PUDUCHERRY | C2: =common!$H$2 -> UT : PUDUCHERRY | D2: =common!$H$2 -> UT : PUDUCHERRY | E2: ='[1]Annex-3'!E2 -> ANNEX-III
A3: ='[1]Annex-3'!A3 -> WORK LOAD OF PATWARI DURING 2024-25 AND 2023-24.
A4: YEAR | B4: NO. OF VILLAGES | D4: SURVEY/ SUB-SURVEY NUMBERS PER VILLAGES | E4: GEOGRAPHICAL AREA (HA) PER VILLAGES
B5: TOTAL | C5: TRS (NO. AND % TO TOTAL)
A6: (1) | B6: (2) | C6: (3) | D6: (4) | E6: (5)
A7: =common!$C$4 -> 2024-25 | B7: =IF(INT('[1]Annex-3'!B7)='[1]Annex-3'!B7,'[1]Annex-3'!B7&".0",ROUND('[1]Annex-3'!B7,1)&" ") -> 10.4 | C7: ='[1]Annex-3'!C7 -> 1.9( 18.3) | D7: =ROUND('[1]Annex-3'!D7,0)&" " -> 1213 | E7: =IF(INT('[1]Annex-3'!E7)='[1]Annex-3'!E7,'[1]Annex-3'!E7&".0",ROUND('[1]Annex-3'!E7,1)&" ") -> 402.9
A8: =common!$C$5 -> 2023-24 | B8: =IF(INT('[1]Annex-3'!B8)='[1]Annex-3'!B8,'[1]Annex-3'!B8&".0",ROUND('[1]Annex-3'!B8,1)&" ") -> 10.2 | C8: ='[1]Annex-3'!C8 -> 1.8( 17.6) | D8: =ROUND('[1]Annex-3'!D8,0)&" " -> 1231 | E8: =IF(INT('[1]Annex-3'!E8)='[1]Annex-3'!E8,'[1]Annex-3'!E8&".0",ROUND('[1]Annex-3'!E8,1)&" ") -> 392.6

Sheet Annex-IV(a)
A1: A-4
A2: =common!$H$2 -> UT : PUDUCHERRY | B2: =common!$H$2 -> UT : PUDUCHERRY | C2: =common!$H$2 -> UT : PUDUCHERRY | D2: =common!$H$2 -> UT : PUDUCHERRY | E2: =common!$H$2 -> UT : PUDUCHERRY | F2: =common!$H$2 -> UT : PUDUCHERRY | G2: ='[1]Annex-4(a)'!G2 -> ANNEX-IV(a)
A3: ='[1]Annex-4(a)'!A3 -> NUMBER AND PERCENTAGE OF PATWARIS OF THE SELECTED VILLAGES ACCORDING TO THE TOTAL NUMBER OF VILLAGES ALLOTED DURING 2024-25 AND 2023-24.
A4: TOTAL | F4: TRS
A5: SL NO. | B5: TOTAL NO OF VILLAGES ALLOTED PER PATWARI | C5: FREQUENCY | D5: PERCENTAGE | F5: TOTAL NO OF VILLAGES ALLOTED PER PATWARI | G5: FREQUENCY | H5: PERCENTAGE
A6: (1) | B6: (2) | C6: (3) | D6: (4) | F6: (5) | G6: (6) | H6: (7)
A7: =common!$J$4 -> YEAR 2024-25
A8: 1 | B8: 1 TO 5 | C8: ='[1]Annex-4(a)'!C8&" " -> 0 | D8: =FIXED('[1]Annex-4(a)'!D8,1)&" " -> 0.0 | F8: 1 | G8: ='[1]Annex-4(a)'!G8&" " -> 1 | H8: =FIXED('[1]Annex-4(a)'!H8,1)&" " -> 5.6
A9: 2 | B9: 6 TO 10 | C9: ='[1]Annex-4(a)'!C9&" " -> 14 | D9: =FIXED('[1]Annex-4(a)'!D9,1)&" " -> 77.8 | F9: 2 | G9: ='[1]Annex-4(a)'!G9&" " -> 17 | H9: =FIXED('[1]Annex-4(a)'!H9,1)&" " -> 94.4
A10: 3 | B10: 11 TO 15 | C10: ='[1]Annex-4(a)'!C10&" " -> 4 | D10: =FIXED('[1]Annex-4(a)'!D10,1)&" " -> 22.2 | F10: 3 | G10: ='[1]Annex-4(a)'!G10&" " -> 0 | H10: =FIXED('[1]Annex-4(a)'!H10,1)&" " -> 0.0
A11: 4 | B11: ABOVE 15 | C11: ='[1]Annex-4(a)'!C11&" " -> 0 | D11: =FIXED('[1]Annex-4(a)'!D11,1)&" " -> 0.0 | F11: GREATER THAN 3 | G11: ='[1]Annex-4(a)'!G11&" " -> 0 | H11: =FIXED('[1]Annex-4(a)'!H11,1)&" " -> 0.0
A12: 5 | B12: I.N.A. | C12: ='[1]Annex-4(a)'!C12&" " -> 0 | D12: =FIXED('[1]Annex-4(a)'!D12,1)&" " -> 0.0 | F12: No TRS | G12: ='[1]Annex-4(a)'!G12&" " -> 0 | H12: =FIXED('[1]Annex-4(a)'!H12,1)&" " -> 0.0
F13: I.N.A. | G13: ='[1]Annex-4(a)'!G13&" " -> 0 | H13: =FIXED('[1]Annex-4(a)'!H13,1)&" " -> 0.0
A14: TOTAL | C14: ='[1]Annex-4(a)'!C14&" " -> 18 | D14: =FIXED('[1]Annex-4(a)'!D14,1)&" " -> 100.0 | F14: TOTAL | G14: ='[1]Annex-4(a)'!G14&" " -> 18 | H14: =FIXED('[1]Annex-4(a)'!H14,1)&" " -> 100.0
A15: =common!$J$5 -> YEAR 2023-24
A16: 1 | B16: 1 TO 5 | C16: ='[1]Annex-4(a)'!C16&" " -> 0 | D16: =FIXED('[1]Annex-4(a)'!D16,1)&" " -> 0.0 | F16: 1 | G16: ='[1]Annex-4(a)'!G16&" " -> 4 | H16: =FIXED('[1]Annex-4(a)'!H16,1)&" " -> 22.2
A17: 2 | B17: 6 TO 10 | C17: ='[1]Annex-4(a)'!C17&" " -> 12 | D17: =FIXED('[1]Annex-4(a)'!D17,1)&" " -> 66.7 | F17: 2 | G17: ='[1]Annex-4(a)'!G17&" " -> 14 | H17: =FIXED('[1]Annex-4(a)'!H17,1)&" " -> 77.8
A18: 3 | B18: 11 TO 15 | C18: ='[1]Annex-4(a)'!C18&" " -> 6 | D18: =FIXED('[1]Annex-4(a)'!D18,1)&" " -> 33.3 | F18: 3 | G18: ='[1]Annex-4(a)'!G18&" " -> 0 | H18: =FIXED('[1]Annex-4(a)'!H18,1)&" " -> 0.0
A19: 4 | B19: ABOVE 15 | C19: ='[1]Annex-4(a)'!C19&" " -> 0 | D19: =FIXED('[1]Annex-4(a)'!D19,1)&" " -> 0.0 | F19: GREATER THAN 3 | G19: ='[1]Annex-4(a)'!G19&" " -> 0 | H19: =FIXED('[1]Annex-4(a)'!H19,1)&" " -> 0.0
A20: 5 | B20: I.N.A. | C20: ='[1]Annex-4(a)'!C20&" " -> 0 | D20: =FIXED('[1]Annex-4(a)'!D20,1)&" " -> 0.0 | F20: No TRS | G20: ='[1]Annex-4(a)'!G20&" " -> 0 | H20: =FIXED('[1]Annex-4(a)'!H20,1)&" " -> 0.0
F21: I.N.A. | G21: ='[1]Annex-4(a)'!G21&" " -> 0 | H21: =FIXED('[1]Annex-4(a)'!H21,1)&" " -> 0.0
A22: TOTAL | C22: ='[1]Annex-4(a)'!C22&" " -> 18 | D22: =FIXED('[1]Annex-4(a)'!D22,1)&" " -> 100.0 | F22: TOTAL | G22: ='[1]Annex-4(a)'!G22&" " -> 18 | H22: =FIXED('[1]Annex-4(a)'!H22,1)&" " -> 100.0
A23: I.N.A. : INFORMATION NOT AVAILABLE

Sheet Annex-IV(b)
A1: A-5
A2: =common!$H$2 -> UT : PUDUCHERRY | G2: ='[1]Annex-4(b)'!G2 -> ANNEX-IV(b)
A3: ='[1]Annex-4(b)'!A3 -> DISTRIBUTION OF SAMPLE VILLAGES ACCORDING TO SL./SUB.SURVEY NOS. AND GEOGRAPHICAL AREA DURING 2024-25 AND 2023-24
A4: SL. NO. | B4: DISTRIBUTION OF VILLAGES ACCORDING TO SL./SUB-SURVEY NOS. | F4: DISTRIBUTION OF VILLAGES ACCORDING TO GEOGRAPHICAL AREA
B5: CLASS INT. (SL. / SUB SURVEY NOS.) | C5: NO. OF VILLAGES/ MOUZAS | D5: (%) 0.00 | F5: CLASS INT. (GEOGRAPHICAL AREA IN HA) | G5: NO. OF VILLAGES | H5: (%) 0.00
A6: (1) | B6: (2) | C6: (3) | D6: (4) | F6: (5) | G6: (6) | H6: (7)
A7: =common!$J$4 -> YEAR 2024-25
A8: 1 | B8: UP TO 50 | C8: ='[1]Annex-4(b)'!C8&" " -> 0 | D8: =FIXED('[1]Annex-4(b)'!D8,1)&" " -> 0.0 | F8: UP TO 50 | G8: ='[1]Annex-4(b)'!G8&" " -> 0 | H8: =FIXED('[1]Annex-4(b)'!H8,1)&" " -> 0.0
A9: 2 | B9: 51 to 100 | C9: ='[1]Annex-4(b)'!C9&" " -> 0 | D9: =FIXED('[1]Annex-4(b)'!D9,1)&" " -> 0.0 | F9: 51 to 100 | G9: ='[1]Annex-4(b)'!G9&" " -> 1 | H9: =FIXED('[1]Annex-4(b)'!H9,1)&" " -> 5.6
A10: 3 | B10: 101 to 200 | C10: ='[1]Annex-4(b)'!C10&" " -> 0 | D10: =FIXED('[1]Annex-4(b)'!D10,1)&" " -> 0.0 | F10: 101 to 200 | G10: ='[1]Annex-4(b)'!G10&" " -> 0 | H10: =FIXED('[1]Annex-4(b)'!H10,1)&" " -> 0.0
A11: 4 | B11: 201 to 400 | C11: ='[1]Annex-4(b)'!C11&" " -> 0 | D11: =FIXED('[1]Annex-4(b)'!D11,1)&" " -> 0.0 | F11: 201 to 400 | G11: ='[1]Annex-4(b)'!G11&" " -> 9 | H11: =FIXED('[1]Annex-4(b)'!H11,1)&" " -> 50.0
A12: 5 | B12: 401 to 600 | C12: ='[1]Annex-4(b)'!C12&" " -> 0 | D12: =FIXED('[1]Annex-4(b)'!D12,1)&" " -> 0.0 | F12: 401 to 600 | G12: ='[1]Annex-4(b)'!G12&" " -> 6 | H12: =FIXED('[1]Annex-4(b)'!H12,1)&" " -> 33.3
A13: 6 | B13: 601 to 800 | C13: ='[1]Annex-4(b)'!C13&" " -> 3 | D13: =FIXED('[1]Annex-4(b)'!D13,1)&" " -> 16.7 | F13: 601 to 800 | G13: ='[1]Annex-4(b)'!G13&" " -> 2 | H13: =FIXED('[1]Annex-4(b)'!H13,1)&" " -> 11.1
A14: 7 | B14: 801 to 1000 | C14: ='[1]Annex-4(b)'!C14&" " -> 3 | D14: =FIXED('[1]Annex-4(b)'!D14,1)&" " -> 16.7 | F14: 801 to 1000 | G14: ='[1]Annex-4(b)'!G14&" " -> 0 | H14: =FIXED('[1]Annex-4(b)'!H14,1)&" " -> 0.0
A15: 8 | B15: 1001 to 5000 | C15: ='[1]Annex-4(b)'!C15&" " -> 12 | D15: =FIXED('[1]Annex-4(b)'!D15,1)&" " -> 66.6 | F15: 1001 to 3000 | G15: ='[1]Annex-4(b)'!G15&" " -> 0 | H15: =FIXED('[1]Annex-4(b)'!H15,1)&" " -> 0.0
A16: 9 | B16: ABOVE 5000 | C16: ='[1]Annex-4(b)'!C16&" " -> 0 | D16: =FIXED('[1]Annex-4(b)'!D16,1)&" " -> 0.0 | F16: MORE THAN 3000 | G16: ='[1]Annex-4(b)'!G16&" " -> 0 | H16: =FIXED('[1]Annex-4(b)'!H16,1)&" " -> 0.0
A17: 10 | B17: NOT REPORTED | C17: ='[1]Annex-4(b)'!C17&" " -> 0 | D17: =FIXED('[1]Annex-4(b)'!D17,1)&" " -> 0.0 | F17: NOT REPORTED | G17: ='[1]Annex-4(b)'!G17&" " -> 0 | H17: =FIXED('[1]Annex-4(b)'!H17,1)&" " -> 0.0
A18: TOTAL | C18: ='[1]Annex-4(b)'!C18&" " -> 18 | D18: =FIXED('[1]Annex-4(b)'!D18,1)&" " -> 100.0 | F18: TOTAL | G18: ='[1]Annex-4(b)'!G18&" " -> 18 | H18: =FIXED('[1]Annex-4(b)'!H18,1)&" " -> 100.0
A19: =common!$J$5 -> YEAR 2023-24
A20: 1 | B20: UP TO 50 | C20: ='[1]Annex-4(b)'!C20&" " -> 0 | D20: =FIXED('[1]Annex-4(b)'!D20,1)&" " -> 0.0 | F20: UP TO 50 | G20: ='[1]Annex-4(b)'!G20&" " -> 0 | H20: =FIXED('[1]Annex-4(b)'!H20,1)&" " -> 0.0
A21: 2 | B21: 51 to 100 | C21: ='[1]Annex-4(b)'!C21&" " -> 0 | D21: =FIXED('[1]Annex-4(b)'!D21,1)&" " -> 0.0 | F21: 51 to 100 | G21: ='[1]Annex-4(b)'!G21&" " -> 0 | H21: =FIXED('[1]Annex-4(b)'!H21,1)&" " -> 0.0
A22: 3 | B22: 101 to 200 | C22: ='[1]Annex-4(b)'!C22&" " -> 0 | D22: =FIXED('[1]Annex-4(b)'!D22,1)&" " -> 0.0 | F22: 101 to 200 | G22: ='[1]Annex-4(b)'!G22&" " -> 2 | H22: =FIXED('[1]Annex-4(b)'!H22,1)&" " -> 11.1
A23: 4 | B23: 201 to 400 | C23: ='[1]Annex-4(b)'!C23&" " -> 0 | D23: =FIXED('[1]Annex-4(b)'!D23,1)&" " -> 0.0 | F23: 201 to 400 | G23: ='[1]Annex-4(b)'!G23&" " -> 8 | H23: =FIXED('[1]Annex-4(b)'!H23,1)&" " -> 44.4
A24: 5 | B24: 401 to 600 | C24: ='[1]Annex-4(b)'!C24&" " -> 2 | D24: =FIXED('[1]Annex-4(b)'!D24,1)&" " -> 11.1 | F24: 401 to 600 | G24: ='[1]Annex-4(b)'!G24&" " -> 6 | H24: =FIXED('[1]Annex-4(b)'!H24,1)&" " -> 33.3
A25: 6 | B25: 601 to 800 | C25: ='[1]Annex-4(b)'!C25&" " -> 0 | D25: =FIXED('[1]Annex-4(b)'!D25,1)&" " -> 0.0 | F25: 601 to 800 | G25: ='[1]Annex-4(b)'!G25&" " -> 1 | H25: =FIXED('[1]Annex-4(b)'!H25,1)&" " -> 5.6
A26: 7 | B26: 801 to 1000 | C26: ='[1]Annex-4(b)'!C26&" " -> 4 | D26: =FIXED('[1]Annex-4(b)'!D26,1)&" " -> 22.2 | F26: 801 to 1000 | G26: ='[1]Annex-4(b)'!G26&" " -> 1 | H26: =FIXED('[1]Annex-4(b)'!H26,1)&" " -> 5.6
A27: 8 | B27: 1001 to 5000 | C27: ='[1]Annex-4(b)'!C27&" " -> 12 | D27: =FIXED('[1]Annex-4(b)'!D27,1)&" " -> 66.7 | F27: 1001 to 3000 | G27: ='[1]Annex-4(b)'!G27&" " -> 0 | H27: =FIXED('[1]Annex-4(b)'!H27,1)&" " -> 0.0
A28: 9 | B28: ABOVE 5000 | C28: ='[1]Annex-4(b)'!C28&" " -> 0 | D28: =FIXED('[1]Annex-4(b)'!D28,1)&" " -> 0.0 | F28: MORE THAN 3000 | G28: ='[1]Annex-4(b)'!G28&" " -> 0 | H28: =FIXED('[1]Annex-4(b)'!H28,1)&" " -> 0.0
A29: 10 | B29: NOT REPORTED | C29: ='[1]Annex-4(b)'!C29&" " -> 0 | D29: =FIXED('[1]Annex-4(b)'!D29,1)&" " -> 0.0 | F29: NOT REPORTED | G29: ='[1]Annex-4(b)'!G29&" " -> 0 | H29: =FIXED('[1]Annex-4(b)'!H29,1)&" " -> 0.0
A30: TOTAL | C30: ='[1]Annex-4(b)'!C30&" " -> 18 | D30: =FIXED('[1]Annex-4(b)'!D30,1)&" " -> 100.0 | F30: TOTAL | G30: ='[1]Annex-4(b)'!G30&" " -> 18 | H30: =FIXED('[1]Annex-4(b)'!H30,1)&" " -> 100.0

Sheet Annex-V
A1: A-2
A2: =common!$H$2 -> UT : PUDUCHERRY | B2: =common!$H$2 -> UT : PUDUCHERRY | C2: =common!$H$2 -> UT : PUDUCHERRY | D2: =common!$H$2 -> UT : PUDUCHERRY | E2: =common!$H$2 -> UT : PUDUCHERRY | F2: =common!$H$2 -> UT : PUDUCHERRY | G2: =common!$H$2 -> UT : PUDUCHERRY | H2: =common!$H$2 -> UT : PUDUCHERRY | I2: =common!$H$2 -> UT : PUDUCHERRY | J2: ='[1]Annex-5'!J2 -> ANNEX-V
A3: ='[1]Annex-5'!A3 -> TIMELINESS IN COMPLETION OF TRS AREA ENUMERATION (NO. OF VILLAGES) DURING 2024-25 AND 2023-24.
A4: SEASON/ AGENCY | B4: NUMBER (PERCENTAGE) OF VILLAGES WHERE
B5: GIRDAWARI COMPLETED | E5: GIRDAWARI PARTIALLY COMPLETED | F5: GIRDAWARI NOT YET STARTED | G5: INFORMATION ABOUT COMPLETION OF GIRDAWARI NOT AVAILABLE | H5: SYSTEM OF GIRDAWARI DOES NOT EXIST | I5: TOTAL | J5: MAINTENANCE OF RECORDS
B6: IN TIME | C6: LATE | D6: BUT DATE OF COMPLETION NOT KNOWN | J6: LATEST FORM USED FOR GIRDAWARI | K6: RECORDS OF GIRDAWARI KEPT IN REGULAR FORM
A7: (1) | B7: (2) | C7: (3) | D7: (4) | E7: (5) | F7: (6) | G7: (7) | H7: (8) | I7: (9) | J7: (10) | K7: (11)
A8: =common!$H$4 -> RABI I 2024-25
A9: CENTRAL | B9: ='[1]Annex-5'!B9 -> 8( 88.9) | C9: ='[1]Annex-5'!C9 -> 1( 11.1) | D9: ='[1]Annex-5'!D9 -> 0( 0.0) | E9: ='[1]Annex-5'!E9 -> 0( 0.0) | F9: ='[1]Annex-5'!F9 -> 0( 0.0) | G9: ='[1]Annex-5'!G9 -> 0( 0.0) | H9: ='[1]Annex-5'!H9 -> 0( 0.0) | I9: ='[1]Annex-5'!I9 -> 9(100.0) | ... K9: ='[1]Annex-5'!K9 -> 9(100.0)
A10: STATE | B10: ='[1]Annex-5'!B10 -> 9(100.0) | C10: ='[1]Annex-5'!C10 -> 0( 0.0) | D10: ='[1]Annex-5'!D10 -> 0( 0.0) | E10: ='[1]Annex-5'!E10 -> 0( 0.0) | F10: ='[1]Annex-5'!F10 -> 0( 0.0) | G10: ='[1]Annex-5'!G10 -> 0( 0.0) | H10: ='[1]Annex-5'!H10 -> 0( 0.0) | I10: ='[1]Annex-5'!I10 -> 9(100.0) | ... K10: ='[1]Annex-5'!K10 -> 3( 33.3)
A11: POOLED | B11: ='[1]Annex-5'!B11 -> 17( 94.4) | C11: ='[1]Annex-5'!C11 -> 1( 5.6) | D11: ='[1]Annex-5'!D11 -> 0( 0.0) | E11: ='[1]Annex-5'!E11 -> 0( 0.0) | F11: ='[1]Annex-5'!F11 -> 0( 0.0) | G11: ='[1]Annex-5'!G11 -> 0( 0.0) | H11: ='[1]Annex-5'!H11 -> 0( 0.0) | I11: ='[1]Annex-5'!I11 -> 18(100.0) | ... K11: ='[1]Annex-5'!K11 -> 12( 66.7)
A12: =common!$I$4 -> RABI II 2024-25
A13: CENTRAL | B13: ='[1]Annex-5'!B13 -> 9(100.0) | C13: ='[1]Annex-5'!C13 -> 0( 0.0) | D13: ='[1]Annex-5'!D13 -> 0( 0.0) | E13: ='[1]Annex-5'!E13 -> 0( 0.0) | F13: ='[1]Annex-5'!F13 -> 0( 0.0) | G13: ='[1]Annex-5'!G13 -> 0( 0.0) | H13: ='[1]Annex-5'!H13 -> 0( 0.0) | I13: ='[1]Annex-5'!I13 -> 9(100.0) | ... K13: ='[1]Annex-5'!K13 -> 9(100.0)
A14: STATE | B14: ='[1]Annex-5'!B14 -> 9(100.0) | C14: ='[1]Annex-5'!C14 -> 0( 0.0) | D14: ='[1]Annex-5'!D14 -> 0( 0.0) | E14: ='[1]Annex-5'!E14 -> 0( 0.0) | F14: ='[1]Annex-5'!F14 -> 0( 0.0) | G14: ='[1]Annex-5'!G14 -> 0( 0.0) | H14: ='[1]Annex-5'!H14 -> 0( 0.0) | I14: ='[1]Annex-5'!I14 -> 9(100.0) | ... K14: ='[1]Annex-5'!K14 -> 5( 55.6)
A15: POOLED | B15: ='[1]Annex-5'!B15 -> 18(100.0) | C15: ='[1]Annex-5'!C15 -> 0( 0.0) | D15: ='[1]Annex-5'!D15 -> 0( 0.0) | E15: ='[1]Annex-5'!E15 -> 0( 0.0) | F15: ='[1]Annex-5'!F15 -> 0( 0.0) | G15: ='[1]Annex-5'!G15 -> 0( 0.0) | H15: ='[1]Annex-5'!H15 -> 0( 0.0) | I15: ='[1]Annex-5'!I15 -> 18(100.0) | ... K15: ='[1]Annex-5'!K15 -> 14( 77.8)
A16: =common!$H$5 -> RABI I 2023-24
A17: CENTRAL | B17: ='[1]Annex-5'!B18 -> 9(100.0) | C17: ='[1]Annex-5'!C18 -> 0( 0.0) | D17: ='[1]Annex-5'!D18 -> 0( 0.0) | E17: ='[1]Annex-5'!E18 -> 0( 0.0) | F17: ='[1]Annex-5'!F18 -> 0( 0.0) | G17: ='[1]Annex-5'!G18 -> 0( 0.0) | H17: ='[1]Annex-5'!H18 -> 0( 0.0) | I17: ='[1]Annex-5'!I18 -> 9(100.0) | ... K17: ='[1]Annex-5'!K18 -> 9(100.0)
A18: STATE | B18: ='[1]Annex-5'!B19 -> 9(100.0) | C18: ='[1]Annex-5'!C19 -> 0( 0.0) | D18: ='[1]Annex-5'!D19 -> 0( 0.0) | E18: ='[1]Annex-5'!E19 -> 0( 0.0) | F18: ='[1]Annex-5'!F19 -> 0( 0.0) | G18: ='[1]Annex-5'!G19 -> 0( 0.0) | H18: ='[1]Annex-5'!H19 -> 0( 0.0) | I18: ='[1]Annex-5'!I19 -> 9(100.0) | ... K18: ='[1]Annex-5'!K19 -> 9(100.0)
A19: POOLED | B19: ='[1]Annex-5'!B20 -> 18(100.0) | C19: ='[1]Annex-5'!C20 -> 0( 0.0) | D19: ='[1]Annex-5'!D20 -> 0( 0.0) | E19: ='[1]Annex-5'!E20 -> 0( 0.0) | F19: ='[1]Annex-5'!F20 -> 0( 0.0) | G19: ='[1]Annex-5'!G20 -> 0( 0.0) | H19: ='[1]Annex-5'!H20 -> 0( 0.0) | I19: ='[1]Annex-5'!I20 -> 18(100.0) | ... K19: ='[1]Annex-5'!K20 -> 18(100.0)
A20: =common!$I$5 -> RABI II 2023-24
A21: CENTRAL | B21: ='[1]Annex-5'!B22 -> 9(100.0) | C21: ='[1]Annex-5'!C22 -> 0( 0.0) | D21: ='[1]Annex-5'!D22 -> 0( 0.0) | E21: ='[1]Annex-5'!E22 -> 0( 0.0) | F21: ='[1]Annex-5'!F22 -> 0( 0.0) | G21: ='[1]Annex-5'!G22 -> 0( 0.0) | H21: ='[1]Annex-5'!H22 -> 0( 0.0) | I21: ='[1]Annex-5'!I22 -> 9(100.0) | ... K21: ='[1]Annex-5'!K22 -> 9(100.0)
A22: STATE | B22: ='[1]Annex-5'!B23 -> 9(100.0) | C22: ='[1]Annex-5'!C23 -> 0( 0.0) | D22: ='[1]Annex-5'!D23 -> 0( 0.0) | E22: ='[1]Annex-5'!E23 -> 0( 0.0) | F22: ='[1]Annex-5'!F23 -> 0( 0.0) | G22: ='[1]Annex-5'!G23 -> 0( 0.0) | H22: ='[1]Annex-5'!H23 -> 0( 0.0) | I22: ='[1]Annex-5'!I23 -> 9(100.0) | ... K22: ='[1]Annex-5'!K23 -> 9(100.0)
A23: POOLED | B23: ='[1]Annex-5'!B24 -> 18(100.0) | C23: ='[1]Annex-5'!C24 -> 0( 0.0) | D23: ='[1]Annex-5'!D24 -> 0( 0.0) | E23: ='[1]Annex-5'!E24 -> 0( 0.0) | F23: ='[1]Annex-5'!F24 -> 0( 0.0) | G23: ='[1]Annex-5'!G24 -> 0( 0.0) | H23: ='[1]Annex-5'!H24 -> 0( 0.0) | I23: ='[1]Annex-5'!I24 -> 18(100.0) | ... K23: ='[1]Annex-5'!K24 -> 18(100.0)

Sheet Annex-VI
A1: A-3
A2: =common!$H$2 -> UT : PUDUCHERRY | B2: =common!$H$2 -> UT : PUDUCHERRY | C2: =common!$H$2 -> UT : PUDUCHERRY | D2: =common!$H$2 -> UT : PUDUCHERRY | E2: =common!$H$2 -> UT : PUDUCHERRY | F2: =common!$H$2 -> UT : PUDUCHERRY | G2: =common!$H$2 -> UT : PUDUCHERRY | H2: =common!$H$2 -> UT : PUDUCHERRY | ... N2: =common!$H$2 -> UT : PUDUCHERRY | O2: ='[1]Annex-6'!O3 -> ANNEX-VI
A3: ='[1]Annex-6'!A4 -> TIMELINESS IN SUBMISSION OF TRS STATEMENTS DURING 2024-25 AND 2023-24
A4: SEASON / AGENCY | B4: TOTAL NO. OF VILLAGES ANALYSED | C4: NUMBER AND PERCENTAGE OF VILLAGES FOR WHICH
C5: TRS STATEMENT SUBMITTED | J5: TRS STATEMENT NOT SUBMITTED | N5: INFORMATION REGARDING TRS SUBMISSION NOT AVAILABLE | O5: TRS STATEMENT SUBMITTED IN STANDARD FORM | P5: DUPLICATE COPY OF THE TRS STATEMENT KEPT
C6: WITHOUT COMPLETING GIRDAWARI | E6: AFTER COMPLETING GIRDAWARI | G6: INFORMATION REGARDING TRS SUBMISSION DATE NOT KNOWN | H6: BUT COULD NOT BE COMPARED WITH GIRDAWARI COMPLETION | I6: TOTAL | J6: THOUGH GIRDAWARI COMPLETED | L6: GIRDAWARI NOT COMPLETED | M6: TOTAL
C7: BY DUE DATE | D7: AFTER DUE DATE | E7: BY DUE DATE | F7: AFTER DUE DATE | J7: AS DUE DATE NOT OVER | K7: OTHER REASONS
A8: (1) | B8: (2) | C8: (3) | D8: (4) | E8: (5) | F8: (6) | G8: (7) | H8: (8) | I8: (9) | J8: (10) | K8: (11) | L8: (12) | M8: (13) | N8: (14) | O8: (15) | P8: (16)
A9: =common!$H$4 -> RABI I 2024-25
A10: CENTRAL | B10: ='[1]Annex-6'!B11&" " -> 9 | C10: ='[1]Annex-6'!C11 -> 0( 0.0) | D10: ='[1]Annex-6'!D11 -> 0( 0.0) | E10: ='[1]Annex-6'!E11 -> 8( 88.9) | F10: ='[1]Annex-6'!F11 -> 1( 11.1) | G10: ='[1]Annex-6'!G11 -> 0( 0.0) | H10: ='[1]Annex-6'!H11 -> 0( 0.0) | I10: ='[1]Annex-6'!I11 -> 9(100.0) | J10: ='[1]Annex-6'!J11 -> 0( 0.0) | ... P10: ='[1]Annex-6'!P11 -> 9(100.0)
A11: STATE | B11: ='[1]Annex-6'!B12&" " -> 9 | C11: ='[1]Annex-6'!C12 -> 0( 0.0) | D11: ='[1]Annex-6'!D12 -> 0( 0.0) | E11: ='[1]Annex-6'!E12 -> 9(100.0) | F11: ='[1]Annex-6'!F12 -> 0( 0.0) | G11: ='[1]Annex-6'!G12 -> 0( 0.0) | H11: ='[1]Annex-6'!H12 -> 0( 0.0) | I11: ='[1]Annex-6'!I12 -> 9(100.0) | J11: ='[1]Annex-6'!J12 -> 0( 0.0) | ... P11: ='[1]Annex-6'!P12 -> 9(100.0)
A12: POOLED | B12: ='[1]Annex-6'!B13&" " -> 18 | C12: ='[1]Annex-6'!C13 -> 0( 0.0) | D12: ='[1]Annex-6'!D13 -> 0( 0.0) | E12: ='[1]Annex-6'!E13 -> 17( 94.4) | F12: ='[1]Annex-6'!F13 -> 1( 5.6) | G12: ='[1]Annex-6'!G13 -> 0( 0.0) | H12: ='[1]Annex-6'!H13 -> 0( 0.0) | I12: ='[1]Annex-6'!I13 -> 18(100.0) | J12: ='[1]Annex-6'!J13 -> 0( 0.0) | ... P12: ='[1]Annex-6'!P13 -> 18(100.0)
A13: =common!$I$4 -> RABI II 2024-25
A14: CENTRAL | B14: ='[1]Annex-6'!B15&" " -> 9 | C14: ='[1]Annex-6'!C15 -> 0( 0.0) | D14: ='[1]Annex-6'!D15 -> 0( 0.0) | E14: ='[1]Annex-6'!E15 -> 9(100.0) | F14: ='[1]Annex-6'!F15 -> 0( 0.0) | G14: ='[1]Annex-6'!G15 -> 0( 0.0) | H14: ='[1]Annex-6'!H15 -> 0( 0.0) | I14: ='[1]Annex-6'!I15 -> 9(100.0) | J14: ='[1]Annex-6'!J15 -> 0( 0.0) | ... P14: ='[1]Annex-6'!P15 -> 9(100.0)
A15: STATE | B15: ='[1]Annex-6'!B16&" " -> 9 | C15: ='[1]Annex-6'!C16 -> 0( 0.0) | D15: ='[1]Annex-6'!D16 -> 0( 0.0) | E15: ='[1]Annex-6'!E16 -> 9(100.0) | F15: ='[1]Annex-6'!F16 -> 0( 0.0) | G15: ='[1]Annex-6'!G16 -> 0( 0.0) | H15: ='[1]Annex-6'!H16 -> 0( 0.0) | I15: ='[1]Annex-6'!I16 -> 9(100.0) | J15: ='[1]Annex-6'!J16 -> 0( 0.0) | ... P15: ='[1]Annex-6'!P16 -> 9(100.0)
A16: POOLED | B16: ='[1]Annex-6'!B17&" " -> 18 | C16: ='[1]Annex-6'!C17 -> 0( 0.0) | D16: ='[1]Annex-6'!D17 -> 0( 0.0) | E16: ='[1]Annex-6'!E17 -> 18(100.0) | F16: ='[1]Annex-6'!F17 -> 0( 0.0) | G16: ='[1]Annex-6'!G17 -> 0( 0.0) | H16: ='[1]Annex-6'!H17 -> 0( 0.0) | I16: ='[1]Annex-6'!I17 -> 18(100.0) | J16: ='[1]Annex-6'!J17 -> 0( 0.0) | ... P16: ='[1]Annex-6'!P17 -> 18(100.0)
A17: =common!$H$5 -> RABI I 2023-24
A18: CENTRAL | B18: ='[1]Annex-6'!B20&" " -> 9 | C18: ='[1]Annex-6'!C20 -> 0( 0.0) | D18: ='[1]Annex-6'!D20 -> 0( 0.0) | E18: ='[1]Annex-6'!E20 -> 9(100.0) | F18: ='[1]Annex-6'!F20 -> 0( 0.0) | G18: ='[1]Annex-6'!G20 -> 0( 0.0) | H18: ='[1]Annex-6'!H20 -> 0( 0.0) | I18: ='[1]Annex-6'!I20 -> 9(100.0) | J18: ='[1]Annex-6'!J20 -> 0( 0.0) | ... P18: ='[1]Annex-6'!P20 -> 9(100.0)
A19: STATE | B19: ='[1]Annex-6'!B21&" " -> 9 | C19: ='[1]Annex-6'!C21 -> 0( 0.0) | D19: ='[1]Annex-6'!D21 -> 0( 0.0) | E19: ='[1]Annex-6'!E21 -> 9(100.0) | F19: ='[1]Annex-6'!F21 -> 0( 0.0) | G19: ='[1]Annex-6'!G21 -> 0( 0.0) | H19: ='[1]Annex-6'!H21 -> 0( 0.0) | I19: ='[1]Annex-6'!I21 -> 9(100.0) | J19: ='[1]Annex-6'!J21 -> 0( 0.0) | ... P19: ='[1]Annex-6'!P21 -> 9(100.0)
A20: POOLED | B20: ='[1]Annex-6'!B22&" " -> 18 | C20: ='[1]Annex-6'!C22 -> 0( 0.0) | D20: ='[1]Annex-6'!D22 -> 0( 0.0) | E20: ='[1]Annex-6'!E22 -> 18(100.0) | F20: ='[1]Annex-6'!F22 -> 0( 0.0) | G20: ='[1]Annex-6'!G22 -> 0( 0.0) | H20: ='[1]Annex-6'!H22 -> 0( 0.0) | I20: ='[1]Annex-6'!I22 -> 18(100.0) | J20: ='[1]Annex-6'!J22 -> 0( 0.0) | ... P20: ='[1]Annex-6'!P22 -> 18(100.0)
A21: =common!$I$5 -> RABI II 2023-24
A22: CENTRAL | B22: ='[1]Annex-6'!B24&" " -> 9 | C22: ='[1]Annex-6'!C24 -> 0( 0.0) | D22: ='[1]Annex-6'!D24 -> 0( 0.0) | E22: ='[1]Annex-6'!E24 -> 9(100.0) | F22: ='[1]Annex-6'!F24 -> 0( 0.0) | G22: ='[1]Annex-6'!G24 -> 0( 0.0) | H22: ='[1]Annex-6'!H24 -> 0( 0.0) | I22: ='[1]Annex-6'!I24 -> 9(100.0) | J22: ='[1]Annex-6'!J24 -> 0( 0.0) | ... P22: ='[1]Annex-6'!P24 -> 9(100.0)
A23: STATE | B23: ='[1]Annex-6'!B25&" " -> 9 | C23: ='[1]Annex-6'!C25 -> 0( 0.0) | D23: ='[1]Annex-6'!D25 -> 0( 0.0) | E23: ='[1]Annex-6'!E25 -> 9(100.0) | F23: ='[1]Annex-6'!F25 -> 0( 0.0) | G23: ='[1]Annex-6'!G25 -> 0( 0.0) | H23: ='[1]Annex-6'!H25 -> 0( 0.0) | I23: ='[1]Annex-6'!I25 -> 9(100.0) | J23: ='[1]Annex-6'!J25 -> 0( 0.0) | ... P23: ='[1]Annex-6'!P25 -> 9(100.0)
A24: POOLED | B24: ='[1]Annex-6'!B26&" " -> 18 | C24: ='[1]Annex-6'!C26 -> 0( 0.0) | D24: ='[1]Annex-6'!D26 -> 0( 0.0) | E24: ='[1]Annex-6'!E26 -> 18(100.0) | F24: ='[1]Annex-6'!F26 -> 0( 0.0) | G24: ='[1]Annex-6'!G26 -> 0( 0.0) | H24: ='[1]Annex-6'!H26 -> 0( 0.0) | I24: ='[1]Annex-6'!I26 -> 18(100.0) | J24: ='[1]Annex-6'!J26 -> 0( 0.0) | ... P24: ='[1]Annex-6'!P26 -> 18(100.0)

Sheet Annex-VII(a)
A1: A-4
A2: =common!$H$2 -> UT : PUDUCHERRY | D2: ='[1]Annex-7(a)'!D2 -> ANNEX-VII(a)
A3: ='[1]Annex-7(a)'!A3 -> AVAILABILITY OF FIGURES OF CROP AREA DURING 2024-25 AND 2023-24 (POOLED SAMPLE)
A4: YEAR/ SEASON | B4: NO. OF VILLAGES ANALYSED | C4: NO.(PERCENTAGE) OF VILLAGES FOR WHICH CROP AREA FIGURES WERE NOT AVAILABLE
C5: FOR CURRENT YEAR | D5: FOR PREVIOUS YEAR (FOR NON-TRS)
C6: FOR VILLAGE AS A WHOLE | D6: FOR SAMPLE CLUSTERS | E6: FOR VILLAGE AS A WHOLE
A7: (1) | B7: (2) | C7: (3) | D7: (4) | E7: (5)
A8: =common!$J$4 -> YEAR 2024-25
A9: ='[1]Annex-7(a)'!A10 -> RABI I | B9: ='[1]Annex-7(a)'!B10 -> 18 | C9: ='[1]Annex-7(a)'!C10 -> 0( 0.0) | D9: ='[1]Annex-7(a)'!D10 -> 5( 27.8) | E9: ='[1]Annex-7(a)'!E10 -> 0( 0.0)
A10: ='[1]Annex-7(a)'!A11 -> RABI II | B10: ='[1]Annex-7(a)'!B11 -> 18 | C10: ='[1]Annex-7(a)'!C11 -> 0( 0.0) | D10: ='[1]Annex-7(a)'!D11 -> 8( 44.4) | E10: ='[1]Annex-7(a)'!E11 -> 0( 0.0)
A11: =common!$J$5 -> YEAR 2023-24
A12: ='[1]Annex-7(a)'!A13 -> RABI I | B12: ='[1]Annex-7(a)'!B13 -> 18 | C12: ='[1]Annex-7(a)'!C13 -> 2( 11.1) | D12: ='[1]Annex-7(a)'!D13 -> 2( 11.1) | E12: ='[1]Annex-7(a)'!E13 -> 0( 0.0)
A13: ='[1]Annex-7(a)'!A14 -> RABI II | B13: ='[1]Annex-7(a)'!B14 -> 18 | C13: ='[1]Annex-7(a)'!C14 -> 0( 0.0) | D13: ='[1]Annex-7(a)'!D14 -> 7( 38.9) | E13: ='[1]Annex-7(a)'!E14 -> 0( 0.0)

Sheet Annex-VII(b)
A1: A-5
A2: =common!$H$2 -> UT : PUDUCHERRY | B2: =common!$H$2 -> UT : PUDUCHERRY | C2: =common!$H$2 -> UT : PUDUCHERRY | D2: =common!$H$2 -> UT : PUDUCHERRY | E2: =common!$H$2 -> UT : PUDUCHERRY | F2: ='[2]Annex-7(b)'!F2 -> ANNEX-VII(b)
A3: ='[2]Annex-7(b)'!A3 -> DISCREPANCIES IN RECORDING OF CROPS AND CROP AREAS DURING 0 AND 0.
A4: YEAR/ SEASON/ AGENCY | B4: NO. OF SURVEY / SUB SURVEY NUMBERS
B5: TOTAL | C5: WHERE CROP AREA TALLIED (E0) | D5: WHERE DISCREPANCIES OBSERVED
D6: CROP REPORTED BY SUPERVISOR BUT NOT REPORTED BY PATWARI (E1) | E6: CROP REPORTED BY PATWARI BUT NOT REPORTED BY SUPERVISOR (E2) | F6: CROP AREAS REPORTED BY SUPERVISOR AND PATWARI DIFFERED (E3) | G6: TOTAL COLS. (4+5+6)
A7: (1) | B7: (2) | C7: (3) | D7: (4) | E7: (5) | F7: (6) | G7: (7)
A8: =common!$H$4 -> RABI I 2024-25
A9: ='[2]Annex-7(b)'!A9 -> CENTRAL | B9: ='[2]Annex-7(b)'!B9&" " -> 52 | C9: ='[2]Annex-7(b)'!C9 -> 34( 65.4) | D9: ='[2]Annex-7(b)'!D9&" " -> 0( 0.0) | E9: ='[2]Annex-7(b)'!E9&" " -> 14( 26.9) | F9: ='[2]Annex-7(b)'!F9&" " -> 4( 7.7) | G9: ='[2]Annex-7(b)'!G9&" " -> 18( 34.6)
A10: ='[2]Annex-7(b)'!A10 -> STATE | B10: ='[2]Annex-7(b)'!B10&" " -> 182 | C10: ='[2]Annex-7(b)'!C10 -> 176( 96.7) | D10: ='[2]Annex-7(b)'!D10&" " -> 2( 1.1) | E10: ='[2]Annex-7(b)'!E10&" " -> 2( 1.1) | F10: ='[2]Annex-7(b)'!F10&" " -> 2( 1.1) | G10: ='[2]Annex-7(b)'!G10&" " -> 6( 3.3)
A11: ='[2]Annex-7(b)'!A11 -> POOLED | B11: ='[2]Annex-7(b)'!B11&" " -> 234 | C11: ='[2]Annex-7(b)'!C11 -> 210( 89.7) | D11: ='[2]Annex-7(b)'!D11&" " -> 2( 0.9) | E11: ='[2]Annex-7(b)'!E11&" " -> 16( 6.8) | F11: ='[2]Annex-7(b)'!F11&" " -> 6( 2.6) | G11: ='[2]Annex-7(b)'!G11&" " -> 24( 10.3)
A12: =common!$I$4 -> RABI II 2024-25
A13: ='[2]Annex-7(b)'!A13 -> CENTRAL | B13: ='[2]Annex-7(b)'!B13&" " -> 32 | C13: ='[2]Annex-7(b)'!C13 -> 20( 62.5) | D13: ='[2]Annex-7(b)'!D13&" " -> 0( 0.0) | E13: ='[2]Annex-7(b)'!E13&" " -> 12( 37.5) | F13: ='[2]Annex-7(b)'!F13&" " -> 0( 0.0) | G13: ='[2]Annex-7(b)'!G13&" " -> 12( 37.5)
A14: ='[2]Annex-7(b)'!A14 -> STATE | B14: ='[2]Annex-7(b)'!B14&" " -> 110 | C14: ='[2]Annex-7(b)'!C14 -> 108( 98.2) | D14: ='[2]Annex-7(b)'!D14&" " -> 0( 0.0) | E14: ='[2]Annex-7(b)'!E14&" " -> 0( 0.0) | F14: ='[2]Annex-7(b)'!F14&" " -> 2( 1.8) | G14: ='[2]Annex-7(b)'!G14&" " -> 2( 1.8)
A15: ='[2]Annex-7(b)'!A15 -> POOLED | B15: ='[2]Annex-7(b)'!B15&" " -> 142 | C15: ='[2]Annex-7(b)'!C15 -> 128( 90.1) | D15: ='[2]Annex-7(b)'!D15&" " -> 0( 0.0) | E15: ='[2]Annex-7(b)'!E15&" " -> 12( 8.5) | F15: ='[2]Annex-7(b)'!F15&" " -> 2( 1.4) | G15: ='[2]Annex-7(b)'!G15&" " -> 14( 9.9)
A16: =common!$H$5 -> RABI I 2023-24
A17: ='[2]Annex-7(b)'!A18 -> CENTRAL | B17: ='[2]Annex-7(b)'!B18&" " -> 50 | C17: ='[2]Annex-7(b)'!C18 -> 42( 84.0) | D17: ='[2]Annex-7(b)'!D18&" " -> 0( 0.0) | E17: ='[2]Annex-7(b)'!E18&" " -> 5( 10.0) | F17: ='[2]Annex-7(b)'!F18&" " -> 3( 6.0) | G17: ='[2]Annex-7(b)'!G18&" " -> 8( 16.0)
A18: ='[2]Annex-7(b)'!A19 -> STATE | B18: ='[2]Annex-7(b)'!B19&" " -> 37 | C18: ='[2]Annex-7(b)'!C19 -> 37(100.0) | D18: ='[2]Annex-7(b)'!D19&" " -> 0( 0.0) | E18: ='[2]Annex-7(b)'!E19&" " -> 0( 0.0) | F18: ='[2]Annex-7(b)'!F19&" " -> 0( 0.0) | G18: ='[2]Annex-7(b)'!G19&" " -> 0( 0.0)
A19: ='[2]Annex-7(b)'!A20 -> POOLED | B19: ='[2]Annex-7(b)'!B20&" " -> 87 | C19: ='[2]Annex-7(b)'!C20 -> 79( 90.9) | D19: ='[2]Annex-7(b)'!D20&" " -> 0( 0.0) | E19: ='[2]Annex-7(b)'!E20&" " -> 5( 5.7) | F19: ='[2]Annex-7(b)'!F20&" " -> 3( 3.4) | G19: ='[2]Annex-7(b)'!G20&" " -> 8( 9.1)
A20: =common!$I$5 -> RABI II 2023-24
A21: ='[2]Annex-7(b)'!A22 -> CENTRAL | B21: ='[2]Annex-7(b)'!B22&" " -> 35 | C21: ='[2]Annex-7(b)'!C22 -> 31( 88.6) | D21: ='[2]Annex-7(b)'!D22&" " -> 0( 0.0) | E21: ='[2]Annex-7(b)'!E22&" " -> 4( 11.4) | F21: ='[2]Annex-7(b)'!F22&" " -> 0( 0.0) | G21: ='[2]Annex-7(b)'!G22&" " -> 4( 11.4)
A22: ='[2]Annex-7(b)'!A23 -> STATE | B22: ='[2]Annex-7(b)'!B23&" " -> 44 | C22: ='[2]Annex-7(b)'!C23 -> 43( 97.7) | D22: ='[2]Annex-7(b)'!D23&" " -> 0( 0.0) | E22: ='[2]Annex-7(b)'!E23&" " -> 0( 0.0) | F22: ='[2]Annex-7(b)'!F23&" " -> 1( 2.3) | G22: ='[2]Annex-7(b)'!G23&" " -> 1( 2.3)
A23: ='[2]Annex-7(b)'!A24 -> POOLED | B23: ='[2]Annex-7(b)'!B24&" " -> 79 | C23: ='[2]Annex-7(b)'!C24 -> 74( 93.6) | D23: ='[2]Annex-7(b)'!D24&" " -> 0( 0.0) | E23: ='[2]Annex-7(b)'!E24&" " -> 4( 5.1) | F23: ='[2]Annex-7(b)'!F24&" " -> 1( 1.3) | G23: ='[2]Annex-7(b)'!G24&" " -> 5( 6.4)

Sheet Annex-VIII
A1: A-6
A2: =common!$H$2 -> UT : PUDUCHERRY | B2: =common!$H$2 -> UT : PUDUCHERRY | C2: =common!$H$2 -> UT : PUDUCHERRY | D2: =common!$H$2 -> UT : PUDUCHERRY | E2: =common!$H$2 -> UT : PUDUCHERRY | F2: =common!$H$2 -> UT : PUDUCHERRY | G2: ='[3]Annex-8'!$G$3 -> ANNEX-VIII
A3: ='[3]Annex-8'!$A$4 -> IMPACT OF DISCREPANCIES IN RECORDING AREA UNDER CROPS DURING 0 AND 0.
A4: SEASON/ CROP | B4: AREA IN HECTARES AS OBSERVED IN SAMPLE CLUSTERS
B5: CENTRAL SAMPLE | D5: STATE SAMPLE | F5: POOLED SAMPLE | H5: IMPACT OF DISCREPANCIES (b-a/a)*100 (POOLED SAMPLE ONLY)
B6: AS PER SUPERVISOR | C6: AS PER PATWARI | D6: AS PER SUPERVISOR | E6: AS PER PATWARI | F6: AS PER SUPERVISOR (a) | G6: AS PER PATWARI (b)
A7: ='[3]Annex-8'!A$8 -> (1) | B7: ='[3]Annex-8'!B$8 -> (2) | C7: ='[3]Annex-8'!C$8 -> (3) | D7: ='[3]Annex-8'!D$8 -> (4) | E7: ='[3]Annex-8'!E$8 -> (5) | F7: ='[3]Annex-8'!F$8 -> (6) | G7: ='[3]Annex-8'!G$8 -> (7) | H7: ='[3]Annex-8'!I$8 -> (8)
A8: =common!$H$4 -> RABI I 2024-25
A9: =IF([4]Crops!$A7="","",[4]Crops!$A7) -> PADDY | B9: =IF(INT('[3]Annex-8'!B10)='[3]Annex-8'!B10,'[3]Annex-8'!B10&".00 ",IF(INT('[3]Annex-8'!B10*10)='[3]Annex-8'!B10*10,'[3]Annex-8'!B10&"0 ",ROUND('[3]Annex-8'!B10,2)&" ")) -> 4.46 | C9: =IF(INT('[3]Annex-8'!C10)='[3]Annex-8'!C10,'[3]Annex-8'!C10&".00 ",IF(INT('[3]Annex-8'!C10*10)='[3]Annex-8'!C10*10,'[3]Annex-8'!C10&"0 ",ROUND('[3]Annex-8'!C10,2)&" ")) -> 4.59 | D9: =IF(INT('[3]Annex-8'!D10)='[3]Annex-8'!D10,'[3]Annex-8'!D10&".00 ",IF(INT('[3]Annex-8'!D10*10)='[3]Annex-8'!D10*10,'[3]Annex-8'!D10&"0 ",ROUND('[3]Annex-8'!D10,2)&" ")) -> 15.62 | E9: =IF(INT('[3]Annex-8'!E10)='[3]Annex-8'!E10,'[3]Annex-8'!E10&".00 ",IF(INT('[3]Annex-8'!E10*10)='[3]Annex-8'!E10*10,'[3]Annex-8'!E10&"0 ",ROUND('[3]Annex-8'!E10,2)&" ")) -> 15.51 | F9: =IF(INT('[3]Annex-8'!F10)='[3]Annex-8'!F10,'[3]Annex-8'!F10&".00 ",IF(INT('[3]Annex-8'!F10*10)='[3]Annex-8'!F10*10,'[3]Annex-8'!F10&"0 ",ROUND('[3]Annex-8'!F10,2)&" ")) -> 20.08 | G9: =IF(INT('[3]Annex-8'!G10)='[3]Annex-8'!G10,'[3]Annex-8'!G10&".00 ",IF(INT('[3]Annex-8'!G10*10)='[3]Annex-8'!G10*10,'[3]Annex-8'!G10&"0 ",ROUND('[3]Annex-8'!G10,2)&" ")) -> 20.1 | H9: =IF('[3]Annex-8'!H10<0,"(-)"&FIXED(ABS('[3]Annex-8'!H10),2)&" ",FIXED('[3]Annex-8'!H10,2)&" ") -> 0.10
A10: =IF([4]Crops!$A8="","",[4]Crops!$A8) -> OTHERS | B10: =IF(INT('[3]Annex-8'!B11)='[3]Annex-8'!B11,'[3]Annex-8'!B11&".00 ",IF(INT('[3]Annex-8'!B11*10)='[3]Annex-8'!B11*10,'[3]Annex-8'!B11&"0 ",ROUND('[3]Annex-8'!B11,2)&" ")) -> 1.73 | C10: =IF(INT('[3]Annex-8'!C11)='[3]Annex-8'!C11,'[3]Annex-8'!C11&".00 ",IF(INT('[3]Annex-8'!C11*10)='[3]Annex-8'!C11*10,'[3]Annex-8'!C11&"0 ",ROUND('[3]Annex-8'!C11,2)&" ")) -> 2.59 | D10: =IF(INT('[3]Annex-8'!D11)='[3]Annex-8'!D11,'[3]Annex-8'!D11&".00 ",IF(INT('[3]Annex-8'!D11*10)='[3]Annex-8'!D11*10,'[3]Annex-8'!D11&"0 ",ROUND('[3]Annex-8'!D11,2)&" ")) -> 5.89 | E10: =IF(INT('[3]Annex-8'!E11)='[3]Annex-8'!E11,'[3]Annex-8'!E11&".00 ",IF(INT('[3]Annex-8'!E11*10)='[3]Annex-8'!E11*10,'[3]Annex-8'!E11&"0 ",ROUND('[3]Annex-8'!E11,2)&" ")) -> 5.99 | F10: =IF(INT('[3]Annex-8'!F11)='[3]Annex-8'!F11,'[3]Annex-8'!F11&".00 ",IF(INT('[3]Annex-8'!F11*10)='[3]Annex-8'!F11*10,'[3]Annex-8'!F11&"0 ",ROUND('[3]Annex-8'!F11,2)&" ")) -> 7.62 | G10: =IF(INT('[3]Annex-8'!G11)='[3]Annex-8'!G11,'[3]Annex-8'!G11&".00 ",IF(INT('[3]Annex-8'!G11*10)='[3]Annex-8'!G11*10,'[3]Annex-8'!G11&"0 ",ROUND('[3]Annex-8'!G11,2)&" ")) -> 8.58 | H10: =IF('[3]Annex-8'!H11<0,"(-)"&FIXED(ABS('[3]Annex-8'!H11),2)&" ",FIXED('[3]Annex-8'!H11,2)&" ") -> 12.70
A11: =IF([4]Crops!$A9="","",[4]Crops!$A9) | B11: =IF(INT('[3]Annex-8'!B12)='[3]Annex-8'!B12,'[3]Annex-8'!B12&".00 ",IF(INT('[3]Annex-8'!B12*10)='[3]Annex-8'!B12*10,'[3]Annex-8'!B12&"0 ",ROUND('[3]Annex-8'!B12,2)&" ")) -> #VALUE! | C11: =IF(INT('[3]Annex-8'!C12)='[3]Annex-8'!C12,'[3]Annex-8'!C12&".00 ",IF(INT('[3]Annex-8'!C12*10)='[3]Annex-8'!C12*10,'[3]Annex-8'!C12&"0 ",ROUND('[3]Annex-8'!C12,2)&" ")) -> #VALUE! | D11: =IF(INT('[3]Annex-8'!D12)='[3]Annex-8'!D12,'[3]Annex-8'!D12&".00 ",IF(INT('[3]Annex-8'!D12*10)='[3]Annex-8'!D12*10,'[3]Annex-8'!D12&"0 ",ROUND('[3]Annex-8'!D12,2)&" ")) -> #VALUE! | E11: =IF(INT('[3]Annex-8'!E12)='[3]Annex-8'!E12,'[3]Annex-8'!E12&".00 ",IF(INT('[3]Annex-8'!E12*10)='[3]Annex-8'!E12*10,'[3]Annex-8'!E12&"0 ",ROUND('[3]Annex-8'!E12,2)&" ")) -> #VALUE! | F11: =IF(INT('[3]Annex-8'!F12)='[3]Annex-8'!F12,'[3]Annex-8'!F12&".00 ",IF(INT('[3]Annex-8'!F12*10)='[3]Annex-8'!F12*10,'[3]Annex-8'!F12&"0 ",ROUND('[3]Annex-8'!F12,2)&" ")) -> #VALUE! | G11: =IF(INT('[3]Annex-8'!G12)='[3]Annex-8'!G12,'[3]Annex-8'!G12&".00 ",IF(INT('[3]Annex-8'!G12*10)='[3]Annex-8'!G12*10,'[3]Annex-8'!G12&"0 ",ROUND('[3]Annex-8'!G12,2)&" ")) -> #VALUE! | H11: =IF('[3]Annex-8'!H12<0,"(-)"&FIXED(ABS('[3]Annex-8'!H12),2)&" ",FIXED('[3]Annex-8'!H12,2)&" ") -> #VALUE!
A12: =IF([4]Crops!$A10="","",[4]Crops!$A10) | B12: =IF(INT('[3]Annex-8'!B13)='[3]Annex-8'!B13,'[3]Annex-8'!B13&".00 ",IF(INT('[3]Annex-8'!B13*10)='[3]Annex-8'!B13*10,'[3]Annex-8'!B13&"0 ",ROUND('[3]Annex-8'!B13,2)&" ")) -> #VALUE! | C12: =IF(INT('[3]Annex-8'!C13)='[3]Annex-8'!C13,'[3]Annex-8'!C13&".00 ",IF(INT('[3]Annex-8'!C13*10)='[3]Annex-8'!C13*10,'[3]Annex-8'!C13&"0 ",ROUND('[3]Annex-8'!C13,2)&" ")) -> #VALUE! | D12: =IF(INT('[3]Annex-8'!D13)='[3]Annex-8'!D13,'[3]Annex-8'!D13&".00 ",IF(INT('[3]Annex-8'!D13*10)='[3]Annex-8'!D13*10,'[3]Annex-8'!D13&"0 ",ROUND('[3]Annex-8'!D13,2)&" ")) -> #VALUE! | E12: =IF(INT('[3]Annex-8'!E13)='[3]Annex-8'!E13,'[3]Annex-8'!E13&".00 ",IF(INT('[3]Annex-8'!E13*10)='[3]Annex-8'!E13*10,'[3]Annex-8'!E13&"0 ",ROUND('[3]Annex-8'!E13,2)&" ")) -> #VALUE! | F12: =IF(INT('[3]Annex-8'!F13)='[3]Annex-8'!F13,'[3]Annex-8'!F13&".00 ",IF(INT('[3]Annex-8'!F13*10)='[3]Annex-8'!F13*10,'[3]Annex-8'!F13&"0 ",ROUND('[3]Annex-8'!F13,2)&" ")) -> #VALUE! | G12: =IF(INT('[3]Annex-8'!G13)='[3]Annex-8'!G13,'[3]Annex-8'!G13&".00 ",IF(INT('[3]Annex-8'!G13*10)='[3]Annex-8'!G13*10,'[3]Annex-8'!G13&"0 ",ROUND('[3]Annex-8'!G13,2)&" ")) -> #VALUE! | H12: =IF('[3]Annex-8'!H13<0,"(-)"&FIXED(ABS('[3]Annex-8'!H13),2)&" ",FIXED('[3]Annex-8'!H13,2)&" ") -> #VALUE!
A13: =IF([4]Crops!$A11="","",[4]Crops!$A11) | B13: =IF(INT('[3]Annex-8'!B14)='[3]Annex-8'!B14,'[3]Annex-8'!B14&".00 ",IF(INT('[3]Annex-8'!B14*10)='[3]Annex-8'!B14*10,'[3]Annex-8'!B14&"0 ",ROUND('[3]Annex-8'!B14,2)&" ")) -> #VALUE! | C13: =IF(INT('[3]Annex-8'!C14)='[3]Annex-8'!C14,'[3]Annex-8'!C14&".00 ",IF(INT('[3]Annex-8'!C14*10)='[3]Annex-8'!C14*10,'[3]Annex-8'!C14&"0 ",ROUND('[3]Annex-8'!C14,2)&" ")) -> #VALUE! | D13: =IF(INT('[3]Annex-8'!D14)='[3]Annex-8'!D14,'[3]Annex-8'!D14&".00 ",IF(INT('[3]Annex-8'!D14*10)='[3]Annex-8'!D14*10,'[3]Annex-8'!D14&"0 ",ROUND('[3]Annex-8'!D14,2)&" ")) -> #VALUE! | E13: =IF(INT('[3]Annex-8'!E14)='[3]Annex-8'!E14,'[3]Annex-8'!E14&".00 ",IF(INT('[3]Annex-8'!E14*10)='[3]Annex-8'!E14*10,'[3]Annex-8'!E14&"0 ",ROUND('[3]Annex-8'!E14,2)&" ")) -> #VALUE! | F13: =IF(INT('[3]Annex-8'!F14)='[3]Annex-8'!F14,'[3]Annex-8'!F14&".00 ",IF(INT('[3]Annex-8'!F14*10)='[3]Annex-8'!F14*10,'[3]Annex-8'!F14&"0 ",ROUND('[3]Annex-8'!F14,2)&" ")) -> #VALUE! | G13: =IF(INT('[3]Annex-8'!G14)='[3]Annex-8'!G14,'[3]Annex-8'!G14&".00 ",IF(INT('[3]Annex-8'!G14*10)='[3]Annex-8'!G14*10,'[3]Annex-8'!G14&"0 ",ROUND('[3]Annex-8'!G14,2)&" ")) -> #VALUE! | H13: =IF('[3]Annex-8'!H14<0,"(-)"&FIXED(ABS('[3]Annex-8'!H14),2)&" ",FIXED('[3]Annex-8'!H14,2)&" ") -> #VALUE!
A14: =IF([4]Crops!$A12="","",[4]Crops!$A12) | B14: =IF(INT('[3]Annex-8'!B15)='[3]Annex-8'!B15,'[3]Annex-8'!B15&".00 ",IF(INT('[3]Annex-8'!B15*10)='[3]Annex-8'!B15*10,'[3]Annex-8'!B15&"0 ",ROUND('[3]Annex-8'!B15,2)&" ")) -> #VALUE! | C14: =IF(INT('[3]Annex-8'!C15)='[3]Annex-8'!C15,'[3]Annex-8'!C15&".00 ",IF(INT('[3]Annex-8'!C15*10)='[3]Annex-8'!C15*10,'[3]Annex-8'!C15&"0 ",ROUND('[3]Annex-8'!C15,2)&" ")) -> #VALUE! | D14: =IF(INT('[3]Annex-8'!D15)='[3]Annex-8'!D15,'[3]Annex-8'!D15&".00 ",IF(INT('[3]Annex-8'!D15*10)='[3]Annex-8'!D15*10,'[3]Annex-8'!D15&"0 ",ROUND('[3]Annex-8'!D15,2)&" ")) -> #VALUE! | E14: =IF(INT('[3]Annex-8'!E15)='[3]Annex-8'!E15,'[3]Annex-8'!E15&".00 ",IF(INT('[3]Annex-8'!E15*10)='[3]Annex-8'!E15*10,'[3]Annex-8'!E15&"0 ",ROUND('[3]Annex-8'!E15,2)&" ")) -> #VALUE! | F14: =IF(INT('[3]Annex-8'!F15)='[3]Annex-8'!F15,'[3]Annex-8'!F15&".00 ",IF(INT('[3]Annex-8'!F15*10)='[3]Annex-8'!F15*10,'[3]Annex-8'!F15&"0 ",ROUND('[3]Annex-8'!F15,2)&" ")) -> #VALUE! | G14: =IF(INT('[3]Annex-8'!G15)='[3]Annex-8'!G15,'[3]Annex-8'!G15&".00 ",IF(INT('[3]Annex-8'!G15*10)='[3]Annex-8'!G15*10,'[3]Annex-8'!G15&"0 ",ROUND('[3]Annex-8'!G15,2)&" ")) -> #VALUE! | H14: =IF('[3]Annex-8'!H15<0,"(-)"&FIXED(ABS('[3]Annex-8'!H15),2)&" ",FIXED('[3]Annex-8'!H15,2)&" ") -> #VALUE!
A15: =IF([4]Crops!$A13="","",[4]Crops!$A13) | B15: =IF(INT('[3]Annex-8'!B16)='[3]Annex-8'!B16,'[3]Annex-8'!B16&".00 ",IF(INT('[3]Annex-8'!B16*10)='[3]Annex-8'!B16*10,'[3]Annex-8'!B16&"0 ",ROUND('[3]Annex-8'!B16,2)&" ")) -> #VALUE! | C15: =IF(INT('[3]Annex-8'!C16)='[3]Annex-8'!C16,'[3]Annex-8'!C16&".00 ",IF(INT('[3]Annex-8'!C16*10)='[3]Annex-8'!C16*10,'[3]Annex-8'!C16&"0 ",ROUND('[3]Annex-8'!C16,2)&" ")) -> #VALUE! | D15: =IF(INT('[3]Annex-8'!D16)='[3]Annex-8'!D16,'[3]Annex-8'!D16&".00 ",IF(INT('[3]Annex-8'!D16*10)='[3]Annex-8'!D16*10,'[3]Annex-8'!D16&"0 ",ROUND('[3]Annex-8'!D16,2)&" ")) -> #VALUE! | E15: =IF(INT('[3]Annex-8'!E16)='[3]Annex-8'!E16,'[3]Annex-8'!E16&".00 ",IF(INT('[3]Annex-8'!E16*10)='[3]Annex-8'!E16*10,'[3]Annex-8'!E16&"0 ",ROUND('[3]Annex-8'!E16,2)&" ")) -> #VALUE! | F15: =IF(INT('[3]Annex-8'!F16)='[3]Annex-8'!F16,'[3]Annex-8'!F16&".00 ",IF(INT('[3]Annex-8'!F16*10)='[3]Annex-8'!F16*10,'[3]Annex-8'!F16&"0 ",ROUND('[3]Annex-8'!F16,2)&" ")) -> #VALUE! | G15: =IF(INT('[3]Annex-8'!G16)='[3]Annex-8'!G16,'[3]Annex-8'!G16&".00 ",IF(INT('[3]Annex-8'!G16*10)='[3]Annex-8'!G16*10,'[3]Annex-8'!G16&"0 ",ROUND('[3]Annex-8'!G16,2)&" ")) -> #VALUE! | H15: =IF('[3]Annex-8'!H16<0,"(-)"&FIXED(ABS('[3]Annex-8'!H16),2)&" ",FIXED('[3]Annex-8'!H16,2)&" ") -> #VALUE!
A16: =IF([4]Crops!$A14="","",[4]Crops!$A14) | B16: =IF(INT('[3]Annex-8'!B17)='[3]Annex-8'!B17,'[3]Annex-8'!B17&".00 ",IF(INT('[3]Annex-8'!B17*10)='[3]Annex-8'!B17*10,'[3]Annex-8'!B17&"0 ",ROUND('[3]Annex-8'!B17,2)&" ")) -> #VALUE! | C16: =IF(INT('[3]Annex-8'!C17)='[3]Annex-8'!C17,'[3]Annex-8'!C17&".00 ",IF(INT('[3]Annex-8'!C17*10)='[3]Annex-8'!C17*10,'[3]Annex-8'!C17&"0 ",ROUND('[3]Annex-8'!C17,2)&" ")) -> #VALUE! | D16: =IF(INT('[3]Annex-8'!D17)='[3]Annex-8'!D17,'[3]Annex-8'!D17&".00 ",IF(INT('[3]Annex-8'!D17*10)='[3]Annex-8'!D17*10,'[3]Annex-8'!D17&"0 ",ROUND('[3]Annex-8'!D17,2)&" ")) -> #VALUE! | E16: =IF(INT('[3]Annex-8'!E17)='[3]Annex-8'!E17,'[3]Annex-8'!E17&".00 ",IF(INT('[3]Annex-8'!E17*10)='[3]Annex-8'!E17*10,'[3]Annex-8'!E17&"0 ",ROUND('[3]Annex-8'!E17,2)&" ")) -> #VALUE! | F16: =IF(INT('[3]Annex-8'!F17)='[3]Annex-8'!F17,'[3]Annex-8'!F17&".00 ",IF(INT('[3]Annex-8'!F17*10)='[3]Annex-8'!F17*10,'[3]Annex-8'!F17&"0 ",ROUND('[3]Annex-8'!F17,2)&" ")) -> #VALUE! | G16: =IF(INT('[3]Annex-8'!G17)='[3]Annex-8'!G17,'[3]Annex-8'!G17&".00 ",IF(INT('[3]Annex-8'!G17*10)='[3]Annex-8'!G17*10,'[3]Annex-8'!G17&"0 ",ROUND('[3]Annex-8'!G17,2)&" ")) -> #VALUE! | H16: =IF('[3]Annex-8'!H17<0,"(-)"&FIXED(ABS('[3]Annex-8'!H17),2)&" ",FIXED('[3]Annex-8'!H17,2)&" ") -> #VALUE!
A17: =IF([4]Crops!$A15="","",[4]Crops!$A15) | B17: =IF(INT('[3]Annex-8'!B18)='[3]Annex-8'!B18,'[3]Annex-8'!B18&".00 ",IF(INT('[3]Annex-8'!B18*10)='[3]Annex-8'!B18*10,'[3]Annex-8'!B18&"0 ",ROUND('[3]Annex-8'!B18,2)&" ")) -> #VALUE! | C17: =IF(INT('[3]Annex-8'!C18)='[3]Annex-8'!C18,'[3]Annex-8'!C18&".00 ",IF(INT('[3]Annex-8'!C18*10)='[3]Annex-8'!C18*10,'[3]Annex-8'!C18&"0 ",ROUND('[3]Annex-8'!C18,2)&" ")) -> #VALUE! | D17: =IF(INT('[3]Annex-8'!D18)='[3]Annex-8'!D18,'[3]Annex-8'!D18&".00 ",IF(INT('[3]Annex-8'!D18*10)='[3]Annex-8'!D18*10,'[3]Annex-8'!D18&"0 ",ROUND('[3]Annex-8'!D18,2)&" ")) -> #VALUE! | E17: =IF(INT('[3]Annex-8'!E18)='[3]Annex-8'!E18,'[3]Annex-8'!E18&".00 ",IF(INT('[3]Annex-8'!E18*10)='[3]Annex-8'!E18*10,'[3]Annex-8'!E18&"0 ",ROUND('[3]Annex-8'!E18,2)&" ")) -> #VALUE! | F17: =IF(INT('[3]Annex-8'!F18)='[3]Annex-8'!F18,'[3]Annex-8'!F18&".00 ",IF(INT('[3]Annex-8'!F18*10)='[3]Annex-8'!F18*10,'[3]Annex-8'!F18&"0 ",ROUND('[3]Annex-8'!F18,2)&" ")) -> #VALUE! | G17: =IF(INT('[3]Annex-8'!G18)='[3]Annex-8'!G18,'[3]Annex-8'!G18&".00 ",IF(INT('[3]Annex-8'!G18*10)='[3]Annex-8'!G18*10,'[3]Annex-8'!G18&"0 ",ROUND('[3]Annex-8'!G18,2)&" ")) -> #VALUE! | H17: =IF('[3]Annex-8'!H18<0,"(-)"&FIXED(ABS('[3]Annex-8'!H18),2)&" ",FIXED('[3]Annex-8'!H18,2)&" ") -> #VALUE!
A18: =IF([4]Crops!$A16="","",[4]Crops!$A16) | B18: =IF(INT('[3]Annex-8'!B19)='[3]Annex-8'!B19,'[3]Annex-8'!B19&".00 ",IF(INT('[3]Annex-8'!B19*10)='[3]Annex-8'!B19*10,'[3]Annex-8'!B19&"0 ",ROUND('[3]Annex-8'!B19,2)&" ")) -> #VALUE! | C18: =IF(INT('[3]Annex-8'!C19)='[3]Annex-8'!C19,'[3]Annex-8'!C19&".00 ",IF(INT('[3]Annex-8'!C19*10)='[3]Annex-8'!C19*10,'[3]Annex-8'!C19&"0 ",ROUND('[3]Annex-8'!C19,2)&" ")) -> #VALUE! | D18: =IF(INT('[3]Annex-8'!D19)='[3]Annex-8'!D19,'[3]Annex-8'!D19&".00 ",IF(INT('[3]Annex-8'!D19*10)='[3]Annex-8'!D19*10,'[3]Annex-8'!D19&"0 ",ROUND('[3]Annex-8'!D19,2)&" ")) -> #VALUE! | E18: =IF(INT('[3]Annex-8'!E19)='[3]Annex-8'!E19,'[3]Annex-8'!E19&".00 ",IF(INT('[3]Annex-8'!E19*10)='[3]Annex-8'!E19*10,'[3]Annex-8'!E19&"0 ",ROUND('[3]Annex-8'!E19,2)&" ")) -> #VALUE! | F18: =IF(INT('[3]Annex-8'!F19)='[3]Annex-8'!F19,'[3]Annex-8'!F19&".00 ",IF(INT('[3]Annex-8'!F19*10)='[3]Annex-8'!F19*10,'[3]Annex-8'!F19&"0 ",ROUND('[3]Annex-8'!F19,2)&" ")) -> #VALUE! | G18: =IF(INT('[3]Annex-8'!G19)='[3]Annex-8'!G19,'[3]Annex-8'!G19&".00 ",IF(INT('[3]Annex-8'!G19*10)='[3]Annex-8'!G19*10,'[3]Annex-8'!G19&"0 ",ROUND('[3]Annex-8'!G19,2)&" ")) -> #VALUE! | H18: =IF('[3]Annex-8'!H19<0,"(-)"&FIXED(ABS('[3]Annex-8'!H19),2)&" ",FIXED('[3]Annex-8'!H19,2)&" ") -> #VALUE!
A19: =IF([4]Crops!$A17="","",[4]Crops!$A17) | B19: =IF(INT('[3]Annex-8'!B20)='[3]Annex-8'!B20,'[3]Annex-8'!B20&".00 ",IF(INT('[3]Annex-8'!B20*10)='[3]Annex-8'!B20*10,'[3]Annex-8'!B20&"0 ",ROUND('[3]Annex-8'!B20,2)&" ")) -> #VALUE! | C19: =IF(INT('[3]Annex-8'!C20)='[3]Annex-8'!C20,'[3]Annex-8'!C20&".00 ",IF(INT('[3]Annex-8'!C20*10)='[3]Annex-8'!C20*10,'[3]Annex-8'!C20&"0 ",ROUND('[3]Annex-8'!C20,2)&" ")) -> #VALUE! | D19: =IF(INT('[3]Annex-8'!D20)='[3]Annex-8'!D20,'[3]Annex-8'!D20&".00 ",IF(INT('[3]Annex-8'!D20*10)='[3]Annex-8'!D20*10,'[3]Annex-8'!D20&"0 ",ROUND('[3]Annex-8'!D20,2)&" ")) -> #VALUE! | E19: =IF(INT('[3]Annex-8'!E20)='[3]Annex-8'!E20,'[3]Annex-8'!E20&".00 ",IF(INT('[3]Annex-8'!E20*10)='[3]Annex-8'!E20*10,'[3]Annex-8'!E20&"0 ",ROUND('[3]Annex-8'!E20,2)&" ")) -> #VALUE! | F19: =IF(INT('[3]Annex-8'!F20)='[3]Annex-8'!F20,'[3]Annex-8'!F20&".00 ",IF(INT('[3]Annex-8'!F20*10)='[3]Annex-8'!F20*10,'[3]Annex-8'!F20&"0 ",ROUND('[3]Annex-8'!F20,2)&" ")) -> #VALUE! | G19: =IF(INT('[3]Annex-8'!G20)='[3]Annex-8'!G20,'[3]Annex-8'!G20&".00 ",IF(INT('[3]Annex-8'!G20*10)='[3]Annex-8'!G20*10,'[3]Annex-8'!G20&"0 ",ROUND('[3]Annex-8'!G20,2)&" ")) -> #VALUE! | H19: =IF('[3]Annex-8'!H20<0,"(-)"&FIXED(ABS('[3]Annex-8'!H20),2)&" ",FIXED('[3]Annex-8'!H20,2)&" ") -> #VALUE!
A20: =IF([4]Crops!$A18="","",[4]Crops!$A18) | B20: =IF(INT('[3]Annex-8'!B21)='[3]Annex-8'!B21,'[3]Annex-8'!B21&".00 ",IF(INT('[3]Annex-8'!B21*10)='[3]Annex-8'!B21*10,'[3]Annex-8'!B21&"0 ",ROUND('[3]Annex-8'!B21,2)&" ")) -> #VALUE! | C20: =IF(INT('[3]Annex-8'!C21)='[3]Annex-8'!C21,'[3]Annex-8'!C21&".00 ",IF(INT('[3]Annex-8'!C21*10)='[3]Annex-8'!C21*10,'[3]Annex-8'!C21&"0 ",ROUND('[3]Annex-8'!C21,2)&" ")) -> #VALUE! | D20: =IF(INT('[3]Annex-8'!D21)='[3]Annex-8'!D21,'[3]Annex-8'!D21&".00 ",IF(INT('[3]Annex-8'!D21*10)='[3]Annex-8'!D21*10,'[3]Annex-8'!D21&"0 ",ROUND('[3]Annex-8'!D21,2)&" ")) -> #VALUE! | E20: =IF(INT('[3]Annex-8'!E21)='[3]Annex-8'!E21,'[3]Annex-8'!E21&".00 ",IF(INT('[3]Annex-8'!E21*10)='[3]Annex-8'!E21*10,'[3]Annex-8'!E21&"0 ",ROUND('[3]Annex-8'!E21,2)&" ")) -> #VALUE! | F20: =IF(INT('[3]Annex-8'!F21)='[3]Annex-8'!F21,'[3]Annex-8'!F21&".00 ",IF(INT('[3]Annex-8'!F21*10)='[3]Annex-8'!F21*10,'[3]Annex-8'!F21&"0 ",ROUND('[3]Annex-8'!F21,2)&" ")) -> #VALUE! | G20: =IF(INT('[3]Annex-8'!G21)='[3]Annex-8'!G21,'[3]Annex-8'!G21&".00 ",IF(INT('[3]Annex-8'!G21*10)='[3]Annex-8'!G21*10,'[3]Annex-8'!G21&"0 ",ROUND('[3]Annex-8'!G21,2)&" ")) -> #VALUE! | H20: =IF('[3]Annex-8'!H21<0,"(-)"&FIXED(ABS('[3]Annex-8'!H21),2)&" ",FIXED('[3]Annex-8'!H21,2)&" ") -> #VALUE!
... A23: =IF([4]Crops!$A21="","",[4]Crops!$A21) | B23: =IF(INT('[3]Annex-8'!B24)='[3]Annex-8'!B24,'[3]Annex-8'!B24&".00 ",IF(INT('[3]Annex-8'!B24*10)='[3]Annex-8'!B24*10,'[3]Annex-8'!B24&"0 ",ROUND('[3]Annex-8'!B24,2)&" ")) -> #VALUE! | C23: =IF(INT('[3]Annex-8'!C24)='[3]Annex-8'!C24,'[3]Annex-8'!C24&".00 ",IF(INT('[3]Annex-8'!C24*10)='[3]Annex-8'!C24*10,'[3]Annex-8'!C24&"0 ",ROUND('[3]Annex-8'!C24,2)&" ")) -> #VALUE! | D23: =IF(INT('[3]Annex-8'!D24)='[3]Annex-8'!D24,'[3]Annex-8'!D24&".00 ",IF(INT('[3]Annex-8'!D24*10)='[3]Annex-8'!D24*10,'[3]Annex-8'!D24&"0 ",ROUND('[3]Annex-8'!D24,2)&" ")) -> #VALUE! | E23: =IF(INT('[3]Annex-8'!E24)='[3]Annex-8'!E24,'[3]Annex-8'!E24&".00 ",IF(INT('[3]Annex-8'!E24*10)='[3]Annex-8'!E24*10,'[3]Annex-8'!E24&"0 ",ROUND('[3]Annex-8'!E24,2)&" ")) -> #VALUE! | F23: =IF(INT('[3]Annex-8'!F24)='[3]Annex-8'!F24,'[3]Annex-8'!F24&".00 ",IF(INT('[3]Annex-8'!F24*10)='[3]Annex-8'!F24*10,'[3]Annex-8'!F24&"0 ",ROUND('[3]Annex-8'!F24,2)&" ")) -> #VALUE! | G23: =IF(INT('[3]Annex-8'!G24)='[3]Annex-8'!G24,'[3]Annex-8'!G24&".00 ",IF(INT('[3]Annex-8'!G24*10)='[3]Annex-8'!G24*10,'[3]Annex-8'!G24&"0 ",ROUND('[3]Annex-8'!G24,2)&" ")) -> #VALUE! | H23: =IF('[3]Annex-8'!H24<0,"(-)"&FIXED(ABS('[3]Annex-8'!H24),2)&" ",FIXED('[3]Annex-8'!H24,2)&" ") -> #VALUE!
A24: =common!$I$4 -> RABI II 2024-25
A25: =IF([4]Crops!$C7="","",[4]Crops!$C7) -> PADDY | B25: =IF(INT('[3]Annex-8'!B26)='[3]Annex-8'!B26,'[3]Annex-8'!B26&".00 ",IF(INT('[3]Annex-8'!B26*10)='[3]Annex-8'!B26*10,'[3]Annex-8'!B26&"0 ",ROUND('[3]Annex-8'!B26,2)&" ")) -> 0.03 | C25: =IF(INT('[3]Annex-8'!C26)='[3]Annex-8'!C26,'[3]Annex-8'!C26&".00 ",IF(INT('[3]Annex-8'!C26*10)='[3]Annex-8'!C26*10,'[3]Annex-8'!C26&"0 ",ROUND('[3]Annex-8'!C26,2)&" ")) -> 0.03 | D25: =IF(INT('[3]Annex-8'!D26)='[3]Annex-8'!D26,'[3]Annex-8'!D26&".00 ",IF(INT('[3]Annex-8'!D26*10)='[3]Annex-8'!D26*10,'[3]Annex-8'!D26&"0 ",ROUND('[3]Annex-8'!D26,2)&" ")) -> 8.79 | E25: =IF(INT('[3]Annex-8'!E26)='[3]Annex-8'!E26,'[3]Annex-8'!E26&".00 ",IF(INT('[3]Annex-8'!E26*10)='[3]Annex-8'!E26*10,'[3]Annex-8'!E26&"0 ",ROUND('[3]Annex-8'!E26,2)&" ")) -> 8.60 | F25: =IF(INT('[3]Annex-8'!F26)='[3]Annex-8'!F26,'[3]Annex-8'!F26&".00 ",IF(INT('[3]Annex-8'!F26*10)='[3]Annex-8'!F26*10,'[3]Annex-8'!F26&"0 ",ROUND('[3]Annex-8'!F26,2)&" ")) -> 8.81 | G25: =IF(INT('[3]Annex-8'!G26)='[3]Annex-8'!G26,'[3]Annex-8'!G26&".00 ",IF(INT('[3]Annex-8'!G26*10)='[3]Annex-8'!G26*10,'[3]Annex-8'!G26&"0 ",ROUND('[3]Annex-8'!G26,2)&" ")) -> 8.63 | H25: =IF('[3]Annex-8'!H26<0,"(-)"&FIXED(ABS('[3]Annex-8'!H26),2)&" ",FIXED('[3]Annex-8'!H26,2)&" ") -> (-)2.10
A26: =IF([4]Crops!$C8="","",[4]Crops!$C8) -> OTHERS | B26: =IF(INT('[3]Annex-8'!B27)='[3]Annex-8'!B27,'[3]Annex-8'!B27&".00 ",IF(INT('[3]Annex-8'!B27*10)='[3]Annex-8'!B27*10,'[3]Annex-8'!B27&"0 ",ROUND('[3]Annex-8'!B27,2)&" ")) -> 1.77 | C26: =IF(INT('[3]Annex-8'!C27)='[3]Annex-8'!C27,'[3]Annex-8'!C27&".00 ",IF(INT('[3]Annex-8'!C27*10)='[3]Annex-8'!C27*10,'[3]Annex-8'!C27&"0 ",ROUND('[3]Annex-8'!C27,2)&" ")) -> 2.62 | D26: =IF(INT('[3]Annex-8'!D27)='[3]Annex-8'!D27,'[3]Annex-8'!D27&".00 ",IF(INT('[3]Annex-8'!D27*10)='[3]Annex-8'!D27*10,'[3]Annex-8'!D27&"0 ",ROUND('[3]Annex-8'!D27,2)&" ")) -> 4.49 | E26: =IF(INT('[3]Annex-8'!E27)='[3]Annex-8'!E27,'[3]Annex-8'!E27&".00 ",IF(INT('[3]Annex-8'!E27*10)='[3]Annex-8'!E27*10,'[3]Annex-8'!E27&"0 ",ROUND('[3]Annex-8'!E27,2)&" ")) -> 4.49 | F26: =IF(INT('[3]Annex-8'!F27)='[3]Annex-8'!F27,'[3]Annex-8'!F27&".00 ",IF(INT('[3]Annex-8'!F27*10)='[3]Annex-8'!F27*10,'[3]Annex-8'!F27&"0 ",ROUND('[3]Annex-8'!F27,2)&" ")) -> 6.26 | G26: =IF(INT('[3]Annex-8'!G27)='[3]Annex-8'!G27,'[3]Annex-8'!G27&".00 ",IF(INT('[3]Annex-8'!G27*10)='[3]Annex-8'!G27*10,'[3]Annex-8'!G27&"0 ",ROUND('[3]Annex-8'!G27,2)&" ")) -> 7.11 | H26: =IF('[3]Annex-8'!H27<0,"(-)"&FIXED(ABS('[3]Annex-8'!H27),2)&" ",FIXED('[3]Annex-8'!H27,2)&" ") -> 13.53
A27: =IF([4]Crops!$C9="","",[4]Crops!$C9) | B27: =IF(INT('[3]Annex-8'!B28)='[3]Annex-8'!B28,'[3]Annex-8'!B28&".00 ",IF(INT('[3]Annex-8'!B28*10)='[3]Annex-8'!B28*10,'[3]Annex-8'!B28&"0 ",ROUND('[3]Annex-8'!B28,2)&" ")) -> #VALUE! | C27: =IF(INT('[3]Annex-8'!C28)='[3]Annex-8'!C28,'[3]Annex-8'!C28&".00 ",IF(INT('[3]Annex-8'!C28*10)='[3]Annex-8'!C28*10,'[3]Annex-8'!C28&"0 ",ROUND('[3]Annex-8'!C28,2)&" ")) -> #VALUE! | D27: =IF(INT('[3]Annex-8'!D28)='[3]Annex-8'!D28,'[3]Annex-8'!D28&".00 ",IF(INT('[3]Annex-8'!D28*10)='[3]Annex-8'!D28*10,'[3]Annex-8'!D28&"0 ",ROUND('[3]Annex-8'!D28,2)&" ")) -> #VALUE! | E27: =IF(INT('[3]Annex-8'!E28)='[3]Annex-8'!E28,'[3]Annex-8'!E28&".00 ",IF(INT('[3]Annex-8'!E28*10)='[3]Annex-8'!E28*10,'[3]Annex-8'!E28&"0 ",ROUND('[3]Annex-8'!E28,2)&" ")) -> #VALUE! | F27: =IF(INT('[3]Annex-8'!F28)='[3]Annex-8'!F28,'[3]Annex-8'!F28&".00 ",IF(INT('[3]Annex-8'!F28*10)='[3]Annex-8'!F28*10,'[3]Annex-8'!F28&"0 ",ROUND('[3]Annex-8'!F28,2)&" ")) -> #VALUE! | G27: =IF(INT('[3]Annex-8'!G28)='[3]Annex-8'!G28,'[3]Annex-8'!G28&".00 ",IF(INT('[3]Annex-8'!G28*10)='[3]Annex-8'!G28*10,'[3]Annex-8'!G28&"0 ",ROUND('[3]Annex-8'!G28,2)&" ")) -> #VALUE! | H27: =IF('[3]Annex-8'!H28<0,"(-)"&FIXED(ABS('[3]Annex-8'!H28),2)&" ",FIXED('[3]Annex-8'!H28,2)&" ") -> #VALUE!
A28: =IF([4]Crops!$C10="","",[4]Crops!$C10) | B28: =IF(INT('[3]Annex-8'!B29)='[3]Annex-8'!B29,'[3]Annex-8'!B29&".00 ",IF(INT('[3]Annex-8'!B29*10)='[3]Annex-8'!B29*10,'[3]Annex-8'!B29&"0 ",ROUND('[3]Annex-8'!B29,2)&" ")) -> #VALUE! | C28: =IF(INT('[3]Annex-8'!C29)='[3]Annex-8'!C29,'[3]Annex-8'!C29&".00 ",IF(INT('[3]Annex-8'!C29*10)='[3]Annex-8'!C29*10,'[3]Annex-8'!C29&"0 ",ROUND('[3]Annex-8'!C29,2)&" ")) -> #VALUE! | D28: =IF(INT('[3]Annex-8'!D29)='[3]Annex-8'!D29,'[3]Annex-8'!D29&".00 ",IF(INT('[3]Annex-8'!D29*10)='[3]Annex-8'!D29*10,'[3]Annex-8'!D29&"0 ",ROUND('[3]Annex-8'!D29,2)&" ")) -> #VALUE! | E28: =IF(INT('[3]Annex-8'!E29)='[3]Annex-8'!E29,'[3]Annex-8'!E29&".00 ",IF(INT('[3]Annex-8'!E29*10)='[3]Annex-8'!E29*10,'[3]Annex-8'!E29&"0 ",ROUND('[3]Annex-8'!E29,2)&" ")) -> #VALUE! | F28: =IF(INT('[3]Annex-8'!F29)='[3]Annex-8'!F29,'[3]Annex-8'!F29&".00 ",IF(INT('[3]Annex-8'!F29*10)='[3]Annex-8'!F29*10,'[3]Annex-8'!F29&"0 ",ROUND('[3]Annex-8'!F29,2)&" ")) -> #VALUE! | G28: =IF(INT('[3]Annex-8'!G29)='[3]Annex-8'!G29,'[3]Annex-8'!G29&".00 ",IF(INT('[3]Annex-8'!G29*10)='[3]Annex-8'!G29*10,'[3]Annex-8'!G29&"0 ",ROUND('[3]Annex-8'!G29,2)&" ")) -> #VALUE! | H28: =IF('[3]Annex-8'!H29<0,"(-)"&FIXED(ABS('[3]Annex-8'!H29),2)&" ",FIXED('[3]Annex-8'!H29,2)&" ") -> #VALUE!
A29: =IF([4]Crops!$C11="","",[4]Crops!$C11) | B29: =IF(INT('[3]Annex-8'!B30)='[3]Annex-8'!B30,'[3]Annex-8'!B30&".00 ",IF(INT('[3]Annex-8'!B30*10)='[3]Annex-8'!B30*10,'[3]Annex-8'!B30&"0 ",ROUND('[3]Annex-8'!B30,2)&" ")) -> #VALUE! | C29: =IF(INT('[3]Annex-8'!C30)='[3]Annex-8'!C30,'[3]Annex-8'!C30&".00 ",IF(INT('[3]Annex-8'!C30*10)='[3]Annex-8'!C30*10,'[3]Annex-8'!C30&"0 ",ROUND('[3]Annex-8'!C30,2)&" ")) -> #VALUE! | D29: =IF(INT('[3]Annex-8'!D30)='[3]Annex-8'!D30,'[3]Annex-8'!D30&".00 ",IF(INT('[3]Annex-8'!D30*10)='[3]Annex-8'!D30*10,'[3]Annex-8'!D30&"0 ",ROUND('[3]Annex-8'!D30,2)&" ")) -> #VALUE! | E29: =IF(INT('[3]Annex-8'!E30)='[3]Annex-8'!E30,'[3]Annex-8'!E30&".00 ",IF(INT('[3]Annex-8'!E30*10)='[3]Annex-8'!E30*10,'[3]Annex-8'!E30&"0 ",ROUND('[3]Annex-8'!E30,2)&" ")) -> #VALUE! | F29: =IF(INT('[3]Annex-8'!F30)='[3]Annex-8'!F30,'[3]Annex-8'!F30&".00 ",IF(INT('[3]Annex-8'!F30*10)='[3]Annex-8'!F30*10,'[3]Annex-8'!F30&"0 ",ROUND('[3]Annex-8'!F30,2)&" ")) -> #VALUE! | G29: =IF(INT('[3]Annex-8'!G30)='[3]Annex-8'!G30,'[3]Annex-8'!G30&".00 ",IF(INT('[3]Annex-8'!G30*10)='[3]Annex-8'!G30*10,'[3]Annex-8'!G30&"0 ",ROUND('[3]Annex-8'!G30,2)&" ")) -> #VALUE! | H29: =IF('[3]Annex-8'!H30<0,"(-)"&FIXED(ABS('[3]Annex-8'!H30),2)&" ",FIXED('[3]Annex-8'!H30,2)&" ") -> #VALUE!
