Workbook

Sheet Basicdata
A1: ='[1]RC-1'!A1 -> RC | B1: ='[1]RC-1'!B1 -> ST | C1: ='[1]RC-1'!C1 -> YR | D1: ='[1]RC-1'!D1 -> SESON | E1: ='[1]RC-1'!E1 -> NOVP | F1: ='[1]RC-1'!F1 -> NOVCOD | G1: ='[1]RC-1'!G1 -> STAT | H1: ='[1]RC-1'!H1 -> DIST | ... AI1: ='[1]RC-1'!AI1 -> REJ
A2: ='[1]RC-1'!A2 -> 1 | B2: ='[1]RC-1'!B2 -> 1 | C2: ='[1]RC-1'!C2 -> 2025 | D2: ='[1]RC-1'!D2 -> 4 | E2: ='[1]RC-1'!E2 -> 9 | F2: ='[1]RC-1'!F2 -> 9 | G2: ='[1]RC-1'!G2 -> 34 | H2: ='[1]RC-1'!H2 -> 2 | ... AI2: ='[1]RC-1'!AI2 -> 0
A3: ='[1]RC-1'!A3 -> 1 | B3: ='[1]RC-1'!B3 -> 1 | C3: ='[1]RC-1'!C3 -> 2025 | D3: ='[1]RC-1'!D3 -> 4 | E3: ='[1]RC-1'!E3 -> 9 | F3: ='[1]RC-1'!F3 -> 9 | G3: ='[1]RC-1'!G3 -> 34 | H3: ='[1]RC-1'!H3 -> 2 | ... AI3: ='[1]RC-1'!AI3 -> 0
A4: ='[1]RC-1'!A4 -> 1 | B4: ='[1]RC-1'!B4 -> 1 | C4: ='[1]RC-1'!C4 -> 2025 | D4: ='[1]RC-1'!D4 -> 4 | E4: ='[1]RC-1'!E4 -> 9 | F4: ='[1]RC-1'!F4 -> 9 | G4: ='[1]RC-1'!G4 -> 34 | H4: ='[1]RC-1'!H4 -> 2 | ... AI4: ='[1]RC-1'!AI4 -> 0
A5: ='[1]RC-1'!A5 -> 1 | B5: ='[1]RC-1'!B5 -> 1 | C5: ='[1]RC-1'!C5 -> 2025 | D5: ='[1]RC-1'!D5 -> 4 | E5: ='[1]RC-1'!E5 -> 9 | F5: ='[1]RC-1'!F5 -> 9 | G5: ='[1]RC-1'!G5 -> 34 | H5: ='[1]RC-1'!H5 -> 2 | ... AI5: ='[1]RC-1'!AI5 -> 0
A6: ='[1]RC-1'!A6 -> 1 | B6: ='[1]RC-1'!B6 -> 1 | C6: ='[1]RC-1'!C6 -> 2025 | D6: ='[1]RC-1'!D6 -> 4 | E6: ='[1]RC-1'!E6 -> 9 | F6: ='[1]RC-1'!F6 -> 9 | G6: ='[1]RC-1'!G6 -> 34 | H6: ='[1]RC-1'!H6 -> 2 | ... AI6: ='[1]RC-1'!AI6 -> 0
A7: ='[1]RC-1'!A7 -> 1 | B7: ='[1]RC-1'!B7 -> 1 | C7: ='[1]RC-1'!C7 -> 2025 | D7: ='[1]RC-1'!D7 -> 4 | E7: ='[1]RC-1'!E7 -> 9 | F7: ='[1]RC-1'!F7 -> 9 | G7: ='[1]RC-1'!G7 -> 34 | H7: ='[1]RC-1'!H7 -> 2 | ... AI7: ='[1]RC-1'!AI7 -> 0
A8: ='[1]RC-1'!A8 -> 1 | B8: ='[1]RC-1'!B8 -> 1 | C8: ='[1]RC-1'!C8 -> 2025 | D8: ='[1]RC-1'!D8 -> 4 | E8: ='[1]RC-1'!E8 -> 9 | F8: ='[1]RC-1'!F8 -> 9 | G8: ='[1]RC-1'!G8 -> 34 | H8: ='[1]RC-1'!H8 -> 4 | ... AI8: ='[1]RC-1'!AI8 -> 0
A9: ='[1]RC-1'!A9 -> 1 | B9: ='[1]RC-1'!B9 -> 1 | C9: ='[1]RC-1'!C9 -> 2025 | D9: ='[1]RC-1'!D9 -> 4 | E9: ='[1]RC-1'!E9 -> 9 | F9: ='[1]RC-1'!F9 -> 9 | G9: ='[1]RC-1'!G9 -> 34 | H9: ='[1]RC-1'!H9 -> 4 | ... AI9: ='[1]RC-1'!AI9 -> 0
A10: ='[1]RC-1'!A10 -> 1 | B10: ='[1]RC-1'!B10 -> 1 | C10: ='[1]RC-1'!C10 -> 2025 | D10: ='[1]RC-1'!D10 -> 4 | E10: ='[1]RC-1'!E10 -> 9 | F10: ='[1]RC-1'!F10 -> 9 | G10: ='[1]RC-1'!G10 -> 34 | H10: ='[1]RC-1'!H10 -> 4 | ... AI10: ='[1]RC-1'!AI10 -> 0
A11: ='[1]RC-1'!A11 -> 1 | B11: ='[1]RC-1'!B11 -> 1 | C11: ='[1]RC-1'!C11 -> 2025 | D11: ='[1]RC-1'!D11 -> 5 | E11: ='[1]RC-1'!E11 -> 9 | F11: ='[1]RC-1'!F11 -> 9 | G11: ='[1]RC-1'!G11 -> 34 | H11: ='[1]RC-1'!H11 -> 2 | ... AI11: ='[1]RC-1'!AI11 -> 0
A12: ='[1]RC-1'!A12 -> 1 | B12: ='[1]RC-1'!B12 -> 1 | C12: ='[1]RC-1'!C12 -> 2025 | D12: ='[1]RC-1'!D12 -> 5 | E12: ='[1]RC-1'!E12 -> 9 | F12: ='[1]RC-1'!F12 -> 9 | G12: ='[1]RC-1'!G12 -> 34 | H12: ='[1]RC-1'!H12 -> 2 | ... AI12: ='[1]RC-1'!AI12 -> 0
... A2500: ='[1]RC-1'!A2500 -> 0 | B2500: ='[1]RC-1'!B2500 -> 0 | C2500: ='[1]RC-1'!C2500 -> 0 | D2500: ='[1]RC-1'!D2500 -> 0 | E2500: ='[1]RC-1'!E2500 -> 0 | F2500: ='[1]RC-1'!F2500 -> 0 | G2500: ='[1]RC-1'!G2500 -> 0 | H2500: ='[1]RC-1'!H2500 -> 0 | ... AI2500: ='[1]RC-1'!AI2500 -> 0

Sheet Crops
A1: =[1]Crops!A1 -> STATE | B1: =[1]Crops!B1 -> Code | C1: =[1]Crops!C1 -> Sample Type | D1: =[1]Crops!D1 -> code | M1: =[1]Crops!M1 -> District
A2: =[1]Crops!A2 -> PUDUCHERRY | B2: =[1]Crops!B2 -> 34 | C2: =[1]Crops!C2 -> CENTRAL | D2: =[1]Crops!D2 -> 1 | F2: Don't cut/delete the cell | M2: =[1]Crops!M2 -> 1
A3: =[1]Crops!A3 -> YEAR | B3: =[1]Crops!B3 -> 2024-25 | C3: =[1]Crops!C3 -> STATE | D3: =[1]Crops!D3 -> 2 | M3: =[1]Crops!M3 -> 2
A4: =[1]Crops!A4 -> Season | B4: =[1]Crops!B4 -> code | C4: =[1]Crops!C4 -> Season | D4: =[1]Crops!D4 -> code | M4: =[1]Crops!M4 -> 3
A5: =[1]Crops!A5 -> RABI I | B5: =[1]Crops!B5 -> 4 | C5: =[1]Crops!C5 -> RABI II | D5: =[1]Crops!D5 -> 5 | M5: =[1]Crops!M5 -> 4
A6: =[1]Crops!A6 -> Crop | B6: =[1]Crops!B6 -> Code | C6: =[1]Crops!C6 -> Crop | D6: =[1]Crops!D6 -> Code | M6: =[1]Crops!M6 -> 5
A7: =[1]Crops!A7 -> PADDY | B7: =[1]Crops!B7 -> 97 | C7: =[1]Crops!C7 -> PADDY | D7: =[1]Crops!D7 -> 98 | M7: =[1]Crops!M7 -> 6
A8: =[1]Crops!A8 -> OTHERS | B8: =[1]Crops!B8 -> 99 | C8: =[1]Crops!C8 -> OTHERS | D8: =[1]Crops!D8 -> 99 | M8: =[1]Crops!M8 -> 7
A9: =[1]Crops!A9 -> 0 | B9: =[1]Crops!B9 -> 0 | C9: =[1]Crops!C9 -> 0 | D9: =[1]Crops!D9 -> 0 | M9: =[1]Crops!M9 -> 8
A10: =[1]Crops!A10 -> 0 | B10: =[1]Crops!B10 -> 0 | C10: =[1]Crops!C10 -> 0 | D10: =[1]Crops!D10 -> 0 | M10: =[1]Crops!M10 -> 9
A11: =[1]Crops!A11 -> 0 | B11: =[1]Crops!B11 -> 0 | C11: =[1]Crops!C11 -> 0 | D11: =[1]Crops!D11 -> 0 | M11: =[1]Crops!M11 -> 10
A12: =[1]Crops!A12 -> 0 | B12: =[1]Crops!B12 -> 0 | C12: =[1]Crops!C12 -> 0 | D12: =[1]Crops!D12 -> 0 | M12: =[1]Crops!M12 -> 11
A13: =[1]Crops!A13 -> 0 | B13: =[1]Crops!B13 -> 0 | C13: =[1]Crops!C13 -> 0 | D13: =[1]Crops!D13 -> 0 | M13: =[1]Crops!M13 -> 12
A14: =[1]Crops!A14 -> 0 | B14: =[1]Crops!B14 -> 0 | C14: =[1]Crops!C14 -> 0 | D14: =[1]Crops!D14 -> 0 | M14: =[1]Crops!M14 -> 13
... A21: =[1]Crops!A21 -> 0 | B21: =[1]Crops!B21 -> 0 | C21: =[1]Crops!C21 -> 0 | D21: =[1]Crops!D21 -> 0 | M21: =[1]Crops!M21 -> 20
M22: =[1]Crops!M22 -> 21
M23: =[1]Crops!M23 -> 22
M24: =[1]Crops!M24 -> 23
M25: =[1]Crops!M25 -> 24
M26: =[1]Crops!M26 -> 25
M27: =[1]Crops!M27 -> 26
M28: =[1]Crops!M28 -> 27
M29: =[1]Crops!M29 -> 28
M30: =[1]Crops!M30 -> 29
M31: =[1]Crops!M31 -> 30
M32: =[1]Crops!M32 -> 31
M33: =[1]Crops!M33 -> 32
... M219: =[1]Crops!M219 -> 218

Sheet Table-1
A2: TABLE :A-1 : DISTRICTWISE DISTRIBUTION OF SELECTED VILLAGES FOR CHECK ON ENUMERATION OF AREA AND RESPONSE ACHIEVED. | L2: TABLE :A-1 : DISTRICTWISE DISTRIBUTION OF SELECTED VILLAGES FOR CHECK ON ENUMERATION OF AREA AND RESPONSE ACHIEVED.
A3: STATE: | B3: =Crops!$A$2&"("&Crops!$B$2&")" -> PUDUCHERRY(34) | D3: YEAR: | E3: =Crops!$B$3 -> 2024-25 | F3: SEASON: | G3: =Crops!$A$5&"("&Crops!$B$5&")" -> RABI I(4) | H3: SAMPLE: | I3: ="CENTRAL"&"("&1&")" -> CENTRAL(1) | L3: STATE: | M3: =Crops!$A$2&"("&Crops!$B$2&")" -> PUDUCHERRY(34) | O3: YEAR: | P3: =Crops!$B$3 -> 2024-25 | Q3: SEASON: | R3: =Crops!$A$5&"("&Crops!$B$5&")" -> RABI I(4) | S3: SAMPLE: | T3: ="STATE"&"("&2&")" -> STATE(2)
A4: DISTRICT | B4: NO.OF VILLAGES FOR WHICH SCHEDULE AS 1.0 RECEIVED | C4: NO. OF VILLAGES FOR WHICH SCHEDULE AS 1.0 IS ANALYSED | G4: PERCENTAGE RESPONSE TO COL.(2) | L4: DISTRICT | M4: NO.OF VILLAGES FOR WHICH SCHEDULE AS 1.0 RECEIVED | N4: NO. OF VILLAGES FOR WHICH SCHEDULE AS 1.0 IS ANALYSED | R4: PERCENTAGE RESPONSE TO COL.(2)
C5: WITH 'a' AND 'b' ENTRIES TOGETHER | D5: WITH 'a' AND 'b' ENTRIES SEPARATELY | E5: WITH 'a' ENTRIES ONLY | F5: TOTAL | G5: WITH 'a' AND 'b' ENTRIES TOGETHER | H5: WITH 'a' AND 'b' ENTRIES SEPARATELY | I5: WITH 'a' ENTRIES ONLY | J5: TOTAL | N5: WITH 'a' AND 'b' ENTRIES TOGETHER | O5: WITH 'a' AND 'b' ENTRIES SEPARATELY | P5: WITH 'a' ENTRIES ONLY | Q5: TOTAL | R5: WITH 'a' AND 'b' ENTRIES TOGETHER | S5: WITH 'a' AND 'b' ENTRIES SEPARATELY | T5: WITH 'a' ENTRIES ONLY | U5: TOTAL
A10: 1 | B10: 2 | C10: 3 | D10: 4 | E10: 5 | F10: 7 | G10: 8 | H10: 9 | I10: 10 | J10: 11 | L10: 1 | M10: 2 | N10: 3 | O10: 4 | P10: 5 | Q10: 7 | R10: 8 | S10: 9 | T10: 10 | U10: 11
A11: =IF(COUNTIFS(Basicdata!$B$2:$B$2500,1,Basicdata!$D$2:$D$2500,Crops!$B$5,Basicdata!$H$2:$H$2500,Crops!$M2)>0,Crops!$M2,"") | B11: =IF(A11="","",COUNTIFS(Basicdata!$B$2:$B$2500,1,Basicdata!$D$2:$D$2500,Crops!$B$5,Basicdata!$H$2:$H$2500,Crops!$M2)) | C11: =IF(A11="","",COUNTIFS(Basicdata!$B$2:$B$2500,1,Basicdata!$D$2:$D$2500,Crops!$B$5,Basicdata!$H$2:$H$2500,Crops!$M2,Basicdata!$K$2:$K$2500,1,Basicdata!$AI$2:$AI$2500,0)) | D11: =IF(A11="","",COUNTIFS(Basicdata!$B$2:$B$2500,1,Basicdata!$D$2:$D$2500,Crops!$B$5,Basicdata!$H$2:$H$2500,Crops!$M2,Basicdata!$K$2:$K$2500,2,Basicdata!$AI$2:$AI$2500,0)) | E11: =IF(A11="","",COUNTIFS(Basicdata!$B$2:$B$2500,1,Basicdata!$D$2:$D$2500,Crops!$B$5,Basicdata!$H$2:$H$2500,Crops!$M2,Basicdata!$K$2:$K$2500,3,Basicdata!$AI$2:$AI$2500,0)) | F11: =IF(A11="","",C11+D11+E11) | G11: =IF(OR(F11="",F11=0),"",C11*100/B11) | H11: =IF(OR(F11="",F11=0),"",D11*100/B11) | I11: =IF(OR(F11="",F11=0),"",J11-G11-H11) | J11: =IF(OR(F11="",F11=0),"",F11*100/B11) | L11: =IF(COUNTIFS(Basicdata!$B$2:$B$2500,2,Basicdata!$D$2:$D$2500,Crops!$B$5,Basicdata!$H$2:$H$2500,Crops!$M2)>0,Crops!$M2,"") | M11: =IF(L11="","",COUNTIFS(Basicdata!$B$2:$B$2500,2,Basicdata!$D$2:$D$2500,Crops!$B$5,Basicdata!$H$2:$H$2500,Crops!$M2)) | N11: =IF(L11="","",COUNTIFS(Basicdata!$B$2:$B$2500,2,Basicdata!$D$2:$D$2500,Crops!$B$5,Basicdata!$H$2:$H$2500,Crops!$M2,Basicdata!$K$2:$K$2500,1,Basicdata!$AI$2:$AI$2500,0)) | O11: =IF(L11="","",COUNTIFS(Basicdata!$B$2:$B$2500,2,Basicdata!$D$2:$D$2500,Crops!$B$5,Basicdata!$H$2:$H$2500,Crops!$M2,Basicdata!$K$2:$K$2500,2,Basicdata!$AI$2:$AI$2500,0)) | P11: =IF(L11="","",COUNTIFS(Basicdata!$B$2:$B$2500,2,Basicdata!$D$2:$D$2500,Crops!$B$5,Basicdata!$H$2:$H$2500,Crops!$M2,Basicdata!$K$2:$K$2500,3,Basicdata!$AI$2:$AI$2500,0)) | Q11: =IF(L11="","",N11+O11+P11) | R11: =IF(OR(Q11="",Q11=0),"",N11*100/M11) | S11: =IF(OR(Q11="",Q11=0),"",O11*100/M11) | T11: =IF(OR(Q11="",Q11=0),"",U11-R11-S11) | U11: =IF(OR(Q11="",Q11=0),"",Q11*100/M11)
A12: =IF(COUNTIFS(Basicdata!$B$2:$B$2500,1,Basicdata!$D$2:$D$2500,Crops!$B$5,Basicdata!$H$2:$H$2500,Crops!$M3)>0,Crops!$M3,"") -> 2 | B12: =IF(A12="","",COUNTIFS(Basicdata!$B$2:$B$2500,1,Basicdata!$D$2:$D$2500,Crops!$B$5,Basicdata!$H$2:$H$2500,Crops!$M3)) -> 6 | C12: =IF(A12="","",COUNTIFS(Basicdata!$B$2:$B$2500,1,Basicdata!$D$2:$D$2500,Crops!$B$5,Basicdata!$H$2:$H$2500,Crops!$M3,Basicdata!$K$2:$K$2500,1,Basicdata!$AI$2:$AI$2500,0)) -> 6 | D12: =IF(A12="","",COUNTIFS(Basicdata!$B$2:$B$2500,1,Basicdata!$D$2:$D$2500,Crops!$B$5,Basicdata!$H$2:$H$2500,Crops!$M3,Basicdata!$K$2:$K$2500,2,Basicdata!$AI$2:$AI$2500,0)) -> 0 | E12: =IF(A12="","",COUNTIFS(Basicdata!$B$2:$B$2500,1,Basicdata!$D$2:$D$2500,Crops!$B$5,Basicdata!$H$2:$H$2500,Crops!$M3,Basicdata!$K$2:$K$2500,3,Basicdata!$AI$2:$AI$2500,0)) -> 0 | F12: =IF(A12="","",C12+D12+E12) -> 6 | G12: =IF(OR(F12="",F12=0),"",C12*100/B12) -> 100 | H12: =IF(OR(F12="",F12=0),"",D12*100/B12) -> 0 | I12: =IF(OR(F12="",F12=0),"",J12-G12-H12) -> 0 | J12: =IF(OR(F12="",F12=0),"",F12*100/B12) -> 100 | L12: =IF(COUNTIFS(Basicdata!$B$2:$B$2500,2,Basicdata!$D$2:$D$2500,Crops!$B$5,Basicdata!$H$2:$H$2500,Crops!$M3)>0,Crops!$M3,"") -> 2 | M12: =IF(L12="","",COUNTIFS(Basicdata!$B$2:$B$2500,2,Basicdata!$D$2:$D$2500,Crops!$B$5,Basicdata!$H$2:$H$2500,Crops!$M3)) -> 6 | N12: =IF(L12="","",COUNTIFS(Basicdata!$B$2:$B$2500,2,Basicdata!$D$2:$D$2500,Crops!$B$5,Basicdata!$H$2:$H$2500,Crops!$M3,Basicdata!$K$2:$K$2500,1,Basicdata!$AI$2:$AI$2500,0)) -> 6 | O12: =IF(L12="","",COUNTIFS(Basicdata!$B$2:$B$2500,2,Basicdata!$D$2:$D$2500,Crops!$B$5,Basicdata!$H$2:$H$2500,Crops!$M3,Basicdata!$K$2:$K$2500,2,Basicdata!$AI$2:$AI$2500,0)) -> 0 | P12: =IF(L12="","",COUNTIFS(Basicdata!$B$2:$B$2500,2,Basicdata!$D$2:$D$2500,Crops!$B$5,Basicdata!$H$2:$H$2500,Crops!$M3,Basicdata!$K$2:$K$2500,3,Basicdata!$AI$2:$AI$2500,0)) -> 0 | Q12: =IF(L12="","",N12+O12+P12) -> 6 | R12: =IF(OR(Q12="",Q12=0),"",N12*100/M12) -> 100 | S12: =IF(OR(Q12="",Q12=0),"",O12*100/M12) -> 0 | T12: =IF(OR(Q12="",Q12=0),"",U12-R12-S12) -> 0 | U12: =IF(OR(Q12="",Q12=0),"",Q12*100/M12) -> 100
A13: =IF(COUNTIFS(Basicdata!$B$2:$B$2500,1,Basicdata!$D$2:$D$2500,Crops!$B$5,Basicdata!$H$2:$H$2500,Crops!$M4)>0,Crops!$M4,"") | B13: =IF(A13="","",COUNTIFS(Basicdata!$B$2:$B$2500,1,Basicdata!$D$2:$D$2500,Crops!$B$5,Basicdata!$H$2:$H$2500,Crops!$M4)) | C13: =IF(A13="","",COUNTIFS(Basicdata!$B$2:$B$2500,1,Basicdata!$D$2:$D$2500,Crops!$B$5,Basicdata!$H$2:$H$2500,Crops!$M4,Basicdata!$K$2:$K$2500,1,Basicdata!$AI$2:$AI$2500,0)) | D13: =IF(A13="","",COUNTIFS(Basicdata!$B$2:$B$2500,1,Basicdata!$D$2:$D$2500,Crops!$B$5,Basicdata!$H$2:$H$2500,Crops!$M4,Basicdata!$K$2:$K$2500,2,Basicdata!$AI$2:$AI$2500,0)) | E13: =IF(A13="","",COUNTIFS(Basicdata!$B$2:$B$2500,1,Basicdata!$D$2:$D$2500,Crops!$B$5,Basicdata!$H$2:$H$2500,Crops!$M4,Basicdata!$K$2:$K$2500,3,Basicdata!$AI$2:$AI$2500,0)) | F13: =IF(A13="","",C13+D13+E13) | G13: =IF(OR(F13="",F13=0),"",C13*100/B13) | H13: =IF(OR(F13="",F13=0),"",D13*100/B13) | I13: =IF(OR(F13="",F13=0),"",J13-G13-H13) | J13: =IF(OR(F13="",F13=0),"",F13*100/B13) | L13: =IF(COUNTIFS(Basicdata!$B$2:$B$2500,2,Basicdata!$D$2:$D$2500,Crops!$B$5,Basicdata!$H$2:$H$2500,Crops!$M4)>0,Crops!$M4,"") | M13: =IF(L13="","",COUNTIFS(Basicdata!$B$2:$B$2500,2,Basicdata!$D$2:$D$2500,Crops!$B$5,Basicdata!$H$2:$H$2500,Crops!$M4)) | N13: =IF(L13="","",COUNTIFS(Basicdata!$B$2:$B$2500,2,Basicdata!$D$2:$D$2500,Crops!$B$5,Basicdata!$H$2:$H$2500,Crops!$M4,Basicdata!$K$2:$K$2500,1,Basicdata!$AI$2:$AI$2500,0)) | O13: =IF(L13="","",COUNTIFS(Basicdata!$B$2:$B$2500,2,Basicdata!$D$2:$D$2500,Crops!$B$5,Basicdata!$H$2:$H$2500,Crops!$M4,Basicdata!$K$2:$K$2500,2,Basicdata!$AI$2:$AI$2500,0)) | P13: =IF(L13="","",COUNTIFS(Basicdata!$B$2:$B$2500,2,Basicdata!$D$2:$D$2500,Crops!$B$5,Basicdata!$H$2:$H$2500,Crops!$M4,Basicdata!$K$2:$K$2500,3,Basicdata!$AI$2:$AI$2500,0)) | Q13: =IF(L13="","",N13+O13+P13) | R13: =IF(OR(Q13="",Q13=0),"",N13*100/M13) | S13: =IF(OR(Q13="",Q13=0),"",O13*100/M13) | T13: =IF(OR(Q13="",Q13=0),"",U13-R13-S13) | U13: =IF(OR(Q13="",Q13=0),"",Q13*100/M13)
A14: =IF(COUNTIFS(Basicdata!$B$2:$B$2500,1,Basicdata!$D$2:$D$2500,Crops!$B$5,Basicdata!$H$2:$H$2500,Crops!$M5)>0,Crops!$M5,"") -> 4 | B14: =IF(A14="","",COUNTIFS(Basicdata!$B$2:$B$2500,1,Basicdata!$D$2:$D$2500,Crops!$B$5,Basicdata!$H$2:$H$2500,Crops!$M5)) -> 3 | C14: =IF(A14="","",COUNTIFS(Basicdata!$B$2:$B$2500,1,Basicdata!$D$2:$D$2500,Crops!$B$5,Basicdata!$H$2:$H$2500,Crops!$M5,Basicdata!$K$2:$K$2500,1,Basicdata!$AI$2:$AI$2500,0)) -> 3 | D14: =IF(A14="","",COUNTIFS(Basicdata!$B$2:$B$2500,1,Basicdata!$D$2:$D$2500,Crops!$B$5,Basicdata!$H$2:$H$2500,Crops!$M5,Basicdata!$K$2:$K$2500,2,Basicdata!$AI$2:$AI$2500,0)) -> 0 | E14: =IF(A14="","",COUNTIFS(Basicdata!$B$2:$B$2500,1,Basicdata!$D$2:$D$2500,Crops!$B$5,Basicdata!$H$2:$H$2500,Crops!$M5,Basicdata!$K$2:$K$2500,3,Basicdata!$AI$2:$AI$2500,0)) -> 0 | F14: =IF(A14="","",C14+D14+E14) -> 3 | G14: =IF(OR(F14="",F14=0),"",C14*100/B14) -> 100 | H14: =IF(OR(F14="",F14=0),"",D14*100/B14) -> 0 | I14: =IF(OR(F14="",F14=0),"",J14-G14-H14) -> 0 | J14: =IF(OR(F14="",F14=0),"",F14*100/B14) -> 100 | L14: =IF(COUNTIFS(Basicdata!$B$2:$B$2500,2,Basicdata!$D$2:$D$2500,Crops!$B$5,Basicdata!$H$2:$H$2500,Crops!$M5)>0,Crops!$M5,"") -> 4 | M14: =IF(L14="","",COUNTIFS(Basicdata!$B$2:$B$2500,2,Basicdata!$D$2:$D$2500,Crops!$B$5,Basicdata!$H$2:$H$2500,Crops!$M5)) -> 3 | N14: =IF(L14="","",COUNTIFS(Basicdata!$B$2:$B$2500,2,Basicdata!$D$2:$D$2500,Crops!$B$5,Basicdata!$H$2:$H$2500,Crops!$M5,Basicdata!$K$2:$K$2500,1,Basicdata!$AI$2:$AI$2500,0)) -> 3 | O14: =IF(L14="","",COUNTIFS(Basicdata!$B$2:$B$2500,2,Basicdata!$D$2:$D$2500,Crops!$B$5,Basicdata!$H$2:$H$2500,Crops!$M5,Basicdata!$K$2:$K$2500,2,Basicdata!$AI$2:$AI$2500,0)) -> 0 | P14: =IF(L14="","",COUNTIFS(Basicdata!$B$2:$B$2500,2,Basicdata!$D$2:$D$2500,Crops!$B$5,Basicdata!$H$2:$H$2500,Crops!$M5,Basicdata!$K$2:$K$2500,3,Basicdata!$AI$2:$AI$2500,0)) -> 0 | Q14: =IF(L14="","",N14+O14+P14) -> 3 | R14: =IF(OR(Q14="",Q14=0),"",N14*100/M14) -> 100 | S14: =IF(OR(Q14="",Q14=0),"",O14*100/M14) -> 0 | T14: =IF(OR(Q14="",Q14=0),"",U14-R14-S14) -> 0 | U14: =IF(OR(Q14="",Q14=0),"",Q14*100/M14) -> 100
A15: =IF(COUNTIFS(Basicdata!$B$2:$B$2500,1,Basicdata!$D$2:$D$2500,Crops!$B$5,Basicdata!$H$2:$H$2500,Crops!$M6)>0,Crops!$M6,"") | B15: =IF(A15="","",COUNTIFS(Basicdata!$B$2:$B$2500,1,Basicdata!$D$2:$D$2500,Crops!$B$5,Basicdata!$H$2:$H$2500,Crops!$M6)) | C15: =IF(A15="","",COUNTIFS(Basicdata!$B$2:$B$2500,1,Basicdata!$D$2:$D$2500,Crops!$B$5,Basicdata!$H$2:$H$2500,Crops!$M6,Basicdata!$K$2:$K$2500,1,Basicdata!$AI$2:$AI$2500,0)) | D15: =IF(A15="","",COUNTIFS(Basicdata!$B$2:$B$2500,1,Basicdata!$D$2:$D$2500,Crops!$B$5,Basicdata!$H$2:$H$2500,Crops!$M6,Basicdata!$K$2:$K$2500,2,Basicdata!$AI$2:$AI$2500,0)) | E15: =IF(A15="","",COUNTIFS(Basicdata!$B$2:$B$2500,1,Basicdata!$D$2:$D$2500,Crops!$B$5,Basicdata!$H$2:$H$2500,Crops!$M6,Basicdata!$K$2:$K$2500,3,Basicdata!$AI$2:$AI$2500,0)) | F15: =IF(A15="","",C15+D15+E15) | G15: =IF(OR(F15="",F15=0),"",C15*100/B15) | H15: =IF(OR(F15="",F15=0),"",D15*100/B15) | I15: =IF(OR(F15="",F15=0),"",J15-G15-H15) | J15: =IF(OR(F15="",F15=0),"",F15*100/B15) | L15: =IF(COUNTIFS(Basicdata!$B$2:$B$2500,2,Basicdata!$D$2:$D$2500,Crops!$B$5,Basicdata!$H$2:$H$2500,Crops!$M6)>0,Crops!$M6,"") | M15: =IF(L15="","",COUNTIFS(Basicdata!$B$2:$B$2500,2,Basicdata!$D$2:$D$2500,Crops!$B$5,Basicdata!$H$2:$H$2500,Crops!$M6)) | N15: =IF(L15="","",COUNTIFS(Basicdata!$B$2:$B$2500,2,Basicdata!$D$2:$D$2500,Crops!$B$5,Basicdata!$H$2:$H$2500,Crops!$M6,Basicdata!$K$2:$K$2500,1,Basicdata!$AI$2:$AI$2500,0)) | O15: =IF(L15="","",COUNTIFS(Basicdata!$B$2:$B$2500,2,Basicdata!$D$2:$D$2500,Crops!$B$5,Basicdata!$H$2:$H$2500,Crops!$M6,Basicdata!$K$2:$K$2500,2,Basicdata!$AI$2:$AI$2500,0)) | P15: =IF(L15="","",COUNTIFS(Basicdata!$B$2:$B$2500,2,Basicdata!$D$2:$D$2500,Crops!$B$5,Basicdata!$H$2:$H$2500,Crops!$M6,Basicdata!$K$2:$K$2500,3,Basicdata!$AI$2:$AI$2500,0)) | Q15: =IF(L15="","",N15+O15+P15) | R15: =IF(OR(Q15="",Q15=0),"",N15*100/M15) | S15: =IF(OR(Q15="",Q15=0),"",O15*100/M15) | T15: =IF(OR(Q15="",Q15=0),"",U15-R15-S15) | U15: =IF(OR(Q15="",Q15=0),"",Q15*100/M15)
A16: =IF(COUNTIFS(Basicdata!$B$2:$B$2500,1,Basicdata!$D$2:$D$2500,Crops!$B$5,Basicdata!$H$2:$H$2500,Crops!$M7)>0,Crops!$M7,"") | B16: =IF(A16="","",COUNTIFS(Basicdata!$B$2:$B$2500,1,Basicdata!$D$2:$D$2500,Crops!$B$5,Basicdata!$H$2:$H$2500,Crops!$M7)) | C16: =IF(A16="","",COUNTIFS(Basicdata!$B$2:$B$2500,1,Basicdata!$D$2:$D$2500,Crops!$B$5,Basicdata!$H$2:$H$2500,Crops!$M7,Basicdata!$K$2:$K$2500,1,Basicdata!$AI$2:$AI$2500,0)) | D16: =IF(A16="","",COUNTIFS(Basicdata!$B$2:$B$2500,1,Basicdata!$D$2:$D$2500,Crops!$B$5,Basicdata!$H$2:$H$2500,Crops!$M7,Basicdata!$K$2:$K$2500,2,Basicdata!$AI$2:$AI$2500,0)) | E16: =IF(A16="","",COUNTIFS(Basicdata!$B$2:$B$2500,1,Basicdata!$D$2:$D$2500,Crops!$B$5,Basicdata!$H$2:$H$2500,Crops!$M7,Basicdata!$K$2:$K$2500,3,Basicdata!$AI$2:$AI$2500,0)) | F16: =IF(A16="","",C16+D16+E16) | G16: =IF(OR(F16="",F16=0),"",C16*100/B16) | H16: =IF(OR(F16="",F16=0),"",D16*100/B16) | I16: =IF(OR(F16="",F16=0),"",J16-G16-H16) | J16: =IF(OR(F16="",F16=0),"",F16*100/B16) | L16: =IF(COUNTIFS(Basicdata!$B$2:$B$2500,2,Basicdata!$D$2:$D$2500,Crops!$B$5,Basicdata!$H$2:$H$2500,Crops!$M7)>0,Crops!$M7,"") | M16: =IF(L16="","",COUNTIFS(Basicdata!$B$2:$B$2500,2,Basicdata!$D$2:$D$2500,Crops!$B$5,Basicdata!$H$2:$H$2500,Crops!$M7)) | N16: =IF(L16="","",COUNTIFS(Basicdata!$B$2:$B$2500,2,Basicdata!$D$2:$D$2500,Crops!$B$5,Basicdata!$H$2:$H$2500,Crops!$M7,Basicdata!$K$2:$K$2500,1,Basicdata!$AI$2:$AI$2500,0)) | O16: =IF(L16="","",COUNTIFS(Basicdata!$B$2:$B$2500,2,Basicdata!$D$2:$D$2500,Crops!$B$5,Basicdata!$H$2:$H$2500,Crops!$M7,Basicdata!$K$2:$K$2500,2,Basicdata!$AI$2:$AI$2500,0)) | P16: =IF(L16="","",COUNTIFS(Basicdata!$B$2:$B$2500,2,Basicdata!$D$2:$D$2500,Crops!$B$5,Basicdata!$H$2:$H$2500,Crops!$M7,Basicdata!$K$2:$K$2500,3,Basicdata!$AI$2:$AI$2500,0)) | Q16: =IF(L16="","",N16+O16+P16) | R16: =IF(OR(Q16="",Q16=0),"",N16*100/M16) | S16: =IF(OR(Q16="",Q16=0),"",O16*100/M16) | T16: =IF(OR(Q16="",Q16=0),"",U16-R16-S16) | U16: =IF(OR(Q16="",Q16=0),"",Q16*100/M16)
A17: =IF(COUNTIFS(Basicdata!$B$2:$B$2500,1,Basicdata!$D$2:$D$2500,Crops!$B$5,Basicdata!$H$2:$H$2500,Crops!$M8)>0,Crops!$M8,"") | B17: =IF(A17="","",COUNTIFS(Basicdata!$B$2:$B$2500,1,Basicdata!$D$2:$D$2500,Crops!$B$5,Basicdata!$H$2:$H$2500,Crops!$M8)) | C17: =IF(A17="","",COUNTIFS(Basicdata!$B$2:$B$2500,1,Basicdata!$D$2:$D$2500,Crops!$B$5,Basicdata!$H$2:$H$2500,Crops!$M8,Basicdata!$K$2:$K$2500,1,Basicdata!$AI$2:$AI$2500,0)) | D17: =IF(A17="","",COUNTIFS(Basicdata!$B$2:$B$2500,1,Basicdata!$D$2:$D$2500,Crops!$B$5,Basicdata!$H$2:$H$2500,Crops!$M8,Basicdata!$K$2:$K$2500,2,Basicdata!$AI$2:$AI$2500,0)) | E17: =IF(A17="","",COUNTIFS(Basicdata!$B$2:$B$2500,1,Basicdata!$D$2:$D$2500,Crops!$B$5,Basicdata!$H$2:$H$2500,Crops!$M8,Basicdata!$K$2:$K$2500,3,Basicdata!$AI$2:$AI$2500,0)) | F17: =IF(A17="","",C17+D17+E17) | G17: =IF(OR(F17="",F17=0),"",C17*100/B17) | H17: =IF(OR(F17="",F17=0),"",D17*100/B17) | I17: =IF(OR(F17="",F17=0),"",J17-G17-H17) | J17: =IF(OR(F17="",F17=0),"",F17*100/B17) | L17: =IF(COUNTIFS(Basicdata!$B$2:$B$2500,2,Basicdata!$D$2:$D$2500,Crops!$B$5,Basicdata!$H$2:$H$2500,Crops!$M8)>0,Crops!$M8,"") | M17: =IF(L17="","",COUNTIFS(Basicdata!$B$2:$B$2500,2,Basicdata!$D$2:$D$2500,Crops!$B$5,Basicdata!$H$2:$H$2500,Crops!$M8)) | N17: =IF(L17="","",COUNTIFS(Basicdata!$B$2:$B$2500,2,Basicdata!$D$2:$D$2500,Crops!$B$5,Basicdata!$H$2:$H$2500,Crops!$M8,Basicdata!$K$2:$K$2500,1,Basicdata!$AI$2:$AI$2500,0)) | O17: =IF(L17="","",COUNTIFS(Basicdata!$B$2:$B$2500,2,Basicdata!$D$2:$D$2500,Crops!$B$5,Basicdata!$H$2:$H$2500,Crops!$M8,Basicdata!$K$2:$K$2500,2,Basicdata!$AI$2:$AI$2500,0)) | P17: =IF(L17="","",COUNTIFS(Basicdata!$B$2:$B$2500,2,Basicdata!$D$2:$D$2500,Crops!$B$5,Basicdata!$H$2:$H$2500,Crops!$M8,Basicdata!$K$2:$K$2500,3,Basicdata!$AI$2:$AI$2500,0)) | Q17: =IF(L17="","",N17+O17+P17) | R17: =IF(OR(Q17="",Q17=0),"",N17*100/M17) | S17: =IF(OR(Q17="",Q17=0),"",O17*100/M17) | T17: =IF(OR(Q17="",Q17=0),"",U17-R17-S17) | U17: =IF(OR(Q17="",Q17=0),"",Q17*100/M17)
A18: =IF(COUNTIFS(Basicdata!$B$2:$B$2500,1,Basicdata!$D$2:$D$2500,Crops!$B$5,Basicdata!$H$2:$H$2500,Crops!$M9)>0,Crops!$M9,"") | B18: =IF(A18="","",COUNTIFS(Basicdata!$B$2:$B$2500,1,Basicdata!$D$2:$D$2500,Crops!$B$5,Basicdata!$H$2:$H$2500,Crops!$M9)) | C18: =IF(A18="","",COUNTIFS(Basicdata!$B$2:$B$2500,1,Basicdata!$D$2:$D$2500,Crops!$B$5,Basicdata!$H$2:$H$2500,Crops!$M9,Basicdata!$K$2:$K$2500,1,Basicdata!$AI$2:$AI$2500,0)) | D18: =IF(A18="","",COUNTIFS(Basicdata!$B$2:$B$2500,1,Basicdata!$D$2:$D$2500,Crops!$B$5,Basicdata!$H$2:$H$2500,Crops!$M9,Basicdata!$K$2:$K$2500,2,Basicdata!$AI$2:$AI$2500,0)) | E18: =IF(A18="","",COUNTIFS(Basicdata!$B$2:$B$2500,1,Basicdata!$D$2:$D$2500,Crops!$B$5,Basicdata!$H$2:$H$2500,Crops!$M9,Basicdata!$K$2:$K$2500,3,Basicdata!$AI$2:$AI$2500,0)) | F18: =IF(A18="","",C18+D18+E18) | G18: =IF(OR(F18="",F18=0),"",C18*100/B18) | H18: =IF(OR(F18="",F18=0),"",D18*100/B18) | I18: =IF(OR(F18="",F18=0),"",J18-G18-H18) | J18: =IF(OR(F18="",F18=0),"",F18*100/B18) | L18: =IF(COUNTIFS(Basicdata!$B$2:$B$2500,2,Basicdata!$D$2:$D$2500,Crops!$B$5,Basicdata!$H$2:$H$2500,Crops!$M9)>0,Crops!$M9,"") | M18: =IF(L18="","",COUNTIFS(Basicdata!$B$2:$B$2500,2,Basicdata!$D$2:$D$2500,Crops!$B$5,Basicdata!$H$2:$H$2500,Crops!$M9)) | N18: =IF(L18="","",COUNTIFS(Basicdata!$B$2:$B$2500,2,Basicdata!$D$2:$D$2500,Crops!$B$5,Basicdata!$H$2:$H$2500,Crops!$M9,Basicdata!$K$2:$K$2500,1,Basicdata!$AI$2:$AI$2500,0)) | O18: =IF(L18="","",COUNTIFS(Basicdata!$B$2:$B$2500,2,Basicdata!$D$2:$D$2500,Crops!$B$5,Basicdata!$H$2:$H$2500,Crops!$M9,Basicdata!$K$2:$K$2500,2,Basicdata!$AI$2:$AI$2500,0)) | P18: =IF(L18="","",COUNTIFS(Basicdata!$B$2:$B$2500,2,Basicdata!$D$2:$D$2500,Crops!$B$5,Basicdata!$H$2:$H$2500,Crops!$M9,Basicdata!$K$2:$K$2500,3,Basicdata!$AI$2:$AI$2500,0)) | Q18: =IF(L18="","",N18+O18+P18) | R18: =IF(OR(Q18="",Q18=0),"",N18*100/M18) | S18: =IF(OR(Q18="",Q18=0),"",O18*100/M18) | T18: =IF(OR(Q18="",Q18=0),"",U18-R18-S18) | U18: =IF(OR(Q18="",Q18=0),"",Q18*100/M18)
A19: =IF(COUNTIFS(Basicdata!$B$2:$B$2500,1,Basicdata!$D$2:$D$2500,Crops!$B$5,Basicdata!$H$2:$H$2500,Crops!$M10)>0,Crops!$M10,"") | B19: =IF(A19="","",COUNTIFS(Basicdata!$B$2:$B$2500,1,Basicdata!$D$2:$D$2500,Crops!$B$5,Basicdata!$H$2:$H$2500,Crops!$M10)) | C19: =IF(A19="","",COUNTIFS(Basicdata!$B$2:$B$2500,1,Basicdata!$D$2:$D$2500,Crops!$B$5,Basicdata!$H$2:$H$2500,Crops!$M10,Basicdata!$K$2:$K$2500,1,Basicdata!$AI$2:$AI$2500,0)) | D19: =IF(A19="","",COUNTIFS(Basicdata!$B$2:$B$2500,1,Basicdata!$D$2:$D$2500,Crops!$B$5,Basicdata!$H$2:$H$2500,Crops!$M10,Basicdata!$K$2:$K$2500,2,Basicdata!$AI$2:$AI$2500,0)) | E19: =IF(A19="","",COUNTIFS(Basicdata!$B$2:$B$2500,1,Basicdata!$D$2:$D$2500,Crops!$B$5,Basicdata!$H$2:$H$2500,Crops!$M10,Basicdata!$K$2:$K$2500,3,Basicdata!$AI$2:$AI$2500,0)) | F19: =IF(A19="","",C19+D19+E19) | G19: =IF(OR(F19="",F19=0),"",C19*100/B19) | H19: =IF(OR(F19="",F19=0),"",D19*100/B19) | I19: =IF(OR(F19="",F19=0),"",J19-G19-H19) | J19: =IF(OR(F19="",F19=0),"",F19*100/B19) | L19: =IF(COUNTIFS(Basicdata!$B$2:$B$2500,2,Basicdata!$D$2:$D$2500,Crops!$B$5,Basicdata!$H$2:$H$2500,Crops!$M10)>0,Crops!$M10,"") | M19: =IF(L19="","",COUNTIFS(Basicdata!$B$2:$B$2500,2,Basicdata!$D$2:$D$2500,Crops!$B$5,Basicdata!$H$2:$H$2500,Crops!$M10)) | N19: =IF(L19="","",COUNTIFS(Basicdata!$B$2:$B$2500,2,Basicdata!$D$2:$D$2500,Crops!$B$5,Basicdata!$H$2:$H$2500,Crops!$M10,Basicdata!$K$2:$K$2500,1,Basicdata!$AI$2:$AI$2500,0)) | O19: =IF(L19="","",COUNTIFS(Basicdata!$B$2:$B$2500,2,Basicdata!$D$2:$D$2500,Crops!$B$5,Basicdata!$H$2:$H$2500,Crops!$M10,Basicdata!$K$2:$K$2500,2,Basicdata!$AI$2:$AI$2500,0)) | P19: =IF(L19="","",COUNTIFS(Basicdata!$B$2:$B$2500,2,Basicdata!$D$2:$D$2500,Crops!$B$5,Basicdata!$H$2:$H$2500,Crops!$M10,Basicdata!$K$2:$K$2500,3,Basicdata!$AI$2:$AI$2500,0)) | Q19: =IF(L19="","",N19+O19+P19) | R19: =IF(OR(Q19="",Q19=0),"",N19*100/M19) | S19: =IF(OR(Q19="",Q19=0),"",O19*100/M19) | T19: =IF(OR(Q19="",Q19=0),"",U19-R19-S19) | U19: =IF(OR(Q19="",Q19=0),"",Q19*100/M19)
A20: =IF(COUNTIFS(Basicdata!$B$2:$B$2500,1,Basicdata!$D$2:$D$2500,Crops!$B$5,Basicdata!$H$2:$H$2500,Crops!$M11)>0,Crops!$M11,"") | B20: =IF(A20="","",COUNTIFS(Basicdata!$B$2:$B$2500,1,Basicdata!$D$2:$D$2500,Crops!$B$5,Basicdata!$H$2:$H$2500,Crops!$M11)) | C20: =IF(A20="","",COUNTIFS(Basicdata!$B$2:$B$2500,1,Basicdata!$D$2:$D$2500,Crops!$B$5,Basicdata!$H$2:$H$2500,Crops!$M11,Basicdata!$K$2:$K$2500,1,Basicdata!$AI$2:$AI$2500,0)) | D20: =IF(A20="","",COUNTIFS(Basicdata!$B$2:$B$2500,1,Basicdata!$D$2:$D$2500,Crops!$B$5,Basicdata!$H$2:$H$2500,Crops!$M11,Basicdata!$K$2:$K$2500,2,Basicdata!$AI$2:$AI$2500,0)) | E20: =IF(A20="","",COUNTIFS(Basicdata!$B$2:$B$2500,1,Basicdata!$D$2:$D$2500,Crops!$B$5,Basicdata!$H$2:$H$2500,Crops!$M11,Basicdata!$K$2:$K$2500,3,Basicdata!$AI$2:$AI$2500,0)) | F20: =IF(A20="","",C20+D20+E20) | G20: =IF(OR(F20="",F20=0),"",C20*100/B20) | H20: =IF(OR(F20="",F20=0),"",D20*100/B20) | I20: =IF(OR(F20="",F20=0),"",J20-G20-H20) | J20: =IF(OR(F20="",F20=0),"",F20*100/B20) | L20: =IF(COUNTIFS(Basicdata!$B$2:$B$2500,2,Basicdata!$D$2:$D$2500,Crops!$B$5,Basicdata!$H$2:$H$2500,Crops!$M11)>0,Crops!$M11,"") | M20: =IF(L20="","",COUNTIFS(Basicdata!$B$2:$B$2500,2,Basicdata!$D$2:$D$2500,Crops!$B$5,Basicdata!$H$2:$H$2500,Crops!$M11)) | N20: =IF(L20="","",COUNTIFS(Basicdata!$B$2:$B$2500,2,Basicdata!$D$2:$D$2500,Crops!$B$5,Basicdata!$H$2:$H$2500,Crops!$M11,Basicdata!$K$2:$K$2500,1,Basicdata!$AI$2:$AI$2500,0)) | O20: =IF(L20="","",COUNTIFS(Basicdata!$B$2:$B$2500,2,Basicdata!$D$2:$D$2500,Crops!$B$5,Basicdata!$H$2:$H$2500,Crops!$M11,Basicdata!$K$2:$K$2500,2,Basicdata!$AI$2:$AI$2500,0)) | P20: =IF(L20="","",COUNTIFS(Basicdata!$B$2:$B$2500,2,Basicdata!$D$2:$D$2500,Crops!$B$5,Basicdata!$H$2:$H$2500,Crops!$M11,Basicdata!$K$2:$K$2500,3,Basicdata!$AI$2:$AI$2500,0)) | Q20: =IF(L20="","",N20+O20+P20) | R20: =IF(OR(Q20="",Q20=0),"",N20*100/M20) | S20: =IF(OR(Q20="",Q20=0),"",O20*100/M20) | T20: =IF(OR(Q20="",Q20=0),"",U20-R20-S20) | U20: =IF(OR(Q20="",Q20=0),"",Q20*100/M20)
A21: =IF(COUNTIFS(Basicdata!$B$2:$B$2500,1,Basicdata!$D$2:$D$2500,Crops!$B$5,Basicdata!$H$2:$H$2500,Crops!$M12)>0,Crops!$M12,"") | B21: =IF(A21="","",COUNTIFS(Basicdata!$B$2:$B$2500,1,Basicdata!$D$2:$D$2500,Crops!$B$5,Basicdata!$H$2:$H$2500,Crops!$M12)) | C21: =IF(A21="","",COUNTIFS(Basicdata!$B$2:$B$2500,1,Basicdata!$D$2:$D$2500,Crops!$B$5,Basicdata!$H$2:$H$2500,Crops!$M12,Basicdata!$K$2:$K$2500,1,Basicdata!$AI$2:$AI$2500,0)) | D21: =IF(A21="","",COUNTIFS(Basicdata!$B$2:$B$2500,1,Basicdata!$D$2:$D$2500,Crops!$B$5,Basicdata!$H$2:$H$2500,Crops!$M12,Basicdata!$K$2:$K$2500,2,Basicdata!$AI$2:$AI$2500,0)) | E21: =IF(A21="","",COUNTIFS(Basicdata!$B$2:$B$2500,1,Basicdata!$D$2:$D$2500,Crops!$B$5,Basicdata!$H$2:$H$2500,Crops!$M12,Basicdata!$K$2:$K$2500,3,Basicdata!$AI$2:$AI$2500,0)) | F21: =IF(A21="","",C21+D21+E21) | G21: =IF(OR(F21="",F21=0),"",C21*100/B21) | H21: =IF(OR(F21="",F21=0),"",D21*100/B21) | I21: =IF(OR(F21="",F21=0),"",J21-G21-H21) | J21: =IF(OR(F21="",F21=0),"",F21*100/B21) | L21: =IF(COUNTIFS(Basicdata!$B$2:$B$2500,2,Basicdata!$D$2:$D$2500,Crops!$B$5,Basicdata!$H$2:$H$2500,Crops!$M12)>0,Crops!$M12,"") | M21: =IF(L21="","",COUNTIFS(Basicdata!$B$2:$B$2500,2,Basicdata!$D$2:$D$2500,Crops!$B$5,Basicdata!$H$2:$H$2500,Crops!$M12)) | N21: =IF(L21="","",COUNTIFS(Basicdata!$B$2:$B$2500,2,Basicdata!$D$2:$D$2500,Crops!$B$5,Basicdata!$H$2:$H$2500,Crops!$M12,Basicdata!$K$2:$K$2500,1,Basicdata!$AI$2:$AI$2500,0)) | O21: =IF(L21="","",COUNTIFS(Basicdata!$B$2:$B$2500,2,Basicdata!$D$2:$D$2500,Crops!$B$5,Basicdata!$H$2:$H$2500,Crops!$M12,Basicdata!$K$2:$K$2500,2,Basicdata!$AI$2:$AI$2500,0)) | P21: =IF(L21="","",COUNTIFS(Basicdata!$B$2:$B$2500,2,Basicdata!$D$2:$D$2500,Crops!$B$5,Basicdata!$H$2:$H$2500,Crops!$M12,Basicdata!$K$2:$K$2500,3,Basicdata!$AI$2:$AI$2500,0)) | Q21: =IF(L21="","",N21+O21+P21) | R21: =IF(OR(Q21="",Q21=0),"",N21*100/M21) | S21: =IF(OR(Q21="",Q21=0),"",O21*100/M21) | T21: =IF(OR(Q21="",Q21=0),"",U21-R21-S21) | U21: =IF(OR(Q21="",Q21=0),"",Q21*100/M21)
A22: =IF(COUNTIFS(Basicdata!$B$2:$B$2500,1,Basicdata!$D$2:$D$2500,Crops!$B$5,Basicdata!$H$2:$H$2500,Crops!$M13)>0,Crops!$M13,"") | B22: =IF(A22="","",COUNTIFS(Basicdata!$B$2:$B$2500,1,Basicdata!$D$2:$D$2500,Crops!$B$5,Basicdata!$H$2:$H$2500,Crops!$M13)) | C22: =IF(A22="","",COUNTIFS(Basicdata!$B$2:$B$2500,1,Basicdata!$D$2:$D$2500,Crops!$B$5,Basicdata!$H$2:$H$2500,Crops!$M13,Basicdata!$K$2:$K$2500,1,Basicdata!$AI$2:$AI$2500,0)) | D22: =IF(A22="","",COUNTIFS(Basicdata!$B$2:$B$2500,1,Basicdata!$D$2:$D$2500,Crops!$B$5,Basicdata!$H$2:$H$2500,Crops!$M13,Basicdata!$K$2:$K$2500,2,Basicdata!$AI$2:$AI$2500,0)) | E22: =IF(A22="","",COUNTIFS(Basicdata!$B$2:$B$2500,1,Basicdata!$D$2:$D$2500,Crops!$B$5,Basicdata!$H$2:$H$2500,Crops!$M13,Basicdata!$K$2:$K$2500,3,Basicdata!$AI$2:$AI$2500,0)) | F22: =IF(A22="","",C22+D22+E22) | G22: =IF(OR(F22="",F22=0),"",C22*100/B22) | H22: =IF(OR(F22="",F22=0),"",D22*100/B22) | I22: =IF(OR(F22="",F22=0),"",J22-G22-H22) | J22: =IF(OR(F22="",F22=0),"",F22*100/B22) | L22: =IF(COUNTIFS(Basicdata!$B$2:$B$2500,2,Basicdata!$D$2:$D$2500,Crops!$B$5,Basicdata!$H$2:$H$2500,Crops!$M13)>0,Crops!$M13,"") | M22: =IF(L22="","",COUNTIFS(Basicdata!$B$2:$B$2500,2,Basicdata!$D$2:$D$2500,Crops!$B$5,Basicdata!$H$2:$H$2500,Crops!$M13)) | N22: =IF(L22="","",COUNTIFS(Basicdata!$B$2:$B$2500,2,Basicdata!$D$2:$D$2500,Crops!$B$5,Basicdata!$H$2:$H$2500,Crops!$M13,Basicdata!$K$2:$K$2500,1,Basicdata!$AI$2:$AI$2500,0)) | O22: =IF(L22="","",COUNTIFS(Basicdata!$B$2:$B$2500,2,Basicdata!$D$2:$D$2500,Crops!$B$5,Basicdata!$H$2:$H$2500,Crops!$M13,Basicdata!$K$2:$K$2500,2,Basicdata!$AI$2:$AI$2500,0)) | P22: =IF(L22="","",COUNTIFS(Basicdata!$B$2:$B$2500,2,Basicdata!$D$2:$D$2500,Crops!$B$5,Basicdata!$H$2:$H$2500,Crops!$M13,Basicdata!$K$2:$K$2500,3,Basicdata!$AI$2:$AI$2500,0)) | Q22: =IF(L22="","",N22+O22+P22) | R22: =IF(OR(Q22="",Q22=0),"",N22*100/M22) | S22: =IF(OR(Q22="",Q22=0),"",O22*100/M22) | T22: =IF(OR(Q22="",Q22=0),"",U22-R22-S22) | U22: =IF(OR(Q22="",Q22=0),"",Q22*100/M22)
... A97: =IF(COUNTIFS(Basicdata!$B$2:$B$2500,1,Basicdata!$D$2:$D$2500,Crops!$B$5,Basicdata!$H$2:$H$2500,Crops!$M88)>0,Crops!$M88,"") | B97: =IF(A97="","",COUNTIFS(Basicdata!$B$2:$B$2500,1,Basicdata!$D$2:$D$2500,Crops!$B$5,Basicdata!$H$2:$H$2500,Crops!$M88)) | C97: =IF(A97="","",COUNTIFS(Basicdata!$B$2:$B$2500,1,Basicdata!$D$2:$D$2500,Crops!$B$5,Basicdata!$H$2:$H$2500,Crops!$M88,Basicdata!$K$2:$K$2500,1,Basicdata!$AI$2:$AI$2500,0)) | D97: =IF(A97="","",COUNTIFS(Basicdata!$B$2:$B$2500,1,Basicdata!$D$2:$D$2500,Crops!$B$5,Basicdata!$H$2:$H$2500,Crops!$M88,Basicdata!$K$2:$K$2500,2,Basicdata!$AI$2:$AI$2500,0)) | E97: =IF(A97="","",COUNTIFS(Basicdata!$B$2:$B$2500,1,Basicdata!$D$2:$D$2500,Crops!$B$5,Basicdata!$H$2:$H$2500,Crops!$M88,Basicdata!$K$2:$K$2500,3,Basicdata!$AI$2:$AI$2500,0)) | F97: =IF(A97="","",C97+D97+E97) | G97: =IF(OR(F97="",F97=0),"",C97*100/B97) | H97: =IF(OR(F97="",F97=0),"",D97*100/B97) | I97: =IF(OR(F97="",F97=0),"",J97-G97-H97) | J97: =IF(OR(F97="",F97=0),"",F97*100/B97) | L97: =IF(COUNTIFS(Basicdata!$B$2:$B$2500,2,Basicdata!$D$2:$D$2500,Crops!$B$5,Basicdata!$H$2:$H$2500,Crops!$M88)>0,Crops!$M88,"") | M97: =IF(L97="","",COUNTIFS(Basicdata!$B$2:$B$2500,2,Basicdata!$D$2:$D$2500,Crops!$B$5,Basicdata!$H$2:$H$2500,Crops!$M88)) | N97: =IF(L97="","",COUNTIFS(Basicdata!$B$2:$B$2500,2,Basicdata!$D$2:$D$2500,Crops!$B$5,Basicdata!$H$2:$H$2500,Crops!$M88,Basicdata!$K$2:$K$2500,1,Basicdata!$AI$2:$AI$2500,0)) | O97: =IF(L97="","",COUNTIFS(Basicdata!$B$2:$B$2500,2,Basicdata!$D$2:$D$2500,Crops!$B$5,Basicdata!$H$2:$H$2500,Crops!$M88,Basicdata!$K$2:$K$2500,2,Basicdata!$AI$2:$AI$2500,0)) | P97: =IF(L97="","",COUNTIFS(Basicdata!$B$2:$B$2500,2,Basicdata!$D$2:$D$2500,Crops!$B$5,Basicdata!$H$2:$H$2500,Crops!$M88,Basicdata!$K$2:$K$2500,3,Basicdata!$AI$2:$AI$2500,0)) | Q97: =IF(L97="","",N97+O97+P97) | R97: =IF(OR(Q97="",Q97=0),"",N97*100/M97) | S97: =IF(OR(Q97="",Q97=0),"",O97*100/M97) | T97: =IF(OR(Q97="",Q97=0),"",U97-R97-S97) | U97: =IF(OR(Q97="",Q97=0),"",Q97*100/M97)
A98: STATE: | B98: =SUM(B11:B97) -> 9 | C98: =SUM(C11:C97) -> 9 | D98: =SUM(D11:D97) -> 0 | E98: =SUM(E11:E97) -> 0 | F98: =SUM(F11:F97) -> 9 | G98: =ROUND(C98*100/$B98,2) -> 100 | H98: =ROUND(D98*100/$B98,2) -> 0 | I98: =J98-G98-H98 -> 0 | J98: =ROUND(F98*100/$B98,2) -> 100 | L98: STATE: | M98: =SUM(M11:M97) -> 9 | N98: =SUM(N11:N97) -> 9 | O98: =SUM(O11:O97) -> 0 | P98: =SUM(P11:P97) -> 0 | Q98: =SUM(Q11:Q97) -> 9 | R98: =ROUND(N98*100/$M98,2) -> 100 | S98: =ROUND(O98*100/$M98,2) -> 0 | T98: =U98-R98-S98 -> 0 | U98: =ROUND(Q98*100/$M98,2) -> 100
A99: NOTE: "A" ENTRIES= AS PER SUPERVISOR, "B" ENTRIES= AS PER PATWARI. | L99: NOTE: "A" ENTRIES= AS PER SUPERVISOR, "B" ENTRIES= AS PER PATWARI.
A100: Developed by: Deepak Kumar Agrawal, Senior Statistical Officer, NSSO (FOD), Faridabad, Haryana | L100: Developed by: Deepak Kumar Agrawal, Senior Statistical Officer, NSSO (FOD), Faridabad, Haryana

Sheet Table-1(p)
A2: TABLE :A-1 : DISTRICTWISE DISTRIBUTION OF SELECTED VILLAGES FOR CHECK ON ENUMERATION OF AREA AND RESPONSE ACHIEVED.
A3: STATE: | B3: ='Table-1'!B3 -> PUDUCHERRY(34) | D3: YEAR: | E3: ='Table-1'!E3 -> 2024-25 | F3: SEASON: | G3: ='Table-1'!G3 -> RABI I(4) | H3: SAMPLE: | I3: ='Table-1'!I3 -> CENTRAL(1)
A4: DISTRICT | B4: NO.OF VILLAGES FOR WHICH SCHEDULE AS 1.0 RECEIVED | C4: NO. OF VILLAGES FOR WHICH SCHEDULE AS 1.0 IS ANALYSED | G4: PERCENTAGE RESPONSE TO COL.(2)
C5: WITH 'a' AND 'b' ENTRIES TOGETHER | D5: WITH 'a' AND 'b' ENTRIES SEPARATELY | E5: WITH 'a' ENTRIES ONLY | F5: TOTAL | G5: WITH 'a' AND 'b' ENTRIES TOGETHER | H5: WITH 'a' AND 'b' ENTRIES SEPARATELY | I5: WITH 'a' ENTRIES ONLY | J5: TOTAL
A10: 1 | B10: 2 | C10: 3 | D10: 4 | E10: 5 | F10: 7 | G10: 8 | H10: 9 | I10: 10 | J10: 11
A11: ='Table-1'!A11 | B11: ='Table-1'!B11 | C11: ='Table-1'!C11 | D11: ='Table-1'!D11 | E11: ='Table-1'!E11 | F11: ='Table-1'!F11 | G11: ='Table-1'!G11 | H11: ='Table-1'!H11 | ... J11: ='Table-1'!J11
A12: ='Table-1'!A12 -> 2 | B12: ='Table-1'!B12 -> 6 | C12: ='Table-1'!C12 -> 6 | D12: ='Table-1'!D12 -> 0 | E12: ='Table-1'!E12 -> 0 | F12: ='Table-1'!F12 -> 6 | G12: ='Table-1'!G12 -> 100 | H12: ='Table-1'!H12 -> 0 | ... J12: ='Table-1'!J12 -> 100
A13: ='Table-1'!A13 | B13: ='Table-1'!B13 | C13: ='Table-1'!C13 | D13: ='Table-1'!D13 | E13: ='Table-1'!E13 | F13: ='Table-1'!F13 | G13: ='Table-1'!G13 | H13: ='Table-1'!H13 | ... J13: ='Table-1'!J13
A14: ='Table-1'!A14 -> 4 | B14: ='Table-1'!B14 -> 3 | C14: ='Table-1'!C14 -> 3 | D14: ='Table-1'!D14 -> 0 | E14: ='Table-1'!E14 -> 0 | F14: ='Table-1'!F14 -> 3 | G14: ='Table-1'!G14 -> 100 | H14: ='Table-1'!H14 -> 0 | ... J14: ='Table-1'!J14 -> 100
A15: ='Table-1'!A15 | B15: ='Table-1'!B15 | C15: ='Table-1'!C15 | D15: ='Table-1'!D15 | E15: ='Table-1'!E15 | F15: ='Table-1'!F15 | G15: ='Table-1'!G15 | H15: ='Table-1'!H15 | ... J15: ='Table-1'!J15
A16: ='Table-1'!A16 | B16: ='Table-1'!B16 | C16: ='Table-1'!C16 | D16: ='Table-1'!D16 | E16: ='Table-1'!E16 | F16: ='Table-1'!F16 | G16: ='Table-1'!G16 | H16: ='Table-1'!H16 | ... J16: ='Table-1'!J16
A17: ='Table-1'!A17 | B17: ='Table-1'!B17 | C17: ='Table-1'!C17 | D17: ='Table-1'!D17 | E17: ='Table-1'!E17 | F17: ='Table-1'!F17 | G17: ='Table-1'!G17 | H17: ='Table-1'!H17 | ... J17: ='Table-1'!J17
A18: ='Table-1'!A18 | B18: ='Table-1'!B18 | C18: ='Table-1'!C18 | D18: ='Table-1'!D18 | E18: ='Table-1'!E18 | F18: ='Table-1'!F18 | G18: ='Table-1'!G18 | H18: ='Table-1'!H18 | ... J18: ='Table-1'!J18
A19: ='Table-1'!A19 | B19: ='Table-1'!B19 | C19: ='Table-1'!C19 | D19: ='Table-1'!D19 | E19: ='Table-1'!E19 | F19: ='Table-1'!F19 | G19: ='Table-1'!G19 | H19: ='Table-1'!H19 | ... J19: ='Table-1'!J19
A20: ='Table-1'!A20 | B20: ='Table-1'!B20 | C20: ='Table-1'!C20 | D20: ='Table-1'!D20 | E20: ='Table-1'!E20 | F20: ='Table-1'!F20 | G20: ='Table-1'!G20 | H20: ='Table-1'!H20 | ... J20: ='Table-1'!J20
A21: ='Table-1'!A21 | B21: ='Table-1'!B21 | C21: ='Table-1'!C21 | D21: ='Table-1'!D21 | E21: ='Table-1'!E21 | F21: ='Table-1'!F21 | G21: ='Table-1'!G21 | H21: ='Table-1'!H21 | ... J21: ='Table-1'!J21
A22: ='Table-1'!A22 | B22: ='Table-1'!B22 | C22: ='Table-1'!C22 | D22: ='Table-1'!D22 | E22: ='Table-1'!E22 | F22: ='Table-1'!F22 | G22: ='Table-1'!G22 | H22: ='Table-1'!H22 | ... J22: ='Table-1'!J22
... A98: ='Table-1'!A98 -> STATE: | B98: ='Table-1'!B98 -> 9 | C98: ='Table-1'!C98 -> 9 | D98: ='Table-1'!D98 -> 0 | E98: ='Table-1'!E98 -> 0 | F98: ='Table-1'!F98 -> 9 | G98: ='Table-1'!G98 -> 100 | H98: ='Table-1'!H98 -> 0 | ... J98: ='Table-1'!J98 -> 100
A99: NOTE: "A" ENTRIES= AS PER SUPERVISOR, "B" ENTRIES= AS PER PATWARI.
A100: Developed by: Deepak Kumar Agrawal, Senior Statistical Officer, NSSO (FOD), Faridabad, Haryana
A102: TABLE :A-1 : DISTRICTWISE DISTRIBUTION OF SELECTED VILLAGES FOR CHECK ON ENUMERATION OF AREA AND RESPONSE ACHIEVED.
A103: STATE: | B103: ='Table-1'!M3 -> PUDUCHERRY(34) | D103: YEAR: | E103: ='Table-1'!P3 -> 2024-25 | F103: SEASON: | G103: ='Table-1'!R3 -> RABI I(4) | H103: SAMPLE: | I103: ='Table-1'!T3 -> STATE(2)
A104: DISTRICT | B104: NO.OF VILLAGES FOR WHICH SCHEDULE AS 1.0 RECEIVED | C104: NO. OF VILLAGES FOR WHICH SCHEDULE AS 1.0 IS ANALYSED | G104: PERCENTAGE RESPONSE TO COL.(2)
C105: WITH 'a' AND 'b' ENTRIES TOGETHER | D105: WITH 'a' AND 'b' ENTRIES SEPARATELY | E105: WITH 'a' ENTRIES ONLY | F105: TOTAL | G105: WITH 'a' AND 'b' ENTRIES TOGETHER | H105: WITH 'a' AND 'b' ENTRIES SEPARATELY | I105: WITH 'a' ENTRIES ONLY | J105: TOTAL
A110: 1 | B110: 2 | C110: 3 | D110: 4 | E110: 5 | F110: 7 | G110: 8 | H110: 9 | I110: 10 | J110: 11
A111: ='Table-1'!L11 | B111: ='Table-1'!M11 | C111: ='Table-1'!N11 | D111: ='Table-1'!O11 | E111: ='Table-1'!P11 | F111: ='Table-1'!Q11 | G111: ='Table-1'!R11 | H111: ='Table-1'!S11 | ... J111: ='Table-1'!U11
A112: ='Table-1'!L12 -> 2 | B112: ='Table-1'!M12 -> 6 | C112: ='Table-1'!N12 -> 6 | D112: ='Table-1'!O12 -> 0 | E112: ='Table-1'!P12 -> 0 | F112: ='Table-1'!Q12 -> 6 | G112: ='Table-1'!R12 -> 100 | H112: ='Table-1'!S12 -> 0 | ... J112: ='Table-1'!U12 -> 100
A113: ='Table-1'!L13 | B113: ='Table-1'!M13 | C113: ='Table-1'!N13 | D113: ='Table-1'!O13 | E113: ='Table-1'!P13 | F113: ='Table-1'!Q13 | G113: ='Table-1'!R13 | H113: ='Table-1'!S13 | ... J113: ='Table-1'!U13
A114: ='Table-1'!L14 -> 4 | B114: ='Table-1'!M14 -> 3 | C114: ='Table-1'!N14 -> 3 | D114: ='Table-1'!O14 -> 0 | E114: ='Table-1'!P14 -> 0 | F114: ='Table-1'!Q14 -> 3 | G114: ='Table-1'!R14 -> 100 | H114: ='Table-1'!S14 -> 0 | ... J114: ='Table-1'!U14 -> 100
A115: ='Table-1'!L15 | B115: ='Table-1'!M15 | C115: ='Table-1'!N15 | D115: ='Table-1'!O15 | E115: ='Table-1'!P15 | F115: ='Table-1'!Q15 | G115: ='Table-1'!R15 | H115: ='Table-1'!S15 | ... J115: ='Table-1'!U15
A116: ='Table-1'!L16 | B116: ='Table-1'!M16 | C116: ='Table-1'!N16 | D116: ='Table-1'!O16 | E116: ='Table-1'!P16 | F116: ='Table-1'!Q16 | G116: ='Table-1'!R16 | H116: ='Table-1'!S16 | ... J116: ='Table-1'!U16
A117: ='Table-1'!L17 | B117: ='Table-1'!M17 | C117: ='Table-1'!N17 | D117: ='Table-1'!O17 | E117: ='Table-1'!P17 | F117: ='Table-1'!Q17 | G117: ='Table-1'!R17 | H117: ='Table-1'!S17 | ... J117: ='Table-1'!U17
A118: ='Table-1'!L18 | B118: ='Table-1'!M18 | C118: ='Table-1'!N18 | D118: ='Table-1'!O18 | E118: ='Table-1'!P18 | F118: ='Table-1'!Q18 | G118: ='Table-1'!R18 | H118: ='Table-1'!S18 | ... J118: ='Table-1'!U18
A119: ='Table-1'!L19 | B119: ='Table-1'!M19 | C119: ='Table-1'!N19 | D119: ='Table-1'!O19 | E119: ='Table-1'!P19 | F119: ='Table-1'!Q19 | G119: ='Table-1'!R19 | H119: ='Table-1'!S19 | ... J119: ='Table-1'!U19
A120: ='Table-1'!L20 | B120: ='Table-1'!M20 | C120: ='Table-1'!N20 | D120: ='Table-1'!O20 | E120: ='Table-1'!P20 | F120: ='Table-1'!Q20 | G120: ='Table-1'!R20 | H120: ='Table-1'!S20 | ... J120: ='Table-1'!U20
A121: ='Table-1'!L21 | B121: ='Table-1'!M21 | C121: ='Table-1'!N21 | D121: ='Table-1'!O21 | E121: ='Table-1'!P21 | F121: ='Table-1'!Q21 | G121: ='Table-1'!R21 | H121: ='Table-1'!S21 | ... J121: ='Table-1'!U21
A122: ='Table-1'!L22 | B122: ='Table-1'!M22 | C122: ='Table-1'!N22 | D122: ='Table-1'!O22 | E122: ='Table-1'!P22 | F122: ='Table-1'!Q22 | G122: ='Table-1'!R22 | H122: ='Table-1'!S22 | ... J122: ='Table-1'!U22
... A198: ='Table-1'!L98 -> STATE: | B198: ='Table-1'!M98 -> 9 | C198: ='Table-1'!N98 -> 9 | D198: ='Table-1'!O98 -> 0 | E198: ='Table-1'!P98 -> 0 | F198: ='Table-1'!Q98 -> 9 | G198: ='Table-1'!R98 -> 100 | H198: ='Table-1'!S98 -> 0 | ... J198: ='Table-1'!U98 -> 100
A199: NOTE: "A" ENTRIES= AS PER SUPERVISOR, "B" ENTRIES= AS PER PATWARI.
A200: Developed by: Deepak Kumar Agrawal, Senior Statistical Officer, NSSO (FOD), Faridabad, Haryana

Sheet Table-2
A2: Table A-2 : DISTRICTWISE DISTRIBUTION OF SELECTED VILLAGES ACCORDING TO TIME LAG BETWEEN THE YEAR OF SURVEY AND UPDATING OF MAPS. | O2: Table A-2 : DISTRICTWISE DISTRIBUTION OF SELECTED VILLAGES ACCORDING TO TIME LAG BETWEEN THE YEAR OF SURVEY AND UPDATING OF MAPS.
A3: STATE: | B3: =Crops!$A$2&"("&Crops!$B$2&")" -> PUDUCHERRY(34) | E3: YEAR: | F3: =Crops!$B$3 -> 2024-25 | H3: SEASON: | I3: =Crops!$A$5&"("&Crops!$B$5&")" -> RABI I(4) | K3: SAMPLE: | L3: ="CENTRAL"&"("&1&")" -> CENTRAL(1) | O3: STATE: | P3: =Crops!$A$2&"("&Crops!$B$2&")" -> PUDUCHERRY(34) | S3: YEAR: | T3: =Crops!$B$3 -> 2024-25 | V3: SEASON: | W3: =Crops!$A$5&"("&Crops!$B$5&")" -> RABI I(4) | Y3: SAMPLE: | Z3: ="STATE"&"("&2&")" -> STATE(2)
A4: DISTRICT | B4: NO. OF VILLAGES ANALYSED | C4: NO. OF VILLAGES ACCORDING TO TIME LAG (YEARS) BETWEEN SURVEY AND UPDATING OF MAP. | H4: NO OF VILLAGES | J4: NO OF VILLAGES FOR WHICH | O4: DISTRICT | P4: NO. OF VILLAGES ANALYSED | Q4: NO. OF VILLAGES ACCORDING TO TIME LAG (YEARS) BETWEEN SURVEY AND UPDATING OF MAP. | V4: NO OF VILLAGES | X4: NO OF VILLAGES FOR WHICH
H5: UNSURVEYED AND INFORMATION NOT APPLICABLE | I5: FOR INFORMATION NOT AVAILABLE | J5: MAPS ARE AVAILABLE WITH PATWARI | M5: MAPS NOT AVAILABLE | V5: UNSURVEYED AND INFORMATION NOT APPLICABLE | W5: FOR INFORMATION NOT AVAILABLE | X5: MAPS ARE AVAILABLE WITH PATWARI | AA5: MAPS NOT AVAILABLE
C6: 1 | D6: 2 TO 5 | E6: 6 TO 10 | F6: 11 TO 20 | G6: ABOVE 20 | J6: USEABLE | K6: UN-USEABLE | L6: TOTAL | Q6: 1 | R6: 2 TO 5 | S6: 6 TO 10 | T6: 11 TO 20 | U6: ABOVE 20 | X6: USEABLE | Y6: UN-USEABLE | Z6: TOTAL
A7: 1 | B7: 2 | C7: 3 | D7: 4 | E7: 5 | F7: 6 | G7: 7 | H7: 8 | I7: 9 | J7: 10 | K7: 11 | L7: 12 | M7: 13 | O7: 1 | P7: 2 | Q7: 3 | R7: 4 | S7: 5 | T7: 6 | U7: 7 | V7: 8 | W7: 9 | X7: 10 | Y7: 11 | Z7: 12 | AA7: 13
A8: =IF(COUNTIFS(Basicdata!$B$2:$B$2500,1,Basicdata!$D$2:$D$2500,Crops!$B$5,Basicdata!$H$2:$H$2500,Crops!$M2,Basicdata!$AI$2:$AI$2500,0)>0,Crops!$M2,"") | B8: =IF(A8="","",COUNTIFS(Basicdata!$B$2:$B$2500,1,Basicdata!$D$2:$D$2500,Crops!$B$5,Basicdata!$H$2:$H$2500,Crops!$M2,Basicdata!$AI$2:$AI$2500,0)) | C8: =IF(A8="","",COUNTIFS(Basicdata!$B$2:$B$2500,1,Basicdata!$D$2:$D$2500,Crops!$B$5,Basicdata!$H$2:$H$2500,Crops!$M2,Basicdata!$O$2:$O$2500,1,Basicdata!$AI$2:$AI$2500,0)) | D8: =IF(A8="","",COUNTIFS(Basicdata!$B$2:$B$2500,1,Basicdata!$D$2:$D$2500,Crops!$B$5,Basicdata!$H$2:$H$2500,Crops!$M2,Basicdata!$O$2:$O$2500,2,Basicdata!$AI$2:$AI$2500,0)) | E8: =IF(A8="","",COUNTIFS(Basicdata!$B$2:$B$2500,1,Basicdata!$D$2:$D$2500,Crops!$B$5,Basicdata!$H$2:$H$2500,Crops!$M2,Basicdata!$O$2:$O$2500,3,Basicdata!$AI$2:$AI$2500,0)) | F8: =IF(A8="","",COUNTIFS(Basicdata!$B$2:$B$2500,1,Basicdata!$D$2:$D$2500,Crops!$B$5,Basicdata!$H$2:$H$2500,Crops!$M2,Basicdata!$O$2:$O$2500,4,Basicdata!$AI$2:$AI$2500,0)) | G8: =IF(A8="","",COUNTIFS(Basicdata!$B$2:$B$2500,1,Basicdata!$D$2:$D$2500,Crops!$B$5,Basicdata!$H$2:$H$2500,Crops!$M2,Basicdata!$O$2:$O$2500,5,Basicdata!$AI$2:$AI$2500,0)) | H8: =IF(A8="","",COUNTIFS(Basicdata!$B$2:$B$2500,1,Basicdata!$D$2:$D$2500,Crops!$B$5,Basicdata!$H$2:$H$2500,Crops!$M2,Basicdata!$N$2:$N$2500,3,Basicdata!$AI$2:$AI$2500,0)) | I8: =IF(A8="","",B8-C8-D8-E8-F8-G8-H8) | J8: =IF(A8="","",COUNTIFS(Basicdata!$B$2:$B$2500,1,Basicdata!$D$2:$D$2500,Crops!$B$5,Basicdata!$H$2:$H$2500,Crops!$M2,Basicdata!$P$2:$P$2500,1,Basicdata!$Q$2:$Q$2500,1,Basicdata!$AI$2:$AI$2500,0)) | K8: =IF(A8="","",COUNTIFS(Basicdata!$B$2:$B$2500,1,Basicdata!$D$2:$D$2500,Crops!$B$5,Basicdata!$H$2:$H$2500,Crops!$M2,Basicdata!$P$2:$P$2500,1,Basicdata!$Q$2:$Q$2500,0,Basicdata!$AI$2:$AI$2500,0)) | L8: =IF(A8="","",J8+K8) | M8: =IF(A8="","",B8-L8) | O8: =IF(COUNTIFS(Basicdata!$B$2:$B$2500,2,Basicdata!$D$2:$D$2500,Crops!$B$5,Basicdata!$H$2:$H$2500,Crops!$M2,Basicdata!$AI$2:$AI$2500,0)>0,Crops!$M2,"") | P8: =IF(O8="","",COUNTIFS(Basicdata!$B$2:$B$2500,2,Basicdata!$D$2:$D$2500,Crops!$B$5,Basicdata!$H$2:$H$2500,Crops!$M2,Basicdata!$AI$2:$AI$2500,0)) | Q8: =IF(O8="","",COUNTIFS(Basicdata!$B$2:$B$2500,2,Basicdata!$D$2:$D$2500,Crops!$B$5,Basicdata!$H$2:$H$2500,Crops!$M2,Basicdata!$O$2:$O$2500,1,Basicdata!$AI$2:$AI$2500,0)) | R8: =IF(O8="","",COUNTIFS(Basicdata!$B$2:$B$2500,2,Basicdata!$D$2:$D$2500,Crops!$B$5,Basicdata!$H$2:$H$2500,Crops!$M2,Basicdata!$O$2:$O$2500,2,Basicdata!$AI$2:$AI$2500,0)) | S8: =IF(O8="","",COUNTIFS(Basicdata!$B$2:$B$2500,2,Basicdata!$D$2:$D$2500,Crops!$B$5,Basicdata!$H$2:$H$2500,Crops!$M2,Basicdata!$O$2:$O$2500,3,Basicdata!$AI$2:$AI$2500,0)) | T8: =IF(O8="","",COUNTIFS(Basicdata!$B$2:$B$2500,2,Basicdata!$D$2:$D$2500,Crops!$B$5,Basicdata!$H$2:$H$2500,Crops!$M2,Basicdata!$O$2:$O$2500,4,Basicdata!$AI$2:$AI$2500,0)) | U8: =IF(O8="","",COUNTIFS(Basicdata!$B$2:$B$2500,2,Basicdata!$D$2:$D$2500,Crops!$B$5,Basicdata!$H$2:$H$2500,Crops!$M2,Basicdata!$O$2:$O$2500,5,Basicdata!$AI$2:$AI$2500,0)) | V8: =IF(O8="","",COUNTIFS(Basicdata!$B$2:$B$2500,2,Basicdata!$D$2:$D$2500,Crops!$B$5,Basicdata!$H$2:$H$2500,Crops!$M2,Basicdata!$N$2:$N$2500,3,Basicdata!$AI$2:$AI$2500,0)) | W8: =IF(O8="","",P8-Q8-R8-S8-T8-U8-V8) | X8: =IF(O8="","",COUNTIFS(Basicdata!$B$2:$B$2500,2,Basicdata!$D$2:$D$2500,Crops!$B$5,Basicdata!$H$2:$H$2500,Crops!$M2,Basicdata!$P$2:$P$2500,1,Basicdata!$Q$2:$Q$2500,1,Basicdata!$AI$2:$AI$2500,0)) | Y8: =IF(O8="","",COUNTIFS(Basicdata!$B$2:$B$2500,2,Basicdata!$D$2:$D$2500,Crops!$B$5,Basicdata!$H$2:$H$2500,Crops!$M2,Basicdata!$P$2:$P$2500,1,Basicdata!$Q$2:$Q$2500,0,Basicdata!$AI$2:$AI$2500,0)) | Z8: =IF(O8="","",X8+Y8) | AA8: =IF(O8="","",P8-Z8)
A9: =IF(COUNTIFS(Basicdata!$B$2:$B$2500,1,Basicdata!$D$2:$D$2500,Crops!$B$5,Basicdata!$H$2:$H$2500,Crops!$M3,Basicdata!$AI$2:$AI$2500,0)>0,Crops!$M3,"") -> 2 | B9: =IF(A9="","",COUNTIFS(Basicdata!$B$2:$B$2500,1,Basicdata!$D$2:$D$2500,Crops!$B$5,Basicdata!$H$2:$H$2500,Crops!$M3,Basicdata!$AI$2:$AI$2500,0)) -> 6 | C9: =IF(A9="","",COUNTIFS(Basicdata!$B$2:$B$2500,1,Basicdata!$D$2:$D$2500,Crops!$B$5,Basicdata!$H$2:$H$2500,Crops!$M3,Basicdata!$O$2:$O$2500,1,Basicdata!$AI$2:$AI$2500,0)) -> 0 | D9: =IF(A9="","",COUNTIFS(Basicdata!$B$2:$B$2500,1,Basicdata!$D$2:$D$2500,Crops!$B$5,Basicdata!$H$2:$H$2500,Crops!$M3,Basicdata!$O$2:$O$2500,2,Basicdata!$AI$2:$AI$2500,0)) -> 0 | E9: =IF(A9="","",COUNTIFS(Basicdata!$B$2:$B$2500,1,Basicdata!$D$2:$D$2500,Crops!$B$5,Basicdata!$H$2:$H$2500,Crops!$M3,Basicdata!$O$2:$O$2500,3,Basicdata!$AI$2:$AI$2500,0)) -> 0 | F9: =IF(A9="","",COUNTIFS(Basicdata!$B$2:$B$2500,1,Basicdata!$D$2:$D$2500,Crops!$B$5,Basicdata!$H$2:$H$2500,Crops!$M3,Basicdata!$O$2:$O$2500,4,Basicdata!$AI$2:$AI$2500,0)) -> 0 | G9: =IF(A9="","",COUNTIFS(Basicdata!$B$2:$B$2500,1,Basicdata!$D$2:$D$2500,Crops!$B$5,Basicdata!$H$2:$H$2500,Crops!$M3,Basicdata!$O$2:$O$2500,5,Basicdata!$AI$2:$AI$2500,0)) -> 6 | H9: =IF(A9="","",COUNTIFS(Basicdata!$B$2:$B$2500,1,Basicdata!$D$2:$D$2500,Crops!$B$5,Basicdata!$H$2:$H$2500,Crops!$M3,Basicdata!$N$2:$N$2500,3,Basicdata!$AI$2:$AI$2500,0)) -> 0 | I9: =IF(A9="","",B9-C9-D9-E9-F9-G9-H9) -> 0 | J9: =IF(A9="","",COUNTIFS(Basicdata!$B$2:$B$2500,1,Basicdata!$D$2:$D$2500,Crops!$B$5,Basicdata!$H$2:$H$2500,Crops!$M3,Basicdata!$P$2:$P$2500,1,Basicdata!$Q$2:$Q$2500,1,Basicdata!$AI$2:$AI$2500,0)) -> 6 | K9: =IF(A9="","",COUNTIFS(Basicdata!$B$2:$B$2500,1,Basicdata!$D$2:$D$2500,Crops!$B$5,Basicdata!$H$2:$H$2500,Crops!$M3,Basicdata!$P$2:$P$2500,1,Basicdata!$Q$2:$Q$2500,0,Basicdata!$AI$2:$AI$2500,0)) -> 0 | L9: =IF(A9="","",J9+K9) -> 6 | M9: =IF(A9="","",B9-L9) -> 0 | O9: =IF(COUNTIFS(Basicdata!$B$2:$B$2500,2,Basicdata!$D$2:$D$2500,Crops!$B$5,Basicdata!$H$2:$H$2500,Crops!$M3,Basicdata!$AI$2:$AI$2500,0)>0,Crops!$M3,"") -> 2 | P9: =IF(O9="","",COUNTIFS(Basicdata!$B$2:$B$2500,2,Basicdata!$D$2:$D$2500,Crops!$B$5,Basicdata!$H$2:$H$2500,Crops!$M3,Basicdata!$AI$2:$AI$2500,0)) -> 6 | Q9: =IF(O9="","",COUNTIFS(Basicdata!$B$2:$B$2500,2,Basicdata!$D$2:$D$2500,Crops!$B$5,Basicdata!$H$2:$H$2500,Crops!$M3,Basicdata!$O$2:$O$2500,1,Basicdata!$AI$2:$AI$2500,0)) -> 0 | R9: =IF(O9="","",COUNTIFS(Basicdata!$B$2:$B$2500,2,Basicdata!$D$2:$D$2500,Crops!$B$5,Basicdata!$H$2:$H$2500,Crops!$M3,Basicdata!$O$2:$O$2500,2,Basicdata!$AI$2:$AI$2500,0)) -> 0 | S9: =IF(O9="","",COUNTIFS(Basicdata!$B$2:$B$2500,2,Basicdata!$D$2:$D$2500,Crops!$B$5,Basicdata!$H$2:$H$2500,Crops!$M3,Basicdata!$O$2:$O$2500,3,Basicdata!$AI$2:$AI$2500,0)) -> 0 | T9: =IF(O9="","",COUNTIFS(Basicdata!$B$2:$B$2500,2,Basicdata!$D$2:$D$2500,Crops!$B$5,Basicdata!$H$2:$H$2500,Crops!$M3,Basicdata!$O$2:$O$2500,4,Basicdata!$AI$2:$AI$2500,0)) -> 0 | U9: =IF(O9="","",COUNTIFS(Basicdata!$B$2:$B$2500,2,Basicdata!$D$2:$D$2500,Crops!$B$5,Basicdata!$H$2:$H$2500,Crops!$M3,Basicdata!$O$2:$O$2500,5,Basicdata!$AI$2:$AI$2500,0)) -> 6 | V9: =IF(O9="","",COUNTIFS(Basicdata!$B$2:$B$2500,2,Basicdata!$D$2:$D$2500,Crops!$B$5,Basicdata!$H$2:$H$2500,Crops!$M3,Basicdata!$N$2:$N$2500,3,Basicdata!$AI$2:$AI$2500,0)) -> 0 | W9: =IF(O9="","",P9-Q9-R9-S9-T9-U9-V9) -> 0 | X9: =IF(O9="","",COUNTIFS(Basicdata!$B$2:$B$2500,2,Basicdata!$D$2:$D$2500,Crops!$B$5,Basicdata!$H$2:$H$2500,Crops!$M3,Basicdata!$P$2:$P$2500,1,Basicdata!$Q$2:$Q$2500,1,Basicdata!$AI$2:$AI$2500,0)) -> 6 | Y9: =IF(O9="","",COUNTIFS(Basicdata!$B$2:$B$2500,2,Basicdata!$D$2:$D$2500,Crops!$B$5,Basicdata!$H$2:$H$2500,Crops!$M3,Basicdata!$P$2:$P$2500,1,Basicdata!$Q$2:$Q$2500,0,Basicdata!$AI$2:$AI$2500,0)) -> 0 | Z9: =IF(O9="","",X9+Y9) -> 6 | AA9: =IF(O9="","",P9-Z9) -> 0
A10: =IF(COUNTIFS(Basicdata!$B$2:$B$2500,1,Basicdata!$D$2:$D$2500,Crops!$B$5,Basicdata!$H$2:$H$2500,Crops!$M4,Basicdata!$AI$2:$AI$2500,0)>0,Crops!$M4,"") | B10: =IF(A10="","",COUNTIFS(Basicdata!$B$2:$B$2500,1,Basicdata!$D$2:$D$2500,Crops!$B$5,Basicdata!$H$2:$H$2500,Crops!$M4,Basicdata!$AI$2:$AI$2500,0)) | C10: =IF(A10="","",COUNTIFS(Basicdata!$B$2:$B$2500,1,Basicdata!$D$2:$D$2500,Crops!$B$5,Basicdata!$H$2:$H$2500,Crops!$M4,Basicdata!$O$2:$O$2500,1,Basicdata!$AI$2:$AI$2500,0)) | D10: =IF(A10="","",COUNTIFS(Basicdata!$B$2:$B$2500,1,Basicdata!$D$2:$D$2500,Crops!$B$5,Basicdata!$H$2:$H$2500,Crops!$M4,Basicdata!$O$2:$O$2500,2,Basicdata!$AI$2:$AI$2500,0)) | E10: =IF(A10="","",COUNTIFS(Basicdata!$B$2:$B$2500,1,Basicdata!$D$2:$D$2500,Crops!$B$5,Basicdata!$H$2:$H$2500,Crops!$M4,Basicdata!$O$2:$O$2500,3,Basicdata!$AI$2:$AI$2500,0)) | F10: =IF(A10="","",COUNTIFS(Basicdata!$B$2:$B$2500,1,Basicdata!$D$2:$D$2500,Crops!$B$5,Basicdata!$H$2:$H$2500,Crops!$M4,Basicdata!$O$2:$O$2500,4,Basicdata!$AI$2:$AI$2500,0)) | G10: =IF(A10="","",COUNTIFS(Basicdata!$B$2:$B$2500,1,Basicdata!$D$2:$D$2500,Crops!$B$5,Basicdata!$H$2:$H$2500,Crops!$M4,Basicdata!$O$2:$O$2500,5,Basicdata!$AI$2:$AI$2500,0)) | H10: =IF(A10="","",COUNTIFS(Basicdata!$B$2:$B$2500,1,Basicdata!$D$2:$D$2500,Crops!$B$5,Basicdata!$H$2:$H$2500,Crops!$M4,Basicdata!$N$2:$N$2500,3,Basicdata!$AI$2:$AI$2500,0)) | I10: =IF(A10="","",B10-C10-D10-E10-F10-G10-H10) | J10: =IF(A10="","",COUNTIFS(Basicdata!$B$2:$B$2500,1,Basicdata!$D$2:$D$2500,Crops!$B$5,Basicdata!$H$2:$H$2500,Crops!$M4,Basicdata!$P$2:$P$2500,1,Basicdata!$Q$2:$Q$2500,1,Basicdata!$AI$2:$AI$2500,0)) | K10: =IF(A10="","",COUNTIFS(Basicdata!$B$2:$B$2500,1,Basicdata!$D$2:$D$2500,Crops!$B$5,Basicdata!$H$2:$H$2500,Crops!$M4,Basicdata!$P$2:$P$2500,1,Basicdata!$Q$2:$Q$2500,0,Basicdata!$AI$2:$AI$2500,0)) | L10: =IF(A10="","",J10+K10) | M10: =IF(A10="","",B10-L10) | O10: =IF(COUNTIFS(Basicdata!$B$2:$B$2500,2,Basicdata!$D$2:$D$2500,Crops!$B$5,Basicdata!$H$2:$H$2500,Crops!$M4,Basicdata!$AI$2:$AI$2500,0)>0,Crops!$M4,"") | P10: =IF(O10="","",COUNTIFS(Basicdata!$B$2:$B$2500,2,Basicdata!$D$2:$D$2500,Crops!$B$5,Basicdata!$H$2:$H$2500,Crops!$M4,Basicdata!$AI$2:$AI$2500,0)) | Q10: =IF(O10="","",COUNTIFS(Basicdata!$B$2:$B$2500,2,Basicdata!$D$2:$D$2500,Crops!$B$5,Basicdata!$H$2:$H$2500,Crops!$M4,Basicdata!$O$2:$O$2500,1,Basicdata!$AI$2:$AI$2500,0)) | R10: =IF(O10="","",COUNTIFS(Basicdata!$B$2:$B$2500,2,Basicdata!$D$2:$D$2500,Crops!$B$5,Basicdata!$H$2:$H$2500,Crops!$M4,Basicdata!$O$2:$O$2500,2,Basicdata!$AI$2:$AI$2500,0)) | S10: =IF(O10="","",COUNTIFS(Basicdata!$B$2:$B$2500,2,Basicdata!$D$2:$D$2500,Crops!$B$5,Basicdata!$H$2:$H$2500,Crops!$M4,Basicdata!$O$2:$O$2500,3,Basicdata!$AI$2:$AI$2500,0)) | T10: =IF(O10="","",COUNTIFS(Basicdata!$B$2:$B$2500,2,Basicdata!$D$2:$D$2500,Crops!$B$5,Basicdata!$H$2:$H$2500,Crops!$M4,Basicdata!$O$2:$O$2500,4,Basicdata!$AI$2:$AI$2500,0)) | U10: =IF(O10="","",COUNTIFS(Basicdata!$B$2:$B$2500,2,Basicdata!$D$2:$D$2500,Crops!$B$5,Basicdata!$H$2:$H$2500,Crops!$M4,Basicdata!$O$2:$O$2500,5,Basicdata!$AI$2:$AI$2500,0)) | V10: =IF(O10="","",COUNTIFS(Basicdata!$B$2:$B$2500,2,Basicdata!$D$2:$D$2500,Crops!$B$5,Basicdata!$H$2:$H$2500,Crops!$M4,Basicdata!$N$2:$N$2500,3,Basicdata!$AI$2:$AI$2500,0)) | W10: =IF(O10="","",P10-Q10-R10-S10-T10-U10-V10) | X10: =IF(O10="","",COUNTIFS(Basicdata!$B$2:$B$2500,2,Basicdata!$D$2:$D$2500,Crops!$B$5,Basicdata!$H$2:$H$2500,Crops!$M4,Basicdata!$P$2:$P$2500,1,Basicdata!$Q$2:$Q$2500,1,Basicdata!$AI$2:$AI$2500,0)) | Y10: =IF(O10="","",COUNTIFS(Basicdata!$B$2:$B$2500,2,Basicdata!$D$2:$D$2500,Crops!$B$5,Basicdata!$H$2:$H$2500,Crops!$M4,Basicdata!$P$2:$P$2500,1,Basicdata!$Q$2:$Q$2500,0,Basicdata!$AI$2:$AI$2500,0)) | Z10: =IF(O10="","",X10+Y10) | AA10: =IF(O10="","",P10-Z10)
A11: =IF(COUNTIFS(Basicdata!$B$2:$B$2500,1,Basicdata!$D$2:$D$2500,Crops!$B$5,Basicdata!$H$2:$H$2500,Crops!$M5,Basicdata!$AI$2:$AI$2500,0)>0,Crops!$M5,"") -> 4 | B11: =IF(A11="","",COUNTIFS(Basicdata!$B$2:$B$2500,1,Basicdata!$D$2:$D$2500,Crops!$B$5,Basicdata!$H$2:$H$2500,Crops!$M5,Basicdata!$AI$2:$AI$2500,0)) -> 3 | C11: =IF(A11="","",COUNTIFS(Basicdata!$B$2:$B$2500,1,Basicdata!$D$2:$D$2500,Crops!$B$5,Basicdata!$H$2:$H$2500,Crops!$M5,Basicdata!$O$2:$O$2500,1,Basicdata!$AI$2:$AI$2500,0)) -> 0 | D11: =IF(A11="","",COUNTIFS(Basicdata!$B$2:$B$2500,1,Basicdata!$D$2:$D$2500,Crops!$B$5,Basicdata!$H$2:$H$2500,Crops!$M5,Basicdata!$O$2:$O$2500,2,Basicdata!$AI$2:$AI$2500,0)) -> 0 | E11: =IF(A11="","",COUNTIFS(Basicdata!$B$2:$B$2500,1,Basicdata!$D$2:$D$2500,Crops!$B$5,Basicdata!$H$2:$H$2500,Crops!$M5,Basicdata!$O$2:$O$2500,3,Basicdata!$AI$2:$AI$2500,0)) -> 0 | F11: =IF(A11="","",COUNTIFS(Basicdata!$B$2:$B$2500,1,Basicdata!$D$2:$D$2500,Crops!$B$5,Basicdata!$H$2:$H$2500,Crops!$M5,Basicdata!$O$2:$O$2500,4,Basicdata!$AI$2:$AI$2500,0)) -> 0 | G11: =IF(A11="","",COUNTIFS(Basicdata!$B$2:$B$2500,1,Basicdata!$D$2:$D$2500,Crops!$B$5,Basicdata!$H$2:$H$2500,Crops!$M5,Basicdata!$O$2:$O$2500,5,Basicdata!$AI$2:$AI$2500,0)) -> 3 | H11: =IF(A11="","",COUNTIFS(Basicdata!$B$2:$B$2500,1,Basicdata!$D$2:$D$2500,Crops!$B$5,Basicdata!$H$2:$H$2500,Crops!$M5,Basicdata!$N$2:$N$2500,3,Basicdata!$AI$2:$AI$2500,0)) -> 0 | I11: =IF(A11="","",B11-C11-D11-E11-F11-G11-H11) -> 0 | J11: =IF(A11="","",COUNTIFS(Basicdata!$B$2:$B$2500,1,Basicdata!$D$2:$D$2500,Crops!$B$5,Basicdata!$H$2:$H$2500,Crops!$M5,Basicdata!$P$2:$P$2500,1,Basicdata!$Q$2:$Q$2500,1,Basicdata!$AI$2:$AI$2500,0)) -> 3 | K11: =IF(A11="","",COUNTIFS(Basicdata!$B$2:$B$2500,1,Basicdata!$D$2:$D$2500,Crops!$B$5,Basicdata!$H$2:$H$2500,Crops!$M5,Basicdata!$P$2:$P$2500,1,Basicdata!$Q$2:$Q$2500,0,Basicdata!$AI$2:$AI$2500,0)) -> 0 | L11: =IF(A11="","",J11+K11) -> 3 | M11: =IF(A11="","",B11-L11) -> 0 | O11: =IF(COUNTIFS(Basicdata!$B$2:$B$2500,2,Basicdata!$D$2:$D$2500,Crops!$B$5,Basicdata!$H$2:$H$2500,Crops!$M5,Basicdata!$AI$2:$AI$2500,0)>0,Crops!$M5,"") -> 4 | P11: =IF(O11="","",COUNTIFS(Basicdata!$B$2:$B$2500,2,Basicdata!$D$2:$D$2500,Crops!$B$5,Basicdata!$H$2:$H$2500,Crops!$M5,Basicdata!$AI$2:$AI$2500,0)) -> 3 | Q11: =IF(O11="","",COUNTIFS(Basicdata!$B$2:$B$2500,2,Basicdata!$D$2:$D$2500,Crops!$B$5,Basicdata!$H$2:$H$2500,Crops!$M5,Basicdata!$O$2:$O$2500,1,Basicdata!$AI$2:$AI$2500,0)) -> 0 | R11: =IF(O11="","",COUNTIFS(Basicdata!$B$2:$B$2500,2,Basicdata!$D$2:$D$2500,Crops!$B$5,Basicdata!$H$2:$H$2500,Crops!$M5,Basicdata!$O$2:$O$2500,2,Basicdata!$AI$2:$AI$2500,0)) -> 0 | S11: =IF(O11="","",COUNTIFS(Basicdata!$B$2:$B$2500,2,Basicdata!$D$2:$D$2500,Crops!$B$5,Basicdata!$H$2:$H$2500,Crops!$M5,Basicdata!$O$2:$O$2500,3,Basicdata!$AI$2:$AI$2500,0)) -> 0 | T11: =IF(O11="","",COUNTIFS(Basicdata!$B$2:$B$2500,2,Basicdata!$D$2:$D$2500,Crops!$B$5,Basicdata!$H$2:$H$2500,Crops!$M5,Basicdata!$O$2:$O$2500,4,Basicdata!$AI$2:$AI$2500,0)) -> 0 | U11: =IF(O11="","",COUNTIFS(Basicdata!$B$2:$B$2500,2,Basicdata!$D$2:$D$2500,Crops!$B$5,Basicdata!$H$2:$H$2500,Crops!$M5,Basicdata!$O$2:$O$2500,5,Basicdata!$AI$2:$AI$2500,0)) -> 3 | V11: =IF(O11="","",COUNTIFS(Basicdata!$B$2:$B$2500,2,Basicdata!$D$2:$D$2500,Crops!$B$5,Basicdata!$H$2:$H$2500,Crops!$M5,Basicdata!$N$2:$N$2500,3,Basicdata!$AI$2:$AI$2500,0)) -> 0 | W11: =IF(O11="","",P11-Q11-R11-S11-T11-U11-V11) -> 0 | X11: =IF(O11="","",COUNTIFS(Basicdata!$B$2:$B$2500,2,Basicdata!$D$2:$D$2500,Crops!$B$5,Basicdata!$H$2:$H$2500,Crops!$M5,Basicdata!$P$2:$P$2500,1,Basicdata!$Q$2:$Q$2500,1,Basicdata!$AI$2:$AI$2500,0)) -> 3 | Y11: =IF(O11="","",COUNTIFS(Basicdata!$B$2:$B$2500,2,Basicdata!$D$2:$D$2500,Crops!$B$5,Basicdata!$H$2:$H$2500,Crops!$M5,Basicdata!$P$2:$P$2500,1,Basicdata!$Q$2:$Q$2500,0,Basicdata!$AI$2:$AI$2500,0)) -> 0 | Z11: =IF(O11="","",X11+Y11) -> 3 | AA11: =IF(O11="","",P11-Z11) -> 0
