Workbook

Sheet BD CY
A1: ='[1]RC-2'!A1 -> RC | B1: ='[1]RC-2'!B1 -> ST | C1: ='[1]RC-2'!C1 -> YR | D1: ='[1]RC-2'!D1 -> SESON | E1: ='[1]RC-2'!E1 -> STAT | F1: ='[1]RC-2'!F1 -> DIST | G1: ='[1]RC-2'!G1 -> STRA | H1: ='[1]RC-2'!H1 -> VILL | ... Q1: ='[1]RC-2'!Q1 -> ARPI
A2: ='[1]RC-2'!A2 -> 2 | B2: ='[1]RC-2'!B2 -> 1 | C2: ='[1]RC-2'!C2 -> 2025 | D2: ='[1]RC-2'!D2 -> 4 | E2: ='[1]RC-2'!E2 -> 34 | F2: ='[1]RC-2'!F2 -> 2 | G2: ='[1]RC-2'!G2 -> 1 | H2: ='[1]RC-2'!H2 -> 1 | ... Q2: ='[1]RC-2'!Q2 -> 0
A3: ='[1]RC-2'!A3 -> 2 | B3: ='[1]RC-2'!B3 -> 1 | C3: ='[1]RC-2'!C3 -> 2025 | D3: ='[1]RC-2'!D3 -> 4 | E3: ='[1]RC-2'!E3 -> 34 | F3: ='[1]RC-2'!F3 -> 2 | G3: ='[1]RC-2'!G3 -> 1 | H3: ='[1]RC-2'!H3 -> 2 | ... Q3: ='[1]RC-2'!Q3 -> 0
A4: ='[1]RC-2'!A4 -> 2 | B4: ='[1]RC-2'!B4 -> 1 | C4: ='[1]RC-2'!C4 -> 2025 | D4: ='[1]RC-2'!D4 -> 4 | E4: ='[1]RC-2'!E4 -> 34 | F4: ='[1]RC-2'!F4 -> 2 | G4: ='[1]RC-2'!G4 -> 1 | H4: ='[1]RC-2'!H4 -> 3 | ... Q4: ='[1]RC-2'!Q4 -> 0
A5: ='[1]RC-2'!A5 -> 2 | B5: ='[1]RC-2'!B5 -> 1 | C5: ='[1]RC-2'!C5 -> 2025 | D5: ='[1]RC-2'!D5 -> 4 | E5: ='[1]RC-2'!E5 -> 34 | F5: ='[1]RC-2'!F5 -> 2 | G5: ='[1]RC-2'!G5 -> 2 | H5: ='[1]RC-2'!H5 -> 1 | ... Q5: ='[1]RC-2'!Q5 -> 0
A6: ='[1]RC-2'!A6 -> 2 | B6: ='[1]RC-2'!B6 -> 1 | C6: ='[1]RC-2'!C6 -> 2025 | D6: ='[1]RC-2'!D6 -> 4 | E6: ='[1]RC-2'!E6 -> 34 | F6: ='[1]RC-2'!F6 -> 2 | G6: ='[1]RC-2'!G6 -> 2 | H6: ='[1]RC-2'!H6 -> 1 | ... Q6: ='[1]RC-2'!Q6 -> 0.8858
A7: ='[1]RC-2'!A7 -> 2 | B7: ='[1]RC-2'!B7 -> 1 | C7: ='[1]RC-2'!C7 -> 2025 | D7: ='[1]RC-2'!D7 -> 4 | E7: ='[1]RC-2'!E7 -> 34 | F7: ='[1]RC-2'!F7 -> 2 | G7: ='[1]RC-2'!G7 -> 2 | H7: ='[1]RC-2'!H7 -> 2 | ... Q7: ='[1]RC-2'!Q7 -> 0
A8: ='[1]RC-2'!A8 -> 2 | B8: ='[1]RC-2'!B8 -> 1 | C8: ='[1]RC-2'!C8 -> 2025 | D8: ='[1]RC-2'!D8 -> 4 | E8: ='[1]RC-2'!E8 -> 34 | F8: ='[1]RC-2'!F8 -> 2 | G8: ='[1]RC-2'!G8 -> 2 | H8: ='[1]RC-2'!H8 -> 2 | ... Q8: ='[1]RC-2'!Q8 -> 0.855
A9: ='[1]RC-2'!A9 -> 2 | B9: ='[1]RC-2'!B9 -> 1 | C9: ='[1]RC-2'!C9 -> 2025 | D9: ='[1]RC-2'!D9 -> 4 | E9: ='[1]RC-2'!E9 -> 34 | F9: ='[1]RC-2'!F9 -> 2 | G9: ='[1]RC-2'!G9 -> 2 | H9: ='[1]RC-2'!H9 -> 3 | ... Q9: ='[1]RC-2'!Q9 -> 0
A10: ='[1]RC-2'!A10 -> 2 | B10: ='[1]RC-2'!B10 -> 1 | C10: ='[1]RC-2'!C10 -> 2025 | D10: ='[1]RC-2'!D10 -> 4 | E10: ='[1]RC-2'!E10 -> 34 | F10: ='[1]RC-2'!F10 -> 2 | G10: ='[1]RC-2'!G10 -> 2 | H10: ='[1]RC-2'!H10 -> 3 | ... Q10: ='[1]RC-2'!Q10 -> 0.84
A11: ='[1]RC-2'!A11 -> 2 | B11: ='[1]RC-2'!B11 -> 1 | C11: ='[1]RC-2'!C11 -> 2025 | D11: ='[1]RC-2'!D11 -> 4 | E11: ='[1]RC-2'!E11 -> 34 | F11: ='[1]RC-2'!F11 -> 4 | G11: ='[1]RC-2'!G11 -> 1 | H11: ='[1]RC-2'!H11 -> 1 | ... Q11: ='[1]RC-2'!Q11 -> 0
A12: ='[1]RC-2'!A12 -> 2 | B12: ='[1]RC-2'!B12 -> 1 | C12: ='[1]RC-2'!C12 -> 2025 | D12: ='[1]RC-2'!D12 -> 4 | E12: ='[1]RC-2'!E12 -> 34 | F12: ='[1]RC-2'!F12 -> 4 | G12: ='[1]RC-2'!G12 -> 1 | H12: ='[1]RC-2'!H12 -> 1 | ... Q12: ='[1]RC-2'!Q12 -> 0.594
... A5000: ='[1]RC-2'!A5000 -> 0 | B5000: ='[1]RC-2'!B5000 -> 0 | C5000: ='[1]RC-2'!C5000 -> 0 | D5000: ='[1]RC-2'!D5000 -> 0 | E5000: ='[1]RC-2'!E5000 -> 0 | F5000: ='[1]RC-2'!F5000 -> 0 | G5000: ='[1]RC-2'!G5000 -> 0 | H5000: ='[1]RC-2'!H5000 -> 0 | ... Q5000: ='[1]RC-2'!Q5000 -> 0

Sheet BD PY
A1: ='[2]RC-2(PY)'!A1 -> RC | B1: ='[2]RC-2(PY)'!B1 -> ST | C1: ='[2]RC-2(PY)'!C1 -> YR | D1: ='[2]RC-2(PY)'!D1 -> SESON | E1: ='[2]RC-2(PY)'!E1 -> STAT | F1: ='[2]RC-2(PY)'!F1 -> DIST | G1: ='[2]RC-2(PY)'!G1 -> STRA | H1: ='[2]RC-2(PY)'!H1 -> VILL | ... Q1: ='[2]RC-2(PY)'!Q1 -> ARPI
A2: ='[2]RC-2(PY)'!A2 -> 2 | B2: ='[2]RC-2(PY)'!B2 -> 1 | C2: ='[2]RC-2(PY)'!C2 -> 2024 | D2: ='[2]RC-2(PY)'!D2 -> 4 | E2: ='[2]RC-2(PY)'!E2 -> 34 | F2: ='[2]RC-2(PY)'!F2 -> 2 | G2: ='[2]RC-2(PY)'!G2 -> 1 | H2: ='[2]RC-2(PY)'!H2 -> 1 | ... Q2: ='[2]RC-2(PY)'!Q2 -> 0
A3: ='[2]RC-2(PY)'!A3 -> 2 | B3: ='[2]RC-2(PY)'!B3 -> 1 | C3: ='[2]RC-2(PY)'!C3 -> 2024 | D3: ='[2]RC-2(PY)'!D3 -> 4 | E3: ='[2]RC-2(PY)'!E3 -> 34 | F3: ='[2]RC-2(PY)'!F3 -> 2 | G3: ='[2]RC-2(PY)'!G3 -> 1 | H3: ='[2]RC-2(PY)'!H3 -> 1 | ... Q3: ='[2]RC-2(PY)'!Q3 -> 3.785
A4: ='[2]RC-2(PY)'!A4 -> 2 | B4: ='[2]RC-2(PY)'!B4 -> 1 | C4: ='[2]RC-2(PY)'!C4 -> 2024 | D4: ='[2]RC-2(PY)'!D4 -> 4 | E4: ='[2]RC-2(PY)'!E4 -> 34 | F4: ='[2]RC-2(PY)'!F4 -> 2 | G4: ='[2]RC-2(PY)'!G4 -> 1 | H4: ='[2]RC-2(PY)'!H4 -> 1 | ... Q4: ='[2]RC-2(PY)'!Q4 -> 3.785
A5: ='[2]RC-2(PY)'!A5 -> 2 | B5: ='[2]RC-2(PY)'!B5 -> 1 | C5: ='[2]RC-2(PY)'!C5 -> 2024 | D5: ='[2]RC-2(PY)'!D5 -> 4 | E5: ='[2]RC-2(PY)'!E5 -> 34 | F5: ='[2]RC-2(PY)'!F5 -> 2 | G5: ='[2]RC-2(PY)'!G5 -> 1 | H5: ='[2]RC-2(PY)'!H5 -> 2 | ... Q5: ='[2]RC-2(PY)'!Q5 -> 0
A6: ='[2]RC-2(PY)'!A6 -> 2 | B6: ='[2]RC-2(PY)'!B6 -> 1 | C6: ='[2]RC-2(PY)'!C6 -> 2024 | D6: ='[2]RC-2(PY)'!D6 -> 4 | E6: ='[2]RC-2(PY)'!E6 -> 34 | F6: ='[2]RC-2(PY)'!F6 -> 2 | G6: ='[2]RC-2(PY)'!G6 -> 1 | H6: ='[2]RC-2(PY)'!H6 -> 2 | ... Q6: ='[2]RC-2(PY)'!Q6 -> 0.735
A7: ='[2]RC-2(PY)'!A7 -> 2 | B7: ='[2]RC-2(PY)'!B7 -> 1 | C7: ='[2]RC-2(PY)'!C7 -> 2024 | D7: ='[2]RC-2(PY)'!D7 -> 4 | E7: ='[2]RC-2(PY)'!E7 -> 34 | F7: ='[2]RC-2(PY)'!F7 -> 2 | G7: ='[2]RC-2(PY)'!G7 -> 1 | H7: ='[2]RC-2(PY)'!H7 -> 3 | ... Q7: ='[2]RC-2(PY)'!Q7 -> 0
A8: ='[2]RC-2(PY)'!A8 -> 2 | B8: ='[2]RC-2(PY)'!B8 -> 1 | C8: ='[2]RC-2(PY)'!C8 -> 2024 | D8: ='[2]RC-2(PY)'!D8 -> 4 | E8: ='[2]RC-2(PY)'!E8 -> 34 | F8: ='[2]RC-2(PY)'!F8 -> 2 | G8: ='[2]RC-2(PY)'!G8 -> 2 | H8: ='[2]RC-2(PY)'!H8 -> 1 | ... Q8: ='[2]RC-2(PY)'!Q8 -> 0
A9: ='[2]RC-2(PY)'!A9 -> 2 | B9: ='[2]RC-2(PY)'!B9 -> 1 | C9: ='[2]RC-2(PY)'!C9 -> 2024 | D9: ='[2]RC-2(PY)'!D9 -> 4 | E9: ='[2]RC-2(PY)'!E9 -> 34 | F9: ='[2]RC-2(PY)'!F9 -> 2 | G9: ='[2]RC-2(PY)'!G9 -> 2 | H9: ='[2]RC-2(PY)'!H9 -> 1 | ... Q9: ='[2]RC-2(PY)'!Q9 -> 1.9
A10: ='[2]RC-2(PY)'!A10 -> 2 | B10: ='[2]RC-2(PY)'!B10 -> 1 | C10: ='[2]RC-2(PY)'!C10 -> 2024 | D10: ='[2]RC-2(PY)'!D10 -> 4 | E10: ='[2]RC-2(PY)'!E10 -> 34 | F10: ='[2]RC-2(PY)'!F10 -> 2 | G10: ='[2]RC-2(PY)'!G10 -> 2 | H10: ='[2]RC-2(PY)'!H10 -> 1 | ... Q10: ='[2]RC-2(PY)'!Q10 -> 1.62
A11: ='[2]RC-2(PY)'!A11 -> 2 | B11: ='[2]RC-2(PY)'!B11 -> 1 | C11: ='[2]RC-2(PY)'!C11 -> 2024 | D11: ='[2]RC-2(PY)'!D11 -> 4 | E11: ='[2]RC-2(PY)'!E11 -> 34 | F11: ='[2]RC-2(PY)'!F11 -> 2 | G11: ='[2]RC-2(PY)'!G11 -> 2 | H11: ='[2]RC-2(PY)'!H11 -> 2 | ... Q11: ='[2]RC-2(PY)'!Q11 -> 0
A12: ='[2]RC-2(PY)'!A12 -> 2 | B12: ='[2]RC-2(PY)'!B12 -> 1 | C12: ='[2]RC-2(PY)'!C12 -> 2024 | D12: ='[2]RC-2(PY)'!D12 -> 4 | E12: ='[2]RC-2(PY)'!E12 -> 34 | F12: ='[2]RC-2(PY)'!F12 -> 2 | G12: ='[2]RC-2(PY)'!G12 -> 2 | H12: ='[2]RC-2(PY)'!H12 -> 2 | ... Q12: ='[2]RC-2(PY)'!Q12 -> 0.76
... A5000: ='[2]RC-2(PY)'!A5000 -> 0 | B5000: ='[2]RC-2(PY)'!B5000 -> 0 | C5000: ='[2]RC-2(PY)'!C5000 -> 0 | D5000: ='[2]RC-2(PY)'!D5000 -> 0 | E5000: ='[2]RC-2(PY)'!E5000 -> 0 | F5000: ='[2]RC-2(PY)'!F5000 -> 0 | G5000: ='[2]RC-2(PY)'!G5000 -> 0 | H5000: ='[2]RC-2(PY)'!H5000 -> 0 | ... Q5000: ='[2]RC-2(PY)'!Q5000 -> 0

Sheet Crops CY
A1: =[1]Crops!A1 -> STATE | B1: =[1]Crops!B1 -> Code | C1: =[1]Crops!C1 -> Sample Type | D1: =[1]Crops!D1 -> code
A2: =[1]Crops!A2 -> PUDUCHERRY | B2: =[1]Crops!B2 -> 34 | C2: =[1]Crops!C2 -> CENTRAL | D2: =[1]Crops!D2 -> 1 | F2: Don't cut/delete the cell
A3: =[1]Crops!A3 -> YEAR | B3: =[1]Crops!B3 -> 0 | C3: =[1]Crops!C3 -> STATE | D3: =[1]Crops!D3 -> 2
A4: =[1]Crops!A4 -> Season | B4: =[1]Crops!B4 -> code | C4: =[1]Crops!C4 -> Season | D4: =[1]Crops!D4 -> code
A5: =[1]Crops!A5 -> RABI I | B5: =[1]Crops!B5 -> 4 | C5: =[1]Crops!C5 -> RABI II | D5: =[1]Crops!D5 -> 5
A6: =[1]Crops!A6 -> Crop | B6: =[1]Crops!B6 -> Code | C6: =[1]Crops!C6 -> Crop | D6: =[1]Crops!D6 -> Code
A7: =[1]Crops!A7 -> PADDY | B7: =[1]Crops!B7 -> 97 | C7: =[1]Crops!C7 -> PADDY | D7: =[1]Crops!D7 -> 98
A8: =[1]Crops!A8 -> OTHERS | B8: =[1]Crops!B8 -> 99 | C8: =[1]Crops!C8 -> OTHERS | D8: =[1]Crops!D8 -> 99
A9: =[1]Crops!A9 -> 0 | B9: =[1]Crops!B9 -> 0 | C9: =[1]Crops!C9 -> 0 | D9: =[1]Crops!D9 -> 0
A10: =[1]Crops!A10 -> 0 | B10: =[1]Crops!B10 -> 0 | C10: =[1]Crops!C10 -> 0 | D10: =[1]Crops!D10 -> 0
A11: =[1]Crops!A11 -> 0 | B11: =[1]Crops!B11 -> 0 | C11: =[1]Crops!C11 -> 0 | D11: =[1]Crops!D11 -> 0
A12: =[1]Crops!A12 -> 0 | B12: =[1]Crops!B12 -> 0 | C12: =[1]Crops!C12 -> 0 | D12: =[1]Crops!D12 -> 0
A13: =[1]Crops!A13 -> 0 | B13: =[1]Crops!B13 -> 0 | C13: =[1]Crops!C13 -> 0 | D13: =[1]Crops!D13 -> 0
A14: =[1]Crops!A14 -> 0 | B14: =[1]Crops!B14 -> 0 | C14: =[1]Crops!C14 -> 0 | D14: =[1]Crops!D14 -> 0
... A21: =[1]Crops!A21 -> 0 | B21: =[1]Crops!B21 -> 0 | C21: =[1]Crops!C21 -> 0 | D21: =[1]Crops!D21 -> 0

Sheet Crops PY
A1: ='[2]Crops(PY)'!A1 -> STATE | B1: ='[2]Crops(PY)'!B1 -> Code | C1: ='[2]Crops(PY)'!C1 -> Sample Type | D1: ='[2]Crops(PY)'!D1 -> code
A2: ='[2]Crops(PY)'!A2 -> PUDUCHERRY | B2: ='[2]Crops(PY)'!B2 -> 34 | C2: ='[2]Crops(PY)'!C2 -> CENTRAL | D2: ='[2]Crops(PY)'!D2 -> 1 | F2: Don't cut/delete the cell
A3: ='[2]Crops(PY)'!A3 -> YEAR | B3: ='[2]Crops(PY)'!B3 -> 0 | C3: ='[2]Crops(PY)'!C3 -> STATE | D3: ='[2]Crops(PY)'!D3 -> 2
A4: ='[2]Crops(PY)'!A4 -> Season | B4: ='[2]Crops(PY)'!B4 -> code | C4: ='[2]Crops(PY)'!C4 -> Season | D4: ='[2]Crops(PY)'!D4 -> code
A5: ='[2]Crops(PY)'!A5 -> RABI I | B5: ='[2]Crops(PY)'!B5 -> 4 | C5: ='[2]Crops(PY)'!C5 -> RABI II | D5: ='[2]Crops(PY)'!D5 -> 5
A6: ='[2]Crops(PY)'!A6 -> Crop | B6: ='[2]Crops(PY)'!B6 -> Code | C6: ='[2]Crops(PY)'!C6 -> Crop | D6: ='[2]Crops(PY)'!D6 -> Code
A7: ='[2]Crops(PY)'!A7 -> PADDY | B7: ='[2]Crops(PY)'!B7 -> 97 | C7: ='[2]Crops(PY)'!C7 -> PADDY | D7: ='[2]Crops(PY)'!D7 -> 98
A8: ='[2]Crops(PY)'!A8 -> OTHERS | B8: ='[2]Crops(PY)'!B8 -> 99 | C8: ='[2]Crops(PY)'!C8 -> OTHERS | D8: ='[2]Crops(PY)'!D8 -> 99
A9: ='[2]Crops(PY)'!A9 -> 0 | B9: ='[2]Crops(PY)'!B9 -> 0 | C9: ='[2]Crops(PY)'!C9 -> 0 | D9: ='[2]Crops(PY)'!D9 -> 0
A10: ='[2]Crops(PY)'!A10 -> 0 | B10: ='[2]Crops(PY)'!B10 -> 0 | C10: ='[2]Crops(PY)'!C10 -> 0 | D10: ='[2]Crops(PY)'!D10 -> 0
A11: ='[2]Crops(PY)'!A11 -> 0 | B11: ='[2]Crops(PY)'!B11 -> 0 | C11: ='[2]Crops(PY)'!C11 -> 0 | D11: ='[2]Crops(PY)'!D11 -> 0
A12: ='[2]Crops(PY)'!A12 -> 0 | B12: ='[2]Crops(PY)'!B12 -> 0 | C12: ='[2]Crops(PY)'!C12 -> 0 | D12: ='[2]Crops(PY)'!D12 -> 0
A13: ='[2]Crops(PY)'!A13 -> 0 | B13: ='[2]Crops(PY)'!B13 -> 0 | C13: ='[2]Crops(PY)'!C13 -> 0 | D13: ='[2]Crops(PY)'!D13 -> 0
A14: ='[2]Crops(PY)'!A14 -> 0 | B14: ='[2]Crops(PY)'!B14 -> 0 | C14: ='[2]Crops(PY)'!C14 -> 0 | D14: ='[2]Crops(PY)'!D14 -> 0
... A21: ='[2]Crops(PY)'!A21 -> 0 | B21: ='[2]Crops(PY)'!B21 -> 0 | C21: ='[2]Crops(PY)'!C21 -> 0 | D21: ='[2]Crops(PY)'!D21 -> 0

Sheet Annex-8
A2: A-10 | N2: TABLE-11(A):CROPWISE COMPARISON OF ENTRIES BY SUPERVISOR AND PATWARI OF CROP AREAS AS PER IRRIGATION AND SEED VARIETY. | AI2: TABLE-11(A):CROPWISE COMPARISON OF ENTRIES BY SUPERVISOR AND PATWARI OF CROP AREAS AS PER IRRIGATION AND SEED VARIETY.
A3: ="STATE:"& 'Crops CY'!$A$2 -> STATE:PUDUCHERRY | G3: ANNEX-VIII | N3: STATE: | O3: MAHARASHTRA(27) | S3: YEAR: | U3: 2014-15 | Y3: SEASON: | Z3: KHARIF(1) | AD3: SAMPLE: | AF3: CENTRAL(1) | AI3: STATE: | AJ3: MAHARASHTRA(27) | AN3: YEAR: | AP3: 2014-15 | AT3: SEASON: | AU3: KHARIF(1) | AY3: SAMPLE: | BA3: STATE(2)
A4: ="IMPACT OF DISCREPANCIES IN RECORDING AREA UNDER CROPS DURING"&" "& 'Crops CY'!$B$3 &" AND "& 'Crops PY'!$B$3&"." -> IMPACT OF DISCREPANCIES IN RECORDING AREA UNDER CROPS DURING 0 AND 0. | N4: CROP | O4: NO. OF VILLAGE REPORTING CROP | R4: COMPARISON AS PER IRRIGATION PARTICULARS | X4: COL (8-5)/5 *100 | Y4: COL (10-7)/7 *100 | Z4: COL (10)/7 (0.0000) | AA4: COMPARISON AS PER VARIETY OF SEED | AG4: COL (17-14)/14 *100 | AI4: CROP | AJ4: NO. OF VILLAGE REPORTING CROP | AM4: COMPARISON AS PER IRRIGATION PARTICULARS | AS4: COL (8-5)/5 *100 | AT4: COL (10-7)/7 *100 | AU4: COL (10)/7 (0.0000) | AV4: COMPARISON AS PER VARIETY OF SEED | BB4: COL (17-14)/14 *100
A5: SEASON / CROP | B5: AREA IN HECTARES AS OBSERVED IN SAMPLE CLUSTERS | R5: AREA UNDER CROP (0.00)HA | AA5: AREA UNDER CROP (0.00)HA | AM5: AREA UNDER CROP (0.00)HA | AV5: AREA UNDER CROP (0.00)HA
B6: CENTRAL SAMPLE | D6: STATE SAMPLE | F6: POOLED SAMPLE | I6: IMPACT OF DISCRIPANCIES (b-a/a)*100 (POOLED SAMPLE ONLY) | R6: AS PER SUPERVISOR | U6: AS PER PATWARIES | AA6: AS PER SUPERVISOR | AD6: AS PER PATWARIES | AM6: AS PER SUPERVISOR | AP6: AS PER PATWARIES | AV6: AS PER SUPERVISOR | AY6: AS PER PATWARIES
B7: AS PER SUPERVISOR | C7: AS PER PATWARI | D7: AS PER SUPERVISOR | E7: AS PER PATWARI | F7: AS PER SUPERVISOR | G7: AS PER PATWARI | O7: TOTAL | P7: IRR | Q7: HY | R7: IRR | S7: UN-IRR | T7: TOTAL | U7: IRR | V7: UN-IRR | W7: TOTAL | AA7: HY | AB7: LOCAL | AC7: TOTAL | AD7: HY | AE7: LOCAL | AF7: TOTAL | AJ7: TOTAL | AK7: IRR | AL7: HY | AM7: IRR | AN7: UN-IRR | AO7: TOTAL | AP7: IRR | AQ7: UN-IRR | AR7: TOTAL | AV7: HY | AW7: LOCAL | AX7: TOTAL | AY7: HY | AZ7: LOCAL | BA7: TOTAL
A8: (1) | B8: (2) | C8: (3) | D8: (4) | E8: (5) | F8: (6) | G8: (7) | I8: (8) | N8: 1 | O8: 2 | P8: 3 | Q8: 4 | R8: 5 | S8: 6 | T8: 7 | U8: 8 | V8: 9 | W8: 10 | X8: 11 | Y8: 12 | Z8: 13 | AA8: 14 | AB8: 15 | AC8: 16 | AD8: 17 | AE8: 18 | AF8: 19 | AG8: 20 | AI8: 1 | AJ8: 2 | AK8: 3 | AL8: 4 | AM8: 5 | AN8: 6 | AO8: 7 | AP8: 8 | AQ8: 9 | AR8: 10 | AS8: 11 | AT8: 12 | AU8: 13 | AV8: 14 | AW8: 15 | AX8: 16 | AY8: 17 | AZ8: 18 | BA8: 19 | BB8: 20
A9: ='Crops CY'!$A$5&" - "&'Crops CY'!$B$3 -> RABI I - 0 | N9: ='Crops CY'!$A$5&" - "&'Crops CY'!$B$3 -> RABI I - 0
A10: =N10 -> PADDY(97) | B10: =T10 -> 4.459 | C10: =W10 -> 4.589 | D10: =AO10 -> 15.6192 | E10: =AR10 -> 15.5092 | F10: =IF($A10="","",B10+D10) -> 20.0782 | G10: =IF($A10="","",C10+E10) -> 20.0982 | H10: =IF($A10="","",IF(F10=0,0,(G10-F10)*100/F10)) -> 0.099610523 | I10: =IF($A10="","",IF(H10<0,"(-)"&ROUND(ABS(H10),2),ROUND(H10,2))) -> 0.1 | N10: ='[3]Table-11(a)-O'!A9 -> PADDY(97) | O10: ='[3]Table-11(a)-O'!B9 -> 3 | P10: ='[3]Table-11(a)-O'!C9 -> 3 | Q10: ='[3]Table-11(a)-O'!D9 -> 3 | R10: ='[3]Table-11(a)-O'!E9 -> 4.459 | S10: ='[3]Table-11(a)-O'!F9 -> 0 | T10: ='[3]Table-11(a)-O'!G9 -> 4.459 | U10: ='[3]Table-11(a)-O'!H9 -> 4.589 | ... AG10: ='[3]Table-11(a)-O'!T9 -> 2.9154519 | AI10: ='[3]Table-11(a)-O'!V9 -> PADDY(97) | AJ10: ='[3]Table-11(a)-O'!W9 -> 8 | AK10: ='[3]Table-11(a)-O'!X9 -> 8 | AL10: ='[3]Table-11(a)-O'!Y9 -> 8 | AM10: ='[3]Table-11(a)-O'!Z9 -> 15.6192 | AN10: ='[3]Table-11(a)-O'!AA9 -> 0 | AO10: ='[3]Table-11(a)-O'!AB9 -> 15.6192 | AP10: ='[3]Table-11(a)-O'!AC9 -> 15.5092 | ... BB10: ='[3]Table-11(a)-O'!AO9 -> 0.70426142
A11: =N11 -> OTHERS(99) | B11: =T11 -> 1.7258 | C11: =W11 -> 2.5933 | D11: =AO11 -> 5.8897 | E11: =AR11 -> 5.9897 | F11: =IF($A11="","",B11+D11) -> 7.6155 | G11: =IF($A11="","",C11+E11) -> 8.583 | H11: =IF($A11="","",IF(F11=0,0,(G11-F11)*100/F11)) -> 12.704353 | I11: =IF($A11="","",IF(H11<0,"(-)"&ROUND(ABS(H11),2),ROUND(H11,2))) -> 12.7 | N11: ='[3]Table-11(a)-O'!A10 -> OTHERS(99) | O11: ='[3]Table-11(a)-O'!B10 -> 4 | P11: ='[3]Table-11(a)-O'!C10 -> 4 | Q11: ='[3]Table-11(a)-O'!D10 -> 4 | R11: ='[3]Table-11(a)-O'!E10 -> 1.7258 | S11: ='[3]Table-11(a)-O'!F10 -> 0 | T11: ='[3]Table-11(a)-O'!G10 -> 1.7258 | U11: ='[3]Table-11(a)-O'!H10 -> 2.5908 | ... AG11: ='[3]Table-11(a)-O'!T10 -> 50.266543 | AI11: ='[3]Table-11(a)-O'!V10 -> OTHERS(99) | AJ11: ='[3]Table-11(a)-O'!W10 -> 7 | AK11: ='[3]Table-11(a)-O'!X10 -> 7 | AL11: ='[3]Table-11(a)-O'!Y10 -> 6 | AM11: ='[3]Table-11(a)-O'!Z10 -> 5.7236 | AN11: ='[3]Table-11(a)-O'!AA10 -> 0.1661 | AO11: ='[3]Table-11(a)-O'!AB10 -> 5.8897 | AP11: ='[3]Table-11(a)-O'!AC10 -> 5.8236 | ... BB11: ='[3]Table-11(a)-O'!AO10 -> 1.7153541
A12: =N12 | B12: =T12 | C12: =W12 | D12: =AO12 | E12: =AR12 | F12: =IF($A12="","",B12+D12) | G12: =IF($A12="","",C12+E12) | H12: =IF($A12="","",IF(F12=0,0,(G12-F12)*100/F12)) | I12: =IF($A12="","",IF(H12<0,"(-)"&ROUND(ABS(H12),2),ROUND(H12,2))) | N12: ='[3]Table-11(a)-O'!A11 | O12: ='[3]Table-11(a)-O'!B11 | P12: ='[3]Table-11(a)-O'!C11 | Q12: ='[3]Table-11(a)-O'!D11 | R12: ='[3]Table-11(a)-O'!E11 | S12: ='[3]Table-11(a)-O'!F11 | T12: ='[3]Table-11(a)-O'!G11 | U12: ='[3]Table-11(a)-O'!H11 | ... AG12: ='[3]Table-11(a)-O'!T11 | AI12: ='[3]Table-11(a)-O'!V11 | AJ12: ='[3]Table-11(a)-O'!W11 | AK12: ='[3]Table-11(a)-O'!X11 | AL12: ='[3]Table-11(a)-O'!Y11 | AM12: ='[3]Table-11(a)-O'!Z11 | AN12: ='[3]Table-11(a)-O'!AA11 | AO12: ='[3]Table-11(a)-O'!AB11 | AP12: ='[3]Table-11(a)-O'!AC11 | ... BB12: ='[3]Table-11(a)-O'!AO11
A13: =N13 | B13: =T13 | C13: =W13 | D13: =AO13 | E13: =AR13 | F13: =IF($A13="","",B13+D13) | G13: =IF($A13="","",C13+E13) | H13: =IF($A13="","",IF(F13=0,0,(G13-F13)*100/F13)) | I13: =IF($A13="","",IF(H13<0,"(-)"&ROUND(ABS(H13),2),ROUND(H13,2))) | N13: ='[3]Table-11(a)-O'!A12 | O13: ='[3]Table-11(a)-O'!B12 | P13: ='[3]Table-11(a)-O'!C12 | Q13: ='[3]Table-11(a)-O'!D12 | R13: ='[3]Table-11(a)-O'!E12 | S13: ='[3]Table-11(a)-O'!F12 | T13: ='[3]Table-11(a)-O'!G12 | U13: ='[3]Table-11(a)-O'!H12 | ... AG13: ='[3]Table-11(a)-O'!T12 | AI13: ='[3]Table-11(a)-O'!V12 | AJ13: ='[3]Table-11(a)-O'!W12 | AK13: ='[3]Table-11(a)-O'!X12 | AL13: ='[3]Table-11(a)-O'!Y12 | AM13: ='[3]Table-11(a)-O'!Z12 | AN13: ='[3]Table-11(a)-O'!AA12 | AO13: ='[3]Table-11(a)-O'!AB12 | AP13: ='[3]Table-11(a)-O'!AC12 | ... BB13: ='[3]Table-11(a)-O'!AO12
A14: =N14 | B14: =T14 | C14: =W14 | D14: =AO14 | E14: =AR14 | F14: =IF($A14="","",B14+D14) | G14: =IF($A14="","",C14+E14) | H14: =IF($A14="","",IF(F14=0,0,(G14-F14)*100/F14)) | I14: =IF($A14="","",IF(H14<0,"(-)"&ROUND(ABS(H14),2),ROUND(H14,2))) | N14: ='[3]Table-11(a)-O'!A13 | O14: ='[3]Table-11(a)-O'!B13 | P14: ='[3]Table-11(a)-O'!C13 | Q14: ='[3]Table-11(a)-O'!D13 | R14: ='[3]Table-11(a)-O'!E13 | S14: ='[3]Table-11(a)-O'!F13 | T14: ='[3]Table-11(a)-O'!G13 | U14: ='[3]Table-11(a)-O'!H13 | ... AG14: ='[3]Table-11(a)-O'!T13 | AI14: ='[3]Table-11(a)-O'!V13 | AJ14: ='[3]Table-11(a)-O'!W13 | AK14: ='[3]Table-11(a)-O'!X13 | AL14: ='[3]Table-11(a)-O'!Y13 | AM14: ='[3]Table-11(a)-O'!Z13 | AN14: ='[3]Table-11(a)-O'!AA13 | AO14: ='[3]Table-11(a)-O'!AB13 | AP14: ='[3]Table-11(a)-O'!AC13 | ... BB14: ='[3]Table-11(a)-O'!AO13
A15: =N15 | B15: =T15 | C15: =W15 | D15: =AO15 | E15: =AR15 | F15: =IF($A15="","",B15+D15) | G15: =IF($A15="","",C15+E15) | H15: =IF($A15="","",IF(F15=0,0,(G15-F15)*100/F15)) | I15: =IF($A15="","",IF(H15<0,"(-)"&ROUND(ABS(H15),2),ROUND(H15,2))) | N15: ='[3]Table-11(a)-O'!A14 | O15: ='[3]Table-11(a)-O'!B14 | P15: ='[3]Table-11(a)-O'!C14 | Q15: ='[3]Table-11(a)-O'!D14 | R15: ='[3]Table-11(a)-O'!E14 | S15: ='[3]Table-11(a)-O'!F14 | T15: ='[3]Table-11(a)-O'!G14 | U15: ='[3]Table-11(a)-O'!H14 | ... AG15: ='[3]Table-11(a)-O'!T14 | AI15: ='[3]Table-11(a)-O'!V14 | AJ15: ='[3]Table-11(a)-O'!W14 | AK15: ='[3]Table-11(a)-O'!X14 | AL15: ='[3]Table-11(a)-O'!Y14 | AM15: ='[3]Table-11(a)-O'!Z14 | AN15: ='[3]Table-11(a)-O'!AA14 | AO15: ='[3]Table-11(a)-O'!AB14 | AP15: ='[3]Table-11(a)-O'!AC14 | ... BB15: ='[3]Table-11(a)-O'!AO14
A16: =N16 | B16: =T16 | C16: =W16 | D16: =AO16 | E16: =AR16 | F16: =IF($A16="","",B16+D16) | G16: =IF($A16="","",C16+E16) | H16: =IF($A16="","",IF(F16=0,0,(G16-F16)*100/F16)) | I16: =IF($A16="","",IF(H16<0,"(-)"&ROUND(ABS(H16),2),ROUND(H16,2))) | N16: ='[3]Table-11(a)-O'!A15 | O16: ='[3]Table-11(a)-O'!B15 | P16: ='[3]Table-11(a)-O'!C15 | Q16: ='[3]Table-11(a)-O'!D15 | R16: ='[3]Table-11(a)-O'!E15 | S16: ='[3]Table-11(a)-O'!F15 | T16: ='[3]Table-11(a)-O'!G15 | U16: ='[3]Table-11(a)-O'!H15 | ... AG16: ='[3]Table-11(a)-O'!T15 | AI16: ='[3]Table-11(a)-O'!V15 | AJ16: ='[3]Table-11(a)-O'!W15 | AK16: ='[3]Table-11(a)-O'!X15 | AL16: ='[3]Table-11(a)-O'!Y15 | AM16: ='[3]Table-11(a)-O'!Z15 | AN16: ='[3]Table-11(a)-O'!AA15 | AO16: ='[3]Table-11(a)-O'!AB15 | AP16: ='[3]Table-11(a)-O'!AC15 | ... BB16: ='[3]Table-11(a)-O'!AO15
A17: =N17 | B17: =T17 | C17: =W17 | D17: =AO17 | E17: =AR17 | F17: =IF($A17="","",B17+D17) | G17: =IF($A17="","",C17+E17) | H17: =IF($A17="","",IF(F17=0,0,(G17-F17)*100/F17)) | I17: =IF($A17="","",IF(H17<0,"(-)"&ROUND(ABS(H17),2),ROUND(H17,2))) | N17: ='[3]Table-11(a)-O'!A16 | O17: ='[3]Table-11(a)-O'!B16 | P17: ='[3]Table-11(a)-O'!C16 | Q17: ='[3]Table-11(a)-O'!D16 | R17: ='[3]Table-11(a)-O'!E16 | S17: ='[3]Table-11(a)-O'!F16 | T17: ='[3]Table-11(a)-O'!G16 | U17: ='[3]Table-11(a)-O'!H16 | ... AG17: ='[3]Table-11(a)-O'!T16 | AI17: ='[3]Table-11(a)-O'!V16 | AJ17: ='[3]Table-11(a)-O'!W16 | AK17: ='[3]Table-11(a)-O'!X16 | AL17: ='[3]Table-11(a)-O'!Y16 | AM17: ='[3]Table-11(a)-O'!Z16 | AN17: ='[3]Table-11(a)-O'!AA16 | AO17: ='[3]Table-11(a)-O'!AB16 | AP17: ='[3]Table-11(a)-O'!AC16 | ... BB17: ='[3]Table-11(a)-O'!AO16
A18: =N18 | B18: =T18 | C18: =W18 | D18: =AO18 | E18: =AR18 | F18: =IF($A18="","",B18+D18) | G18: =IF($A18="","",C18+E18) | H18: =IF($A18="","",IF(F18=0,0,(G18-F18)*100/F18)) | I18: =IF($A18="","",IF(H18<0,"(-)"&ROUND(ABS(H18),2),ROUND(H18,2))) | N18: ='[3]Table-11(a)-O'!A17 | O18: ='[3]Table-11(a)-O'!B17 | P18: ='[3]Table-11(a)-O'!C17 | Q18: ='[3]Table-11(a)-O'!D17 | R18: ='[3]Table-11(a)-O'!E17 | S18: ='[3]Table-11(a)-O'!F17 | T18: ='[3]Table-11(a)-O'!G17 | U18: ='[3]Table-11(a)-O'!H17 | ... AG18: ='[3]Table-11(a)-O'!T17 | AI18: ='[3]Table-11(a)-O'!V17 | AJ18: ='[3]Table-11(a)-O'!W17 | AK18: ='[3]Table-11(a)-O'!X17 | AL18: ='[3]Table-11(a)-O'!Y17 | AM18: ='[3]Table-11(a)-O'!Z17 | AN18: ='[3]Table-11(a)-O'!AA17 | AO18: ='[3]Table-11(a)-O'!AB17 | AP18: ='[3]Table-11(a)-O'!AC17 | ... BB18: ='[3]Table-11(a)-O'!AO17
A19: =N19 | B19: =T19 | C19: =W19 | D19: =AO19 | E19: =AR19 | F19: =IF($A19="","",B19+D19) | G19: =IF($A19="","",C19+E19) | H19: =IF($A19="","",IF(F19=0,0,(G19-F19)*100/F19)) | I19: =IF($A19="","",IF(H19<0,"(-)"&ROUND(ABS(H19),2),ROUND(H19,2))) | N19: ='[3]Table-11(a)-O'!A18 | O19: ='[3]Table-11(a)-O'!B18 | P19: ='[3]Table-11(a)-O'!C18 | Q19: ='[3]Table-11(a)-O'!D18 | R19: ='[3]Table-11(a)-O'!E18 | S19: ='[3]Table-11(a)-O'!F18 | T19: ='[3]Table-11(a)-O'!G18 | U19: ='[3]Table-11(a)-O'!H18 | ... AG19: ='[3]Table-11(a)-O'!T18 | AI19: ='[3]Table-11(a)-O'!V18 | AJ19: ='[3]Table-11(a)-O'!W18 | AK19: ='[3]Table-11(a)-O'!X18 | AL19: ='[3]Table-11(a)-O'!Y18 | AM19: ='[3]Table-11(a)-O'!Z18 | AN19: ='[3]Table-11(a)-O'!AA18 | AO19: ='[3]Table-11(a)-O'!AB18 | AP19: ='[3]Table-11(a)-O'!AC18 | ... BB19: ='[3]Table-11(a)-O'!AO18
A20: =N20 | B20: =T20 | C20: =W20 | D20: =AO20 | E20: =AR20 | F20: =IF($A20="","",B20+D20) | G20: =IF($A20="","",C20+E20) | H20: =IF($A20="","",IF(F20=0,0,(G20-F20)*100/F20)) | I20: =IF($A20="","",IF(H20<0,"(-)"&ROUND(ABS(H20),2),ROUND(H20,2))) | N20: ='[3]Table-11(a)-O'!A19 | O20: ='[3]Table-11(a)-O'!B19 | P20: ='[3]Table-11(a)-O'!C19 | Q20: ='[3]Table-11(a)-O'!D19 | R20: ='[3]Table-11(a)-O'!E19 | S20: ='[3]Table-11(a)-O'!F19 | T20: ='[3]Table-11(a)-O'!G19 | U20: ='[3]Table-11(a)-O'!H19 | ... AG20: ='[3]Table-11(a)-O'!T19 | AI20: ='[3]Table-11(a)-O'!V19 | AJ20: ='[3]Table-11(a)-O'!W19 | AK20: ='[3]Table-11(a)-O'!X19 | AL20: ='[3]Table-11(a)-O'!Y19 | AM20: ='[3]Table-11(a)-O'!Z19 | AN20: ='[3]Table-11(a)-O'!AA19 | AO20: ='[3]Table-11(a)-O'!AB19 | AP20: ='[3]Table-11(a)-O'!AC19 | ... BB20: ='[3]Table-11(a)-O'!AO19
A21: =N21 | B21: =T21 | C21: =W21 | D21: =AO21 | E21: =AR21 | F21: =IF($A21="","",B21+D21) | G21: =IF($A21="","",C21+E21) | H21: =IF($A21="","",IF(F21=0,0,(G21-F21)*100/F21)) | I21: =IF($A21="","",IF(H21<0,"(-)"&ROUND(ABS(H21),2),ROUND(H21,2))) | N21: ='[3]Table-11(a)-O'!A20 | O21: ='[3]Table-11(a)-O'!B20 | P21: ='[3]Table-11(a)-O'!C20 | Q21: ='[3]Table-11(a)-O'!D20 | R21: ='[3]Table-11(a)-O'!E20 | S21: ='[3]Table-11(a)-O'!F20 | T21: ='[3]Table-11(a)-O'!G20 | U21: ='[3]Table-11(a)-O'!H20 | ... AG21: ='[3]Table-11(a)-O'!T20 | AI21: ='[3]Table-11(a)-O'!V20 | AJ21: ='[3]Table-11(a)-O'!W20 | AK21: ='[3]Table-11(a)-O'!X20 | AL21: ='[3]Table-11(a)-O'!Y20 | AM21: ='[3]Table-11(a)-O'!Z20 | AN21: ='[3]Table-11(a)-O'!AA20 | AO21: ='[3]Table-11(a)-O'!AB20 | AP21: ='[3]Table-11(a)-O'!AC20 | ... BB21: ='[3]Table-11(a)-O'!AO20
... A24: =N24 | B24: =T24 | C24: =W24 | D24: =AO24 | E24: =AR24 | F24: =IF($A24="","",B24+D24) | G24: =IF($A24="","",C24+E24) | H24: =IF($A24="","",IF(F24=0,0,(G24-F24)*100/F24)) | I24: =IF($A24="","",IF(H24<0,"(-)"&ROUND(ABS(H24),2),ROUND(H24,2))) | N24: ='[3]Table-11(a)-O'!A23 | O24: ='[3]Table-11(a)-O'!B23 | P24: ='[3]Table-11(a)-O'!C23 | Q24: ='[3]Table-11(a)-O'!D23 | R24: ='[3]Table-11(a)-O'!E23 | S24: ='[3]Table-11(a)-O'!F23 | T24: ='[3]Table-11(a)-O'!G23 | U24: ='[3]Table-11(a)-O'!H23 | ... AG24: ='[3]Table-11(a)-O'!T23 | AI24: ='[3]Table-11(a)-O'!V23 | AJ24: ='[3]Table-11(a)-O'!W23 | AK24: ='[3]Table-11(a)-O'!X23 | AL24: ='[3]Table-11(a)-O'!Y23 | AM24: ='[3]Table-11(a)-O'!Z23 | AN24: ='[3]Table-11(a)-O'!AA23 | AO24: ='[3]Table-11(a)-O'!AB23 | AP24: ='[3]Table-11(a)-O'!AC23 | ... BB24: ='[3]Table-11(a)-O'!AO23
A25: ='Crops CY'!$C$5&" - "&'Crops CY'!$B$3 -> RABI II - 0 | N25: ='Crops CY'!$C$5&" - "&'Crops CY'!$B$3 -> RABI II - 0
A26: =N26 -> PADDY(98) | B26: =T26 -> 0.025 | C26: =W26 -> 0.025 | D26: =AO26 -> 8.785 | E26: =AR26 -> 8.6 | F26: =IF($A26="","",B26+D26) -> 8.81 | G26: =IF($A26="","",C26+E26) -> 8.625 | H26: =IF($A26="","",IF(F26=0,0,(G26-F26)*100/F26)) -> -2.0998865 | I26: =IF($A26="","",IF(H26<0,"(-)"&ROUND(ABS(H26),2),ROUND(H26,2))) -> (-)2.1 | N26: ='[4]Table-11(a)-O'!A9 -> PADDY(98) | O26: ='[4]Table-11(a)-O'!B9 -> 1 | P26: ='[4]Table-11(a)-O'!C9 -> 1 | Q26: ='[4]Table-11(a)-O'!D9 -> 1 | R26: ='[4]Table-11(a)-O'!E9 -> 0.025 | S26: ='[4]Table-11(a)-O'!F9 -> 0 | T26: ='[4]Table-11(a)-O'!G9 -> 0.025 | U26: ='[4]Table-11(a)-O'!H9 -> 0.025 | ... AG26: ='[4]Table-11(a)-O'!T9 -> 0 | AI26: ='[4]Table-11(a)-O'!V9 -> PADDY(98) | AJ26: ='[4]Table-11(a)-O'!W9 -> 5 | AK26: ='[4]Table-11(a)-O'!X9 -> 5 | AL26: ='[4]Table-11(a)-O'!Y9 -> 5 | AM26: ='[4]Table-11(a)-O'!Z9 -> 8.785 | AN26: ='[4]Table-11(a)-O'!AA9 -> 0 | AO26: ='[4]Table-11(a)-O'!AB9 -> 8.785 | AP26: ='[4]Table-11(a)-O'!AC9 -> 8.6 | ... BB26: ='[4]Table-11(a)-O'!AO9 -> 2.1058623
A27: =N27 -> OTHERS(99) | B27: =T27 -> 1.77 | C27: =W27 -> 2.6175 | D27: =AO27 -> 4.4943 | E27: =AR27 -> 4.4943 | F27: =IF($A27="","",B27+D27) -> 6.2643 | G27: =IF($A27="","",C27+E27) -> 7.1118 | H27: =IF($A27="","",IF(F27=0,0,(G27-F27)*100/F27)) -> 13.529046 | I27: =IF($A27="","",IF(H27<0,"(-)"&ROUND(ABS(H27),2),ROUND(H27,2))) -> 13.53 | N27: ='[4]Table-11(a)-O'!A10 -> OTHERS(99) | O27: ='[4]Table-11(a)-O'!B10 -> 4 | P27: ='[4]Table-11(a)-O'!C10 -> 4 | Q27: ='[4]Table-11(a)-O'!D10 -> 4 | R27: ='[4]Table-11(a)-O'!E10 -> 1.77 | S27: ='[4]Table-11(a)-O'!F10 -> 0 | T27: ='[4]Table-11(a)-O'!G10 -> 1.77 | U27: ='[4]Table-11(a)-O'!H10 -> 2.615 | ... AG27: ='[4]Table-11(a)-O'!T10 -> 47.881356 | AI27: ='[4]Table-11(a)-O'!V10 -> OTHERS(99) | AJ27: ='[4]Table-11(a)-O'!W10 -> 7 | AK27: ='[4]Table-11(a)-O'!X10 -> 7 | AL27: ='[4]Table-11(a)-O'!Y10 -> 6 | AM27: ='[4]Table-11(a)-O'!Z10 -> 3.5894 | AN27: ='[4]Table-11(a)-O'!AA10 -> 0.9049 | AO27: ='[4]Table-11(a)-O'!AB10 -> 4.4943 | AP27: ='[4]Table-11(a)-O'!AC10 -> 3.5894 | ... BB27: ='[4]Table-11(a)-O'!AO10 -> 0
A28: =N28 | B28: =T28 | C28: =W28 | D28: =AO28 | E28: =AR28 | F28: =IF($A28="","",B28+D28) | G28: =IF($A28="","",C28+E28) | H28: =IF($A28="","",IF(F28=0,0,(G28-F28)*100/F28)) | I28: =IF($A28="","",IF(H28<0,"(-)"&ROUND(ABS(H28),2),ROUND(H28,2))) | N28: ='[4]Table-11(a)-O'!A11 | O28: ='[4]Table-11(a)-O'!B11 | P28: ='[4]Table-11(a)-O'!C11 | Q28: ='[4]Table-11(a)-O'!D11 | R28: ='[4]Table-11(a)-O'!E11 | S28: ='[4]Table-11(a)-O'!F11 | T28: ='[4]Table-11(a)-O'!G11 | U28: ='[4]Table-11(a)-O'!H11 | ... AG28: ='[4]Table-11(a)-O'!T11 | AI28: ='[4]Table-11(a)-O'!V11 | AJ28: ='[4]Table-11(a)-O'!W11 | AK28: ='[4]Table-11(a)-O'!X11 | AL28: ='[4]Table-11(a)-O'!Y11 | AM28: ='[4]Table-11(a)-O'!Z11 | AN28: ='[4]Table-11(a)-O'!AA11 | AO28: ='[4]Table-11(a)-O'!AB11 | AP28: ='[4]Table-11(a)-O'!AC11 | ... BB28: ='[4]Table-11(a)-O'!AO11
A29: =N29 | B29: =T29 | C29: =W29 | D29: =AO29 | E29: =AR29 | F29: =IF($A29="","",B29+D29) | G29: =IF($A29="","",C29+E29) | H29: =IF($A29="","",IF(F29=0,0,(G29-F29)*100/F29)) | I29: =IF($A29="","",IF(H29<0,"(-)"&ROUND(ABS(H29),2),ROUND(H29,2))) | N29: ='[4]Table-11(a)-O'!A12 | O29: ='[4]Table-11(a)-O'!B12 | P29: ='[4]Table-11(a)-O'!C12 | Q29: ='[4]Table-11(a)-O'!D12 | R29: ='[4]Table-11(a)-O'!E12 | S29: ='[4]Table-11(a)-O'!F12 | T29: ='[4]Table-11(a)-O'!G12 | U29: ='[4]Table-11(a)-O'!H12 | ... AG29: ='[4]Table-11(a)-O'!T12 | AI29: ='[4]Table-11(a)-O'!V12 | AJ29: ='[4]Table-11(a)-O'!W12 | AK29: ='[4]Table-11(a)-O'!X12 | AL29: ='[4]Table-11(a)-O'!Y12 | AM29: ='[4]Table-11(a)-O'!Z12 | AN29: ='[4]Table-11(a)-O'!AA12 | AO29: ='[4]Table-11(a)-O'!AB12 | AP29: ='[4]Table-11(a)-O'!AC12 | ... BB29: ='[4]Table-11(a)-O'!AO12
A30: =N30 | B30: =T30 | C30: =W30 | D30: =AO30 | E30: =AR30 | F30: =IF($A30="","",B30+D30) | G30: =IF($A30="","",C30+E30) | H30: =IF($A30="","",IF(F30=0,0,(G30-F30)*100/F30)) | I30: =IF($A30="","",IF(H30<0,"(-)"&ROUND(ABS(H30),2),ROUND(H30,2))) | N30: ='[4]Table-11(a)-O'!A13 | O30: ='[4]Table-11(a)-O'!B13 | P30: ='[4]Table-11(a)-O'!C13 | Q30: ='[4]Table-11(a)-O'!D13 | R30: ='[4]Table-11(a)-O'!E13 | S30: ='[4]Table-11(a)-O'!F13 | T30: ='[4]Table-11(a)-O'!G13 | U30: ='[4]Table-11(a)-O'!H13 | ... AG30: ='[4]Table-11(a)-O'!T13 | AI30: ='[4]Table-11(a)-O'!V13 | AJ30: ='[4]Table-11(a)-O'!W13 | AK30: ='[4]Table-11(a)-O'!X13 | AL30: ='[4]Table-11(a)-O'!Y13 | AM30: ='[4]Table-11(a)-O'!Z13 | AN30: ='[4]Table-11(a)-O'!AA13 | AO30: ='[4]Table-11(a)-O'!AB13 | AP30: ='[4]Table-11(a)-O'!AC13 | ... BB30: ='[4]Table-11(a)-O'!AO13
A31: =N31 | B31: =T31 | C31: =W31 | D31: =AO31 | E31: =AR31 | F31: =IF($A31="","",B31+D31) | G31: =IF($A31="","",C31+E31) | H31: =IF($A31="","",IF(F31=0,0,(G31-F31)*100/F31)) | I31: =IF($A31="","",IF(H31<0,"(-)"&ROUND(ABS(H31),2),ROUND(H31,2))) | N31: ='[4]Table-11(a)-O'!A14 | O31: ='[4]Table-11(a)-O'!B14 | P31: ='[4]Table-11(a)-O'!C14 | Q31: ='[4]Table-11(a)-O'!D14 | R31: ='[4]Table-11(a)-O'!E14 | S31: ='[4]Table-11(a)-O'!F14 | T31: ='[4]Table-11(a)-O'!G14 | U31: ='[4]Table-11(a)-O'!H14 | ... AG31: ='[4]Table-11(a)-O'!T14 | AI31: ='[4]Table-11(a)-O'!V14 | AJ31: ='[4]Table-11(a)-O'!W14 | AK31: ='[4]Table-11(a)-O'!X14 | AL31: ='[4]Table-11(a)-O'!Y14 | AM31: ='[4]Table-11(a)-O'!Z14 | AN31: ='[4]Table-11(a)-O'!AA14 | AO31: ='[4]Table-11(a)-O'!AB14 | AP31: ='[4]Table-11(a)-O'!AC14 | ... BB31: ='[4]Table-11(a)-O'!AO14
A32: =N32 | B32: =T32 | C32: =W32 | D32: =AO32 | E32: =AR32 | F32: =IF($A32="","",B32+D32) | G32: =IF($A32="","",C32+E32) | H32: =IF($A32="","",IF(F32=0,0,(G32-F32)*100/F32)) | I32: =IF($A32="","",IF(H32<0,"(-)"&ROUND(ABS(H32),2),ROUND(H32,2))) | N32: ='[4]Table-11(a)-O'!A15 | O32: ='[4]Table-11(a)-O'!B15 | P32: ='[4]Table-11(a)-O'!C15 | Q32: ='[4]Table-11(a)-O'!D15 | R32: ='[4]Table-11(a)-O'!E15 | S32: ='[4]Table-11(a)-O'!F15 | T32: ='[4]Table-11(a)-O'!G15 | U32: ='[4]Table-11(a)-O'!H15 | ... AG32: ='[4]Table-11(a)-O'!T15 | AI32: ='[4]Table-11(a)-O'!V15 | AJ32: ='[4]Table-11(a)-O'!W15 | AK32: ='[4]Table-11(a)-O'!X15 | AL32: ='[4]Table-11(a)-O'!Y15 | AM32: ='[4]Table-11(a)-O'!Z15 | AN32: ='[4]Table-11(a)-O'!AA15 | AO32: ='[4]Table-11(a)-O'!AB15 | AP32: ='[4]Table-11(a)-O'!AC15 | ... BB32: ='[4]Table-11(a)-O'!AO15
A33: =N33 | B33: =T33 | C33: =W33 | D33: =AO33 | E33: =AR33 | F33: =IF($A33="","",B33+D33) | G33: =IF($A33="","",C33+E33) | H33: =IF($A33="","",IF(F33=0,0,(G33-F33)*100/F33)) | I33: =IF($A33="","",IF(H33<0,"(-)"&ROUND(ABS(H33),2),ROUND(H33,2))) | N33: ='[4]Table-11(a)-O'!A16 | O33: ='[4]Table-11(a)-O'!B16 | P33: ='[4]Table-11(a)-O'!C16 | Q33: ='[4]Table-11(a)-O'!D16 | R33: ='[4]Table-11(a)-O'!E16 | S33: ='[4]Table-11(a)-O'!F16 | T33: ='[4]Table-11(a)-O'!G16 | U33: ='[4]Table-11(a)-O'!H16 | ... AG33: ='[4]Table-11(a)-O'!T16 | AI33: ='[4]Table-11(a)-O'!V16 | AJ33: ='[4]Table-11(a)-O'!W16 | AK33: ='[4]Table-11(a)-O'!X16 | AL33: ='[4]Table-11(a)-O'!Y16 | AM33: ='[4]Table-11(a)-O'!Z16 | AN33: ='[4]Table-11(a)-O'!AA16 | AO33: ='[4]Table-11(a)-O'!AB16 | AP33: ='[4]Table-11(a)-O'!AC16 | ... BB33: ='[4]Table-11(a)-O'!AO16
A34: =N34 | B34: =T34 | C34: =W34 | D34: =AO34 | E34: =AR34 | F34: =IF($A34="","",B34+D34) | G34: =IF($A34="","",C34+E34) | H34: =IF($A34="","",IF(F34=0,0,(G34-F34)*100/F34)) | I34: =IF($A34="","",IF(H34<0,"(-)"&ROUND(ABS(H34),2),ROUND(H34,2))) | N34: ='[4]Table-11(a)-O'!A17 | O34: ='[4]Table-11(a)-O'!B17 | P34: ='[4]Table-11(a)-O'!C17 | Q34: ='[4]Table-11(a)-O'!D17 | R34: ='[4]Table-11(a)-O'!E17 | S34: ='[4]Table-11(a)-O'!F17 | T34: ='[4]Table-11(a)-O'!G17 | U34: ='[4]Table-11(a)-O'!H17 | ... AG34: ='[4]Table-11(a)-O'!T17 | AI34: ='[4]Table-11(a)-O'!V17 | AJ34: ='[4]Table-11(a)-O'!W17 | AK34: ='[4]Table-11(a)-O'!X17 | AL34: ='[4]Table-11(a)-O'!Y17 | AM34: ='[4]Table-11(a)-O'!Z17 | AN34: ='[4]Table-11(a)-O'!AA17 | AO34: ='[4]Table-11(a)-O'!AB17 | AP34: ='[4]Table-11(a)-O'!AC17 | ... BB34: ='[4]Table-11(a)-O'!AO17
A35: =N35 | B35: =T35 | C35: =W35 | D35: =AO35 | E35: =AR35 | F35: =IF($A35="","",B35+D35) | G35: =IF($A35="","",C35+E35) | H35: =IF($A35="","",IF(F35=0,0,(G35-F35)*100/F35)) | I35: =IF($A35="","",IF(H35<0,"(-)"&ROUND(ABS(H35),2),ROUND(H35,2))) | N35: ='[4]Table-11(a)-O'!A18 | O35: ='[4]Table-11(a)-O'!B18 | P35: ='[4]Table-11(a)-O'!C18 | Q35: ='[4]Table-11(a)-O'!D18 | R35: ='[4]Table-11(a)-O'!E18 | S35: ='[4]Table-11(a)-O'!F18 | T35: ='[4]Table-11(a)-O'!G18 | U35: ='[4]Table-11(a)-O'!H18 | ... AG35: ='[4]Table-11(a)-O'!T18 | AI35: ='[4]Table-11(a)-O'!V18 | AJ35: ='[4]Table-11(a)-O'!W18 | AK35: ='[4]Table-11(a)-O'!X18 | AL35: ='[4]Table-11(a)-O'!Y18 | AM35: ='[4]Table-11(a)-O'!Z18 | AN35: ='[4]Table-11(a)-O'!AA18 | AO35: ='[4]Table-11(a)-O'!AB18 | AP35: ='[4]Table-11(a)-O'!AC18 | ... BB35: ='[4]Table-11(a)-O'!AO18
A36: =N36 | B36: =T36 | C36: =W36 | D36: =AO36 | E36: =AR36 | F36: =IF($A36="","",B36+D36) | G36: =IF($A36="","",C36+E36) | H36: =IF($A36="","",IF(F36=0,0,(G36-F36)*100/F36)) | I36: =IF($A36="","",IF(H36<0,"(-)"&ROUND(ABS(H36),2),ROUND(H36,2))) | N36: ='[4]Table-11(a)-O'!A19 | O36: ='[4]Table-11(a)-O'!B19 | P36: ='[4]Table-11(a)-O'!C19 | Q36: ='[4]Table-11(a)-O'!D19 | R36: ='[4]Table-11(a)-O'!E19 | S36: ='[4]Table-11(a)-O'!F19 | T36: ='[4]Table-11(a)-O'!G19 | U36: ='[4]Table-11(a)-O'!H19 | ... AG36: ='[4]Table-11(a)-O'!T19 | AI36: ='[4]Table-11(a)-O'!V19 | AJ36: ='[4]Table-11(a)-O'!W19 | AK36: ='[4]Table-11(a)-O'!X19 | AL36: ='[4]Table-11(a)-O'!Y19 | AM36: ='[4]Table-11(a)-O'!Z19 | AN36: ='[4]Table-11(a)-O'!AA19 | AO36: ='[4]Table-11(a)-O'!AB19 | AP36: ='[4]Table-11(a)-O'!AC19 | ... BB36: ='[4]Table-11(a)-O'!AO19
A37: =N37 | B37: =T37 | C37: =W37 | D37: =AO37 | E37: =AR37 | F37: =IF($A37="","",B37+D37) | G37: =IF($A37="","",C37+E37) | H37: =IF($A37="","",IF(F37=0,0,(G37-F37)*100/F37)) | I37: =IF($A37="","",IF(H37<0,"(-)"&ROUND(ABS(H37),2),ROUND(H37,2))) | N37: ='[4]Table-11(a)-O'!A20 | O37: ='[4]Table-11(a)-O'!B20 | P37: ='[4]Table-11(a)-O'!C20 | Q37: ='[4]Table-11(a)-O'!D20 | R37: ='[4]Table-11(a)-O'!E20 | S37: ='[4]Table-11(a)-O'!F20 | T37: ='[4]Table-11(a)-O'!G20 | U37: ='[4]Table-11(a)-O'!H20 | ... AG37: ='[4]Table-11(a)-O'!T20 | AI37: ='[4]Table-11(a)-O'!V20 | AJ37: ='[4]Table-11(a)-O'!W20 | AK37: ='[4]Table-11(a)-O'!X20 | AL37: ='[4]Table-11(a)-O'!Y20 | AM37: ='[4]Table-11(a)-O'!Z20 | AN37: ='[4]Table-11(a)-O'!AA20 | AO37: ='[4]Table-11(a)-O'!AB20 | AP37: ='[4]Table-11(a)-O'!AC20 | ... BB37: ='[4]Table-11(a)-O'!AO20
... A40: =N40 | B40: =T40 | C40: =W40 | D40: =AO40 | E40: =AR40 | F40: =IF($A40="","",B40+D40) | G40: =IF($A40="","",C40+E40) | H40: =IF($A40="","",IF(F40=0,0,(G40-F40)*100/F40)) | I40: =IF($A40="","",IF(H40<0,"(-)"&ROUND(ABS(H40),2),ROUND(H40,2))) | N40: ='[4]Table-11(a)-O'!A23 | O40: ='[4]Table-11(a)-O'!B23 | P40: ='[4]Table-11(a)-O'!C23 | Q40: ='[4]Table-11(a)-O'!D23 | R40: ='[4]Table-11(a)-O'!E23 | S40: ='[4]Table-11(a)-O'!F23 | T40: ='[4]Table-11(a)-O'!G23 | U40: ='[4]Table-11(a)-O'!H23 | ... AG40: ='[4]Table-11(a)-O'!T23 | AI40: ='[4]Table-11(a)-O'!V23 | AJ40: ='[4]Table-11(a)-O'!W23 | AK40: ='[4]Table-11(a)-O'!X23 | AL40: ='[4]Table-11(a)-O'!Y23 | AM40: ='[4]Table-11(a)-O'!Z23 | AN40: ='[4]Table-11(a)-O'!AA23 | AO40: ='[4]Table-11(a)-O'!AB23 | AP40: ='[4]Table-11(a)-O'!AC23 | ... BB40: ='[4]Table-11(a)-O'!AO23
A41: ='Crops PY'!$A$5&" - "&'Crops PY'!$B$3 -> RABI I - 0 | N41: ='Crops PY'!$A$5&" - "&'Crops PY'!$B$3 -> RABI I - 0
A42: =N42 -> PADDY(97) | B42: =T42 -> 26.545 | C42: =W42 -> 26.625 | D42: =AO42 -> 7.648 | E42: =AR42 -> 7.543 | F42: =IF($A42="","",B42+D42) -> 34.193 | G42: =IF($A42="","",C42+E42) -> 34.168 | H42: =IF($A42="","",IF(F42=0,0,(G42-F42)*100/F42)) -> -0.07311438 | I42: =IF($A42="","",IF(H42<0,"(-)"&ROUND(ABS(H42),2),ROUND(H42,2))) -> (-)0.07 | N42: ='[5]Table-11(a)'!A9 -> PADDY(97) | O42: ='[5]Table-11(a)'!B9 -> 7 | P42: ='[5]Table-11(a)'!C9 -> 7 | Q42: ='[5]Table-11(a)'!D9 -> 7 | R42: ='[5]Table-11(a)'!E9 -> 26.43 | S42: ='[5]Table-11(a)'!F9 -> 0.115 | T42: ='[5]Table-11(a)'!G9 -> 26.545 | U42: ='[5]Table-11(a)'!H9 -> 26.51 | ... AG42: ='[5]Table-11(a)'!T9 -> 0.35327887 | AI42: ='[5]Table-11(a)'!V9 -> PADDY(97) | AJ42: ='[5]Table-11(a)'!W9 -> 7 | AK42: ='[5]Table-11(a)'!X9 -> 7 | AL42: ='[5]Table-11(a)'!Y9 -> 7 | AM42: ='[5]Table-11(a)'!Z9 -> 7.648 | AN42: ='[5]Table-11(a)'!AA9 -> 0 | AO42: ='[5]Table-11(a)'!AB9 -> 7.648 | AP42: ='[5]Table-11(a)'!AC9 -> 7.543 | ... BB42: ='[5]Table-11(a)'!AO9 -> 1.3729079
A43: =N43 -> OTHERS(99) | B43: =T43 -> 3.295 | C43: =W43 -> 3.025 | D43: =AO43 -> 3.3839 | E43: =AR43 -> 3.3839 | F43: =IF($A43="","",B43+D43) -> 6.6789 | G43: =IF($A43="","",C43+E43) -> 6.4089 | H43: =IF($A43="","",IF(F43=0,0,(G43-F43)*100/F43)) -> -4.0425819 | I43: =IF($A43="","",IF(H43<0,"(-)"&ROUND(ABS(H43),2),ROUND(H43,2))) -> (-)4.04 | N43: ='[5]Table-11(a)'!A10 -> OTHERS(99) | O43: ='[5]Table-11(a)'!B10 -> 3 | P43: ='[5]Table-11(a)'!C10 -> 3 | Q43: ='[5]Table-11(a)'!D10 -> 2 | R43: ='[5]Table-11(a)'!E10 -> 3.295 | S43: ='[5]Table-11(a)'!F10 -> 0 | T43: ='[5]Table-11(a)'!G10 -> 3.295 | U43: ='[5]Table-11(a)'!H10 -> 3.025 | ... AG43: ='[5]Table-11(a)'!T10 -> 0 | AI43: ='[5]Table-11(a)'!V10 -> OTHERS(99) | AJ43: ='[5]Table-11(a)'!W10 -> 3 | AK43: ='[5]Table-11(a)'!X10 -> 3 | AL43: ='[5]Table-11(a)'!Y10 -> 3 | AM43: ='[5]Table-11(a)'!Z10 -> 2.6339 | AN43: ='[5]Table-11(a)'!AA10 -> 0.75 | AO43: ='[5]Table-11(a)'!AB10 -> 3.3839 | AP43: ='[5]Table-11(a)'!AC10 -> 2.6339 | ... BB43: ='[5]Table-11(a)'!AO10 -> 0
A44: =N44 | B44: =T44 | C44: =W44 | D44: =AO44 | E44: =AR44 | F44: =IF($A44="","",B44+D44) | G44: =IF($A44="","",C44+E44) | H44: =IF($A44="","",IF(F44=0,0,(G44-F44)*100/F44)) | I44: =IF($A44="","",IF(H44<0,"(-)"&ROUND(ABS(H44),2),ROUND(H44,2))) | N44: ='[5]Table-11(a)'!A11 | O44: ='[5]Table-11(a)'!B11 | P44: ='[5]Table-11(a)'!C11 | Q44: ='[5]Table-11(a)'!D11 | R44: ='[5]Table-11(a)'!E11 | S44: ='[5]Table-11(a)'!F11 | T44: ='[5]Table-11(a)'!G11 | U44: ='[5]Table-11(a)'!H11 | ... AG44: ='[5]Table-11(a)'!T11 | AI44: ='[5]Table-11(a)'!V11 | AJ44: ='[5]Table-11(a)'!W11 | AK44: ='[5]Table-11(a)'!X11 | AL44: ='[5]Table-11(a)'!Y11 | AM44: ='[5]Table-11(a)'!Z11 | AN44: ='[5]Table-11(a)'!AA11 | AO44: ='[5]Table-11(a)'!AB11 | AP44: ='[5]Table-11(a)'!AC11 | ... BB44: ='[5]Table-11(a)'!AO11
A45: =N45 | B45: =T45 | C45: =W45 | D45: =AO45 | E45: =AR45 | F45: =IF($A45="","",B45+D45) | G45: =IF($A45="","",C45+E45) | H45: =IF($A45="","",IF(F45=0,0,(G45-F45)*100/F45)) | I45: =IF($A45="","",IF(H45<0,"(-)"&ROUND(ABS(H45),2),ROUND(H45,2))) | N45: ='[5]Table-11(a)'!A12 | O45: ='[5]Table-11(a)'!B12 | P45: ='[5]Table-11(a)'!C12 | Q45: ='[5]Table-11(a)'!D12 | R45: ='[5]Table-11(a)'!E12 | S45: ='[5]Table-11(a)'!F12 | T45: ='[5]Table-11(a)'!G12 | U45: ='[5]Table-11(a)'!H12 | ... AG45: ='[5]Table-11(a)'!T12 | AI45: ='[5]Table-11(a)'!V12 | AJ45: ='[5]Table-11(a)'!W12 | AK45: ='[5]Table-11(a)'!X12 | AL45: ='[5]Table-11(a)'!Y12 | AM45: ='[5]Table-11(a)'!Z12 | AN45: ='[5]Table-11(a)'!AA12 | AO45: ='[5]Table-11(a)'!AB12 | AP45: ='[5]Table-11(a)'!AC12 | ... BB45: ='[5]Table-11(a)'!AO12
...

Sheet Annex-10
A2: A-12 | N2: TABLE-11(A):CROPWISE COMPARISON OF ENTRIES BY SUPERVISOR AND PATWARI OF CROP AREAS AS PER IRRIGATION AND SEED VARIETY. | AI2: TABLE-11(A):CROPWISE COMPARISON OF ENTRIES BY SUPERVISOR AND PATWARI OF CROP AREAS AS PER IRRIGATION AND SEED VARIETY.
A3: ="STATE:"& 'Crops CY'!$A$2 -> STATE:PUDUCHERRY | J3: ANNEX-X | N3: STATE: | O3: MAHARASHTRA(27) | S3: YEAR: | U3: 2014-15 | Y3: SEASON: | Z3: KHARIF(1) | AD3: SAMPLE: | AF3: CENTRAL(1) | AI3: STATE: | AJ3: MAHARASHTRA(27) | AN3: YEAR: | AP3: 2014-15 | AT3: SEASON: | AU3: KHARIF(1) | AY3: SAMPLE: | BA3: STATE(2)
A4: ="IMPACT OF DISCREPANCIES IN RECORDING AREA UNDER CROPS(IRRIGATED) DURING"&" "& 'Crops CY'!$B$3 &" AND "& 'Crops PY'!$B$3&"." -> IMPACT OF DISCREPANCIES IN RECORDING AREA UNDER CROPS(IRRIGATED) DURING 0 AND 0. | N4: CROP | O4: NO. OF VILLAGE REPORTING CROP | R4: COMPARISON AS PER IRRIGATION PARTICULARS | X4: COL (8-5)/5 *100 | Y4: COL (10-7)/7 *100 | Z4: COL (10)/7 (0.0000) | AA4: COMPARISON AS PER VARIETY OF SEED | AG4: COL (17-14)/14 *100 | AI4: CROP | AJ4: NO. OF VILLAGE REPORTING CROP | AM4: COMPARISON AS PER IRRIGATION PARTICULARS | AS4: COL (8-5)/5 *100 | AT4: COL (10-7)/7 *100 | AU4: COL (10)/7 (0.0000) | AV4: COMPARISON AS PER VARIETY OF SEED | BB4: COL (17-14)/14 *100
A5: SEASON / CROP | B5: AREA IN HECTARES AS OBSERVED IN SAMPLE CLUSTERS | R5: AREA UNDER CROP (0.00)HA | AA5: AREA UNDER CROP (0.00)HA | AM5: AREA UNDER CROP (0.00)HA | AV5: AREA UNDER CROP (0.00)HA
B6: CENTRAL SAMPLE | E6: STATE SAMPLE | H6: POOLED SAMPLE | L6: IMPACT OF DISCRIPANCIES (b-a/a)*100 (POOLED SAMPLE ONLY) | R6: AS PER SUPERVISOR | U6: AS PER PATWARIES | AA6: AS PER SUPERVISOR | AD6: AS PER PATWARIES | AM6: AS PER SUPERVISOR | AP6: AS PER PATWARIES | AV6: AS PER SUPERVISOR | AY6: AS PER PATWARIES
B7: NO OF VILLAGES REPORTING CROP | C7: AS PER SUPERVISOR | D7: AS PER PATWARI | E7: NO OF VILLAGES REPORTING CROP | F7: AS PER SUPERVISOR | G7: AS PER PATWARI | H7: NO OF VILLAGES REPORTING CROP | I7: AS PER SUPERVISOR | J7: AS PER PATWARI | O7: TOTAL | P7: IRR | Q7: HY | R7: IRR | S7: UN-IRR | T7: TOTAL | U7: IRR | V7: UN-IRR | W7: TOTAL | AA7: HY | AB7: LOCAL | AC7: TOTAL | AD7: HY | AE7: LOCAL | AF7: TOTAL | AJ7: TOTAL | AK7: IRR | AL7: HY | AM7: IRR | AN7: UN-IRR | AO7: TOTAL | AP7: IRR | AQ7: UN-IRR | AR7: TOTAL | AV7: HY | AW7: LOCAL | AX7: TOTAL | AY7: HY | AZ7: LOCAL | BA7: TOTAL
A8: (1) | B8: (2) | C8: (3) | D8: (4) | E8: (5) | F8: (6) | G8: (7) | H8: (8) | I8: (9) | J8: (10) | L8: (11) | N8: 1 | O8: 2 | P8: 3 | Q8: 4 | R8: 5 | S8: 6 | T8: 7 | U8: 8 | V8: 9 | W8: 10 | X8: 11 | Y8: 12 | Z8: 13 | AA8: 14 | AB8: 15 | AC8: 16 | AD8: 17 | AE8: 18 | AF8: 19 | AG8: 20 | AI8: 1 | AJ8: 2 | AK8: 3 | AL8: 4 | AM8: 5 | AN8: 6 | AO8: 7 | AP8: 8 | AQ8: 9 | AR8: 10 | AS8: 11 | AT8: 12 | AU8: 13 | AV8: 14 | AW8: 15 | AX8: 16 | AY8: 17 | AZ8: 18 | BA8: 19 | BB8: 20
A9: ='Crops CY'!$A$5&" - "&'Crops CY'!$B$3 -> RABI I - 0 | N9: ='Crops CY'!$A$5&" - "&'Crops CY'!$B$3 -> RABI I - 0
A10: =N10 -> PADDY(97) | B10: =P10 -> 3 | C10: =R10 -> 4.459 | D10: =U10 -> 4.589 | E10: =AK10 -> 8 | F10: =AM10 -> 15.6192 | G10: =AP10 -> 15.5092 | H10: =IF($A10="","",B10+E10) -> 11 | I10: =IF($A10="","",C10+F10) -> 20.0782 | J10: =IF($A10="","",D10+G10) -> 20.0982 | K10: =IF($A10="","",IF(I10=0,0,(J10-I10)*100/I10)) -> 0.099610523 | L10: =IF($A10="","",IF(K10<0,"(-)"&ROUND(ABS(K10),2),ROUND(K10,2))) -> 0.1 | N10: ='Annex-8'!N10 -> PADDY(97) | O10: ='Annex-8'!O10 -> 3 | P10: ='Annex-8'!P10 -> 3 | Q10: ='Annex-8'!Q10 -> 3 | R10: ='Annex-8'!R10 -> 4.459 | S10: ='Annex-8'!S10 -> 0 | T10: ='Annex-8'!T10 -> 4.459 | U10: ='Annex-8'!U10 -> 4.589 | ... AG10: ='Annex-8'!AG10 -> 2.9154519 | AI10: ='Annex-8'!AI10 -> PADDY(97) | AJ10: ='Annex-8'!AJ10 -> 8 | AK10: ='Annex-8'!AK10 -> 8 | AL10: ='Annex-8'!AL10 -> 8 | AM10: ='Annex-8'!AM10 -> 15.6192 | AN10: ='Annex-8'!AN10 -> 0 | AO10: ='Annex-8'!AO10 -> 15.6192 | AP10: ='Annex-8'!AP10 -> 15.5092 | ... BB10: ='Annex-8'!BB10 -> 0.70426142
A11: =N11 -> OTHERS(99) | B11: =P11 -> 4 | C11: =R11 -> 1.7258 | D11: =U11 -> 2.5908 | E11: =AK11 -> 7 | F11: =AM11 -> 5.7236 | G11: =AP11 -> 5.8236 | H11: =IF($A11="","",B11+E11) -> 11 | I11: =IF($A11="","",C11+F11) -> 7.4494 | J11: =IF($A11="","",D11+G11) -> 8.4144 | K11: =IF($A11="","",IF(I11=0,0,(J11-I11)*100/I11)) -> 12.954063 | L11: =IF($A11="","",IF(K11<0,"(-)"&ROUND(ABS(K11),2),ROUND(K11,2))) -> 12.95 | N11: ='Annex-8'!N11 -> OTHERS(99) | O11: ='Annex-8'!O11 -> 4 | P11: ='Annex-8'!P11 -> 4 | Q11: ='Annex-8'!Q11 -> 4 | R11: ='Annex-8'!R11 -> 1.7258 | S11: ='Annex-8'!S11 -> 0 | T11: ='Annex-8'!T11 -> 1.7258 | U11: ='Annex-8'!U11 -> 2.5908 | ... AG11: ='Annex-8'!AG11 -> 50.266543 | AI11: ='Annex-8'!AI11 -> OTHERS(99) | AJ11: ='Annex-8'!AJ11 -> 7 | AK11: ='Annex-8'!AK11 -> 7 | AL11: ='Annex-8'!AL11 -> 6 | AM11: ='Annex-8'!AM11 -> 5.7236 | AN11: ='Annex-8'!AN11 -> 0.1661 | AO11: ='Annex-8'!AO11 -> 5.8897 | AP11: ='Annex-8'!AP11 -> 5.8236 | ... BB11: ='Annex-8'!BB11 -> 1.7153541
A12: =N12 | B12: =P12 | C12: =R12 | D12: =U12 | E12: =AK12 | F12: =AM12 | G12: =AP12 | H12: =IF($A12="","",B12+E12) | I12: =IF($A12="","",C12+F12) | J12: =IF($A12="","",D12+G12) | K12: =IF($A12="","",IF(I12=0,0,(J12-I12)*100/I12)) | L12: =IF($A12="","",IF(K12<0,"(-)"&ROUND(ABS(K12),2),ROUND(K12,2))) | N12: ='Annex-8'!N12 | O12: ='Annex-8'!O12 | P12: ='Annex-8'!P12 | Q12: ='Annex-8'!Q12 | R12: ='Annex-8'!R12 | S12: ='Annex-8'!S12 | T12: ='Annex-8'!T12 | U12: ='Annex-8'!U12 | ... AG12: ='Annex-8'!AG12 | AI12: ='Annex-8'!AI12 | AJ12: ='Annex-8'!AJ12 | AK12: ='Annex-8'!AK12 | AL12: ='Annex-8'!AL12 | AM12: ='Annex-8'!AM12 | AN12: ='Annex-8'!AN12 | AO12: ='Annex-8'!AO12 | AP12: ='Annex-8'!AP12 | ... BB12: ='Annex-8'!BB12
A13: =N13 | B13: =P13 | C13: =R13 | D13: =U13 | E13: =AK13 | F13: =AM13 | G13: =AP13 | H13: =IF($A13="","",B13+E13) | I13: =IF($A13="","",C13+F13) | J13: =IF($A13="","",D13+G13) | K13: =IF($A13="","",IF(I13=0,0,(J13-I13)*100/I13)) | L13: =IF($A13="","",IF(K13<0,"(-)"&ROUND(ABS(K13),2),ROUND(K13,2))) | N13: ='Annex-8'!N13 | O13: ='Annex-8'!O13 | P13: ='Annex-8'!P13 | Q13: ='Annex-8'!Q13 | R13: ='Annex-8'!R13 | S13: ='Annex-8'!S13 | T13: ='Annex-8'!T13 | U13: ='Annex-8'!U13 | ... AG13: ='Annex-8'!AG13 | AI13: ='Annex-8'!AI13 | AJ13: ='Annex-8'!AJ13 | AK13: ='Annex-8'!AK13 | AL13: ='Annex-8'!AL13 | AM13: ='Annex-8'!AM13 | AN13: ='Annex-8'!AN13 | AO13: ='Annex-8'!AO13 | AP13: ='Annex-8'!AP13 | ... BB13: ='Annex-8'!BB13
A14: =N14 | B14: =P14 | C14: =R14 | D14: =U14 | E14: =AK14 | F14: =AM14 | G14: =AP14 | H14: =IF($A14="","",B14+E14) | I14: =IF($A14="","",C14+F14) | J14: =IF($A14="","",D14+G14) | K14: =IF($A14="","",IF(I14=0,0,(J14-I14)*100/I14)) | L14: =IF($A14="","",IF(K14<0,"(-)"&ROUND(ABS(K14),2),ROUND(K14,2))) | N14: ='Annex-8'!N14 | O14: ='Annex-8'!O14 | P14: ='Annex-8'!P14 | Q14: ='Annex-8'!Q14 | R14: ='Annex-8'!R14 | S14: ='Annex-8'!S14 | T14: ='Annex-8'!T14 | U14: ='Annex-8'!U14 | ... AG14: ='Annex-8'!AG14 | AI14: ='Annex-8'!AI14 | AJ14: ='Annex-8'!AJ14 | AK14: ='Annex-8'!AK14 | AL14: ='Annex-8'!AL14 | AM14: ='Annex-8'!AM14 | AN14: ='Annex-8'!AN14 | AO14: ='Annex-8'!AO14 | AP14: ='Annex-8'!AP14 | ... BB14: ='Annex-8'!BB14
A15: =N15 | B15: =P15 | C15: =R15 | D15: =U15 | E15: =AK15 | F15: =AM15 | G15: =AP15 | H15: =IF($A15="","",B15+E15) | I15: =IF($A15="","",C15+F15) | J15: =IF($A15="","",D15+G15) | K15: =IF($A15="","",IF(I15=0,0,(J15-I15)*100/I15)) | L15: =IF($A15="","",IF(K15<0,"(-)"&ROUND(ABS(K15),2),ROUND(K15,2))) | N15: ='Annex-8'!N15 | O15: ='Annex-8'!O15 | P15: ='Annex-8'!P15 | Q15: ='Annex-8'!Q15 | R15: ='Annex-8'!R15 | S15: ='Annex-8'!S15 | T15: ='Annex-8'!T15 | U15: ='Annex-8'!U15 | ... AG15: ='Annex-8'!AG15 | AI15: ='Annex-8'!AI15 | AJ15: ='Annex-8'!AJ15 | AK15: ='Annex-8'!AK15 | AL15: ='Annex-8'!AL15 | AM15: ='Annex-8'!AM15 | AN15: ='Annex-8'!AN15 | AO15: ='Annex-8'!AO15 | AP15: ='Annex-8'!AP15 | ... BB15: ='Annex-8'!BB15
A16: =N16 | B16: =P16 | C16: =R16 | D16: =U16 | E16: =AK16 | F16: =AM16 | G16: =AP16 | H16: =IF($A16="","",B16+E16) | I16: =IF($A16="","",C16+F16) | J16: =IF($A16="","",D16+G16) | K16: =IF($A16="","",IF(I16=0,0,(J16-I16)*100/I16)) | L16: =IF($A16="","",IF(K16<0,"(-)"&ROUND(ABS(K16),2),ROUND(K16,2))) | N16: ='Annex-8'!N16 | O16: ='Annex-8'!O16 | P16: ='Annex-8'!P16 | Q16: ='Annex-8'!Q16 | R16: ='Annex-8'!R16 | S16: ='Annex-8'!S16 | T16: ='Annex-8'!T16 | U16: ='Annex-8'!U16 | ... AG16: ='Annex-8'!AG16 | AI16: ='Annex-8'!AI16 | AJ16: ='Annex-8'!AJ16 | AK16: ='Annex-8'!AK16 | AL16: ='Annex-8'!AL16 | AM16: ='Annex-8'!AM16 | AN16: ='Annex-8'!AN16 | AO16: ='Annex-8'!AO16 | AP16: ='Annex-8'!AP16 | ... BB16: ='Annex-8'!BB16
A17: =N17 | B17: =P17 | C17: =R17 | D17: =U17 | E17: =AK17 | F17: =AM17 | G17: =AP17 | H17: =IF($A17="","",B17+E17) | I17: =IF($A17="","",C17+F17) | J17: =IF($A17="","",D17+G17) | K17: =IF($A17="","",IF(I17=0,0,(J17-I17)*100/I17)) | L17: =IF($A17="","",IF(K17<0,"(-)"&ROUND(ABS(K17),2),ROUND(K17,2))) | N17: ='Annex-8'!N17 | O17: ='Annex-8'!O17 | P17: ='Annex-8'!P17 | Q17: ='Annex-8'!Q17 | R17: ='Annex-8'!R17 | S17: ='Annex-8'!S17 | T17: ='Annex-8'!T17 | U17: ='Annex-8'!U17 | ... AG17: ='Annex-8'!AG17 | AI17: ='Annex-8'!AI17 | AJ17: ='Annex-8'!AJ17 | AK17: ='Annex-8'!AK17 | AL17: ='Annex-8'!AL17 | AM17: ='Annex-8'!AM17 | AN17: ='Annex-8'!AN17 | AO17: ='Annex-8'!AO17 | AP17: ='Annex-8'!AP17 | ... BB17: ='Annex-8'!BB17
A18: =N18 | B18: =P18 | C18: =R18 | D18: =U18 | E18: =AK18 | F18: =AM18 | G18: =AP18 | H18: =IF($A18="","",B18+E18) | I18: =IF($A18="","",C18+F18) | J18: =IF($A18="","",D18+G18) | K18: =IF($A18="","",IF(I18=0,0,(J18-I18)*100/I18)) | L18: =IF($A18="","",IF(K18<0,"(-)"&ROUND(ABS(K18),2),ROUND(K18,2))) | N18: ='Annex-8'!N18 | O18: ='Annex-8'!O18 | P18: ='Annex-8'!P18 | Q18: ='Annex-8'!Q18 | R18: ='Annex-8'!R18 | S18: ='Annex-8'!S18 | T18: ='Annex-8'!T18 | U18: ='Annex-8'!U18 | ... AG18: ='Annex-8'!AG18 | AI18: ='Annex-8'!AI18 | AJ18: ='Annex-8'!AJ18 | AK18: ='Annex-8'!AK18 | AL18: ='Annex-8'!AL18 | AM18: ='Annex-8'!AM18 | AN18: ='Annex-8'!AN18 | AO18: ='Annex-8'!AO18 | AP18: ='Annex-8'!AP18 | ... BB18: ='Annex-8'!BB18
A19: =N19 | B19: =P19 | C19: =R19 | D19: =U19 | E19: =AK19 | F19: =AM19 | G19: =AP19 | H19: =IF($A19="","",B19+E19) | I19: =IF($A19="","",C19+F19) | J19: =IF($A19="","",D19+G19) | K19: =IF($A19="","",IF(I19=0,0,(J19-I19)*100/I19)) | L19: =IF($A19="","",IF(K19<0,"(-)"&ROUND(ABS(K19),2),ROUND(K19,2))) | N19: ='Annex-8'!N19 | O19: ='Annex-8'!O19 | P19: ='Annex-8'!P19 | Q19: ='Annex-8'!Q19 | R19: ='Annex-8'!R19 | S19: ='Annex-8'!S19 | T19: ='Annex-8'!T19 | U19: ='Annex-8'!U19 | ... AG19: ='Annex-8'!AG19 | AI19: ='Annex-8'!AI19 | AJ19: ='Annex-8'!AJ19 | AK19: ='Annex-8'!AK19 | AL19: ='Annex-8'!AL19 | AM19: ='Annex-8'!AM19 | AN19: ='Annex-8'!AN19 | AO19: ='Annex-8'!AO19 | AP19: ='Annex-8'!AP19 | ... BB19: ='Annex-8'!BB19
A20: =N20 | B20: =P20 | C20: =R20 | D20: =U20 | E20: =AK20 | F20: =AM20 | G20: =AP20 | H20: =IF($A20="","",B20+E20) | I20: =IF($A20="","",C20+F20) | J20: =IF($A20="","",D20+G20) | K20: =IF($A20="","",IF(I20=0,0,(J20-I20)*100/I20)) | L20: =IF($A20="","",IF(K20<0,"(-)"&ROUND(ABS(K20),2),ROUND(K20,2))) | N20: ='Annex-8'!N20 | O20: ='Annex-8'!O20 | P20: ='Annex-8'!P20 | Q20: ='Annex-8'!Q20 | R20: ='Annex-8'!R20 | S20: ='Annex-8'!S20 | T20: ='Annex-8'!T20 | U20: ='Annex-8'!U20 | ... AG20: ='Annex-8'!AG20 | AI20: ='Annex-8'!AI20 | AJ20: ='Annex-8'!AJ20 | AK20: ='Annex-8'!AK20 | AL20: ='Annex-8'!AL20 | AM20: ='Annex-8'!AM20 | AN20: ='Annex-8'!AN20 | AO20: ='Annex-8'!AO20 | AP20: ='Annex-8'!AP20 | ... BB20: ='Annex-8'!BB20
A21: =N21 | B21: =P21 | C21: =R21 | D21: =U21 | E21: =AK21 | F21: =AM21 | G21: =AP21 | H21: =IF($A21="","",B21+E21) | I21: =IF($A21="","",C21+F21) | J21: =IF($A21="","",D21+G21) | K21: =IF($A21="","",IF(I21=0,0,(J21-I21)*100/I21)) | L21: =IF($A21="","",IF(K21<0,"(-)"&ROUND(ABS(K21),2),ROUND(K21,2))) | N21: ='Annex-8'!N21 | O21: ='Annex-8'!O21 | P21: ='Annex-8'!P21 | Q21: ='Annex-8'!Q21 | R21: ='Annex-8'!R21 | S21: ='Annex-8'!S21 | T21: ='Annex-8'!T21 | U21: ='Annex-8'!U21 | ... AG21: ='Annex-8'!AG21 | AI21: ='Annex-8'!AI21 | AJ21: ='Annex-8'!AJ21 | AK21: ='Annex-8'!AK21 | AL21: ='Annex-8'!AL21 | AM21: ='Annex-8'!AM21 | AN21: ='Annex-8'!AN21 | AO21: ='Annex-8'!AO21 | AP21: ='Annex-8'!AP21 | ... BB21: ='Annex-8'!BB21
... A24: =N24 | B24: =P24 | C24: =R24 | D24: =U24 | E24: =AK24 | F24: =AM24 | G24: =AP24 | H24: =IF($A24="","",B24+E24) | I24: =IF($A24="","",C24+F24) | J24: =IF($A24="","",D24+G24) | K24: =IF($A24="","",IF(I24=0,0,(J24-I24)*100/I24)) | L24: =IF($A24="","",IF(K24<0,"(-)"&ROUND(ABS(K24),2),ROUND(K24,2))) | N24: ='Annex-8'!N24 | O24: ='Annex-8'!O24 | P24: ='Annex-8'!P24 | Q24: ='Annex-8'!Q24 | R24: ='Annex-8'!R24 | S24: ='Annex-8'!S24 | T24: ='Annex-8'!T24 | U24: ='Annex-8'!U24 | ... AG24: ='Annex-8'!AG24 | AI24: ='Annex-8'!AI24 | AJ24: ='Annex-8'!AJ24 | AK24: ='Annex-8'!AK24 | AL24: ='Annex-8'!AL24 | AM24: ='Annex-8'!AM24 | AN24: ='Annex-8'!AN24 | AO24: ='Annex-8'!AO24 | AP24: ='Annex-8'!AP24 | ... BB24: ='Annex-8'!BB24
A25: ='Crops CY'!$C$5&" - "&'Crops CY'!$B$3 -> RABI II - 0 | N25: ='Crops CY'!$C$5&" - "&'Crops CY'!$B$3 -> RABI II - 0
A26: =N26 -> PADDY(98) | B26: =P26 -> 1 | C26: =R26 -> 0.025 | D26: =U26 -> 0.025 | E26: =AK26 -> 5 | F26: =AM26 -> 8.785 | G26: =AP26 -> 8.6 | H26: =IF($A26="","",B26+E26) -> 6 | I26: =IF($A26="","",C26+F26) -> 8.81 | J26: =IF($A26="","",D26+G26) -> 8.625 | K26: =IF($A26="","",IF(I26=0,0,(J26-I26)*100/I26)) -> -2.0998865 | L26: =IF($A26="","",IF(K26<0,"(-)"&ROUND(ABS(K26),2),ROUND(K26,2))) -> (-)2.1 | N26: ='Annex-8'!N26 -> PADDY(98) | O26: ='Annex-8'!O26 -> 1 | P26: ='Annex-8'!P26 -> 1 | Q26: ='Annex-8'!Q26 -> 1 | R26: ='Annex-8'!R26 -> 0.025 | S26: ='Annex-8'!S26 -> 0 | T26: ='Annex-8'!T26 -> 0.025 | U26: ='Annex-8'!U26 -> 0.025 | ... AG26: ='Annex-8'!AG26 -> 0 | AI26: ='Annex-8'!AI26 -> PADDY(98) | AJ26: ='Annex-8'!AJ26 -> 5 | AK26: ='Annex-8'!AK26 -> 5 | AL26: ='Annex-8'!AL26 -> 5 | AM26: ='Annex-8'!AM26 -> 8.785 | AN26: ='Annex-8'!AN26 -> 0 | AO26: ='Annex-8'!AO26 -> 8.785 | AP26: ='Annex-8'!AP26 -> 8.6 | ... BB26: ='Annex-8'!BB26 -> 2.1058623
A27: =N27 -> OTHERS(99) | B27: =P27 -> 4 | C27: =R27 -> 1.77 | D27: =U27 -> 2.615 | E27: =AK27 -> 7 | F27: =AM27 -> 3.5894 | G27: =AP27 -> 3.5894 | H27: =IF($A27="","",B27+E27) -> 11 | I27: =IF($A27="","",C27+F27) -> 5.3594 | J27: =IF($A27="","",D27+G27) -> 6.2044 | K27: =IF($A27="","",IF(I27=0,0,(J27-I27)*100/I27)) -> 15.76669 | L27: =IF($A27="","",IF(K27<0,"(-)"&ROUND(ABS(K27),2),ROUND(K27,2))) -> 15.77 | N27: ='Annex-8'!N27 -> OTHERS(99) | O27: ='Annex-8'!O27 -> 4 | P27: ='Annex-8'!P27 -> 4 | Q27: ='Annex-8'!Q27 -> 4 | R27: ='Annex-8'!R27 -> 1.77 | S27: ='Annex-8'!S27 -> 0 | T27: ='Annex-8'!T27 -> 1.77 | U27: ='Annex-8'!U27 -> 2.615 | ... AG27: ='Annex-8'!AG27 -> 47.881356 | AI27: ='Annex-8'!AI27 -> OTHERS(99) | AJ27: ='Annex-8'!AJ27 -> 7 | AK27: ='Annex-8'!AK27 -> 7 | AL27: ='Annex-8'!AL27 -> 6 | AM27: ='Annex-8'!AM27 -> 3.5894 | AN27: ='Annex-8'!AN27 -> 0.9049 | AO27: ='Annex-8'!AO27 -> 4.4943 | AP27: ='Annex-8'!AP27 -> 3.5894 | ... BB27: ='Annex-8'!BB27 -> 0
A28: =N28 | B28: =P28 | C28: =R28 | D28: =U28 | E28: =AK28 | F28: =AM28 | G28: =AP28 | H28: =IF($A28="","",B28+E28) | I28: =IF($A28="","",C28+F28) | J28: =IF($A28="","",D28+G28) | K28: =IF($A28="","",IF(I28=0,0,(J28-I28)*100/I28)) | L28: =IF($A28="","",IF(K28<0,"(-)"&ROUND(ABS(K28),2),ROUND(K28,2))) | N28: ='Annex-8'!N28 | O28: ='Annex-8'!O28 | P28: ='Annex-8'!P28 | Q28: ='Annex-8'!Q28 | R28: ='Annex-8'!R28 | S28: ='Annex-8'!S28 | T28: ='Annex-8'!T28 | U28: ='Annex-8'!U28 | ... AG28: ='Annex-8'!AG28 | AI28: ='Annex-8'!AI28 | AJ28: ='Annex-8'!AJ28 | AK28: ='Annex-8'!AK28 | AL28: ='Annex-8'!AL28 | AM28: ='Annex-8'!AM28 | AN28: ='Annex-8'!AN28 | AO28: ='Annex-8'!AO28 | AP28: ='Annex-8'!AP28 | ... BB28: ='Annex-8'!BB28
A29: =N29 | B29: =P29 | C29: =R29 | D29: =U29 | E29: =AK29 | F29: =AM29 | G29: =AP29 | H29: =IF($A29="","",B29+E29) | I29: =IF($A29="","",C29+F29) | J29: =IF($A29="","",D29+G29) | K29: =IF($A29="","",IF(I29=0,0,(J29-I29)*100/I29)) | L29: =IF($A29="","",IF(K29<0,"(-)"&ROUND(ABS(K29),2),ROUND(K29,2))) | N29: ='Annex-8'!N29 | O29: ='Annex-8'!O29 | P29: ='Annex-8'!P29 | Q29: ='Annex-8'!Q29 | R29: ='Annex-8'!R29 | S29: ='Annex-8'!S29 | T29: ='Annex-8'!T29 | U29: ='Annex-8'!U29 | ... AG29: ='Annex-8'!AG29 | AI29: ='Annex-8'!AI29 | AJ29: ='Annex-8'!AJ29 | AK29: ='Annex-8'!AK29 | AL29: ='Annex-8'!AL29 | AM29: ='Annex-8'!AM29 | AN29: ='Annex-8'!AN29 | AO29: ='Annex-8'!AO29 | AP29: ='Annex-8'!AP29 | ... BB29: ='Annex-8'!BB29
A30: =N30 | B30: =P30 | C30: =R30 | D30: =U30 | E30: =AK30 | F30: =AM30 | G30: =AP30 | H30: =IF($A30="","",B30+E30) | I30: =IF($A30="","",C30+F30) | J30: =IF($A30="","",D30+G30) | K30: =IF($A30="","",IF(I30=0,0,(J30-I30)*100/I30)) | L30: =IF($A30="","",IF(K30<0,"(-)"&ROUND(ABS(K30),2),ROUND(K30,2))) | N30: ='Annex-8'!N30 | O30: ='Annex-8'!O30 | P30: ='Annex-8'!P30 | Q30: ='Annex-8'!Q30 | R30: ='Annex-8'!R30 | S30: ='Annex-8'!S30 | T30: ='Annex-8'!T30 | U30: ='Annex-8'!U30 | ... AG30: ='Annex-8'!AG30 | AI30: ='Annex-8'!AI30 | AJ30: ='Annex-8'!AJ30 | AK30: ='Annex-8'!AK30 | AL30: ='Annex-8'!AL30 | AM30: ='Annex-8'!AM30 | AN30: ='Annex-8'!AN30 | AO30: ='Annex-8'!AO30 | AP30: ='Annex-8'!AP30 | ... BB30: ='Annex-8'!BB30
A31: =N31 | B31: =P31 | C31: =R31 | D31: =U31 | E31: =AK31 | F31: =AM31 | G31: =AP31 | H31: =IF($A31="","",B31+E31) | I31: =IF($A31="","",C31+F31) | J31: =IF($A31="","",D31+G31) | K31: =IF($A31="","",IF(I31=0,0,(J31-I31)*100/I31)) | L31: =IF($A31="","",IF(K31<0,"(-)"&ROUND(ABS(K31),2),ROUND(K31,2))) | N31: ='Annex-8'!N31 | O31: ='Annex-8'!O31 | P31: ='Annex-8'!P31 | Q31: ='Annex-8'!Q31 | R31: ='Annex-8'!R31 | S31: ='Annex-8'!S31 | T31: ='Annex-8'!T31 | U31: ='Annex-8'!U31 | ... AG31: ='Annex-8'!AG31 | AI31: ='Annex-8'!AI31 | AJ31: ='Annex-8'!AJ31 | AK31: ='Annex-8'!AK31 | AL31: ='Annex-8'!AL31 | AM31: ='Annex-8'!AM31 | AN31: ='Annex-8'!AN31 | AO31: ='Annex-8'!AO31 | AP31: ='Annex-8'!AP31 | ... BB31: ='Annex-8'!BB31
A32: =N32 | B32: =P32 | C32: =R32 | D32: =U32 | E32: =AK32 | F32: =AM32 | G32: =AP32 | H32: =IF($A32="","",B32+E32) | I32: =IF($A32="","",C32+F32) | J32: =IF($A32="","",D32+G32) | K32: =IF($A32="","",IF(I32=0,0,(J32-I32)*100/I32)) | L32: =IF($A32="","",IF(K32<0,"(-)"&ROUND(ABS(K32),2),ROUND(K32,2))) | N32: ='Annex-8'!N32 | O32: ='Annex-8'!O32 | P32: ='Annex-8'!P32 | Q32: ='Annex-8'!Q32 | R32: ='Annex-8'!R32 | S32: ='Annex-8'!S32 | T32: ='Annex-8'!T32 | U32: ='Annex-8'!U32 | ... AG32: ='Annex-8'!AG32 | AI32: ='Annex-8'!AI32 | AJ32: ='Annex-8'!AJ32 | AK32: ='Annex-8'!AK32 | AL32: ='Annex-8'!AL32 | AM32: ='Annex-8'!AM32 | AN32: ='Annex-8'!AN32 | AO32: ='Annex-8'!AO32 | AP32: ='Annex-8'!AP32 | ... BB32: ='Annex-8'!BB32
A33: =N33 | B33: =P33 | C33: =R33 | D33: =U33 | E33: =AK33 | F33: =AM33 | G33: =AP33 | H33: =IF($A33="","",B33+E33) | I33: =IF($A33="","",C33+F33) | J33: =IF($A33="","",D33+G33) | K33: =IF($A33="","",IF(I33=0,0,(J33-I33)*100/I33)) | L33: =IF($A33="","",IF(K33<0,"(-)"&ROUND(ABS(K33),2),ROUND(K33,2))) | N33: ='Annex-8'!N33 | O33: ='Annex-8'!O33 | P33: ='Annex-8'!P33 | Q33: ='Annex-8'!Q33 | R33: ='Annex-8'!R33 | S33: ='Annex-8'!S33 | T33: ='Annex-8'!T33 | U33: ='Annex-8'!U33 | ... AG33: ='Annex-8'!AG33 | AI33: ='Annex-8'!AI33 | AJ33: ='Annex-8'!AJ33 | AK33: ='Annex-8'!AK33 | AL33: ='Annex-8'!AL33 | AM33: ='Annex-8'!AM33 | AN33: ='Annex-8'!AN33 | AO33: ='Annex-8'!AO33 | AP33: ='Annex-8'!AP33 | ... BB33: ='Annex-8'!BB33
A34: =N34 | B34: =P34 | C34: =R34 | D34: =U34 | E34: =AK34 | F34: =AM34 | G34: =AP34 | H34: =IF($A34="","",B34+E34) | I34: =IF($A34="","",C34+F34) | J34: =IF($A34="","",D34+G34) | K34: =IF($A34="","",IF(I34=0,0,(J34-I34)*100/I34)) | L34: =IF($A34="","",IF(K34<0,"(-)"&ROUND(ABS(K34),2),ROUND(K34,2))) | N34: ='Annex-8'!N34 | O34: ='Annex-8'!O34 | P34: ='Annex-8'!P34 | Q34: ='Annex-8'!Q34 | R34: ='Annex-8'!R34 | S34: ='Annex-8'!S34 | T34: ='Annex-8'!T34 | U34: ='Annex-8'!U34 | ... AG34: ='Annex-8'!AG34 | AI34: ='Annex-8'!AI34 | AJ34: ='Annex-8'!AJ34 | AK34: ='Annex-8'!AK34 | AL34: ='Annex-8'!AL34 | AM34: ='Annex-8'!AM34 | AN34: ='Annex-8'!AN34 | AO34: ='Annex-8'!AO34 | AP34: ='Annex-8'!AP34 | ... BB34: ='Annex-8'!BB34
