Workbook

Sheet year
B2: UT | C2: PUDUCHERRY | H2: =CONCATENATE(B2," : ",C2) -> UT : PUDUCHERRY
B3: SEASON | C3: RABI I | D3: 4 | E3: RABI II | F3: 5 | H3: =CONCATENATE(B3," : ",C3) -> SEASON : RABI I | I3: =CONCATENATE(B3," : ",E3) -> SEASON : RABI II
B4: YEAR | C4: 2023-24 | H4: =CONCATENATE($C$3," ",C4) -> RABI I 2023-24 | I4: =CONCATENATE($E$3," ",C4) -> RABI II 2023-24 | J4: =CONCATENATE($B$4," ",C4) -> YEAR 2023-24
B5: PREV. YEAR | C5: =CONCATENATE(LEFT(C4,4)-1,"-",RIGHT(C4,2)-1) -> 2022-23 | H5: =CONCATENATE($C$3," ",C5) -> RABI I 2022-23 | I5: =CONCATENATE($E$3," ",C5) -> RABI II 2022-23 | J5: =CONCATENATE($B$4," ",C5) -> YEAR 2022-23
C6: =CONCATENATE(LEFT(C5,4)-1,"-",RIGHT(C5,2)-1) -> 2021-22 | H6: =CONCATENATE($C$3," ",C6) -> RABI I 2021-22 | I6: =CONCATENATE($E$3," ",C6) -> RABI II 2021-22 | J6: =CONCATENATE($B$4," ",C6) -> YEAR 2021-22
C7: =CONCATENATE(LEFT(C6,4)-1,"-",RIGHT(C6,2)-1) -> 2020-21 | H7: =CONCATENATE($C$3," ",C7) -> RABI I 2020-21 | I7: =CONCATENATE($E$3," ",C7) -> RABI II 2020-21 | J7: =CONCATENATE($B$4," ",C7) -> YEAR 2020-21
C8: =CONCATENATE(LEFT(C7,4)-1,"-",RIGHT(C7,2)-1) -> 2019-20 | H8: =CONCATENATE($C$3," ",C8) -> RABI I 2019-20 | I8: =CONCATENATE($E$3," ",C8) -> RABI II 2019-20 | J8: =CONCATENATE($B$4," ",C8) -> YEAR 2019-20
B9: CROP | C9: PADDY | D9: 97 | E9: PADDY | F9: 98
C10: OTHERS | D10: 99 | E10: OTHERS | F10: 99
C11: 0 | D11: 0 | E11: 0 | F11: 0
C12: 0 | D12: 0 | E12: 0 | F12: 0
C13: 0 | D13: 0 | E13: 0 | F13: 0
C14: 0 | D14: 0 | E14: 0 | F14: 0
C15: 0 | D15: 0 | E15: 0 | F15: 0
C16: 0 | D16: 0 | E16: 0 | F16: 0
C17: 0 | D17: 0 | E17: 0 | F17: 0
C18: 0 | D18: 0 | E18: 0 | F18: 0

Sheet Annex-I
A1: A-1
A2: =year!$H$2 -> UT : PUDUCHERRY | G2: ANNEX-I
A3: RESPONSE IN SAMPLE CHECK ON ENUMERATION OF AREA DURING 2023-24 AND 2022-23.
A4: YEAR/ SEASON/ AGENCY | B4: NO.OF VILLAGES PLANNED | C4: NO. ( % ) OF VILLAGES FOR WHICH SCHEDULES WERE RECEIVED | E4: NO. ( % ) OF SCHEDULES ANALYSED
E5: TOTAL | F5: WITH 'a' & 'b' ENTRIES TOGETHER | G5: WITH 'a' & 'b' ENTRIES SEPARATELY | H5: WITH 'a' ENTRIES ONLY
C6: TOTAL RECEIVED | D6: BY CUT OFF DATE
A7: (1) | B7: (2) | C7: (3) | D7: (4) | E7: (5) | F7: (6) | G7: (7) | H7: (8)
A8: =year!$H$4 -> RABI I 2023-24
A9: CENTRAL | B9: 9 | C9: 9(100.0) | D9: 9(100.0) | E9: 9(100.0) | F9: 9(100.0) | G9: 0( 0.0) | H9: 0( 0.0)
A10: STATE | B10: 9 | C10: 9(100.0) | D10: 9(100.0) | E10: 9(100.0) | F10: 9(100.0) | G10: 0( 0.0) | H10: 0( 0.0)
A11: POOLED | B11: 18 | C11: 18(100.0) | D11: 18(100.0) | E11: 18(100.0) | F11: 18(100.0) | G11: 0( 0.0) | H11: 0( 0.0)
A12: =year!$I$4 -> RABI II 2023-24
A13: CENTRAL | B13: 9 | C13: 9(100.0) | D13: 9(100.0) | E13: 9(100.0) | F13: 9(100.0) | G13: 0( 0.0) | H13: 0( 0.0)
A14: STATE | B14: 9 | C14: 9(100.0) | D14: 9(100.0) | E14: 9(100.0) | F14: 9(100.0) | G14: 0( 0.0) | H14: 0( 0.0)
A15: POOLED | B15: 18 | C15: 18(100.0) | D15: 18(100.0) | E15: 18(100.0) | F15: 18(100.0) | G15: 0( 0.0) | H15: 0( 0.0)
A16: =year!$H$5 -> RABI I 2022-23
A17: CENTRAL | B17: 9 | C17: 9(100.0) | D17: 9(100.0) | E17: 9(100.0) | F17: 9(100.0) | G17: 0( 0.0) | H17: 0( 0.0)
A18: STATE | B18: 9 | C18: 9(100.0) | D18: 9(100.0) | E18: 9(100.0) | F18: 9(100.0) | G18: 0( 0.0) | H18: 0( 0.0)
A19: POOLED | B19: 18 | C19: 18(100.0) | D19: 18(100.0) | E19: 18(100.0) | F19: 18(100.0) | G19: 0( 0.0) | H19: 0( 0.0)
A20: =year!$I$5 -> RABI II 2022-23
A21: CENTRAL | B21: 9 | C21: 9(100.0) | D21: 9(100.0) | E21: 9(100.0) | F21: 9(100.0) | G21: 0( 0.0) | H21: 0( 0.0)
A22: STATE | B22: 9 | C22: 9(100.0) | D22: 9(100.0) | E22: 9(100.0) | F22: 9(100.0) | G22: 0( 0.0) | H22: 0( 0.0)
A23: POOLED | B23: 18 | C23: 18(100.0) | D23: 18(100.0) | E23: 18(100.0) | F23: 18(100.0) | G23: 0( 0.0) | H23: 0( 0.0)

Sheet Annex-II
A1: A-2
A2: =year!$H$2 -> UT : PUDUCHERRY | C2: ANNEX-II
A3: INFORMATION REGARDING UPDATING OF VILLAGE MAPS AND THEIR USABILITY DURING 2023-24 AND 2022-23.
A4: NUMBER OF YEARS SINCE UPDATED | B4: NUMBER AND PERCENTAGE OF VILLAGES
B5: =year!$C$4 -> 2023-24 | C5: =year!$C$5 -> 2022-23
A6: (A) 1 TO 5 | B6: 0( 0.0) | C6: 0( 0.0)
A7: (B) 6 TO 10 | B7: 0( 0.0) | C7: 0( 0.0)
A8: (C) 11 TO 20 | B8: 0( 0.0) | C8: 0( 0.0)
A9: (D) MORE THAN 20 YEARS | B9: 17( 94.4) | C9: 18(100.0)
A10: (E) INFORMATION NOT AVAILABLE | B10: 1( 5.6) | C10: 0( 0.0)
A11: AVAILABILITY OF MAPS WITH PATWARI
A12: (A) MAPS AVAILABLE | B12: 18(100.0) | C12: 18(100.0)
A13: (I) USABLE MAPS | B13: 18(100.0) | C13: 18(100.0)
A14: (II) UNUSABLE MAPS | B14: 0( 0.0) | C14: 0( 0.0)
A15: (B) MAPS NOT AVAILABLE | B15: 0( 0.0) | C15: 0( 0.0)
A16: FIGURES IN () INDICATES %AGE TO NO. OF VILLAGES ANALYSED.

Sheet Annex-III
A1: A-3
A2: =year!$H$2 -> UT : PUDUCHERRY | B2: =year!$H$2 -> UT : PUDUCHERRY | C2: =year!$H$2 -> UT : PUDUCHERRY | D2: =year!$H$2 -> UT : PUDUCHERRY | E2: ANNEX-III
A3: WORK LOAD OF PATWARI DURING 2023-24 AND 2022-23.
A4: YEAR | B4: NO. OF VILLAGES | D4: SURVEY/ SUB-SURVEY NUMBERS PER VILLAGES | E4: GEOGRAPHICAL AREA (HA) PER VILLAGES
B5: TOTAL | C5: TRS (NO. AND % TO TOTAL)
A6: (1) | B6: (2) | C6: (3) | D6: (4) | E6: (5)
A7: =year!$C$4 -> 2023-24 | B7: 10.2 | C7: 1.8( 17.6) | D7: 1231 | E7: 392.6
A8: =year!$C$5 -> 2022-23 | B8: 8.8 | C8: 1.7( 19.3) | D8: 1095 | E8: 322.1

Sheet Annex-IV(a)
A1: A-4
A2: =year!$H$2 -> UT : PUDUCHERRY | B2: =year!$H$2 -> UT : PUDUCHERRY | C2: =year!$H$2 -> UT : PUDUCHERRY | D2: =year!$H$2 -> UT : PUDUCHERRY | E2: =year!$H$2 -> UT : PUDUCHERRY | F2: =year!$H$2 -> UT : PUDUCHERRY | G2: ANNEX-IV(a)
A3: NUMBER AND PERCENTAGE OF PATWARIS OF THE SELECTED VILLAGES ACCORDING TO THE TOTAL NUMBER OF VILLAGES ALLOTED DURING 2023-24 AND 2022-23.
A4: TOTAL | F4: TRS
A5: SL NO. | B5: TOTAL NO OF VILLAGES ALLOTED PER PATWARI | C5: FREQUENCY | D5: PERCENTAGE | F5: TOTAL NO OF VILLAGES ALLOTED PER PATWARI | G5: FREQUENCY | H5: PERCENTAGE
A6: (1) | B6: (2) | C6: (3) | D6: (4) | F6: (5) | G6: (6) | H6: (7)
A7: =year!$J$4 -> YEAR 2023-24
A8: 1 | B8: 1 TO 5 | C8: 0 | D8: 0.0 | F8: 1 | G8: 4 | H8: 22.2
A9: 2 | B9: 6 TO 10 | C9: 12 | D9: 66.7 | F9: 2 | G9: 14 | H9: 77.8
A10: 3 | B10: 11 TO 15 | C10: 6 | D10: 33.3 | F10: 3 | G10: 0 | H10: 0.0
A11: 4 | B11: ABOVE 15 | C11: 0 | D11: 0.0 | F11: GREATER THAN 3 | G11: 0 | H11: 0.0
A12: 5 | B12: I.N.A. | C12: 0 | D12: 0.0 | F12: No TRS | G12: 0 | H12: 0.0
F13: I.N.A. | G13: 0 | H13: 0.0
A14: TOTAL | C14: 18 | D14: 100.0 | F14: TOTAL | G14: 18 | H14: 100.0
A15: =year!$J$5 -> YEAR 2022-23
A16: 1 | B16: 1 TO 5 | C16: 3 | D16: 16.7 | F16: 1 | G16: 7 | H16: 38.9
A17: 2 | B17: 6 TO 10 | C17: 10 | D17: 55.5 | F17: 2 | G17: 10 | H17: 55.5
A18: 3 | B18: 11 TO 15 | C18: 5 | D18: 27.8 | F18: 3 | G18: 1 | H18: 5.6
A19: 4 | B19: ABOVE 15 | C19: 0 | D19: 0.0 | F19: GREATER THAN 3 | G19: 0 | H19: 0.0
A20: 5 | B20: I.N.A. | C20: 0 | D20: 0.0 | F20: No TRS | G20: 0 | H20: 0.0
F21: I.N.A. | G21: 0 | H21: 0.0
A22: TOTAL | C22: 18 | D22: 100.0 | F22: TOTAL | G22: 18 | H22: 100.0
A23: I.N.A. : INFORMATION NOT AVAILABLE

Sheet Annex-IV(b)
A1: A-5
A2: =year!$H$2 -> UT : PUDUCHERRY | G2: ANNEX-IV(b)
A3: DISTRIBUTION OF SAMPLE VILLAGES ACCORDING TO SL./SUB.SURVEY NOS. AND GEOGRAPHICAL AREA DURING 2023-24 AND 2022-23
A4: SL. NO. | B4: DISTRIBUTION OF VILLAGES ACCORDING TO SL./SUB-SURVEY NOS. | F4: DISTRIBUTION OF VILLAGES ACCORDING TO GEOGRAPHICAL AREA
B5: CLASS INT. (SL. / SUB SURVEY NOS.) | C5: NO. OF VILLAGES/ MOUZAS | D5: (%) 0.00 | F5: CLASS INT. (GEOGRAPHICAL AREA IN HA) | G5: NO. OF VILLAGES | H5: (%) 0.00
A6: (1) | B6: (2) | C6: (3) | D6: (4) | F6: (5) | G6: (6) | H6: (7)
A7: =year!$J$4 -> YEAR 2023-24
A8: 1 | B8: UP TO 50 | C8: 0 | D8: 0.0 | F8: UP TO 50 | G8: 0 | H8: 0.0
A9: 2 | B9: 51 to 100 | C9: 0 | D9: 0.0 | F9: 51 to 100 | G9: 0 | H9: 0.0
A10: 3 | B10: 101 to 200 | C10: 0 | D10: 0.0 | F10: 101 to 200 | G10: 2 | H10: 11.1
A11: 4 | B11: 201 to 400 | C11: 0 | D11: 0.0 | F11: 201 to 400 | G11: 8 | H11: 44.4
A12: 5 | B12: 401 to 600 | C12: 2 | D12: 11.1 | F12: 401 to 600 | G12: 6 | H12: 33.3
A13: 6 | B13: 601 to 800 | C13: 0 | D13: 0.0 | F13: 601 to 800 | G13: 1 | H13: 5.6
A14: 7 | B14: 801 to 1000 | C14: 4 | D14: 22.2 | F14: 801 to 1000 | G14: 1 | H14: 5.6
A15: 8 | B15: 1001 to 5000 | C15: 12 | D15: 66.7 | F15: 1001 to 3000 | G15: 0 | H15: 0.0
A16: 9 | B16: ABOVE 5000 | C16: 0 | D16: 0.0 | F16: MORE THAN 3000 | G16: 0 | H16: 0.0
A17: 10 | B17: NOT REPORTED | C17: 0 | D17: 0.0 | F17: NOT REPORTED | G17: 0 | H17: 0.0
A18: TOTAL | C18: 18 | D18: 100.0 | F18: TOTAL | G18: 18 | H18: 100.0
A19: =year!$J$5 -> YEAR 2022-23
A20: 1 | B20: UP TO 50 | C20: 0 | D20: 0.0 | F20: UP TO 50 | G20: 1 | H20: 5.6
A21: 2 | B21: 51 to 100 | C21: 0 | D21: 0.0 | F21: 51 to 100 | G21: 0 | H21: 0.0
A22: 3 | B22: 101 to 200 | C22: 0 | D22: 0.0 | F22: 101 to 200 | G22: 3 | H22: 16.7
A23: 4 | B23: 201 to 400 | C23: 1 | D23: 5.6 | F23: 201 to 400 | G23: 8 | H23: 44.4
A24: 5 | B24: 401 to 600 | C24: 2 | D24: 11.1 | F24: 401 to 600 | G24: 6 | H24: 33.3
A25: 6 | B25: 601 to 800 | C25: 2 | D25: 11.1 | F25: 601 to 800 | G25: 0 | H25: 0.0
A26: 7 | B26: 801 to 1000 | C26: 3 | D26: 16.7 | F26: 801 to 1000 | G26: 0 | H26: 0.0
A27: 8 | B27: 1001 to 5000 | C27: 10 | D27: 55.5 | F27: 1001 to 3000 | G27: 0 | H27: 0.0
A28: 9 | B28: ABOVE 5000 | C28: 0 | D28: 0.0 | F28: MORE THAN 3000 | G28: 0 | H28: 0.0
A29: 10 | B29: NOT REPORTED | C29: 0 | D29: 0.0 | F29: NOT REPORTED | G29: 0 | H29: 0.0
A30: TOTAL | C30: 18 | D30: 100.0 | F30: TOTAL | G30: 18 | H30: 100.0

Sheet Annex-V
A1: A-2
A2: =year!$H$2 -> UT : PUDUCHERRY | B2: =year!$H$2 -> UT : PUDUCHERRY | C2: =year!$H$2 -> UT : PUDUCHERRY | D2: =year!$H$2 -> UT : PUDUCHERRY | E2: =year!$H$2 -> UT : PUDUCHERRY | F2: =year!$H$2 -> UT : PUDUCHERRY | G2: =year!$H$2 -> UT : PUDUCHERRY | H2: =year!$H$2 -> UT : PUDUCHERRY | I2: =year!$H$2 -> UT : PUDUCHERRY | J2: ANNEX-V
A3: TIMELINESS IN COMPLETION OF TRS AREA ENUMERATION (NO. OF VILLAGES) DURING 2023-24 AND 2022-23.
A4: SEASON/ AGENCY | B4: NUMBER (PERCENTAGE) OF VILLAGES WHERE
B5: GIRDAWARI COMPLETED | E5: GIRDAWARI PARTIALLY COMPLETED | F5: GIRDAWARI NOT YET STARTED | G5: INFORMATION ABOUT COMPLETION OF GIRDAWARI NOT AVAILABLE | H5: SYSTEM OF GIRDAWARI DOES NOT EXIST | I5: TOTAL | J5: MAINTENANCE OF RECORDS
B6: IN TIME | C6: LATE | D6: BUT DATE OF COMPLETION NOT KNOWN | J6: LATEST FORM USED FOR GIRDAWARI | K6: RECORDS OF GIRDAWARI KEPT IN REGULAR FORM
A7: (1) | B7: (2) | C7: (3) | D7: (4) | E7: (5) | F7: (6) | G7: (7) | H7: (8) | I7: (9) | J7: (10) | K7: (11)
A8: =year!$H$4 -> RABI I 2023-24
A9: CENTRAL | B9: 9(100.0) | C9: 0( 0.0) | D9: 0( 0.0) | E9: 0( 0.0) | F9: 0( 0.0) | G9: 0( 0.0) | H9: 0( 0.0) | I9: 9(100.0) | J9: 9(100.0) | K9: 9(100.0)
A10: STATE | B10: 9(100.0) | C10: 0( 0.0) | D10: 0( 0.0) | E10: 0( 0.0) | F10: 0( 0.0) | G10: 0( 0.0) | H10: 0( 0.0) | I10: 9(100.0) | J10: 9(100.0) | K10: 9(100.0)
A11: POOLED | B11: 18(100.0) | C11: 0( 0.0) | D11: 0( 0.0) | E11: 0( 0.0) | F11: 0( 0.0) | G11: 0( 0.0) | H11: 0( 0.0) | I11: 18(100.0) | J11: 18(100.0) | K11: 18(100.0)
A12: =year!$I$4 -> RABI II 2023-24
A13: CENTRAL | B13: 9(100.0) | C13: 0( 0.0) | D13: 0( 0.0) | E13: 0( 0.0) | F13: 0( 0.0) | G13: 0( 0.0) | H13: 0( 0.0) | I13: 9(100.0) | J13: 9(100.0) | K13: 9(100.0)
A14: STATE | B14: 9(100.0) | C14: 0( 0.0) | D14: 0( 0.0) | E14: 0( 0.0) | F14: 0( 0.0) | G14: 0( 0.0) | H14: 0( 0.0) | I14: 9(100.0) | J14: 9(100.0) | K14: 9(100.0)
A15: POOLED | B15: 18(100.0) | C15: 0( 0.0) | D15: 0( 0.0) | E15: 0( 0.0) | F15: 0( 0.0) | G15: 0( 0.0) | H15: 0( 0.0) | I15: 18(100.0) | J15: 18(100.0) | K15: 18(100.0)
A16: =year!$H$5 -> RABI I 2022-23
A17: CENTRAL | B17: 9(100.0) | C17: 0( 0.0) | D17: 0( 0.0) | E17: 0( 0.0) | F17: 0( 0.0) | G17: 0( 0.0) | H17: 0( 0.0) | I17: 9(100.0) | J17: 9(100.0) | K17: 8( 88.9)
A18: STATE | B18: 9(100.0) | C18: 0( 0.0) | D18: 0( 0.0) | E18: 0( 0.0) | F18: 0( 0.0) | G18: 0( 0.0) | H18: 0( 0.0) | I18: 9(100.0) | J18: 9(100.0) | K18: 9(100.0)
A19: POOLED | B19: 18(100.0) | C19: 0( 0.0) | D19: 0( 0.0) | E19: 0( 0.0) | F19: 0( 0.0) | G19: 0( 0.0) | H19: 0( 0.0) | I19: 18(100.0) | J19: 18(100.0) | K19: 17( 94.4)
A20: =year!$I$5 -> RABI II 2022-23
A21: CENTRAL | B21: 9(100.0) | C21: 0( 0.0) | D21: 0( 0.0) | E21: 0( 0.0) | F21: 0( 0.0) | G21: 0( 0.0) | H21: 0( 0.0) | I21: 9(100.0) | J21: 9(100.0) | K21: 9(100.0)
A22: STATE | B22: 9(100.0) | C22: 0( 0.0) | D22: 0( 0.0) | E22: 0( 0.0) | F22: 0( 0.0) | G22: 0( 0.0) | H22: 0( 0.0) | I22: 9(100.0) | J22: 9(100.0) | K22: 9(100.0)
A23: POOLED | B23: 18(100.0) | C23: 0( 0.0) | D23: 0( 0.0) | E23: 0( 0.0) | F23: 0( 0.0) | G23: 0( 0.0) | H23: 0( 0.0) | I23: 18(100.0) | J23: 18(100.0) | K23: 18(100.0)

Sheet Annex-VI
A1: A-3
A2: =year!$H$2 -> UT : PUDUCHERRY | B2: =year!$H$2 -> UT : PUDUCHERRY | C2: =year!$H$2 -> UT : PUDUCHERRY | D2: =year!$H$2 -> UT : PUDUCHERRY | E2: =year!$H$2 -> UT : PUDUCHERRY | F2: =year!$H$2 -> UT : PUDUCHERRY | G2: =year!$H$2 -> UT : PUDUCHERRY | H2: =year!$H$2 -> UT : PUDUCHERRY | ... N2: =year!$H$2 -> UT : PUDUCHERRY | O2: ANNEX-VI
A3: TIMELINESS IN SUBMISSION OF TRS STATEMENTS DURING 2023-24 AND 2022-23
A4: SEASON / AGENCY | B4: TOTAL NO. OF VILLAGES ANALYSED | C4: NUMBER AND PERCENTAGE OF VILLAGES FOR WHICH
C5: TRS STATEMENT SUBMITTED | J5: TRS STATEMENT NOT SUBMITTED | N5: INFORMATION REGARDING TRS SUBMISSION NOT AVAILABLE | O5: TRS STATEMENT SUBMITTED IN STANDARD FORM | P5: DUPLICATE COPY OF THE TRS STATEMENT KEPT
C6: WITHOUT COMPLETING GIRDAWARI | E6: AFTER COMPLETING GIRDAWARI | G6: INFORMATION REGARDING TRS SUBMISSION DATE NOT KNOWN | H6: BUT COULD NOT BE COMPARED WITH GIRDAWARI COMPLETION | I6: TOTAL | J6: THOUGH GIRDAWARI COMPLETED | L6: GIRDAWARI NOT COMPLETED | M6: TOTAL
C7: BY DUE DATE | D7: AFTER DUE DATE | E7: BY DUE DATE | F7: AFTER DUE DATE | J7: AS DUE DATE NOT OVER | K7: OTHER REASONS
A8: (1) | B8: (2) | C8: (3) | D8: (4) | E8: (5) | F8: (6) | G8: (7) | H8: (8) | I8: (9) | J8: (10) | K8: (11) | L8: (12) | M8: (13) | N8: (14) | O8: (15) | P8: (16)
A9: =year!$H$4 -> RABI I 2023-24
A10: CENTRAL | B10: 9 | C10: 0( 0.0) | D10: 0( 0.0) | E10: 9(100.0) | F10: 0( 0.0) | G10: 0( 0.0) | H10: 0( 0.0) | I10: 9(100.0) | J10: 0( 0.0) | K10: 0( 0.0) | L10: 0( 0.0) | M10: 0( 0.0) | N10: 0( 0.0) | O10: 9(100.0) | P10: 9(100.0)
A11: STATE | B11: 9 | C11: 0( 0.0) | D11: 0( 0.0) | E11: 9(100.0) | F11: 0( 0.0) | G11: 0( 0.0) | H11: 0( 0.0) | I11: 9(100.0) | J11: 0( 0.0) | K11: 0( 0.0) | L11: 0( 0.0) | M11: 0( 0.0) | N11: 0( 0.0) | O11: 9(100.0) | P11: 9(100.0)
A12: POOLED | B12: 18 | C12: 0( 0.0) | D12: 0( 0.0) | E12: 18(100.0) | F12: 0( 0.0) | G12: 0( 0.0) | H12: 0( 0.0) | I12: 18(100.0) | J12: 0( 0.0) | K12: 0( 0.0) | L12: 0( 0.0) | M12: 0( 0.0) | N12: 0( 0.0) | O12: 18(100.0) | P12: 18(100.0)
A13: =year!$I$4 -> RABI II 2023-24
A14: CENTRAL | B14: 9 | C14: 0( 0.0) | D14: 0( 0.0) | E14: 9(100.0) | F14: 0( 0.0) | G14: 0( 0.0) | H14: 0( 0.0) | I14: 9(100.0) | J14: 0( 0.0) | K14: 0( 0.0) | L14: 0( 0.0) | M14: 0( 0.0) | N14: 0( 0.0) | O14: 9(100.0) | P14: 9(100.0)
A15: STATE | B15: 9 | C15: 0( 0.0) | D15: 0( 0.0) | E15: 9(100.0) | F15: 0( 0.0) | G15: 0( 0.0) | H15: 0( 0.0) | I15: 9(100.0) | J15: 0( 0.0) | K15: 0( 0.0) | L15: 0( 0.0) | M15: 0( 0.0) | N15: 0( 0.0) | O15: 9(100.0) | P15: 9(100.0)
A16: POOLED | B16: 18 | C16: 0( 0.0) | D16: 0( 0.0) | E16: 18(100.0) | F16: 0( 0.0) | G16: 0( 0.0) | H16: 0( 0.0) | I16: 18(100.0) | J16: 0( 0.0) | K16: 0( 0.0) | L16: 0( 0.0) | M16: 0( 0.0) | N16: 0( 0.0) | O16: 18(100.0) | P16: 18(100.0)
A17: =year!$H$5 -> RABI I 2022-23
A18: CENTRAL | B18: 9 | C18: 0( 0.0) | D18: 0( 0.0) | E18: 9(100.0) | F18: 0( 0.0) | G18: 0( 0.0) | H18: 0( 0.0) | I18: 9(100.0) | J18: 0( 0.0) | K18: 0( 0.0) | L18: 0( 0.0) | M18: 0( 0.0) | N18: 0( 0.0) | O18: 9(100.0) | P18: 9(100.0)
A19: STATE | B19: 9 | C19: 0( 0.0) | D19: 0( 0.0) | E19: 9(100.0) | F19: 0( 0.0) | G19: 0( 0.0) | H19: 0( 0.0) | I19: 9(100.0) | J19: 0( 0.0) | K19: 0( 0.0) | L19: 0( 0.0) | M19: 0( 0.0) | N19: 0( 0.0) | O19: 9(100.0) | P19: 9(100.0)
A20: POOLED | B20: 18 | C20: 0( 0.0) | D20: 0( 0.0) | E20: 18(100.0) | F20: 0( 0.0) | G20: 0( 0.0) | H20: 0( 0.0) | I20: 18(100.0) | J20: 0( 0.0) | K20: 0( 0.0) | L20: 0( 0.0) | M20: 0( 0.0) | N20: 0( 0.0) | O20: 18(100.0) | P20: 18(100.0)
A21: =year!$I$5 -> RABI II 2022-23
A22: CENTRAL | B22: 9 | C22: 0( 0.0) | D22: 0( 0.0) | E22: 9(100.0) | F22: 0( 0.0) | G22: 0( 0.0) | H22: 0( 0.0) | I22: 9(100.0) | J22: 0( 0.0) | K22: 0( 0.0) | L22: 0( 0.0) | M22: 0( 0.0) | N22: 0( 0.0) | O22: 9(100.0) | P22: 9(100.0)
A23: STATE | B23: 9 | C23: 0( 0.0) | D23: 0( 0.0) | E23: 9(100.0) | F23: 0( 0.0) | G23: 0( 0.0) | H23: 0( 0.0) | I23: 9(100.0) | J23: 0( 0.0) | K23: 0( 0.0) | L23: 0( 0.0) | M23: 0( 0.0) | N23: 0( 0.0) | O23: 9(100.0) | P23: 9(100.0)
A24: POOLED | B24: 18 | C24: 0( 0.0) | D24: 0( 0.0) | E24: 18(100.0) | F24: 0( 0.0) | G24: 0( 0.0) | H24: 0( 0.0) | I24: 18(100.0) | J24: 0( 0.0) | K24: 0( 0.0) | L24: 0( 0.0) | M24: 0( 0.0) | N24: 0( 0.0) | O24: 18(100.0) | P24: 18(100.0)

Sheet Annex-VII(a)
A1: A-4
A2: =year!$H$2 -> UT : PUDUCHERRY | D2: ANNEX-VII(a)
A3: AVAILABILITY OF FIGURES OF CROP AREA DURING 2023-24 AND 2022-23 (POOLED SAMPLE)
A4: YEAR/ SEASON | B4: NO. OF VILLAGES ANALYSED | C4: NO.(PERCENTAGE) OF VILLAGES FOR WHICH CROP AREA FIGURES WERE NOT AVAILABLE
C5: FOR CURRENT YEAR | D5: FOR PREVIOUS YEAR (FOR NON-TRS)
C6: FOR VILLAGE AS A WHOLE | D6: FOR SAMPLE CLUSTERS | E6: FOR VILLAGE AS A WHOLE
A7: (1) | B7: (2) | C7: (3) | D7: (4) | E7: (5)
A8: =year!$J$4 -> YEAR 2023-24
A9: RABI I | B9: 18 | C9: 2( 11.1) | D9: 2( 11.1) | E9: 0( 0.0)
A10: RABI II | B10: 18 | C10: 0( 0.0) | D10: 7( 38.9) | E10: 0( 0.0)
A11: =year!$J$5 -> YEAR 2022-23
A12: RABI I | B12: 18 | C12: 0( 0.0) | D12: 2( 11.1) | E12: 0( 0.0)
A13: RABI II | B13: 18 | C13: 1( 5.6) | D13: 3( 16.7) | E13: 3( 16.7)

Sheet Annex-VII(b)
A1: A-5
A2: =year!$H$2 -> UT : PUDUCHERRY | B2: =year!$H$2 -> UT : PUDUCHERRY | C2: =year!$H$2 -> UT : PUDUCHERRY | D2: =year!$H$2 -> UT : PUDUCHERRY | E2: =year!$H$2 -> UT : PUDUCHERRY | F2: ANNEX-VII(b)
A3: DISCREPANCIES IN RECORDING OF CROPS AND CROP AREAS DURING 2023-24 AND 2022-23.
A4: YEAR/ SEASON/ AGENCY | B4: NO. OF SURVEY / SUB SURVEY NUMBERS
B5: TOTAL | C5: WHERE CROP AREA TALLIED (E0) | D5: WHERE DISCREPANCIES OBSERVED
D6: CROP REPORTED BY SUPERVISOR BUT NOT REPORTED BY PATWARI (E1) | E6: CROP REPORTED BY PATWARI BUT NOT REPORTED BY SUPERVISOR (E2) | F6: CROP AREAS REPORTED BY SUPERVISOR AND PATWARI DIFFERED (E3) | G6: TOTAL COLS. (4+5+6)
A7: (1) | B7: (2) | C7: (3) | D7: (4) | E7: (5) | F7: (6) | G7: (7)
A8: =year!$H$4 -> RABI I 2023-24
A9: CENTRAL | B9: 50 | C9: 42( 84.0) | D9: 0( 0.0) | E9: 5( 10.0) | F9: 3( 6.0) | G9: 8( 16.0)
A10: STATE | B10: 37 | C10: 37(100.0) | D10: 0( 0.0) | E10: 0( 0.0) | F10: 0( 0.0) | G10: 0( 0.0)
A11: POOLED | B11: 87 | C11: 79( 90.9) | D11: 0( 0.0) | E11: 5( 5.7) | F11: 3( 3.4) | G11: 8( 9.1)
A12: =year!$I$4 -> RABI II 2023-24
A13: CENTRAL | B13: 35 | C13: 31( 88.6) | D13: 0( 0.0) | E13: 4( 11.4) | F13: 0( 0.0) | G13: 4( 11.4)
A14: STATE | B14: 44 | C14: 43( 97.7) | D14: 0( 0.0) | E14: 0( 0.0) | F14: 1( 2.3) | G14: 1( 2.3)
A15: POOLED | B15: 79 | C15: 74( 93.6) | D15: 0( 0.0) | E15: 4( 5.1) | F15: 1( 1.3) | G15: 5( 6.4)
A16: =year!$H$5 -> RABI I 2022-23
A17: CENTRAL | B17: 68 | C17: 68(100.0) | D17: 0( 0.0) | E17: 0( 0.0) | F17: 0( 0.0) | G17: 0( 0.0)
A18: STATE | B18: 74 | C18: 74(100.0) | D18: 0( 0.0) | E18: 0( 0.0) | F18: 0( 0.0) | G18: 0( 0.0)
A19: POOLED | B19: 142 | C19: 142(100.0) | D19: 0( 0.0) | E19: 0( 0.0) | F19: 0( 0.0) | G19: 0( 0.0)
A20: =year!$I$5 -> RABI II 2022-23
A21: CENTRAL | B21: 84 | C21: 75( 89.3) | D21: 7( 8.3) | E21: 0( 0.0) | F21: 2( 2.4) | G21: 9( 10.7)
A22: STATE | B22: 65 | C22: 61( 93.8) | D22: 0( 0.0) | E22: 0( 0.0) | F22: 4( 6.2) | G22: 4( 6.2)
A23: POOLED | B23: 149 | C23: 136( 91.3) | D23: 7( 4.7) | E23: 0( 0.0) | F23: 6( 4.0) | G23: 13( 8.7)

Sheet Annex-VIII
A1: A-6
A2: =year!$H$2 -> UT : PUDUCHERRY | B2: =year!$H$2 -> UT : PUDUCHERRY | C2: =year!$H$2 -> UT : PUDUCHERRY | D2: =year!$H$2 -> UT : PUDUCHERRY | E2: =year!$H$2 -> UT : PUDUCHERRY | F2: =year!$H$2 -> UT : PUDUCHERRY | G2: ANNEX-VIII
A3: IMPACT OF DISCREPANCIES IN RECORDING AREA UNDER CROPS DURING 2023-24 AND 2022-23.
A4: SEASON/ CROP | B4: AREA IN HECTARES AS OBSERVED IN SAMPLE CLUSTERS
B5: CENTRAL SAMPLE | D5: STATE SAMPLE | F5: POOLED SAMPLE | H5: IMPACT OF DISCREPANCIES (b-a/a)*100 (POOLED SAMPLE ONLY)
B6: AS PER SUPERVISOR | C6: AS PER PATWARI | D6: AS PER SUPERVISOR | E6: AS PER PATWARI | F6: AS PER SUPERVISOR (a) | G6: AS PER PATWARI (b)
A7: (1) | B7: (2) | C7: (3) | D7: (4) | E7: (5) | F7: (6) | G7: (7) | H7: (8)
A8: =year!$H$4 -> RABI I 2023-24
A9: PADDY | B9: 26.55 | C9: 26.63 | D9: 7.65 | E9: 7.54 | F9: 34.19 | G9: 34.17 | H9: (-)0.07
A10: OTHERS | B10: 3.3 | C10: 3.03 | D10: 3.38 | E10: 3.38 | F10: 6.68 | G10: 6.41 | H10: (-)4.04
B11: #VALUE! | C11: #VALUE! | D11: #VALUE! | E11: #VALUE! | F11: #VALUE! | G11: #VALUE! | H11: #VALUE!
B12: #VALUE! | C12: #VALUE! | D12: #VALUE! | E12: #VALUE! | F12: #VALUE! | G12: #VALUE! | H12: #VALUE!
B13: #VALUE! | C13: #VALUE! | D13: #VALUE! | E13: #VALUE! | F13: #VALUE! | G13: #VALUE! | H13: #VALUE!
B14: #VALUE! | C14: #VALUE! | D14: #VALUE! | E14: #VALUE! | F14: #VALUE! | G14: #VALUE! | H14: #VALUE!
B15: #VALUE! | C15: #VALUE! | D15: #VALUE! | E15: #VALUE! | F15: #VALUE! | G15: #VALUE! | H15: #VALUE!
B16: #VALUE! | C16: #VALUE! | D16: #VALUE! | E16: #VALUE! | F16: #VALUE! | G16: #VALUE! | H16: #VALUE!
B17: #VALUE! | C17: #VALUE! | D17: #VALUE! | E17: #VALUE! | F17: #VALUE! | G17: #VALUE! | H17: #VALUE!
B18: #VALUE! | C18: #VALUE! | D18: #VALUE! | E18: #VALUE! | F18: #VALUE! | G18: #VALUE! | H18: #VALUE!
B19: #VALUE! | C19: #VALUE! | D19: #VALUE! | E19: #VALUE! | F19: #VALUE! | G19: #VALUE! | H19: #VALUE!
B20: #VALUE! | C20: #VALUE! | D20: #VALUE! | E20: #VALUE! | F20: #VALUE! | G20: #VALUE! | H20: #VALUE!
B21: #VALUE! | C21: #VALUE! | D21: #VALUE! | E21: #VALUE! | F21: #VALUE! | G21: #VALUE! | H21: #VALUE!
B22: #VALUE! | C22: #VALUE! | D22: #VALUE! | E22: #VALUE! | F22: #VALUE! | G22: #VALUE! | H22: #VALUE!
B23: #VALUE! | C23: #VALUE! | D23: #VALUE! | E23: #VALUE! | F23: #VALUE! | G23: #VALUE! | H23: #VALUE!
A24: =year!$I$4 -> RABI II 2023-24
A25: PADDY | B25: 9.52 | C25: 9.52 | D25: 3.17 | E25: 3.17 | F25: 12.69 | G25: 12.69 | H25: 0.00
A26: OTHERS | B26: 2.53 | C26: 2.53 | D26: 2.89 | E26: 2.81 | F26: 5.42 | G26: 5.34 | H26: (-)1.48
B27: #VALUE! | C27: #VALUE! | D27: #VALUE! | E27: #VALUE! | F27: #VALUE! | G27: #VALUE! | H27: #VALUE!
B28: #VALUE! | C28: #VALUE! | D28: #VALUE! | E28: #VALUE! | F28: #VALUE! | G28: #VALUE! | H28: #VALUE!
B29: #VALUE! | C29: #VALUE! | D29: #VALUE! | E29: #VALUE! | F29: #VALUE! | G29: #VALUE! | H29: #VALUE!
B30: #VALUE! | C30: #VALUE! | D30: #VALUE! | E30: #VALUE! | F30: #VALUE! | G30: #VALUE! | H30: #VALUE!
B31: #VALUE! | C31: #VALUE! | D31: #VALUE! | E31: #VALUE! | F31: #VALUE! | G31: #VALUE! | H31: #VALUE!
B32: #VALUE! | C32: #VALUE! | D32: #VALUE! | E32: #VALUE! | F32: #VALUE! | G32: #VALUE! | H32: #VALUE!
B33: #VALUE! | C33: #VALUE! | D33: #VALUE! | E33: #VALUE! | F33: #VALUE! | G33: #VALUE! | H33: #VALUE!
B34: #VALUE! | C34: #VALUE! | D34: #VALUE! | E34: #VALUE! | F34: #VALUE! | G34: #VALUE! | H34: #VALUE!
B35: #VALUE! | C35: #VALUE! | D35: #VALUE! | E35: #VALUE! | F35: #VALUE! | G35: #VALUE! | H35: #VALUE!
B36: #VALUE! | C36: #VALUE! | D36: #VALUE! | E36: #VALUE! | F36: #VALUE! | G36: #VALUE! | H36: #VALUE!
B37: #VALUE! | C37: #VALUE! | D37: #VALUE! | E37: #VALUE! | F37: #VALUE! | G37: #VALUE! | H37: #VALUE!
B38: #VALUE! | C38: #VALUE! | D38: #VALUE! | E38: #VALUE! | F38: #VALUE! | G38: #VALUE! | H38: #VALUE!
B39: #VALUE! | C39: #VALUE! | D39: #VALUE! | E39: #VALUE! | F39: #VALUE! | G39: #VALUE! | H39: #VALUE!
A40: # NOT COMPARABLE AS THE IMPACT IS 100% OR MORE
...

Sheet Annex-IX
A1: A-7
A2: =year!$H$2 -> UT : PUDUCHERRY | B2: =year!$H$2 -> UT : PUDUCHERRY | C2: =year!$H$2 -> UT : PUDUCHERRY | D2: =year!$H$2 -> UT : PUDUCHERRY | E2: =year!$H$2 -> UT : PUDUCHERRY | F2: =year!$H$2 -> UT : PUDUCHERRY | G2: =year!$H$2 -> UT : PUDUCHERRY | H2: =year!$H$2 -> UT : PUDUCHERRY | ... N2: =year!$H$2 -> UT : PUDUCHERRY | O2: ANNEX-IX
A3: DISCREPANCIES IN RECORDING IRRIGATION PARTICULARS DURING 2023-24 AND 2022-23.
A4: YEAR/ SEASON/ AGENCY | B4: NO. OF SURVEY/ SUB SURVEY NUMBERS | C4: NO. AND PERCENTAGE OF SURVEY NUMBERS IN WHICH PARTICULARS TALLIED | G4: NO. AND PERCENTAGE OF SURVEY NUMBERS IN WHICH PARTICULARS NOT TALLIED
C5: I | D5: UI | E5: I & UI | F5: TOTAL | G5: SUPERVISOR | L5: PATWARI
G6: I | H6: UI | I6: I&UI | J6: NR | K6: TOTAL | L6: I | M6: UI | N6: I&UI | O6: NR | P6: TOTAL
A7: (1) | B7: (2) | C7: (3) | D7: (4) | E7: (5) | F7: (6) | G7: (7) | H7: (8) | I7: (9) | J7: (10) | K7: (11) | L7: (12) | M7: (13) | N7: (14) | O7: (15) | P7: (16)
A8: =year!$H$4 -> RABI I 2023-24
A9: CENTRAL | B9: 50 | C9: 47 | D9: 1 | E9: 0 | F9: 48 | G9: 0 | H9: 0 | I9: 0 | J9: 2 | K9: 2 | L9: 2 | M9: 0 | N9: 0 | O9: 0 | P9: 2
A10: (%) | C10: ( 94.0) | D10: ( 2.0) | E10: ( 0.0) | F10: ( 96.0) | G10: ( 0.0) | H10: ( 0.0) | I10: ( 0.0) | J10: ( 4.0) | K10: ( 4.0) | L10: ( 4.0) | M10: ( 0.0) | N10: ( 0.0) | O10: ( 0.0) | P10: ( 4.0)
A11: STATE | B11: 37 | C11: 35 | D11: 2 | E11: 0 | F11: 37 | G11: 0 | H11: 0 | I11: 0 | J11: 0 | K11: 0 | L11: 0 | M11: 0 | N11: 0 | O11: 0 | P11: 0
A12: (%) | C12: ( 94.6) | D12: ( 5.4) | E12: ( 0.0) | F12: ( 100.0) | G12: ( 0.0) | H12: ( 0.0) | I12: ( 0.0) | J12: ( 0.0) | K12: ( 0.0) | L12: ( 0.0) | M12: ( 0.0) | N12: ( 0.0) | O12: ( 0.0) | P12: ( 0.0)
A13: POOLED | B13: 87 | C13: 82 | D13: 3 | E13: 0 | F13: 85 | G13: 0 | H13: 0 | I13: 0 | J13: 2 | K13: 2 | L13: 2 | M13: 0 | N13: 0 | O13: 0 | P13: 2
A14: (%) | C14: ( 94.3) | D14: ( 3.4) | E14: ( 0.0) | F14: ( 97.7) | G14: ( 0.0) | H14: ( 0.0) | I14: ( 0.0) | J14: ( 2.3) | K14: ( 2.3) | L14: ( 2.3) | M14: ( 0.0) | N14: ( 0.0) | O14: ( 0.0) | P14: ( 2.3)
A15: =year!$I$4 -> RABI II 2023-24
A16: CENTRAL | B16: 35 | C16: 30 | D16: 2 | E16: 0 | F16: 32 | G16: 0 | H16: 0 | I16: 0 | J16: 3 | K16: 3 | L16: 3 | M16: 0 | N16: 0 | O16: 0 | P16: 3
A17: (%) | C17: ( 85.7) | D17: ( 5.7) | E17: ( 0.0) | F17: ( 91.4) | G17: ( 0.0) | H17: ( 0.0) | I17: ( 0.0) | J17: ( 8.6) | K17: ( 8.6) | L17: ( 8.6) | M17: ( 0.0) | N17: ( 0.0) | O17: ( 0.0) | P17: ( 8.6)
A18: STATE | B18: 44 | C18: 28 | D18: 16 | E18: 0 | F18: 44 | G18: 0 | H18: 0 | I18: 0 | J18: 0 | K18: 0 | L18: 0 | M18: 0 | N18: 0 | O18: 0 | P18: 0
A19: (%) | C19: ( 63.6) | D19: ( 36.4) | E19: ( 0.0) | F19: ( 100.0) | G19: ( 0.0) | H19: ( 0.0) | I19: ( 0.0) | J19: ( 0.0) | K19: ( 0.0) | L19: ( 0.0) | M19: ( 0.0) | N19: ( 0.0) | O19: ( 0.0) | P19: ( 0.0)
A20: POOLED | B20: 79 | C20: 58 | D20: 18 | E20: 0 | F20: 76 | G20: 0 | H20: 0 | I20: 0 | J20: 3 | K20: 3 | L20: 3 | M20: 0 | N20: 0 | O20: 0 | P20: 3
A21: (%) | C21: ( 73.4) | D21: ( 22.8) | E21: ( 0.0) | F21: ( 96.2) | G21: ( 0.0) | H21: ( 0.0) | I21: ( 0.0) | J21: ( 3.8) | K21: ( 3.8) | L21: ( 3.8) | M21: ( 0.0) | N21: ( 0.0) | O21: ( 0.0) | P21: ( 3.8)
A22: =year!$H$5 -> RABI I 2022-23
A23: CENTRAL | B23: 68 | C23: 52 | D23: 16 | E23: 0 | F23: 68 | G23: 0 | H23: 0 | I23: 0 | J23: 0 | K23: 0 | L23: 0 | M23: 0 | N23: 0 | O23: 0 | P23: 0
A24: (%) | C24: ( 76.5) | D24: ( 23.5) | E24: ( 0.0) | F24: ( 100.0) | G24: ( 0.0) | H24: ( 0.0) | I24: ( 0.0) | J24: ( 0.0) | K24: ( 0.0) | L24: ( 0.0) | M24: ( 0.0) | N24: ( 0.0) | O24: ( 0.0) | P24: ( 0.0)
A25: STATE | B25: 74 | C25: 64 | D25: 7 | E25: 3 | F25: 74 | G25: 0 | H25: 0 | I25: 0 | J25: 0 | K25: 0 | L25: 0 | M25: 0 | N25: 0 | O25: 0 | P25: 0
A26: (%) | C26: ( 86.5) | D26: ( 9.5) | E26: ( 4.1) | F26: ( 100.0) | G26: ( 0.0) | H26: ( 0.0) | I26: ( 0.0) | J26: ( 0.0) | K26: ( 0.0) | L26: ( 0.0) | M26: ( 0.0) | N26: ( 0.0) | O26: ( 0.0) | P26: ( 0.0)
A27: POOLED | B27: 142 | C27: 116 | D27: 23 | E27: 3 | F27: 142 | G27: 0 | H27: 0 | I27: 0 | J27: 0 | K27: 0 | L27: 0 | M27: 0 | N27: 0 | O27: 0 | P27: 0
A28: (%) | C28: ( 81.7) | D28: ( 16.2) | E28: ( 2.1) | F28: ( 100.0) | G28: ( 0.0) | H28: ( 0.0) | I28: ( 0.0) | J28: ( 0.0) | K28: ( 0.0) | L28: ( 0.0) | M28: ( 0.0) | N28: ( 0.0) | O28: ( 0.0) | P28: ( 0.0)
A29: =year!$I$5 -> RABI II 2022-23
A30: CENTRAL | B30: 84 | C30: 31 | D30: 45 | E30: 1 | F30: 77 | G30: 0 | H30: 7 | I30: 0 | J30: 0 | K30: 7 | L30: 0 | M30: 0 | N30: 0 | O30: 7 | P30: 7
A31: (%) | C31: ( 36.9) | D31: ( 53.6) | E31: ( 1.2) | F31: ( 91.7) | G31: ( 0.0) | H31: ( 8.3) | I31: ( 0.0) | J31: ( 0.0) | K31: ( 8.3) | L31: ( 0.0) | M31: ( 0.0) | N31: ( 0.0) | O31: ( 8.3) | P31: ( 8.3)
A32: STATE | B32: 65 | C32: 52 | D32: 11 | E32: 2 | F32: 65 | G32: 0 | H32: 0 | I32: 0 | J32: 0 | K32: 0 | L32: 0 | M32: 0 | N32: 0 | O32: 0 | P32: 0
A33: (%) | C33: ( 80.0) | D33: ( 16.9) | E33: ( 3.1) | F33: ( 100.0) | G33: ( 0.0) | H33: ( 0.0) | I33: ( 0.0) | J33: ( 0.0) | K33: ( 0.0) | L33: ( 0.0) | M33: ( 0.0) | N33: ( 0.0) | O33: ( 0.0) | P33: ( 0.0)
A34: POOLED | B34: 149 | C34: 83 | D34: 56 | E34: 3 | F34: 142 | G34: 0 | H34: 7 | I34: 0 | J34: 0 | K34: 7 | L34: 0 | M34: 0 | N34: 0 | O34: 7 | P34: 7
A35: (%) | C35: ( 55.7) | D35: ( 37.6) | E35: ( 2.0) | F35: ( 95.3) | G35: ( 0.0) | H35: ( 4.7) | I35: ( 0.0) | J35: ( 0.0) | K35: ( 4.7) | L35: ( 0.0) | M35: ( 0.0) | N35: ( 0.0) | O35: ( 4.7) | P35: ( 4.7)

Sheet Annex-X
A1: A-8
A2: =year!$H$2 -> UT : PUDUCHERRY | B2: =year!$H$2 -> UT : PUDUCHERRY | C2: =year!$H$2 -> UT : PUDUCHERRY | D2: =year!$H$2 -> UT : PUDUCHERRY | E2: =year!$H$2 -> UT : PUDUCHERRY | F2: =year!$H$2 -> UT : PUDUCHERRY | G2: =year!$H$2 -> UT : PUDUCHERRY | H2: =year!$H$2 -> UT : PUDUCHERRY | I2: =year!$H$2 -> UT : PUDUCHERRY | J2: ANNEX-X
A3: IMPACT OF DISCREPANCIES IN RECORDING AREA UNDER CROPS(IRRIGATED) DURING 2023-24 AND 2022-23.
A4: SEASON/ CROP | B4: AREA IN HECTARES AS OBSERVED IN SAMPLE CLUSTERS
B5: CENTRAL SAMPLE | E5: STATE SAMPLE | H5: POOLED SAMPLE | K5: IMPACT OF DISCREPANCIES (b-a/a)*100 (POOLED SAMPLE ONLY)
B6: NO. OF VILLAGES REPORTING CROP | C6: AS PER SUPERVISOR | D6: AS PER PATWARI | E6: NO. OF VILLAGES REPORTING CROP | F6: AS PER SUPERVISOR | G6: AS PER PATWARI | H6: NO. OF VILLAGES REPORTING CROP | I6: AS PER SUPERVISOR (a) | J6: AS PER PATWARI (b)
A7: (1) | B7: (2) | C7: (3) | D7: (4) | E7: (5) | F7: (6) | G7: (7) | H7: (8) | I7: (9) | J7: (10) | K7: (11)
A8: =year!$H$4 -> RABI I 2023-24
A9: PADDY | B9: 7 | C9: 26.43 | D9: 26.51 | E9: 7 | F9: 7.65 | G9: 7.54 | H9: 14 | I9: 34.08 | J9: 34.05 | K9: (-)0.07
A10: OTHERS | B10: 3 | C10: 3.3 | D10: 3.03 | E10: 3 | F10: 2.63 | G10: 2.63 | H10: 6 | I10: 5.93 | J10: 5.66 | K10: (-)4.55
B11: #VALUE! | C11: #VALUE! | D11: #VALUE! | E11: #VALUE! | F11: #VALUE! | G11: #VALUE! | H11: #VALUE! | I11: #VALUE! | J11: #VALUE! | K11: #VALUE!
B12: #VALUE! | C12: #VALUE! | D12: #VALUE! | E12: #VALUE! | F12: #VALUE! | G12: #VALUE! | H12: #VALUE! | I12: #VALUE! | J12: #VALUE! | K12: #VALUE!
B13: #VALUE! | C13: #VALUE! | D13: #VALUE! | E13: #VALUE! | F13: #VALUE! | G13: #VALUE! | H13: #VALUE! | I13: #VALUE! | J13: #VALUE! | K13: #VALUE!
B14: #VALUE! | C14: #VALUE! | D14: #VALUE! | E14: #VALUE! | F14: #VALUE! | G14: #VALUE! | H14: #VALUE! | I14: #VALUE! | J14: #VALUE! | K14: #VALUE!
B15: #VALUE! | C15: #VALUE! | D15: #VALUE! | E15: #VALUE! | F15: #VALUE! | G15: #VALUE! | H15: #VALUE! | I15: #VALUE! | J15: #VALUE! | K15: #VALUE!
B16: #VALUE! | C16: #VALUE! | D16: #VALUE! | E16: #VALUE! | F16: #VALUE! | G16: #VALUE! | H16: #VALUE! | I16: #VALUE! | J16: #VALUE! | K16: #VALUE!
B17: #VALUE! | C17: #VALUE! | D17: #VALUE! | E17: #VALUE! | F17: #VALUE! | G17: #VALUE! | H17: #VALUE! | I17: #VALUE! | J17: #VALUE! | K17: #VALUE!
B18: #VALUE! | C18: #VALUE! | D18: #VALUE! | E18: #VALUE! | F18: #VALUE! | G18: #VALUE! | H18: #VALUE! | I18: #VALUE! | J18: #VALUE! | K18: #VALUE!
B19: #VALUE! | C19: #VALUE! | D19: #VALUE! | E19: #VALUE! | F19: #VALUE! | G19: #VALUE! | H19: #VALUE! | I19: #VALUE! | J19: #VALUE! | K19: #VALUE!
B20: #VALUE! | C20: #VALUE! | D20: #VALUE! | E20: #VALUE! | F20: #VALUE! | G20: #VALUE! | H20: #VALUE! | I20: #VALUE! | J20: #VALUE! | K20: #VALUE!
B21: #VALUE! | C21: #VALUE! | D21: #VALUE! | E21: #VALUE! | F21: #VALUE! | G21: #VALUE! | H21: #VALUE! | I21: #VALUE! | J21: #VALUE! | K21: #VALUE!
B22: #VALUE! | C22: #VALUE! | D22: #VALUE! | E22: #VALUE! | F22: #VALUE! | G22: #VALUE! | H22: #VALUE! | I22: #VALUE! | J22: #VALUE! | K22: #VALUE!
B23: #VALUE! | C23: #VALUE! | D23: #VALUE! | E23: #VALUE! | F23: #VALUE! | G23: #VALUE! | H23: #VALUE! | I23: #VALUE! | J23: #VALUE! | K23: #VALUE!
A24: =year!$I$4 -> RABI II 2023-24
A25: PADDY | B25: 5 | C25: 8.65 | D25: 8.8 | E25: 2 | F25: 2.46 | G25: 2.46 | H25: 7 | I25: 11.11 | J25: 11.26 | K25: 1.35
A26: OTHERS | B26: 4 | C26: 2.53 | D26: 2.53 | E26: 3 | F26: 1.74 | G26: 1.74 | H26: 7 | I26: 4.27 | J26: 4.27 | K26: 0.00
B27: #VALUE! | C27: #VALUE! | D27: #VALUE! | E27: #VALUE! | F27: #VALUE! | G27: #VALUE! | H27: #VALUE! | I27: #VALUE! | J27: #VALUE! | K27: #VALUE!
B28: #VALUE! | C28: #VALUE! | D28: #VALUE! | E28: #VALUE! | F28: #VALUE! | G28: #VALUE! | H28: #VALUE! | I28: #VALUE! | J28: #VALUE! | K28: #VALUE!
B29: #VALUE! | C29: #VALUE! | D29: #VALUE! | E29: #VALUE! | F29: #VALUE! | G29: #VALUE! | H29: #VALUE! | I29: #VALUE! | J29: #VALUE! | K29: #VALUE!
B30: #VALUE! | C30: #VALUE! | D30: #VALUE! | E30: #VALUE! | F30: #VALUE! | G30: #VALUE! | H30: #VALUE! | I30: #VALUE! | J30: #VALUE! | K30: #VALUE!
B31: #VALUE! | C31: #VALUE! | D31: #VALUE! | E31: #VALUE! | F31: #VALUE! | G31: #VALUE! | H31: #VALUE! | I31: #VALUE! | J31: #VALUE! | K31: #VALUE!
B32: #VALUE! | C32: #VALUE! | D32: #VALUE! | E32: #VALUE! | F32: #VALUE! | G32: #VALUE! | H32: #VALUE! | I32: #VALUE! | J32: #VALUE! | K32: #VALUE!
B33: #VALUE! | C33: #VALUE! | D33: #VALUE! | E33: #VALUE! | F33: #VALUE! | G33: #VALUE! | H33: #VALUE! | I33: #VALUE! | J33: #VALUE! | K33: #VALUE!
B34: #VALUE! | C34: #VALUE! | D34: #VALUE! | E34: #VALUE! | F34: #VALUE! | G34: #VALUE! | H34: #VALUE! | I34: #VALUE! | J34: #VALUE! | K34: #VALUE!
B35: #VALUE! | C35: #VALUE! | D35: #VALUE! | E35: #VALUE! | F35: #VALUE! | G35: #VALUE! | H35: #VALUE! | I35: #VALUE! | J35: #VALUE! | K35: #VALUE!
B36: #VALUE! | C36: #VALUE! | D36: #VALUE! | E36: #VALUE! | F36: #VALUE! | G36: #VALUE! | H36: #VALUE! | I36: #VALUE! | J36: #VALUE! | K36: #VALUE!
B37: #VALUE! | C37: #VALUE! | D37: #VALUE! | E37: #VALUE! | F37: #VALUE! | G37: #VALUE! | H37: #VALUE! | I37: #VALUE! | J37: #VALUE! | K37: #VALUE!
B38: #VALUE! | C38: #VALUE! | D38: #VALUE! | E38: #VALUE! | F38: #VALUE! | G38: #VALUE! | H38: #VALUE! | I38: #VALUE! | J38: #VALUE! | K38: #VALUE!
B39: #VALUE! | C39: #VALUE! | D39: #VALUE! | E39: #VALUE! | F39: #VALUE! | G39: #VALUE! | H39: #VALUE! | I39: #VALUE! | J39: #VALUE! | K39: #VALUE!
A40: # NOT COMPARABLE AS THE IMPACT IS 100% OR MORE
...

Sheet Annex-XI
A1: A-9
A2: =year!$H$2 -> UT : PUDUCHERRY | B2: =year!$H$2 -> UT : PUDUCHERRY | C2: =year!$H$2 -> UT : PUDUCHERRY | D2: =year!$H$2 -> UT : PUDUCHERRY | E2: =year!$H$2 -> UT : PUDUCHERRY | F2: =year!$H$2 -> UT : PUDUCHERRY | G2: =year!$H$2 -> UT : PUDUCHERRY | H2: =year!$H$2 -> UT : PUDUCHERRY | ... N2: =year!$H$2 -> UT : PUDUCHERRY | O2: ANNEX-XI
A3: DISCREPANCIES IN RECORDING SEED VARIETY PARTICULARS DURING 2023-24 AND 2022-23.
A4: YEAR/ SEASON/ AGENCY | B4: NO. OF SURVEY/ SUB SURVEY NUMBERS | C4: NO. AND PERCENTAGE OF SURVEY NUMBERS IN WHICH PARTICULARS TALLIED | G4: NO. AND PERCENTAGE OF SURVEY NUMBERS IN WHICH PARTICULARS NOT TALLIED
C5: HY | D5: L | E5: HY&L | F5: TOTAL | G5: SUPERVISOR | L5: PATWARI
G6: HY | H6: L | I6: HY&L | J6: NR | K6: TOTAL | L6: HY | M6: L | N6: HY&L | O6: NR | P6: TOTAL
A7: (1) | B7: (2) | C7: (3) | D7: (4) | E7: (5) | F7: (6) | G7: (7) | H7: (8) | I7: (9) | J7: (10) | K7: (11) | L7: (12) | M7: (13) | N7: (14) | O7: (15) | P7: (16)
A8: =year!$H$4 -> RABI I 2023-24
A9: CENTRAL | B9: 50 | C9: 39 | D9: 8 | E9: 1 | F9: 48 | G9: 1 | H9: 0 | I9: 0 | J9: 1 | K9: 2 | L9: 0 | M9: 2 | N9: 0 | O9: 0 | P9: 2
A10: (%) | C10: ( 78.0) | D10: ( 16.0) | E10: ( 2.0) | F10: ( 96.0) | G10: ( 2.0) | H10: ( 0.0) | I10: ( 0.0) | J10: ( 2.0) | K10: ( 4.0) | L10: ( 0.0) | M10: ( 4.0) | N10: ( 0.0) | O10: ( 0.0) | P10: ( 4.0)
A11: STATE | B11: 37 | C11: 37 | D11: 0 | E11: 0 | F11: 37 | G11: 0 | H11: 0 | I11: 0 | J11: 0 | K11: 0 | L11: 0 | M11: 0 | N11: 0 | O11: 0 | P11: 0
A12: (%) | C12: ( 100.0) | D12: ( 0.0) | E12: ( 0.0) | F12: ( 100.0) | G12: ( 0.0) | H12: ( 0.0) | I12: ( 0.0) | J12: ( 0.0) | K12: ( 0.0) | L12: ( 0.0) | M12: ( 0.0) | N12: ( 0.0) | O12: ( 0.0) | P12: ( 0.0)
A13: POOLED | B13: 87 | C13: 76 | D13: 8 | E13: 1 | F13: 85 | G13: 1 | H13: 0 | I13: 0 | J13: 1 | K13: 2 | L13: 0 | M13: 2 | N13: 0 | O13: 0 | P13: 2
A14: (%) | C14: ( 87.4) | D14: ( 9.2) | E14: ( 1.1) | F14: ( 97.7) | G14: ( 1.1) | H14: ( 0.0) | I14: ( 0.0) | J14: ( 1.1) | K14: ( 2.3) | L14: ( 0.0) | M14: ( 2.3) | N14: ( 0.0) | O14: ( 0.0) | P14: ( 2.3)
A15: =year!$I$4 -> RABI II 2023-24
A16: CENTRAL | B16: 35 | C16: 30 | D16: 4 | E16: 0 | F16: 34 | G16: 0 | H16: 0 | I16: 0 | J16: 1 | K16: 1 | L16: 1 | M16: 0 | N16: 0 | O16: 0 | P16: 1
A17: (%) | C17: ( 85.7) | D17: ( 11.4) | E17: ( 0.0) | F17: ( 97.1) | G17: ( 0.0) | H17: ( 0.0) | I17: ( 0.0) | J17: ( 2.9) | K17: ( 2.9) | L17: ( 2.9) | M17: ( 0.0) | N17: ( 0.0) | O17: ( 0.0) | P17: ( 2.9)
A18: STATE | B18: 44 | C18: 31 | D18: 13 | E18: 0 | F18: 44 | G18: 0 | H18: 0 | I18: 0 | J18: 0 | K18: 0 | L18: 0 | M18: 0 | N18: 0 | O18: 0 | P18: 0
A19: (%) | C19: ( 70.5) | D19: ( 29.5) | E19: ( 0.0) | F19: ( 100.0) | G19: ( 0.0) | H19: ( 0.0) | I19: ( 0.0) | J19: ( 0.0) | K19: ( 0.0) | L19: ( 0.0) | M19: ( 0.0) | N19: ( 0.0) | O19: ( 0.0) | P19: ( 0.0)
A20: POOLED | B20: 79 | C20: 61 | D20: 17 | E20: 0 | F20: 78 | G20: 0 | H20: 0 | I20: 0 | J20: 1 | K20: 1 | L20: 1 | M20: 0 | N20: 0 | O20: 0 | P20: 1
A21: (%) | C21: ( 77.2) | D21: ( 21.5) | E21: ( 0.0) | F21: ( 98.7) | G21: ( 0.0) | H21: ( 0.0) | I21: ( 0.0) | J21: ( 1.3) | K21: ( 1.3) | L21: ( 1.3) | M21: ( 0.0) | N21: ( 0.0) | O21: ( 0.0) | P21: ( 1.3)
A22: =year!$H$5 -> RABI I 2022-23
A23: CENTRAL | B23: 68 | C23: 52 | D23: 16 | E23: 0 | F23: 68 | G23: 0 | H23: 0 | I23: 0 | J23: 0 | K23: 0 | L23: 0 | M23: 0 | N23: 0 | O23: 0 | P23: 0
A24: (%) | C24: ( 76.5) | D24: ( 23.5) | E24: ( 0.0) | F24: ( 100.0) | G24: ( 0.0) | H24: ( 0.0) | I24: ( 0.0) | J24: ( 0.0) | K24: ( 0.0) | L24: ( 0.0) | M24: ( 0.0) | N24: ( 0.0) | O24: ( 0.0) | P24: ( 0.0)
A25: STATE | B25: 74 | C25: 61 | D25: 12 | E25: 1 | F25: 74 | G25: 0 | H25: 0 | I25: 0 | J25: 0 | K25: 0 | L25: 0 | M25: 0 | N25: 0 | O25: 0 | P25: 0
A26: (%) | C26: ( 82.4) | D26: ( 16.2) | E26: ( 1.4) | F26: ( 100.0) | G26: ( 0.0) | H26: ( 0.0) | I26: ( 0.0) | J26: ( 0.0) | K26: ( 0.0) | L26: ( 0.0) | M26: ( 0.0) | N26: ( 0.0) | O26: ( 0.0) | P26: ( 0.0)
A27: POOLED | B27: 142 | C27: 113 | D27: 28 | E27: 1 | F27: 142 | G27: 0 | H27: 0 | I27: 0 | J27: 0 | K27: 0 | L27: 0 | M27: 0 | N27: 0 | O27: 0 | P27: 0
A28: (%) | C28: ( 79.6) | D28: ( 19.7) | E28: ( 0.7) | F28: ( 100.0) | G28: ( 0.0) | H28: ( 0.0) | I28: ( 0.0) | J28: ( 0.0) | K28: ( 0.0) | L28: ( 0.0) | M28: ( 0.0) | N28: ( 0.0) | O28: ( 0.0) | P28: ( 0.0)
A29: =year!$I$5 -> RABI II 2022-23
A30: CENTRAL | B30: 84 | C30: 31 | D30: 45 | E30: 1 | F30: 77 | G30: 0 | H30: 7 | I30: 0 | J30: 0 | K30: 7 | L30: 0 | M30: 0 | N30: 0 | O30: 7 | P30: 7
A31: (%) | C31: ( 36.9) | D31: ( 53.6) | E31: ( 1.2) | F31: ( 91.7) | G31: ( 0.0) | H31: ( 8.3) | I31: ( 0.0) | J31: ( 0.0) | K31: ( 8.3) | L31: ( 0.0) | M31: ( 0.0) | N31: ( 0.0) | O31: ( 8.3) | P31: ( 8.3)
A32: STATE | B32: 65 | C32: 55 | D32: 8 | E32: 1 | F32: 64 | G32: 1 | H32: 0 | I32: 0 | J32: 0 | K32: 1 | L32: 0 | M32: 0 | N32: 0 | O32: 1 | P32: 1
A33: (%) | C33: ( 84.6) | D33: ( 12.3) | E33: ( 1.5) | F33: ( 98.5) | G33: ( 1.5) | H33: ( 0.0) | I33: ( 0.0) | J33: ( 0.0) | K33: ( 1.5) | L33: ( 0.0) | M33: ( 0.0) | N33: ( 0.0) | O33: ( 1.5) | P33: ( 1.5)
A34: POOLED | B34: 149 | C34: 86 | D34: 53 | E34: 2 | F34: 141 | G34: 1 | H34: 7 | I34: 0 | J34: 0 | K34: 8 | L34: 0 | M34: 0 | N34: 0 | O34: 8 | P34: 8
A35: (%) | C35: ( 57.7) | D35: ( 35.6) | E35: ( 1.3) | F35: ( 94.6) | G35: ( 0.7) | H35: ( 4.7) | I35: ( 0.0) | J35: ( 0.0) | K35: ( 5.4) | L35: ( 0.0) | M35: ( 0.0) | N35: ( 0.0) | O35: ( 5.4) | P35: ( 5.4)

Sheet Annex-XII
A1: A-10
A2: =year!$H$2 -> UT : PUDUCHERRY | B2: =year!$H$2 -> UT : PUDUCHERRY | C2: =year!$H$2 -> UT : PUDUCHERRY | D2: =year!$H$2 -> UT : PUDUCHERRY | E2: =year!$H$2 -> UT : PUDUCHERRY | F2: =year!$H$2 -> UT : PUDUCHERRY | G2: =year!$H$2 -> UT : PUDUCHERRY | H2: =year!$H$2 -> UT : PUDUCHERRY | I2: =year!$H$2 -> UT : PUDUCHERRY | J2: ANNEX-XII
A3: IMPACT OF DISCREPANCIES IN RECORDING AREA UNDER CROPS(HIGH YIELDING VARIETY OF SEEDS) DURING 2023-24 AND 2022-23.
A4: SEASON/ CROP | B4: AREA IN HECTARES AS OBSERVED IN SAMPLE CLUSTERS
B5: CENTRAL SAMPLE | E5: STATE SAMPLE | H5: POOLED SAMPLE | K5: IMPACT OF DISCREPANCIES (b-a/a)*100 (POOLED SAMPLE ONLY)
B6: NO. OF VILLAGES REPORTING CROP | C6: AS PER SUPERVISOR | D6: AS PER PATWARI | E6: NO. OF VILLAGES REPORTING CROP | F6: AS PER SUPERVISOR | G6: AS PER PATWARI | H6: NO. OF VILLAGES REPORTING CROP | I6: AS PER SUPERVISOR (a) | J6: AS PER PATWARI (b)
A7: (1) | B7: (2) | C7: (3) | D7: (4) | E7: (5) | F7: (6) | G7: (7) | H7: (8) | I7: (9) | J7: (10) | K7: (11)
A8: =year!$H$4 -> RABI I 2023-24
A9: PADDY | B9: 7 | C9: 22.65 | D9: 22.73 | E9: 7 | F9: 7.65 | G9: 7.54 | H9: 14 | I9: 30.29 | J9: 30.27 | K9: (-)0.08
A10: OTHERS | B10: 2 | C10: 0.88 | D10: 0.88 | E10: 3 | F10: 3.38 | G10: 3.38 | H10: 5 | I10: 4.26 | J10: 4.26 | K10: 0.00
B11: #VALUE! | C11: #VALUE! | D11: #VALUE! | E11: #VALUE! | F11: #VALUE! | G11: #VALUE! | H11: #VALUE! | I11: #VALUE! | J11: #VALUE! | K11: #VALUE!
B12: #VALUE! | C12: #VALUE! | D12: #VALUE! | E12: #VALUE! | F12: #VALUE! | G12: #VALUE! | H12: #VALUE! | I12: #VALUE! | J12: #VALUE! | K12: #VALUE!
B13: #VALUE! | C13: #VALUE! | D13: #VALUE! | E13: #VALUE! | F13: #VALUE! | G13: #VALUE! | H13: #VALUE! | I13: #VALUE! | J13: #VALUE! | K13: #VALUE!
B14: #VALUE! | C14: #VALUE! | D14: #VALUE! | E14: #VALUE! | F14: #VALUE! | G14: #VALUE! | H14: #VALUE! | I14: #VALUE! | J14: #VALUE! | K14: #VALUE!
B15: #VALUE! | C15: #VALUE! | D15: #VALUE! | E15: #VALUE! | F15: #VALUE! | G15: #VALUE! | H15: #VALUE! | I15: #VALUE! | J15: #VALUE! | K15: #VALUE!
B16: #VALUE! | C16: #VALUE! | D16: #VALUE! | E16: #VALUE! | F16: #VALUE! | G16: #VALUE! | H16: #VALUE! | I16: #VALUE! | J16: #VALUE! | K16: #VALUE!
B17: #VALUE! | C17: #VALUE! | D17: #VALUE! | E17: #VALUE! | F17: #VALUE! | G17: #VALUE! | H17: #VALUE! | I17: #VALUE! | J17: #VALUE! | K17: #VALUE!
B18: #VALUE! | C18: #VALUE! | D18: #VALUE! | E18: #VALUE! | F18: #VALUE! | G18: #VALUE! | H18: #VALUE! | I18: #VALUE! | J18: #VALUE! | K18: #VALUE!
B19: #VALUE! | C19: #VALUE! | D19: #VALUE! | E19: #VALUE! | F19: #VALUE! | G19: #VALUE! | H19: #VALUE! | I19: #VALUE! | J19: #VALUE! | K19: #VALUE!
B20: #VALUE! | C20: #VALUE! | D20: #VALUE! | E20: #VALUE! | F20: #VALUE! | G20: #VALUE! | H20: #VALUE! | I20: #VALUE! | J20: #VALUE! | K20: #VALUE!
B21: #VALUE! | C21: #VALUE! | D21: #VALUE! | E21: #VALUE! | F21: #VALUE! | G21: #VALUE! | H21: #VALUE! | I21: #VALUE! | J21: #VALUE! | K21: #VALUE!
B22: #VALUE! | C22: #VALUE! | D22: #VALUE! | E22: #VALUE! | F22: #VALUE! | G22: #VALUE! | H22: #VALUE! | I22: #VALUE! | J22: #VALUE! | K22: #VALUE!
B23: #VALUE! | C23: #VALUE! | D23: #VALUE! | E23: #VALUE! | F23: #VALUE! | G23: #VALUE! | H23: #VALUE! | I23: #VALUE! | J23: #VALUE! | K23: #VALUE!
A24: =year!$I$4 -> RABI II 2023-24
A25: PADDY | B25: 5 | C25: 8.65 | D25: 8.8 | E25: 2 | F25: 2.46 | G25: 2.46 | H25: 7 | I25: 11.11 | J25: 11.26 | K25: 1.35
A26: OTHERS | B26: 3 | C26: 1.68 | D26: 1.68 | E26: 4 | F26: 2.39 | G26: 2.31 | H26: 7 | I26: 4.07 | J26: 3.99 | K26: (-)1.96
B27: #VALUE! | C27: #VALUE! | D27: #VALUE! | E27: #VALUE! | F27: #VALUE! | G27: #VALUE! | H27: #VALUE! | I27: #VALUE! | J27: #VALUE! | K27: #VALUE!
B28: #VALUE! | C28: #VALUE! | D28: #VALUE! | E28: #VALUE! | F28: #VALUE! | G28: #VALUE! | H28: #VALUE! | I28: #VALUE! | J28: #VALUE! | K28: #VALUE!
B29: #VALUE! | C29: #VALUE! | D29: #VALUE! | E29: #VALUE! | F29: #VALUE! | G29: #VALUE! | H29: #VALUE! | I29: #VALUE! | J29: #VALUE! | K29: #VALUE!
B30: #VALUE! | C30: #VALUE! | D30: #VALUE! | E30: #VALUE! | F30: #VALUE! | G30: #VALUE! | H30: #VALUE! | I30: #VALUE! | J30: #VALUE! | K30: #VALUE!
B31: #VALUE! | C31: #VALUE! | D31: #VALUE! | E31: #VALUE! | F31: #VALUE! | G31: #VALUE! | H31: #VALUE! | I31: #VALUE! | J31: #VALUE! | K31: #VALUE!
B32: #VALUE! | C32: #VALUE! | D32: #VALUE! | E32: #VALUE! | F32: #VALUE! | G32: #VALUE! | H32: #VALUE! | I32: #VALUE! | J32: #VALUE! | K32: #VALUE!
B33: #VALUE! | C33: #VALUE! | D33: #VALUE! | E33: #VALUE! | F33: #VALUE! | G33: #VALUE! | H33: #VALUE! | I33: #VALUE! | J33: #VALUE! | K33: #VALUE!
B34: #VALUE! | C34: #VALUE! | D34: #VALUE! | E34: #VALUE! | F34: #VALUE! | G34: #VALUE! | H34: #VALUE! | I34: #VALUE! | J34: #VALUE! | K34: #VALUE!
B35: #VALUE! | C35: #VALUE! | D35: #VALUE! | E35: #VALUE! | F35: #VALUE! | G35: #VALUE! | H35: #VALUE! | I35: #VALUE! | J35: #VALUE! | K35: #VALUE!
B36: #VALUE! | C36: #VALUE! | D36: #VALUE! | E36: #VALUE! | F36: #VALUE! | G36: #VALUE! | H36: #VALUE! | I36: #VALUE! | J36: #VALUE! | K36: #VALUE!
B37: #VALUE! | C37: #VALUE! | D37: #VALUE! | E37: #VALUE! | F37: #VALUE! | G37: #VALUE! | H37: #VALUE! | I37: #VALUE! | J37: #VALUE! | K37: #VALUE!
B38: #VALUE! | C38: #VALUE! | D38: #VALUE! | E38: #VALUE! | F38: #VALUE! | G38: #VALUE! | H38: #VALUE! | I38: #VALUE! | J38: #VALUE! | K38: #VALUE!
B39: #VALUE! | C39: #VALUE! | D39: #VALUE! | E39: #VALUE! | F39: #VALUE! | G39: #VALUE! | H39: #VALUE! | I39: #VALUE! | J39: #VALUE! | K39: #VALUE!
A40: # NOT COMPARABLE AS THE IMPACT IS 100% OR MORE
...

Sheet Annex-XVI
A1: A-11
A2: =year!$H$2 -> UT : PUDUCHERRY | G2: ANNEX-XVI
A3: ="TRAINING OF PRIMARY WORKERS UNDER CES DURING THE YEAR "& A12 &" AND "& A13&"." -> TRAINING OF PRIMARY WORKERS UNDER CES DURING THE YEAR 2023-24 AND 2022-23.
A4: YEAR | B4: AGENCY | C4: NO. OF C.E.S. TRAINING CENTRES | F4: ATTENDANCE IN TRAINING CENTRES
C5: ORGANISED BY S.A.S.A. | D5: COVERED BY N.S.O. | F5: TOTAL CALLED | G5: TOTAL TRAINED | H5: NO. OF PRIMARY WORKERS TRAINED BY N.S.O.
D6: AS TRAINING OFFICER | E6: AS OBSERVER
A7: =-(1) -> -1 | B7: -2 | C7: -3 | D7: -4 | E7: -6 | F7: -7 | G7: -8 | H7: -9
A8: SEASON : RABI-I & RABI-II
A9: 2023-24 | B9: STATISTICAL/ AGRICULTURAL | C9: 2 | D9: 2 | E9: 2 | F9: 39 | G9: 39 | H9: -
A10: 2022-23 | B10: STATISTICAL/ AGRICULTURAL | C10: 2 | D10: 3 | E10: - | F10: 24 | G10: 24 | H10: -
A11: =year!$I$3 -> SEASON : RABI II
A12: =year!$C$4 -> 2023-24 | B12: STATISTICAL/ AGRICULTURAL
A13: =year!$C$5 -> 2022-23 | B13: STATISTICAL/ AGRICULTURAL

Sheet Annex-XVII
A1: A-12
A2: =year!$H$2 -> UT : PUDUCHERRY | H2: ANNEX-XVII
A3: ="CROPWISE RESPONSE AND LEVEL OF PRECISION OF ESTIMATES UNDER CES DURING "& B4 &" AND "& F4&"." -> CROPWISE RESPONSE AND LEVEL OF PRECISION OF ESTIMATES UNDER CES DURING 2023-24 AND 2022-23.
A4: SEASON/ CROPS | B4: =year!$C$4 -> 2023-24 | C4: =year!$C$4 -> 2023-24 | D4: =year!$C$4 -> 2023-24 | E4: =year!$C$4 -> 2023-24 | F4: =year!$C$5 -> 2022-23 | G4: =year!$C$5 -> 2022-23 | H4: =year!$C$5 -> 2022-23 | I4: =year!$C$5 -> 2022-23
B5: Response | E5: Estimated Yield (% SE) | F5: Response | I5: Estimated Yield (% SE)
B6: No. of Expts. | D6: % age | F6: No. of Expts. | H6: % age
B7: Planned | C7: Analysed | F7: Planned | G7: Analysed
A8: =-(1) -> -1 | B8: -2 | C8: -3 | D8: -4 | E8: -5 | F8: -6 | G8: -7 | H8: -8 | I8: -9
A9: =year!$H$3 -> SEASON : RABI I
A10: =year!$C$9 -> PADDY | B10: 138 | C10: 138 | D10: 100 | E10: 2831(1.80) | F10: 140 | G10: 140 | H10: 100 | I10: 2902(1.87)
A25: =year!$I$3 -> SEASON : RABI II
A26: =year!E9 -> PADDY | B26: 70 | C26: 70 | D26: 100 | E26: 2909(2.88) | F26: 70 | G26: 70 | H26: 100 | I26: 3395(1.67)

Sheet Annex-XVIII
A1: A-13
A2: =year!$H$2 -> UT : PUDUCHERRY | E2: ANNEX-XVIII
A3: ="SUPERVISION OF EXPERIMENTS UNDER C.E.S. DURING "& B5&" AND "& E5&"." -> SUPERVISION OF EXPERIMENTS UNDER C.E.S. DURING 2023-24 AND 2022-23.
A4: SEASON/ CROP | B4: NO. OF EXPERIMENTS SUPERVISED BY STATISTICAL AGENCY
B5: =year!$C$4 -> 2023-24 | C5: =year!$C$4 -> 2023-24 | D5: =year!$C$4 -> 2023-24 | E5: =year!$C$5 -> 2022-23 | F5: =year!$C$5 -> 2022-23 | G5: =year!$C$5 -> 2022-23
B6: PLANNED | C6: TOTAL (%) | D6: HARVEST (%) | E6: PLANNED | F6: TOTAL (%) | G6: HARVEST (%)
A8: =-(1) -> -1 | B8: -2 | C8: -3 | D8: -4 | E8: -5 | F8: -6 | G8: -7
A9: =year!$C$3 -> RABI I
A10: =year!$C$9 -> PADDY | B10: 138 | C10: 138(100) | D10: 138(100) | E10: 140 | F10: 140 (100) | G10: 140 (100)
A11: =year!$E$3 -> RABI II
A12: =year!$E$9 -> PADDY | B12: 70 | C12: 70(100) | D12: 70(100) | E12: 70 | F12: 70 (100) | G12: 70 (100)
A13: TOTAL | B13: 208 | C13: 208(100) | D13: 208(100) | E13: 210 | F13: 210 (100) | G13: 210 (100)

Sheet Annex-XIX
A1: A-14
A2: =year!$H$2 -> UT : PUDUCHERRY | G2: ANNEX-XIX
A3: ="SAMPLE CHECK ON CROP CUTTING EXPERIMENTS DURING "& year!$C$4 &" AND "& year!$C$5 & "." -> SAMPLE CHECK ON CROP CUTTING EXPERIMENTS DURING 2023-24 AND 2022-23.
A4: SL. NO | B4: ITEM | C4: NUMBER (PERCENTAGE) OF EXPERIMENTS
C5: SEASONS
C6: =year!$C$3 -> RABI I | F6: =year!$E$3 -> RABI II
C7: CENTRAL | D7: STATE | E7: POOLED | F7: =IF(F6="","","CENTRAL") -> CENTRAL | G7: =IF(F7="","","STATE") -> STATE | H7: =IF(F8="","","POOLED") -> POOLED
A8: (1) | B8: (2) | C8: (3) | D8: (4) | E8: (5) | F8: =IF(F7="","","(6)") -> (6) | G8: =IF(G7="","","(7)") -> (7) | H8: =IF(H7="","","(8)") -> (8)
A9: =year!$J$4 -> YEAR 2023-24
A10: 1 | B10: PLANNED | C10: 10 | D10: 10 | E10: 20 | F10: 10 | G10: 10 | H10: 20
A11: 2 | B11: CHECKED AT HARVEST STAGE | C11: 10 | D11: 10 | E11: 20 | F11: 10 | G11: 10 | H11: 20
B12: PERCENTAGE | C12: (100.0) | D12: (100.0) | E12: (100.0) | F12: (100.0) | G12: (100.0) | H12: (100.0)
A13: 3 | B13: CHECKED AT POST HARVEST STAGE
B14: PERCENTAGE
A15: 4 | B15: LOST
B16: PERCENTAGE
A17: 5 | B17: REJECTED FOR ANALYSIS
B18: PERCENTAGE
A19: 6 | B19: FOR WHICH SCHEDULES NOT RECEIVED
B20: PERCENTAGE
A21: =year!$J$5 -> YEAR 2022-23
A22: 1 | B22: PLANNED | C22: 10 | D22: 10 | E22: 20 | F22: 10 | G22: 10 | H22: 20
A23: 2 | B23: CHECKED AT HARVEST STAGE | C23: 10 | D23: 10 | E23: 20 | F23: 10 | G23: 10 | H23: 20
B24: PERCENTAGE | C24: (100.0) | D24: (100.0) | E24: (100.0) | F24: (100.0) | G24: (100.0) | H24: (100.0)
A25: 3 | B25: CHECKED AT POST HARVEST STAGE
B26: PERCENTAGE
A27: 4 | B27: LOST
B28: PERCENTAGE
A29: 5 | B29: REJECTED FOR ANALYSIS
B30: PERCENTAGE
A31: 6 | B31: FOR WHICH SCHEDULES NOT RECEIVED
B32: PERCENTAGE

Sheet Annex-XX
A1: A-15
A2: =year!$H$2 -> UT : PUDUCHERRY | L2: ANNEX-XX
A3: ="CROPWISE RESPONSE IN SAMPLE CHECK ON CROP CUTTING EXPERIMENT DURING "&year!$C$4&" AND "&year!$C$5 & "." -> CROPWISE RESPONSE IN SAMPLE CHECK ON CROP CUTTING EXPERIMENT DURING 2023-24 AND 2022-23.
A4: SEASON / CROP/ AGENCY | B4: NUMBER OF EXPERIMENTS
B5: =year!$J$4 -> YEAR 2023-24 | H5: =year!$J$5 -> YEAR 2022-23
B6: PLANNED | C6: CHECKED AT HARVEST STAGE(%) | D6: CHECKED AT POST HARVEST STAGE(%) | E6: LOST(%) | F6: REJECTED FOR ANALYSIS (%) | G6: FOR WHICH SCH NOT RECEIVED (%) | H6: PLANNED | I6: CHECKED AT HARVEST STAGE(%) | J6: CHECKED AT POST HARVEST STAGE(%) | K6: LOST(%) | L6: REJECTED FOR ANALYSIS (%) | M6: FOR WHICH SCH NOT RECEIVED (%)
A7: (1) | B7: (2) | C7: (3) | D7: (4) | E7: (5) | F7: (6) | G7: (7) | H7: (8) | I7: (9) | J7: (10) | K7: (11) | L7: (12) | M7: (13)
A8: =year!$C$3 -> RABI I
A9: =year!$C$9 -> PADDY
A10: =IF(A9="","","CENTRAL" ) -> CENTRAL | B10: 10 | C10: 10 | D10: 0 | E10: 0 | F10: 0 | G10: 0 | H10: 10 | I10: 10 | J10: 0 | K10: 0 | L10: 0 | M10: 0
A11: =IF(A9="","","(%)") -> (%) | C11: (100.0) | D11: ( 0.0) | E11: ( 0.0) | F11: ( 0.0) | G11: ( 0.0) | I11: (100.0) | J11: ( 0.0) | K11: ( 0.0) | L11: ( 0.0) | M11: ( 0.0)
A12: =IF(A9="","","STATE") -> STATE | B12: 10 | C12: 10 | D12: 0 | E12: 0 | F12: 0 | G12: 0 | H12: 10 | I12: 10 | J12: 0 | K12: 0 | L12: 0 | M12: 0
A13: =IF(A9="","","(%)") -> (%) | C13: (100.0) | D13: ( 0.0) | E13: ( 0.0) | F13: ( 0.0) | G13: ( 0.0) | I13: (100.0) | J13: ( 0.0) | K13: ( 0.0) | L13: ( 0.0) | M13: ( 0.0)
A14: =IF(A9="","","POOLED") -> POOLED | B14: 20 | C14: 20 | D14: 0 | E14: 0 | F14: 0 | G14: 0 | H14: 20 | I14: 20 | J14: 0 | K14: 0 | L14: 0 | M14: 0
A15: =IF(A9="","","(%)") -> (%) | C15: (100.0) | D15: ( 0.0) | E15: ( 0.0) | F15: ( 0.0) | G15: ( 0.0) | I15: (100.0) | J15: ( 0.0) | K15: ( 0.0) | L15: ( 0.0) | M15: ( 0.0)
A17: =IF(A16="","","CENTRAL" )
A18: =IF(A16="","","(%)")
A19: =IF(A16="","","STATE")
A20: =IF(A16="","","(%)")
A21: =IF(A16="","","POOLED")
A22: =IF(A16="","","(%)")
A24: =IF(A23="","","CENTRAL" )
A25: =IF(A23="","","(%)")
A26: =IF(A23="","","STATE")
A27: =IF(A23="","","(%)")
A28: =IF(A23="","","POOLED")
A29: =IF(A23="","","(%)")
A31: =IF(A30="","","CENTRAL" )
A32: =IF(A30="","","(%)")
A33: =IF(A30="","","STATE")
A34: =IF(A30="","","(%)")
A35: =IF(A30="","","POOLED")
A36: =IF(A30="","","(%)")
A38: =IF(A37="","","CENTRAL" )
A39: =IF(A37="","","(%)")
A40: =IF(A37="","","STATE")
A41: =IF(A37="","","(%)")
A42: =IF(A37="","","POOLED")
A43: =IF(A37="","","(%)")
A45: =IF(A44="","","CENTRAL" )
...

Sheet Annex-XXI
A1: A-16
A2: =year!$H$2 -> UT : PUDUCHERRY | I2: ANNEX-XXI
A3: ="SUBSTITUTION OF SAMPLING UNITS DURING "& year!$C$4 &" AND "& year!$C$5 &"(POOLED SAMPLE)." -> SUBSTITUTION OF SAMPLING UNITS DURING 2023-24 AND 2022-23(POOLED SAMPLE).
A4: SL. NO | B4: SEASON/ CROP | C4: NO. & (%) OF EXPERIMENTS FOR WHICH SUBSTITUTION WAS DONE IN RESPECT OF
C5: SELECTED VILLAGE DUE TO REASON CODE (@) | G5: SELECTED SURVEY NOS. DUE TO REASON CODE ($)
C6: 1 | D6: 2 | E6: 3 | F6: 9 | G6: 1 | H6: 2 | I6: 3 | J6: 9
A7: (1) | B7: (2) | C7: (3) | D7: (4) | E7: (5) | F7: (6) | G7: (7) | H7: (8) | I7: (9) | J7: (10)
A8: =year!$H$4 -> RABI I 2023-24
A9: =IF(B9="","",1) -> 1 | B9: PADDY | C9: 0( 0.0) | D9: 0( 0.0) | E9: 0( 0.0) | F9: 0( 0.0) | G9: 0( 0.0) | H9: 0( 0.0) | I9: 0( 0.0) | J9: 0( 0.0)
A10: =IF(B10="","",A9+1)
A11: =IF(B11="","",A10+1)
A12: =IF(B12="","",A11+1)
A13: =IF(B13="","",A12+1)
A14: =IF(B14="","",A13+1)
A15: =IF(B15="","",A14+1)
A16: =IF(B16="","",A15+1)
A17: =IF(B17="","",A16+1)
A18: =IF(B18="","",A17+1)
A19: =IF(B19="","",A18+1)
A20: =IF(B20="","",A19+1)
A21: =IF(B21="","",A20+1)
... A23: =IF(B23="","",A22+1)
B24: TOTAL | C24: 0( 0.0) | D24: 0( 0.0) | E24: 0( 0.0) | F24: 0( 0.0) | G24: 0( 0.0) | H24: 0( 0.0) | I24: 0( 0.0) | J24: 0( 0.0)
A25: =year!$I$4 -> RABI II 2023-24
A26: =IF(B26="","",1) -> 1 | B26: PADDY | C26: 0( 0.0) | D26: 0( 0.0) | E26: 0( 0.0) | F26: 0( 0.0) | G26: 0( 0.0) | H26: 0( 0.0) | I26: 0( 0.0) | J26: 0( 0.0)
A27: =IF(B27="","",A26+1)
A28: =IF(B28="","",A27+1)
A29: =IF(B29="","",A28+1)
A30: =IF(B30="","",A29+1)
A31: =IF(B31="","",A30+1)
A32: =IF(B32="","",A31+1)
A33: =IF(B33="","",A32+1)
A34: =IF(B34="","",A33+1)
A35: =IF(B35="","",A34+1)
A36: =IF(B36="","",A35+1)
A37: =IF(B37="","",A36+1)
A38: =IF(B38="","",A37+1)
... A40: =IF(B40="","",A39+1)
B41: TOTAL | C41: 0( 0.0) | D41: 0( 0.0) | E41: 0( 0.0) | F41: 0( 0.0) | G41: 0( 0.0) | H41: 0( 0.0) | I41: 0( 0.0) | J41: 0( 0.0)
A42: =year!$H$5 -> RABI I 2022-23
...

Sheet Annex-XXII
A1: A-17
A2: =year!$H$2 -> UT : PUDUCHERRY | G2: ANNEX-XXII Contd..
A3: ="DEPARTURE FROM PRESCRIBED PROCEDURE IN EXPERIMENTS AND DISCREPANCIES IN REPORTING ANCILLARY INFORMATION DURING "& year!$C$4 &" AND "& year!$C$5 & "." -> DEPARTURE FROM PRESCRIBED PROCEDURE IN EXPERIMENTS AND DISCREPANCIES IN REPORTING ANCILLARY INFORMATION DURING 2023-24 AND 2022-23.
A4: =year!$H$3 -> SEASON : RABI I
A5: PARTICULARS | C5: =year!$J$4 -> YEAR 2023-24 | F5: =year!$J$5 -> YEAR 2022-23
C6: CENTRAL | D6: STATE | E6: POOLED | F6: CENTRAL | G6: STATE | H6: POOLED
A7: (1) | C7: (2) | D7: (3) | E7: (4) | F7: (5) | G7: (6) | H7: (7)
A8: 1. | B8: No.OF EXPTS. CHECKED | C8: 10 | D8: 10 | E8: 20 | F8: 10 | G8: 10 | H8: 20
A9: 2. | B9: NO. OF EXPET WITHOUT ERROR (E0) | C9: 6 | D9: 10 | E9: 16 | F9: 8 | G9: 9 | H9: 17
C10: ( 60.0) | D10: (100.0) | E10: ( 80.0) | F10: ( 80.0) | G10: ( 90.0) | H10: ( 85.0)
A11: 3. | B11: NO. OF EXPTS. WHICH DEPARTURE FROM INSTRUCTION IN CONDUCT OF EXPTS. WAS OBSERVED IN RESPECT OF: | C11: 0 | D11: 0 | E11: 0 | F11: 0 | G11: 0 | H11: 0
A12: I | B12: SELECTION OF SURVEY NO. (E1) | C12: 0 | D12: 0 | E12: 0 | F12: 0 | G12: 0 | H12: 0
C13: ( 0.0) | D13: ( 0.0) | E13: ( 0.0) | F13: ( 0.0) | G13: ( 0.0) | H13: ( 0.0)
A14: II | B14: SELECTION OF FIELD WITHIN SURVEY NO.(E2) | C14: 0 | D14: 0 | E14: 0 | F14: 0 | G14: 0 | H14: 0
C15: ( 0.0) | D15: ( 0.0) | E15: ( 0.0) | F15: ( 0.0) | G15: ( 0.0) | H15: ( 0.0)
A16: III | B16: MEASUREMENT OF FIELD (E9) | C16: 0 | D16: 0 | E16: 0 | F16: 0 | G16: 0 | H16: 0
C17: ( 0.0) | D17: ( 0.0) | E17: ( 0.0) | F17: ( 0.0) | G17: ( 0.0) | H17: ( 0.0)
A18: IV | B18: CHOOSING RANDOM NO. FOR LOCATION PLOT (E10) | C18: 0 | D18: 0 | E18: 0 | F18: 0 | G18: 0 | H18: 0
C19: ( 0.0) | D19: ( 0.0) | E19: ( 0.0) | F19: ( 0.0) | G19: ( 0.0) | H19: ( 0.0)
A20: V | B20: LOCATION PLOT (E11) | C20: 0 | D20: 0 | E20: 0 | F20: 0 | G20: 0 | H20: 0
C21: ( 0.0) | D21: ( 0.0) | E21: ( 0.0) | F21: ( 0.0) | G21: ( 0.0) | H21: ( 0.0)
A22: VI | B22: DIMENSION OF PLOT (E12) | C22: 0 | D22: 0 | E22: 0 | F22: 0 | G22: 0 | H22: 0
C23: ( 0.0) | D23: ( 0.0) | E23: ( 0.0) | F23: ( 0.0) | G23: ( 0.0) | H23: ( 0.0)
A24: VII | B24: WEIGHMENT OF PRODUCT (E13) | C24: 0 | D24: 0 | E24: 0 | F24: 0 | G24: 0 | H24: 0
C25: ( 0.0) | D25: ( 0.0) | E25: ( 0.0) | F25: ( 0.0) | G25: ( 0.0) | H25: ( 0.0)
A26: 4. | B26: NO. OF EXPERIMENTS WITH DISCREPANT REPORTING OF ANCILLARY PARTICULARS | C26: 0 | D26: 0 | E26: 0 | F26: 0 | G26: 0 | H26: 0
A27: I | B27: SEED VARIETY (E3) | C27: 0 | D27: 0 | E27: 0 | F27: 0 | G27: 0 | H27: 0
C28: ( 0.0) | D28: ( 0.0) | E28: ( 0.0) | F28: ( 0.0) | G28: ( 0.0) | H28: ( 0.0)
A29: II | B29: SEED RATE (E4) | C29: 0 | D29: 0 | E29: 0 | F29: 0 | G29: 1 | H29: 1
C30: ( 0.0) | D30: ( 0.0) | E30: ( 0.0) | F30: ( 0.0) | G30: ( 10.0) | H30: ( 5.0)
A31: III | B31: IRRIGATION PARTICULARS (E5) | C31: 0 | D31: 0 | E31: 0 | F31: 0 | G31: 0 | H31: 0
C32: ( 0.0) | D32: ( 0.0) | E32: ( 0.0) | F32: ( 0.0) | G32: ( 0.0) | H32: ( 0.0)
A33: IV | B33: APPLICATION OF FERTILIZERS (E6) | C33: 0 | D33: 0 | E33: 0 | F33: 0 | G33: 0 | H33: 0
C34: ( 0.0) | D34: ( 0.0) | E34: ( 0.0) | F34: ( 0.0) | G34: ( 0.0) | H34: ( 0.0)
A35: V | B35: APPLICATION OF MANURES (E7) | C35: 0 | D35: 0 | E35: 0 | F35: 1 | G35: 0 | H35: 1
C36: ( 0.0) | D36: ( 0.0) | E36: ( 0.0) | F36: ( 10.0) | G36: ( 0.0) | H36: ( 5.0)
A37: VI | B37: APPLICATION OF PESTICIDES (E8) | C37: 0 | D37: 0 | E37: 0 | F37: 0 | G37: 0 | H37: 0
C38: ( 0.0) | D38: ( 0.0) | E38: ( 0.0) | F38: ( 0.0) | G38: ( 0.0) | H38: ( 0.0)
A39: 5. | B39: NO. OF EXPTS. WHERE INADEQUATE ARRANGEMENT FOR DRIAGE WAS MADE (E14) | C39: 0 | D39: 0 | E39: 0 | F39: 0 | G39: 0 | H39: 0
C40: ( 0.0) | D40: ( 0.0) | E40: ( 0.0) | F40: ( 0.0) | G40: ( 0.0) | H40: ( 0.0)
...

Sheet Annex-XXIII
A1: A-19
A2: =year!$H$2 -> UT : PUDUCHERRY | H2: ANNEX-XXIII
A3: ="SUPPLY AND USE OF EQUIPMENTS FOR THE CONDUCT OF CROP CUTTING EXPERIMENTS DURING "& year!$C$4 &" AND "& year!$C$5 & "." -> SUPPLY AND USE OF EQUIPMENTS FOR THE CONDUCT OF CROP CUTTING EXPERIMENTS DURING 2023-24 AND 2022-23.
A4: SEASON/ AGENCY | B4: NO. & (%) OF EXPERIMENTS FOR WHICH
B5: THE PRIMARY WORKERS WERE FOUND NOT SUPPLIED WITH | F5: THE PRIMARY WORKERS WERE FOUND NOT USING THE SUPPLIED EQUIPMENTS
B6: TAPE | C6: BALANCE | D6: WEIGHT | E6: PEGS | F6: TAPE | G6: BALANCE | H6: WEIGHT | I6: PEGS
A7: (1) | B7: (2) | C7: (3) | D7: (4) | E7: (5) | F7: (6) | G7: (7) | H7: (8) | I7: (9)
A8: =year!$H$4 -> RABI I 2023-24
A9: CENTRAL | B9: 0( 0.0) | C9: 0( 0.0) | D9: 0( 0.0) | E9: 0( 0.0) | F9: 0( 0.0) | G9: 0( 0.0) | H9: 0( 0.0) | I9: 0( 0.0)
A10: STATE | B10: 0( 0.0) | C10: 0( 0.0) | D10: 0( 0.0) | E10: 0( 0.0) | F10: 0( 0.0) | G10: 0( 0.0) | H10: 0( 0.0) | I10: 0( 0.0)
A11: POOLED | B11: 0( 0.0) | C11: 0( 0.0) | D11: 0( 0.0) | E11: 0( 0.0) | F11: 0( 0.0) | G11: 0( 0.0) | H11: 0( 0.0) | I11: 0( 0.0)
A12: =year!$I$4 -> RABI II 2023-24
A13: =IF(A12="","","CENTRAL") -> CENTRAL | B13: 0( 0.0) | C13: 0( 0.0) | D13: 0( 0.0) | E13: 0( 0.0) | F13: 0( 0.0) | G13: 0( 0.0) | H13: 0( 0.0) | I13: 0( 0.0)
