Workbook

Sheet Dist-wise
B1: District | C1: PAD-KK | D1: PAD-S | E1: PAD-S | F1: PAD-NK | G1: CHLM_K | H1: CHLM_K | I1: CHLM_R | J1: CHLM_R | K1: CMBU_K | L1: CMBU_K | M1: CMBU_R | N1: CMBU_R | O1: RAGI-K | P1: RAGI-K | Q1: RAGI-R | R1: MAIZE_K | S1: MAIZE_K | T1: MAIZE_R | U1: MAIZE_R | V1: RGRM_K | W1: BGRM_K | X1: BGRM_K | Y1: BGRM_R | Z1: BGRM_R | AA1: GGRM_K | AB1: GGRM_R | AC1: GGRM_R | AD1: HGRM_R | AE1: VRGU_K | AF1: SMAI_K | AG1: COTT_K | AH1: COTT_K | AI1: COTT_R | AJ1: COTT_R | AK1: GNUT_K | AL1: GNUT_K | AM1: GNUT_R | AN1: GNUT_R | AO1: SCAN_K | AP1: GNGL_K | AQ1: GNGL_K | AR1: GNGL_R | AS1: GNGL_R | AT1: SUNF_K | AU1: SUNF_K | AV1: SUNF_R | AW1: SUNF_R | AX1: COWP_K | AY1: COWP_R | AZ1: THINAI | BA1: KUDIRAI VALI | BB1: PANI VARAGU | BC1: BENGAL GRAM | BD1: MOCHAI | BE1: SOYA BEAN | BF1: CASTOR | BG1: G. Total
C2: (1-1) | D2: (2-1) | E2: (2-2) | F2: (3-1) | G2: (4-1) | H2: (4-2) | I2: (5-1) | J2: (5-2) | K2: (6-1) | L2: (6-2) | M2: (7-1) | N2: (7-2) | O2: (8-1) | P2: (8-2) | Q2: (9-1) | R2: (10-1) | S2: (10-2) | T2: (11-1) | U2: (11-2) | V2: (12-2) | W2: (14-1) | X2: (14-2) | Y2: (15-1) | Z2: (15-2) | AA2: (16-2) | AB2: (17-1) | AC2: (17-2) | AD2: (19-2) | AE2: (20-2) | AF2: (22-2) | AG2: (24-1) | AH2: (24-2) | AI2: (25-1) | AJ2: (25-2) | AK2: (26-1) | AL2: (26-2) | AM2: (27-1) | AN2: (27-2) | AO2: (28-1) | AP2: (29-1) | AQ2: (29-2) | AR2: (30-1) | AS2: (30-2) | AT2: (31-1) | AU2: (31-2) | AV2: (32-1) | AW2: (32-2) | AX2: (33-2) | AY2: (34-2) | AZ2: 35 | BA2: 36 | BB2: 37 | BC2: 38 | BD2: 39 | BE2: 40 | BF2: 41
A3: 1 | B3: KANCHEEPURAM | C3: 20 | D3: 20 | E3: - | F3: 8 | G3: - | H3: - | I3: - | J3: - | K3: - | L3: - | M3: - | N3: - | O3: - | P3: - | Q3: - | R3: - | S3: - | T3: - | U3: - | V3: - | W3: - | X3: - | Y3: - | Z3: - | AA3: - | AB3: - | AC3: - | AD3: - | AE3: - | AF3: - | AG3: - | AH3: - | AI3: - | AJ3: - | AK3: 12 | AL3: - | AM3: 4 | AN3: - | AO3: 4 | AP3: 8 | AQ3: - | AR3: - | AS3: - | AT3: - | AU3: - | AV3: - | AW3: - | AX3: - | AY3: - | AZ3: - | BA3: - | BG3: 76
A4: 2 | B4: THIRUVALLUR | C4: 36 | D4: 52 | E4: - | F4: 20 | G4: - | H4: - | I4: - | J4: - | K4: - | L4: - | M4: - | N4: - | O4: - | P4: - | Q4: - | R4: - | S4: - | T4: - | U4: - | V4: - | W4: - | X4: - | Y4: - | Z4: - | AA4: - | AB4: 16 | AC4: - | AD4: - | AE4: - | AF4: - | AG4: - | AH4: - | AI4: - | AJ4: - | AK4: - | AL4: - | AM4: 16 | AN4: - | AO4: 16 | AP4: - | AQ4: - | AR4: - | AS4: - | AT4: - | AU4: - | AV4: - | AW4: - | AX4: - | AY4: - | AZ4: - | BA4: - | BE4: 4 | BG4: 160
A5: 3 | B5: CUDDALORE | C5: 48 | D5: 84 | E5: - | F5: 16 | G5: - | H5: - | I5: - | J5: - | K5: 20 | L5: 16 | M5: - | N5: 8 | O5: - | P5: - | Q5: - | R5: - | S5: 16 | T5: - | U5: - | V5: - | W5: - | X5: - | Y5: - | Z5: 28 | AA5: - | AB5: - | AC5: 20 | AD5: - | AE5: 48 | AF5: - | AG5: - | AH5: 36 | AI5: - | AJ5: - | AK5: 16 | AL5: - | AM5: 16 | AN5: - | AO5: 32 | AP5: - | AQ5: 16 | AR5: 16 | AS5: - | AT5: - | AU5: - | AV5: - | AW5: - | AX5: - | AY5: - | AZ5: 4 | BA5: - | BG5: 440
A6: 4 | B6: VILLUPURAM | C6: 24 | D6: 52 | E6: - | F6: 8 | G6: - | H6: - | I6: - | J6: - | K6: 12 | L6: 48 | M6: - | N6: - | O6: - | P6: - | Q6: 20 | R6: - | S6: - | T6: - | U6: - | V6: - | W6: - | X6: 16 | Y6: 24 | Z6: 8 | AA6: - | AB6: - | AC6: - | AD6: - | AE6: - | AF6: - | AG6: - | AH6: - | AI6: - | AJ6: - | AK6: 12 | AL6: 36 | AM6: 28 | AN6: - | AO6: 24 | AP6: - | AQ6: - | AR6: 8 | AS6: 8 | AT6: - | AU6: - | AV6: - | AW6: - | AX6: - | AY6: - | AZ6: 4 | BA6: - | BG6: 332
A7: 5 | B7: VELLORE | C7: - | D7: - | E7: - | F7: 4 | G7: - | H7: 4 | I7: - | J7: - | K7: - | L7: 4 | M7: - | N7: - | O7: - | P7: - | Q7: 20 | R7: - | S7: - | T7: - | U7: - | V7: 36 | W7: - | X7: 4 | Y7: - | Z7: - | AA7: 4 | AB7: - | AC7: - | AD7: 10 | AE7: - | AF7: 4 | AG7: - | AH7: 4 | AI7: - | AJ7: - | AK7: - | AL7: 28 | AM7: - | AN7: - | AO7: 4 | AP7: - | AQ7: - | AR7: - | AS7: - | AT7: - | AU7: - | AV7: - | AW7: - | AX7: 6 | AY7: - | AZ7: - | BA7: - | BD7: 4 | BG7: 136
A8: 6 | B8: THIRUVANNAMALAI | C8: 24 | D8: 52 | E8: - | F8: 20 | G8: - | H8: - | I8: - | J8: - | K8: - | L8: 44 | M8: - | N8: - | O8: - | P8: - | Q8: 32 | R8: - | S8: - | T8: - | U8: - | V8: 16 | W8: - | X8: 16 | Y8: 16 | Z8: 16 | AA8: - | AB8: - | AC8: - | AD8: 16 | AE8: - | AF8: 16 | AG8: 24 | AH8: - | AI8: - | AJ8: - | AK8: 24 | AL8: 72 | AM8: 48 | AN8: 16 | AO8: 36 | AP8: 16 | AQ8: - | AR8: - | AS8: 32 | AT8: - | AU8: - | AV8: - | AW8: - | AX8: - | AY8: 10 | AZ8: - | BA8: - | BE8: 4 | BG8: 550
A9: 7 | B9: SALEM | C9: - | D9: 16 | E9: - | F9: 16 | G9: - | H9: 60 | I9: 36 | J9: 24 | K9: - | L9: - | M9: 8 | N9: - | O9: - | P9: 20 | Q9: 28 | R9: 20 | S9: 16 | T9: 16 | U9: - | V9: 24 | W9: - | X9: 16 | Y9: - | Z9: - | AA9: 32 | AB9: - | AC9: - | AD9: 32 | AE9: - | AF9: 16 | AG9: 16 | AH9: 48 | AI9: 16 | AJ9: - | AK9: - | AL9: 56 | AM9: 16 | AN9: - | AO9: 16 | AP9: 16 | AQ9: 16 | AR9: 16 | AS9: - | AT9: - | AU9: - | AV9: - | AW9: - | AX9: 16 | AY9: 16 | AZ9: 4 | BA9: - | BB9: 4 | BD9: 16 | BE9: 4 | BF9: 4 | BG9: 660
A10: 8 | B10: NAMAKKAL | C10: - | D10: 16 | E10: - | F10: - | G10: 16 | H10: 80 | I10: 30 | J10: 86 | K10: - | L10: - | M10: - | N10: - | O10: 16 | P10: - | Q10: - | R10: - | S10: - | T10: 16 | U10: - | V10: - | W10: - | X10: - | Y10: - | Z10: - | AA10: 20 | AB10: - | AC10: - | AD10: - | AE10: - | AF10: - | AG10: 16 | AH10: 16 | AI10: - | AJ10: - | AK10: - | AL10: 68 | AM10: 16 | AN10: - | AO10: 20 | AP10: - | AQ10: - | AR10: 16 | AS10: - | AT10: - | AU10: - | AV10: - | AW10: - | AX10: - | AY10: - | AZ10: 4 | BA10: - | BC10: 4 | BF10: 4 | BG10: 444
A11: 9 | B11: DHARMAPURI | C11: - | D11: 28 | E11: - | F11: 16 | G11: - | H11: 32 | I11: - | J11: - | K11: - | L11: - | M11: - | N11: - | O11: - | P11: 32 | Q11: 40 | R11: 12 | S11: 20 | T11: - | U11: - | V11: 48 | W11: - | X11: 16 | Y11: - | Z11: - | AA11: 16 | AB11: - | AC11: - | AD11: 50 | AE11: - | AF11: 36 | AG11: - | AH11: 56 | AI11: - | AJ11: - | AK11: - | AL11: 20 | AM11: 16 | AN11: - | AO11: 16 | AP11: - | AQ11: 16 | AR11: - | AS11: - | AT11: - | AU11: - | AV11: - | AW11: - | AX11: 16 | AY11: - | AZ11: 4 | BA11: - | BB11: 4 | BC11: 4 | BD11: 16 | BF11: 4 | BG11: 518
A12: 10 | B12: COIMBATORE | C12: - | D12: - | E12: - | F12: - | G12: - | H12: 32 | I12: - | J12: 36 | K12: - | L12: - | M12: - | N12: 8 | O12: - | P12: - | Q12: - | R12: - | S12: - | T12: - | U12: - | V12: - | W12: - | X12: - | Y12: - | Z12: - | AA12: - | AB12: - | AC12: - | AD12: 16 | AE12: - | AF12: - | AG12: - | AH12: - | AI12: - | AJ12: - | AK12: - | AL12: 16 | AM12: - | AN12: - | AO12: - | AP12: - | AQ12: - | AR12: - | AS12: - | AT12: - | AU12: - | AV12: - | AW12: - | AX12: 16 | AY12: 16 | AZ12: - | BA12: - | BC12: 4 | BG12: 144
A13: 11 | B13: ERODE | C13: - | D13: 16 | E13: - | F13: - | G13: - | H13: - | I13: - | J13: - | K13: - | L13: - | M13: - | N13: - | O13: - | P13: 16 | Q13: - | R13: 20 | S13: 16 | T13: 16 | U13: - | V13: 16 | W13: - | X13: - | Y13: - | Z13: - | AA13: - | AB13: - | AC13: - | AD13: - | AE13: 8 | AF13: - | AG13: - | AH13: - | AI13: - | AJ13: - | AK13: 16 | AL13: 44 | AM13: 16 | AN13: - | AO13: 36 | AP13: - | AQ13: - | AR13: 16 | AS13: - | AT13: - | AU13: 4 | AV13: - | AW13: - | AX13: - | AY13: - | AZ13: - | BA13: - | BG13: 240
A14: 12 | B14: TIRUCHIRAPPALLI | C14: 16 | D14: 48 | E14: - | F14: 16 | G14: - | H14: 44 | I14: 16 | J14: 20 | K14: - | L14: - | M14: - | N14: - | O14: - | P14: - | Q14: - | R14: - | S14: 16 | T14: - | U14: - | V14: 16 | W14: - | X14: - | Y14: - | Z14: 16 | AA14: - | AB14: - | AC14: - | AD14: - | AE14: - | AF14: - | AG14: - | AH14: 72 | AI14: - | AJ14: - | AK14: - | AL14: 20 | AM14: 16 | AN14: - | AO14: 16 | AP14: - | AQ14: - | AR14: 16 | AS14: - | AT14: 16 | AU14: 8 | AV14: - | AW14: 8 | AX14: - | AY14: - | AZ14: - | BA14: - | BF14: 4 | BG14: 384
A15: 13 | B15: KARUR | C15: - | D15: 16 | E15: - | F15: - | G15: 20 | H15: 24 | I15: 16 | J15: 24 | K15: - | L15: - | M15: - | N15: 20 | O15: - | P15: - | Q15: - | R15: - | S15: - | T15: - | U15: - | V15: 16 | W15: - | X15: - | Y15: - | Z15: - | AA15: - | AB15: - | AC15: - | AD15: 16 | AE15: - | AF15: - | AG15: - | AH15: - | AI15: - | AJ15: - | AK15: - | AL15: - | AM15: 16 | AN15: - | AO15: 16 | AP15: - | AQ15: 24 | AR15: - | AS15: - | AT15: 36 | AU15: - | AV15: 16 | AW15: - | AX15: - | AY15: - | AZ15: - | BA15: - | BG15: 260
A16: 14 | B16: PERAMBALUR | C16: - | D16: 16 | E16: - | F16: - | G16: - | H16: - | I16: - | J16: - | K16: - | L16: - | M16: - | N16: - | O16: - | P16: - | Q16: - | R16: - | S16: 20 | T16: - | U16: - | V16: 16 | W16: - | X16: - | Y16: - | Z16: - | AA16: - | AB16: - | AC16: - | AD16: - | AE16: 16 | AF16: - | AG16: - | AH16: 64 | AI16: - | AJ16: - | AK16: - | AL16: - | AM16: 16 | AN16: - | AO16: 16 | AP16: - | AQ16: - | AR16: - | AS16: - | AT16: - | AU16: 4 | AV16: - | AW16: - | AX16: - | AY16: - | AZ16: - | BA16: - | BG16: 168
A17: 15 | B17: THANJAVUR | C17: 36 | D17: 92 | E17: - | F17: 16 | G17: - | H17: - | I17: - | J17: - | K17: - | L17: - | M17: - | N17: - | O17: - | P17: - | Q17: - | R17: - | S17: - | T17: - | U17: - | V17: - | W17: 32 | X17: - | Y17: - | Z17: 16 | AA17: - | AB17: - | AC17: 16 | AD17: - | AE17: - | AF17: - | AG17: - | AH17: - | AI17: - | AJ17: - | AK17: - | AL17: - | AM17: 16 | AN17: - | AO17: 16 | AP17: 20 | AQ17: - | AR17: 16 | AS17: 28 | AT17: - | AU17: - | AV17: - | AW17: - | AX17: - | AY17: - | AZ17: - | BA17: - | BE17: 4 | BG17: 308
A18: 16 | B18: THIRUVARUR | C18: 36 | D18: 92 | E18: - | F18: 16 | G18: - | H18: - | I18: - | J18: - | K18: - | L18: - | M18: - | N18: - | O18: - | P18: - | Q18: - | R18: - | S18: - | T18: - | U18: - | V18: - | W18: - | X18: - | Y18: 12 | Z18: 32 | AA18: - | AB18: - | AC18: 68 | AD18: - | AE18: - | AF18: - | AG18: - | AH18: - | AI18: 16 | AJ18: - | AK18: - | AL18: - | AM18: 16 | AN18: - | AO18: - | AP18: - | AQ18: - | AR18: - | AS18: 16 | AT18: - | AU18: - | AV18: - | AW18: - | AX18: - | AY18: - | AZ18: - | BA18: - | BG18: 304
A19: 17 | B19: NAGAPATTINAM | C19: 4 | D19: 48 | E19: - | F19: - | G19: - | H19: - | I19: - | J19: - | K19: - | L19: - | M19: - | N19: - | O19: - | P19: - | Q19: - | R19: - | S19: - | T19: - | U19: - | V19: - | W19: - | X19: - | Y19: - | Z19: 8 | AA19: - | AB19: - | AC19: 28 | AD19: - | AE19: - | AF19: - | AG19: - | AH19: - | AI19: 4 | AJ19: - | AK19: - | AL19: - | AM19: - | AN19: - | AO19: - | AP19: - | AQ19: - | AR19: - | AS19: - | AT19: - | AU19: - | AV19: - | AW19: - | AX19: - | AY19: - | AZ19: - | BA19: - | BG19: 92
A20: 18 | B20: PUDUKOTTAI | C20: 16 | D20: 72 | E20: - | F20: 16 | G20: - | H20: - | I20: - | J20: - | K20: - | L20: - | M20: - | N20: - | O20: - | P20: - | Q20: - | R20: - | S20: - | T20: - | U20: - | V20: 24 | W20: - | X20: - | Y20: - | Z20: - | AA20: - | AB20: - | AC20: - | AD20: - | AE20: - | AF20: - | AG20: - | AH20: - | AI20: - | AJ20: - | AK20: 16 | AL20: 16 | AM20: 16 | AN20: - | AO20: 16 | AP20: - | AQ20: - | AR20: - | AS20: 16 | AT20: - | AU20: - | AV20: - | AW20: - | AX20: - | AY20: - | AZ20: - | BA20: - | BG20: 208
A21: 19 | B21: MADURAI | C21: - | D21: 40 | E21: - | F21: 16 | G21: - | H21: 20 | I21: - | J21: 16 | K21: - | L21: 16 | M21: - | N21: 16 | O21: - | P21: - | Q21: - | R21: - | S21: 16 | T21: - | U21: - | V21: 16 | W21: - | X21: - | Y21: - | Z21: - | AA21: 16 | AB21: - | AC21: - | AD21: - | AE21: 24 | AF21: - | AG21: - | AH21: 24 | AI21: 16 | AJ21: 16 | AK21: - | AL21: 16 | AM21: - | AN21: - | AO21: 16 | AP21: - | AQ21: - | AR21: - | AS21: - | AT21: - | AU21: - | AV21: - | AW21: - | AX21: 16 | AY21: 16 | AZ21: - | BA21: 4 | BB21: 4 | BD21: 4 | BG21: 328
A22: 20 | B22: THENI | C22: 16 | D22: 16 | E22: - | F22: - | G22: - | H22: 16 | I22: 16 | J22: 16 | K22: - | L22: - | M22: - | N22: 24 | O22: - | P22: - | Q22: - | R22: - | S22: - | T22: - | U22: - | V22: 16 | W22: - | X22: - | Y22: - | Z22: - | AA22: 16 | AB22: - | AC22: 16 | AD22: - | AE22: - | AF22: - | AG22: 16 | AH22: - | AI22: 16 | AJ22: - | AK22: - | AL22: 16 | AM22: - | AN22: - | AO22: 16 | AP22: - | AQ22: 16 | AR22: - | AS22: - | AT22: - | AU22: - | AV22: - | AW22: - | AX22: 16 | AY22: 16 | AZ22: - | BA22: - | BD22: 16 | BG22: 280
A23: 21 | B23: DINDIGUL | C23: - | D23: 16 | E23: - | F23: 16 | G23: - | H23: 24 | I23: 16 | J23: 92 | K23: - | L23: - | M23: - | N23: 16 | O23: - | P23: - | Q23: - | R23: - | S23: - | T23: 16 | U23: 16 | V23: - | W23: - | X23: - | Y23: - | Z23: 16 | AA23: - | AB23: - | AC23: 16 | AD23: 16 | AE23: - | AF23: - | AG23: - | AH23: - | AI23: 16 | AJ23: 16 | AK23: - | AL23: 16 | AM23: 16 | AN23: 16 | AO23: 16 | AP23: - | AQ23: - | AR23: - | AS23: - | AT23: 12 | AU23: - | AV23: 32 | AW23: - | AX23: 16 | AY23: 32 | AZ23: - | BA23: - | BC23: 4 | BD23: 8 | BG23: 460
A24: 22 | B24: RAMANATHAPURAM | C24: - | D24: - | E24: 92 | F24: - | G24: - | H24: - | I24: - | J24: 16 | K24: - | L24: - | M24: - | N24: 16 | O24: - | P24: - | Q24: - | R24: - | S24: - | T24: - | U24: - | V24: - | W24: - | X24: - | Y24: - | Z24: 16 | AA24: - | AB24: - | AC24: - | AD24: - | AE24: - | AF24: - | AG24: - | AH24: - | AI24: - | AJ24: 16 | AK24: - | AL24: - | AM24: - | AN24: 20 | AO24: - | AP24: - | AQ24: - | AR24: - | AS24: 16 | AT24: - | AU24: - | AV24: - | AW24: 32 | AX24: - | AY24: - | AZ24: - | BA24: 4 | BB24: 4 | BG24: 232
A25: 23 | B25: VIRUDHUNAGAR | C25: - | D25: 24 | E25: - | F25: 16 | G25: - | H25: 16 | I25: - | J25: 44 | K25: - | L25: - | M25: - | N25: 32 | O25: - | P25: - | Q25: - | R25: - | S25: 16 | T25: 16 | U25: 16 | V25: - | W25: - | X25: - | Y25: - | Z25: - | AA25: 16 | AB25: - | AC25: 16 | AD25: - | AE25: - | AF25: - | AG25: - | AH25: 28 | AI25: 16 | AJ25: 40 | AK25: - | AL25: 16 | AM25: - | AN25: 20 | AO25: 16 | AP25: - | AQ25: 16 | AR25: - | AS25: 16 | AT25: - | AU25: 4 | AV25: - | AW25: 52 | AX25: - | AY25: - | AZ25: - | BA25: 4 | BB25: 4 | BG25: 444
A26: 24 | B26: SIVAGANGAI | C26: - | D26: 72 | E26: - | F26: - | G26: - | H26: - | I26: - | J26: - | K26: - | L26: - | M26: - | N26: - | O26: - | P26: - | Q26: - | R26: - | S26: - | T26: - | U26: - | V26: - | W26: - | X26: - | Y26: - | Z26: - | AA26: - | AB26: - | AC26: - | AD26: - | AE26: - | AF26: - | AG26: - | AH26: - | AI26: - | AJ26: - | AK26: - | AL26: 16 | AM26: - | AN26: - | AO26: 16 | AP26: - | AQ26: - | AR26: - | AS26: - | AT26: - | AU26: - | AV26: - | AW26: - | AX26: - | AY26: - | AZ26: - | BA26: 4 | BG26: 108
A27: 25 | B27: TIRUNELVELI | C27: 4 | D27: 36 | E27: - | F27: 8 | G27: - | H27: - | I27: - | J27: - | K27: - | L27: - | M27: - | N27: - | O27: - | P27: - | Q27: - | R27: - | S27: - | T27: - | U27: - | V27: - | W27: - | X27: - | Y27: - | Z27: 4 | AA27: - | AB27: - | AC27: - | AD27: - | AE27: - | AF27: - | AG27: - | AH27: - | AI27: - | AJ27: - | AK27: - | AL27: - | AM27: - | AN27: - | AO27: - | AP27: - | AQ27: - | AR27: - | AS27: - | AT27: - | AU27: 4 | AV27: - | AW27: - | AX27: - | AY27: - | AZ27: - | BA27: - | BG27: 56
A28: 26 | B28: THOOTHUKUDI | C28: - | D28: 16 | E28: - | F28: 16 | G28: - | H28: - | I28: - | J28: 32 | K28: - | L28: - | M28: - | N28: 56 | O28: - | P28: - | Q28: - | R28: - | S28: - | T28: - | U28: 16 | V28: - | W28: - | X28: - | Y28: - | Z28: 28 | AA28: - | AB28: - | AC28: 52 | AD28: - | AE28: - | AF28: - | AG28: - | AH28: - | AI28: - | AJ28: 24 | AK28: - | AL28: - | AM28: - | AN28: - | AO28: - | AP28: - | AQ28: - | AR28: - | AS28: - | AT28: - | AU28: - | AV28: - | AW28: 48 | AX28: - | AY28: - | AZ28: - | BG28: 288
A29: 27 | B29: KANYAKUMARI | C29: 16 | D29: 16 | E29: - | F29: - | G29: - | H29: - | I29: - | J29: - | K29: - | L29: - | M29: - | N29: - | O29: - | P29: - | Q29: - | R29: - | S29: - | T29: - | U29: - | V29: - | W29: - | X29: - | Y29: - | Z29: - | AA29: - | AB29: - | AC29: - | AD29: - | AE29: - | AF29: - | AG29: - | AH29: - | AI29: - | AJ29: - | AK29: - | AL29: - | AM29: - | AN29: - | AO29: - | AP29: - | AQ29: - | AR29: - | AS29: - | AT29: - | AU29: - | AV29: - | AW29: - | AX29: - | AY29: - | AZ29: - | BG29: 32
A30: 28 | B30: THE NILGIRIS | C30: - | D30: - | E30: - | F30: - | G30: - | H30: - | I30: - | J30: - | K30: - | L30: - | M30: - | N30: - | O30: - | P30: - | Q30: - | R30: - | S30: - | T30: - | U30: - | V30: - | W30: - | X30: - | Y30: - | Z30: - | AA30: - | AB30: - | AC30: - | AD30: - | AE30: - | AF30: - | AG30: - | AH30: - | AI30: - | AJ30: - | AK30: - | AL30: - | AM30: - | AN30: - | AO30: - | AP30: - | AQ30: - | AR30: - | AS30: - | AT30: - | AU30: - | AV30: - | AW30: - | AX30: - | AY30: - | AZ30: - | BG30: 0
A31: 29 | B31: KRISHNAGIRI | C31: 16 | D31: 16 | E31: - | F31: 16 | G31: - | H31: 16 | I31: - | J31: - | K31: - | L31: - | M31: - | N31: - | O31: - | P31: 60 | Q31: 40 | R31: 16 | S31: - | T31: - | U31: - | V31: 48 | W31: - | X31: - | Y31: - | Z31: - | AA31: - | AB31: - | AC31: - | AD31: 88 | AE31: - | AF31: 16 | AG31: - | AH31: 16 | AI31: - | AJ31: - | AK31: - | AL31: 36 | AM31: 16 | AN31: - | AO31: - | AP31: - | AQ31: 16 | AR31: - | AS31: - | AT31: - | AU31: - | AV31: - | AW31: - | AX31: 16 | AY31: - | AZ31: - | BD31: 16 | BF31: 4 | BG31: 452
A32: 30 | B32: ARIYALUR | C32: 16 | D32: 28 | E32: - | F32: - | G32: - | H32: - | I32: - | J32: - | K32: - | L32: 16 | M32: - | N32: - | O32: - | P32: - | Q32: - | R32: - | S32: 16 | T32: - | U32: - | V32: - | W32: - | X32: - | Y32: - | Z32: 16 | AA32: - | AB32: - | AC32: - | AD32: - | AE32: 8 | AF32: - | AG32: - | AH32: 48 | AI32: - | AJ32: - | AK32: 16 | AL32: 16 | AM32: 16 | AN32: - | AO32: 16 | AP32: 20 | AQ32: - | AR32: - | AS32: - | AT32: 4 | AU32: 16 | AV32: - | AW32: - | AX32: - | AY32: - | AZ32: - | BG32: 252
A33: 31 | B33: THIRUPPUR | C33: - | D33: 16 | E33: - | F33: - | G33: - | H33: 24 | I33: - | J33: 104 | K33: - | L33: - | M33: - | N33: - | O33: - | P33: - | Q33: - | R33: 16 | S33: - | T33: 16 | U33: - | V33: - | W33: - | X33: - | Y33: - | Z33: - | AA33: - | AB33: - | AC33: 16 | AD33: 28 | AE33: - | AF33: - | AG33: - | AH33: - | AI33: 16 | AJ33: - | AK33: - | AL33: 16 | AM33: 16 | AN33: - | AO33: 16 | AP33: - | AQ33: - | AR33: - | AS33: - | AT33: - | AU33: - | AV33: - | AW33: - | AX33: - | AY33: 16 | AZ33: - | BC33: 4 | BG33: 304
A34: 32 | B34: CHANGALPATTU | C34: 16 | D34: 28 | E34: - | F34: 12 | G34: - | H34: - | I34: - | J34: - | K34: - | L34: - | M34: - | N34: - | O34: - | P34: - | Q34: - | R34: - | S34: - | T34: - | U34: - | V34: - | W34: - | X34: - | Y34: - | Z34: - | AA34: - | AB34: - | AC34: - | AD34: - | AE34: - | AF34: - | AG34: - | AH34: - | AI34: - | AJ34: - | AK34: 4 | AL34: - | AM34: 16 | AN34: - | AO34: 12 | AP34: 8 | AQ34: - | AR34: - | AS34: - | AT34: - | AU34: - | AV34: - | AW34: - | AX34: - | AY34: - | AZ34: - | BG34: 96
A35: 33 | B35: KALLAKURICHI | C35: 12 | D35: 36 | E35: - | F35: 8 | G35: - | H35: - | I35: - | J35: - | K35: - | L35: 48 | M35: - | N35: - | O35: - | P35: - | Q35: - | R35: 20 | S35: - | T35: 16 | U35: - | V35: - | W35: - | X35: - | Y35: - | Z35: 20 | AA35: - | AB35: - | AC35: - | AD35: - | AE35: 20 | AF35: - | AG35: 28 | AH35: 20 | AI35: - | AJ35: - | AK35: 8 | AL35: 8 | AM35: 4 | AN35: - | AO35: 32 | AP35: - | AQ35: - | AR35: 12 | AS35: 8 | AT35: - | AU35: - | AV35: - | AW35: - | AX35: - | AY35: - | AZ35: - | BG35: 300
A36: 34 | B36: RANIPET | C36: 16 | D36: 12 | E36: - | F36: 12 | G36: - | H36: - | I36: - | J36: - | K36: - | L36: 4 | M36: - | N36: - | O36: - | P36: - | Q36: - | R36: - | S36: - | T36: - | U36: - | V36: 16 | W36: - | X36: 4 | Y36: - | Z36: - | AA36: - | AB36: - | AC36: - | AD36: - | AE36: - | AF36: - | AG36: - | AH36: - | AI36: - | AJ36: - | AK36: - | AL36: 16 | AM36: 16 | AN36: - | AO36: 8 | AP36: - | AQ36: - | AR36: - | AS36: - | AT36: - | AU36: - | AV36: - | AW36: - | AX36: 4 | AY36: - | AZ36: - | BG36: 108
A37: 35 | B37: TIRUPPATHUR | C37: - | D37: 4 | E37: - | F37: - | G37: - | H37: 12 | I37: - | J37: - | K37: - | L37: 12 | M37: - | N37: - | O37: - | P37: 16 | Q37: 20 | R37: - | S37: - | T37: - | U37: - | V37: 28 | W37: - | X37: 8 | Y37: - | Z37: - | AA37: 12 | AB37: - | AC37: - | AD37: 28 | AE37: - | AF37: 12 | AG37: - | AH37: 32 | AI37: - | AJ37: - | AK37: - | AL37: 28 | AM37: - | AN37: - | AO37: 4 | AP37: - | AQ37: - | AR37: - | AS37: - | AT37: - | AU37: - | AV37: - | AW37: - | AX37: - | AY37: - | AZ37: - | BG37: 216
A38: 36 | B38: THENKASI | C38: 16 | D38: 28 | E38: - | F38: 8 | G38: - | H38: - | I38: - | J38: - | K38: - | L38: - | M38: - | N38: - | O38: - | P38: - | Q38: - | R38: - | S38: - | T38: - | U38: 16 | V38: - | W38: - | X38: - | Y38: - | Z38: 16 | AA38: - | AB38: - | AC38: 16 | AD38: - | AE38: - | AF38: - | AG38: - | AH38: - | AI38: - | AJ38: 16 | AK38: - | AL38: - | AM38: - | AN38: - | AO38: 16 | AP38: - | AQ38: 16 | AR38: - | AS38: - | AT38: 12 | AU38: - | AV38: - | AW38: 16 | AX38: - | AY38: - | AZ38: - | BA38: 4 | BG38: 180
A39: 37 | B39: MYLADUTHURAI | C39: 40 | D39: 44 | E39: - | F39: - | G39: - | H39: - | I39: - | J39: - | K39: - | L39: - | M39: - | N39: - | O39: - | P39: - | Q39: - | R39: - | S39: - | T39: - | U39: - | V39: - | W39: - | X39: - | Y39: - | Z39: 20 | AA39: - | AB39: - | AC39: 28 | AD39: - | AE39: - | AF39: - | AG39: - | AH39: - | AI39: 12 | AJ39: - | AK39: - | AL39: - | AM39: 16 | AN39: - | AO39: - | AP39: - | AQ39: - | AR39: - | AS39: - | AT39: - | AU39: - | AV39: - | AW39: - | AX39: - | AY39: - | AZ39: - | BE39: 4 | BG39: 164
B40: TOTAL | C40: 428 | D40: 1168 | E40: 92 | F40: 300 | G40: 36 | H40: 404 | I40: 130 | J40: 510 | K40: 32 | L40: 208 | M40: 8 | N40: 196 | O40: 16 | P40: 144 | Q40: 200 | R40: 104 | S40: 152 | T40: 112 | U40: 64 | V40: 336 | W40: 32 | X40: 80 | Y40: 52 | Z40: 260 | AA40: 132 | AB40: 16 | AC40: 292 | AD40: 300 | AE40: 124 | AF40: 100 | AG40: 100 | AH40: 464 | AI40: 128 | AJ40: 128 | AK40: 124 | AL40: 576 | AM40: 388 | AN40: 72 | AO40: 468 | AP40: 88 | AQ40: 136 | AR40: 116 | AS40: 140 | AT40: 80 | AU40: 40 | AV40: 48 | AW40: 156 | AX40: 122 | AY40: 122 | AZ40: 20 | BA40: 20 | BB40: 20 | BC40: 20 | BD40: 80 | BE40: 20 | BF40: 20 | BG40: 9724

Sheet GCES
A1: CROP ESTIMATION SURVEY FASLI 1435 (2025- 2026) DISTRICT WISE ALLOCATION
A2: SL. NO | B2: District | C2: PAD-KK | D2: PAD-S | E2: PAD-S | F2: PAD-NK | G2: CHLM_K | H2: CHLM_K | I2: CHLM_R | J2: CHLM_R | K2: CMBU_K | L2: CMBU_K | M2: CMBU_R | N2: CMBU_R | O2: RAGI-K | P2: RAGI-K | Q2: RAGI-R | R2: MAIZE_K | S2: MAIZE_K | T2: MAIZE_R | U2: MAIZE_R | V2: RGRM_K | W2: BGRM_K | X2: BGRM_K | Y2: BGRM_R | Z2: BGRM_R | AA2: GGRM_K | AB2: GGRM_R | AC2: GGRM_R | AD2: HGRM_R | AE2: VRGU_K | AF2: SMAI_K | AG2: COTT_K | AH2: COTT_K | AI2: COTT_R | AJ2: COTT_R | AK2: GNUT_K | AL2: GNUT_K | AM2: GNUT_R | AN2: GNUT_R | AO2: SCAN_K | AP2: GNGL_K | AQ2: GNGL_K | AR2: GNGL_R | AS2: GNGL_R | AT2: SUNF_K | AU2: SUNF_K | AV2: SUNF_R | AW2: SUNF_R | AX2: COWP_K | AY2: COWP_R | AZ2: G. Total
C3: (1-1) | D3: (2-1) | E3: (2-2) | F3: (3-1) | G3: (4-1) | H3: (4-2) | I3: (5-1) | J3: (5-2) | K3: (6-1) | L3: (6-2) | M3: (7-1) | N3: (7-2) | O3: (8-1) | P3: (8-2) | Q3: (9-1) | R3: (10-1) | S3: (10-2) | T3: (11-1) | U3: (11-2) | V3: (12-2) | W3: (14-1) | X3: (14-2) | Y3: (15-1) | Z3: (15-2) | AA3: (16-2) | AB3: (17-1) | AC3: (17-2) | AD3: (19-2) | AE3: (20-2) | AF3: (22-2) | AG3: (24-1) | AH3: (24-2) | AI3: (25-1) | AJ3: (25-2) | AK3: (26-1) | AL3: (26-2) | AM3: (27-1) | AN3: (27-2) | AO3: (28-1) | AP3: (29-1) | AQ3: (29-2) | AR3: (30-1) | AS3: (30-2) | AT3: (31-1) | AU3: (31-2) | AV3: (32-1) | AW3: (32-2) | AX3: (33-2) | AY3: (34-2)
A4: 1 | B4: KANCHEEPURAM | C4: 20 | D4: 20 | F4: 8 | AK4: 12 | AM4: 4 | AO4: 4 | AP4: 8 | AZ4: =SUM(C4:AY4) -> 76
A5: 2 | B5: THIRUVALLUR | C5: 36 | D5: 52 | F5: 20 | AB5: 16 | AM5: 16 | AO5: 16 | AZ5: =SUM(C5:AY5) -> 156
A6: 3 | B6: CUDDALORE | C6: 48 | D6: 84 | F6: 16 | K6: 20 | L6: 16 | N6: 8 | S6: 16 | Z6: 28 | AC6: 20 | AE6: 48 | AH6: 36 | AK6: 16 | AM6: 16 | AO6: 32 | AQ6: 16 | AR6: 16 | AZ6: =SUM(C6:AY6) -> 436
A7: 4 | B7: VILLUPURAM | C7: 24 | D7: 52 | F7: 8 | K7: 12 | L7: 48 | Q7: 20 | X7: 16 | Y7: 24 | Z7: 8 | AK7: 12 | AL7: 36 | AM7: 28 | AO7: 24 | AR7: 8 | AS7: 8 | AZ7: =SUM(C7:AY7) -> 328
A8: 5 | B8: VELLORE | F8: 4 | H8: 4 | L8: 4 | Q8: 20 | V8: 36 | X8: 4 | AA8: 4 | AD8: 10 | AF8: 4 | AH8: 4 | AL8: 28 | AO8: 4 | AX8: 6 | AZ8: =SUM(C8:AY8) -> 132
A9: 6 | B9: THIRUVANNAMALAI | C9: 24 | D9: 52 | F9: 20 | L9: 44 | Q9: 32 | V9: 16 | X9: 16 | Y9: 16 | Z9: 16 | AD9: 16 | AF9: 16 | AG9: 24 | AK9: 24 | AL9: 72 | AM9: 48 | AN9: 16 | AO9: 36 | AP9: 16 | AS9: 32 | AY9: 10 | AZ9: =SUM(C9:AY9) -> 546
A10: 7 | B10: SALEM | D10: 16 | F10: 16 | H10: 60 | I10: 36 | J10: 24 | M10: 8 | P10: 20 | Q10: 28 | R10: 20 | S10: 16 | T10: 16 | V10: 24 | X10: 16 | AA10: 32 | AD10: 32 | AF10: 16 | AG10: 16 | AH10: 48 | AI10: 16 | AL10: 56 | AM10: 16 | AO10: 16 | AP10: 16 | AQ10: 16 | AR10: 16 | AX10: 16 | AY10: 16 | AZ10: =SUM(C10:AY10) -> 628
A11: 8 | B11: NAMAKKAL | D11: 16 | G11: 16 | H11: 80 | I11: 30 | J11: 86 | O11: 16 | T11: 16 | AA11: 20 | AG11: 16 | AH11: 16 | AL11: 68 | AM11: 16 | AO11: 20 | AR11: 16 | AZ11: =SUM(C11:AY11) -> 432
A12: 9 | B12: DHARMAPURI | D12: 28 | F12: 16 | H12: 32 | P12: 32 | Q12: 40 | R12: 12 | S12: 20 | V12: 48 | X12: 16 | AA12: 16 | AD12: 50 | AF12: 36 | AH12: 56 | AL12: 20 | AM12: 16 | AO12: 16 | AQ12: 16 | AX12: 16 | AZ12: =SUM(C12:AY12) -> 486
A13: 10 | B13: COIMBATORE | H13: 32 | J13: 36 | N13: 8 | AD13: 16 | AL13: 16 | AX13: 16 | AY13: 16 | AZ13: =SUM(C13:AY13) -> 140
A14: 11 | B14: ERODE | D14: 16 | P14: 16 | R14: 20 | S14: 16 | T14: 16 | V14: 16 | AE14: 8 | AK14: 16 | AL14: 44 | AM14: 16 | AO14: 36 | AR14: 16 | AU14: 4 | AZ14: =SUM(C14:AY14) -> 240
A15: 12 | B15: TIRUCHIRAPALLI | C15: 16 | D15: 48 | F15: 16 | H15: 44 | I15: 16 | J15: 20 | S15: 16 | V15: 16 | Z15: 16 | AH15: 72 | AL15: 20 | AM15: 16 | AO15: 16 | AR15: 16 | AT15: 16 | AU15: 8 | AW15: 8 | AZ15: =SUM(C15:AY15) -> 380
A16: 13 | B16: KARUR | D16: 16 | G16: 20 | H16: 24 | I16: 16 | J16: 24 | N16: 20 | V16: 16 | AD16: 16 | AM16: 16 | AO16: 16 | AQ16: 24 | AT16: 36 | AV16: 16 | AZ16: =SUM(C16:AY16) -> 260
A17: 14 | B17: PERAMBALUR | D17: 16 | S17: 20 | V17: 16 | AE17: 16 | AH17: 64 | AM17: 16 | AO17: 16 | AU17: 4 | AZ17: =SUM(C17:AY17) -> 168
A18: 15 | B18: THANJAVUR | C18: 36 | D18: 92 | F18: 16 | W18: 32 | Z18: 16 | AC18: 16 | AM18: 16 | AO18: 16 | AP18: 20 | AR18: 16 | AS18: 28 | AZ18: =SUM(C18:AY18) -> 304
A19: 16 | B19: THIRUVARUR | C19: 36 | D19: 92 | F19: 16 | Y19: 12 | Z19: 32 | AC19: 68 | AI19: 16 | AM19: 16 | AS19: 16 | AZ19: =SUM(C19:AY19) -> 304
A20: 17 | B20: NAGAPATTINAM | C20: 4 | D20: 48 | Z20: 8 | AC20: 28 | AI20: 4 | AZ20: =SUM(C20:AY20) -> 92
A21: 18 | B21: PUDUKOTTAI | C21: 16 | D21: 72 | F21: 16 | V21: 24 | AK21: 16 | AL21: 16 | AM21: 16 | AO21: 16 | AS21: 16 | AZ21: =SUM(C21:AY21) -> 208
A22: 19 | B22: MADURAI | D22: 40 | F22: 16 | H22: 20 | J22: 16 | L22: 16 | N22: 16 | S22: 16 | V22: 16 | AA22: 16 | AE22: 24 | AH22: 24 | AI22: 16 | AJ22: 16 | AL22: 16 | AO22: 16 | AX22: 16 | AY22: 16 | AZ22: =SUM(C22:AY22) -> 316
A23: 20 | B23: THENI | C23: 16 | D23: 16 | H23: 16 | I23: 16 | J23: 16 | N23: 24 | V23: 16 | AA23: 16 | AC23: 16 | AG23: 16 | AI23: 16 | AL23: 16 | AO23: 16 | AQ23: 16 | AX23: 16 | AY23: 16 | AZ23: =SUM(C23:AY23) -> 264
A24: 21 | B24: DINDIGUL | D24: 16 | F24: 16 | H24: 24 | I24: 16 | J24: 92 | N24: 16 | T24: 16 | U24: 16 | Z24: 16 | AC24: 16 | AD24: 16 | AI24: 16 | AJ24: 16 | AL24: 16 | AM24: 16 | AN24: 16 | AO24: 16 | AT24: 12 | AV24: 32 | AX24: 16 | AY24: 32 | AZ24: =SUM(C24:AY24) -> 448
A25: 22 | B25: RAMANATHAPURAM | E25: 92 | J25: 16 | N25: 16 | Z25: 16 | AJ25: 16 | AN25: 20 | AS25: 16 | AW25: 32 | AZ25: =SUM(C25:AY25) -> 224
A26: 23 | B26: VIRUDHUNAGAR | D26: 24 | F26: 16 | H26: 16 | J26: 44 | N26: 32 | S26: 16 | T26: 16 | U26: 16 | AA26: 16 | AC26: 16 | AH26: 28 | AI26: 16 | AJ26: 40 | AL26: 16 | AN26: 20 | AO26: 16 | AQ26: 16 | AS26: 16 | AU26: 4 | AW26: 52 | AZ26: =SUM(C26:AY26) -> 436
A27: 24 | B27: SIVAGANGAI | D27: 72 | AL27: 16 | AO27: 16 | AZ27: =SUM(C27:AY27) -> 104
A28: 25 | B28: TIRUNELVELI | C28: 4 | D28: 36 | F28: 8 | Z28: 4 | AU28: 4 | AZ28: =SUM(C28:AY28) -> 56
A29: 26 | B29: THOOTHUKUDI | D29: 16 | F29: 16 | J29: 32 | N29: 56 | U29: 16 | Z29: 28 | AC29: 52 | AJ29: 24 | AW29: 48 | AZ29: =SUM(C29:AY29) -> 288
A30: 27 | B30: KANYAKUMARI | C30: 16 | D30: 16 | AZ30: =SUM(C30:AY30) -> 32
A31: 28 | B31: THE NILGIRIS | AZ31: =SUM(C31:AY31) -> 0
A32: 29 | B32: KRISHNAGIRI | C32: 16 | D32: 16 | F32: 16 | H32: 16 | P32: 60 | Q32: 40 | R32: 16 | V32: 48 | AD32: 88 | AF32: 16 | AH32: 16 | AL32: 36 | AM32: 16 | AQ32: 16 | AX32: 16 | AZ32: =SUM(C32:AY32) -> 432
A33: 30 | B33: ARIYALUR | C33: 16 | D33: 28 | L33: 16 | S33: 16 | Z33: 16 | AE33: 8 | AH33: 48 | AK33: 16 | AL33: 16 | AM33: 16 | AO33: 16 | AP33: 20 | AT33: 4 | AU33: 16 | AZ33: =SUM(C33:AY33) -> 252
A34: 31 | B34: THIRUPPUR | D34: 16 | H34: 24 | J34: 104 | R34: 16 | T34: 16 | AC34: 16 | AD34: 28 | AI34: 16 | AL34: 16 | AM34: 16 | AO34: 16 | AY34: 16 | AZ34: =SUM(C34:AY34) -> 300
A35: 32 | B35: CHENGALPATTU | C35: 16 | D35: 28 | F35: 12 | AK35: 4 | AM35: 16 | AO35: 12 | AP35: 8 | AZ35: =SUM(C35:AY35) -> 96
A36: 33 | B36: KALLAKURICHI | C36: 12 | D36: 36 | F36: 8 | L36: 48 | R36: 20 | T36: 16 | Z36: 20 | AE36: 20 | AG36: 28 | AH36: 20 | AK36: 8 | AL36: 8 | AM36: 4 | AO36: 32 | AR36: 12 | AS36: 8 | AZ36: =SUM(C36:AY36) -> 300
A37: 34 | B37: RANIPET | C37: 16 | D37: 12 | F37: 12 | L37: 4 | V37: 16 | X37: 4 | AL37: 16 | AM37: 16 | AO37: 8 | AX37: 4 | AZ37: =SUM(C37:AY37) -> 108
A38: 35 | B38: TIRUPATHUR | D38: 4 | H38: 12 | L38: 12 | P38: 16 | Q38: 20 | V38: 28 | X38: 8 | AA38: 12 | AD38: 28 | AF38: 12 | AH38: 32 | AL38: 28 | AO38: 4 | AZ38: =SUM(C38:AY38) -> 216
A39: 36 | B39: TENKASI | C39: 16 | D39: 28 | F39: 8 | U39: 16 | Z39: 16 | AC39: 16 | AJ39: 16 | AO39: 16 | AQ39: 16 | AT39: 12 | AW39: 16 | AZ39: =SUM(C39:AY39) -> 176
A40: 37 | B40: MYLADUTHURAI | C40: 40 | D40: 44 | Z40: 20 | AC40: 28 | AI40: 12 | AM40: 16 | AZ40: =SUM(C40:AY40) -> 160
...

Sheet 2.0WS
A1: CENTRAL WORKING SHEET FOR AS2.0 OF TAMIL NADU BASED ON CES PLANNING 2026-27
C2: KHARIF | BC2: RABI | CZ2: GRAND TOTAL
C3: PADDY-I (K) | F3: PADDY-II (S) | L3: JOWAR | R3: BAJRA | X3: MAIZE | AD3: GROUNDNUT | AJ3: GINGELLY | AP3: REDGRAM | AS3: COTTON | AY3: SUGARCANE | BB3: TOTAL | BC3: PADDY-III (N) | BF3: JOWAR | BL3: GROUNDNUT | BR3: BLACKGRAM | BX3: GREENGRAM | CD3: GINGELLY | CJ3: BAJRA | CP3: HORSEGRAM | CS3: COTTON | CY3: TOTAL
C4: IR | F4: UI | I4: IR | L4: UI | O4: IR | R4: UI | U4: IR | X4: UI | AA4: IR | AD4: UI | AG4: IR | AJ4: UI | AM4: IR | AP4: UI | AS4: UI | AV4: IR | BC4: IR | BF4: UI | BI4: IR | BL4: UI | BO4: IR | BR4: UI | BU4: IR | BX4: UI | CA4: IR | CD4: UI | CG4: IR | CJ4: UI | CM4: IR | CP4: UI | CS4: UI | CV4: IR
A5: D_CD | B5: DIST_NM | C5: CES | D5: ICS | E5: ADJ | F5: CES | G5: ICS | H5: ADJ | I5: CES | J5: ICS | K5: ADJ | L5: CES | M5: ICS | N5: ADJ | O5: CES | P5: ICS | Q5: ADJ | R5: CES | S5: ICS | T5: ADJ | U5: CES | V5: ICS | W5: ADJ | X5: CES | Y5: ICS | Z5: ADJ | AA5: CES | AB5: ICS | AC5: ADJ | AD5: CES | AE5: ICS | AF5: ADJ | AG5: CES | AH5: ICS | AI5: ADJ | AJ5: CES | AK5: ICS | AL5: ADJ | AM5: CES | AN5: ICS | AO5: ADJ | AP5: CES | AQ5: ICS | AR5: ADJ | AS5: CES | AT5: ICS | AU5: ADJ | AV5: CES | AW5: ICS | AX5: ADJ | AY5: CES | AZ5: ICS | BA5: ADJ | BC5: CES | BD5: ICS | BE5: ADJ | BF5: CES | BG5: ICS | BH5: ADJ | BI5: CES | BJ5: ICS | BK5: ADJ | BL5: CES | BM5: ICS | BN5: ADJ | BO5: CES | BP5: ICS | BQ5: ADJ | BR5: CES | BS5: ICS | BT5: ADJ | BU5: CES | BV5: ICS | BW5: ADJ | BX5: CES | BY5: ICS | BZ5: ADJ | CA5: CES | CB5: ICS | CC5: ADJ | CD5: CES | CE5: ICS | CF5: ADJ | CG5: CES | CH5: ICS | CI5: ADJ | CJ5: CES | CK5: ICS | CL5: ADJ | CM5: CES | CN5: ICS | CO5: ADJ | CP5: CES | CQ5: ICS | CR5: ADJ | CS5: CES | CT5: ICS | CU5: ADJ | CV5: CES | CW5: ICS | CX5: ADJ
A6: 10 | B6: ERODE | C6: =_xlfn.XLOOKUP($B6,GCES!$B:$B,GCES!$C:$C,"",0,1) | D6: =IF(C6="","",D$58*C6/C$57) | E6: =IF(C6="","",IF(D6>4,ROUND(D6/2,0)*2,IF(D6>D$59,4,""))) | F6: =_xlfn.XLOOKUP($B6,GCES!$B:$B,GCES!$E:$E,"",0,1) | G6: =IF(F6="","",G$58*F6/F$57) | H6: =IF(F6="","",IF(G6>4,ROUND(G6/2,0)*2,IF(G6>G$59,4,""))) | I6: =_xlfn.XLOOKUP($B6,GCES!$B:$B,GCES!$D:$D,"",0,1) -> 16 | J6: =IF(I6="","",J$58*I6/I$57) -> 1.5115207 | K6: =IF(I6="","",IF(J6>4,ROUND(J6/2,0)*2,IF(J6>J$59,4,""))) | L6: =_xlfn.XLOOKUP($B6,GCES!$B:$B,GCES!$H:$H,"",0,1) | M6: =IF(L6="","",M$58*L6/L$57) | N6: =IF(L6="","",IF(M6>4,ROUND(M6/2,0)*2,IF(M6>M$59,4,""))) | O6: =_xlfn.XLOOKUP($B6,GCES!$B:$B,GCES!$G:$G,"",0,1) | P6: =IF(O6="","",P$58*O6/O$57) | Q6: =IF(O6="","",IF(P6>4,ROUND(P6/2,0)*2,IF(P6>P$59,4,""))) | R6: =_xlfn.XLOOKUP($B6,GCES!$B:$B,GCES!$L:$L,"",0,1) | S6: =IF(R6="","",S$58*R6/R$57) | T6: =IF(R6="","",IF(S6>4,ROUND(S6/2,0)*2,IF(S6>S$59,4,""))) | U6: =_xlfn.XLOOKUP($B6,GCES!$B:$B,GCES!$K:$K,"",0,1) | V6: =IF(U6="","",V$58*U6/U$57) | W6: =IF(U6="","",IF(V6>4,ROUND(V6/2,0)*2,IF(V6>V$59,4,""))) | X6: =_xlfn.XLOOKUP($B6,GCES!$B:$B,GCES!$S:$S,"",0,1) -> 16 | Y6: =IF(X6="","",Y$58*X6/X$57) -> 5.6470588 | Z6: =IF(X6="","",IF(Y6>4,ROUND(Y6/2,0)*2,IF(Y6>Y$59,4,""))) -> 6 | AA6: =_xlfn.XLOOKUP($B6,GCES!$B:$B,GCES!$R:$R,"",0,1) -> 20 | AB6: =IF(AA6="","",AB$58*AA6/AA$57) -> 6.8181818 | AC6: 8 | AD6: =_xlfn.XLOOKUP($B6,GCES!$B:$B,GCES!$AL:$AL,"",0,1) -> 44 | AE6: =IF(AD6="","",AE$58*AD6/AD$57) -> 5.2884615 | AF6: =IF(AD6="","",IF(AE6>4,ROUND(AE6/2,0)*2,IF(AE6>AE$59,4,""))) -> 6 | AG6: =_xlfn.XLOOKUP($B6,GCES!$B:$B,GCES!$AK:$AK,"",0,1) -> 16 | AH6: =IF(AG6="","",AH$58*AG6/AG$57) -> 2.6666667 | AI6: =IF(AG6="","",IF(AH6>4,ROUND(AH6/2,0)*2,IF(AH6>AH$59,4,""))) -> 4 | AJ6: =_xlfn.XLOOKUP($B6,GCES!$B:$B,GCES!$AQ:$AQ,"",0,1) | AK6: =IF(AJ6="","",AK$58*AJ6/AJ$57) | AL6: =IF(AJ6="","",IF(AK6>4,ROUND(AK6/2,0)*2,IF(AK6>AK$59,4,""))) | AM6: =_xlfn.XLOOKUP($B6,GCES!$B:$B,GCES!$AP:$AP,"",0,1) | AN6: =IF(AM6="","",AN$58*AM6/AM$57) | AO6: =IF(AM6="","",IF(AN6>4,ROUND(AN6/2,0)*2,IF(AN6>AN$59,4,""))) | AP6: =_xlfn.XLOOKUP($B6,GCES!$B:$B,GCES!$V:$V,"",0,1) -> 16 | AQ6: =IF(AP6="","",AQ$58*AP6/AP$57) -> 4.4571429 | AR6: =IF(AP6="","",IF(AQ6>4,ROUND(AQ6/2,0)*2,IF(AQ6>AQ$59,4,""))) -> 4 | AS6: =_xlfn.XLOOKUP($B6,GCES!$B:$B,GCES!$AH:$AH,"",0,1) | AT6: =IF(AS6="","",AT$58*AS6/AS$57) | AU6: =IF(AS6="","",IF(AT6>4,ROUND(AT6/2,0)*2,IF(AT6>AT$59,4,""))) | AV6: =_xlfn.XLOOKUP($B6,GCES!$B:$B,GCES!$AG:$AG,"",0,1) | AW6: =IF(AV6="","",AW$58*AV6/AV$57) | AX6: =IF(AV6="","",IF(AW6>4,ROUND(AW6/2,0)*2,IF(AW6>AW$59,4,""))) | AY6: =_xlfn.XLOOKUP($B6,GCES!$B:$B,GCES!$AO:$AO,"",0,1) -> 36 | AZ6: =IF(AY6="","",AZ$58*AY6/AY$57) -> 6.6 | BA6: =IF(AY6="","",IF(AZ6>4,ROUND(AZ6/2,0)*2,IF(AZ6>AZ$59,4,""))) -> 6 | BB6: =SUM(E6,H6,K6,N6,Q6,T6,W6,Z6,AC6,AF6,AI6,AL6,AO6,AR6,AU6,AX6,BA6) -> 34 | BC6: =_xlfn.XLOOKUP($B6,GCES!$B:$B,GCES!$F:$F,"",0,1) | BD6: =IF(BC6="","",BD$58*BC6/BC$57) | BE6: =IF(BC6="","",IF(BD6>4,ROUND(BD6/2,0)*2,IF(BD6>BD$59,4,""))) | BF6: =_xlfn.XLOOKUP($B6,GCES!$B:$B,GCES!$J:$J,"",0,1) | BG6: =IF(BF6="","",BG$58*BF6/BF$57) | BH6: =IF(BF6="","",IF(BG6>4,ROUND(BG6/2,0)*2,IF(BG6>BG$59,4,""))) | BI6: =_xlfn.XLOOKUP($B6,GCES!$B:$B,GCES!$I:$I,"",0,1) | BJ6: =IF(BI6="","",BJ$58*BI6/BI$57) | BK6: =IF(BI6="","",IF(BJ6>4,ROUND(BJ6/2,0)*2,IF(BJ6>BJ$59,4,""))) | BL6: =_xlfn.XLOOKUP($B6,GCES!$B:$B,GCES!$AN:$AN,"",0,1) | BM6: =IF(BL6="","",BM$58*BL6/BL$57) | BN6: =IF(BL6="","",IF(BM6>4,ROUND(BM6/2,0)*2,IF(BM6>BM$59,4,""))) | BO6: =_xlfn.XLOOKUP($B6,GCES!$B:$B,GCES!$AM:$AM,"",0,1) -> 16 | BP6: =IF(BO6="","",BP$58*BO6/BO$57) -> 3.8709677 | BQ6: =IF(BO6="","",IF(BP6>4,ROUND(BP6/2,0)*2,IF(BP6>BP$59,4,""))) -> 4 | BR6: =_xlfn.XLOOKUP($B6,GCES!$B:$B,GCES!$Z:$Z,"",0,1) | BS6: =IF(BR6="","",BS$58*BR6/BR$57) | BT6: =IF(BR6="","",IF(BS6>4,ROUND(BS6/2,0)*2,IF(BS6>BS$59,4,""))) | BU6: =_xlfn.XLOOKUP($B6,GCES!$B:$B,GCES!$Y:$Y,"",0,1) | BV6: =IF(BU6="","",BV$58*BU6/BU$57) | BW6: =IF(BU6="","",IF(BV6>4,ROUND(BV6/2,0)*2,IF(BV6>BV$59,4,""))) | BX6: =_xlfn.XLOOKUP($B6,GCES!$B:$B,GCES!$AC:$AC,"",0,1) | BY6: =IF(BX6="","",BY$58*BX6/BX$57) | BZ6: =IF(BX6="","",IF(BY6>4,ROUND(BY6/2,0)*2,IF(BY6>BY$59,4,""))) | CA6: =_xlfn.XLOOKUP($B6,GCES!$B:$B,GCES!$AB:$AB,"",0,1) | CB6: =IF(CA6="","",CB$58*CA6/CA$57) | CC6: =IF(CA6="","",IF(CB6>4,ROUND(CB6/2,0)*2,IF(CB6>CB$59,4,""))) | CD6: =_xlfn.XLOOKUP($B6,GCES!$B:$B,GCES!$AS:$AS,"",0,1) | CE6: =IF(CD6="","",CE$58*CD6/CD$57) | CF6: =IF(CD6="","",IF(CE6>4,ROUND(CE6/2,0)*2,IF(CE6>CE$59,4,""))) | CG6: =_xlfn.XLOOKUP($B6,GCES!$B:$B,GCES!$AR:$AR,"",0,1) -> 16 | CH6: =IF(CG6="","",CH$58*CG6/CG$57) -> 5.2173913 | CI6: =IF(CG6="","",IF(CH6>4,ROUND(CH6/2,0)*2,IF(CH6>CH$59,4,""))) -> 6 | CJ6: =_xlfn.XLOOKUP($B6,GCES!$B:$B,GCES!$N:$N,"",0,1) | CK6: =IF(CJ6="","",CK$58*CJ6/CJ$57) | CL6: =IF(CJ6="","",IF(CK6>4,ROUND(CK6/2,0)*2,IF(CK6>CK$59,4,""))) | CM6: =_xlfn.XLOOKUP($B6,GCES!$B:$B,GCES!$M:$M,"",0,1) | CN6: =IF(CM6="","",CN$58*CM6/CM$57) | CO6: =IF(CM6="","",IF(CN6>4,ROUND(CN6/2,0)*2,IF(CN6>CN$59,4,""))) | CP6: =_xlfn.XLOOKUP($B6,GCES!$B:$B,GCES!$AD:$AD,"",0,1) | CQ6: =IF(CP6="","",CQ$58*CP6/CP$57) | CR6: =IF(CP6="","",IF(CQ6>4,ROUND(CQ6/2,0)*2,IF(CQ6>CQ$59,4,""))) | CS6: =_xlfn.XLOOKUP($B6,GCES!$B:$B,GCES!$AJ:$AJ,"",0,1) | CT6: =IF(CS6="","",CT$58*CS6/CS$57) | CU6: =IF(CS6="","",IF(CT6>4,ROUND(CT6/2,0)*2,IF(CT6>CT$59,4,""))) | CV6: =_xlfn.XLOOKUP($B6,GCES!$B:$B,GCES!$AI:$AI,"",0,1) | CW6: =IF(CV6="","",CW$58*CV6/CV$57) | CX6: =IF(CV6="","",IF(CW6>4,ROUND(CW6/2,0)*2,IF(CW6>CW$59,4,""))) | CY6: =SUM(BE6,BH6,BK6,BN6,BQ6,BT6,BW6,BZ6,CC6,CF6,CI6,CL6,CO6,CR6,CU6,CX6) -> 10 | CZ6: =SUM(BB6,CY6) -> 44
A7: 11 | B7: THE NILGIRIS | C7: =_xlfn.XLOOKUP($B7,GCES!$B:$B,GCES!$C:$C,"",0,1) | D7: =IF(C7="","",D$58*C7/C$57) | E7: =IF(C7="","",IF(D7>4,ROUND(D7/2,0)*2,IF(D7>D$59,4,""))) | F7: =_xlfn.XLOOKUP($B7,GCES!$B:$B,GCES!$E:$E,"",0,1) | G7: =IF(F7="","",G$58*F7/F$57) | H7: =IF(F7="","",IF(G7>4,ROUND(G7/2,0)*2,IF(G7>G$59,4,""))) | I7: =_xlfn.XLOOKUP($B7,GCES!$B:$B,GCES!$D:$D,"",0,1) | J7: =IF(I7="","",J$58*I7/I$57) | K7: =IF(I7="","",IF(J7>4,ROUND(J7/2,0)*2,IF(J7>J$59,4,""))) | L7: =_xlfn.XLOOKUP($B7,GCES!$B:$B,GCES!$H:$H,"",0,1) | M7: =IF(L7="","",M$58*L7/L$57) | N7: =IF(L7="","",IF(M7>4,ROUND(M7/2,0)*2,IF(M7>M$59,4,""))) | O7: =_xlfn.XLOOKUP($B7,GCES!$B:$B,GCES!$G:$G,"",0,1) | P7: =IF(O7="","",P$58*O7/O$57) | Q7: =IF(O7="","",IF(P7>4,ROUND(P7/2,0)*2,IF(P7>P$59,4,""))) | R7: =_xlfn.XLOOKUP($B7,GCES!$B:$B,GCES!$L:$L,"",0,1) | S7: =IF(R7="","",S$58*R7/R$57) | T7: =IF(R7="","",IF(S7>4,ROUND(S7/2,0)*2,IF(S7>S$59,4,""))) | U7: =_xlfn.XLOOKUP($B7,GCES!$B:$B,GCES!$K:$K,"",0,1) | V7: =IF(U7="","",V$58*U7/U$57) | W7: =IF(U7="","",IF(V7>4,ROUND(V7/2,0)*2,IF(V7>V$59,4,""))) | X7: =_xlfn.XLOOKUP($B7,GCES!$B:$B,GCES!$S:$S,"",0,1) | Y7: =IF(X7="","",Y$58*X7/X$57) | Z7: =IF(X7="","",IF(Y7>4,ROUND(Y7/2,0)*2,IF(Y7>Y$59,4,""))) | AA7: =_xlfn.XLOOKUP($B7,GCES!$B:$B,GCES!$R:$R,"",0,1) | AB7: =IF(AA7="","",AB$58*AA7/AA$57) | AC7: =IF(AA7="","",IF(AB7>4,ROUND(AB7/2,0)*2,IF(AB7>AB$59,4,""))) | AD7: =_xlfn.XLOOKUP($B7,GCES!$B:$B,GCES!$AL:$AL,"",0,1) | AE7: =IF(AD7="","",AE$58*AD7/AD$57) | AF7: =IF(AD7="","",IF(AE7>4,ROUND(AE7/2,0)*2,IF(AE7>AE$59,4,""))) | AG7: =_xlfn.XLOOKUP($B7,GCES!$B:$B,GCES!$AK:$AK,"",0,1) | AH7: =IF(AG7="","",AH$58*AG7/AG$57) | AI7: =IF(AG7="","",IF(AH7>4,ROUND(AH7/2,0)*2,IF(AH7>AH$59,4,""))) | AJ7: =_xlfn.XLOOKUP($B7,GCES!$B:$B,GCES!$AQ:$AQ,"",0,1) | AK7: =IF(AJ7="","",AK$58*AJ7/AJ$57) | AL7: =IF(AJ7="","",IF(AK7>4,ROUND(AK7/2,0)*2,IF(AK7>AK$59,4,""))) | AM7: =_xlfn.XLOOKUP($B7,GCES!$B:$B,GCES!$AP:$AP,"",0,1) | AN7: =IF(AM7="","",AN$58*AM7/AM$57) | AO7: =IF(AM7="","",IF(AN7>4,ROUND(AN7/2,0)*2,IF(AN7>AN$59,4,""))) | AP7: =_xlfn.XLOOKUP($B7,GCES!$B:$B,GCES!$V:$V,"",0,1) | AQ7: =IF(AP7="","",AQ$58*AP7/AP$57) | AR7: =IF(AP7="","",IF(AQ7>4,ROUND(AQ7/2,0)*2,IF(AQ7>AQ$59,4,""))) | AS7: =_xlfn.XLOOKUP($B7,GCES!$B:$B,GCES!$AH:$AH,"",0,1) | AT7: =IF(AS7="","",AT$58*AS7/AS$57) | AU7: =IF(AS7="","",IF(AT7>4,ROUND(AT7/2,0)*2,IF(AT7>AT$59,4,""))) | AV7: =_xlfn.XLOOKUP($B7,GCES!$B:$B,GCES!$AG:$AG,"",0,1) | AW7: =IF(AV7="","",AW$58*AV7/AV$57) | AX7: =IF(AV7="","",IF(AW7>4,ROUND(AW7/2,0)*2,IF(AW7>AW$59,4,""))) | AY7: =_xlfn.XLOOKUP($B7,GCES!$B:$B,GCES!$AO:$AO,"",0,1) | AZ7: =IF(AY7="","",AZ$58*AY7/AY$57) | BA7: =IF(AY7="","",IF(AZ7>4,ROUND(AZ7/2,0)*2,IF(AZ7>AZ$59,4,""))) | BB7: =SUM(E7,H7,K7,N7,Q7,T7,W7,Z7,AC7,AF7,AI7,AL7,AO7,AR7,AU7,AX7,BA7) -> 0 | BC7: =_xlfn.XLOOKUP($B7,GCES!$B:$B,GCES!$F:$F,"",0,1) | BD7: =IF(BC7="","",BD$58*BC7/BC$57) | BE7: =IF(BC7="","",IF(BD7>4,ROUND(BD7/2,0)*2,IF(BD7>BD$59,4,""))) | BF7: =_xlfn.XLOOKUP($B7,GCES!$B:$B,GCES!$J:$J,"",0,1) | BG7: =IF(BF7="","",BG$58*BF7/BF$57) | BH7: =IF(BF7="","",IF(BG7>4,ROUND(BG7/2,0)*2,IF(BG7>BG$59,4,""))) | BI7: =_xlfn.XLOOKUP($B7,GCES!$B:$B,GCES!$I:$I,"",0,1) | BJ7: =IF(BI7="","",BJ$58*BI7/BI$57) | BK7: =IF(BI7="","",IF(BJ7>4,ROUND(BJ7/2,0)*2,IF(BJ7>BJ$59,4,""))) | BL7: =_xlfn.XLOOKUP($B7,GCES!$B:$B,GCES!$AN:$AN,"",0,1) | BM7: =IF(BL7="","",BM$58*BL7/BL$57) | BN7: =IF(BL7="","",IF(BM7>4,ROUND(BM7/2,0)*2,IF(BM7>BM$59,4,""))) | BO7: =_xlfn.XLOOKUP($B7,GCES!$B:$B,GCES!$AM:$AM,"",0,1) | BP7: =IF(BO7="","",BP$58*BO7/BO$57) | BQ7: =IF(BO7="","",IF(BP7>4,ROUND(BP7/2,0)*2,IF(BP7>BP$59,4,""))) | BR7: =_xlfn.XLOOKUP($B7,GCES!$B:$B,GCES!$Z:$Z,"",0,1) | BS7: =IF(BR7="","",BS$58*BR7/BR$57) | BT7: =IF(BR7="","",IF(BS7>4,ROUND(BS7/2,0)*2,IF(BS7>BS$59,4,""))) | BU7: =_xlfn.XLOOKUP($B7,GCES!$B:$B,GCES!$Y:$Y,"",0,1) | BV7: =IF(BU7="","",BV$58*BU7/BU$57) | BW7: =IF(BU7="","",IF(BV7>4,ROUND(BV7/2,0)*2,IF(BV7>BV$59,4,""))) | BX7: =_xlfn.XLOOKUP($B7,GCES!$B:$B,GCES!$AC:$AC,"",0,1) | BY7: =IF(BX7="","",BY$58*BX7/BX$57) | BZ7: =IF(BX7="","",IF(BY7>4,ROUND(BY7/2,0)*2,IF(BY7>BY$59,4,""))) | CA7: =_xlfn.XLOOKUP($B7,GCES!$B:$B,GCES!$AB:$AB,"",0,1) | CB7: =IF(CA7="","",CB$58*CA7/CA$57) | CC7: =IF(CA7="","",IF(CB7>4,ROUND(CB7/2,0)*2,IF(CB7>CB$59,4,""))) | CD7: =_xlfn.XLOOKUP($B7,GCES!$B:$B,GCES!$AS:$AS,"",0,1) | CE7: =IF(CD7="","",CE$58*CD7/CD$57) | CF7: =IF(CD7="","",IF(CE7>4,ROUND(CE7/2,0)*2,IF(CE7>CE$59,4,""))) | CG7: =_xlfn.XLOOKUP($B7,GCES!$B:$B,GCES!$AR:$AR,"",0,1) | CH7: =IF(CG7="","",CH$58*CG7/CG$57) | CI7: =IF(CG7="","",IF(CH7>4,ROUND(CH7/2,0)*2,IF(CH7>CH$59,4,""))) | CJ7: =_xlfn.XLOOKUP($B7,GCES!$B:$B,GCES!$N:$N,"",0,1) | CK7: =IF(CJ7="","",CK$58*CJ7/CJ$57) | CL7: =IF(CJ7="","",IF(CK7>4,ROUND(CK7/2,0)*2,IF(CK7>CK$59,4,""))) | CM7: =_xlfn.XLOOKUP($B7,GCES!$B:$B,GCES!$M:$M,"",0,1) | CN7: =IF(CM7="","",CN$58*CM7/CM$57) | CO7: =IF(CM7="","",IF(CN7>4,ROUND(CN7/2,0)*2,IF(CN7>CN$59,4,""))) | CP7: =_xlfn.XLOOKUP($B7,GCES!$B:$B,GCES!$AD:$AD,"",0,1) | CQ7: =IF(CP7="","",CQ$58*CP7/CP$57) | CR7: =IF(CP7="","",IF(CQ7>4,ROUND(CQ7/2,0)*2,IF(CQ7>CQ$59,4,""))) | CS7: =_xlfn.XLOOKUP($B7,GCES!$B:$B,GCES!$AJ:$AJ,"",0,1) | CT7: =IF(CS7="","",CT$58*CS7/CS$57) | CU7: =IF(CS7="","",IF(CT7>4,ROUND(CT7/2,0)*2,IF(CT7>CT$59,4,""))) | CV7: =_xlfn.XLOOKUP($B7,GCES!$B:$B,GCES!$AI:$AI,"",0,1) | CW7: =IF(CV7="","",CW$58*CV7/CV$57) | CX7: =IF(CV7="","",IF(CW7>4,ROUND(CW7/2,0)*2,IF(CW7>CW$59,4,""))) | CY7: =SUM(BE7,BH7,BK7,BN7,BQ7,BT7,BW7,BZ7,CC7,CF7,CI7,CL7,CO7,CR7,CU7,CX7) -> 0 | CZ7: =SUM(BB7,CY7) -> 0
A8: 12 | B8: COIMBATORE | C8: =_xlfn.XLOOKUP($B8,GCES!$B:$B,GCES!$C:$C,"",0,1) | D8: =IF(C8="","",D$58*C8/C$57) | E8: =IF(C8="","",IF(D8>4,ROUND(D8/2,0)*2,IF(D8>D$59,4,""))) | F8: =_xlfn.XLOOKUP($B8,GCES!$B:$B,GCES!$E:$E,"",0,1) | G8: =IF(F8="","",G$58*F8/F$57) | H8: =IF(F8="","",IF(G8>4,ROUND(G8/2,0)*2,IF(G8>G$59,4,""))) | I8: =_xlfn.XLOOKUP($B8,GCES!$B:$B,GCES!$D:$D,"",0,1) | J8: =IF(I8="","",J$58*I8/I$57) | K8: =IF(I8="","",IF(J8>4,ROUND(J8/2,0)*2,IF(J8>J$59,4,""))) | L8: =_xlfn.XLOOKUP($B8,GCES!$B:$B,GCES!$H:$H,"",0,1) -> 32 | M8: =IF(L8="","",M$58*L8/L$57) -> 6.0952381 | N8: =IF(L8="","",IF(M8>4,ROUND(M8/2,0)*2,IF(M8>M$59,4,""))) -> 6 | O8: =_xlfn.XLOOKUP($B8,GCES!$B:$B,GCES!$G:$G,"",0,1) | P8: =IF(O8="","",P$58*O8/O$57) | Q8: =IF(O8="","",IF(P8>4,ROUND(P8/2,0)*2,IF(P8>P$59,4,""))) | R8: =_xlfn.XLOOKUP($B8,GCES!$B:$B,GCES!$L:$L,"",0,1) | S8: =IF(R8="","",S$58*R8/R$57) | T8: =IF(R8="","",IF(S8>4,ROUND(S8/2,0)*2,IF(S8>S$59,4,""))) | U8: =_xlfn.XLOOKUP($B8,GCES!$B:$B,GCES!$K:$K,"",0,1) | V8: =IF(U8="","",V$58*U8/U$57) | W8: =IF(U8="","",IF(V8>4,ROUND(V8/2,0)*2,IF(V8>V$59,4,""))) | X8: =_xlfn.XLOOKUP($B8,GCES!$B:$B,GCES!$S:$S,"",0,1) | Y8: =IF(X8="","",Y$58*X8/X$57) | Z8: =IF(X8="","",IF(Y8>4,ROUND(Y8/2,0)*2,IF(Y8>Y$59,4,""))) | AA8: =_xlfn.XLOOKUP($B8,GCES!$B:$B,GCES!$R:$R,"",0,1) | AB8: =IF(AA8="","",AB$58*AA8/AA$57) | AC8: =IF(AA8="","",IF(AB8>4,ROUND(AB8/2,0)*2,IF(AB8>AB$59,4,""))) | AD8: =_xlfn.XLOOKUP($B8,GCES!$B:$B,GCES!$AL:$AL,"",0,1) -> 16 | AE8: =IF(AD8="","",AE$58*AD8/AD$57) -> 1.9230769 | AF8: =IF(AD8="","",IF(AE8>4,ROUND(AE8/2,0)*2,IF(AE8>AE$59,4,""))) | AG8: =_xlfn.XLOOKUP($B8,GCES!$B:$B,GCES!$AK:$AK,"",0,1) | AH8: =IF(AG8="","",AH$58*AG8/AG$57) | AI8: =IF(AG8="","",IF(AH8>4,ROUND(AH8/2,0)*2,IF(AH8>AH$59,4,""))) | AJ8: =_xlfn.XLOOKUP($B8,GCES!$B:$B,GCES!$AQ:$AQ,"",0,1) | AK8: =IF(AJ8="","",AK$58*AJ8/AJ$57) | AL8: =IF(AJ8="","",IF(AK8>4,ROUND(AK8/2,0)*2,IF(AK8>AK$59,4,""))) | AM8: =_xlfn.XLOOKUP($B8,GCES!$B:$B,GCES!$AP:$AP,"",0,1) | AN8: =IF(AM8="","",AN$58*AM8/AM$57) | AO8: =IF(AM8="","",IF(AN8>4,ROUND(AN8/2,0)*2,IF(AN8>AN$59,4,""))) | AP8: =_xlfn.XLOOKUP($B8,GCES!$B:$B,GCES!$V:$V,"",0,1) | AQ8: =IF(AP8="","",AQ$58*AP8/AP$57) | AR8: =IF(AP8="","",IF(AQ8>4,ROUND(AQ8/2,0)*2,IF(AQ8>AQ$59,4,""))) | AS8: =_xlfn.XLOOKUP($B8,GCES!$B:$B,GCES!$AH:$AH,"",0,1) | AT8: =IF(AS8="","",AT$58*AS8/AS$57) | AU8: =IF(AS8="","",IF(AT8>4,ROUND(AT8/2,0)*2,IF(AT8>AT$59,4,""))) | AV8: =_xlfn.XLOOKUP($B8,GCES!$B:$B,GCES!$AG:$AG,"",0,1) | AW8: =IF(AV8="","",AW$58*AV8/AV$57) | AX8: =IF(AV8="","",IF(AW8>4,ROUND(AW8/2,0)*2,IF(AW8>AW$59,4,""))) | AY8: =_xlfn.XLOOKUP($B8,GCES!$B:$B,GCES!$AO:$AO,"",0,1) | AZ8: =IF(AY8="","",AZ$58*AY8/AY$57) | BA8: =IF(AY8="","",IF(AZ8>4,ROUND(AZ8/2,0)*2,IF(AZ8>AZ$59,4,""))) | BB8: =SUM(E8,H8,K8,N8,Q8,T8,W8,Z8,AC8,AF8,AI8,AL8,AO8,AR8,AU8,AX8,BA8) -> 6 | BC8: =_xlfn.XLOOKUP($B8,GCES!$B:$B,GCES!$F:$F,"",0,1) | BD8: =IF(BC8="","",BD$58*BC8/BC$57) | BE8: =IF(BC8="","",IF(BD8>4,ROUND(BD8/2,0)*2,IF(BD8>BD$59,4,""))) | BF8: =_xlfn.XLOOKUP($B8,GCES!$B:$B,GCES!$J:$J,"",0,1) -> 36 | BG8: =IF(BF8="","",BG$58*BF8/BF$57) -> 6.1554404 | BH8: =IF(BF8="","",IF(BG8>4,ROUND(BG8/2,0)*2,IF(BG8>BG$59,4,""))) -> 6 | BI8: =_xlfn.XLOOKUP($B8,GCES!$B:$B,GCES!$I:$I,"",0,1) | BJ8: =IF(BI8="","",BJ$58*BI8/BI$57) | BK8: =IF(BI8="","",IF(BJ8>4,ROUND(BJ8/2,0)*2,IF(BJ8>BJ$59,4,""))) | BL8: =_xlfn.XLOOKUP($B8,GCES!$B:$B,GCES!$AN:$AN,"",0,1) | BM8: =IF(BL8="","",BM$58*BL8/BL$57) | BN8: =IF(BL8="","",IF(BM8>4,ROUND(BM8/2,0)*2,IF(BM8>BM$59,4,""))) | BO8: =_xlfn.XLOOKUP($B8,GCES!$B:$B,GCES!$AM:$AM,"",0,1) | BP8: =IF(BO8="","",BP$58*BO8/BO$57) | BQ8: =IF(BO8="","",IF(BP8>4,ROUND(BP8/2,0)*2,IF(BP8>BP$59,4,""))) | BR8: =_xlfn.XLOOKUP($B8,GCES!$B:$B,GCES!$Z:$Z,"",0,1) | BS8: =IF(BR8="","",BS$58*BR8/BR$57) | BT8: =IF(BR8="","",IF(BS8>4,ROUND(BS8/2,0)*2,IF(BS8>BS$59,4,""))) | BU8: =_xlfn.XLOOKUP($B8,GCES!$B:$B,GCES!$Y:$Y,"",0,1) | BV8: =IF(BU8="","",BV$58*BU8/BU$57) | BW8: =IF(BU8="","",IF(BV8>4,ROUND(BV8/2,0)*2,IF(BV8>BV$59,4,""))) | BX8: =_xlfn.XLOOKUP($B8,GCES!$B:$B,GCES!$AC:$AC,"",0,1) | BY8: =IF(BX8="","",BY$58*BX8/BX$57) | BZ8: =IF(BX8="","",IF(BY8>4,ROUND(BY8/2,0)*2,IF(BY8>BY$59,4,""))) | CA8: =_xlfn.XLOOKUP($B8,GCES!$B:$B,GCES!$AB:$AB,"",0,1) | CB8: =IF(CA8="","",CB$58*CA8/CA$57) | CC8: =IF(CA8="","",IF(CB8>4,ROUND(CB8/2,0)*2,IF(CB8>CB$59,4,""))) | CD8: =_xlfn.XLOOKUP($B8,GCES!$B:$B,GCES!$AS:$AS,"",0,1) | CE8: =IF(CD8="","",CE$58*CD8/CD$57) | CF8: =IF(CD8="","",IF(CE8>4,ROUND(CE8/2,0)*2,IF(CE8>CE$59,4,""))) | CG8: =_xlfn.XLOOKUP($B8,GCES!$B:$B,GCES!$AR:$AR,"",0,1) | CH8: =IF(CG8="","",CH$58*CG8/CG$57) | CI8: =IF(CG8="","",IF(CH8>4,ROUND(CH8/2,0)*2,IF(CH8>CH$59,4,""))) | CJ8: =_xlfn.XLOOKUP($B8,GCES!$B:$B,GCES!$N:$N,"",0,1) -> 8 | CK8: =IF(CJ8="","",CK$58*CJ8/CJ$57) -> 2.122449 | CL8: =IF(CJ8="","",IF(CK8>4,ROUND(CK8/2,0)*2,IF(CK8>CK$59,4,""))) | CM8: =_xlfn.XLOOKUP($B8,GCES!$B:$B,GCES!$M:$M,"",0,1) | CN8: =IF(CM8="","",CN$58*CM8/CM$57) | CO8: =IF(CM8="","",IF(CN8>4,ROUND(CN8/2,0)*2,IF(CN8>CN$59,4,""))) | CP8: =_xlfn.XLOOKUP($B8,GCES!$B:$B,GCES!$AD:$AD,"",0,1) -> 16 | CQ8: =IF(CP8="","",CQ$58*CP8/CP$57) -> 4 | CR8: =IF(CP8="","",IF(CQ8>4,ROUND(CQ8/2,0)*2,IF(CQ8>CQ$59,4,""))) -> 4 | CS8: =_xlfn.XLOOKUP($B8,GCES!$B:$B,GCES!$AJ:$AJ,"",0,1) | CT8: =IF(CS8="","",CT$58*CS8/CS$57) | CU8: =IF(CS8="","",IF(CT8>4,ROUND(CT8/2,0)*2,IF(CT8>CT$59,4,""))) | CV8: =_xlfn.XLOOKUP($B8,GCES!$B:$B,GCES!$AI:$AI,"",0,1) | CW8: =IF(CV8="","",CW$58*CV8/CV$57) | CX8: =IF(CV8="","",IF(CW8>4,ROUND(CW8/2,0)*2,IF(CW8>CW$59,4,""))) | CY8: =SUM(BE8,BH8,BK8,BN8,BQ8,BT8,BW8,BZ8,CC8,CF8,CI8,CL8,CO8,CR8,CU8,CX8) -> 10 | CZ8: =SUM(BB8,CY8) -> 16
A9: 32 | B9: TIRUPPUR | C9: =_xlfn.XLOOKUP($B9,GCES!$B:$B,GCES!$C:$C,"",0,1) | D9: =IF(C9="","",D$58*C9/C$57) | E9: =IF(C9="","",IF(D9>4,ROUND(D9/2,0)*2,IF(D9>D$59,4,""))) | F9: =_xlfn.XLOOKUP($B9,GCES!$B:$B,GCES!$E:$E,"",0,1) | G9: =IF(F9="","",G$58*F9/F$57) | H9: =IF(F9="","",IF(G9>4,ROUND(G9/2,0)*2,IF(G9>G$59,4,""))) | I9: =_xlfn.XLOOKUP($B9,GCES!$B:$B,GCES!$D:$D,"",0,1) | J9: =IF(I9="","",J$58*I9/I$57) | K9: =IF(I9="","",IF(J9>4,ROUND(J9/2,0)*2,IF(J9>J$59,4,""))) | L9: =_xlfn.XLOOKUP($B9,GCES!$B:$B,GCES!$H:$H,"",0,1) | M9: =IF(L9="","",M$58*L9/L$57) | N9: =IF(L9="","",IF(M9>4,ROUND(M9/2,0)*2,IF(M9>M$59,4,""))) | O9: =_xlfn.XLOOKUP($B9,GCES!$B:$B,GCES!$G:$G,"",0,1) | P9: =IF(O9="","",P$58*O9/O$57) | Q9: =IF(O9="","",IF(P9>4,ROUND(P9/2,0)*2,IF(P9>P$59,4,""))) | R9: =_xlfn.XLOOKUP($B9,GCES!$B:$B,GCES!$L:$L,"",0,1) | S9: =IF(R9="","",S$58*R9/R$57) | T9: =IF(R9="","",IF(S9>4,ROUND(S9/2,0)*2,IF(S9>S$59,4,""))) | U9: =_xlfn.XLOOKUP($B9,GCES!$B:$B,GCES!$K:$K,"",0,1) | V9: =IF(U9="","",V$58*U9/U$57) | W9: =IF(U9="","",IF(V9>4,ROUND(V9/2,0)*2,IF(V9>V$59,4,""))) | X9: =_xlfn.XLOOKUP($B9,GCES!$B:$B,GCES!$S:$S,"",0,1) | Y9: =IF(X9="","",Y$58*X9/X$57) | Z9: =IF(X9="","",IF(Y9>4,ROUND(Y9/2,0)*2,IF(Y9>Y$59,4,""))) | AA9: =_xlfn.XLOOKUP($B9,GCES!$B:$B,GCES!$R:$R,"",0,1) | AB9: =IF(AA9="","",AB$58*AA9/AA$57) | AC9: =IF(AA9="","",IF(AB9>4,ROUND(AB9/2,0)*2,IF(AB9>AB$59,4,""))) | AD9: =_xlfn.XLOOKUP($B9,GCES!$B:$B,GCES!$AL:$AL,"",0,1) | AE9: =IF(AD9="","",AE$58*AD9/AD$57) | AF9: =IF(AD9="","",IF(AE9>4,ROUND(AE9/2,0)*2,IF(AE9>AE$59,4,""))) | AG9: =_xlfn.XLOOKUP($B9,GCES!$B:$B,GCES!$AK:$AK,"",0,1) | AH9: =IF(AG9="","",AH$58*AG9/AG$57) | AI9: =IF(AG9="","",IF(AH9>4,ROUND(AH9/2,0)*2,IF(AH9>AH$59,4,""))) | AJ9: =_xlfn.XLOOKUP($B9,GCES!$B:$B,GCES!$AQ:$AQ,"",0,1) | AK9: =IF(AJ9="","",AK$58*AJ9/AJ$57) | AL9: =IF(AJ9="","",IF(AK9>4,ROUND(AK9/2,0)*2,IF(AK9>AK$59,4,""))) | AM9: =_xlfn.XLOOKUP($B9,GCES!$B:$B,GCES!$AP:$AP,"",0,1) | AN9: =IF(AM9="","",AN$58*AM9/AM$57) | AO9: =IF(AM9="","",IF(AN9>4,ROUND(AN9/2,0)*2,IF(AN9>AN$59,4,""))) | AP9: =_xlfn.XLOOKUP($B9,GCES!$B:$B,GCES!$V:$V,"",0,1) | AQ9: =IF(AP9="","",AQ$58*AP9/AP$57) | AR9: =IF(AP9="","",IF(AQ9>4,ROUND(AQ9/2,0)*2,IF(AQ9>AQ$59,4,""))) | AS9: =_xlfn.XLOOKUP($B9,GCES!$B:$B,GCES!$AH:$AH,"",0,1) | AT9: =IF(AS9="","",AT$58*AS9/AS$57) | AU9: =IF(AS9="","",IF(AT9>4,ROUND(AT9/2,0)*2,IF(AT9>AT$59,4,""))) | AV9: =_xlfn.XLOOKUP($B9,GCES!$B:$B,GCES!$AG:$AG,"",0,1) | AW9: =IF(AV9="","",AW$58*AV9/AV$57) | AX9: =IF(AV9="","",IF(AW9>4,ROUND(AW9/2,0)*2,IF(AW9>AW$59,4,""))) | AY9: =_xlfn.XLOOKUP($B9,GCES!$B:$B,GCES!$AO:$AO,"",0,1) | AZ9: =IF(AY9="","",AZ$58*AY9/AY$57) | BA9: =IF(AY9="","",IF(AZ9>4,ROUND(AZ9/2,0)*2,IF(AZ9>AZ$59,4,""))) | BB9: =SUM(E9,H9,K9,N9,Q9,T9,W9,Z9,AC9,AF9,AI9,AL9,AO9,AR9,AU9,AX9,BA9) -> 0 | BC9: =_xlfn.XLOOKUP($B9,GCES!$B:$B,GCES!$F:$F,"",0,1) | BD9: =IF(BC9="","",BD$58*BC9/BC$57) | BE9: =IF(BC9="","",IF(BD9>4,ROUND(BD9/2,0)*2,IF(BD9>BD$59,4,""))) | BF9: =_xlfn.XLOOKUP($B9,GCES!$B:$B,GCES!$J:$J,"",0,1) | BG9: =IF(BF9="","",BG$58*BF9/BF$57) | BH9: =IF(BF9="","",IF(BG9>4,ROUND(BG9/2,0)*2,IF(BG9>BG$59,4,""))) | BI9: =_xlfn.XLOOKUP($B9,GCES!$B:$B,GCES!$I:$I,"",0,1) | BJ9: =IF(BI9="","",BJ$58*BI9/BI$57) | BK9: =IF(BI9="","",IF(BJ9>4,ROUND(BJ9/2,0)*2,IF(BJ9>BJ$59,4,""))) | BL9: =_xlfn.XLOOKUP($B9,GCES!$B:$B,GCES!$AN:$AN,"",0,1) | BM9: =IF(BL9="","",BM$58*BL9/BL$57) | BN9: =IF(BL9="","",IF(BM9>4,ROUND(BM9/2,0)*2,IF(BM9>BM$59,4,""))) | BO9: =_xlfn.XLOOKUP($B9,GCES!$B:$B,GCES!$AM:$AM,"",0,1) | BP9: =IF(BO9="","",BP$58*BO9/BO$57) | BQ9: =IF(BO9="","",IF(BP9>4,ROUND(BP9/2,0)*2,IF(BP9>BP$59,4,""))) | BR9: =_xlfn.XLOOKUP($B9,GCES!$B:$B,GCES!$Z:$Z,"",0,1) | BS9: =IF(BR9="","",BS$58*BR9/BR$57) | BT9: =IF(BR9="","",IF(BS9>4,ROUND(BS9/2,0)*2,IF(BS9>BS$59,4,""))) | BU9: =_xlfn.XLOOKUP($B9,GCES!$B:$B,GCES!$Y:$Y,"",0,1) | BV9: =IF(BU9="","",BV$58*BU9/BU$57) | BW9: =IF(BU9="","",IF(BV9>4,ROUND(BV9/2,0)*2,IF(BV9>BV$59,4,""))) | BX9: =_xlfn.XLOOKUP($B9,GCES!$B:$B,GCES!$AC:$AC,"",0,1) | BY9: =IF(BX9="","",BY$58*BX9/BX$57) | BZ9: =IF(BX9="","",IF(BY9>4,ROUND(BY9/2,0)*2,IF(BY9>BY$59,4,""))) | CA9: =_xlfn.XLOOKUP($B9,GCES!$B:$B,GCES!$AB:$AB,"",0,1) | CB9: =IF(CA9="","",CB$58*CA9/CA$57) | CC9: =IF(CA9="","",IF(CB9>4,ROUND(CB9/2,0)*2,IF(CB9>CB$59,4,""))) | CD9: =_xlfn.XLOOKUP($B9,GCES!$B:$B,GCES!$AS:$AS,"",0,1) | CE9: =IF(CD9="","",CE$58*CD9/CD$57) | CF9: =IF(CD9="","",IF(CE9>4,ROUND(CE9/2,0)*2,IF(CE9>CE$59,4,""))) | CG9: =_xlfn.XLOOKUP($B9,GCES!$B:$B,GCES!$AR:$AR,"",0,1) | CH9: =IF(CG9="","",CH$58*CG9/CG$57) | CI9: =IF(CG9="","",IF(CH9>4,ROUND(CH9/2,0)*2,IF(CH9>CH$59,4,""))) | CJ9: =_xlfn.XLOOKUP($B9,GCES!$B:$B,GCES!$N:$N,"",0,1) | CK9: =IF(CJ9="","",CK$58*CJ9/CJ$57) | CL9: =IF(CJ9="","",IF(CK9>4,ROUND(CK9/2,0)*2,IF(CK9>CK$59,4,""))) | CM9: =_xlfn.XLOOKUP($B9,GCES!$B:$B,GCES!$M:$M,"",0,1) | CN9: =IF(CM9="","",CN$58*CM9/CM$57) | CO9: =IF(CM9="","",IF(CN9>4,ROUND(CN9/2,0)*2,IF(CN9>CN$59,4,""))) | CP9: =_xlfn.XLOOKUP($B9,GCES!$B:$B,GCES!$AD:$AD,"",0,1) | CQ9: =IF(CP9="","",CQ$58*CP9/CP$57) | CR9: =IF(CP9="","",IF(CQ9>4,ROUND(CQ9/2,0)*2,IF(CQ9>CQ$59,4,""))) | CS9: =_xlfn.XLOOKUP($B9,GCES!$B:$B,GCES!$AJ:$AJ,"",0,1) | CT9: =IF(CS9="","",CT$58*CS9/CS$57) | CU9: =IF(CS9="","",IF(CT9>4,ROUND(CT9/2,0)*2,IF(CT9>CT$59,4,""))) | CV9: =_xlfn.XLOOKUP($B9,GCES!$B:$B,GCES!$AI:$AI,"",0,1) | CW9: =IF(CV9="","",CW$58*CV9/CV$57) | CX9: =IF(CV9="","",IF(CW9>4,ROUND(CW9/2,0)*2,IF(CW9>CW$59,4,""))) | CY9: =SUM(BE9,BH9,BK9,BN9,BQ9,BT9,BW9,BZ9,CC9,CF9,CI9,CL9,CO9,CR9,CU9,CX9) -> 0 | CZ9: =SUM(BB9,CY9) -> 0
A10: SRO COIMBATORE TOTAL | C10: =SUM(C6:C9) -> 0 | D10: =SUM(D6:D9) -> 0 | E10: =SUM(E6:E9) -> 0 | F10: =SUM(F6:F9) -> 0 | G10: =SUM(G6:G9) -> 0 | H10: =SUM(H6:H9) -> 0 | I10: =SUM(I6:I9) -> 16 | J10: =SUM(J6:J9) -> 1.5115207 | ... BA10: =SUM(BA6:BA9) -> 6 | BB10: =SUM(E10,H10,K10,N10,Q10,T10,W10,Z10,AC10,AF10,AI10,AL10,AO10,AR10,AU10,AX10,BA10) -> 40 | BC10: =SUM(BC6:BC9) -> 0 | BD10: =SUM(BD6:BD9) -> 0 | BE10: =SUM(BE6:BE9) -> 0 | BF10: =SUM(BF6:BF9) -> 36 | BG10: =SUM(BG6:BG9) -> 6.1554404 | BH10: =SUM(BH6:BH9) -> 6 | BI10: =SUM(BI6:BI9) -> 0 | BJ10: =SUM(BJ6:BJ9) -> 0 | ... CX10: =SUM(CX6:CX9) -> 0 | CY10: =SUM(BE10,BH10,BK10,BN10,BQ10,BT10,BW10,BZ10,CC10,CF10,CI10,CL10,CO10,CR10,CU10,CX10) -> 20 | CZ10: =SUM(BB10,CY10) -> 60
