Workbook

Sheet 2.0WP - Cen
A1: CENTRAL WORK PROGRAMME FOR AS2.0 OF TAMIL NADU BASED ON CES PLANNING 2026-27
C2: KHARIF | U2: RABI | AL2: GRAND TOTAL
C3: PAD | D3: PAD-II | F3: JWAR | H3: BJRA | J3: MAIZE | L3: GNUT | N3: GNGL | P3: RGRM | Q3: COTT | S3: SCAN | T3: TOTAL | U3: PAD | V3: JWAR | X3: GNUT | Z3: BGRM | AB3: GGRM | AD3: GNGL | AF3: BJRA | AH3: HGRM | AI3: COTT | AK3: TOTAL
C4: I | U4: III
A5: D_CD | B5: DIST_NM | C5: IR | D5: UI | E5: IR | F5: UI | G5: IR | H5: UI | I5: IR | J5: UI | K5: IR | L5: UI | M5: IR | N5: UI | O5: IR | P5: UI | Q5: UI | R5: IR | U5: IR | V5: UI | W5: IR | X5: UI | Y5: IR | Z5: UI | AA5: IR | AB5: UI | AC5: IR | AD5: UI | AE5: IR | AF5: UI | AG5: IR | AH5: UI | AI5: UI | AJ5: IR
A6: ='[1]2.0WS'!A6 -> 10 | B6: ='[1]2.0WS'!B6 -> ERODE | C6: ='[1]2.0WP'!C6 | D6: ='[1]2.0WP'!D6 | E6: ='[1]2.0WP'!E6 | F6: ='[1]2.0WP'!F6 | G6: ='[1]2.0WP'!G6 | H6: ='[1]2.0WP'!H6 | I6: ='[1]2.0WP'!I6 | J6: ='[1]2.0WP'!J6 -> 6 | ... S6: ='[1]2.0WP'!S6 -> 6 | T6: =SUM(C6:S6) -> 34 | U6: ='[1]2.0WP'!U6 | V6: ='[1]2.0WP'!V6 | W6: ='[1]2.0WP'!W6 | X6: ='[1]2.0WP'!X6 | Y6: ='[1]2.0WP'!Y6 -> 4 | Z6: ='[1]2.0WP'!Z6 | AA6: ='[1]2.0WP'!AA6 | AB6: ='[1]2.0WP'!AB6 | ... AJ6: ='[1]2.0WP'!AJ6 | AK6: =SUM(U6:AJ6) -> 10 | AL6: =SUM(T6,AK6) -> 44
A7: ='[1]2.0WS'!A7 -> 11 | B7: ='[1]2.0WS'!B7 -> THE NILGIRIS | C7: ='[1]2.0WP'!C7 | D7: ='[1]2.0WP'!D7 | E7: ='[1]2.0WP'!E7 | F7: ='[1]2.0WP'!F7 | G7: ='[1]2.0WP'!G7 | H7: ='[1]2.0WP'!H7 | I7: ='[1]2.0WP'!I7 | J7: ='[1]2.0WP'!J7 | ... S7: ='[1]2.0WP'!S7 | T7: =SUM(C7:S7) -> 0 | U7: ='[1]2.0WP'!U7 | V7: ='[1]2.0WP'!V7 | W7: ='[1]2.0WP'!W7 | X7: ='[1]2.0WP'!X7 | Y7: ='[1]2.0WP'!Y7 | Z7: ='[1]2.0WP'!Z7 | AA7: ='[1]2.0WP'!AA7 | AB7: ='[1]2.0WP'!AB7 | ... AJ7: ='[1]2.0WP'!AJ7 | AK7: =SUM(U7:AJ7) -> 0 | AL7: =SUM(T7,AK7) -> 0
A8: ='[1]2.0WS'!A8 -> 12 | B8: ='[1]2.0WS'!B8 -> COIMBATORE | C8: ='[1]2.0WP'!C8 | D8: ='[1]2.0WP'!D8 | E8: ='[1]2.0WP'!E8 | F8: ='[1]2.0WP'!F8 -> 6 | G8: ='[1]2.0WP'!G8 | H8: ='[1]2.0WP'!H8 | I8: ='[1]2.0WP'!I8 | J8: ='[1]2.0WP'!J8 | ... S8: ='[1]2.0WP'!S8 | T8: =SUM(C8:S8) -> 6 | U8: ='[1]2.0WP'!U8 | V8: ='[1]2.0WP'!V8 -> 6 | W8: ='[1]2.0WP'!W8 | X8: ='[1]2.0WP'!X8 | Y8: ='[1]2.0WP'!Y8 | Z8: ='[1]2.0WP'!Z8 | AA8: ='[1]2.0WP'!AA8 | AB8: ='[1]2.0WP'!AB8 | ... AJ8: ='[1]2.0WP'!AJ8 | AK8: =SUM(U8:AJ8) -> 10 | AL8: =SUM(T8,AK8) -> 16
A9: ='[1]2.0WS'!A9 -> 32 | B9: ='[1]2.0WS'!B9 -> TIRUPPUR | C9: ='[1]2.0WP'!C9 | D9: ='[1]2.0WP'!D9 | E9: ='[1]2.0WP'!E9 | F9: ='[1]2.0WP'!F9 | G9: ='[1]2.0WP'!G9 | H9: ='[1]2.0WP'!H9 | I9: ='[1]2.0WP'!I9 | J9: ='[1]2.0WP'!J9 | ... S9: ='[1]2.0WP'!S9 | T9: =SUM(C9:S9) -> 0 | U9: ='[1]2.0WP'!U9 | V9: ='[1]2.0WP'!V9 | W9: ='[1]2.0WP'!W9 | X9: ='[1]2.0WP'!X9 | Y9: ='[1]2.0WP'!Y9 | Z9: ='[1]2.0WP'!Z9 | AA9: ='[1]2.0WP'!AA9 | AB9: ='[1]2.0WP'!AB9 | ... AJ9: ='[1]2.0WP'!AJ9 | AK9: =SUM(U9:AJ9) -> 0 | AL9: =SUM(T9,AK9) -> 0
A10: ='[1]2.0WS'!A10 -> SRO COIMBATORE TOTAL | C10: =SUM(C6:C9) -> 0 | D10: =SUM(D6:D9) -> 0 | E10: =SUM(E6:E9) -> 0 | F10: =SUM(F6:F9) -> 6 | G10: =SUM(G6:G9) -> 0 | H10: =SUM(H6:H9) -> 0 | I10: =SUM(I6:I9) -> 0 | J10: =SUM(J6:J9) -> 6 | ... S10: =SUM(S6:S9) -> 6 | T10: =SUM(C10:S10) -> 40 | U10: =SUM(U6:U9) -> 0 | V10: =SUM(V6:V9) -> 6 | W10: =SUM(W6:W9) -> 0 | X10: =SUM(X6:X9) -> 0 | Y10: =SUM(Y6:Y9) -> 4 | Z10: =SUM(Z6:Z9) -> 0 | AA10: =SUM(AA6:AA9) -> 0 | AB10: =SUM(AB6:AB9) -> 0 | ... AJ10: =SUM(AJ6:AJ9) -> 0 | AK10: =SUM(U10:AJ10) -> 20 | AL10: =SUM(T10,AK10) -> 60
A11: ='[1]2.0WS'!A11 -> 05 | B11: ='[1]2.0WS'!B11 -> DHARMAPURI | C11: ='[1]2.0WP'!C11 | D11: ='[1]2.0WP'!D11 | E11: ='[1]2.0WP'!E11 -> 4 | F11: ='[1]2.0WP'!F11 -> 6 | G11: ='[1]2.0WP'!G11 | H11: ='[1]2.0WP'!H11 | I11: ='[1]2.0WP'!I11 | J11: ='[1]2.0WP'!J11 -> 6 | ... S11: ='[1]2.0WP'!S11 -> 4 | T11: =SUM(C11:S11) -> 56 | U11: ='[1]2.0WP'!U11 -> 4 | V11: ='[1]2.0WP'!V11 | W11: ='[1]2.0WP'!W11 | X11: ='[1]2.0WP'!X11 | Y11: ='[1]2.0WP'!Y11 -> 4 | Z11: ='[1]2.0WP'!Z11 | AA11: ='[1]2.0WP'!AA11 | AB11: ='[1]2.0WP'!AB11 | ... AJ11: ='[1]2.0WP'!AJ11 | AK11: =SUM(U11:AJ11) -> 20 | AL11: =SUM(T11,AK11) -> 76
A12: ='[1]2.0WS'!A12 -> 31 | B12: ='[1]2.0WS'!B12 -> KRISHNAGIRI | C12: ='[1]2.0WP'!C12 -> 4 | D12: ='[1]2.0WP'!D12 | E12: ='[1]2.0WP'!E12 | F12: ='[1]2.0WP'!F12 -> 4 | G12: ='[1]2.0WP'!G12 | H12: ='[1]2.0WP'!H12 | I12: ='[1]2.0WP'!I12 | J12: ='[1]2.0WP'!J12 | ... S12: ='[1]2.0WP'!S12 | T12: =SUM(C12:S12) -> 44 | U12: ='[1]2.0WP'!U12 -> 4 | V12: ='[1]2.0WP'!V12 | W12: ='[1]2.0WP'!W12 | X12: ='[1]2.0WP'!X12 | Y12: ='[1]2.0WP'!Y12 -> 4 | Z12: ='[1]2.0WP'!Z12 | AA12: ='[1]2.0WP'!AA12 | AB12: ='[1]2.0WP'!AB12 | ... AJ12: ='[1]2.0WP'!AJ12 | AK12: =SUM(U12:AJ12) -> 28 | AL12: =SUM(T12,AK12) -> 72
A13: ='[1]2.0WS'!A13 -> 36 | B13: ='[1]2.0WS'!B13 -> TIRUPATHUR | C13: ='[1]2.0WP'!C13 | D13: ='[1]2.0WP'!D13 | E13: ='[1]2.0WP'!E13 | F13: ='[1]2.0WP'!F13 -> 4 | G13: ='[1]2.0WP'!G13 | H13: ='[1]2.0WP'!H13 -> 6 | I13: ='[1]2.0WP'!I13 | J13: ='[1]2.0WP'!J13 | ... S13: ='[1]2.0WP'!S13 | T13: =SUM(C13:S13) -> 28 | U13: ='[1]2.0WP'!U13 | V13: ='[1]2.0WP'!V13 | W13: ='[1]2.0WP'!W13 | X13: ='[1]2.0WP'!X13 | Y13: ='[1]2.0WP'!Y13 | Z13: ='[1]2.0WP'!Z13 | AA13: ='[1]2.0WP'!AA13 | AB13: ='[1]2.0WP'!AB13 | ... AJ13: ='[1]2.0WP'!AJ13 | AK13: =SUM(U13:AJ13) -> 8 | AL13: =SUM(T13,AK13) -> 36
A14: ='[1]2.0WS'!A14 -> SRO DHARMAPURI TOTAL | C14: =SUM(C11:C13) -> 4 | D14: =SUM(D11:D13) -> 0 | E14: =SUM(E11:E13) -> 4 | F14: =SUM(F11:F13) -> 14 | G14: =SUM(G11:G13) -> 0 | H14: =SUM(H11:H13) -> 6 | I14: =SUM(I11:I13) -> 0 | J14: =SUM(J11:J13) -> 6 | ... S14: =SUM(S11:S13) -> 4 | T14: =SUM(C14:S14) -> 128 | U14: =SUM(U11:U13) -> 8 | V14: =SUM(V11:V13) -> 0 | W14: =SUM(W11:W13) -> 0 | X14: =SUM(X11:X13) -> 0 | Y14: =SUM(Y11:Y13) -> 8 | Z14: =SUM(Z11:Z13) -> 0 | AA14: =SUM(AA11:AA13) -> 0 | AB14: =SUM(AB11:AB13) -> 0 | ... AJ14: =SUM(AJ11:AJ13) -> 0 | AK14: =SUM(U14:AJ14) -> 56 | AL14: =SUM(T14,AK14) -> 184
A15: ='[1]2.0WS'!A15 -> 08 | B15: ='[1]2.0WS'!B15 -> SALEM | C15: ='[1]2.0WP'!C15 | D15: ='[1]2.0WP'!D15 | E15: ='[1]2.0WP'!E15 | F15: ='[1]2.0WP'!F15 -> 10 | G15: ='[1]2.0WP'!G15 | H15: ='[1]2.0WP'!H15 | I15: ='[1]2.0WP'!I15 | J15: ='[1]2.0WP'!J15 -> 6 | ... S15: ='[1]2.0WP'!S15 -> 4 | T15: =SUM(C15:S15) -> 62 | U15: ='[1]2.0WP'!U15 -> 4 | V15: ='[1]2.0WP'!V15 -> 4 | W15: ='[1]2.0WP'!W15 -> 6 | X15: ='[1]2.0WP'!X15 | Y15: ='[1]2.0WP'!Y15 -> 4 | Z15: ='[1]2.0WP'!Z15 | AA15: ='[1]2.0WP'!AA15 | AB15: ='[1]2.0WP'!AB15 | ... AJ15: ='[1]2.0WP'!AJ15 -> 6 | AK15: =SUM(U15:AJ15) -> 42 | AL15: =SUM(T15,AK15) -> 104
A16: ='[1]2.0WS'!A16 -> 09 | B16: ='[1]2.0WS'!B16 -> NAMAKKAL | C16: ='[1]2.0WP'!C16 | D16: ='[1]2.0WP'!D16 | E16: ='[1]2.0WP'!E16 -> 4 | F16: ='[1]2.0WP'!F16 -> 14 | G16: ='[1]2.0WP'!G16 -> 0 | H16: ='[1]2.0WP'!H16 | I16: ='[1]2.0WP'!I16 | J16: ='[1]2.0WP'!J16 | ... S16: ='[1]2.0WP'!S16 -> 4 | T16: =SUM(C16:S16) -> 40 | U16: ='[1]2.0WP'!U16 | V16: ='[1]2.0WP'!V16 -> 14 | W16: ='[1]2.0WP'!W16 -> 6 | X16: ='[1]2.0WP'!X16 | Y16: ='[1]2.0WP'!Y16 -> 4 | Z16: ='[1]2.0WP'!Z16 | AA16: ='[1]2.0WP'!AA16 | AB16: ='[1]2.0WP'!AB16 | ... AJ16: ='[1]2.0WP'!AJ16 | AK16: =SUM(U16:AJ16) -> 28 | AL16: =SUM(T16,AK16) -> 68
A17: ='[1]2.0WS'!A17 -> SRO SALEM TOTAL | C17: =SUM(C15:C16) -> 0 | D17: =SUM(D15:D16) -> 0 | E17: =SUM(E15:E16) -> 4 | F17: =SUM(F15:F16) -> 24 | G17: =SUM(G15:G16) -> 0 | H17: =SUM(H15:H16) -> 0 | I17: =SUM(I15:I16) -> 0 | J17: =SUM(J15:J16) -> 6 | ... S17: =SUM(S15:S16) -> 8 | T17: =SUM(C17:S17) -> 102 | U17: =SUM(U15:U16) -> 4 | V17: =SUM(V15:V16) -> 18 | W17: =SUM(W15:W16) -> 12 | X17: =SUM(X15:X16) -> 0 | Y17: =SUM(Y15:Y16) -> 8 | Z17: =SUM(Z15:Z16) -> 0 | AA17: =SUM(AA15:AA16) -> 0 | AB17: =SUM(AB15:AB16) -> 0 | ... AJ17: =SUM(AJ15:AJ16) -> 6 | AK17: =SUM(U17:AJ17) -> 70 | AL17: =SUM(T17,AK17) -> 172
A18: ='[1]2.0WS'!A18 -> 14 | B18: ='[1]2.0WS'!B18 -> KARUR | C18: ='[1]2.0WP'!C18 | D18: ='[1]2.0WP'!D18 | E18: ='[1]2.0WP'!E18 | F18: ='[1]2.0WP'!F18 -> 4 | G18: ='[1]2.0WP'!G18 -> 6 | H18: ='[1]2.0WP'!H18 | I18: ='[1]2.0WP'!I18 | J18: ='[1]2.0WP'!J18 | ... S18: ='[1]2.0WP'!S18 -> 4 | T18: =SUM(C18:S18) -> 26 | U18: ='[1]2.0WP'!U18 | V18: ='[1]2.0WP'!V18 -> 4 | W18: ='[1]2.0WP'!W18 -> 4 | X18: ='[1]2.0WP'!X18 | Y18: ='[1]2.0WP'!Y18 -> 4 | Z18: ='[1]2.0WP'!Z18 | AA18: ='[1]2.0WP'!AA18 | AB18: ='[1]2.0WP'!AB18 | ... AJ18: ='[1]2.0WP'!AJ18 | AK18: =SUM(U18:AJ18) -> 22 | AL18: =SUM(T18,AK18) -> 48
A19: ='[1]2.0WS'!A19 -> 15 | B19: ='[1]2.0WS'!B19 -> TIRUCHIRAPPALLI | C19: ='[1]2.0WP'!C19 | D19: ='[1]2.0WP'!D19 | E19: ='[1]2.0WP'!E19 | F19: ='[1]2.0WP'!F19 | G19: ='[1]2.0WP'!G19 | H19: ='[1]2.0WP'!H19 | I19: ='[1]2.0WP'!I19 | J19: ='[1]2.0WP'!J19 | ... S19: ='[1]2.0WP'!S19 | T19: =SUM(C19:S19) -> 0 | U19: ='[1]2.0WP'!U19 | V19: ='[1]2.0WP'!V19 | W19: ='[1]2.0WP'!W19 | X19: ='[1]2.0WP'!X19 | Y19: ='[1]2.0WP'!Y19 | Z19: ='[1]2.0WP'!Z19 | AA19: ='[1]2.0WP'!AA19 | AB19: ='[1]2.0WP'!AB19 | ... AJ19: ='[1]2.0WP'!AJ19 | AK19: =SUM(U19:AJ19) -> 0 | AL19: =SUM(T19,AK19) -> 0
A20: ='[1]2.0WS'!A20 -> 16 | B20: ='[1]2.0WS'!B20 -> PERAMBALUR | C20: ='[1]2.0WP'!C20 | D20: ='[1]2.0WP'!D20 | E20: ='[1]2.0WP'!E20 | F20: ='[1]2.0WP'!F20 | G20: ='[1]2.0WP'!G20 | H20: ='[1]2.0WP'!H20 | I20: ='[1]2.0WP'!I20 | J20: ='[1]2.0WP'!J20 -> 6 | ... S20: ='[1]2.0WP'!S20 -> 4 | T20: =SUM(C20:S20) -> 26 | U20: ='[1]2.0WP'!U20 | V20: ='[1]2.0WP'!V20 | W20: ='[1]2.0WP'!W20 | X20: ='[1]2.0WP'!X20 | Y20: ='[1]2.0WP'!Y20 -> 4 | Z20: ='[1]2.0WP'!Z20 | AA20: ='[1]2.0WP'!AA20 | AB20: ='[1]2.0WP'!AB20 | ... AJ20: ='[1]2.0WP'!AJ20 | AK20: =SUM(U20:AJ20) -> 4 | AL20: =SUM(T20,AK20) -> 30
A21: ='[1]2.0WS'!A21 -> 17 | B21: ='[1]2.0WS'!B21 -> ARIYALUR | C21: ='[1]2.0WP'!C21 -> 4 | D21: ='[1]2.0WP'!D21 | E21: ='[1]2.0WP'!E21 -> 4 | F21: ='[1]2.0WP'!F21 | G21: ='[1]2.0WP'!G21 | H21: ='[1]2.0WP'!H21 -> 8 | I21: ='[1]2.0WP'!I21 | J21: ='[1]2.0WP'!J21 -> 6 | ... S21: ='[1]2.0WP'!S21 -> 0 | T21: =SUM(C21:S21) -> 40 | U21: ='[1]2.0WP'!U21 | V21: ='[1]2.0WP'!V21 | W21: ='[1]2.0WP'!W21 | X21: ='[1]2.0WP'!X21 | Y21: ='[1]2.0WP'!Y21 -> 4 | Z21: ='[1]2.0WP'!Z21 -> 4 | AA21: ='[1]2.0WP'!AA21 | AB21: ='[1]2.0WP'!AB21 | ... AJ21: ='[1]2.0WP'!AJ21 | AK21: =SUM(U21:AJ21) -> 8 | AL21: =SUM(T21,AK21) -> 48
A22: ='[1]2.0WS'!A22 -> SRO TIRUCHIRAPALLI TOTAL | C22: =SUM(C18:C21) -> 4 | D22: =SUM(D18:D21) -> 0 | E22: =SUM(E18:E21) -> 4 | F22: =SUM(F18:F21) -> 4 | G22: =SUM(G18:G21) -> 6 | H22: =SUM(H18:H21) -> 8 | I22: =SUM(I18:I21) -> 0 | J22: =SUM(J18:J21) -> 12 | ... S22: =SUM(S18:S21) -> 8 | T22: =SUM(C22:S22) -> 92 | U22: =SUM(U18:U21) -> 0 | V22: =SUM(V18:V21) -> 4 | W22: =SUM(W18:W21) -> 4 | X22: =SUM(X18:X21) -> 0 | Y22: =SUM(Y18:Y21) -> 12 | Z22: =SUM(Z18:Z21) -> 4 | AA22: =SUM(AA18:AA21) -> 0 | AB22: =SUM(AB18:AB21) -> 0 | ... AJ22: =SUM(AJ18:AJ21) -> 0 | AK22: =SUM(U22:AJ22) -> 34 | AL22: =SUM(T22,AK22) -> 126
A23: ='[1]2.0WS'!A23 -> RO COIMBATORE TOTAL | C23: =SUM(C22,C17,C14,C10) -> 8 | D23: =SUM(D22,D17,D14,D10) -> 0 | E23: =SUM(E22,E17,E14,E10) -> 12 | F23: =SUM(F22,F17,F14,F10) -> 48 | G23: =SUM(G22,G17,G14,G10) -> 6 | H23: =SUM(H22,H17,H14,H10) -> 14 | I23: =SUM(I22,I17,I14,I10) -> 0 | J23: =SUM(J22,J17,J14,J10) -> 30 | ... S23: =SUM(S22,S17,S14,S10) -> 26 | T23: =SUM(C23:S23) -> 362 | U23: =SUM(U22,U17,U14,U10) -> 12 | V23: =SUM(V22,V17,V14,V10) -> 28 | W23: =SUM(W22,W17,W14,W10) -> 16 | X23: =SUM(X22,X17,X14,X10) -> 0 | Y23: =SUM(Y22,Y17,Y14,Y10) -> 32 | Z23: =SUM(Z22,Z17,Z14,Z10) -> 4 | AA23: =SUM(AA22,AA17,AA14,AA10) -> 0 | AB23: =SUM(AB22,AB17,AB14,AB10) -> 0 | ... AJ23: =SUM(AJ22,AJ17,AJ14,AJ10) -> 6 | AK23: =SUM(U23:AJ23) -> 180 | AL23: =SUM(T23,AK23) -> 542
A24: ='[1]2.0WS'!A24 -> 01 | B24: ='[1]2.0WS'!B24 -> THIRUVALLUR | C24: ='[1]2.0WP'!C24 -> 8 | D24: ='[1]2.0WP'!D24 | E24: ='[1]2.0WP'!E24 -> 6 | F24: ='[1]2.0WP'!F24 | G24: ='[1]2.0WP'!G24 | H24: ='[1]2.0WP'!H24 | I24: ='[1]2.0WP'!I24 | J24: ='[1]2.0WP'!J24 | ... S24: ='[1]2.0WP'!S24 -> 4 | T24: =SUM(C24:S24) -> 18 | U24: ='[1]2.0WP'!U24 -> 6 | V24: ='[1]2.0WP'!V24 | W24: ='[1]2.0WP'!W24 | X24: ='[1]2.0WP'!X24 | Y24: ='[1]2.0WP'!Y24 -> 4 | Z24: ='[1]2.0WP'!Z24 | AA24: ='[1]2.0WP'!AA24 | AB24: ='[1]2.0WP'!AB24 | ... AJ24: ='[1]2.0WP'!AJ24 | AK24: =SUM(U24:AJ24) -> 18 | AL24: =SUM(T24,AK24) -> 36
A25: ='[1]2.0WS'!A25 -> 03 | B25: ='[1]2.0WS'!B25 -> KANCHEEPURAM | C25: ='[1]2.0WP'!C25 -> 4 | D25: ='[1]2.0WP'!D25 | E25: ='[1]2.0WP'!E25 -> 4 | F25: ='[1]2.0WP'!F25 | G25: ='[1]2.0WP'!G25 | H25: ='[1]2.0WP'!H25 | I25: ='[1]2.0WP'!I25 | J25: ='[1]2.0WP'!J25 | ... S25: ='[1]2.0WP'!S25 | T25: =SUM(C25:S25) -> 12 | U25: ='[1]2.0WP'!U25 | V25: ='[1]2.0WP'!V25 | W25: ='[1]2.0WP'!W25 | X25: ='[1]2.0WP'!X25 | Y25: ='[1]2.0WP'!Y25 | Z25: ='[1]2.0WP'!Z25 | AA25: ='[1]2.0WP'!AA25 | AB25: ='[1]2.0WP'!AB25 | ... AJ25: ='[1]2.0WP'!AJ25 | AK25: =SUM(U25:AJ25) -> 0 | AL25: =SUM(T25,AK25) -> 12
A26: ='[1]2.0WS'!A26 -> 33 | B26: ='[1]2.0WS'!B26 -> CHENGALPATTU | C26: ='[1]2.0WP'!C26 -> 4 | D26: ='[1]2.0WP'!D26 | E26: ='[1]2.0WP'!E26 -> 4 | F26: ='[1]2.0WP'!F26 | G26: ='[1]2.0WP'!G26 | H26: ='[1]2.0WP'!H26 | I26: ='[1]2.0WP'!I26 | J26: ='[1]2.0WP'!J26 | ... S26: ='[1]2.0WP'!S26 -> 4 | T26: =SUM(C26:S26) -> 16 | U26: ='[1]2.0WP'!U26 -> 4 | V26: ='[1]2.0WP'!V26 | W26: ='[1]2.0WP'!W26 | X26: ='[1]2.0WP'!X26 | Y26: ='[1]2.0WP'!Y26 -> 4 | Z26: ='[1]2.0WP'!Z26 | AA26: ='[1]2.0WP'!AA26 | AB26: ='[1]2.0WP'!AB26 | ... AJ26: ='[1]2.0WP'!AJ26 | AK26: =SUM(U26:AJ26) -> 8 | AL26: =SUM(T26,AK26) -> 24
A27: ='[1]2.0WS'!A27 -> SRO CHENNAI TOTAL | C27: =SUM(C24:C26) -> 16 | D27: =SUM(D24:D26) -> 0 | E27: =SUM(E24:E26) -> 14 | F27: =SUM(F24:F26) -> 0 | G27: =SUM(G24:G26) -> 0 | H27: =SUM(H24:H26) -> 0 | I27: =SUM(I24:I26) -> 0 | J27: =SUM(J24:J26) -> 0 | ... S27: =SUM(S24:S26) -> 8 | T27: =SUM(C27:S27) -> 46 | U27: =SUM(U24:U26) -> 10 | V27: =SUM(V24:V26) -> 0 | W27: =SUM(W24:W26) -> 0 | X27: =SUM(X24:X26) -> 0 | Y27: =SUM(Y24:Y26) -> 8 | Z27: =SUM(Z24:Z26) -> 0 | AA27: =SUM(AA24:AA26) -> 0 | AB27: =SUM(AB24:AB26) -> 0 | ... AJ27: =SUM(AJ24:AJ26) -> 0 | AK27: =SUM(U27:AJ27) -> 26 | AL27: =SUM(T27,AK27) -> 72
A28: ='[1]2.0WS'!A28 -> 07 | B28: ='[1]2.0WS'!B28 -> VILUPPURAM | C28: ='[1]2.0WP'!C28 | D28: ='[1]2.0WP'!D28 | E28: ='[1]2.0WP'!E28 | F28: ='[1]2.0WP'!F28 | G28: ='[1]2.0WP'!G28 | H28: ='[1]2.0WP'!H28 | I28: ='[1]2.0WP'!I28 | J28: ='[1]2.0WP'!J28 | ... S28: ='[1]2.0WP'!S28 | T28: =SUM(C28:S28) -> 0 | U28: ='[1]2.0WP'!U28 | V28: ='[1]2.0WP'!V28 | W28: ='[1]2.0WP'!W28 | X28: ='[1]2.0WP'!X28 | Y28: ='[1]2.0WP'!Y28 | Z28: ='[1]2.0WP'!Z28 | AA28: ='[1]2.0WP'!AA28 | AB28: ='[1]2.0WP'!AB28 | ... AJ28: ='[1]2.0WP'!AJ28 | AK28: =SUM(U28:AJ28) -> 0 | AL28: =SUM(T28,AK28) -> 0
A29: ='[1]2.0WS'!A29 -> 18 | B29: ='[1]2.0WS'!B29 -> CUDDALORE | C29: ='[1]2.0WP'!C29 -> 8 | D29: ='[1]2.0WP'!D29 | E29: ='[1]2.0WP'!E29 -> 8 | F29: ='[1]2.0WP'!F29 | G29: ='[1]2.0WP'!G29 | H29: ='[1]2.0WP'!H29 -> 8 | I29: ='[1]2.0WP'!I29 -> 12 | J29: ='[1]2.0WP'!J29 -> 6 | ... S29: ='[1]2.0WP'!S29 -> 6 | T29: =SUM(C29:S29) -> 64 | U29: ='[1]2.0WP'!U29 -> 4 | V29: ='[1]2.0WP'!V29 | W29: ='[1]2.0WP'!W29 | X29: ='[1]2.0WP'!X29 | Y29: ='[1]2.0WP'!Y29 -> 4 | Z29: ='[1]2.0WP'!Z29 -> 8 | AA29: ='[1]2.0WP'!AA29 | AB29: ='[1]2.0WP'!AB29 -> 6 | ... AJ29: ='[1]2.0WP'!AJ29 | AK29: =SUM(U29:AJ29) -> 28 | AL29: =SUM(T29,AK29) -> 92
A30: ='[1]2.0WS'!A30 -> 34 | B30: ='[1]2.0WS'!B30 -> KALLAKURICHI | C30: ='[1]2.0WP'!C30 -> 4 | D30: ='[1]2.0WP'!D30 | E30: ='[1]2.0WP'!E30 -> 4 | F30: ='[1]2.0WP'!F30 | G30: ='[1]2.0WP'!G30 | H30: ='[1]2.0WP'!H30 -> 24 | I30: ='[1]2.0WP'!I30 | J30: ='[1]2.0WP'!J30 | ... S30: ='[1]2.0WP'!S30 -> 6 | T30: =SUM(C30:S30) -> 54 | U30: ='[1]2.0WP'!U30 -> 4 | V30: ='[1]2.0WP'!V30 | W30: ='[1]2.0WP'!W30 | X30: ='[1]2.0WP'!X30 | Y30: ='[1]2.0WP'!Y30 | Z30: ='[1]2.0WP'!Z30 -> 6 | AA30: ='[1]2.0WP'!AA30 | AB30: ='[1]2.0WP'!AB30 | ... AJ30: ='[1]2.0WP'!AJ30 | AK30: =SUM(U30:AJ30) -> 18 | AL30: =SUM(T30,AK30) -> 72
A31: ='[1]2.0WS'!A31 -> 38 | B31: ='[1]2.0WS'!B31 -> MAYILADUTHURAI | C31: ='[1]2.0WP'!C31 | D31: ='[1]2.0WP'!D31 | E31: ='[1]2.0WP'!E31 | F31: ='[1]2.0WP'!F31 | G31: ='[1]2.0WP'!G31 | H31: ='[1]2.0WP'!H31 | I31: ='[1]2.0WP'!I31 | J31: ='[1]2.0WP'!J31 | ... S31: ='[1]2.0WP'!S31 | T31: =SUM(C31:S31) -> 0 | U31: ='[1]2.0WP'!U31 | V31: ='[1]2.0WP'!V31 | W31: ='[1]2.0WP'!W31 | X31: ='[1]2.0WP'!X31 | Y31: ='[1]2.0WP'!Y31 | Z31: ='[1]2.0WP'!Z31 | AA31: ='[1]2.0WP'!AA31 | AB31: ='[1]2.0WP'!AB31 | ... AJ31: ='[1]2.0WP'!AJ31 | AK31: =SUM(U31:AJ31) -> 0 | AL31: =SUM(T31,AK31) -> 0
A32: ='[1]2.0WS'!A32 -> SRO CUDDALORE TOTAL | C32: =SUM(C28:C31) -> 12 | D32: =SUM(D28:D31) -> 0 | E32: =SUM(E28:E31) -> 12 | F32: =SUM(F28:F31) -> 0 | G32: =SUM(G28:G31) -> 0 | H32: =SUM(H28:H31) -> 32 | I32: =SUM(I28:I31) -> 12 | J32: =SUM(J28:J31) -> 6 | ... S32: =SUM(S28:S31) -> 12 | T32: =SUM(C32:S32) -> 118 | U32: =SUM(U28:U31) -> 8 | V32: =SUM(V28:V31) -> 0 | W32: =SUM(W28:W31) -> 0 | X32: =SUM(X28:X31) -> 0 | Y32: =SUM(Y28:Y31) -> 4 | Z32: =SUM(Z28:Z31) -> 14 | AA32: =SUM(AA28:AA31) -> 0 | AB32: =SUM(AB28:AB31) -> 6 | ... AJ32: =SUM(AJ28:AJ31) -> 0 | AK32: =SUM(U32:AJ32) -> 46 | AL32: =SUM(T32,AK32) -> 164
A33: ='[1]2.0WS'!A33 -> 04 | B33: ='[1]2.0WS'!B33 -> VELLORE | C33: ='[1]2.0WP'!C33 | D33: ='[1]2.0WP'!D33 | E33: ='[1]2.0WP'!E33 | F33: ='[1]2.0WP'!F33 | G33: ='[1]2.0WP'!G33 | H33: ='[1]2.0WP'!H33 | I33: ='[1]2.0WP'!I33 | J33: ='[1]2.0WP'!J33 | ... S33: ='[1]2.0WP'!S33 | T33: =SUM(C33:S33) -> 14 | U33: ='[1]2.0WP'!U33 | V33: ='[1]2.0WP'!V33 | W33: ='[1]2.0WP'!W33 | X33: ='[1]2.0WP'!X33 | Y33: ='[1]2.0WP'!Y33 | Z33: ='[1]2.0WP'!Z33 | AA33: ='[1]2.0WP'!AA33 | AB33: ='[1]2.0WP'!AB33 | ... AJ33: ='[1]2.0WP'!AJ33 | AK33: =SUM(U33:AJ33) -> 4 | AL33: =SUM(T33,AK33) -> 18
A34: ='[1]2.0WS'!A34 -> 06 | B34: ='[1]2.0WS'!B34 -> TIRUVANNAMALAI | C34: ='[1]2.0WP'!C34 | D34: ='[1]2.0WP'!D34 | E34: ='[1]2.0WP'!E34 | F34: ='[1]2.0WP'!F34 | G34: ='[1]2.0WP'!G34 | H34: ='[1]2.0WP'!H34 | I34: ='[1]2.0WP'!I34 | J34: ='[1]2.0WP'!J34 | ... S34: ='[1]2.0WP'!S34 | T34: =SUM(C34:S34) -> 0 | U34: ='[1]2.0WP'!U34 | V34: ='[1]2.0WP'!V34 | W34: ='[1]2.0WP'!W34 | X34: ='[1]2.0WP'!X34 | Y34: ='[1]2.0WP'!Y34 | Z34: ='[1]2.0WP'!Z34 | AA34: ='[1]2.0WP'!AA34 | AB34: ='[1]2.0WP'!AB34 | ... AJ34: ='[1]2.0WP'!AJ34 | AK34: =SUM(U34:AJ34) -> 0 | AL34: =SUM(T34,AK34) -> 0
A35: ='[1]2.0WS'!A35 -> 35 | B35: ='[1]2.0WS'!B35 -> RANIPET | C35: ='[1]2.0WP'!C35 -> 4 | D35: ='[1]2.0WP'!D35 | E35: ='[1]2.0WP'!E35 | F35: ='[1]2.0WP'!F35 | G35: ='[1]2.0WP'!G35 | H35: ='[1]2.0WP'!H35 | I35: ='[1]2.0WP'!I35 | J35: ='[1]2.0WP'!J35 | ... S35: ='[1]2.0WP'!S35 | T35: =SUM(C35:S35) -> 8 | U35: ='[1]2.0WP'!U35 -> 4 | V35: ='[1]2.0WP'!V35 | W35: ='[1]2.0WP'!W35 | X35: ='[1]2.0WP'!X35 | Y35: ='[1]2.0WP'!Y35 -> 4 | Z35: ='[1]2.0WP'!Z35 | AA35: ='[1]2.0WP'!AA35 | AB35: ='[1]2.0WP'!AB35 | ... AJ35: ='[1]2.0WP'!AJ35 | AK35: =SUM(U35:AJ35) -> 8 | AL35: =SUM(T35,AK35) -> 16
A36: ='[1]2.0WS'!A36 -> SRO VELLORE TOTAL | C36: =SUM(C33:C35) -> 4 | D36: =SUM(D33:D35) -> 0 | E36: =SUM(E33:E35) -> 0 | F36: =SUM(F33:F35) -> 0 | G36: =SUM(G33:G35) -> 0 | H36: =SUM(H33:H35) -> 0 | I36: =SUM(I33:I35) -> 0 | J36: =SUM(J33:J35) -> 0 | ... S36: =SUM(S33:S35) -> 0 | T36: =SUM(C36:S36) -> 22 | U36: =SUM(U33:U35) -> 4 | V36: =SUM(V33:V35) -> 0 | W36: =SUM(W33:W35) -> 0 | X36: =SUM(X33:X35) -> 0 | Y36: =SUM(Y33:Y35) -> 4 | Z36: =SUM(Z33:Z35) -> 0 | AA36: =SUM(AA33:AA35) -> 0 | AB36: =SUM(AB33:AB35) -> 0 | ... AJ36: =SUM(AJ33:AJ35) -> 0 | AK36: =SUM(U36:AJ36) -> 12 | AL36: =SUM(T36,AK36) -> 34
A37: ='[1]2.0WS'!A37 -> RO CHENNAI TOTAL | C37: =SUM(C36,C32,C27) -> 32 | D37: =SUM(D36,D32,D27) -> 0 | E37: =SUM(E36,E32,E27) -> 26 | F37: =SUM(F36,F32,F27) -> 0 | G37: =SUM(G36,G32,G27) -> 0 | H37: =SUM(H36,H32,H27) -> 32 | I37: =SUM(I36,I32,I27) -> 12 | J37: =SUM(J36,J32,J27) -> 6 | ... S37: =SUM(S36,S32,S27) -> 20 | T37: =SUM(C37:S37) -> 186 | U37: =SUM(U36,U32,U27) -> 22 | V37: =SUM(V36,V32,V27) -> 0 | W37: =SUM(W36,W32,W27) -> 0 | X37: =SUM(X36,X32,X27) -> 0 | Y37: =SUM(Y36,Y32,Y27) -> 16 | Z37: =SUM(Z36,Z32,Z27) -> 14 | AA37: =SUM(AA36,AA32,AA27) -> 0 | AB37: =SUM(AB36,AB32,AB27) -> 6 | ... AJ37: =SUM(AJ36,AJ32,AJ27) -> 0 | AK37: =SUM(U37:AJ37) -> 84 | AL37: =SUM(T37,AK37) -> 270
A38: ='[1]2.0WS'!A38 -> 13 | B38: ='[1]2.0WS'!B38 -> DINDIGUL | C38: ='[1]2.0WP'!C38 | D38: ='[1]2.0WP'!D38 | E38: ='[1]2.0WP'!E38 | F38: ='[1]2.0WP'!F38 -> 4 | G38: ='[1]2.0WP'!G38 | H38: ='[1]2.0WP'!H38 | I38: ='[1]2.0WP'!I38 | J38: ='[1]2.0WP'!J38 | ... S38: ='[1]2.0WP'!S38 -> 4 | T38: =SUM(C38:S38) -> 12 | U38: ='[1]2.0WP'!U38 -> 4 | V38: ='[1]2.0WP'!V38 -> 14 | W38: ='[1]2.0WP'!W38 -> 0 | X38: ='[1]2.0WP'!X38 -> 4 | Y38: ='[1]2.0WP'!Y38 -> 4 | Z38: ='[1]2.0WP'!Z38 -> 4 | AA38: ='[1]2.0WP'!AA38 | AB38: ='[1]2.0WP'!AB38 -> 6 | ... AJ38: ='[1]2.0WP'!AJ38 -> 4 | AK38: =SUM(U38:AJ38) -> 52 | AL38: =SUM(T38,AK38) -> 64
A39: ='[1]2.0WS'!A39 -> 23 | B39: ='[1]2.0WS'!B39 -> SIVAGANGAI | C39: ='[1]2.0WP'!C39 | D39: ='[1]2.0WP'!D39 | E39: ='[1]2.0WP'!E39 -> 8 | F39: ='[1]2.0WP'!F39 | G39: ='[1]2.0WP'!G39 | H39: ='[1]2.0WP'!H39 | I39: ='[1]2.0WP'!I39 | J39: ='[1]2.0WP'!J39 | ... S39: ='[1]2.0WP'!S39 -> 4 | T39: =SUM(C39:S39) -> 18 | U39: ='[1]2.0WP'!U39 | V39: ='[1]2.0WP'!V39 | W39: ='[1]2.0WP'!W39 | X39: ='[1]2.0WP'!X39 | Y39: ='[1]2.0WP'!Y39 | Z39: ='[1]2.0WP'!Z39 | AA39: ='[1]2.0WP'!AA39 | AB39: ='[1]2.0WP'!AB39 | ... AJ39: ='[1]2.0WP'!AJ39 | AK39: =SUM(U39:AJ39) -> 0 | AL39: =SUM(T39,AK39) -> 18
A40: ='[1]2.0WS'!A40 -> 24 | B40: ='[1]2.0WS'!B40 -> MADURAI | C40: ='[1]2.0WP'!C40 | D40: ='[1]2.0WP'!D40 | E40: ='[1]2.0WP'!E40 -> 4 | F40: ='[1]2.0WP'!F40 -> 4 | G40: ='[1]2.0WP'!G40 | H40: ='[1]2.0WP'!H40 -> 8 | I40: ='[1]2.0WP'!I40 | J40: ='[1]2.0WP'!J40 -> 6 | ... S40: ='[1]2.0WP'!S40 -> 0 | T40: =SUM(C40:S40) -> 30 | U40: ='[1]2.0WP'!U40 -> 4 | V40: ='[1]2.0WP'!V40 -> 4 | W40: ='[1]2.0WP'!W40 | X40: ='[1]2.0WP'!X40 | Y40: ='[1]2.0WP'!Y40 | Z40: ='[1]2.0WP'!Z40 | AA40: ='[1]2.0WP'!AA40 | AB40: ='[1]2.0WP'!AB40 | ... AJ40: ='[1]2.0WP'!AJ40 -> 6 | AK40: =SUM(U40:AJ40) -> 22 | AL40: =SUM(T40,AK40) -> 52
...

Sheet 2.0WP - State
A1: STATE WORK PROGRAMME FOR AS2.0 OF TAMIL NADU BASED ON CES PLANNING 2026-27
C2: KHARIF | U2: RABI | AL2: GRAND TOTAL
C3: PAD | D3: PAD-II | F3: JWAR | H3: BJRA | J3: MAIZE | L3: GNUT | N3: GNGL | P3: RGRM | Q3: COTT | S3: SCAN | T3: TOTAL | U3: PAD | V3: JWAR | X3: GNUT | Z3: BGRM | AB3: GGRM | AD3: GNGL | AF3: BJRA | AH3: HGRM | AI3: COTT | AK3: TOTAL
C4: I | U4: III
A5: D_CD | B5: DIST_NM | C5: IR | D5: UI | E5: IR | F5: UI | G5: IR | H5: UI | I5: IR | J5: UI | K5: IR | L5: UI | M5: IR | N5: UI | O5: IR | P5: UI | Q5: UI | R5: IR | U5: IR | V5: UI | W5: IR | X5: UI | Y5: IR | Z5: UI | AA5: IR | AB5: UI | AC5: IR | AD5: UI | AE5: IR | AF5: UI | AG5: IR | AH5: UI | AI5: UI | AJ5: IR
A6: ='[2]2.0WS'!A6 -> 10 | B6: ='[2]2.0WS'!B6 -> ERODE | C6: ='[2]2.0WP'!C6 | D6: ='[2]2.0WP'!D6 | E6: ='[2]2.0WP'!E6 | F6: ='[2]2.0WP'!F6 | G6: ='[2]2.0WP'!G6 | H6: ='[2]2.0WP'!H6 | I6: ='[2]2.0WP'!I6 | J6: ='[2]2.0WP'!J6 -> 4 | ... S6: ='[2]2.0WP'!S6 -> 4 | T6: =SUM(C6:S6) -> 20 | U6: ='[2]2.0WP'!U6 | V6: ='[2]2.0WP'!V6 | W6: ='[2]2.0WP'!W6 | X6: ='[2]2.0WP'!X6 | Y6: ='[2]2.0WP'!Y6 -> 4 | Z6: ='[2]2.0WP'!Z6 | AA6: ='[2]2.0WP'!AA6 | AB6: ='[2]2.0WP'!AB6 | ... AJ6: ='[2]2.0WP'!AJ6 | AK6: =SUM(U6:AJ6) -> 8 | AL6: =SUM(T6,AK6) -> 28
A7: ='[2]2.0WS'!A7 -> 11 | B7: ='[2]2.0WS'!B7 -> THE NILGIRIS | C7: ='[2]2.0WP'!C7 | D7: ='[2]2.0WP'!D7 | E7: ='[2]2.0WP'!E7 | F7: ='[2]2.0WP'!F7 | G7: ='[2]2.0WP'!G7 | H7: ='[2]2.0WP'!H7 | I7: ='[2]2.0WP'!I7 | J7: ='[2]2.0WP'!J7 | ... S7: ='[2]2.0WP'!S7 | T7: =SUM(C7:S7) -> 0 | U7: ='[2]2.0WP'!U7 | V7: ='[2]2.0WP'!V7 | W7: ='[2]2.0WP'!W7 | X7: ='[2]2.0WP'!X7 | Y7: ='[2]2.0WP'!Y7 | Z7: ='[2]2.0WP'!Z7 | AA7: ='[2]2.0WP'!AA7 | AB7: ='[2]2.0WP'!AB7 | ... AJ7: ='[2]2.0WP'!AJ7 | AK7: =SUM(U7:AJ7) -> 0 | AL7: =SUM(T7,AK7) -> 0
A8: ='[2]2.0WS'!A8 -> 12 | B8: ='[2]2.0WS'!B8 -> COIMBATORE | C8: ='[2]2.0WP'!C8 | D8: ='[2]2.0WP'!D8 | E8: ='[2]2.0WP'!E8 | F8: ='[2]2.0WP'!F8 -> 4 | G8: ='[2]2.0WP'!G8 | H8: ='[2]2.0WP'!H8 | I8: ='[2]2.0WP'!I8 | J8: ='[2]2.0WP'!J8 | ... S8: ='[2]2.0WP'!S8 | T8: =SUM(C8:S8) -> 4 | U8: ='[2]2.0WP'!U8 | V8: ='[2]2.0WP'!V8 -> 4 | W8: ='[2]2.0WP'!W8 | X8: ='[2]2.0WP'!X8 | Y8: ='[2]2.0WP'!Y8 | Z8: ='[2]2.0WP'!Z8 | AA8: ='[2]2.0WP'!AA8 | AB8: ='[2]2.0WP'!AB8 | ... AJ8: ='[2]2.0WP'!AJ8 | AK8: =SUM(U8:AJ8) -> 8 | AL8: =SUM(T8,AK8) -> 12
A9: ='[2]2.0WS'!A9 -> 32 | B9: ='[2]2.0WS'!B9 -> TIRUPPUR | C9: ='[2]2.0WP'!C9 | D9: ='[2]2.0WP'!D9 | E9: ='[2]2.0WP'!E9 | F9: ='[2]2.0WP'!F9 | G9: ='[2]2.0WP'!G9 | H9: ='[2]2.0WP'!H9 | I9: ='[2]2.0WP'!I9 | J9: ='[2]2.0WP'!J9 | ... S9: ='[2]2.0WP'!S9 | T9: =SUM(C9:S9) -> 0 | U9: ='[2]2.0WP'!U9 | V9: ='[2]2.0WP'!V9 | W9: ='[2]2.0WP'!W9 | X9: ='[2]2.0WP'!X9 | Y9: ='[2]2.0WP'!Y9 | Z9: ='[2]2.0WP'!Z9 | AA9: ='[2]2.0WP'!AA9 | AB9: ='[2]2.0WP'!AB9 | ... AJ9: ='[2]2.0WP'!AJ9 | AK9: =SUM(U9:AJ9) -> 0 | AL9: =SUM(T9,AK9) -> 0
A10: ='[2]2.0WS'!A10 -> SRO COIMBATORE TOTAL | C10: =SUM(C6:C9) -> 0 | D10: =SUM(D6:D9) -> 0 | E10: =SUM(E6:E9) -> 0 | F10: =SUM(F6:F9) -> 4 | G10: =SUM(G6:G9) -> 0 | H10: =SUM(H6:H9) -> 0 | I10: =SUM(I6:I9) -> 0 | J10: =SUM(J6:J9) -> 4 | ... S10: =SUM(S6:S9) -> 4 | T10: =SUM(C10:S10) -> 24 | U10: =SUM(U6:U9) -> 0 | V10: =SUM(V6:V9) -> 4 | W10: =SUM(W6:W9) -> 0 | X10: =SUM(X6:X9) -> 0 | Y10: =SUM(Y6:Y9) -> 4 | Z10: =SUM(Z6:Z9) -> 0 | AA10: =SUM(AA6:AA9) -> 0 | AB10: =SUM(AB6:AB9) -> 0 | ... AJ10: =SUM(AJ6:AJ9) -> 0 | AK10: =SUM(U10:AJ10) -> 16 | AL10: =SUM(T10,AK10) -> 40
A11: ='[2]2.0WS'!A11 -> 05 | B11: ='[2]2.0WS'!B11 -> DHARMAPURI | C11: ='[2]2.0WP'!C11 | D11: ='[2]2.0WP'!D11 | E11: ='[2]2.0WP'!E11 -> 4 | F11: ='[2]2.0WP'!F11 -> 4 | G11: ='[2]2.0WP'!G11 | H11: ='[2]2.0WP'!H11 | I11: ='[2]2.0WP'!I11 | J11: ='[2]2.0WP'!J11 -> 4 | ... S11: ='[2]2.0WP'!S11 -> 4 | T11: =SUM(C11:S11) -> 34 | U11: ='[2]2.0WP'!U11 -> 4 | V11: ='[2]2.0WP'!V11 | W11: ='[2]2.0WP'!W11 | X11: ='[2]2.0WP'!X11 | Y11: ='[2]2.0WP'!Y11 -> 4 | Z11: ='[2]2.0WP'!Z11 | AA11: ='[2]2.0WP'!AA11 | AB11: ='[2]2.0WP'!AB11 | ... AJ11: ='[2]2.0WP'!AJ11 | AK11: =SUM(U11:AJ11) -> 16 | AL11: =SUM(T11,AK11) -> 50
A12: ='[2]2.0WS'!A12 -> 31 | B12: ='[2]2.0WS'!B12 -> KRISHNAGIRI | C12: ='[2]2.0WP'!C12 -> 4 | D12: ='[2]2.0WP'!D12 | E12: ='[2]2.0WP'!E12 | F12: ='[2]2.0WP'!F12 | G12: ='[2]2.0WP'!G12 | H12: ='[2]2.0WP'!H12 | I12: ='[2]2.0WP'!I12 | J12: ='[2]2.0WP'!J12 | ... S12: ='[2]2.0WP'!S12 | T12: =SUM(C12:S12) -> 22 | U12: ='[2]2.0WP'!U12 -> 4 | V12: ='[2]2.0WP'!V12 | W12: ='[2]2.0WP'!W12 | X12: ='[2]2.0WP'!X12 | Y12: ='[2]2.0WP'!Y12 -> 0 | Z12: ='[2]2.0WP'!Z12 | AA12: ='[2]2.0WP'!AA12 | AB12: ='[2]2.0WP'!AB12 | ... AJ12: ='[2]2.0WP'!AJ12 | AK12: =SUM(U12:AJ12) -> 18 | AL12: =SUM(T12,AK12) -> 40
A13: ='[2]2.0WS'!A13 -> 36 | B13: ='[2]2.0WS'!B13 -> TIRUPATHUR | C13: ='[2]2.0WP'!C13 | D13: ='[2]2.0WP'!D13 | E13: ='[2]2.0WP'!E13 | F13: ='[2]2.0WP'!F13 | G13: ='[2]2.0WP'!G13 | H13: ='[2]2.0WP'!H13 -> 4 | I13: ='[2]2.0WP'!I13 | J13: ='[2]2.0WP'!J13 | ... S13: ='[2]2.0WP'!S13 | T13: =SUM(C13:S13) -> 16 | U13: ='[2]2.0WP'!U13 | V13: ='[2]2.0WP'!V13 | W13: ='[2]2.0WP'!W13 | X13: ='[2]2.0WP'!X13 | Y13: ='[2]2.0WP'!Y13 | Z13: ='[2]2.0WP'!Z13 | AA13: ='[2]2.0WP'!AA13 | AB13: ='[2]2.0WP'!AB13 | ... AJ13: ='[2]2.0WP'!AJ13 | AK13: =SUM(U13:AJ13) -> 4 | AL13: =SUM(T13,AK13) -> 20
A14: ='[2]2.0WS'!A14 -> SRO DHARMAPURI TOTAL | C14: =SUM(C11:C13) -> 4 | D14: =SUM(D11:D13) -> 0 | E14: =SUM(E11:E13) -> 4 | F14: =SUM(F11:F13) -> 4 | G14: =SUM(G11:G13) -> 0 | H14: =SUM(H11:H13) -> 4 | I14: =SUM(I11:I13) -> 0 | J14: =SUM(J11:J13) -> 4 | ... S14: =SUM(S11:S13) -> 4 | T14: =SUM(C14:S14) -> 72 | U14: =SUM(U11:U13) -> 8 | V14: =SUM(V11:V13) -> 0 | W14: =SUM(W11:W13) -> 0 | X14: =SUM(X11:X13) -> 0 | Y14: =SUM(Y11:Y13) -> 4 | Z14: =SUM(Z11:Z13) -> 0 | AA14: =SUM(AA11:AA13) -> 0 | AB14: =SUM(AB11:AB13) -> 0 | ... AJ14: =SUM(AJ11:AJ13) -> 0 | AK14: =SUM(U14:AJ14) -> 38 | AL14: =SUM(T14,AK14) -> 110
A15: ='[2]2.0WS'!A15 -> 08 | B15: ='[2]2.0WS'!B15 -> SALEM | C15: ='[2]2.0WP'!C15 | D15: ='[2]2.0WP'!D15 | E15: ='[2]2.0WP'!E15 | F15: ='[2]2.0WP'!F15 -> 6 | G15: ='[2]2.0WP'!G15 | H15: ='[2]2.0WP'!H15 | I15: ='[2]2.0WP'!I15 | J15: ='[2]2.0WP'!J15 -> 0 | ... S15: ='[2]2.0WP'!S15 | T15: =SUM(C15:S15) -> 26 | U15: ='[2]2.0WP'!U15 -> 4 | V15: ='[2]2.0WP'!V15 -> 0 | W15: ='[2]2.0WP'!W15 -> 6 | X15: ='[2]2.0WP'!X15 | Y15: ='[2]2.0WP'!Y15 -> 0 | Z15: ='[2]2.0WP'!Z15 | AA15: ='[2]2.0WP'!AA15 | AB15: ='[2]2.0WP'!AB15 | ... AJ15: ='[2]2.0WP'!AJ15 -> 4 | AK15: =SUM(U15:AJ15) -> 24 | AL15: =SUM(T15,AK15) -> 50
A16: ='[2]2.0WS'!A16 -> 09 | B16: ='[2]2.0WS'!B16 -> NAMAKKAL | C16: ='[2]2.0WP'!C16 | D16: ='[2]2.0WP'!D16 | E16: ='[2]2.0WP'!E16 | F16: ='[2]2.0WP'!F16 -> 10 | G16: ='[2]2.0WP'!G16 | H16: ='[2]2.0WP'!H16 | I16: ='[2]2.0WP'!I16 | J16: ='[2]2.0WP'!J16 | ... S16: ='[2]2.0WP'!S16 -> 4 | T16: =SUM(C16:S16) -> 22 | U16: ='[2]2.0WP'!U16 | V16: ='[2]2.0WP'!V16 -> 6 | W16: ='[2]2.0WP'!W16 -> 4 | X16: ='[2]2.0WP'!X16 | Y16: ='[2]2.0WP'!Y16 -> 4 | Z16: ='[2]2.0WP'!Z16 | AA16: ='[2]2.0WP'!AA16 | AB16: ='[2]2.0WP'!AB16 | ... AJ16: ='[2]2.0WP'!AJ16 | AK16: =SUM(U16:AJ16) -> 18 | AL16: =SUM(T16,AK16) -> 40
A17: ='[2]2.0WS'!A17 -> SRO SALEM TOTAL | C17: =SUM(C15:C16) -> 0 | D17: =SUM(D15:D16) -> 0 | E17: =SUM(E15:E16) -> 0 | F17: =SUM(F15:F16) -> 16 | G17: =SUM(G15:G16) -> 0 | H17: =SUM(H15:H16) -> 0 | I17: =SUM(I15:I16) -> 0 | J17: =SUM(J15:J16) -> 0 | ... S17: =SUM(S15:S16) -> 4 | T17: =SUM(C17:S17) -> 48 | U17: =SUM(U15:U16) -> 4 | V17: =SUM(V15:V16) -> 6 | W17: =SUM(W15:W16) -> 10 | X17: =SUM(X15:X16) -> 0 | Y17: =SUM(Y15:Y16) -> 4 | Z17: =SUM(Z15:Z16) -> 0 | AA17: =SUM(AA15:AA16) -> 0 | AB17: =SUM(AB15:AB16) -> 0 | ... AJ17: =SUM(AJ15:AJ16) -> 4 | AK17: =SUM(U17:AJ17) -> 42 | AL17: =SUM(T17,AK17) -> 90
A18: ='[2]2.0WS'!A18 -> 14 | B18: ='[2]2.0WS'!B18 -> KARUR | C18: ='[2]2.0WP'!C18 | D18: ='[2]2.0WP'!D18 | E18: ='[2]2.0WP'!E18 | F18: ='[2]2.0WP'!F18 -> 4 | G18: ='[2]2.0WP'!G18 -> 4 | H18: ='[2]2.0WP'!H18 | I18: ='[2]2.0WP'!I18 | J18: ='[2]2.0WP'!J18 | ... S18: ='[2]2.0WP'!S18 | T18: =SUM(C18:S18) -> 16 | U18: ='[2]2.0WP'!U18 | V18: ='[2]2.0WP'!V18 -> 4 | W18: ='[2]2.0WP'!W18 | X18: ='[2]2.0WP'!X18 | Y18: ='[2]2.0WP'!Y18 -> 0 | Z18: ='[2]2.0WP'!Z18 | AA18: ='[2]2.0WP'!AA18 | AB18: ='[2]2.0WP'!AB18 | ... AJ18: ='[2]2.0WP'!AJ18 | AK18: =SUM(U18:AJ18) -> 12 | AL18: =SUM(T18,AK18) -> 28
A19: ='[2]2.0WS'!A19 -> 15 | B19: ='[2]2.0WS'!B19 -> TIRUCHIRAPPALLI | C19: ='[2]2.0WP'!C19 | D19: ='[2]2.0WP'!D19 | E19: ='[2]2.0WP'!E19 | F19: ='[2]2.0WP'!F19 | G19: ='[2]2.0WP'!G19 | H19: ='[2]2.0WP'!H19 | I19: ='[2]2.0WP'!I19 | J19: ='[2]2.0WP'!J19 | ... S19: ='[2]2.0WP'!S19 | T19: =SUM(C19:S19) -> 0 | U19: ='[2]2.0WP'!U19 | V19: ='[2]2.0WP'!V19 | W19: ='[2]2.0WP'!W19 | X19: ='[2]2.0WP'!X19 | Y19: ='[2]2.0WP'!Y19 | Z19: ='[2]2.0WP'!Z19 | AA19: ='[2]2.0WP'!AA19 | AB19: ='[2]2.0WP'!AB19 | ... AJ19: ='[2]2.0WP'!AJ19 | AK19: =SUM(U19:AJ19) -> 0 | AL19: =SUM(T19,AK19) -> 0
A20: ='[2]2.0WS'!A20 -> 16 | B20: ='[2]2.0WS'!B20 -> PERAMBALUR | C20: ='[2]2.0WP'!C20 | D20: ='[2]2.0WP'!D20 | E20: ='[2]2.0WP'!E20 | F20: ='[2]2.0WP'!F20 | G20: ='[2]2.0WP'!G20 | H20: ='[2]2.0WP'!H20 | I20: ='[2]2.0WP'!I20 | J20: ='[2]2.0WP'!J20 -> 4 | ... S20: ='[2]2.0WP'!S20 -> 4 | T20: =SUM(C20:S20) -> 16 | U20: ='[2]2.0WP'!U20 | V20: ='[2]2.0WP'!V20 | W20: ='[2]2.0WP'!W20 | X20: ='[2]2.0WP'!X20 | Y20: ='[2]2.0WP'!Y20 -> 4 | Z20: ='[2]2.0WP'!Z20 | AA20: ='[2]2.0WP'!AA20 | AB20: ='[2]2.0WP'!AB20 | ... AJ20: ='[2]2.0WP'!AJ20 | AK20: =SUM(U20:AJ20) -> 4 | AL20: =SUM(T20,AK20) -> 20
A21: ='[2]2.0WS'!A21 -> 17 | B21: ='[2]2.0WS'!B21 -> ARIYALUR | C21: ='[2]2.0WP'!C21 -> 0 | D21: ='[2]2.0WP'!D21 | E21: ='[2]2.0WP'!E21 -> 4 | F21: ='[2]2.0WP'!F21 | G21: ='[2]2.0WP'!G21 | H21: ='[2]2.0WP'!H21 -> 4 | I21: ='[2]2.0WP'!I21 | J21: ='[2]2.0WP'!J21 -> 4 | ... S21: ='[2]2.0WP'!S21 | T21: =SUM(C21:S21) -> 20 | U21: ='[2]2.0WP'!U21 | V21: ='[2]2.0WP'!V21 | W21: ='[2]2.0WP'!W21 | X21: ='[2]2.0WP'!X21 | Y21: ='[2]2.0WP'!Y21 -> 0 | Z21: ='[2]2.0WP'!Z21 -> 4 | AA21: ='[2]2.0WP'!AA21 | AB21: ='[2]2.0WP'!AB21 | ... AJ21: ='[2]2.0WP'!AJ21 | AK21: =SUM(U21:AJ21) -> 4 | AL21: =SUM(T21,AK21) -> 24
A22: ='[2]2.0WS'!A22 -> SRO TIRUCHIRAPALLI TOTAL | C22: =SUM(C18:C21) -> 0 | D22: =SUM(D18:D21) -> 0 | E22: =SUM(E18:E21) -> 4 | F22: =SUM(F18:F21) -> 4 | G22: =SUM(G18:G21) -> 4 | H22: =SUM(H18:H21) -> 4 | I22: =SUM(I18:I21) -> 0 | J22: =SUM(J18:J21) -> 8 | ... S22: =SUM(S18:S21) -> 4 | T22: =SUM(C22:S22) -> 52 | U22: =SUM(U18:U21) -> 0 | V22: =SUM(V18:V21) -> 4 | W22: =SUM(W18:W21) -> 0 | X22: =SUM(X18:X21) -> 0 | Y22: =SUM(Y18:Y21) -> 4 | Z22: =SUM(Z18:Z21) -> 4 | AA22: =SUM(AA18:AA21) -> 0 | AB22: =SUM(AB18:AB21) -> 0 | ... AJ22: =SUM(AJ18:AJ21) -> 0 | AK22: =SUM(U22:AJ22) -> 20 | AL22: =SUM(T22,AK22) -> 72
A23: ='[2]2.0WS'!A23 -> RO COIMBATORE TOTAL | C23: =SUM(C22,C17,C14,C10) -> 4 | D23: =SUM(D22,D17,D14,D10) -> 0 | E23: =SUM(E22,E17,E14,E10) -> 8 | F23: =SUM(F22,F17,F14,F10) -> 28 | G23: =SUM(G22,G17,G14,G10) -> 4 | H23: =SUM(H22,H17,H14,H10) -> 8 | I23: =SUM(I22,I17,I14,I10) -> 0 | J23: =SUM(J22,J17,J14,J10) -> 16 | ... S23: =SUM(S22,S17,S14,S10) -> 16 | T23: =SUM(C23:S23) -> 196 | U23: =SUM(U22,U17,U14,U10) -> 12 | V23: =SUM(V22,V17,V14,V10) -> 14 | W23: =SUM(W22,W17,W14,W10) -> 10 | X23: =SUM(X22,X17,X14,X10) -> 0 | Y23: =SUM(Y22,Y17,Y14,Y10) -> 16 | Z23: =SUM(Z22,Z17,Z14,Z10) -> 4 | AA23: =SUM(AA22,AA17,AA14,AA10) -> 0 | AB23: =SUM(AB22,AB17,AB14,AB10) -> 0 | ... AJ23: =SUM(AJ22,AJ17,AJ14,AJ10) -> 4 | AK23: =SUM(U23:AJ23) -> 116 | AL23: =SUM(T23,AK23) -> 312
A24: ='[2]2.0WS'!A24 -> 01 | B24: ='[2]2.0WS'!B24 -> THIRUVALLUR | C24: ='[2]2.0WP'!C24 -> 4 | D24: ='[2]2.0WP'!D24 | E24: ='[2]2.0WP'!E24 -> 4 | F24: ='[2]2.0WP'!F24 | G24: ='[2]2.0WP'!G24 | H24: ='[2]2.0WP'!H24 | I24: ='[2]2.0WP'!I24 | J24: ='[2]2.0WP'!J24 | ... S24: ='[2]2.0WP'!S24 -> 4 | T24: =SUM(C24:S24) -> 12 | U24: ='[2]2.0WP'!U24 -> 4 | V24: ='[2]2.0WP'!V24 | W24: ='[2]2.0WP'!W24 | X24: ='[2]2.0WP'!X24 | Y24: ='[2]2.0WP'!Y24 -> 4 | Z24: ='[2]2.0WP'!Z24 | AA24: ='[2]2.0WP'!AA24 | AB24: ='[2]2.0WP'!AB24 | ... AJ24: ='[2]2.0WP'!AJ24 | AK24: =SUM(U24:AJ24) -> 12 | AL24: =SUM(T24,AK24) -> 24
A25: ='[2]2.0WS'!A25 -> 03 | B25: ='[2]2.0WS'!B25 -> KANCHEEPURAM | C25: ='[2]2.0WP'!C25 -> 4 | D25: ='[2]2.0WP'!D25 | E25: ='[2]2.0WP'!E25 | F25: ='[2]2.0WP'!F25 | G25: ='[2]2.0WP'!G25 | H25: ='[2]2.0WP'!H25 | I25: ='[2]2.0WP'!I25 | J25: ='[2]2.0WP'!J25 | ... S25: ='[2]2.0WP'!S25 | T25: =SUM(C25:S25) -> 4 | U25: ='[2]2.0WP'!U25 | V25: ='[2]2.0WP'!V25 | W25: ='[2]2.0WP'!W25 | X25: ='[2]2.0WP'!X25 | Y25: ='[2]2.0WP'!Y25 | Z25: ='[2]2.0WP'!Z25 | AA25: ='[2]2.0WP'!AA25 | AB25: ='[2]2.0WP'!AB25 | ... AJ25: ='[2]2.0WP'!AJ25 | AK25: =SUM(U25:AJ25) -> 0 | AL25: =SUM(T25,AK25) -> 4
A26: ='[2]2.0WS'!A26 -> 33 | B26: ='[2]2.0WS'!B26 -> CHENGALPATTU | C26: ='[2]2.0WP'!C26 -> 4 | D26: ='[2]2.0WP'!D26 | E26: ='[2]2.0WP'!E26 -> 4 | F26: ='[2]2.0WP'!F26 | G26: ='[2]2.0WP'!G26 | H26: ='[2]2.0WP'!H26 | I26: ='[2]2.0WP'!I26 | J26: ='[2]2.0WP'!J26 | ... S26: ='[2]2.0WP'!S26 | T26: =SUM(C26:S26) -> 12 | U26: ='[2]2.0WP'!U26 | V26: ='[2]2.0WP'!V26 | W26: ='[2]2.0WP'!W26 | X26: ='[2]2.0WP'!X26 | Y26: ='[2]2.0WP'!Y26 -> 4 | Z26: ='[2]2.0WP'!Z26 | AA26: ='[2]2.0WP'!AA26 | AB26: ='[2]2.0WP'!AB26 | ... AJ26: ='[2]2.0WP'!AJ26 | AK26: =SUM(U26:AJ26) -> 4 | AL26: =SUM(T26,AK26) -> 16
A27: ='[2]2.0WS'!A27 -> SRO CHENNAI TOTAL | C27: =SUM(C24:C26) -> 12 | D27: =SUM(D24:D26) -> 0 | E27: =SUM(E24:E26) -> 8 | F27: =SUM(F24:F26) -> 0 | G27: =SUM(G24:G26) -> 0 | H27: =SUM(H24:H26) -> 0 | I27: =SUM(I24:I26) -> 0 | J27: =SUM(J24:J26) -> 0 | ... S27: =SUM(S24:S26) -> 4 | T27: =SUM(C27:S27) -> 28 | U27: =SUM(U24:U26) -> 4 | V27: =SUM(V24:V26) -> 0 | W27: =SUM(W24:W26) -> 0 | X27: =SUM(X24:X26) -> 0 | Y27: =SUM(Y24:Y26) -> 8 | Z27: =SUM(Z24:Z26) -> 0 | AA27: =SUM(AA24:AA26) -> 0 | AB27: =SUM(AB24:AB26) -> 0 | ... AJ27: =SUM(AJ24:AJ26) -> 0 | AK27: =SUM(U27:AJ27) -> 16 | AL27: =SUM(T27,AK27) -> 44
A28: ='[2]2.0WS'!A28 -> 07 | B28: ='[2]2.0WS'!B28 -> VILUPPURAM | C28: ='[2]2.0WP'!C28 | D28: ='[2]2.0WP'!D28 | E28: ='[2]2.0WP'!E28 | F28: ='[2]2.0WP'!F28 | G28: ='[2]2.0WP'!G28 | H28: ='[2]2.0WP'!H28 | I28: ='[2]2.0WP'!I28 | J28: ='[2]2.0WP'!J28 | ... S28: ='[2]2.0WP'!S28 | T28: =SUM(C28:S28) -> 0 | U28: ='[2]2.0WP'!U28 | V28: ='[2]2.0WP'!V28 | W28: ='[2]2.0WP'!W28 | X28: ='[2]2.0WP'!X28 | Y28: ='[2]2.0WP'!Y28 | Z28: ='[2]2.0WP'!Z28 | AA28: ='[2]2.0WP'!AA28 | AB28: ='[2]2.0WP'!AB28 | ... AJ28: ='[2]2.0WP'!AJ28 | AK28: =SUM(U28:AJ28) -> 0 | AL28: =SUM(T28,AK28) -> 0
A29: ='[2]2.0WS'!A29 -> 18 | B29: ='[2]2.0WS'!B29 -> CUDDALORE | C29: ='[2]2.0WP'!C29 -> 4 | D29: ='[2]2.0WP'!D29 | E29: ='[2]2.0WP'!E29 -> 6 | F29: ='[2]2.0WP'!F29 | G29: ='[2]2.0WP'!G29 | H29: ='[2]2.0WP'!H29 -> 6 | I29: ='[2]2.0WP'!I29 -> 8 | J29: ='[2]2.0WP'!J29 -> 4 | ... S29: ='[2]2.0WP'!S29 -> 4 | T29: =SUM(C29:S29) -> 44 | U29: ='[2]2.0WP'!U29 -> 4 | V29: ='[2]2.0WP'!V29 | W29: ='[2]2.0WP'!W29 | X29: ='[2]2.0WP'!X29 | Y29: ='[2]2.0WP'!Y29 -> 0 | Z29: ='[2]2.0WP'!Z29 -> 4 | AA29: ='[2]2.0WP'!AA29 | AB29: ='[2]2.0WP'!AB29 -> 4 | ... AJ29: ='[2]2.0WP'!AJ29 | AK29: =SUM(U29:AJ29) -> 16 | AL29: =SUM(T29,AK29) -> 60
A30: ='[2]2.0WS'!A30 -> 34 | B30: ='[2]2.0WS'!B30 -> KALLAKURICHI | C30: ='[2]2.0WP'!C30 -> 0 | D30: ='[2]2.0WP'!D30 | E30: ='[2]2.0WP'!E30 -> 4 | F30: ='[2]2.0WP'!F30 | G30: ='[2]2.0WP'!G30 | H30: ='[2]2.0WP'!H30 -> 14 | I30: ='[2]2.0WP'!I30 | J30: ='[2]2.0WP'!J30 | ... S30: ='[2]2.0WP'!S30 -> 4 | T30: =SUM(C30:S30) -> 30 | U30: ='[2]2.0WP'!U30 | V30: ='[2]2.0WP'!V30 | W30: ='[2]2.0WP'!W30 | X30: ='[2]2.0WP'!X30 | Y30: ='[2]2.0WP'!Y30 | Z30: ='[2]2.0WP'!Z30 -> 4 | AA30: ='[2]2.0WP'!AA30 | AB30: ='[2]2.0WP'!AB30 | ... AJ30: ='[2]2.0WP'!AJ30 | AK30: =SUM(U30:AJ30) -> 8 | AL30: =SUM(T30,AK30) -> 38
A31: ='[2]2.0WS'!A31 -> 38 | B31: ='[2]2.0WS'!B31 -> MAYILADUTHURAI | C31: ='[2]2.0WP'!C31 | D31: ='[2]2.0WP'!D31 | E31: ='[2]2.0WP'!E31 | F31: ='[2]2.0WP'!F31 | G31: ='[2]2.0WP'!G31 | H31: ='[2]2.0WP'!H31 | I31: ='[2]2.0WP'!I31 | J31: ='[2]2.0WP'!J31 | ... S31: ='[2]2.0WP'!S31 | T31: =SUM(C31:S31) -> 0 | U31: ='[2]2.0WP'!U31 | V31: ='[2]2.0WP'!V31 | W31: ='[2]2.0WP'!W31 | X31: ='[2]2.0WP'!X31 | Y31: ='[2]2.0WP'!Y31 | Z31: ='[2]2.0WP'!Z31 | AA31: ='[2]2.0WP'!AA31 | AB31: ='[2]2.0WP'!AB31 | ... AJ31: ='[2]2.0WP'!AJ31 | AK31: =SUM(U31:AJ31) -> 0 | AL31: =SUM(T31,AK31) -> 0
A32: ='[2]2.0WS'!A32 -> SRO CUDDALORE TOTAL | C32: =SUM(C28:C31) -> 4 | D32: =SUM(D28:D31) -> 0 | E32: =SUM(E28:E31) -> 10 | F32: =SUM(F28:F31) -> 0 | G32: =SUM(G28:G31) -> 0 | H32: =SUM(H28:H31) -> 20 | I32: =SUM(I28:I31) -> 8 | J32: =SUM(J28:J31) -> 4 | ... S32: =SUM(S28:S31) -> 8 | T32: =SUM(C32:S32) -> 74 | U32: =SUM(U28:U31) -> 4 | V32: =SUM(V28:V31) -> 0 | W32: =SUM(W28:W31) -> 0 | X32: =SUM(X28:X31) -> 0 | Y32: =SUM(Y28:Y31) -> 0 | Z32: =SUM(Z28:Z31) -> 8 | AA32: =SUM(AA28:AA31) -> 0 | AB32: =SUM(AB28:AB31) -> 4 | ... AJ32: =SUM(AJ28:AJ31) -> 0 | AK32: =SUM(U32:AJ32) -> 24 | AL32: =SUM(T32,AK32) -> 98
A33: ='[2]2.0WS'!A33 -> 04 | B33: ='[2]2.0WS'!B33 -> VELLORE | C33: ='[2]2.0WP'!C33 | D33: ='[2]2.0WP'!D33 | E33: ='[2]2.0WP'!E33 | F33: ='[2]2.0WP'!F33 | G33: ='[2]2.0WP'!G33 | H33: ='[2]2.0WP'!H33 | I33: ='[2]2.0WP'!I33 | J33: ='[2]2.0WP'!J33 | ... S33: ='[2]2.0WP'!S33 | T33: =SUM(C33:S33) -> 8 | U33: ='[2]2.0WP'!U33 | V33: ='[2]2.0WP'!V33 | W33: ='[2]2.0WP'!W33 | X33: ='[2]2.0WP'!X33 | Y33: ='[2]2.0WP'!Y33 | Z33: ='[2]2.0WP'!Z33 | AA33: ='[2]2.0WP'!AA33 | AB33: ='[2]2.0WP'!AB33 | ... AJ33: ='[2]2.0WP'!AJ33 | AK33: =SUM(U33:AJ33) -> 0 | AL33: =SUM(T33,AK33) -> 8
A34: ='[2]2.0WS'!A34 -> 06 | B34: ='[2]2.0WS'!B34 -> TIRUVANNAMALAI | C34: ='[2]2.0WP'!C34 | D34: ='[2]2.0WP'!D34 | E34: ='[2]2.0WP'!E34 | F34: ='[2]2.0WP'!F34 | G34: ='[2]2.0WP'!G34 | H34: ='[2]2.0WP'!H34 | I34: ='[2]2.0WP'!I34 | J34: ='[2]2.0WP'!J34 | ... S34: ='[2]2.0WP'!S34 | T34: =SUM(C34:S34) -> 0 | U34: ='[2]2.0WP'!U34 | V34: ='[2]2.0WP'!V34 | W34: ='[2]2.0WP'!W34 | X34: ='[2]2.0WP'!X34 | Y34: ='[2]2.0WP'!Y34 | Z34: ='[2]2.0WP'!Z34 | AA34: ='[2]2.0WP'!AA34 | AB34: ='[2]2.0WP'!AB34 | ... AJ34: ='[2]2.0WP'!AJ34 | AK34: =SUM(U34:AJ34) -> 0 | AL34: =SUM(T34,AK34) -> 0
A35: ='[2]2.0WS'!A35 -> 35 | B35: ='[2]2.0WS'!B35 -> RANIPET | C35: ='[2]2.0WP'!C35 -> 4 | D35: ='[2]2.0WP'!D35 | E35: ='[2]2.0WP'!E35 | F35: ='[2]2.0WP'!F35 | G35: ='[2]2.0WP'!G35 | H35: ='[2]2.0WP'!H35 | I35: ='[2]2.0WP'!I35 | J35: ='[2]2.0WP'!J35 | ... S35: ='[2]2.0WP'!S35 | T35: =SUM(C35:S35) -> 8 | U35: ='[2]2.0WP'!U35 | V35: ='[2]2.0WP'!V35 | W35: ='[2]2.0WP'!W35 | X35: ='[2]2.0WP'!X35 | Y35: ='[2]2.0WP'!Y35 -> 4 | Z35: ='[2]2.0WP'!Z35 | AA35: ='[2]2.0WP'!AA35 | AB35: ='[2]2.0WP'!AB35 | ... AJ35: ='[2]2.0WP'!AJ35 | AK35: =SUM(U35:AJ35) -> 4 | AL35: =SUM(T35,AK35) -> 12
A36: ='[2]2.0WS'!A36 -> SRO VELLORE TOTAL | C36: =SUM(C33:C35) -> 4 | D36: =SUM(D33:D35) -> 0 | E36: =SUM(E33:E35) -> 0 | F36: =SUM(F33:F35) -> 0 | G36: =SUM(G33:G35) -> 0 | H36: =SUM(H33:H35) -> 0 | I36: =SUM(I33:I35) -> 0 | J36: =SUM(J33:J35) -> 0 | ... S36: =SUM(S33:S35) -> 0 | T36: =SUM(C36:S36) -> 16 | U36: =SUM(U33:U35) -> 0 | V36: =SUM(V33:V35) -> 0 | W36: =SUM(W33:W35) -> 0 | X36: =SUM(X33:X35) -> 0 | Y36: =SUM(Y33:Y35) -> 4 | Z36: =SUM(Z33:Z35) -> 0 | AA36: =SUM(AA33:AA35) -> 0 | AB36: =SUM(AB33:AB35) -> 0 | ... AJ36: =SUM(AJ33:AJ35) -> 0 | AK36: =SUM(U36:AJ36) -> 4 | AL36: =SUM(T36,AK36) -> 20
A37: ='[2]2.0WS'!A37 -> RO CHENNAI TOTAL | C37: =SUM(C36,C32,C27) -> 20 | D37: =SUM(D36,D32,D27) -> 0 | E37: =SUM(E36,E32,E27) -> 18 | F37: =SUM(F36,F32,F27) -> 0 | G37: =SUM(G36,G32,G27) -> 0 | H37: =SUM(H36,H32,H27) -> 20 | I37: =SUM(I36,I32,I27) -> 8 | J37: =SUM(J36,J32,J27) -> 4 | ... S37: =SUM(S36,S32,S27) -> 12 | T37: =SUM(C37:S37) -> 118 | U37: =SUM(U36,U32,U27) -> 8 | V37: =SUM(V36,V32,V27) -> 0 | W37: =SUM(W36,W32,W27) -> 0 | X37: =SUM(X36,X32,X27) -> 0 | Y37: =SUM(Y36,Y32,Y27) -> 12 | Z37: =SUM(Z36,Z32,Z27) -> 8 | AA37: =SUM(AA36,AA32,AA27) -> 0 | AB37: =SUM(AB36,AB32,AB27) -> 4 | ... AJ37: =SUM(AJ36,AJ32,AJ27) -> 0 | AK37: =SUM(U37:AJ37) -> 44 | AL37: =SUM(T37,AK37) -> 162
A38: ='[2]2.0WS'!A38 -> 13 | B38: ='[2]2.0WS'!B38 -> DINDIGUL | C38: ='[2]2.0WP'!C38 | D38: ='[2]2.0WP'!D38 | E38: ='[2]2.0WP'!E38 | F38: ='[2]2.0WP'!F38 -> 4 | G38: ='[2]2.0WP'!G38 | H38: ='[2]2.0WP'!H38 | I38: ='[2]2.0WP'!I38 | J38: ='[2]2.0WP'!J38 | ... S38: ='[2]2.0WP'!S38 -> 4 | T38: =SUM(C38:S38) -> 8 | U38: ='[2]2.0WP'!U38 -> 4 | V38: ='[2]2.0WP'!V38 -> 8 | W38: ='[2]2.0WP'!W38 | X38: ='[2]2.0WP'!X38 -> 4 | Y38: ='[2]2.0WP'!Y38 -> 0 | Z38: ='[2]2.0WP'!Z38 -> 0 | AA38: ='[2]2.0WP'!AA38 | AB38: ='[2]2.0WP'!AB38 -> 0 | ... AJ38: ='[2]2.0WP'!AJ38 -> 0 | AK38: =SUM(U38:AJ38) -> 20 | AL38: =SUM(T38,AK38) -> 28
A39: ='[2]2.0WS'!A39 -> 23 | B39: ='[2]2.0WS'!B39 -> SIVAGANGAI | C39: ='[2]2.0WP'!C39 | D39: ='[2]2.0WP'!D39 | E39: ='[2]2.0WP'!E39 -> 4 | F39: ='[2]2.0WP'!F39 | G39: ='[2]2.0WP'!G39 | H39: ='[2]2.0WP'!H39 | I39: ='[2]2.0WP'!I39 | J39: ='[2]2.0WP'!J39 | ... S39: ='[2]2.0WP'!S39 -> 4 | T39: =SUM(C39:S39) -> 12 | U39: ='[2]2.0WP'!U39 | V39: ='[2]2.0WP'!V39 | W39: ='[2]2.0WP'!W39 | X39: ='[2]2.0WP'!X39 | Y39: ='[2]2.0WP'!Y39 | Z39: ='[2]2.0WP'!Z39 | AA39: ='[2]2.0WP'!AA39 | AB39: ='[2]2.0WP'!AB39 | ... AJ39: ='[2]2.0WP'!AJ39 | AK39: =SUM(U39:AJ39) -> 0 | AL39: =SUM(T39,AK39) -> 12
A40: ='[2]2.0WS'!A40 -> 24 | B40: ='[2]2.0WS'!B40 -> MADURAI | C40: ='[2]2.0WP'!C40 | D40: ='[2]2.0WP'!D40 | E40: ='[2]2.0WP'!E40 -> 4 | F40: ='[2]2.0WP'!F40 -> 4 | G40: ='[2]2.0WP'!G40 | H40: ='[2]2.0WP'!H40 -> 4 | I40: ='[2]2.0WP'!I40 | J40: ='[2]2.0WP'!J40 -> 0 | ... S40: ='[2]2.0WP'!S40 | T40: =SUM(C40:S40) -> 16 | U40: ='[2]2.0WP'!U40 -> 4 | V40: ='[2]2.0WP'!V40 | W40: ='[2]2.0WP'!W40 | X40: ='[2]2.0WP'!X40 | Y40: ='[2]2.0WP'!Y40 | Z40: ='[2]2.0WP'!Z40 | AA40: ='[2]2.0WP'!AA40 | AB40: ='[2]2.0WP'!AB40 | ... AJ40: ='[2]2.0WP'!AJ40 -> 4 | AK40: =SUM(U40:AJ40) -> 16 | AL40: =SUM(T40,AK40) -> 32
...

Sheet 2.0WP - DIFF
A1: DIFFERENCE IN CENTRAL & STATE (CENTRAL - STATE) WORK PROGRAMME FOR AS2.0 OF TAMIL NADU BASED ON CES PLANNING 2026-27
C2: KHARIF | U2: RABI | AL2: GRAND TOTAL
C3: PAD | D3: PAD-II | F3: JWAR | H3: BJRA | J3: MAIZE | L3: GNUT | N3: GNGL | P3: RGRM | Q3: COTT | S3: SCAN | T3: TOTAL | U3: PAD | V3: JWAR | X3: GNUT | Z3: BGRM | AB3: GGRM | AD3: GNGL | AF3: BJRA | AH3: HGRM | AI3: COTT | AK3: TOTAL
C4: I | U4: III
A5: D_CD | B5: DIST_NM | C5: IR | D5: UI | E5: IR | F5: UI | G5: IR | H5: UI | I5: IR | J5: UI | K5: IR | L5: UI | M5: IR | N5: UI | O5: IR | P5: UI | Q5: UI | R5: IR | U5: IR | V5: UI | W5: IR | X5: UI | Y5: IR | Z5: UI | AA5: IR | AB5: UI | AC5: IR | AD5: UI | AE5: IR | AF5: UI | AG5: IR | AH5: UI | AI5: UI | AJ5: IR
A6: ='[1]2.0WS'!A6 -> 10 | B6: ='[1]2.0WS'!B6 -> ERODE | C6: =IF(_xlfn.NUMBERVALUE('2.0WP - Cen'!C6)-_xlfn.NUMBERVALUE('2.0WP - State'!C6)=0,"",_xlfn.NUMBERVALUE('2.0WP - Cen'!C6)-_xlfn.NUMBERVALUE('2.0WP - State'!C6)) | D6: =IF(_xlfn.NUMBERVALUE('2.0WP - Cen'!D6)-_xlfn.NUMBERVALUE('2.0WP - State'!D6)=0,"",_xlfn.NUMBERVALUE('2.0WP - Cen'!D6)-_xlfn.NUMBERVALUE('2.0WP - State'!D6)) | E6: =IF(_xlfn.NUMBERVALUE('2.0WP - Cen'!E6)-_xlfn.NUMBERVALUE('2.0WP - State'!E6)=0,"",_xlfn.NUMBERVALUE('2.0WP - Cen'!E6)-_xlfn.NUMBERVALUE('2.0WP - State'!E6)) | F6: =IF(_xlfn.NUMBERVALUE('2.0WP - Cen'!F6)-_xlfn.NUMBERVALUE('2.0WP - State'!F6)=0,"",_xlfn.NUMBERVALUE('2.0WP - Cen'!F6)-_xlfn.NUMBERVALUE('2.0WP - State'!F6)) | G6: =IF(_xlfn.NUMBERVALUE('2.0WP - Cen'!G6)-_xlfn.NUMBERVALUE('2.0WP - State'!G6)=0,"",_xlfn.NUMBERVALUE('2.0WP - Cen'!G6)-_xlfn.NUMBERVALUE('2.0WP - State'!G6)) | H6: =IF(_xlfn.NUMBERVALUE('2.0WP - Cen'!H6)-_xlfn.NUMBERVALUE('2.0WP - State'!H6)=0,"",_xlfn.NUMBERVALUE('2.0WP - Cen'!H6)-_xlfn.NUMBERVALUE('2.0WP - State'!H6)) | I6: =IF(_xlfn.NUMBERVALUE('2.0WP - Cen'!I6)-_xlfn.NUMBERVALUE('2.0WP - State'!I6)=0,"",_xlfn.NUMBERVALUE('2.0WP - Cen'!I6)-_xlfn.NUMBERVALUE('2.0WP - State'!I6)) | J6: =IF(_xlfn.NUMBERVALUE('2.0WP - Cen'!J6)-_xlfn.NUMBERVALUE('2.0WP - State'!J6)=0,"",_xlfn.NUMBERVALUE('2.0WP - Cen'!J6)-_xlfn.NUMBERVALUE('2.0WP - State'!J6)) -> 2 | ... S6: =IF(_xlfn.NUMBERVALUE('2.0WP - Cen'!S6)-_xlfn.NUMBERVALUE('2.0WP - State'!S6)=0,"",_xlfn.NUMBERVALUE('2.0WP - Cen'!S6)-_xlfn.NUMBERVALUE('2.0WP - State'!S6)) -> 2 | T6: =SUM(C6:S6) -> 14 | U6: =IF(_xlfn.NUMBERVALUE('2.0WP - Cen'!U6)-_xlfn.NUMBERVALUE('2.0WP - State'!U6)=0,"",_xlfn.NUMBERVALUE('2.0WP - Cen'!U6)-_xlfn.NUMBERVALUE('2.0WP - State'!U6)) | V6: =IF(_xlfn.NUMBERVALUE('2.0WP - Cen'!V6)-_xlfn.NUMBERVALUE('2.0WP - State'!V6)=0,"",_xlfn.NUMBERVALUE('2.0WP - Cen'!V6)-_xlfn.NUMBERVALUE('2.0WP - State'!V6)) | W6: =IF(_xlfn.NUMBERVALUE('2.0WP - Cen'!W6)-_xlfn.NUMBERVALUE('2.0WP - State'!W6)=0,"",_xlfn.NUMBERVALUE('2.0WP - Cen'!W6)-_xlfn.NUMBERVALUE('2.0WP - State'!W6)) | X6: =IF(_xlfn.NUMBERVALUE('2.0WP - Cen'!X6)-_xlfn.NUMBERVALUE('2.0WP - State'!X6)=0,"",_xlfn.NUMBERVALUE('2.0WP - Cen'!X6)-_xlfn.NUMBERVALUE('2.0WP - State'!X6)) | Y6: =IF(_xlfn.NUMBERVALUE('2.0WP - Cen'!Y6)-_xlfn.NUMBERVALUE('2.0WP - State'!Y6)=0,"",_xlfn.NUMBERVALUE('2.0WP - Cen'!Y6)-_xlfn.NUMBERVALUE('2.0WP - State'!Y6)) | Z6: =IF(_xlfn.NUMBERVALUE('2.0WP - Cen'!Z6)-_xlfn.NUMBERVALUE('2.0WP - State'!Z6)=0,"",_xlfn.NUMBERVALUE('2.0WP - Cen'!Z6)-_xlfn.NUMBERVALUE('2.0WP - State'!Z6)) | AA6: =IF(_xlfn.NUMBERVALUE('2.0WP - Cen'!AA6)-_xlfn.NUMBERVALUE('2.0WP - State'!AA6)=0,"",_xlfn.NUMBERVALUE('2.0WP - Cen'!AA6)-_xlfn.NUMBERVALUE('2.0WP - State'!AA6)) | AB6: =IF(_xlfn.NUMBERVALUE('2.0WP - Cen'!AB6)-_xlfn.NUMBERVALUE('2.0WP - State'!AB6)=0,"",_xlfn.NUMBERVALUE('2.0WP - Cen'!AB6)-_xlfn.NUMBERVALUE('2.0WP - State'!AB6)) | ... AJ6: =IF(_xlfn.NUMBERVALUE('2.0WP - Cen'!AJ6)-_xlfn.NUMBERVALUE('2.0WP - State'!AJ6)=0,"",_xlfn.NUMBERVALUE('2.0WP - Cen'!AJ6)-_xlfn.NUMBERVALUE('2.0WP - State'!AJ6)) | AK6: =SUM(U6:AJ6) -> 2 | AL6: =SUM(T6,AK6) -> 16
A7: ='[1]2.0WS'!A7 -> 11 | B7: ='[1]2.0WS'!B7 -> THE NILGIRIS | C7: =IF(_xlfn.NUMBERVALUE('2.0WP - Cen'!C7)-_xlfn.NUMBERVALUE('2.0WP - State'!C7)=0,"",_xlfn.NUMBERVALUE('2.0WP - Cen'!C7)-_xlfn.NUMBERVALUE('2.0WP - State'!C7)) | D7: =IF(_xlfn.NUMBERVALUE('2.0WP - Cen'!D7)-_xlfn.NUMBERVALUE('2.0WP - State'!D7)=0,"",_xlfn.NUMBERVALUE('2.0WP - Cen'!D7)-_xlfn.NUMBERVALUE('2.0WP - State'!D7)) | E7: =IF(_xlfn.NUMBERVALUE('2.0WP - Cen'!E7)-_xlfn.NUMBERVALUE('2.0WP - State'!E7)=0,"",_xlfn.NUMBERVALUE('2.0WP - Cen'!E7)-_xlfn.NUMBERVALUE('2.0WP - State'!E7)) | F7: =IF(_xlfn.NUMBERVALUE('2.0WP - Cen'!F7)-_xlfn.NUMBERVALUE('2.0WP - State'!F7)=0,"",_xlfn.NUMBERVALUE('2.0WP - Cen'!F7)-_xlfn.NUMBERVALUE('2.0WP - State'!F7)) | G7: =IF(_xlfn.NUMBERVALUE('2.0WP - Cen'!G7)-_xlfn.NUMBERVALUE('2.0WP - State'!G7)=0,"",_xlfn.NUMBERVALUE('2.0WP - Cen'!G7)-_xlfn.NUMBERVALUE('2.0WP - State'!G7)) | H7: =IF(_xlfn.NUMBERVALUE('2.0WP - Cen'!H7)-_xlfn.NUMBERVALUE('2.0WP - State'!H7)=0,"",_xlfn.NUMBERVALUE('2.0WP - Cen'!H7)-_xlfn.NUMBERVALUE('2.0WP - State'!H7)) | I7: =IF(_xlfn.NUMBERVALUE('2.0WP - Cen'!I7)-_xlfn.NUMBERVALUE('2.0WP - State'!I7)=0,"",_xlfn.NUMBERVALUE('2.0WP - Cen'!I7)-_xlfn.NUMBERVALUE('2.0WP - State'!I7)) | J7: =IF(_xlfn.NUMBERVALUE('2.0WP - Cen'!J7)-_xlfn.NUMBERVALUE('2.0WP - State'!J7)=0,"",_xlfn.NUMBERVALUE('2.0WP - Cen'!J7)-_xlfn.NUMBERVALUE('2.0WP - State'!J7)) | ... S7: =IF(_xlfn.NUMBERVALUE('2.0WP - Cen'!S7)-_xlfn.NUMBERVALUE('2.0WP - State'!S7)=0,"",_xlfn.NUMBERVALUE('2.0WP - Cen'!S7)-_xlfn.NUMBERVALUE('2.0WP - State'!S7)) | T7: =SUM(C7:S7) -> 0 | U7: =IF(_xlfn.NUMBERVALUE('2.0WP - Cen'!U7)-_xlfn.NUMBERVALUE('2.0WP - State'!U7)=0,"",_xlfn.NUMBERVALUE('2.0WP - Cen'!U7)-_xlfn.NUMBERVALUE('2.0WP - State'!U7)) | V7: =IF(_xlfn.NUMBERVALUE('2.0WP - Cen'!V7)-_xlfn.NUMBERVALUE('2.0WP - State'!V7)=0,"",_xlfn.NUMBERVALUE('2.0WP - Cen'!V7)-_xlfn.NUMBERVALUE('2.0WP - State'!V7)) | W7: =IF(_xlfn.NUMBERVALUE('2.0WP - Cen'!W7)-_xlfn.NUMBERVALUE('2.0WP - State'!W7)=0,"",_xlfn.NUMBERVALUE('2.0WP - Cen'!W7)-_xlfn.NUMBERVALUE('2.0WP - State'!W7)) | X7: =IF(_xlfn.NUMBERVALUE('2.0WP - Cen'!X7)-_xlfn.NUMBERVALUE('2.0WP - State'!X7)=0,"",_xlfn.NUMBERVALUE('2.0WP - Cen'!X7)-_xlfn.NUMBERVALUE('2.0WP - State'!X7)) | Y7: =IF(_xlfn.NUMBERVALUE('2.0WP - Cen'!Y7)-_xlfn.NUMBERVALUE('2.0WP - State'!Y7)=0,"",_xlfn.NUMBERVALUE('2.0WP - Cen'!Y7)-_xlfn.NUMBERVALUE('2.0WP - State'!Y7)) | Z7: =IF(_xlfn.NUMBERVALUE('2.0WP - Cen'!Z7)-_xlfn.NUMBERVALUE('2.0WP - State'!Z7)=0,"",_xlfn.NUMBERVALUE('2.0WP - Cen'!Z7)-_xlfn.NUMBERVALUE('2.0WP - State'!Z7)) | AA7: =IF(_xlfn.NUMBERVALUE('2.0WP - Cen'!AA7)-_xlfn.NUMBERVALUE('2.0WP - State'!AA7)=0,"",_xlfn.NUMBERVALUE('2.0WP - Cen'!AA7)-_xlfn.NUMBERVALUE('2.0WP - State'!AA7)) | AB7: =IF(_xlfn.NUMBERVALUE('2.0WP - Cen'!AB7)-_xlfn.NUMBERVALUE('2.0WP - State'!AB7)=0,"",_xlfn.NUMBERVALUE('2.0WP - Cen'!AB7)-_xlfn.NUMBERVALUE('2.0WP - State'!AB7)) | ... AJ7: =IF(_xlfn.NUMBERVALUE('2.0WP - Cen'!AJ7)-_xlfn.NUMBERVALUE('2.0WP - State'!AJ7)=0,"",_xlfn.NUMBERVALUE('2.0WP - Cen'!AJ7)-_xlfn.NUMBERVALUE('2.0WP - State'!AJ7)) | AK7: =SUM(U7:AJ7) -> 0 | AL7: =SUM(T7,AK7) -> 0
A8: ='[1]2.0WS'!A8 -> 12 | B8: ='[1]2.0WS'!B8 -> COIMBATORE | C8: =IF(_xlfn.NUMBERVALUE('2.0WP - Cen'!C8)-_xlfn.NUMBERVALUE('2.0WP - State'!C8)=0,"",_xlfn.NUMBERVALUE('2.0WP - Cen'!C8)-_xlfn.NUMBERVALUE('2.0WP - State'!C8)) | D8: =IF(_xlfn.NUMBERVALUE('2.0WP - Cen'!D8)-_xlfn.NUMBERVALUE('2.0WP - State'!D8)=0,"",_xlfn.NUMBERVALUE('2.0WP - Cen'!D8)-_xlfn.NUMBERVALUE('2.0WP - State'!D8)) | E8: =IF(_xlfn.NUMBERVALUE('2.0WP - Cen'!E8)-_xlfn.NUMBERVALUE('2.0WP - State'!E8)=0,"",_xlfn.NUMBERVALUE('2.0WP - Cen'!E8)-_xlfn.NUMBERVALUE('2.0WP - State'!E8)) | F8: =IF(_xlfn.NUMBERVALUE('2.0WP - Cen'!F8)-_xlfn.NUMBERVALUE('2.0WP - State'!F8)=0,"",_xlfn.NUMBERVALUE('2.0WP - Cen'!F8)-_xlfn.NUMBERVALUE('2.0WP - State'!F8)) -> 2 | G8: =IF(_xlfn.NUMBERVALUE('2.0WP - Cen'!G8)-_xlfn.NUMBERVALUE('2.0WP - State'!G8)=0,"",_xlfn.NUMBERVALUE('2.0WP - Cen'!G8)-_xlfn.NUMBERVALUE('2.0WP - State'!G8)) | H8: =IF(_xlfn.NUMBERVALUE('2.0WP - Cen'!H8)-_xlfn.NUMBERVALUE('2.0WP - State'!H8)=0,"",_xlfn.NUMBERVALUE('2.0WP - Cen'!H8)-_xlfn.NUMBERVALUE('2.0WP - State'!H8)) | I8: =IF(_xlfn.NUMBERVALUE('2.0WP - Cen'!I8)-_xlfn.NUMBERVALUE('2.0WP - State'!I8)=0,"",_xlfn.NUMBERVALUE('2.0WP - Cen'!I8)-_xlfn.NUMBERVALUE('2.0WP - State'!I8)) | J8: =IF(_xlfn.NUMBERVALUE('2.0WP - Cen'!J8)-_xlfn.NUMBERVALUE('2.0WP - State'!J8)=0,"",_xlfn.NUMBERVALUE('2.0WP - Cen'!J8)-_xlfn.NUMBERVALUE('2.0WP - State'!J8)) | ... S8: =IF(_xlfn.NUMBERVALUE('2.0WP - Cen'!S8)-_xlfn.NUMBERVALUE('2.0WP - State'!S8)=0,"",_xlfn.NUMBERVALUE('2.0WP - Cen'!S8)-_xlfn.NUMBERVALUE('2.0WP - State'!S8)) | T8: =SUM(C8:S8) -> 2 | U8: =IF(_xlfn.NUMBERVALUE('2.0WP - Cen'!U8)-_xlfn.NUMBERVALUE('2.0WP - State'!U8)=0,"",_xlfn.NUMBERVALUE('2.0WP - Cen'!U8)-_xlfn.NUMBERVALUE('2.0WP - State'!U8)) | V8: =IF(_xlfn.NUMBERVALUE('2.0WP - Cen'!V8)-_xlfn.NUMBERVALUE('2.0WP - State'!V8)=0,"",_xlfn.NUMBERVALUE('2.0WP - Cen'!V8)-_xlfn.NUMBERVALUE('2.0WP - State'!V8)) -> 2 | W8: =IF(_xlfn.NUMBERVALUE('2.0WP - Cen'!W8)-_xlfn.NUMBERVALUE('2.0WP - State'!W8)=0,"",_xlfn.NUMBERVALUE('2.0WP - Cen'!W8)-_xlfn.NUMBERVALUE('2.0WP - State'!W8)) | X8: =IF(_xlfn.NUMBERVALUE('2.0WP - Cen'!X8)-_xlfn.NUMBERVALUE('2.0WP - State'!X8)=0,"",_xlfn.NUMBERVALUE('2.0WP - Cen'!X8)-_xlfn.NUMBERVALUE('2.0WP - State'!X8)) | Y8: =IF(_xlfn.NUMBERVALUE('2.0WP - Cen'!Y8)-_xlfn.NUMBERVALUE('2.0WP - State'!Y8)=0,"",_xlfn.NUMBERVALUE('2.0WP - Cen'!Y8)-_xlfn.NUMBERVALUE('2.0WP - State'!Y8)) | Z8: =IF(_xlfn.NUMBERVALUE('2.0WP - Cen'!Z8)-_xlfn.NUMBERVALUE('2.0WP - State'!Z8)=0,"",_xlfn.NUMBERVALUE('2.0WP - Cen'!Z8)-_xlfn.NUMBERVALUE('2.0WP - State'!Z8)) | AA8: =IF(_xlfn.NUMBERVALUE('2.0WP - Cen'!AA8)-_xlfn.NUMBERVALUE('2.0WP - State'!AA8)=0,"",_xlfn.NUMBERVALUE('2.0WP - Cen'!AA8)-_xlfn.NUMBERVALUE('2.0WP - State'!AA8)) | AB8: =IF(_xlfn.NUMBERVALUE('2.0WP - Cen'!AB8)-_xlfn.NUMBERVALUE('2.0WP - State'!AB8)=0,"",_xlfn.NUMBERVALUE('2.0WP - Cen'!AB8)-_xlfn.NUMBERVALUE('2.0WP - State'!AB8)) | ... AJ8: =IF(_xlfn.NUMBERVALUE('2.0WP - Cen'!AJ8)-_xlfn.NUMBERVALUE('2.0WP - State'!AJ8)=0,"",_xlfn.NUMBERVALUE('2.0WP - Cen'!AJ8)-_xlfn.NUMBERVALUE('2.0WP - State'!AJ8)) | AK8: =SUM(U8:AJ8) -> 2 | AL8: =SUM(T8,AK8) -> 4
A9: ='[1]2.0WS'!A9 -> 32 | B9: ='[1]2.0WS'!B9 -> TIRUPPUR | C9: =IF(_xlfn.NUMBERVALUE('2.0WP - Cen'!C9)-_xlfn.NUMBERVALUE('2.0WP - State'!C9)=0,"",_xlfn.NUMBERVALUE('2.0WP - Cen'!C9)-_xlfn.NUMBERVALUE('2.0WP - State'!C9)) | D9: =IF(_xlfn.NUMBERVALUE('2.0WP - Cen'!D9)-_xlfn.NUMBERVALUE('2.0WP - State'!D9)=0,"",_xlfn.NUMBERVALUE('2.0WP - Cen'!D9)-_xlfn.NUMBERVALUE('2.0WP - State'!D9)) | E9: =IF(_xlfn.NUMBERVALUE('2.0WP - Cen'!E9)-_xlfn.NUMBERVALUE('2.0WP - State'!E9)=0,"",_xlfn.NUMBERVALUE('2.0WP - Cen'!E9)-_xlfn.NUMBERVALUE('2.0WP - State'!E9)) | F9: =IF(_xlfn.NUMBERVALUE('2.0WP - Cen'!F9)-_xlfn.NUMBERVALUE('2.0WP - State'!F9)=0,"",_xlfn.NUMBERVALUE('2.0WP - Cen'!F9)-_xlfn.NUMBERVALUE('2.0WP - State'!F9)) | G9: =IF(_xlfn.NUMBERVALUE('2.0WP - Cen'!G9)-_xlfn.NUMBERVALUE('2.0WP - State'!G9)=0,"",_xlfn.NUMBERVALUE('2.0WP - Cen'!G9)-_xlfn.NUMBERVALUE('2.0WP - State'!G9)) | H9: =IF(_xlfn.NUMBERVALUE('2.0WP - Cen'!H9)-_xlfn.NUMBERVALUE('2.0WP - State'!H9)=0,"",_xlfn.NUMBERVALUE('2.0WP - Cen'!H9)-_xlfn.NUMBERVALUE('2.0WP - State'!H9)) | I9: =IF(_xlfn.NUMBERVALUE('2.0WP - Cen'!I9)-_xlfn.NUMBERVALUE('2.0WP - State'!I9)=0,"",_xlfn.NUMBERVALUE('2.0WP - Cen'!I9)-_xlfn.NUMBERVALUE('2.0WP - State'!I9)) | J9: =IF(_xlfn.NUMBERVALUE('2.0WP - Cen'!J9)-_xlfn.NUMBERVALUE('2.0WP - State'!J9)=0,"",_xlfn.NUMBERVALUE('2.0WP - Cen'!J9)-_xlfn.NUMBERVALUE('2.0WP - State'!J9)) | ... S9: =IF(_xlfn.NUMBERVALUE('2.0WP - Cen'!S9)-_xlfn.NUMBERVALUE('2.0WP - State'!S9)=0,"",_xlfn.NUMBERVALUE('2.0WP - Cen'!S9)-_xlfn.NUMBERVALUE('2.0WP - State'!S9)) | T9: =SUM(C9:S9) -> 0 | U9: =IF(_xlfn.NUMBERVALUE('2.0WP - Cen'!U9)-_xlfn.NUMBERVALUE('2.0WP - State'!U9)=0,"",_xlfn.NUMBERVALUE('2.0WP - Cen'!U9)-_xlfn.NUMBERVALUE('2.0WP - State'!U9)) | V9: =IF(_xlfn.NUMBERVALUE('2.0WP - Cen'!V9)-_xlfn.NUMBERVALUE('2.0WP - State'!V9)=0,"",_xlfn.NUMBERVALUE('2.0WP - Cen'!V9)-_xlfn.NUMBERVALUE('2.0WP - State'!V9)) | W9: =IF(_xlfn.NUMBERVALUE('2.0WP - Cen'!W9)-_xlfn.NUMBERVALUE('2.0WP - State'!W9)=0,"",_xlfn.NUMBERVALUE('2.0WP - Cen'!W9)-_xlfn.NUMBERVALUE('2.0WP - State'!W9)) | X9: =IF(_xlfn.NUMBERVALUE('2.0WP - Cen'!X9)-_xlfn.NUMBERVALUE('2.0WP - State'!X9)=0,"",_xlfn.NUMBERVALUE('2.0WP - Cen'!X9)-_xlfn.NUMBERVALUE('2.0WP - State'!X9)) | Y9: =IF(_xlfn.NUMBERVALUE('2.0WP - Cen'!Y9)-_xlfn.NUMBERVALUE('2.0WP - State'!Y9)=0,"",_xlfn.NUMBERVALUE('2.0WP - Cen'!Y9)-_xlfn.NUMBERVALUE('2.0WP - State'!Y9)) | Z9: =IF(_xlfn.NUMBERVALUE('2.0WP - Cen'!Z9)-_xlfn.NUMBERVALUE('2.0WP - State'!Z9)=0,"",_xlfn.NUMBERVALUE('2.0WP - Cen'!Z9)-_xlfn.NUMBERVALUE('2.0WP - State'!Z9)) | AA9: =IF(_xlfn.NUMBERVALUE('2.0WP - Cen'!AA9)-_xlfn.NUMBERVALUE('2.0WP - State'!AA9)=0,"",_xlfn.NUMBERVALUE('2.0WP - Cen'!AA9)-_xlfn.NUMBERVALUE('2.0WP - State'!AA9)) | AB9: =IF(_xlfn.NUMBERVALUE('2.0WP - Cen'!AB9)-_xlfn.NUMBERVALUE('2.0WP - State'!AB9)=0,"",_xlfn.NUMBERVALUE('2.0WP - Cen'!AB9)-_xlfn.NUMBERVALUE('2.0WP - State'!AB9)) | ... AJ9: =IF(_xlfn.NUMBERVALUE('2.0WP - Cen'!AJ9)-_xlfn.NUMBERVALUE('2.0WP - State'!AJ9)=0,"",_xlfn.NUMBERVALUE('2.0WP - Cen'!AJ9)-_xlfn.NUMBERVALUE('2.0WP - State'!AJ9)) | AK9: =SUM(U9:AJ9) -> 0 | AL9: =SUM(T9,AK9) -> 0
A10: ='[1]2.0WS'!A10 -> SRO COIMBATORE TOTAL | C10: =SUM(C6:C9) -> 0 | D10: =SUM(D6:D9) -> 0 | E10: =SUM(E6:E9) -> 0 | F10: =SUM(F6:F9) -> 2 | G10: =SUM(G6:G9) -> 0 | H10: =SUM(H6:H9) -> 0 | I10: =SUM(I6:I9) -> 0 | J10: =SUM(J6:J9) -> 2 | ... S10: =SUM(S6:S9) -> 2 | T10: =SUM(C10:S10) -> 16 | U10: =SUM(U6:U9) -> 0 | V10: =SUM(V6:V9) -> 2 | W10: =SUM(W6:W9) -> 0 | X10: =SUM(X6:X9) -> 0 | Y10: =SUM(Y6:Y9) -> 0 | Z10: =SUM(Z6:Z9) -> 0 | AA10: =SUM(AA6:AA9) -> 0 | AB10: =SUM(AB6:AB9) -> 0 | ... AJ10: =SUM(AJ6:AJ9) -> 0 | AK10: =SUM(U10:AJ10) -> 4 | AL10: =SUM(T10,AK10) -> 20
