Workbook

Sheet GCA
A1: Gross Cropped Area (in Hectares)
A2: Sl.No. | B2: District | C2: Taluk | D2: Block | E2: 2024-25 | F2: 2023-24 | G2: 2022-23
A3: 1 | B3: Ariyalur | C3: ANDIMADAM | D3: ANDIMADAM | E3: 21571.297 | F3: 21937.5 | G3: 21630.84 | H3: =CONCATENATE(B3,"_",C3,"_",D3) -> Ariyalur_ANDIMADAM_ANDIMADAM
A4: 2 | B4: Ariyalur | C4: ARIYALUR | D4: ARIYALUR | E4: 15329.845 | F4: 15690.225 | G4: 15423.815 | H4: =CONCATENATE(B4,"_",C4,"_",D4) -> Ariyalur_ARIYALUR_ARIYALUR
A5: 3 | B5: Ariyalur | C5: ARIYALUR | D5: THIRUMANUR | E5: 21167.06 | F5: 20610.33 | G5: 21691.355 | H5: =CONCATENATE(B5,"_",C5,"_",D5) -> Ariyalur_ARIYALUR_THIRUMANUR
A6: 4 | B6: Ariyalur | C6: SENDURAI | D6: SENDURAI | E6: 23545.394 | F6: 23545.42 | G6: 23514.965 | H6: =CONCATENATE(B6,"_",C6,"_",D6) -> Ariyalur_SENDURAI_SENDURAI
A7: 5 | B7: Ariyalur | C7: UDAYARPALAYAM | D7: JAYANKONDAM | E7: 18012.39 | F7: 16495.535 | G7: 16649.215 | H7: =CONCATENATE(B7,"_",C7,"_",D7) -> Ariyalur_UDAYARPALAYAM_JAYANKONDAM
A8: 6 | B8: Ariyalur | C8: UDAYARPALAYAM | D8: T.PALUR | E8: 19559.49 | F8: 19847.685 | G8: 19832.58 | H8: =CONCATENATE(B8,"_",C8,"_",D8) -> Ariyalur_UDAYARPALAYAM_T.PALUR
A9: 7 | B9: Chengalpattu | C9: CHENGALPATTU | D9: KATTANKULATHUR | E9: 2424.747 | F9: 2232.171 | G9: 2506.056 | H9: =CONCATENATE(B9,"_",C9,"_",D9) -> Chengalpattu_CHENGALPATTU_KATTANKULATHUR
A10: 8 | B10: Chengalpattu | C10: CHEYYUR | D10: CHITHAMUR | E10: 15569.97 | F10: 15283.593 | G10: 15515.933 | H10: =CONCATENATE(B10,"_",C10,"_",D10) -> Chengalpattu_CHEYYUR_CHITHAMUR
A11: 9 | B11: Chengalpattu | C11: CHEYYUR | D11: LATHUR | E11: 12361.23 | F11: 13243.663 | G11: 12772.265 | H11: =CONCATENATE(B11,"_",C11,"_",D11) -> Chengalpattu_CHEYYUR_LATHUR
A12: 10 | B12: Chengalpattu | C12: MADHURANTHAKAM | D12: ACHARAPPAKKAM | E12: 13125.365 | F12: 12665.805 | G12: 12694.155 | H12: =CONCATENATE(B12,"_",C12,"_",D12) -> Chengalpattu_MADHURANTHAKAM_ACHARAPPAKKAM
A13: 11 | B13: Chengalpattu | C13: MADHURANTHAKAM | D13: MADHURANTHAKAM | E13: 17723.02 | F13: 17836.94 | G13: 16344.87 | H13: =CONCATENATE(B13,"_",C13,"_",D13) -> Chengalpattu_MADHURANTHAKAM_MADHURANTHAKAM
A14: 12 | B14: Chengalpattu | C14: PALLAVARAM | D14: CHITLAPAKKAM | E14: 40.697 | F14: 65.903 | G14: 54.178 | H14: =CONCATENATE(B14,"_",C14,"_",D14) -> Chengalpattu_PALLAVARAM_CHITLAPAKKAM
... A593: 591 | B593: Virudhunagar | C593: VIRUDHUNAGAR | D593: VIRUDHUNAGAR | E593: 9326.68 | F593: 9730.14 | G593: 9577.93 | H593: =CONCATENATE(B593,"_",C593,"_",D593) -> Virudhunagar_VIRUDHUNAGAR_VIRUDHUNAGAR

Sheet 1.0WS_TN
A1: PLAN OF WORK FOR UNDERTAKING SAMPLE CHECK ON AREA ENUMERATION BY CENTRAL AND STATE AGENCIES & SAMPLE CHECK ON AGGREGATION OF AREA BY STATE AGENCY UNDER ICS
A2: STATE: TAMIL NADU
A3: SEASON: PH-I (Early Kharif), PH-II (Late Kharif) and PH-III (Rabi) | P3: YEAR: 2026-27
A4: RO | B4: SRO | C4: Distt. | D4: Distt. Code | E4: Stratum | F4: Taluka | G4: Block | H4: AREA | L4: TOTAL | M4: PLAN | N4: ADJ | O4: #Vill. Planned | V4: Area
H5: 2024-25 | I5: 2023-24 | J5: 2022-23 | K5: Average | O5: Central | P5: State | R5: Distt | S5: Taluk | T5: Block | U5: concatenation | V5: yr1 | W5: yr2 | X5: yr3
A6: Coimbatore | B6: Coimbatore | C6: Erode | D6: 10 | E6: 1 | F6: Anthiyur | G6: Ammapettai | H6: =V6 -> 9926.9 | I6: =W6 -> 9168.079 | J6: =X6 -> 9852.788 | K6: =IFERROR(AVERAGE(H6:J6),"") -> 9649.2557 | L6: =SUM(K6:K11) -> 48464.442 | M6: =L6*$L$643/$L$642 -> 2.0342482 | N6: =IF(M6>=2, ROUND(M6,0), IF(M6>1.1,2,"")) -> 2 | O6: =N6 -> 2 | P6: =O6 -> 2 | R6: =C6 -> Erode | S6: =F6 -> Anthiyur | T6: =G6 -> Ammapettai | U6: =CONCATENATE(R6,"_",S6,"_",T6) -> Erode_Anthiyur_Ammapettai | V6: =IF(_xlfn.XLOOKUP($U6,GCA!$H$3:$H$593,GCA!E$3:E$593,"",0,1)="","",_xlfn.XLOOKUP($U6,GCA!$H$3:$H$593,GCA!E$3:E$593,"",0,1)) -> 9926.9 | W6: =IF(_xlfn.XLOOKUP($U6,GCA!$H$3:$H$593,GCA!F$3:F$593,"",0,1)="","",_xlfn.XLOOKUP($U6,GCA!$H$3:$H$593,GCA!F$3:F$593,"",0,1)) -> 9168.079 | X6: =IF(_xlfn.XLOOKUP($U6,GCA!$H$3:$H$593,GCA!G$3:G$593,"",0,1)="","",_xlfn.XLOOKUP($U6,GCA!$H$3:$H$593,GCA!G$3:G$593,"",0,1)) -> 9852.788
F7: Anthiyur | G7: Anthiyur | H7: =V7 -> 15268.971 | I7: =W7 -> 13246.645 | J7: =X7 -> 14112.506 | K7: =IFERROR(AVERAGE(H7:J7),"") -> 14209.374 | M7: =L7*$L$643/$L$642 -> 0 | N7: =IF(M7>=2, ROUND(M7,0), IF(M7>1.1,2,"")) | O7: =N7 | P7: =O7 | R7: =R6 -> Erode | S7: =F7 -> Anthiyur | T7: =G7 -> Anthiyur | U7: =CONCATENATE(R7,"_",S7,"_",T7) -> Erode_Anthiyur_Anthiyur | V7: =IF(_xlfn.XLOOKUP($U7,GCA!$H$3:$H$593,GCA!E$3:E$593,"",0,1)="","",_xlfn.XLOOKUP($U7,GCA!$H$3:$H$593,GCA!E$3:E$593,"",0,1)) -> 15268.971 | W7: =IF(_xlfn.XLOOKUP($U7,GCA!$H$3:$H$593,GCA!F$3:F$593,"",0,1)="","",_xlfn.XLOOKUP($U7,GCA!$H$3:$H$593,GCA!F$3:F$593,"",0,1)) -> 13246.645 | X7: =IF(_xlfn.XLOOKUP($U7,GCA!$H$3:$H$593,GCA!G$3:G$593,"",0,1)="","",_xlfn.XLOOKUP($U7,GCA!$H$3:$H$593,GCA!G$3:G$593,"",0,1)) -> 14112.506
F8: Bhavani | G8: Ammapettai | H8: =V8 -> 5219.21 | I8: =W8 -> 3644.061 | J8: =X8 -> 5000.14 | K8: =IFERROR(AVERAGE(H8:J8),"") -> 4621.137 | M8: =L8*$L$643/$L$642 -> 0 | N8: =IF(M8>=2, ROUND(M8,0), IF(M8>1.1,2,"")) | O8: =N8 | P8: =O8 | R8: =R7 -> Erode | S8: =F8 -> Bhavani | T8: =G8 -> Ammapettai | U8: =CONCATENATE(R8,"_",S8,"_",T8) -> Erode_Bhavani_Ammapettai | V8: =IF(_xlfn.XLOOKUP($U8,GCA!$H$3:$H$593,GCA!E$3:E$593,"",0,1)="","",_xlfn.XLOOKUP($U8,GCA!$H$3:$H$593,GCA!E$3:E$593,"",0,1)) -> 5219.21 | W8: =IF(_xlfn.XLOOKUP($U8,GCA!$H$3:$H$593,GCA!F$3:F$593,"",0,1)="","",_xlfn.XLOOKUP($U8,GCA!$H$3:$H$593,GCA!F$3:F$593,"",0,1)) -> 3644.061 | X8: =IF(_xlfn.XLOOKUP($U8,GCA!$H$3:$H$593,GCA!G$3:G$593,"",0,1)="","",_xlfn.XLOOKUP($U8,GCA!$H$3:$H$593,GCA!G$3:G$593,"",0,1)) -> 5000.14
F9: Bhavani | G9: Bhavani | H9: =V9 -> 14129.05 | I9: =W9 -> 13052.005 | J9: =X9 -> 13810.765 | K9: =IFERROR(AVERAGE(H9:J9),"") -> 13663.94 | M9: =L9*$L$643/$L$642 -> 0 | N9: =IF(M9>=2, ROUND(M9,0), IF(M9>1.1,2,"")) | O9: =N9 | P9: =O9 | R9: =R8 -> Erode | S9: =F9 -> Bhavani | T9: =G9 -> Bhavani | U9: =CONCATENATE(R9,"_",S9,"_",T9) -> Erode_Bhavani_Bhavani | V9: =IF(_xlfn.XLOOKUP($U9,GCA!$H$3:$H$593,GCA!E$3:E$593,"",0,1)="","",_xlfn.XLOOKUP($U9,GCA!$H$3:$H$593,GCA!E$3:E$593,"",0,1)) -> 14129.05 | W9: =IF(_xlfn.XLOOKUP($U9,GCA!$H$3:$H$593,GCA!F$3:F$593,"",0,1)="","",_xlfn.XLOOKUP($U9,GCA!$H$3:$H$593,GCA!F$3:F$593,"",0,1)) -> 13052.005 | X9: =IF(_xlfn.XLOOKUP($U9,GCA!$H$3:$H$593,GCA!G$3:G$593,"",0,1)="","",_xlfn.XLOOKUP($U9,GCA!$H$3:$H$593,GCA!G$3:G$593,"",0,1)) -> 13810.765
F10: Bhavani | G10: Gobichettipalayam | H10: =V10 -> 1396.995 | I10: =W10 -> 1303.32 | J10: =X10 -> 1440.765 | K10: =IFERROR(AVERAGE(H10:J10),"") -> 1380.36 | M10: =L10*$L$643/$L$642 -> 0 | N10: =IF(M10>=2, ROUND(M10,0), IF(M10>1.1,2,"")) | O10: =N10 | P10: =O10 | R10: =R9 -> Erode | S10: =F10 -> Bhavani | T10: =G10 -> Gobichettipalayam | U10: =CONCATENATE(R10,"_",S10,"_",T10) -> Erode_Bhavani_Gobichettipalayam | V10: =IF(_xlfn.XLOOKUP($U10,GCA!$H$3:$H$593,GCA!E$3:E$593,"",0,1)="","",_xlfn.XLOOKUP($U10,GCA!$H$3:$H$593,GCA!E$3:E$593,"",0,1)) -> 1396.995 | W10: =IF(_xlfn.XLOOKUP($U10,GCA!$H$3:$H$593,GCA!F$3:F$593,"",0,1)="","",_xlfn.XLOOKUP($U10,GCA!$H$3:$H$593,GCA!F$3:F$593,"",0,1)) -> 1303.32 | X10: =IF(_xlfn.XLOOKUP($U10,GCA!$H$3:$H$593,GCA!G$3:G$593,"",0,1)="","",_xlfn.XLOOKUP($U10,GCA!$H$3:$H$593,GCA!G$3:G$593,"",0,1)) -> 1440.765
F11: Erode | G11: Erode | H11: =V11 -> 5092.544 | I11: =W11 -> 4744.562 | J11: =X11 -> 4984.02 | K11: =IFERROR(AVERAGE(H11:J11),"") -> 4940.3753 | M11: =L11*$L$643/$L$642 -> 0 | N11: =IF(M11>=2, ROUND(M11,0), IF(M11>1.1,2,"")) | O11: =N11 | P11: =O11 | R11: =R10 -> Erode | S11: =F11 -> Erode | T11: =G11 -> Erode | U11: =CONCATENATE(R11,"_",S11,"_",T11) -> Erode_Erode_Erode | V11: =IF(_xlfn.XLOOKUP($U11,GCA!$H$3:$H$593,GCA!E$3:E$593,"",0,1)="","",_xlfn.XLOOKUP($U11,GCA!$H$3:$H$593,GCA!E$3:E$593,"",0,1)) -> 5092.544 | W11: =IF(_xlfn.XLOOKUP($U11,GCA!$H$3:$H$593,GCA!F$3:F$593,"",0,1)="","",_xlfn.XLOOKUP($U11,GCA!$H$3:$H$593,GCA!F$3:F$593,"",0,1)) -> 4744.562 | X11: =IF(_xlfn.XLOOKUP($U11,GCA!$H$3:$H$593,GCA!G$3:G$593,"",0,1)="","",_xlfn.XLOOKUP($U11,GCA!$H$3:$H$593,GCA!G$3:G$593,"",0,1)) -> 4984.02
E12: 2 | F12: Gobichettipalayam | G12: Gobichettipalayam | H12: =V12 -> 19961.81 | I12: =W12 -> 19407.275 | J12: =X12 -> 20098.05 | K12: =IFERROR(AVERAGE(H12:J12),"") -> 19822.378 | L12: =SUM(K12:K14) -> 44761.684 | M12: =L12*$L$643/$L$642 -> 1.8788285 | N12: =IF(M12>=2, ROUND(M12,0), IF(M12>1.1,2,"")) -> 2 | O12: =N12 -> 2 | P12: =O12 -> 2 | R12: =R11 -> Erode | S12: =F12 -> Gobichettipalayam | T12: =G12 -> Gobichettipalayam | U12: =CONCATENATE(R12,"_",S12,"_",T12) -> Erode_Gobichettipalayam_Gobichettipalayam | V12: =IF(_xlfn.XLOOKUP($U12,GCA!$H$3:$H$593,GCA!E$3:E$593,"",0,1)="","",_xlfn.XLOOKUP($U12,GCA!$H$3:$H$593,GCA!E$3:E$593,"",0,1)) -> 19961.81 | W12: =IF(_xlfn.XLOOKUP($U12,GCA!$H$3:$H$593,GCA!F$3:F$593,"",0,1)="","",_xlfn.XLOOKUP($U12,GCA!$H$3:$H$593,GCA!F$3:F$593,"",0,1)) -> 19407.275 | X12: =IF(_xlfn.XLOOKUP($U12,GCA!$H$3:$H$593,GCA!G$3:G$593,"",0,1)="","",_xlfn.XLOOKUP($U12,GCA!$H$3:$H$593,GCA!G$3:G$593,"",0,1)) -> 20098.05
F13: Gobichettipalayam | G13: Thukkanaickenpalayam | H13: =V13 -> 11393.772 | I13: =W13 -> 11321.419 | J13: =X13 -> 11428.695 | K13: =IFERROR(AVERAGE(H13:J13),"") -> 11381.295 | M13: =L13*$L$643/$L$642 -> 0 | N13: =IF(M13>=2, ROUND(M13,0), IF(M13>1.1,2,"")) | O13: =N13 | P13: =O13 | R13: =R12 -> Erode | S13: =F13 -> Gobichettipalayam | T13: =G13 -> Thukkanaickenpalayam | U13: =CONCATENATE(R13,"_",S13,"_",T13) -> Erode_Gobichettipalayam_Thukkanaickenpalayam | V13: =IF(_xlfn.XLOOKUP($U13,GCA!$H$3:$H$593,GCA!E$3:E$593,"",0,1)="","",_xlfn.XLOOKUP($U13,GCA!$H$3:$H$593,GCA!E$3:E$593,"",0,1)) -> 11393.772 | W13: =IF(_xlfn.XLOOKUP($U13,GCA!$H$3:$H$593,GCA!F$3:F$593,"",0,1)="","",_xlfn.XLOOKUP($U13,GCA!$H$3:$H$593,GCA!F$3:F$593,"",0,1)) -> 11321.419 | X13: =IF(_xlfn.XLOOKUP($U13,GCA!$H$3:$H$593,GCA!G$3:G$593,"",0,1)="","",_xlfn.XLOOKUP($U13,GCA!$H$3:$H$593,GCA!G$3:G$593,"",0,1)) -> 11428.695
F14: Kodumudi | G14: Kodumudi | H14: =V14 -> 14443.277 | I14: =W14 -> 12955.858 | J14: =X14 -> 13274.897 | K14: =IFERROR(AVERAGE(H14:J14),"") -> 13558.011 | M14: =L14*$L$643/$L$642 -> 0 | N14: =IF(M14>=2, ROUND(M14,0), IF(M14>1.1,2,"")) | O14: =N14 | P14: =O14 | R14: =R13 -> Erode | S14: =F14 -> Kodumudi | T14: =G14 -> Kodumudi | U14: =CONCATENATE(R14,"_",S14,"_",T14) -> Erode_Kodumudi_Kodumudi | V14: =IF(_xlfn.XLOOKUP($U14,GCA!$H$3:$H$593,GCA!E$3:E$593,"",0,1)="","",_xlfn.XLOOKUP($U14,GCA!$H$3:$H$593,GCA!E$3:E$593,"",0,1)) -> 14443.277 | W14: =IF(_xlfn.XLOOKUP($U14,GCA!$H$3:$H$593,GCA!F$3:F$593,"",0,1)="","",_xlfn.XLOOKUP($U14,GCA!$H$3:$H$593,GCA!F$3:F$593,"",0,1)) -> 12955.858 | X14: =IF(_xlfn.XLOOKUP($U14,GCA!$H$3:$H$593,GCA!G$3:G$593,"",0,1)="","",_xlfn.XLOOKUP($U14,GCA!$H$3:$H$593,GCA!G$3:G$593,"",0,1)) -> 13274.897
E15: 3 | F15: Modakurichi | G15: Modakurichi | H15: =V15 -> 17293.745 | I15: =W15 -> 16618.923 | J15: =X15 -> 16632.766 | K15: =IFERROR(AVERAGE(H15:J15),"") -> 16848.478 | L15: =SUM(K15:K19) -> 49208.115 | M15: =L15*$L$643/$L$642 -> 2.0654632 | N15: =IF(M15>=2, ROUND(M15,0), IF(M15>1.1,2,"")) -> 2 | O15: =N15 -> 2 | P15: =O15 -> 2 | R15: =R14 -> Erode | S15: =F15 -> Modakurichi | T15: =G15 -> Modakurichi | U15: =CONCATENATE(R15,"_",S15,"_",T15) -> Erode_Modakurichi_Modakurichi | V15: =IF(_xlfn.XLOOKUP($U15,GCA!$H$3:$H$593,GCA!E$3:E$593,"",0,1)="","",_xlfn.XLOOKUP($U15,GCA!$H$3:$H$593,GCA!E$3:E$593,"",0,1)) -> 17293.745 | W15: =IF(_xlfn.XLOOKUP($U15,GCA!$H$3:$H$593,GCA!F$3:F$593,"",0,1)="","",_xlfn.XLOOKUP($U15,GCA!$H$3:$H$593,GCA!F$3:F$593,"",0,1)) -> 16618.923 | X15: =IF(_xlfn.XLOOKUP($U15,GCA!$H$3:$H$593,GCA!G$3:G$593,"",0,1)="","",_xlfn.XLOOKUP($U15,GCA!$H$3:$H$593,GCA!G$3:G$593,"",0,1)) -> 16632.766
F16: Nambiyur | G16: Bhavanisagar | H16: =V16 -> 2472.978 | I16: =W16 -> 2356.34 | J16: =X16 -> 2403.445 | K16: =IFERROR(AVERAGE(H16:J16),"") -> 2410.921 | R16: =R15 -> Erode | S16: =F16 -> Nambiyur | T16: =G16 -> Bhavanisagar | U16: =CONCATENATE(R16,"_",S16,"_",T16) -> Erode_Nambiyur_Bhavanisagar | V16: =IF(_xlfn.XLOOKUP($U16,GCA!$H$3:$H$593,GCA!E$3:E$593,"",0,1)="","",_xlfn.XLOOKUP($U16,GCA!$H$3:$H$593,GCA!E$3:E$593,"",0,1)) -> 2472.978 | W16: =IF(_xlfn.XLOOKUP($U16,GCA!$H$3:$H$593,GCA!F$3:F$593,"",0,1)="","",_xlfn.XLOOKUP($U16,GCA!$H$3:$H$593,GCA!F$3:F$593,"",0,1)) -> 2356.34 | X16: =IF(_xlfn.XLOOKUP($U16,GCA!$H$3:$H$593,GCA!G$3:G$593,"",0,1)="","",_xlfn.XLOOKUP($U16,GCA!$H$3:$H$593,GCA!G$3:G$593,"",0,1)) -> 2403.445
F17: Nambiyur | G17: Nambiyur | H17: =V17 -> 13986.107 | I17: =W17 -> 13614.9 | J17: =X17 -> 14146.38 | K17: =IFERROR(AVERAGE(H17:J17),"") -> 13915.796 | R17: =R16 -> Erode | S17: =F17 -> Nambiyur | T17: =G17 -> Nambiyur | U17: =CONCATENATE(R17,"_",S17,"_",T17) -> Erode_Nambiyur_Nambiyur | V17: =IF(_xlfn.XLOOKUP($U17,GCA!$H$3:$H$593,GCA!E$3:E$593,"",0,1)="","",_xlfn.XLOOKUP($U17,GCA!$H$3:$H$593,GCA!E$3:E$593,"",0,1)) -> 13986.107 | W17: =IF(_xlfn.XLOOKUP($U17,GCA!$H$3:$H$593,GCA!F$3:F$593,"",0,1)="","",_xlfn.XLOOKUP($U17,GCA!$H$3:$H$593,GCA!F$3:F$593,"",0,1)) -> 13614.9 | X17: =IF(_xlfn.XLOOKUP($U17,GCA!$H$3:$H$593,GCA!G$3:G$593,"",0,1)="","",_xlfn.XLOOKUP($U17,GCA!$H$3:$H$593,GCA!G$3:G$593,"",0,1)) -> 14146.38
F18: Perundurai | G18: Chennimalai | H18: =V18 -> 4963.58 | I18: =W18 -> 5029.225 | J18: =X18 -> 5029.815 | K18: =IFERROR(AVERAGE(H18:J18),"") -> 5007.54 | R18: =R17 -> Erode | S18: =F18 -> Perundurai | T18: =G18 -> Chennimalai | U18: =CONCATENATE(R18,"_",S18,"_",T18) -> Erode_Perundurai_Chennimalai | V18: =IF(_xlfn.XLOOKUP($U18,GCA!$H$3:$H$593,GCA!E$3:E$593,"",0,1)="","",_xlfn.XLOOKUP($U18,GCA!$H$3:$H$593,GCA!E$3:E$593,"",0,1)) -> 4963.58 | W18: =IF(_xlfn.XLOOKUP($U18,GCA!$H$3:$H$593,GCA!F$3:F$593,"",0,1)="","",_xlfn.XLOOKUP($U18,GCA!$H$3:$H$593,GCA!F$3:F$593,"",0,1)) -> 5029.225 | X18: =IF(_xlfn.XLOOKUP($U18,GCA!$H$3:$H$593,GCA!G$3:G$593,"",0,1)="","",_xlfn.XLOOKUP($U18,GCA!$H$3:$H$593,GCA!G$3:G$593,"",0,1)) -> 5029.815
F19: Perundurai | G19: Perundurai | H19: =V19 -> 10625.64 | I19: =W19 -> 9535.545 | J19: =X19 -> 12914.955 | K19: =IFERROR(AVERAGE(H19:J19),"") -> 11025.38 | R19: =R18 -> Erode | S19: =F19 -> Perundurai | T19: =G19 -> Perundurai | U19: =CONCATENATE(R19,"_",S19,"_",T19) -> Erode_Perundurai_Perundurai | V19: =IF(_xlfn.XLOOKUP($U19,GCA!$H$3:$H$593,GCA!E$3:E$593,"",0,1)="","",_xlfn.XLOOKUP($U19,GCA!$H$3:$H$593,GCA!E$3:E$593,"",0,1)) -> 10625.64 | W19: =IF(_xlfn.XLOOKUP($U19,GCA!$H$3:$H$593,GCA!F$3:F$593,"",0,1)="","",_xlfn.XLOOKUP($U19,GCA!$H$3:$H$593,GCA!F$3:F$593,"",0,1)) -> 9535.545 | X19: =IF(_xlfn.XLOOKUP($U19,GCA!$H$3:$H$593,GCA!G$3:G$593,"",0,1)="","",_xlfn.XLOOKUP($U19,GCA!$H$3:$H$593,GCA!G$3:G$593,"",0,1)) -> 12914.955
E20: 4 | F20: Sathyamangalam | G20: Bhavanisagar | H20: =V20 -> 6126.35 | I20: =W20 -> 5978.09 | J20: =X20 -> 5548.351 | K20: =IFERROR(AVERAGE(H20:J20),"") -> 5884.2637 | L20: =SUM(K20:K23) -> 30541.373 | M20: =L20*$L$643/$L$642 -> 1.2819447 | N20: =IF(M20>=2, ROUND(M20,0), IF(M20>1.1,2,"")) -> 2 | O20: =N20 -> 2 | P20: =O20 -> 2 | R20: =R19 -> Erode | S20: =F20 -> Sathyamangalam | T20: =G20 -> Bhavanisagar | U20: =CONCATENATE(R20,"_",S20,"_",T20) -> Erode_Sathyamangalam_Bhavanisagar | V20: =IF(_xlfn.XLOOKUP($U20,GCA!$H$3:$H$593,GCA!E$3:E$593,"",0,1)="","",_xlfn.XLOOKUP($U20,GCA!$H$3:$H$593,GCA!E$3:E$593,"",0,1)) -> 6126.35 | W20: =IF(_xlfn.XLOOKUP($U20,GCA!$H$3:$H$593,GCA!F$3:F$593,"",0,1)="","",_xlfn.XLOOKUP($U20,GCA!$H$3:$H$593,GCA!F$3:F$593,"",0,1)) -> 5978.09 | X20: =IF(_xlfn.XLOOKUP($U20,GCA!$H$3:$H$593,GCA!G$3:G$593,"",0,1)="","",_xlfn.XLOOKUP($U20,GCA!$H$3:$H$593,GCA!G$3:G$593,"",0,1)) -> 5548.351
F21: Sathyamangalam | G21: Sathyamangalam | H21: =V21 -> 12454.92 | I21: =W21 -> 12419.095 | J21: =X21 -> 12578.43 | K21: =IFERROR(AVERAGE(H21:J21),"") -> 12484.148 | R21: =R20 -> Erode | S21: =F21 -> Sathyamangalam | T21: =G21 -> Sathyamangalam | U21: =CONCATENATE(R21,"_",S21,"_",T21) -> Erode_Sathyamangalam_Sathyamangalam | V21: =IF(_xlfn.XLOOKUP($U21,GCA!$H$3:$H$593,GCA!E$3:E$593,"",0,1)="","",_xlfn.XLOOKUP($U21,GCA!$H$3:$H$593,GCA!E$3:E$593,"",0,1)) -> 12454.92 | W21: =IF(_xlfn.XLOOKUP($U21,GCA!$H$3:$H$593,GCA!F$3:F$593,"",0,1)="","",_xlfn.XLOOKUP($U21,GCA!$H$3:$H$593,GCA!F$3:F$593,"",0,1)) -> 12419.095 | X21: =IF(_xlfn.XLOOKUP($U21,GCA!$H$3:$H$593,GCA!G$3:G$593,"",0,1)="","",_xlfn.XLOOKUP($U21,GCA!$H$3:$H$593,GCA!G$3:G$593,"",0,1)) -> 12578.43
F22: Sathyamangalam | G22: Talavadi | H22: =V22 -> 1491.555 | I22: =W22 -> 1458.508 | J22: =X22 -> 1465.77 | K22: =IFERROR(AVERAGE(H22:J22),"") -> 1471.9443 | R22: =R21 -> Erode | S22: =F22 -> Sathyamangalam | T22: =G22 -> Talavadi | U22: =CONCATENATE(R22,"_",S22,"_",T22) -> Erode_Sathyamangalam_Talavadi | V22: =IF(_xlfn.XLOOKUP($U22,GCA!$H$3:$H$593,GCA!E$3:E$593,"",0,1)="","",_xlfn.XLOOKUP($U22,GCA!$H$3:$H$593,GCA!E$3:E$593,"",0,1)) -> 1491.555 | W22: =IF(_xlfn.XLOOKUP($U22,GCA!$H$3:$H$593,GCA!F$3:F$593,"",0,1)="","",_xlfn.XLOOKUP($U22,GCA!$H$3:$H$593,GCA!F$3:F$593,"",0,1)) -> 1458.508 | X22: =IF(_xlfn.XLOOKUP($U22,GCA!$H$3:$H$593,GCA!G$3:G$593,"",0,1)="","",_xlfn.XLOOKUP($U22,GCA!$H$3:$H$593,GCA!G$3:G$593,"",0,1)) -> 1465.77
F23: Talavadi | G23: Talavadi | H23: =V23 -> 10232.625 | I23: =W23 -> 9890.685 | J23: =X23 -> 11979.74 | K23: =IFERROR(AVERAGE(H23:J23),"") -> 10701.017 | R23: =R22 -> Erode | S23: =F23 -> Talavadi | T23: =G23 -> Talavadi | U23: =CONCATENATE(R23,"_",S23,"_",T23) -> Erode_Talavadi_Talavadi | V23: =IF(_xlfn.XLOOKUP($U23,GCA!$H$3:$H$593,GCA!E$3:E$593,"",0,1)="","",_xlfn.XLOOKUP($U23,GCA!$H$3:$H$593,GCA!E$3:E$593,"",0,1)) -> 10232.625 | W23: =IF(_xlfn.XLOOKUP($U23,GCA!$H$3:$H$593,GCA!F$3:F$593,"",0,1)="","",_xlfn.XLOOKUP($U23,GCA!$H$3:$H$593,GCA!F$3:F$593,"",0,1)) -> 9890.685 | X23: =IF(_xlfn.XLOOKUP($U23,GCA!$H$3:$H$593,GCA!G$3:G$593,"",0,1)="","",_xlfn.XLOOKUP($U23,GCA!$H$3:$H$593,GCA!G$3:G$593,"",0,1)) -> 11979.74
E24: DISTT. TOTAL | H24: =SUM(H6:H23) -> 176480.03 | I24: =SUM(I6:I23) -> 165744.53 | J24: =SUM(J6:J23) -> 176702.28 | K24: =SUM(K6:K23) -> 172975.61 | L24: =SUM(L6:L23) -> 172975.61 | M24: =SUM(M6:M23) -> 7.2604846 | N24: =SUM(N6:N23) -> 8 | O24: =SUM(O6:O23) -> 8 | P24: =SUM(P6:P23) -> 8 | R24: =R23 -> Erode | S24: =F24 -> 0 | T24: =G24 -> 0 | U24: =CONCATENATE(R24,"_",S24,"_",T24) -> Erode_0_0 | V24: =IF(_xlfn.XLOOKUP($U24,GCA!$H$3:$H$593,GCA!E$3:E$593,"",0,1)="","",_xlfn.XLOOKUP($U24,GCA!$H$3:$H$593,GCA!E$3:E$593,"",0,1)) | W24: =IF(_xlfn.XLOOKUP($U24,GCA!$H$3:$H$593,GCA!F$3:F$593,"",0,1)="","",_xlfn.XLOOKUP($U24,GCA!$H$3:$H$593,GCA!F$3:F$593,"",0,1)) | X24: =IF(_xlfn.XLOOKUP($U24,GCA!$H$3:$H$593,GCA!G$3:G$593,"",0,1)="","",_xlfn.XLOOKUP($U24,GCA!$H$3:$H$593,GCA!G$3:G$593,"",0,1))
C25: The Nilgiris | D25: 11 | E25: 1 | F25: Coonoor | G25: Coonoor | H25: =V25 -> 13031.92 | I25: =W25 -> 12779.968 | J25: =X25 -> 12566.936 | K25: =IFERROR(AVERAGE(H25:J25),"") -> 12792.941 | L25: =SUM(K25:K32) -> 75701.639 | M25: =L25*$L$643/$L$642 -> 3.1775033 | N25: =IF(M25>=2, ROUND(M25,0), IF(M25>1.1,2,"")) -> 3 | O25: =N25 -> 3 | P25: =O25 -> 3 | R25: =C25 -> The Nilgiris | S25: =F25 -> Coonoor | T25: =G25 -> Coonoor | U25: =CONCATENATE(R25,"_",S25,"_",T25) -> The Nilgiris_Coonoor_Coonoor | V25: =IF(_xlfn.XLOOKUP($U25,GCA!$H$3:$H$593,GCA!E$3:E$593,"",0,1)="","",_xlfn.XLOOKUP($U25,GCA!$H$3:$H$593,GCA!E$3:E$593,"",0,1)) -> 13031.92 | W25: =IF(_xlfn.XLOOKUP($U25,GCA!$H$3:$H$593,GCA!F$3:F$593,"",0,1)="","",_xlfn.XLOOKUP($U25,GCA!$H$3:$H$593,GCA!F$3:F$593,"",0,1)) -> 12779.968 | X25: =IF(_xlfn.XLOOKUP($U25,GCA!$H$3:$H$593,GCA!G$3:G$593,"",0,1)="","",_xlfn.XLOOKUP($U25,GCA!$H$3:$H$593,GCA!G$3:G$593,"",0,1)) -> 12566.936
F26: Gudalur | G26: Gudalur | H26: =V26 -> 14061.047 | I26: =W26 -> 14069.272 | J26: =X26 -> 14280.78 | K26: =IFERROR(AVERAGE(H26:J26),"") -> 14137.033 | M26: =L26*$L$643/$L$642 -> 0 | N26: =IF(M26>=2, ROUND(M26,0), IF(M26>1.1,2,"")) | O26: =N26 | P26: =O26 | R26: =R25 -> The Nilgiris | S26: =F26 -> Gudalur | T26: =G26 -> Gudalur | U26: =CONCATENATE(R26,"_",S26,"_",T26) -> The Nilgiris_Gudalur_Gudalur | V26: =IF(_xlfn.XLOOKUP($U26,GCA!$H$3:$H$593,GCA!E$3:E$593,"",0,1)="","",_xlfn.XLOOKUP($U26,GCA!$H$3:$H$593,GCA!E$3:E$593,"",0,1)) -> 14061.047 | W26: =IF(_xlfn.XLOOKUP($U26,GCA!$H$3:$H$593,GCA!F$3:F$593,"",0,1)="","",_xlfn.XLOOKUP($U26,GCA!$H$3:$H$593,GCA!F$3:F$593,"",0,1)) -> 14069.272 | X26: =IF(_xlfn.XLOOKUP($U26,GCA!$H$3:$H$593,GCA!G$3:G$593,"",0,1)="","",_xlfn.XLOOKUP($U26,GCA!$H$3:$H$593,GCA!G$3:G$593,"",0,1)) -> 14280.78
F27: Kotagiri | G27: Coonoor | H27: =V27 -> 754.145 | I27: =W27 -> 747.762 | J27: =X27 -> 770.239 | K27: =IFERROR(AVERAGE(H27:J27),"") -> 757.382 | M27: =L27*$L$643/$L$642 -> 0 | N27: =IF(M27>=2, ROUND(M27,0), IF(M27>1.1,2,"")) | O27: =N27 | P27: =O27 | R27: =R26 -> The Nilgiris | S27: =F27 -> Kotagiri | T27: =G27 -> Coonoor | U27: =CONCATENATE(R27,"_",S27,"_",T27) -> The Nilgiris_Kotagiri_Coonoor | V27: =IF(_xlfn.XLOOKUP($U27,GCA!$H$3:$H$593,GCA!E$3:E$593,"",0,1)="","",_xlfn.XLOOKUP($U27,GCA!$H$3:$H$593,GCA!E$3:E$593,"",0,1)) -> 754.145 | W27: =IF(_xlfn.XLOOKUP($U27,GCA!$H$3:$H$593,GCA!F$3:F$593,"",0,1)="","",_xlfn.XLOOKUP($U27,GCA!$H$3:$H$593,GCA!F$3:F$593,"",0,1)) -> 747.762 | X27: =IF(_xlfn.XLOOKUP($U27,GCA!$H$3:$H$593,GCA!G$3:G$593,"",0,1)="","",_xlfn.XLOOKUP($U27,GCA!$H$3:$H$593,GCA!G$3:G$593,"",0,1)) -> 770.239
F28: Kotagiri | G28: Kotagiri | H28: =V28 -> 12144.999 | I28: =W28 -> 12148.339 | J28: =X28 -> 12362.475 | K28: =IFERROR(AVERAGE(H28:J28),"") -> 12218.604 | M28: =L28*$L$643/$L$642 -> 0 | N28: =IF(M28>=2, ROUND(M28,0), IF(M28>1.1,2,"")) | O28: =N28 | P28: =O28 | R28: =R27 -> The Nilgiris | S28: =F28 -> Kotagiri | T28: =G28 -> Kotagiri | U28: =CONCATENATE(R28,"_",S28,"_",T28) -> The Nilgiris_Kotagiri_Kotagiri | V28: =IF(_xlfn.XLOOKUP($U28,GCA!$H$3:$H$593,GCA!E$3:E$593,"",0,1)="","",_xlfn.XLOOKUP($U28,GCA!$H$3:$H$593,GCA!E$3:E$593,"",0,1)) -> 12144.999 | W28: =IF(_xlfn.XLOOKUP($U28,GCA!$H$3:$H$593,GCA!F$3:F$593,"",0,1)="","",_xlfn.XLOOKUP($U28,GCA!$H$3:$H$593,GCA!F$3:F$593,"",0,1)) -> 12148.339 | X28: =IF(_xlfn.XLOOKUP($U28,GCA!$H$3:$H$593,GCA!G$3:G$593,"",0,1)="","",_xlfn.XLOOKUP($U28,GCA!$H$3:$H$593,GCA!G$3:G$593,"",0,1)) -> 12362.475
F29: Kundah | G29: Udhagamandalam | H29: =V29 -> 7799.298 | I29: =W29 -> 7805.928 | J29: =X29 -> 7634.629 | K29: =IFERROR(AVERAGE(H29:J29),"") -> 7746.6183 | M29: =L29*$L$643/$L$642 -> 0 | N29: =IF(M29>=2, ROUND(M29,0), IF(M29>1.1,2,"")) | O29: =N29 | P29: =O29 | R29: =R28 -> The Nilgiris | S29: =F29 -> Kundah | T29: =G29 -> Udhagamandalam | U29: =CONCATENATE(R29,"_",S29,"_",T29) -> The Nilgiris_Kundah_Udhagamandalam | V29: =IF(_xlfn.XLOOKUP($U29,GCA!$H$3:$H$593,GCA!E$3:E$593,"",0,1)="","",_xlfn.XLOOKUP($U29,GCA!$H$3:$H$593,GCA!E$3:E$593,"",0,1)) -> 7799.298 | W29: =IF(_xlfn.XLOOKUP($U29,GCA!$H$3:$H$593,GCA!F$3:F$593,"",0,1)="","",_xlfn.XLOOKUP($U29,GCA!$H$3:$H$593,GCA!F$3:F$593,"",0,1)) -> 7805.928 | X29: =IF(_xlfn.XLOOKUP($U29,GCA!$H$3:$H$593,GCA!G$3:G$593,"",0,1)="","",_xlfn.XLOOKUP($U29,GCA!$H$3:$H$593,GCA!G$3:G$593,"",0,1)) -> 7634.629
F30: Pandalur | G30: Gudalur | H30: =V30 -> 12207.626 | I30: =W30 -> 12233.435 | J30: =X30 -> 12338.904 | K30: =IFERROR(AVERAGE(H30:J30),"") -> 12259.988 | M30: =L30*$L$643/$L$642 -> 0 | N30: =IF(M30>=2, ROUND(M30,0), IF(M30>1.1,2,"")) | O30: =N30 | P30: =O30 | R30: =R29 -> The Nilgiris | S30: =F30 -> Pandalur | T30: =G30 -> Gudalur | U30: =CONCATENATE(R30,"_",S30,"_",T30) -> The Nilgiris_Pandalur_Gudalur | V30: =IF(_xlfn.XLOOKUP($U30,GCA!$H$3:$H$593,GCA!E$3:E$593,"",0,1)="","",_xlfn.XLOOKUP($U30,GCA!$H$3:$H$593,GCA!E$3:E$593,"",0,1)) -> 12207.626 | W30: =IF(_xlfn.XLOOKUP($U30,GCA!$H$3:$H$593,GCA!F$3:F$593,"",0,1)="","",_xlfn.XLOOKUP($U30,GCA!$H$3:$H$593,GCA!F$3:F$593,"",0,1)) -> 12233.435 | X30: =IF(_xlfn.XLOOKUP($U30,GCA!$H$3:$H$593,GCA!G$3:G$593,"",0,1)="","",_xlfn.XLOOKUP($U30,GCA!$H$3:$H$593,GCA!G$3:G$593,"",0,1)) -> 12338.904
F31: Udhagamandalam | G31: Gudalur | H31: =V31 -> 740.505 | I31: =W31 -> 751.725 | J31: =X31 -> 751.22 | K31: =IFERROR(AVERAGE(H31:J31),"") -> 747.81667 | M31: =L31*$L$643/$L$642 -> 0 | N31: =IF(M31>=2, ROUND(M31,0), IF(M31>1.1,2,"")) | O31: =N31 | P31: =O31 | R31: =R30 -> The Nilgiris | S31: =F31 -> Udhagamandalam | T31: =G31 -> Gudalur | U31: =CONCATENATE(R31,"_",S31,"_",T31) -> The Nilgiris_Udhagamandalam_Gudalur | V31: =IF(_xlfn.XLOOKUP($U31,GCA!$H$3:$H$593,GCA!E$3:E$593,"",0,1)="","",_xlfn.XLOOKUP($U31,GCA!$H$3:$H$593,GCA!E$3:E$593,"",0,1)) -> 740.505 | W31: =IF(_xlfn.XLOOKUP($U31,GCA!$H$3:$H$593,GCA!F$3:F$593,"",0,1)="","",_xlfn.XLOOKUP($U31,GCA!$H$3:$H$593,GCA!F$3:F$593,"",0,1)) -> 751.725 | X31: =IF(_xlfn.XLOOKUP($U31,GCA!$H$3:$H$593,GCA!G$3:G$593,"",0,1)="","",_xlfn.XLOOKUP($U31,GCA!$H$3:$H$593,GCA!G$3:G$593,"",0,1)) -> 751.22
F32: Udhagamandalam | G32: Udhagamandalam | H32: =V32 -> 14980.885 | I32: =W32 -> 14912.145 | J32: =X32 -> 15230.735 | K32: =IFERROR(AVERAGE(H32:J32),"") -> 15041.255 | M32: =L32*$L$643/$L$642 -> 0 | N32: =IF(M32>=2, ROUND(M32,0), IF(M32>1.1,2,"")) | O32: =N32 | P32: =O32 | R32: =R31 -> The Nilgiris | S32: =F32 -> Udhagamandalam | T32: =G32 -> Udhagamandalam | U32: =CONCATENATE(R32,"_",S32,"_",T32) -> The Nilgiris_Udhagamandalam_Udhagamandalam | V32: =IF(_xlfn.XLOOKUP($U32,GCA!$H$3:$H$593,GCA!E$3:E$593,"",0,1)="","",_xlfn.XLOOKUP($U32,GCA!$H$3:$H$593,GCA!E$3:E$593,"",0,1)) -> 14980.885 | W32: =IF(_xlfn.XLOOKUP($U32,GCA!$H$3:$H$593,GCA!F$3:F$593,"",0,1)="","",_xlfn.XLOOKUP($U32,GCA!$H$3:$H$593,GCA!F$3:F$593,"",0,1)) -> 14912.145 | X32: =IF(_xlfn.XLOOKUP($U32,GCA!$H$3:$H$593,GCA!G$3:G$593,"",0,1)="","",_xlfn.XLOOKUP($U32,GCA!$H$3:$H$593,GCA!G$3:G$593,"",0,1)) -> 15230.735
E33: DISTT. TOTAL | H33: =SUM(H25:H32) -> 75720.425 | I33: =SUM(I25:I32) -> 75448.574 | J33: =SUM(J25:J32) -> 75935.918 | K33: =SUM(K25:K32) -> 75701.639 | L33: =SUM(L25:L32) -> 75701.639 | M33: =SUM(M25:M32) -> 3.1775033 | N33: =SUM(N25:N32) -> 3 | O33: =SUM(O25:O32) -> 3 | P33: =SUM(P25:P32) -> 3 | R33: =R32 -> The Nilgiris | S33: =F33 -> 0 | T33: =G33 -> 0 | U33: =CONCATENATE(R33,"_",S33,"_",T33) -> The Nilgiris_0_0 | V33: =IF(_xlfn.XLOOKUP($U33,GCA!$H$3:$H$593,GCA!E$3:E$593,"",0,1)="","",_xlfn.XLOOKUP($U33,GCA!$H$3:$H$593,GCA!E$3:E$593,"",0,1)) | W33: =IF(_xlfn.XLOOKUP($U33,GCA!$H$3:$H$593,GCA!F$3:F$593,"",0,1)="","",_xlfn.XLOOKUP($U33,GCA!$H$3:$H$593,GCA!F$3:F$593,"",0,1)) | X33: =IF(_xlfn.XLOOKUP($U33,GCA!$H$3:$H$593,GCA!G$3:G$593,"",0,1)="","",_xlfn.XLOOKUP($U33,GCA!$H$3:$H$593,GCA!G$3:G$593,"",0,1))
C34: Coimbatore | D34: 12 | E34: 1 | F34: Anaimalai | G34: Anaimalai | H34: =V34 -> 27447.15 | I34: =W34 -> 26537.542 | J34: =X34 -> 28259.78 | K34: =IFERROR(AVERAGE(H34:J34),"") -> 27414.824 | L34: =SUM(K34:K37) -> 46287.932 | M34: =L34*$L$643/$L$642 -> 1.9428913 | N34: =IF(M34>=2, ROUND(M34,0), IF(M34>1.1,2,"")) -> 2 | O34: =N34 -> 2 | P34: =O34 -> 2 | R34: =C34 -> Coimbatore | S34: =F34 -> Anaimalai | T34: =G34 -> Anaimalai | U34: =CONCATENATE(R34,"_",S34,"_",T34) -> Coimbatore_Anaimalai_Anaimalai | V34: =IF(_xlfn.XLOOKUP($U34,GCA!$H$3:$H$593,GCA!E$3:E$593,"",0,1)="","",_xlfn.XLOOKUP($U34,GCA!$H$3:$H$593,GCA!E$3:E$593,"",0,1)) -> 27447.15 | W34: =IF(_xlfn.XLOOKUP($U34,GCA!$H$3:$H$593,GCA!F$3:F$593,"",0,1)="","",_xlfn.XLOOKUP($U34,GCA!$H$3:$H$593,GCA!F$3:F$593,"",0,1)) -> 26537.542 | X34: =IF(_xlfn.XLOOKUP($U34,GCA!$H$3:$H$593,GCA!G$3:G$593,"",0,1)="","",_xlfn.XLOOKUP($U34,GCA!$H$3:$H$593,GCA!G$3:G$593,"",0,1)) -> 28259.78
F35: Anaimalai | G35: Pollachi South | H35: =V35 -> 5369.63 | I35: =W35 -> 5022.18 | J35: =X35 -> 5565.899 | K35: =IFERROR(AVERAGE(H35:J35),"") -> 5319.2363 | M35: =L35*$L$643/$L$642 -> 0 | N35: =IF(M35>=2, ROUND(M35,0), IF(M35>1.1,2,"")) | O35: =N35 | P35: =O35 | R35: =R34 -> Coimbatore | S35: =F35 -> Anaimalai | T35: =G35 -> Pollachi South | U35: =CONCATENATE(R35,"_",S35,"_",T35) -> Coimbatore_Anaimalai_Pollachi South | V35: =IF(_xlfn.XLOOKUP($U35,GCA!$H$3:$H$593,GCA!E$3:E$593,"",0,1)="","",_xlfn.XLOOKUP($U35,GCA!$H$3:$H$593,GCA!E$3:E$593,"",0,1)) -> 5369.63 | W35: =IF(_xlfn.XLOOKUP($U35,GCA!$H$3:$H$593,GCA!F$3:F$593,"",0,1)="","",_xlfn.XLOOKUP($U35,GCA!$H$3:$H$593,GCA!F$3:F$593,"",0,1)) -> 5022.18 | X35: =IF(_xlfn.XLOOKUP($U35,GCA!$H$3:$H$593,GCA!G$3:G$593,"",0,1)="","",_xlfn.XLOOKUP($U35,GCA!$H$3:$H$593,GCA!G$3:G$593,"",0,1)) -> 5565.899
F36: Annur | G36: Annur | H36: =V36 -> 9396.175 | I36: =W36 -> 10243.545 | J36: =X36 -> 11140.985 | K36: =IFERROR(AVERAGE(H36:J36),"") -> 10260.235 | M36: =L36*$L$643/$L$642 -> 0 | N36: =IF(M36>=2, ROUND(M36,0), IF(M36>1.1,2,"")) | O36: =N36 | P36: =O36 | R36: =R35 -> Coimbatore | S36: =F36 -> Annur | T36: =G36 -> Annur | U36: =CONCATENATE(R36,"_",S36,"_",T36) -> Coimbatore_Annur_Annur | V36: =IF(_xlfn.XLOOKUP($U36,GCA!$H$3:$H$593,GCA!E$3:E$593,"",0,1)="","",_xlfn.XLOOKUP($U36,GCA!$H$3:$H$593,GCA!E$3:E$593,"",0,1)) -> 9396.175 | W36: =IF(_xlfn.XLOOKUP($U36,GCA!$H$3:$H$593,GCA!F$3:F$593,"",0,1)="","",_xlfn.XLOOKUP($U36,GCA!$H$3:$H$593,GCA!F$3:F$593,"",0,1)) -> 10243.545 | X36: =IF(_xlfn.XLOOKUP($U36,GCA!$H$3:$H$593,GCA!G$3:G$593,"",0,1)="","",_xlfn.XLOOKUP($U36,GCA!$H$3:$H$593,GCA!G$3:G$593,"",0,1)) -> 11140.985
F37: Annur | G37: Sarkar Samakulam | H37: =V37 -> 3094.04 | I37: =W37 -> 3252.455 | J37: =X37 -> 3534.415 | K37: =IFERROR(AVERAGE(H37:J37),"") -> 3293.6367 | M37: =L37*$L$643/$L$642 -> 0 | N37: =IF(M37>=2, ROUND(M37,0), IF(M37>1.1,2,"")) | O37: =N37 | P37: =O37 | R37: =R36 -> Coimbatore | S37: =F37 -> Annur | T37: =G37 -> Sarkar Samakulam | U37: =CONCATENATE(R37,"_",S37,"_",T37) -> Coimbatore_Annur_Sarkar Samakulam | V37: =IF(_xlfn.XLOOKUP($U37,GCA!$H$3:$H$593,GCA!E$3:E$593,"",0,1)="","",_xlfn.XLOOKUP($U37,GCA!$H$3:$H$593,GCA!E$3:E$593,"",0,1)) -> 3094.04 | W37: =IF(_xlfn.XLOOKUP($U37,GCA!$H$3:$H$593,GCA!F$3:F$593,"",0,1)="","",_xlfn.XLOOKUP($U37,GCA!$H$3:$H$593,GCA!F$3:F$593,"",0,1)) -> 3252.455 | X37: =IF(_xlfn.XLOOKUP($U37,GCA!$H$3:$H$593,GCA!G$3:G$593,"",0,1)="","",_xlfn.XLOOKUP($U37,GCA!$H$3:$H$593,GCA!G$3:G$593,"",0,1)) -> 3534.415
E38: 2 | F38: Coimbatore North | G38: Periyanaickenpalayam | H38: =V38 -> 4536.28 | I38: =W38 -> 4405.214 | J38: =X38 -> 4581.572 | K38: =IFERROR(AVERAGE(H38:J38),"") -> 4507.6887 | L38: =SUM(K38:K44) -> 48020.175 | M38: =L38*$L$643/$L$642 -> 2.0156005 | N38: =IF(M38>=2, ROUND(M38,0), IF(M38>1.1,2,"")) -> 2 | O38: =N38 -> 2 | P38: =O38 -> 2 | R38: =R37 -> Coimbatore | S38: =F38 -> Coimbatore North | T38: =G38 -> Periyanaickenpalayam | U38: =CONCATENATE(R38,"_",S38,"_",T38) -> Coimbatore_Coimbatore North_Periyanaickenpalayam | V38: =IF(_xlfn.XLOOKUP($U38,GCA!$H$3:$H$593,GCA!E$3:E$593,"",0,1)="","",_xlfn.XLOOKUP($U38,GCA!$H$3:$H$593,GCA!E$3:E$593,"",0,1)) -> 4536.28 | W38: =IF(_xlfn.XLOOKUP($U38,GCA!$H$3:$H$593,GCA!F$3:F$593,"",0,1)="","",_xlfn.XLOOKUP($U38,GCA!$H$3:$H$593,GCA!F$3:F$593,"",0,1)) -> 4405.214 | X38: =IF(_xlfn.XLOOKUP($U38,GCA!$H$3:$H$593,GCA!G$3:G$593,"",0,1)="","",_xlfn.XLOOKUP($U38,GCA!$H$3:$H$593,GCA!G$3:G$593,"",0,1)) -> 4581.572
F39: Coimbatore North | G39: Sarkar Samakulam | H39: =V39 -> 960.944 | I39: =W39 -> 967.035 | J39: =X39 -> 996.81 | K39: =IFERROR(AVERAGE(H39:J39),"") -> 974.92967 | M39: =L39*$L$643/$L$642 -> 0 | N39: =IF(M39>=2, ROUND(M39,0), IF(M39>1.1,2,"")) | O39: =N39 | P39: =O39 | R39: =R38 -> Coimbatore | S39: =F39 -> Coimbatore North | T39: =G39 -> Sarkar Samakulam | U39: =CONCATENATE(R39,"_",S39,"_",T39) -> Coimbatore_Coimbatore North_Sarkar Samakulam | V39: =IF(_xlfn.XLOOKUP($U39,GCA!$H$3:$H$593,GCA!E$3:E$593,"",0,1)="","",_xlfn.XLOOKUP($U39,GCA!$H$3:$H$593,GCA!E$3:E$593,"",0,1)) -> 960.944 | W39: =IF(_xlfn.XLOOKUP($U39,GCA!$H$3:$H$593,GCA!F$3:F$593,"",0,1)="","",_xlfn.XLOOKUP($U39,GCA!$H$3:$H$593,GCA!F$3:F$593,"",0,1)) -> 967.035 | X39: =IF(_xlfn.XLOOKUP($U39,GCA!$H$3:$H$593,GCA!G$3:G$593,"",0,1)="","",_xlfn.XLOOKUP($U39,GCA!$H$3:$H$593,GCA!G$3:G$593,"",0,1)) -> 996.81
F40: Coimbatore South | G40: Madukkarai | H40: =V40 -> 296.027 | I40: =W40 -> 280.876 | J40: =X40 -> 282.687 | K40: =IFERROR(AVERAGE(H40:J40),"") -> 286.53 | M40: =L40*$L$643/$L$642 -> 0 | N40: =IF(M40>=2, ROUND(M40,0), IF(M40>1.1,2,"")) | O40: =N40 | P40: =O40 | R40: =R39 -> Coimbatore | S40: =F40 -> Coimbatore South | T40: =G40 -> Madukkarai | U40: =CONCATENATE(R40,"_",S40,"_",T40) -> Coimbatore_Coimbatore South_Madukkarai | V40: =IF(_xlfn.XLOOKUP($U40,GCA!$H$3:$H$593,GCA!E$3:E$593,"",0,1)="","",_xlfn.XLOOKUP($U40,GCA!$H$3:$H$593,GCA!E$3:E$593,"",0,1)) -> 296.027 | W40: =IF(_xlfn.XLOOKUP($U40,GCA!$H$3:$H$593,GCA!F$3:F$593,"",0,1)="","",_xlfn.XLOOKUP($U40,GCA!$H$3:$H$593,GCA!F$3:F$593,"",0,1)) -> 280.876 | X40: =IF(_xlfn.XLOOKUP($U40,GCA!$H$3:$H$593,GCA!G$3:G$593,"",0,1)="","",_xlfn.XLOOKUP($U40,GCA!$H$3:$H$593,GCA!G$3:G$593,"",0,1)) -> 282.687
...

Sheet 1.0WP
A1: PLAN OF WORK FOR UNDERTAKING SAMPLE CHECK ON AREA ENUMERATION BY CENTRAL AND STATE AGENCIES & SAMPLE CHECK ON AGGREGATION OF AREA BY STATE AGENCY UNDER ICS
A2: STATE: TAMIL NADU
A3: SEASON: PH-I (Early Kharif), PH-II (Late Kharif) and PH-III (Rabi) | P3: YEAR: 2026-27
A4: RO | B4: SRO | C4: Distt. | D4: Distt. Code | E4: Stratum | F4: Taluka | G4: Block | H4: AREA | L4: TOTAL | M4: PLAN | N4: ADJ | O4: #Vill. Planned | V4: Area
H5: 2024-25 | I5: 2023-24 | J5: 2022-23 | K5: Average | O5: Central | P5: State | R5: Distt | S5: Taluk | T5: Block | U5: concatenation | V5: yr1 | W5: yr2 | X5: yr3
A6: Coimbatore | B6: Coimbatore | C6: Erode | D6: 10 | E6: 1 | F6: Anthiyur | G6: Ammapettai | H6: =V6 -> 9926.9 | I6: =W6 -> 9168.079 | J6: =X6 -> 9852.788 | K6: =IFERROR(AVERAGE(H6:J6),"") -> 9649.2557 | L6: =SUM(K6:K11) -> 48464.442 | M6: =L6*$L$643/$L$642 -> 2.0342482 | N6: =IF(M6>=2, ROUND(M6,0), IF(M6>1.1,2,"")) -> 2 | O6: =N6 -> 2 | P6: =O6 -> 2 | R6: =C6 -> Erode | S6: =F6 -> Anthiyur | T6: =G6 -> Ammapettai | U6: =CONCATENATE(R6,"_",S6,"_",T6) -> Erode_Anthiyur_Ammapettai | V6: =IF(_xlfn.XLOOKUP($U6,GCA!$H$3:$H$593,GCA!E$3:E$593,"",0,1)="","",_xlfn.XLOOKUP($U6,GCA!$H$3:$H$593,GCA!E$3:E$593,"",0,1)) -> 9926.9 | W6: =IF(_xlfn.XLOOKUP($U6,GCA!$H$3:$H$593,GCA!F$3:F$593,"",0,1)="","",_xlfn.XLOOKUP($U6,GCA!$H$3:$H$593,GCA!F$3:F$593,"",0,1)) -> 9168.079 | X6: =IF(_xlfn.XLOOKUP($U6,GCA!$H$3:$H$593,GCA!G$3:G$593,"",0,1)="","",_xlfn.XLOOKUP($U6,GCA!$H$3:$H$593,GCA!G$3:G$593,"",0,1)) -> 9852.788
F7: Anthiyur | G7: Anthiyur | H7: =V7 -> 15268.971 | I7: =W7 -> 13246.645 | J7: =X7 -> 14112.506 | K7: =IFERROR(AVERAGE(H7:J7),"") -> 14209.374 | M7: =L7*$L$643/$L$642 -> 0 | N7: =IF(M7>=2, ROUND(M7,0), IF(M7>1.1,2,"")) | O7: =N7 | P7: =O7 | R7: =R6 -> Erode | S7: =F7 -> Anthiyur | T7: =G7 -> Anthiyur | U7: =CONCATENATE(R7,"_",S7,"_",T7) -> Erode_Anthiyur_Anthiyur | V7: =IF(_xlfn.XLOOKUP($U7,GCA!$H$3:$H$593,GCA!E$3:E$593,"",0,1)="","",_xlfn.XLOOKUP($U7,GCA!$H$3:$H$593,GCA!E$3:E$593,"",0,1)) -> 15268.971 | W7: =IF(_xlfn.XLOOKUP($U7,GCA!$H$3:$H$593,GCA!F$3:F$593,"",0,1)="","",_xlfn.XLOOKUP($U7,GCA!$H$3:$H$593,GCA!F$3:F$593,"",0,1)) -> 13246.645 | X7: =IF(_xlfn.XLOOKUP($U7,GCA!$H$3:$H$593,GCA!G$3:G$593,"",0,1)="","",_xlfn.XLOOKUP($U7,GCA!$H$3:$H$593,GCA!G$3:G$593,"",0,1)) -> 14112.506
F8: Bhavani | G8: Ammapettai | H8: =V8 -> 5219.21 | I8: =W8 -> 3644.061 | J8: =X8 -> 5000.14 | K8: =IFERROR(AVERAGE(H8:J8),"") -> 4621.137 | M8: =L8*$L$643/$L$642 -> 0 | N8: =IF(M8>=2, ROUND(M8,0), IF(M8>1.1,2,"")) | O8: =N8 | P8: =O8 | R8: =R7 -> Erode | S8: =F8 -> Bhavani | T8: =G8 -> Ammapettai | U8: =CONCATENATE(R8,"_",S8,"_",T8) -> Erode_Bhavani_Ammapettai | V8: =IF(_xlfn.XLOOKUP($U8,GCA!$H$3:$H$593,GCA!E$3:E$593,"",0,1)="","",_xlfn.XLOOKUP($U8,GCA!$H$3:$H$593,GCA!E$3:E$593,"",0,1)) -> 5219.21 | W8: =IF(_xlfn.XLOOKUP($U8,GCA!$H$3:$H$593,GCA!F$3:F$593,"",0,1)="","",_xlfn.XLOOKUP($U8,GCA!$H$3:$H$593,GCA!F$3:F$593,"",0,1)) -> 3644.061 | X8: =IF(_xlfn.XLOOKUP($U8,GCA!$H$3:$H$593,GCA!G$3:G$593,"",0,1)="","",_xlfn.XLOOKUP($U8,GCA!$H$3:$H$593,GCA!G$3:G$593,"",0,1)) -> 5000.14
F9: Bhavani | G9: Bhavani | H9: =V9 -> 14129.05 | I9: =W9 -> 13052.005 | J9: =X9 -> 13810.765 | K9: =IFERROR(AVERAGE(H9:J9),"") -> 13663.94 | M9: =L9*$L$643/$L$642 -> 0 | N9: =IF(M9>=2, ROUND(M9,0), IF(M9>1.1,2,"")) | O9: =N9 | P9: =O9 | R9: =R8 -> Erode | S9: =F9 -> Bhavani | T9: =G9 -> Bhavani | U9: =CONCATENATE(R9,"_",S9,"_",T9) -> Erode_Bhavani_Bhavani | V9: =IF(_xlfn.XLOOKUP($U9,GCA!$H$3:$H$593,GCA!E$3:E$593,"",0,1)="","",_xlfn.XLOOKUP($U9,GCA!$H$3:$H$593,GCA!E$3:E$593,"",0,1)) -> 14129.05 | W9: =IF(_xlfn.XLOOKUP($U9,GCA!$H$3:$H$593,GCA!F$3:F$593,"",0,1)="","",_xlfn.XLOOKUP($U9,GCA!$H$3:$H$593,GCA!F$3:F$593,"",0,1)) -> 13052.005 | X9: =IF(_xlfn.XLOOKUP($U9,GCA!$H$3:$H$593,GCA!G$3:G$593,"",0,1)="","",_xlfn.XLOOKUP($U9,GCA!$H$3:$H$593,GCA!G$3:G$593,"",0,1)) -> 13810.765
F10: Bhavani | G10: Gobichettipalayam | H10: =V10 -> 1396.995 | I10: =W10 -> 1303.32 | J10: =X10 -> 1440.765 | K10: =IFERROR(AVERAGE(H10:J10),"") -> 1380.36 | M10: =L10*$L$643/$L$642 -> 0 | N10: =IF(M10>=2, ROUND(M10,0), IF(M10>1.1,2,"")) | O10: =N10 | P10: =O10 | R10: =R9 -> Erode | S10: =F10 -> Bhavani | T10: =G10 -> Gobichettipalayam | U10: =CONCATENATE(R10,"_",S10,"_",T10) -> Erode_Bhavani_Gobichettipalayam | V10: =IF(_xlfn.XLOOKUP($U10,GCA!$H$3:$H$593,GCA!E$3:E$593,"",0,1)="","",_xlfn.XLOOKUP($U10,GCA!$H$3:$H$593,GCA!E$3:E$593,"",0,1)) -> 1396.995 | W10: =IF(_xlfn.XLOOKUP($U10,GCA!$H$3:$H$593,GCA!F$3:F$593,"",0,1)="","",_xlfn.XLOOKUP($U10,GCA!$H$3:$H$593,GCA!F$3:F$593,"",0,1)) -> 1303.32 | X10: =IF(_xlfn.XLOOKUP($U10,GCA!$H$3:$H$593,GCA!G$3:G$593,"",0,1)="","",_xlfn.XLOOKUP($U10,GCA!$H$3:$H$593,GCA!G$3:G$593,"",0,1)) -> 1440.765
F11: Erode | G11: Erode | H11: =V11 -> 5092.544 | I11: =W11 -> 4744.562 | J11: =X11 -> 4984.02 | K11: =IFERROR(AVERAGE(H11:J11),"") -> 4940.3753 | M11: =L11*$L$643/$L$642 -> 0 | N11: =IF(M11>=2, ROUND(M11,0), IF(M11>1.1,2,"")) | O11: =N11 | P11: =O11 | R11: =R10 -> Erode | S11: =F11 -> Erode | T11: =G11 -> Erode | U11: =CONCATENATE(R11,"_",S11,"_",T11) -> Erode_Erode_Erode | V11: =IF(_xlfn.XLOOKUP($U11,GCA!$H$3:$H$593,GCA!E$3:E$593,"",0,1)="","",_xlfn.XLOOKUP($U11,GCA!$H$3:$H$593,GCA!E$3:E$593,"",0,1)) -> 5092.544 | W11: =IF(_xlfn.XLOOKUP($U11,GCA!$H$3:$H$593,GCA!F$3:F$593,"",0,1)="","",_xlfn.XLOOKUP($U11,GCA!$H$3:$H$593,GCA!F$3:F$593,"",0,1)) -> 4744.562 | X11: =IF(_xlfn.XLOOKUP($U11,GCA!$H$3:$H$593,GCA!G$3:G$593,"",0,1)="","",_xlfn.XLOOKUP($U11,GCA!$H$3:$H$593,GCA!G$3:G$593,"",0,1)) -> 4984.02
E12: 2 | F12: Gobichettipalayam | G12: Gobichettipalayam | H12: =V12 -> 19961.81 | I12: =W12 -> 19407.275 | J12: =X12 -> 20098.05 | K12: =IFERROR(AVERAGE(H12:J12),"") -> 19822.378 | L12: =SUM(K12:K14) -> 44761.684 | M12: =L12*$L$643/$L$642 -> 1.8788285 | N12: =IF(M12>=2, ROUND(M12,0), IF(M12>1.1,2,"")) -> 2 | O12: =N12 -> 2 | P12: =O12 -> 2 | R12: =R11 -> Erode | S12: =F12 -> Gobichettipalayam | T12: =G12 -> Gobichettipalayam | U12: =CONCATENATE(R12,"_",S12,"_",T12) -> Erode_Gobichettipalayam_Gobichettipalayam | V12: =IF(_xlfn.XLOOKUP($U12,GCA!$H$3:$H$593,GCA!E$3:E$593,"",0,1)="","",_xlfn.XLOOKUP($U12,GCA!$H$3:$H$593,GCA!E$3:E$593,"",0,1)) -> 19961.81 | W12: =IF(_xlfn.XLOOKUP($U12,GCA!$H$3:$H$593,GCA!F$3:F$593,"",0,1)="","",_xlfn.XLOOKUP($U12,GCA!$H$3:$H$593,GCA!F$3:F$593,"",0,1)) -> 19407.275 | X12: =IF(_xlfn.XLOOKUP($U12,GCA!$H$3:$H$593,GCA!G$3:G$593,"",0,1)="","",_xlfn.XLOOKUP($U12,GCA!$H$3:$H$593,GCA!G$3:G$593,"",0,1)) -> 20098.05
F13: Gobichettipalayam | G13: Thukkanaickenpalayam | H13: =V13 -> 11393.772 | I13: =W13 -> 11321.419 | J13: =X13 -> 11428.695 | K13: =IFERROR(AVERAGE(H13:J13),"") -> 11381.295 | M13: =L13*$L$643/$L$642 -> 0 | N13: =IF(M13>=2, ROUND(M13,0), IF(M13>1.1,2,"")) | O13: =N13 | P13: =O13 | R13: =R12 -> Erode | S13: =F13 -> Gobichettipalayam | T13: =G13 -> Thukkanaickenpalayam | U13: =CONCATENATE(R13,"_",S13,"_",T13) -> Erode_Gobichettipalayam_Thukkanaickenpalayam | V13: =IF(_xlfn.XLOOKUP($U13,GCA!$H$3:$H$593,GCA!E$3:E$593,"",0,1)="","",_xlfn.XLOOKUP($U13,GCA!$H$3:$H$593,GCA!E$3:E$593,"",0,1)) -> 11393.772 | W13: =IF(_xlfn.XLOOKUP($U13,GCA!$H$3:$H$593,GCA!F$3:F$593,"",0,1)="","",_xlfn.XLOOKUP($U13,GCA!$H$3:$H$593,GCA!F$3:F$593,"",0,1)) -> 11321.419 | X13: =IF(_xlfn.XLOOKUP($U13,GCA!$H$3:$H$593,GCA!G$3:G$593,"",0,1)="","",_xlfn.XLOOKUP($U13,GCA!$H$3:$H$593,GCA!G$3:G$593,"",0,1)) -> 11428.695
F14: Kodumudi | G14: Kodumudi | H14: =V14 -> 14443.277 | I14: =W14 -> 12955.858 | J14: =X14 -> 13274.897 | K14: =IFERROR(AVERAGE(H14:J14),"") -> 13558.011 | M14: =L14*$L$643/$L$642 -> 0 | N14: =IF(M14>=2, ROUND(M14,0), IF(M14>1.1,2,"")) | O14: =N14 | P14: =O14 | R14: =R13 -> Erode | S14: =F14 -> Kodumudi | T14: =G14 -> Kodumudi | U14: =CONCATENATE(R14,"_",S14,"_",T14) -> Erode_Kodumudi_Kodumudi | V14: =IF(_xlfn.XLOOKUP($U14,GCA!$H$3:$H$593,GCA!E$3:E$593,"",0,1)="","",_xlfn.XLOOKUP($U14,GCA!$H$3:$H$593,GCA!E$3:E$593,"",0,1)) -> 14443.277 | W14: =IF(_xlfn.XLOOKUP($U14,GCA!$H$3:$H$593,GCA!F$3:F$593,"",0,1)="","",_xlfn.XLOOKUP($U14,GCA!$H$3:$H$593,GCA!F$3:F$593,"",0,1)) -> 12955.858 | X14: =IF(_xlfn.XLOOKUP($U14,GCA!$H$3:$H$593,GCA!G$3:G$593,"",0,1)="","",_xlfn.XLOOKUP($U14,GCA!$H$3:$H$593,GCA!G$3:G$593,"",0,1)) -> 13274.897
E15: 3 | F15: Modakurichi | G15: Modakurichi | H15: =V15 -> 17293.745 | I15: =W15 -> 16618.923 | J15: =X15 -> 16632.766 | K15: =IFERROR(AVERAGE(H15:J15),"") -> 16848.478 | L15: =SUM(K15:K19) -> 49208.115 | M15: =L15*$L$643/$L$642 -> 2.0654632 | N15: =IF(M15>=2, ROUND(M15,0), IF(M15>1.1,2,"")) -> 2 | O15: =N15 -> 2 | P15: =O15 -> 2 | R15: =R14 -> Erode | S15: =F15 -> Modakurichi | T15: =G15 -> Modakurichi | U15: =CONCATENATE(R15,"_",S15,"_",T15) -> Erode_Modakurichi_Modakurichi | V15: =IF(_xlfn.XLOOKUP($U15,GCA!$H$3:$H$593,GCA!E$3:E$593,"",0,1)="","",_xlfn.XLOOKUP($U15,GCA!$H$3:$H$593,GCA!E$3:E$593,"",0,1)) -> 17293.745 | W15: =IF(_xlfn.XLOOKUP($U15,GCA!$H$3:$H$593,GCA!F$3:F$593,"",0,1)="","",_xlfn.XLOOKUP($U15,GCA!$H$3:$H$593,GCA!F$3:F$593,"",0,1)) -> 16618.923 | X15: =IF(_xlfn.XLOOKUP($U15,GCA!$H$3:$H$593,GCA!G$3:G$593,"",0,1)="","",_xlfn.XLOOKUP($U15,GCA!$H$3:$H$593,GCA!G$3:G$593,"",0,1)) -> 16632.766
F16: Nambiyur | G16: Bhavanisagar | H16: =V16 -> 2472.978 | I16: =W16 -> 2356.34 | J16: =X16 -> 2403.445 | K16: =IFERROR(AVERAGE(H16:J16),"") -> 2410.921 | R16: =R15 -> Erode | S16: =F16 -> Nambiyur | T16: =G16 -> Bhavanisagar | U16: =CONCATENATE(R16,"_",S16,"_",T16) -> Erode_Nambiyur_Bhavanisagar | V16: =IF(_xlfn.XLOOKUP($U16,GCA!$H$3:$H$593,GCA!E$3:E$593,"",0,1)="","",_xlfn.XLOOKUP($U16,GCA!$H$3:$H$593,GCA!E$3:E$593,"",0,1)) -> 2472.978 | W16: =IF(_xlfn.XLOOKUP($U16,GCA!$H$3:$H$593,GCA!F$3:F$593,"",0,1)="","",_xlfn.XLOOKUP($U16,GCA!$H$3:$H$593,GCA!F$3:F$593,"",0,1)) -> 2356.34 | X16: =IF(_xlfn.XLOOKUP($U16,GCA!$H$3:$H$593,GCA!G$3:G$593,"",0,1)="","",_xlfn.XLOOKUP($U16,GCA!$H$3:$H$593,GCA!G$3:G$593,"",0,1)) -> 2403.445
F17: Nambiyur | G17: Nambiyur | H17: =V17 -> 13986.107 | I17: =W17 -> 13614.9 | J17: =X17 -> 14146.38 | K17: =IFERROR(AVERAGE(H17:J17),"") -> 13915.796 | R17: =R16 -> Erode | S17: =F17 -> Nambiyur | T17: =G17 -> Nambiyur | U17: =CONCATENATE(R17,"_",S17,"_",T17) -> Erode_Nambiyur_Nambiyur | V17: =IF(_xlfn.XLOOKUP($U17,GCA!$H$3:$H$593,GCA!E$3:E$593,"",0,1)="","",_xlfn.XLOOKUP($U17,GCA!$H$3:$H$593,GCA!E$3:E$593,"",0,1)) -> 13986.107 | W17: =IF(_xlfn.XLOOKUP($U17,GCA!$H$3:$H$593,GCA!F$3:F$593,"",0,1)="","",_xlfn.XLOOKUP($U17,GCA!$H$3:$H$593,GCA!F$3:F$593,"",0,1)) -> 13614.9 | X17: =IF(_xlfn.XLOOKUP($U17,GCA!$H$3:$H$593,GCA!G$3:G$593,"",0,1)="","",_xlfn.XLOOKUP($U17,GCA!$H$3:$H$593,GCA!G$3:G$593,"",0,1)) -> 14146.38
F18: Perundurai | G18: Chennimalai | H18: =V18 -> 4963.58 | I18: =W18 -> 5029.225 | J18: =X18 -> 5029.815 | K18: =IFERROR(AVERAGE(H18:J18),"") -> 5007.54 | R18: =R17 -> Erode | S18: =F18 -> Perundurai | T18: =G18 -> Chennimalai | U18: =CONCATENATE(R18,"_",S18,"_",T18) -> Erode_Perundurai_Chennimalai | V18: =IF(_xlfn.XLOOKUP($U18,GCA!$H$3:$H$593,GCA!E$3:E$593,"",0,1)="","",_xlfn.XLOOKUP($U18,GCA!$H$3:$H$593,GCA!E$3:E$593,"",0,1)) -> 4963.58 | W18: =IF(_xlfn.XLOOKUP($U18,GCA!$H$3:$H$593,GCA!F$3:F$593,"",0,1)="","",_xlfn.XLOOKUP($U18,GCA!$H$3:$H$593,GCA!F$3:F$593,"",0,1)) -> 5029.225 | X18: =IF(_xlfn.XLOOKUP($U18,GCA!$H$3:$H$593,GCA!G$3:G$593,"",0,1)="","",_xlfn.XLOOKUP($U18,GCA!$H$3:$H$593,GCA!G$3:G$593,"",0,1)) -> 5029.815
F19: Perundurai | G19: Perundurai | H19: =V19 -> 10625.64 | I19: =W19 -> 9535.545 | J19: =X19 -> 12914.955 | K19: =IFERROR(AVERAGE(H19:J19),"") -> 11025.38 | R19: =R18 -> Erode | S19: =F19 -> Perundurai | T19: =G19 -> Perundurai | U19: =CONCATENATE(R19,"_",S19,"_",T19) -> Erode_Perundurai_Perundurai | V19: =IF(_xlfn.XLOOKUP($U19,GCA!$H$3:$H$593,GCA!E$3:E$593,"",0,1)="","",_xlfn.XLOOKUP($U19,GCA!$H$3:$H$593,GCA!E$3:E$593,"",0,1)) -> 10625.64 | W19: =IF(_xlfn.XLOOKUP($U19,GCA!$H$3:$H$593,GCA!F$3:F$593,"",0,1)="","",_xlfn.XLOOKUP($U19,GCA!$H$3:$H$593,GCA!F$3:F$593,"",0,1)) -> 9535.545 | X19: =IF(_xlfn.XLOOKUP($U19,GCA!$H$3:$H$593,GCA!G$3:G$593,"",0,1)="","",_xlfn.XLOOKUP($U19,GCA!$H$3:$H$593,GCA!G$3:G$593,"",0,1)) -> 12914.955
E20: 4 | F20: Sathyamangalam | G20: Bhavanisagar | H20: =V20 -> 6126.35 | I20: =W20 -> 5978.09 | J20: =X20 -> 5548.351 | K20: =IFERROR(AVERAGE(H20:J20),"") -> 5884.2637 | L20: =SUM(K20:K23) -> 30541.373 | M20: =L20*$L$643/$L$642 -> 1.2819447 | N20: =IF(M20>=2, ROUND(M20,0), IF(M20>1.1,2,"")) -> 2 | O20: =N20 -> 2 | P20: =O20 -> 2 | R20: =R19 -> Erode | S20: =F20 -> Sathyamangalam | T20: =G20 -> Bhavanisagar | U20: =CONCATENATE(R20,"_",S20,"_",T20) -> Erode_Sathyamangalam_Bhavanisagar | V20: =IF(_xlfn.XLOOKUP($U20,GCA!$H$3:$H$593,GCA!E$3:E$593,"",0,1)="","",_xlfn.XLOOKUP($U20,GCA!$H$3:$H$593,GCA!E$3:E$593,"",0,1)) -> 6126.35 | W20: =IF(_xlfn.XLOOKUP($U20,GCA!$H$3:$H$593,GCA!F$3:F$593,"",0,1)="","",_xlfn.XLOOKUP($U20,GCA!$H$3:$H$593,GCA!F$3:F$593,"",0,1)) -> 5978.09 | X20: =IF(_xlfn.XLOOKUP($U20,GCA!$H$3:$H$593,GCA!G$3:G$593,"",0,1)="","",_xlfn.XLOOKUP($U20,GCA!$H$3:$H$593,GCA!G$3:G$593,"",0,1)) -> 5548.351
F21: Sathyamangalam | G21: Sathyamangalam | H21: =V21 -> 12454.92 | I21: =W21 -> 12419.095 | J21: =X21 -> 12578.43 | K21: =IFERROR(AVERAGE(H21:J21),"") -> 12484.148 | R21: =R20 -> Erode | S21: =F21 -> Sathyamangalam | T21: =G21 -> Sathyamangalam | U21: =CONCATENATE(R21,"_",S21,"_",T21) -> Erode_Sathyamangalam_Sathyamangalam | V21: =IF(_xlfn.XLOOKUP($U21,GCA!$H$3:$H$593,GCA!E$3:E$593,"",0,1)="","",_xlfn.XLOOKUP($U21,GCA!$H$3:$H$593,GCA!E$3:E$593,"",0,1)) -> 12454.92 | W21: =IF(_xlfn.XLOOKUP($U21,GCA!$H$3:$H$593,GCA!F$3:F$593,"",0,1)="","",_xlfn.XLOOKUP($U21,GCA!$H$3:$H$593,GCA!F$3:F$593,"",0,1)) -> 12419.095 | X21: =IF(_xlfn.XLOOKUP($U21,GCA!$H$3:$H$593,GCA!G$3:G$593,"",0,1)="","",_xlfn.XLOOKUP($U21,GCA!$H$3:$H$593,GCA!G$3:G$593,"",0,1)) -> 12578.43
F22: Sathyamangalam | G22: Talavadi | H22: =V22 -> 1491.555 | I22: =W22 -> 1458.508 | J22: =X22 -> 1465.77 | K22: =IFERROR(AVERAGE(H22:J22),"") -> 1471.9443 | R22: =R21 -> Erode | S22: =F22 -> Sathyamangalam | T22: =G22 -> Talavadi | U22: =CONCATENATE(R22,"_",S22,"_",T22) -> Erode_Sathyamangalam_Talavadi | V22: =IF(_xlfn.XLOOKUP($U22,GCA!$H$3:$H$593,GCA!E$3:E$593,"",0,1)="","",_xlfn.XLOOKUP($U22,GCA!$H$3:$H$593,GCA!E$3:E$593,"",0,1)) -> 1491.555 | W22: =IF(_xlfn.XLOOKUP($U22,GCA!$H$3:$H$593,GCA!F$3:F$593,"",0,1)="","",_xlfn.XLOOKUP($U22,GCA!$H$3:$H$593,GCA!F$3:F$593,"",0,1)) -> 1458.508 | X22: =IF(_xlfn.XLOOKUP($U22,GCA!$H$3:$H$593,GCA!G$3:G$593,"",0,1)="","",_xlfn.XLOOKUP($U22,GCA!$H$3:$H$593,GCA!G$3:G$593,"",0,1)) -> 1465.77
F23: Talavadi | G23: Talavadi | H23: =V23 -> 10232.625 | I23: =W23 -> 9890.685 | J23: =X23 -> 11979.74 | K23: =IFERROR(AVERAGE(H23:J23),"") -> 10701.017 | R23: =R22 -> Erode | S23: =F23 -> Talavadi | T23: =G23 -> Talavadi | U23: =CONCATENATE(R23,"_",S23,"_",T23) -> Erode_Talavadi_Talavadi | V23: =IF(_xlfn.XLOOKUP($U23,GCA!$H$3:$H$593,GCA!E$3:E$593,"",0,1)="","",_xlfn.XLOOKUP($U23,GCA!$H$3:$H$593,GCA!E$3:E$593,"",0,1)) -> 10232.625 | W23: =IF(_xlfn.XLOOKUP($U23,GCA!$H$3:$H$593,GCA!F$3:F$593,"",0,1)="","",_xlfn.XLOOKUP($U23,GCA!$H$3:$H$593,GCA!F$3:F$593,"",0,1)) -> 9890.685 | X23: =IF(_xlfn.XLOOKUP($U23,GCA!$H$3:$H$593,GCA!G$3:G$593,"",0,1)="","",_xlfn.XLOOKUP($U23,GCA!$H$3:$H$593,GCA!G$3:G$593,"",0,1)) -> 11979.74
E24: DISTT. TOTAL | H24: =SUM(H6:H23) -> 176480.03 | I24: =SUM(I6:I23) -> 165744.53 | J24: =SUM(J6:J23) -> 176702.28 | K24: =SUM(K6:K23) -> 172975.61 | L24: =SUM(L6:L23) -> 172975.61 | M24: =SUM(M6:M23) -> 7.2604846 | N24: =SUM(N6:N23) -> 8 | O24: =SUM(O6:O23) -> 8 | P24: =SUM(P6:P23) -> 8 | R24: =R23 -> Erode | S24: =F24 -> 0 | T24: =G24 -> 0 | U24: =CONCATENATE(R24,"_",S24,"_",T24) -> Erode_0_0 | V24: =IF(_xlfn.XLOOKUP($U24,GCA!$H$3:$H$593,GCA!E$3:E$593,"",0,1)="","",_xlfn.XLOOKUP($U24,GCA!$H$3:$H$593,GCA!E$3:E$593,"",0,1)) | W24: =IF(_xlfn.XLOOKUP($U24,GCA!$H$3:$H$593,GCA!F$3:F$593,"",0,1)="","",_xlfn.XLOOKUP($U24,GCA!$H$3:$H$593,GCA!F$3:F$593,"",0,1)) | X24: =IF(_xlfn.XLOOKUP($U24,GCA!$H$3:$H$593,GCA!G$3:G$593,"",0,1)="","",_xlfn.XLOOKUP($U24,GCA!$H$3:$H$593,GCA!G$3:G$593,"",0,1))
C25: The Nilgiris | D25: 11 | E25: 1 | F25: Coonoor | G25: Coonoor | H25: =V25 -> 13031.92 | I25: =W25 -> 12779.968 | J25: =X25 -> 12566.936 | K25: =IFERROR(AVERAGE(H25:J25),"") -> 12792.941 | L25: =SUM(K25:K32) -> 75701.639 | M25: =L25*$L$643/$L$642 -> 3.1775033 | N25: =IF(M25>=2, ROUND(M25,0), IF(M25>1.1,2,"")) -> 3 | O25: =N25 -> 3 | P25: =O25 -> 3 | R25: =C25 -> The Nilgiris | S25: =F25 -> Coonoor | T25: =G25 -> Coonoor | U25: =CONCATENATE(R25,"_",S25,"_",T25) -> The Nilgiris_Coonoor_Coonoor | V25: =IF(_xlfn.XLOOKUP($U25,GCA!$H$3:$H$593,GCA!E$3:E$593,"",0,1)="","",_xlfn.XLOOKUP($U25,GCA!$H$3:$H$593,GCA!E$3:E$593,"",0,1)) -> 13031.92 | W25: =IF(_xlfn.XLOOKUP($U25,GCA!$H$3:$H$593,GCA!F$3:F$593,"",0,1)="","",_xlfn.XLOOKUP($U25,GCA!$H$3:$H$593,GCA!F$3:F$593,"",0,1)) -> 12779.968 | X25: =IF(_xlfn.XLOOKUP($U25,GCA!$H$3:$H$593,GCA!G$3:G$593,"",0,1)="","",_xlfn.XLOOKUP($U25,GCA!$H$3:$H$593,GCA!G$3:G$593,"",0,1)) -> 12566.936
F26: Gudalur | G26: Gudalur | H26: =V26 -> 14061.047 | I26: =W26 -> 14069.272 | J26: =X26 -> 14280.78 | K26: =IFERROR(AVERAGE(H26:J26),"") -> 14137.033 | M26: =L26*$L$643/$L$642 -> 0 | N26: =IF(M26>=2, ROUND(M26,0), IF(M26>1.1,2,"")) | O26: =N26 | P26: =O26 | R26: =R25 -> The Nilgiris | S26: =F26 -> Gudalur | T26: =G26 -> Gudalur | U26: =CONCATENATE(R26,"_",S26,"_",T26) -> The Nilgiris_Gudalur_Gudalur | V26: =IF(_xlfn.XLOOKUP($U26,GCA!$H$3:$H$593,GCA!E$3:E$593,"",0,1)="","",_xlfn.XLOOKUP($U26,GCA!$H$3:$H$593,GCA!E$3:E$593,"",0,1)) -> 14061.047 | W26: =IF(_xlfn.XLOOKUP($U26,GCA!$H$3:$H$593,GCA!F$3:F$593,"",0,1)="","",_xlfn.XLOOKUP($U26,GCA!$H$3:$H$593,GCA!F$3:F$593,"",0,1)) -> 14069.272 | X26: =IF(_xlfn.XLOOKUP($U26,GCA!$H$3:$H$593,GCA!G$3:G$593,"",0,1)="","",_xlfn.XLOOKUP($U26,GCA!$H$3:$H$593,GCA!G$3:G$593,"",0,1)) -> 14280.78
F27: Kotagiri | G27: Coonoor | H27: =V27 -> 754.145 | I27: =W27 -> 747.762 | J27: =X27 -> 770.239 | K27: =IFERROR(AVERAGE(H27:J27),"") -> 757.382 | M27: =L27*$L$643/$L$642 -> 0 | N27: =IF(M27>=2, ROUND(M27,0), IF(M27>1.1,2,"")) | O27: =N27 | P27: =O27 | R27: =R26 -> The Nilgiris | S27: =F27 -> Kotagiri | T27: =G27 -> Coonoor | U27: =CONCATENATE(R27,"_",S27,"_",T27) -> The Nilgiris_Kotagiri_Coonoor | V27: =IF(_xlfn.XLOOKUP($U27,GCA!$H$3:$H$593,GCA!E$3:E$593,"",0,1)="","",_xlfn.XLOOKUP($U27,GCA!$H$3:$H$593,GCA!E$3:E$593,"",0,1)) -> 754.145 | W27: =IF(_xlfn.XLOOKUP($U27,GCA!$H$3:$H$593,GCA!F$3:F$593,"",0,1)="","",_xlfn.XLOOKUP($U27,GCA!$H$3:$H$593,GCA!F$3:F$593,"",0,1)) -> 747.762 | X27: =IF(_xlfn.XLOOKUP($U27,GCA!$H$3:$H$593,GCA!G$3:G$593,"",0,1)="","",_xlfn.XLOOKUP($U27,GCA!$H$3:$H$593,GCA!G$3:G$593,"",0,1)) -> 770.239
F28: Kotagiri | G28: Kotagiri | H28: =V28 -> 12144.999 | I28: =W28 -> 12148.339 | J28: =X28 -> 12362.475 | K28: =IFERROR(AVERAGE(H28:J28),"") -> 12218.604 | M28: =L28*$L$643/$L$642 -> 0 | N28: =IF(M28>=2, ROUND(M28,0), IF(M28>1.1,2,"")) | O28: =N28 | P28: =O28 | R28: =R27 -> The Nilgiris | S28: =F28 -> Kotagiri | T28: =G28 -> Kotagiri | U28: =CONCATENATE(R28,"_",S28,"_",T28) -> The Nilgiris_Kotagiri_Kotagiri | V28: =IF(_xlfn.XLOOKUP($U28,GCA!$H$3:$H$593,GCA!E$3:E$593,"",0,1)="","",_xlfn.XLOOKUP($U28,GCA!$H$3:$H$593,GCA!E$3:E$593,"",0,1)) -> 12144.999 | W28: =IF(_xlfn.XLOOKUP($U28,GCA!$H$3:$H$593,GCA!F$3:F$593,"",0,1)="","",_xlfn.XLOOKUP($U28,GCA!$H$3:$H$593,GCA!F$3:F$593,"",0,1)) -> 12148.339 | X28: =IF(_xlfn.XLOOKUP($U28,GCA!$H$3:$H$593,GCA!G$3:G$593,"",0,1)="","",_xlfn.XLOOKUP($U28,GCA!$H$3:$H$593,GCA!G$3:G$593,"",0,1)) -> 12362.475
F29: Kundah | G29: Udhagamandalam | H29: =V29 -> 7799.298 | I29: =W29 -> 7805.928 | J29: =X29 -> 7634.629 | K29: =IFERROR(AVERAGE(H29:J29),"") -> 7746.6183 | M29: =L29*$L$643/$L$642 -> 0 | N29: =IF(M29>=2, ROUND(M29,0), IF(M29>1.1,2,"")) | O29: =N29 | P29: =O29 | R29: =R28 -> The Nilgiris | S29: =F29 -> Kundah | T29: =G29 -> Udhagamandalam | U29: =CONCATENATE(R29,"_",S29,"_",T29) -> The Nilgiris_Kundah_Udhagamandalam | V29: =IF(_xlfn.XLOOKUP($U29,GCA!$H$3:$H$593,GCA!E$3:E$593,"",0,1)="","",_xlfn.XLOOKUP($U29,GCA!$H$3:$H$593,GCA!E$3:E$593,"",0,1)) -> 7799.298 | W29: =IF(_xlfn.XLOOKUP($U29,GCA!$H$3:$H$593,GCA!F$3:F$593,"",0,1)="","",_xlfn.XLOOKUP($U29,GCA!$H$3:$H$593,GCA!F$3:F$593,"",0,1)) -> 7805.928 | X29: =IF(_xlfn.XLOOKUP($U29,GCA!$H$3:$H$593,GCA!G$3:G$593,"",0,1)="","",_xlfn.XLOOKUP($U29,GCA!$H$3:$H$593,GCA!G$3:G$593,"",0,1)) -> 7634.629
F30: Pandalur | G30: Gudalur | H30: =V30 -> 12207.626 | I30: =W30 -> 12233.435 | J30: =X30 -> 12338.904 | K30: =IFERROR(AVERAGE(H30:J30),"") -> 12259.988 | M30: =L30*$L$643/$L$642 -> 0 | N30: =IF(M30>=2, ROUND(M30,0), IF(M30>1.1,2,"")) | O30: =N30 | P30: =O30 | R30: =R29 -> The Nilgiris | S30: =F30 -> Pandalur | T30: =G30 -> Gudalur | U30: =CONCATENATE(R30,"_",S30,"_",T30) -> The Nilgiris_Pandalur_Gudalur | V30: =IF(_xlfn.XLOOKUP($U30,GCA!$H$3:$H$593,GCA!E$3:E$593,"",0,1)="","",_xlfn.XLOOKUP($U30,GCA!$H$3:$H$593,GCA!E$3:E$593,"",0,1)) -> 12207.626 | W30: =IF(_xlfn.XLOOKUP($U30,GCA!$H$3:$H$593,GCA!F$3:F$593,"",0,1)="","",_xlfn.XLOOKUP($U30,GCA!$H$3:$H$593,GCA!F$3:F$593,"",0,1)) -> 12233.435 | X30: =IF(_xlfn.XLOOKUP($U30,GCA!$H$3:$H$593,GCA!G$3:G$593,"",0,1)="","",_xlfn.XLOOKUP($U30,GCA!$H$3:$H$593,GCA!G$3:G$593,"",0,1)) -> 12338.904
F31: Udhagamandalam | G31: Gudalur | H31: =V31 -> 740.505 | I31: =W31 -> 751.725 | J31: =X31 -> 751.22 | K31: =IFERROR(AVERAGE(H31:J31),"") -> 747.81667 | M31: =L31*$L$643/$L$642 -> 0 | N31: =IF(M31>=2, ROUND(M31,0), IF(M31>1.1,2,"")) | O31: =N31 | P31: =O31 | R31: =R30 -> The Nilgiris | S31: =F31 -> Udhagamandalam | T31: =G31 -> Gudalur | U31: =CONCATENATE(R31,"_",S31,"_",T31) -> The Nilgiris_Udhagamandalam_Gudalur | V31: =IF(_xlfn.XLOOKUP($U31,GCA!$H$3:$H$593,GCA!E$3:E$593,"",0,1)="","",_xlfn.XLOOKUP($U31,GCA!$H$3:$H$593,GCA!E$3:E$593,"",0,1)) -> 740.505 | W31: =IF(_xlfn.XLOOKUP($U31,GCA!$H$3:$H$593,GCA!F$3:F$593,"",0,1)="","",_xlfn.XLOOKUP($U31,GCA!$H$3:$H$593,GCA!F$3:F$593,"",0,1)) -> 751.725 | X31: =IF(_xlfn.XLOOKUP($U31,GCA!$H$3:$H$593,GCA!G$3:G$593,"",0,1)="","",_xlfn.XLOOKUP($U31,GCA!$H$3:$H$593,GCA!G$3:G$593,"",0,1)) -> 751.22
F32: Udhagamandalam | G32: Udhagamandalam | H32: =V32 -> 14980.885 | I32: =W32 -> 14912.145 | J32: =X32 -> 15230.735 | K32: =IFERROR(AVERAGE(H32:J32),"") -> 15041.255 | M32: =L32*$L$643/$L$642 -> 0 | N32: =IF(M32>=2, ROUND(M32,0), IF(M32>1.1,2,"")) | O32: =N32 | P32: =O32 | R32: =R31 -> The Nilgiris | S32: =F32 -> Udhagamandalam | T32: =G32 -> Udhagamandalam | U32: =CONCATENATE(R32,"_",S32,"_",T32) -> The Nilgiris_Udhagamandalam_Udhagamandalam | V32: =IF(_xlfn.XLOOKUP($U32,GCA!$H$3:$H$593,GCA!E$3:E$593,"",0,1)="","",_xlfn.XLOOKUP($U32,GCA!$H$3:$H$593,GCA!E$3:E$593,"",0,1)) -> 14980.885 | W32: =IF(_xlfn.XLOOKUP($U32,GCA!$H$3:$H$593,GCA!F$3:F$593,"",0,1)="","",_xlfn.XLOOKUP($U32,GCA!$H$3:$H$593,GCA!F$3:F$593,"",0,1)) -> 14912.145 | X32: =IF(_xlfn.XLOOKUP($U32,GCA!$H$3:$H$593,GCA!G$3:G$593,"",0,1)="","",_xlfn.XLOOKUP($U32,GCA!$H$3:$H$593,GCA!G$3:G$593,"",0,1)) -> 15230.735
E33: DISTT. TOTAL | H33: =SUM(H25:H32) -> 75720.425 | I33: =SUM(I25:I32) -> 75448.574 | J33: =SUM(J25:J32) -> 75935.918 | K33: =SUM(K25:K32) -> 75701.639 | L33: =SUM(L25:L32) -> 75701.639 | M33: =SUM(M25:M32) -> 3.1775033 | N33: =SUM(N25:N32) -> 3 | O33: =SUM(O25:O32) -> 3 | P33: =SUM(P25:P32) -> 3 | R33: =R32 -> The Nilgiris | S33: =F33 -> 0 | T33: =G33 -> 0 | U33: =CONCATENATE(R33,"_",S33,"_",T33) -> The Nilgiris_0_0 | V33: =IF(_xlfn.XLOOKUP($U33,GCA!$H$3:$H$593,GCA!E$3:E$593,"",0,1)="","",_xlfn.XLOOKUP($U33,GCA!$H$3:$H$593,GCA!E$3:E$593,"",0,1)) | W33: =IF(_xlfn.XLOOKUP($U33,GCA!$H$3:$H$593,GCA!F$3:F$593,"",0,1)="","",_xlfn.XLOOKUP($U33,GCA!$H$3:$H$593,GCA!F$3:F$593,"",0,1)) | X33: =IF(_xlfn.XLOOKUP($U33,GCA!$H$3:$H$593,GCA!G$3:G$593,"",0,1)="","",_xlfn.XLOOKUP($U33,GCA!$H$3:$H$593,GCA!G$3:G$593,"",0,1))
C34: Coimbatore | D34: 12 | E34: 1 | F34: Anaimalai | G34: Anaimalai | H34: =V34 -> 27447.15 | I34: =W34 -> 26537.542 | J34: =X34 -> 28259.78 | K34: =IFERROR(AVERAGE(H34:J34),"") -> 27414.824 | L34: =SUM(K34:K37) -> 46287.932 | M34: =L34*$L$643/$L$642 -> 1.9428913 | N34: =IF(M34>=2, ROUND(M34,0), IF(M34>1.1,2,"")) -> 2 | O34: =N34 -> 2 | P34: =O34 -> 2 | R34: =C34 -> Coimbatore | S34: =F34 -> Anaimalai | T34: =G34 -> Anaimalai | U34: =CONCATENATE(R34,"_",S34,"_",T34) -> Coimbatore_Anaimalai_Anaimalai | V34: =IF(_xlfn.XLOOKUP($U34,GCA!$H$3:$H$593,GCA!E$3:E$593,"",0,1)="","",_xlfn.XLOOKUP($U34,GCA!$H$3:$H$593,GCA!E$3:E$593,"",0,1)) -> 27447.15 | W34: =IF(_xlfn.XLOOKUP($U34,GCA!$H$3:$H$593,GCA!F$3:F$593,"",0,1)="","",_xlfn.XLOOKUP($U34,GCA!$H$3:$H$593,GCA!F$3:F$593,"",0,1)) -> 26537.542 | X34: =IF(_xlfn.XLOOKUP($U34,GCA!$H$3:$H$593,GCA!G$3:G$593,"",0,1)="","",_xlfn.XLOOKUP($U34,GCA!$H$3:$H$593,GCA!G$3:G$593,"",0,1)) -> 28259.78
F35: Anaimalai | G35: Pollachi South | H35: =V35 -> 5369.63 | I35: =W35 -> 5022.18 | J35: =X35 -> 5565.899 | K35: =IFERROR(AVERAGE(H35:J35),"") -> 5319.2363 | M35: =L35*$L$643/$L$642 -> 0 | N35: =IF(M35>=2, ROUND(M35,0), IF(M35>1.1,2,"")) | O35: =N35 | P35: =O35 | R35: =R34 -> Coimbatore | S35: =F35 -> Anaimalai | T35: =G35 -> Pollachi South | U35: =CONCATENATE(R35,"_",S35,"_",T35) -> Coimbatore_Anaimalai_Pollachi South | V35: =IF(_xlfn.XLOOKUP($U35,GCA!$H$3:$H$593,GCA!E$3:E$593,"",0,1)="","",_xlfn.XLOOKUP($U35,GCA!$H$3:$H$593,GCA!E$3:E$593,"",0,1)) -> 5369.63 | W35: =IF(_xlfn.XLOOKUP($U35,GCA!$H$3:$H$593,GCA!F$3:F$593,"",0,1)="","",_xlfn.XLOOKUP($U35,GCA!$H$3:$H$593,GCA!F$3:F$593,"",0,1)) -> 5022.18 | X35: =IF(_xlfn.XLOOKUP($U35,GCA!$H$3:$H$593,GCA!G$3:G$593,"",0,1)="","",_xlfn.XLOOKUP($U35,GCA!$H$3:$H$593,GCA!G$3:G$593,"",0,1)) -> 5565.899
F36: Annur | G36: Annur | H36: =V36 -> 9396.175 | I36: =W36 -> 10243.545 | J36: =X36 -> 11140.985 | K36: =IFERROR(AVERAGE(H36:J36),"") -> 10260.235 | M36: =L36*$L$643/$L$642 -> 0 | N36: =IF(M36>=2, ROUND(M36,0), IF(M36>1.1,2,"")) | O36: =N36 | P36: =O36 | R36: =R35 -> Coimbatore | S36: =F36 -> Annur | T36: =G36 -> Annur | U36: =CONCATENATE(R36,"_",S36,"_",T36) -> Coimbatore_Annur_Annur | V36: =IF(_xlfn.XLOOKUP($U36,GCA!$H$3:$H$593,GCA!E$3:E$593,"",0,1)="","",_xlfn.XLOOKUP($U36,GCA!$H$3:$H$593,GCA!E$3:E$593,"",0,1)) -> 9396.175 | W36: =IF(_xlfn.XLOOKUP($U36,GCA!$H$3:$H$593,GCA!F$3:F$593,"",0,1)="","",_xlfn.XLOOKUP($U36,GCA!$H$3:$H$593,GCA!F$3:F$593,"",0,1)) -> 10243.545 | X36: =IF(_xlfn.XLOOKUP($U36,GCA!$H$3:$H$593,GCA!G$3:G$593,"",0,1)="","",_xlfn.XLOOKUP($U36,GCA!$H$3:$H$593,GCA!G$3:G$593,"",0,1)) -> 11140.985
F37: Annur | G37: Sarkar Samakulam | H37: =V37 -> 3094.04 | I37: =W37 -> 3252.455 | J37: =X37 -> 3534.415 | K37: =IFERROR(AVERAGE(H37:J37),"") -> 3293.6367 | M37: =L37*$L$643/$L$642 -> 0 | N37: =IF(M37>=2, ROUND(M37,0), IF(M37>1.1,2,"")) | O37: =N37 | P37: =O37 | R37: =R36 -> Coimbatore | S37: =F37 -> Annur | T37: =G37 -> Sarkar Samakulam | U37: =CONCATENATE(R37,"_",S37,"_",T37) -> Coimbatore_Annur_Sarkar Samakulam | V37: =IF(_xlfn.XLOOKUP($U37,GCA!$H$3:$H$593,GCA!E$3:E$593,"",0,1)="","",_xlfn.XLOOKUP($U37,GCA!$H$3:$H$593,GCA!E$3:E$593,"",0,1)) -> 3094.04 | W37: =IF(_xlfn.XLOOKUP($U37,GCA!$H$3:$H$593,GCA!F$3:F$593,"",0,1)="","",_xlfn.XLOOKUP($U37,GCA!$H$3:$H$593,GCA!F$3:F$593,"",0,1)) -> 3252.455 | X37: =IF(_xlfn.XLOOKUP($U37,GCA!$H$3:$H$593,GCA!G$3:G$593,"",0,1)="","",_xlfn.XLOOKUP($U37,GCA!$H$3:$H$593,GCA!G$3:G$593,"",0,1)) -> 3534.415
