Workbook

Sheet RC1-A1
F1: T-1
A2: TABLE A-1: DISTRICT-WISE DISTRIBUTION OF SELECTED VILLAGES FOR CHECK ON ENUMERATION OF AREA AND RESPONSE ACHIEVED.
A3: ='RC1-A3'!A3 -> STATE:PUDUCHERRY(34) | E3: YEAR: | F3: ='[1]Table-1'!E3 -> 2023-24 | G3: SEASON: | H3: ='[1]Table-1'!G3 -> RABI I(4)
A4: DISTRICT | B4: DISTRICT NAME | C4: NO.OF VILLAGES FOR WHICH SCHEDULE AS 1.0 RECEIVED | D4: NO. OF VILLAGES FOR WHICH SCHEDULE AS 1.0 IS ANALYSED | H4: PERCENTAGE RESPONSE TO COL.(2)
D5: WITH 'a' AND 'b' ENTRIES TOGETHER | E5: WITH 'a' AND 'b' ENTRIES SEPARATELY | F5: WITH 'a' ENTRIES ONLY | G5: TOTAL | H5: WITH 'a' AND 'b' ENTRIES TOGETHER | I5: WITH 'a' AND 'b' ENTRIES SEPARATELY | J5: WITH 'a' ENTRIES ONLY | K5: TOTAL
A10: 1 | B10: 2 | C10: 3 | D10: 4 | E10: 5 | F10: 7 | G10: 8 | H10: 9 | I10: 10 | J10: 11 | K10: 12
A11: ='[1]Table-1'!A11 | C11: ='[1]Table-1'!B11 | D11: ='[1]Table-1'!C11 | E11: ='[1]Table-1'!D11 | F11: ='[1]Table-1'!E11 | G11: ='[1]Table-1'!F11 | H11: ='[1]Table-1'!G11 | I11: ='[1]Table-1'!H11 | J11: ="SAMPLE: "&'[1]Table-1'!I3 -> SAMPLE: CENTRAL(1)
A12: ='[1]Table-1'!A12 -> 2 | B12: Puducherry | C12: ='[1]Table-1'!B12 -> 6 | D12: ='[1]Table-1'!C12 -> 6 | E12: ='[1]Table-1'!D12 -> 0 | F12: ='[1]Table-1'!E12 -> 0 | G12: ='[1]Table-1'!F12 -> 6 | H12: ='[1]Table-1'!G12 -> 100 | I12: ='[1]Table-1'!H12 -> 0 | J12: ='[1]Table-1'!I12 -> 0 | K12: ='[1]Table-1'!J12 -> 100
A13: ='[1]Table-1'!A13 | C13: ='[1]Table-1'!B13 | D13: ='[1]Table-1'!C13 | E13: ='[1]Table-1'!D13 | F13: ='[1]Table-1'!E13 | G13: ='[1]Table-1'!F13 | H13: ='[1]Table-1'!G13 | I13: ='[1]Table-1'!H13 | J13: ='[1]Table-1'!I13 | K13: ='[1]Table-1'!J13
A14: ='[1]Table-1'!A14 -> 4 | B14: Karaikal | C14: ='[1]Table-1'!B14 -> 3 | D14: ='[1]Table-1'!C14 -> 3 | E14: ='[1]Table-1'!D14 -> 0 | F14: ='[1]Table-1'!E14 -> 0 | G14: ='[1]Table-1'!F14 -> 3 | H14: ='[1]Table-1'!G14 -> 100 | I14: ='[1]Table-1'!H14 -> 0 | J14: ='[1]Table-1'!I14 -> 0 | K14: ='[1]Table-1'!J14 -> 100
A15: ='[1]Table-1'!A15 | C15: ='[1]Table-1'!B15 | D15: ='[1]Table-1'!C15 | E15: ='[1]Table-1'!D15 | F15: ='[1]Table-1'!E15 | G15: ='[1]Table-1'!F15 | H15: ='[1]Table-1'!G15 | I15: ='[1]Table-1'!H15 | J15: ='[1]Table-1'!I15 | K15: ='[1]Table-1'!J15
A16: ='[1]Table-1'!A16 | C16: ='[1]Table-1'!B16 | D16: ='[1]Table-1'!C16 | E16: ='[1]Table-1'!D16 | F16: ='[1]Table-1'!E16 | G16: ='[1]Table-1'!F16 | H16: ='[1]Table-1'!G16 | I16: ='[1]Table-1'!H16 | J16: ='[1]Table-1'!I16 | K16: ='[1]Table-1'!J16
A17: ='[1]Table-1'!A17 | C17: ='[1]Table-1'!B17 | D17: ='[1]Table-1'!C17 | E17: ='[1]Table-1'!D17 | F17: ='[1]Table-1'!E17 | G17: ='[1]Table-1'!F17 | H17: ='[1]Table-1'!G17 | I17: ='[1]Table-1'!H17 | J17: ='[1]Table-1'!I17 | K17: ='[1]Table-1'!J17
A18: ='[1]Table-1'!A18 | C18: ='[1]Table-1'!B18 | D18: ='[1]Table-1'!C18 | E18: ='[1]Table-1'!D18 | F18: ='[1]Table-1'!E18 | G18: ='[1]Table-1'!F18 | H18: ='[1]Table-1'!G18 | I18: ='[1]Table-1'!H18 | J18: ='[1]Table-1'!I18 | K18: ='[1]Table-1'!J18
A19: ='[1]Table-1'!A19 | C19: ='[1]Table-1'!B19 | D19: ='[1]Table-1'!C19 | E19: ='[1]Table-1'!D19 | F19: ='[1]Table-1'!E19 | G19: ='[1]Table-1'!F19 | H19: ='[1]Table-1'!G19 | I19: ='[1]Table-1'!H19 | J19: ='[1]Table-1'!I19 | K19: ='[1]Table-1'!J19
A20: ='[1]Table-1'!A20 | C20: ='[1]Table-1'!B20 | D20: ='[1]Table-1'!C20 | E20: ='[1]Table-1'!D20 | F20: ='[1]Table-1'!E20 | G20: ='[1]Table-1'!F20 | H20: ='[1]Table-1'!G20 | I20: ='[1]Table-1'!H20 | J20: ='[1]Table-1'!I20 | K20: ='[1]Table-1'!J20
A21: ='[1]Table-1'!A21 | C21: ='[1]Table-1'!B21 | D21: ='[1]Table-1'!C21 | E21: ='[1]Table-1'!D21 | F21: ='[1]Table-1'!E21 | G21: ='[1]Table-1'!F21 | H21: ='[1]Table-1'!G21 | I21: ='[1]Table-1'!H21 | J21: ='[1]Table-1'!I21 | K21: ='[1]Table-1'!J21
A22: ='[1]Table-1'!A22 | C22: ='[1]Table-1'!B22 | D22: ='[1]Table-1'!C22 | E22: ='[1]Table-1'!D22 | F22: ='[1]Table-1'!E22 | G22: ='[1]Table-1'!F22 | H22: ='[1]Table-1'!G22 | I22: ='[1]Table-1'!H22 | J22: ='[1]Table-1'!I22 | K22: ='[1]Table-1'!J22
A23: ='[1]Table-1'!A23 | C23: ='[1]Table-1'!B23 | D23: ='[1]Table-1'!C23 | E23: ='[1]Table-1'!D23 | F23: ='[1]Table-1'!E23 | G23: ='[1]Table-1'!F23 | H23: ='[1]Table-1'!G23 | I23: ='[1]Table-1'!H23 | J23: ='[1]Table-1'!I23 | K23: ='[1]Table-1'!J23
A24: ='[1]Table-1'!A24 | C24: ='[1]Table-1'!B24 | D24: ='[1]Table-1'!C24 | E24: ='[1]Table-1'!D24 | F24: ='[1]Table-1'!E24 | G24: ='[1]Table-1'!F24 | H24: ='[1]Table-1'!G24 | I24: ='[1]Table-1'!H24 | J24: ='[1]Table-1'!I24 | K24: ='[1]Table-1'!J24
A25: ='[1]Table-1'!A25 | C25: ='[1]Table-1'!B25 | D25: ='[1]Table-1'!C25 | E25: ='[1]Table-1'!D25 | F25: ='[1]Table-1'!E25 | G25: ='[1]Table-1'!F25 | H25: ='[1]Table-1'!G25 | I25: ='[1]Table-1'!H25 | J25: ='[1]Table-1'!I25 | K25: ='[1]Table-1'!J25
A26: ='[1]Table-1'!A26 | C26: ='[1]Table-1'!B26 | D26: ='[1]Table-1'!C26 | E26: ='[1]Table-1'!D26 | F26: ='[1]Table-1'!E26 | G26: ='[1]Table-1'!F26 | H26: ='[1]Table-1'!G26 | I26: ='[1]Table-1'!H26 | J26: ='[1]Table-1'!I26 | K26: ='[1]Table-1'!J26
... A98: ='[1]Table-1'!A98 -> STATE: | C98: ='[1]Table-1'!B98 -> 9 | D98: ='[1]Table-1'!C98 -> 9 | E98: ='[1]Table-1'!D98 -> 0 | F98: ='[1]Table-1'!E98 -> 0 | G98: ='[1]Table-1'!F98 -> 9 | H98: ='[1]Table-1'!G98 -> 100 | I98: ='[1]Table-1'!H98 -> 0 | J98: ='[1]Table-1'!I98 -> 0 | K98: ='[1]Table-1'!J98 -> 100
A99: NOTE: "a" ENTRIES= AS PER SUPERVISOR, "b" ENTRIES= AS PER PATWARI.
A100: Developed by: Deepak Kumar Agrawal, Senior Statistical Officer, NSSO (FOD), Faridabad, Haryana
A102: TABLE :A-1 : DISTRICT-WISE DISTRIBUTION OF SELECTED VILLAGES FOR CHECK ON ENUMERATION OF AREA AND RESPONSE ACHIEVED.
A103: =A3 -> STATE:PUDUCHERRY(34) | E103: YEAR: | F103: ='[1]Table-1'!P3 -> 2023-24 | G103: SEASON: | H103: ='[1]Table-1'!R3 -> RABI I(4)
A104: DISTRICT | B104: DISTRICT NAME | C104: NO.OF VILLAGES FOR WHICH SCHEDULE AS 1.0 RECEIVED | D104: NO. OF VILLAGES FOR WHICH SCHEDULE AS 1.0 IS ANALYSED | H104: PERCENTAGE RESPONSE TO COL.(2)
D105: WITH 'a' AND 'b' ENTRIES TOGETHER | E105: WITH 'a' AND 'b' ENTRIES SEPARATELY | F105: WITH 'a' ENTRIES ONLY | G105: TOTAL | H105: WITH 'a' AND 'b' ENTRIES TOGETHER | I105: WITH 'a' AND 'b' ENTRIES SEPARATELY | J105: WITH 'a' ENTRIES ONLY | K105: TOTAL
A110: 1 | B110: 2 | C110: 3 | D110: 4 | E110: 5 | F110: 7 | G110: 8 | H110: 9 | I110: 10 | J110: 11 | K110: 12
A111: ='[1]Table-1'!L11 | C111: ='[1]Table-1'!M11 | D111: ='[1]Table-1'!N11 | E111: ='[1]Table-1'!O11 | F111: ='[1]Table-1'!P11 | G111: ='[1]Table-1'!Q11 | H111: ='[1]Table-1'!R11 | I111: ='[1]Table-1'!S11 | J111: ="SAMPLE: "&'[1]Table-1'!T3 -> SAMPLE: STATE(2)
A112: ='[1]Table-1'!L12 -> 2 | B112: Puducherry | C112: ='[1]Table-1'!M12 -> 6 | D112: ='[1]Table-1'!N12 -> 6 | E112: ='[1]Table-1'!O12 -> 0 | F112: ='[1]Table-1'!P12 -> 0 | G112: ='[1]Table-1'!Q12 -> 6 | H112: ='[1]Table-1'!R12 -> 100 | I112: ='[1]Table-1'!S12 -> 0 | J112: ='[1]Table-1'!T12 -> 0 | K112: ='[1]Table-1'!U12 -> 100
A113: ='[1]Table-1'!L13 | C113: ='[1]Table-1'!M13 | D113: ='[1]Table-1'!N13 | E113: ='[1]Table-1'!O13 | F113: ='[1]Table-1'!P13 | G113: ='[1]Table-1'!Q13 | H113: ='[1]Table-1'!R13 | I113: ='[1]Table-1'!S13 | J113: ='[1]Table-1'!T13 | K113: ='[1]Table-1'!U13
A114: ='[1]Table-1'!L14 -> 4 | B114: Karaikal | C114: ='[1]Table-1'!M14 -> 3 | D114: ='[1]Table-1'!N14 -> 3 | E114: ='[1]Table-1'!O14 -> 0 | F114: ='[1]Table-1'!P14 -> 0 | G114: ='[1]Table-1'!Q14 -> 3 | H114: ='[1]Table-1'!R14 -> 100 | I114: ='[1]Table-1'!S14 -> 0 | J114: ='[1]Table-1'!T14 -> 0 | K114: ='[1]Table-1'!U14 -> 100
A115: ='[1]Table-1'!L15 | C115: ='[1]Table-1'!M15 | D115: ='[1]Table-1'!N15 | E115: ='[1]Table-1'!O15 | F115: ='[1]Table-1'!P15 | G115: ='[1]Table-1'!Q15 | H115: ='[1]Table-1'!R15 | I115: ='[1]Table-1'!S15 | J115: ='[1]Table-1'!T15 | K115: ='[1]Table-1'!U15
A116: ='[1]Table-1'!L16 | C116: ='[1]Table-1'!M16 | D116: ='[1]Table-1'!N16 | E116: ='[1]Table-1'!O16 | F116: ='[1]Table-1'!P16 | G116: ='[1]Table-1'!Q16 | H116: ='[1]Table-1'!R16 | I116: ='[1]Table-1'!S16 | J116: ='[1]Table-1'!T16 | K116: ='[1]Table-1'!U16
A117: ='[1]Table-1'!L17 | C117: ='[1]Table-1'!M17 | D117: ='[1]Table-1'!N17 | E117: ='[1]Table-1'!O17 | F117: ='[1]Table-1'!P17 | G117: ='[1]Table-1'!Q17 | H117: ='[1]Table-1'!R17 | I117: ='[1]Table-1'!S17 | J117: ='[1]Table-1'!T17 | K117: ='[1]Table-1'!U17
A118: ='[1]Table-1'!L18 | C118: ='[1]Table-1'!M18 | D118: ='[1]Table-1'!N18 | E118: ='[1]Table-1'!O18 | F118: ='[1]Table-1'!P18 | G118: ='[1]Table-1'!Q18 | H118: ='[1]Table-1'!R18 | I118: ='[1]Table-1'!S18 | J118: ='[1]Table-1'!T18 | K118: ='[1]Table-1'!U18
A119: ='[1]Table-1'!L19 | C119: ='[1]Table-1'!M19 | D119: ='[1]Table-1'!N19 | E119: ='[1]Table-1'!O19 | F119: ='[1]Table-1'!P19 | G119: ='[1]Table-1'!Q19 | H119: ='[1]Table-1'!R19 | I119: ='[1]Table-1'!S19 | J119: ='[1]Table-1'!T19 | K119: ='[1]Table-1'!U19
A120: ='[1]Table-1'!L20 | C120: ='[1]Table-1'!M20 | D120: ='[1]Table-1'!N20 | E120: ='[1]Table-1'!O20 | F120: ='[1]Table-1'!P20 | G120: ='[1]Table-1'!Q20 | H120: ='[1]Table-1'!R20 | I120: ='[1]Table-1'!S20 | J120: ='[1]Table-1'!T20 | K120: ='[1]Table-1'!U20
...

Sheet RC1-A2
A2: Table A-2 : DISTRICTWISE DISTRIBUTION OF SELECTED VILLAGES ACCORDING TO TIME LAG BETWEEN THE YEAR OF SURVEY AND UPDATING OF MAPS.
A3: ='RC1-A3'!A3 -> STATE:PUDUCHERRY(34) | F3: YEAR: | G3: ='[1]Table-2'!F3 -> 2023-24 | I3: SEASON: | J3: ='[1]Table-2'!I3 -> RABI I(4)
A4: DISTRICT | B4: DISTRICT NAME | C4: NO. OF VILLAGES ANALYSED | D4: NO. OF VILLAGES ACCORDING TO TIME LAG (YEARS) BETWEEN SURVEY AND UPDATING OF MAP. | I4: NO OF VILLAGES | K4: NO OF VILLAGES FOR WHICH
I5: UNSURVEYED AND INFORMATION NOT APPLICABLE | J5: FOR INFORMATION NOT AVAILABLE | K5: MAPS ARE AVAILABLE WITH PATWARI | N5: MAPS NOT AVAILABLE
D6: 1 | E6: 2 TO 5 | F6: 6 TO 10 | G6: 11 TO 20 | H6: ABOVE 20 | K6: USEABLE | L6: UN-USEABLE | M6: TOTAL
A7: 1 | B7: 2 | C7: 3 | D7: 4 | E7: 5 | F7: 6 | G7: 7 | H7: 8 | I7: 9 | J7: 10 | K7: 11 | L7: 12 | M7: 13 | N7: 14
A8: ='[1]Table-2'!A8 | C8: ='[1]Table-2'!B8 | D8: ='[1]Table-2'!C8 | E8: ='[1]Table-2'!D8 | F8: ='[1]Table-2'!E8 | G8: ='[1]Table-2'!F8 | H8: ='[1]Table-2'!G8 | I8: ='[1]Table-2'!H8 | J8: ='[1]Table-2'!I8 | ... L8: ='[1]Table-2'!K8 | M8: ='RC1-A1'!J11 -> SAMPLE: CENTRAL(1)
A9: ='[1]Table-2'!A9 -> 2 | B9: Puducherry | C9: ='[1]Table-2'!B9 -> 6 | D9: ='[1]Table-2'!C9 -> 0 | E9: ='[1]Table-2'!D9 -> 0 | F9: ='[1]Table-2'!E9 -> 0 | G9: ='[1]Table-2'!F9 -> 0 | H9: ='[1]Table-2'!G9 -> 6 | I9: ='[1]Table-2'!H9 -> 0 | J9: ='[1]Table-2'!I9 -> 0 | ... N9: ='[1]Table-2'!M9 -> 0
A10: ='[1]Table-2'!A10 | C10: ='[1]Table-2'!B10 | D10: ='[1]Table-2'!C10 | E10: ='[1]Table-2'!D10 | F10: ='[1]Table-2'!E10 | G10: ='[1]Table-2'!F10 | H10: ='[1]Table-2'!G10 | I10: ='[1]Table-2'!H10 | J10: ='[1]Table-2'!I10 | ... N10: ='[1]Table-2'!M10
A11: ='[1]Table-2'!A11 -> 4 | B11: Karaikal | C11: ='[1]Table-2'!B11 -> 3 | D11: ='[1]Table-2'!C11 -> 0 | E11: ='[1]Table-2'!D11 -> 0 | F11: ='[1]Table-2'!E11 -> 0 | G11: ='[1]Table-2'!F11 -> 0 | H11: ='[1]Table-2'!G11 -> 2 | I11: ='[1]Table-2'!H11 -> 0 | J11: ='[1]Table-2'!I11 -> 1 | ... N11: ='[1]Table-2'!M11 -> 0
A12: ='[1]Table-2'!A12 | C12: ='[1]Table-2'!B12 | D12: ='[1]Table-2'!C12 | E12: ='[1]Table-2'!D12 | F12: ='[1]Table-2'!E12 | G12: ='[1]Table-2'!F12 | H12: ='[1]Table-2'!G12 | I12: ='[1]Table-2'!H12 | J12: ='[1]Table-2'!I12 | ... N12: ='[1]Table-2'!M12
A13: ='[1]Table-2'!A13 | C13: ='[1]Table-2'!B13 | D13: ='[1]Table-2'!C13 | E13: ='[1]Table-2'!D13 | F13: ='[1]Table-2'!E13 | G13: ='[1]Table-2'!F13 | H13: ='[1]Table-2'!G13 | I13: ='[1]Table-2'!H13 | J13: ='[1]Table-2'!I13 | ... N13: ='[1]Table-2'!M13
A14: ='[1]Table-2'!A14 | C14: ='[1]Table-2'!B14 | D14: ='[1]Table-2'!C14 | E14: ='[1]Table-2'!D14 | F14: ='[1]Table-2'!E14 | G14: ='[1]Table-2'!F14 | H14: ='[1]Table-2'!G14 | I14: ='[1]Table-2'!H14 | J14: ='[1]Table-2'!I14 | ... N14: ='[1]Table-2'!M14
A15: ='[1]Table-2'!A15 | C15: ='[1]Table-2'!B15 | D15: ='[1]Table-2'!C15 | E15: ='[1]Table-2'!D15 | F15: ='[1]Table-2'!E15 | G15: ='[1]Table-2'!F15 | H15: ='[1]Table-2'!G15 | I15: ='[1]Table-2'!H15 | J15: ='[1]Table-2'!I15 | ... N15: ='[1]Table-2'!M15
A16: ='[1]Table-2'!A16 | C16: ='[1]Table-2'!B16 | D16: ='[1]Table-2'!C16 | E16: ='[1]Table-2'!D16 | F16: ='[1]Table-2'!E16 | G16: ='[1]Table-2'!F16 | H16: ='[1]Table-2'!G16 | I16: ='[1]Table-2'!H16 | J16: ='[1]Table-2'!I16 | ... N16: ='[1]Table-2'!M16
A17: ='[1]Table-2'!A17 | C17: ='[1]Table-2'!B17 | D17: ='[1]Table-2'!C17 | E17: ='[1]Table-2'!D17 | F17: ='[1]Table-2'!E17 | G17: ='[1]Table-2'!F17 | H17: ='[1]Table-2'!G17 | I17: ='[1]Table-2'!H17 | J17: ='[1]Table-2'!I17 | ... N17: ='[1]Table-2'!M17
A18: ='[1]Table-2'!A18 | C18: ='[1]Table-2'!B18 | D18: ='[1]Table-2'!C18 | E18: ='[1]Table-2'!D18 | F18: ='[1]Table-2'!E18 | G18: ='[1]Table-2'!F18 | H18: ='[1]Table-2'!G18 | I18: ='[1]Table-2'!H18 | J18: ='[1]Table-2'!I18 | ... N18: ='[1]Table-2'!M18
A19: ='[1]Table-2'!A19 | C19: ='[1]Table-2'!B19 | D19: ='[1]Table-2'!C19 | E19: ='[1]Table-2'!D19 | F19: ='[1]Table-2'!E19 | G19: ='[1]Table-2'!F19 | H19: ='[1]Table-2'!G19 | I19: ='[1]Table-2'!H19 | J19: ='[1]Table-2'!I19 | ... N19: ='[1]Table-2'!M19
A20: ='[1]Table-2'!A20 | C20: ='[1]Table-2'!B20 | D20: ='[1]Table-2'!C20 | E20: ='[1]Table-2'!D20 | F20: ='[1]Table-2'!E20 | G20: ='[1]Table-2'!F20 | H20: ='[1]Table-2'!G20 | I20: ='[1]Table-2'!H20 | J20: ='[1]Table-2'!I20 | ... N20: ='[1]Table-2'!M20
A21: ='[1]Table-2'!A21 | C21: ='[1]Table-2'!B21 | D21: ='[1]Table-2'!C21 | E21: ='[1]Table-2'!D21 | F21: ='[1]Table-2'!E21 | G21: ='[1]Table-2'!F21 | H21: ='[1]Table-2'!G21 | I21: ='[1]Table-2'!H21 | J21: ='[1]Table-2'!I21 | ... N21: ='[1]Table-2'!M21
A22: ='[1]Table-2'!A22 | C22: ='[1]Table-2'!B22 | D22: ='[1]Table-2'!C22 | E22: ='[1]Table-2'!D22 | F22: ='[1]Table-2'!E22 | G22: ='[1]Table-2'!F22 | H22: ='[1]Table-2'!G22 | I22: ='[1]Table-2'!H22 | J22: ='[1]Table-2'!I22 | ... N22: ='[1]Table-2'!M22
A23: ='[1]Table-2'!A23 | C23: ='[1]Table-2'!B23 | D23: ='[1]Table-2'!C23 | E23: ='[1]Table-2'!D23 | F23: ='[1]Table-2'!E23 | G23: ='[1]Table-2'!F23 | H23: ='[1]Table-2'!G23 | I23: ='[1]Table-2'!H23 | J23: ='[1]Table-2'!I23 | ... N23: ='[1]Table-2'!M23
... A101: ='[1]Table-2'!A101 -> STATE: | C101: ='[1]Table-2'!B101 -> 9 | D101: ='[1]Table-2'!C101 -> 0 | E101: ='[1]Table-2'!D101 -> 0 | F101: ='[1]Table-2'!E101 -> 0 | G101: ='[1]Table-2'!F101 -> 0 | H101: ='[1]Table-2'!G101 -> 8 | I101: ='[1]Table-2'!H101 -> 0 | J101: ='[1]Table-2'!I101 -> 1 | ... N101: ='[1]Table-2'!M101 -> 0
A102: %AGE TO COL (2) | D102: ='[1]Table-2'!C102 -> 0 | E102: ='[1]Table-2'!D102 -> 0 | F102: ='[1]Table-2'!E102 -> 0 | G102: ='[1]Table-2'!F102 -> 0 | H102: ='[1]Table-2'!G102 -> 88.89 | I102: ='[1]Table-2'!H102 -> 0 | J102: ='[1]Table-2'!I102 -> 11.11 | K102: ='[1]Table-2'!J102 -> 100 | ... N102: ='[1]Table-2'!M102 -> 0
A103: NOTE: THIS TABLE WILL BE PREPARED ONLY FOR THE FIRST SEASON OF THE YEAR
A104: COL.2=(COL. 3 TO COL. 9)=COL.12+COL.13
A105: Developed by: Deepak Kumar Agrawal, Senior Statistical Officer, NSSO (FOD), Faridabad, Haryana
A107: Table A-2 : DISTRICTWISE DISTRIBUTION OF SELECTED VILLAGES ACCORDING TO TIME LAG BETWEEN THE YEAR OF SURVEY AND UPDATING OF MAPS.
A108: =A3 -> STATE:PUDUCHERRY(34) | F108: YEAR: | G108: ='[1]Table-2'!T3 -> 2023-24 | I108: SEASON: | J108: ='[1]Table-2'!W3 -> RABI I(4)
A109: DISTRICT | B109: DISTRICT NAME | C109: NO. OF VILLAGES ANALYSED | D109: NO. OF VILLAGES ACCORDING TO TIME LAG (YEARS) BETWEEN SURVEY AND UPDATING OF MAP. | I109: NO OF VILLAGES | K109: NO OF VILLAGES FOR WHICH
I110: UNSURVEYED AND INFORMATION NOT APPLICABLE | J110: FOR INFORMATION NOT AVAILABLE | K110: MAPS ARE AVAILABLE WITH PATWARI | N110: MAPS NOT AVAILABLE
D111: 1 | E111: 2 TO 5 | F111: 6 TO 10 | G111: 11 TO 20 | H111: ABOVE 20 | K111: USEABLE | L111: UN-USEABLE | M111: TOTAL
A112: 1 | B112: 2 | C112: 3 | D112: 4 | E112: 5 | F112: 6 | G112: 7 | H112: 8 | I112: 9 | J112: 10 | K112: 11 | L112: 12 | M112: 13 | N112: 14
A113: ='[1]Table-2'!O8 | C113: ='[1]Table-2'!P8 | D113: ='[1]Table-2'!Q8 | E113: ='[1]Table-2'!R8 | F113: ='[1]Table-2'!S8 | G113: ='[1]Table-2'!T8 | H113: ='[1]Table-2'!U8 | I113: ='[1]Table-2'!V8 | J113: ='[1]Table-2'!W8 | ... L113: ='[1]Table-2'!Y8 | M113: ='RC1-A1'!J111 -> SAMPLE: STATE(2)
A114: ='[1]Table-2'!O9 -> 2 | B114: Puducherry | C114: ='[1]Table-2'!P9 -> 6 | D114: ='[1]Table-2'!Q9 -> 0 | E114: ='[1]Table-2'!R9 -> 0 | F114: ='[1]Table-2'!S9 -> 0 | G114: ='[1]Table-2'!T9 -> 0 | H114: ='[1]Table-2'!U9 -> 6 | I114: ='[1]Table-2'!V9 -> 0 | J114: ='[1]Table-2'!W9 -> 0 | ... N114: ='[1]Table-2'!AA9 -> 0
A115: ='[1]Table-2'!O10 | C115: ='[1]Table-2'!P10 | D115: ='[1]Table-2'!Q10 | E115: ='[1]Table-2'!R10 | F115: ='[1]Table-2'!S10 | G115: ='[1]Table-2'!T10 | H115: ='[1]Table-2'!U10 | I115: ='[1]Table-2'!V10 | J115: ='[1]Table-2'!W10 | ... N115: ='[1]Table-2'!AA10
A116: ='[1]Table-2'!O11 -> 4 | B116: Karaikal | C116: ='[1]Table-2'!P11 -> 3 | D116: ='[1]Table-2'!Q11 -> 0 | E116: ='[1]Table-2'!R11 -> 0 | F116: ='[1]Table-2'!S11 -> 0 | G116: ='[1]Table-2'!T11 -> 0 | H116: ='[1]Table-2'!U11 -> 3 | I116: ='[1]Table-2'!V11 -> 0 | J116: ='[1]Table-2'!W11 -> 0 | ... N116: ='[1]Table-2'!AA11 -> 0
A117: ='[1]Table-2'!O12 | C117: ='[1]Table-2'!P12 | D117: ='[1]Table-2'!Q12 | E117: ='[1]Table-2'!R12 | F117: ='[1]Table-2'!S12 | G117: ='[1]Table-2'!T12 | H117: ='[1]Table-2'!U12 | I117: ='[1]Table-2'!V12 | J117: ='[1]Table-2'!W12 | ... N117: ='[1]Table-2'!AA12
A118: ='[1]Table-2'!O13 | C118: ='[1]Table-2'!P13 | D118: ='[1]Table-2'!Q13 | E118: ='[1]Table-2'!R13 | F118: ='[1]Table-2'!S13 | G118: ='[1]Table-2'!T13 | H118: ='[1]Table-2'!U13 | I118: ='[1]Table-2'!V13 | J118: ='[1]Table-2'!W13 | ... N118: ='[1]Table-2'!AA13
A119: ='[1]Table-2'!O14 | C119: ='[1]Table-2'!P14 | D119: ='[1]Table-2'!Q14 | E119: ='[1]Table-2'!R14 | F119: ='[1]Table-2'!S14 | G119: ='[1]Table-2'!T14 | H119: ='[1]Table-2'!U14 | I119: ='[1]Table-2'!V14 | J119: ='[1]Table-2'!W14 | ... N119: ='[1]Table-2'!AA14
...

Sheet RC1-A3
A2: TABLE A-3: DISTRICTWISE AVERAGE WORKLOAD PER PATWARI IN THE SELECTED VILLAGES
A3: ='[1]Table-3'!A3 -> STATE:PUDUCHERRY(34) | D3: ='[1]Table-3'!C3 -> YEAR:2023-24 | E3: ='[1]Table-3'!D3 -> SEASON:RABI I(4)
A4: DISTRICT | B4: DISTRICT NAME | C4: AVERAGE NUMBER OF VILLAGES ALLOTED PER PATWARI(0.0) | E4: AVERAGE WORKLOAD PER VILLAGE IN TERM OF
C5: TOTAL | D5: TRS | E5: SURVEY NUMBER | F5: GEOGRAPHICAL AREA (HA)
A7: 1 | B7: 2 | C7: 3 | D7: 4 | E7: 5 | F7: 6
A8: ='[1]Table-3'!A8 | C8: ='[1]Table-3'!B8 | D8: ='[1]Table-3'!C8 | E8: ='[1]Table-3'!D8 | F8: ='[1]Table-3'!E3 -> SAMPLE:CENTRAL(1)
A9: ='[1]Table-3'!A9 -> 2 | B9: Puducherry | C9: ='[1]Table-3'!B9 -> 9 | D9: ='[1]Table-3'!C9 -> 2 | E9: ='[1]Table-3'!D9 -> 1178.6667 | F9: ='[1]Table-3'!E9 -> 411.66333
A10: ='[1]Table-3'!A10 | C10: ='[1]Table-3'!B10 | D10: ='[1]Table-3'!C10 | E10: ='[1]Table-3'!D10 | F10: ='[1]Table-3'!E10
A11: ='[1]Table-3'!A11 -> 4 | B11: Karaikal | C11: ='[1]Table-3'!B11 -> 12.666667 | D11: ='[1]Table-3'!C11 -> 2 | E11: ='[1]Table-3'!D11 -> 1446.3333 | F11: ='[1]Table-3'!E11 -> 368.51333
A12: ='[1]Table-3'!A12 | C12: ='[1]Table-3'!B12 | D12: ='[1]Table-3'!C12 | E12: ='[1]Table-3'!D12 | F12: ='[1]Table-3'!E12
A13: ='[1]Table-3'!A13 | C13: ='[1]Table-3'!B13 | D13: ='[1]Table-3'!C13 | E13: ='[1]Table-3'!D13 | F13: ='[1]Table-3'!E13
A14: ='[1]Table-3'!A14 | C14: ='[1]Table-3'!B14 | D14: ='[1]Table-3'!C14 | E14: ='[1]Table-3'!D14 | F14: ='[1]Table-3'!E14
A15: ='[1]Table-3'!A15 | C15: ='[1]Table-3'!B15 | D15: ='[1]Table-3'!C15 | E15: ='[1]Table-3'!D15 | F15: ='[1]Table-3'!E15
A16: ='[1]Table-3'!A16 | C16: ='[1]Table-3'!B16 | D16: ='[1]Table-3'!C16 | E16: ='[1]Table-3'!D16 | F16: ='[1]Table-3'!E16
A17: ='[1]Table-3'!A17 | C17: ='[1]Table-3'!B17 | D17: ='[1]Table-3'!C17 | E17: ='[1]Table-3'!D17 | F17: ='[1]Table-3'!E17
A18: ='[1]Table-3'!A18 | C18: ='[1]Table-3'!B18 | D18: ='[1]Table-3'!C18 | E18: ='[1]Table-3'!D18 | F18: ='[1]Table-3'!E18
A19: ='[1]Table-3'!A19 | C19: ='[1]Table-3'!B19 | D19: ='[1]Table-3'!C19 | E19: ='[1]Table-3'!D19 | F19: ='[1]Table-3'!E19
A20: ='[1]Table-3'!A20 | C20: ='[1]Table-3'!B20 | D20: ='[1]Table-3'!C20 | E20: ='[1]Table-3'!D20 | F20: ='[1]Table-3'!E20
A21: ='[1]Table-3'!A21 | C21: ='[1]Table-3'!B21 | D21: ='[1]Table-3'!C21 | E21: ='[1]Table-3'!D21 | F21: ='[1]Table-3'!E21
A22: ='[1]Table-3'!A22 | C22: ='[1]Table-3'!B22 | D22: ='[1]Table-3'!C22 | E22: ='[1]Table-3'!D22 | F22: ='[1]Table-3'!E22
A23: ='[1]Table-3'!A23 | C23: ='[1]Table-3'!B23 | D23: ='[1]Table-3'!C23 | E23: ='[1]Table-3'!D23 | F23: ='[1]Table-3'!E23
... A101: ='[1]Table-3'!A101 -> STATE: | C101: ='[1]Table-3'!B101 -> 10.222222 | D101: ='[1]Table-3'!C101 -> 2 | E101: ='[1]Table-3'!D101 -> 1267.8889 | F101: ='[1]Table-3'!E101 -> 397.28
A102: NOTE: (i) THIS TABLE WILL BE PREPARED ONLY FOR THE FIRST SEASON OF THE YEAR
A103: (II) COL.3 IS NOT APPLICABLE FOR EARAS STATE
A104: Developed by: Deepak Kumar Agrawal, Senior Statistical Officer, NSSO (FOD), Faridabad, Haryana
A106: TABLE A-3: DISTRICTWISE AVERAGE WORKLOAD PER PATWARI IN THE SELECTED VILLAGES
A107: ='[1]Table-3'!G3 -> STATE:PUDUCHERRY(34) | D107: ='[1]Table-3'!I3 -> YEAR:2023-24 | E107: ='[1]Table-3'!J3 -> SEASON:RABI I(4)
A108: DISTRICT | B108: DISTRICT NAME | C108: AVERAGE NUMBER OF VILLAGES ALLOTED PER PATWARI(0.0) | E108: AVERAGE WORKLOAD PER VILLAGE IN TERM OF
C109: TOTAL | D109: TRS | E109: SURVEY NUMBER | F109: GEOGRAPHICAL AREA (HA)
A111: 1 | B111: 2 | C111: 3 | D111: 4 | E111: 5 | F111: 6
A112: ='[1]Table-3'!G8 | C112: ='[1]Table-3'!H8 | D112: ='[1]Table-3'!I8 | E112: ='[1]Table-3'!J8 | F112: ='[1]Table-3'!K3 -> SAMPLE:STATE(2)
A113: ='[1]Table-3'!G9 -> 2 | B113: Puducherry | C113: ='[1]Table-3'!H9 -> 9 | D113: ='[1]Table-3'!I9 -> 1.3333333 | E113: ='[1]Table-3'!J9 -> 1349.3333 | F113: ='[1]Table-3'!K9 -> 397.41833
A114: ='[1]Table-3'!G10 | C114: ='[1]Table-3'!H10 | D114: ='[1]Table-3'!I10 | E114: ='[1]Table-3'!J10 | F114: ='[1]Table-3'!K10
A115: ='[1]Table-3'!G11 -> 4 | B115: Karaikal | C115: ='[1]Table-3'!H11 -> 12.333333 | D115: ='[1]Table-3'!I11 -> 2 | E115: ='[1]Table-3'!J11 -> 881.66667 | F115: ='[1]Table-3'!K11 -> 369.21333
A116: ='[1]Table-3'!G12 | C116: ='[1]Table-3'!H12 | D116: ='[1]Table-3'!I12 | E116: ='[1]Table-3'!J12 | F116: ='[1]Table-3'!K12
A117: ='[1]Table-3'!G13 | C117: ='[1]Table-3'!H13 | D117: ='[1]Table-3'!I13 | E117: ='[1]Table-3'!J13 | F117: ='[1]Table-3'!K13
A118: ='[1]Table-3'!G14 | C118: ='[1]Table-3'!H14 | D118: ='[1]Table-3'!I14 | E118: ='[1]Table-3'!J14 | F118: ='[1]Table-3'!K14
A119: ='[1]Table-3'!G15 | C119: ='[1]Table-3'!H15 | D119: ='[1]Table-3'!I15 | E119: ='[1]Table-3'!J15 | F119: ='[1]Table-3'!K15
A120: ='[1]Table-3'!G16 | C120: ='[1]Table-3'!H16 | D120: ='[1]Table-3'!I16 | E120: ='[1]Table-3'!J16 | F120: ='[1]Table-3'!K16
A121: ='[1]Table-3'!G17 | C121: ='[1]Table-3'!H17 | D121: ='[1]Table-3'!I17 | E121: ='[1]Table-3'!J17 | F121: ='[1]Table-3'!K17
...

Sheet RC1-A4
A2: TABLE A-4:BIVARIATE FREQUENCY DISTRIBUTION OF SELECTED VILLAGE ACCORDING TO TOTAL NUMBER OR SERIAL/SURVEY NUMBERS AND GEOGRAPHICAL AREA
A4: ='RC1-A3'!A3:C3 -> STATE:PUDUCHERRY(34) | E4: YEAR: | F4: ='[1]Table-4'!F5 -> 2023-24 | H4: SEASON: | I4: ='[1]Table-4'!I5 -> RABI I(4) | L4: ='RC1-A3'!F8 -> SAMPLE:CENTRAL(1)
A5: CLASS INTERVAL OF SERIAL/ SURVEY (CODE) | B5: CLASS INTERVAL OF GEOGRAPHICAL AREA(HA)
B6: UP TO 50 | C6: 51 TO 100 | D6: 101 TO 200 | E6: 201 TO 400 | F6: 401 TO 600 | G6: 601 TO 800 | H6: 801 TO 1000 | I6: 1001 TO 3000 | J6: 3001 and ABOVE | K6: NOT REPORTED | L6: TOTAL | M6: %AGE
A7: UPTO 50 | B7: ='[1]Table-4'!B8 -> 0 | C7: ='[1]Table-4'!C8 -> 0 | D7: ='[1]Table-4'!D8 -> 0 | E7: ='[1]Table-4'!E8 -> 0 | F7: ='[1]Table-4'!F8 -> 0 | G7: ='[1]Table-4'!G8 -> 0 | H7: ='[1]Table-4'!H8 -> 0 | I7: ='[1]Table-4'!I8 -> 0 | ... M7: ='[1]Table-4'!M8 -> 0
A8: 51 to 100 | B8: ='[1]Table-4'!B9 -> 0 | C8: ='[1]Table-4'!C9 -> 0 | D8: ='[1]Table-4'!D9 -> 0 | E8: ='[1]Table-4'!E9 -> 0 | F8: ='[1]Table-4'!F9 -> 0 | G8: ='[1]Table-4'!G9 -> 0 | H8: ='[1]Table-4'!H9 -> 0 | I8: ='[1]Table-4'!I9 -> 0 | ... M8: ='[1]Table-4'!M9 -> 0
A9: 101 to 200 | B9: ='[1]Table-4'!B10 -> 0 | C9: ='[1]Table-4'!C10 -> 0 | D9: ='[1]Table-4'!D10 -> 0 | E9: ='[1]Table-4'!E10 -> 0 | F9: ='[1]Table-4'!F10 -> 0 | G9: ='[1]Table-4'!G10 -> 0 | H9: ='[1]Table-4'!H10 -> 0 | I9: ='[1]Table-4'!I10 -> 0 | ... M9: ='[1]Table-4'!M10 -> 0
A10: 201 to 400 | B10: ='[1]Table-4'!B11 -> 0 | C10: ='[1]Table-4'!C11 -> 0 | D10: ='[1]Table-4'!D11 -> 0 | E10: ='[1]Table-4'!E11 -> 0 | F10: ='[1]Table-4'!F11 -> 0 | G10: ='[1]Table-4'!G11 -> 0 | H10: ='[1]Table-4'!H11 -> 0 | I10: ='[1]Table-4'!I11 -> 0 | ... M10: ='[1]Table-4'!M11 -> 0
A11: 401 to 600 | B11: ='[1]Table-4'!B12 -> 0 | C11: ='[1]Table-4'!C12 -> 0 | D11: ='[1]Table-4'!D12 -> 1 | E11: ='[1]Table-4'!E12 -> 0 | F11: ='[1]Table-4'!F12 -> 0 | G11: ='[1]Table-4'!G12 -> 0 | H11: ='[1]Table-4'!H12 -> 0 | I11: ='[1]Table-4'!I12 -> 0 | ... M11: ='[1]Table-4'!M12 -> 11.11
A12: 601 to 800 | B12: ='[1]Table-4'!B13 -> 0 | C12: ='[1]Table-4'!C13 -> 0 | D12: ='[1]Table-4'!D13 -> 0 | E12: ='[1]Table-4'!E13 -> 0 | F12: ='[1]Table-4'!F13 -> 0 | G12: ='[1]Table-4'!G13 -> 0 | H12: ='[1]Table-4'!H13 -> 0 | I12: ='[1]Table-4'!I13 -> 0 | ... M12: ='[1]Table-4'!M13 -> 0
A13: 801 to 1000 | B13: ='[1]Table-4'!B14 -> 0 | C13: ='[1]Table-4'!C14 -> 0 | D13: ='[1]Table-4'!D14 -> 0 | E13: ='[1]Table-4'!E14 -> 1 | F13: ='[1]Table-4'!F14 -> 0 | G13: ='[1]Table-4'!G14 -> 1 | H13: ='[1]Table-4'!H14 -> 0 | I13: ='[1]Table-4'!I14 -> 0 | ... M13: ='[1]Table-4'!M14 -> 22.22
A14: 1001 to 5000 | B14: ='[1]Table-4'!B15 -> 0 | C14: ='[1]Table-4'!C15 -> 0 | D14: ='[1]Table-4'!D15 -> 0 | E14: ='[1]Table-4'!E15 -> 2 | F14: ='[1]Table-4'!F15 -> 4 | G14: ='[1]Table-4'!G15 -> 0 | H14: ='[1]Table-4'!H15 -> 0 | I14: ='[1]Table-4'!I15 -> 0 | ... M14: ='[1]Table-4'!M15 -> 66.67
A15: ABOVE 5000 | B15: ='[1]Table-4'!B16 -> 0 | C15: ='[1]Table-4'!C16 -> 0 | D15: ='[1]Table-4'!D16 -> 0 | E15: ='[1]Table-4'!E16 -> 0 | F15: ='[1]Table-4'!F16 -> 0 | G15: ='[1]Table-4'!G16 -> 0 | H15: ='[1]Table-4'!H16 -> 0 | I15: ='[1]Table-4'!I16 -> 0 | ... M15: ='[1]Table-4'!M16 -> 0
A16: INFORMATION NOT REPORTED | B16: ='[1]Table-4'!B17 -> 0 | C16: ='[1]Table-4'!C17 -> 0 | D16: ='[1]Table-4'!D17 -> 0 | E16: ='[1]Table-4'!E17 -> 0 | F16: ='[1]Table-4'!F17 -> 0 | G16: ='[1]Table-4'!G17 -> 0 | H16: ='[1]Table-4'!H17 -> 0 | I16: ='[1]Table-4'!I17 -> 0 | ... M16: ='[1]Table-4'!M17 -> 0
A17: TOTAL | B17: ='[1]Table-4'!B18 -> 0 | C17: ='[1]Table-4'!C18 -> 0 | D17: ='[1]Table-4'!D18 -> 1 | E17: ='[1]Table-4'!E18 -> 3 | F17: ='[1]Table-4'!F18 -> 4 | G17: ='[1]Table-4'!G18 -> 1 | H17: ='[1]Table-4'!H18 -> 0 | I17: ='[1]Table-4'!I18 -> 0 | ... M17: ='[1]Table-4'!M18 -> 100
A18: %AGE | B18: ='[1]Table-4'!B19 -> 0 | C18: ='[1]Table-4'!C19 -> 0 | D18: ='[1]Table-4'!D19 -> 11.11 | E18: ='[1]Table-4'!E19 -> 33.34 | F18: ='[1]Table-4'!F19 -> 44.44 | G18: ='[1]Table-4'!G19 -> 11.11 | H18: ='[1]Table-4'!H19 -> 0 | I18: ='[1]Table-4'!I19 -> 0 | ... L18: ='[1]Table-4'!L19 -> 100
A19: NOTE: (i) THIS TABLE WILL BE PREPARED ONLY FOR THE FIRST SEASON OF THE YEAR
A20: (ii) THE PERCENTAGE OF COL.2 TO COL.12 IN THE LAST ROW AND THE PERCENTAGE OF ALL ROWS IN COL.13 WILL BE CALCULATED AS PER THE TOTAL OF COL.12
A22: Developed by: Deepak Kumar Agrawal, Senior Statistical Officer, NSSO (FOD), Faridabad, Haryana
A24: TABLE A-4:BIVARIATE FREQUENCY DISTRIBUTION OF SELECTED VILLAGE ACCORDING TO TOTAL NUMBER OR SERIAL/SURVEY NUMBERS AND GEOGRAPHICAL AREA
A26: =A4 -> STATE:PUDUCHERRY(34) | E26: YEAR: | F26: ='[1]Table-4'!T5 -> 2023-24 | H26: SEASON: | I26: ='[1]Table-4'!W5 -> RABI I(4) | L26: ='RC1-A3'!F112 -> SAMPLE:STATE(2)
A27: CLASS INTERVAL OF SERIAL/ SURVEY (CODE) | B27: CLASS INTERVAL OF GEOGRAPHICAL AREA(HA)
B28: UP TO 50 | C28: 51 TO 100 | D28: 101 TO 200 | E28: 201 TO 400 | F28: 401 TO 600 | G28: 601 TO 800 | H28: 801 TO 1000 | I28: 1001 TO 3000 | J28: ABOVE TO 3001 | K28: NOT REPORTED | L28: TOTAL | M28: %AGE
A29: UPTO 50 | B29: ='[1]Table-4'!P8 -> 0 | C29: ='[1]Table-4'!Q8 -> 0 | D29: ='[1]Table-4'!R8 -> 0 | E29: ='[1]Table-4'!S8 -> 0 | F29: ='[1]Table-4'!T8 -> 0 | G29: ='[1]Table-4'!U8 -> 0 | H29: ='[1]Table-4'!V8 -> 0 | I29: ='[1]Table-4'!W8 -> 0 | ... M29: ='[1]Table-4'!AA8 -> 0
A30: 51 to 100 | B30: ='[1]Table-4'!P9 -> 0 | C30: ='[1]Table-4'!Q9 -> 0 | D30: ='[1]Table-4'!R9 -> 0 | E30: ='[1]Table-4'!S9 -> 0 | F30: ='[1]Table-4'!T9 -> 0 | G30: ='[1]Table-4'!U9 -> 0 | H30: ='[1]Table-4'!V9 -> 0 | I30: ='[1]Table-4'!W9 -> 0 | ... M30: ='[1]Table-4'!AA9 -> 0
A31: 101 to 200 | B31: ='[1]Table-4'!P10 -> 0 | C31: ='[1]Table-4'!Q10 -> 0 | D31: ='[1]Table-4'!R10 -> 0 | E31: ='[1]Table-4'!S10 -> 0 | F31: ='[1]Table-4'!T10 -> 0 | G31: ='[1]Table-4'!U10 -> 0 | H31: ='[1]Table-4'!V10 -> 0 | I31: ='[1]Table-4'!W10 -> 0 | ... M31: ='[1]Table-4'!AA10 -> 0
A32: 201 to 400 | B32: ='[1]Table-4'!P11 -> 0 | C32: ='[1]Table-4'!Q11 -> 0 | D32: ='[1]Table-4'!R11 -> 0 | E32: ='[1]Table-4'!S11 -> 0 | F32: ='[1]Table-4'!T11 -> 0 | G32: ='[1]Table-4'!U11 -> 0 | H32: ='[1]Table-4'!V11 -> 0 | I32: ='[1]Table-4'!W11 -> 0 | ... M32: ='[1]Table-4'!AA11 -> 0
A33: 401 to 600 | B33: ='[1]Table-4'!P12 -> 0 | C33: ='[1]Table-4'!Q12 -> 0 | D33: ='[1]Table-4'!R12 -> 0 | E33: ='[1]Table-4'!S12 -> 1 | F33: ='[1]Table-4'!T12 -> 0 | G33: ='[1]Table-4'!U12 -> 0 | H33: ='[1]Table-4'!V12 -> 0 | I33: ='[1]Table-4'!W12 -> 0 | ... M33: ='[1]Table-4'!AA12 -> 11.11
A34: 601 to 800 | B34: ='[1]Table-4'!P13 -> 0 | C34: ='[1]Table-4'!Q13 -> 0 | D34: ='[1]Table-4'!R13 -> 0 | E34: ='[1]Table-4'!S13 -> 0 | F34: ='[1]Table-4'!T13 -> 0 | G34: ='[1]Table-4'!U13 -> 0 | H34: ='[1]Table-4'!V13 -> 0 | I34: ='[1]Table-4'!W13 -> 0 | ... M34: ='[1]Table-4'!AA13 -> 0
A35: 801 to 1000 | B35: ='[1]Table-4'!P14 -> 0 | C35: ='[1]Table-4'!Q14 -> 0 | D35: ='[1]Table-4'!R14 -> 0 | E35: ='[1]Table-4'!S14 -> 2 | F35: ='[1]Table-4'!T14 -> 0 | G35: ='[1]Table-4'!U14 -> 0 | H35: ='[1]Table-4'!V14 -> 0 | I35: ='[1]Table-4'!W14 -> 0 | ... M35: ='[1]Table-4'!AA14 -> 22.22
A36: 1001 to 5000 | B36: ='[1]Table-4'!P15 -> 0 | C36: ='[1]Table-4'!Q15 -> 0 | D36: ='[1]Table-4'!R15 -> 1 | E36: ='[1]Table-4'!S15 -> 2 | F36: ='[1]Table-4'!T15 -> 2 | G36: ='[1]Table-4'!U15 -> 0 | H36: ='[1]Table-4'!V15 -> 1 | I36: ='[1]Table-4'!W15 -> 0 | ... M36: ='[1]Table-4'!AA15 -> 66.67
A37: ABOVE 5000 | B37: ='[1]Table-4'!P16 -> 0 | C37: ='[1]Table-4'!Q16 -> 0 | D37: ='[1]Table-4'!R16 -> 0 | E37: ='[1]Table-4'!S16 -> 0 | F37: ='[1]Table-4'!T16 -> 0 | G37: ='[1]Table-4'!U16 -> 0 | H37: ='[1]Table-4'!V16 -> 0 | I37: ='[1]Table-4'!W16 -> 0 | ... M37: ='[1]Table-4'!AA16 -> 0
A38: INFORMATION NOT REPORTED | B38: ='[1]Table-4'!P17 -> 0 | C38: ='[1]Table-4'!Q17 -> 0 | D38: ='[1]Table-4'!R17 -> 0 | E38: ='[1]Table-4'!S17 -> 0 | F38: ='[1]Table-4'!T17 -> 0 | G38: ='[1]Table-4'!U17 -> 0 | H38: ='[1]Table-4'!V17 -> 0 | I38: ='[1]Table-4'!W17 -> 0 | ... M38: ='[1]Table-4'!AA17 -> 0
A39: TOTAL | B39: ='[1]Table-4'!P18 -> 0 | C39: ='[1]Table-4'!Q18 -> 0 | D39: ='[1]Table-4'!R18 -> 1 | E39: ='[1]Table-4'!S18 -> 5 | F39: ='[1]Table-4'!T18 -> 2 | G39: ='[1]Table-4'!U18 -> 0 | H39: ='[1]Table-4'!V18 -> 1 | I39: ='[1]Table-4'!W18 -> 0 | ... M39: ='[1]Table-4'!AA18 -> 100
A40: %AGE | B40: ='[1]Table-4'!P19 -> 0 | C40: ='[1]Table-4'!Q19 -> 0 | D40: ='[1]Table-4'!R19 -> 11.11 | E40: ='[1]Table-4'!S19 -> 55.56 | F40: ='[1]Table-4'!T19 -> 22.22 | G40: ='[1]Table-4'!U19 -> 0 | H40: ='[1]Table-4'!V19 -> 11.11 | I40: ='[1]Table-4'!W19 -> 0 | ... L40: ='[1]Table-4'!Z19 -> 100
A41: NOTE: (i) THIS TABLE WILL BE PREPARED ONLY FOR THE FIRST SEASON OF THE YEAR
A42: (ii) THE PERCENTAGE OF COL.2 TO COL.12 IN THE LAST ROW AND THE PERCENTAGE OF ALL ROWS IN COL.13 WILL BE CALCULATED AS PER THE TOTAL OF COL.12
A44: Developed by: Deepak Kumar Agrawal, Senior Statistical Officer, NSSO (FOD), Faridabad, Haryana

Sheet RC1-A5
L1: T-3
A2: TABLE A-5: DISTRICT-WISE DISTRIBUTION OF SELECTED VILLAGES ACCORDING TO COMPLETION OR OTHERWISE OF GIRDAWARI BY PATWARI AS PER THE PRESCRIBED TIME SCHEDULE.
A3: ='RC1-A3'!A3 -> STATE:PUDUCHERRY(34) | H3: YEAR: | I3: ='[1]Table-5'!H3 -> 2023-24 | M3: SEASON: | O3: ='[1]Table-5'!N3 -> RABI I(4)
A4: DISTRICT | B4: DISTRICT NAME | C4: NO. OF VILLAGE ANALYSED | D4: NUMBER OF VILLAGES WHERE GIRDAWARI HAS BEEN | M4: NO. OF VILLAGES IN WHICH | O4: NO. OF VILLAGES IN WHICH GIRDAWARI NOT YET STARTED DUE TO REASON (CODE)* | T4: TOTAL (COL. 6 +11+ 18) | U4: NO. OF VILLAGES FOR WHICH
D5: COMPLETED | H5: PARTIALLY COMPLETED DUE TO REASON (CODE)@ | U5: SYSTEM OF GIRDAWARI DOES NOT EXIST | V5: INFORMATION ABOUT COMPLETION OF GIRDAWARI NOT AVAILABLE
D6: IN TIME | E6: LATE | F6: BUT DATE OF COMPLETION IS NOT KNOWN | G6: SUB TOTAL (COL. 3+4+5) | H6: 1 | I6: 2 | J6: 3 | K6: 4 | L6: SUB TOTAL (COL. 7 + 8+9+ 10) | M6: LATEST FORM FOR GIRDAWARI USED | N6: RECORD OF GIRDAWARI KEPT IN REGULAR FORM | O6: 1 | P6: 2 | Q6: 3 | R6: 4 | S6: SUB TOTAL (COL. 14 + 15+ 16+ 17)
A7: 1 | B7: 2 | C7: 3 | D7: 4 | E7: 5 | F7: 6 | G7: 7 | H7: 8 | I7: 9 | J7: 10 | K7: 11 | L7: 12 | M7: 13 | N7: 14 | O7: 15 | P7: 16 | Q7: 17 | R7: 18 | S7: 19 | T7: 20 | U7: 21 | V7: 22
A8: ='[1]Table-5'!A8 | C8: ='[1]Table-5'!B8 | D8: ='[1]Table-5'!C8 | E8: ='[1]Table-5'!D8 | F8: ='[1]Table-5'!E8 | G8: ='[1]Table-5'!F8 | H8: ='[1]Table-5'!G8 | I8: ='[1]Table-5'!H8 | J8: ='[1]Table-5'!I8 | ... T8: ='[1]Table-5'!S8 | U8: ='RC1-A3'!F8 -> SAMPLE:CENTRAL(1)
A9: ='[1]Table-5'!A9 -> 2 | B9: Puducherry | C9: ='[1]Table-5'!B9 -> 6 | D9: ='[1]Table-5'!C9 -> 6 | E9: ='[1]Table-5'!D9 -> 0 | F9: ='[1]Table-5'!E9 -> 0 | G9: ='[1]Table-5'!F9 -> 6 | H9: ='[1]Table-5'!G9 -> 0 | I9: ='[1]Table-5'!H9 -> 0 | J9: ='[1]Table-5'!I9 -> 0 | ... V9: ='[1]Table-5'!U9 -> 0
A10: ='[1]Table-5'!A10 | C10: ='[1]Table-5'!B10 | D10: ='[1]Table-5'!C10 | E10: ='[1]Table-5'!D10 | F10: ='[1]Table-5'!E10 | G10: ='[1]Table-5'!F10 | H10: ='[1]Table-5'!G10 | I10: ='[1]Table-5'!H10 | J10: ='[1]Table-5'!I10 | ... V10: ='[1]Table-5'!U10
A11: ='[1]Table-5'!A11 -> 4 | B11: Karaikal | C11: ='[1]Table-5'!B11 -> 3 | D11: ='[1]Table-5'!C11 -> 3 | E11: ='[1]Table-5'!D11 -> 0 | F11: ='[1]Table-5'!E11 -> 0 | G11: ='[1]Table-5'!F11 -> 3 | H11: ='[1]Table-5'!G11 -> 0 | I11: ='[1]Table-5'!H11 -> 0 | J11: ='[1]Table-5'!I11 -> 0 | ... V11: ='[1]Table-5'!U11 -> 0
A12: ='[1]Table-5'!A12 | C12: ='[1]Table-5'!B12 | D12: ='[1]Table-5'!C12 | E12: ='[1]Table-5'!D12 | F12: ='[1]Table-5'!E12 | G12: ='[1]Table-5'!F12 | H12: ='[1]Table-5'!G12 | I12: ='[1]Table-5'!H12 | J12: ='[1]Table-5'!I12 | ... V12: ='[1]Table-5'!U12
A13: ='[1]Table-5'!A13 | C13: ='[1]Table-5'!B13 | D13: ='[1]Table-5'!C13 | E13: ='[1]Table-5'!D13 | F13: ='[1]Table-5'!E13 | G13: ='[1]Table-5'!F13 | H13: ='[1]Table-5'!G13 | I13: ='[1]Table-5'!H13 | J13: ='[1]Table-5'!I13 | ... V13: ='[1]Table-5'!U13
A14: ='[1]Table-5'!A14 | C14: ='[1]Table-5'!B14 | D14: ='[1]Table-5'!C14 | E14: ='[1]Table-5'!D14 | F14: ='[1]Table-5'!E14 | G14: ='[1]Table-5'!F14 | H14: ='[1]Table-5'!G14 | I14: ='[1]Table-5'!H14 | J14: ='[1]Table-5'!I14 | ... V14: ='[1]Table-5'!U14
A15: ='[1]Table-5'!A15 | C15: ='[1]Table-5'!B15 | D15: ='[1]Table-5'!C15 | E15: ='[1]Table-5'!D15 | F15: ='[1]Table-5'!E15 | G15: ='[1]Table-5'!F15 | H15: ='[1]Table-5'!G15 | I15: ='[1]Table-5'!H15 | J15: ='[1]Table-5'!I15 | ... V15: ='[1]Table-5'!U15
A16: ='[1]Table-5'!A16 | C16: ='[1]Table-5'!B16 | D16: ='[1]Table-5'!C16 | E16: ='[1]Table-5'!D16 | F16: ='[1]Table-5'!E16 | G16: ='[1]Table-5'!F16 | H16: ='[1]Table-5'!G16 | I16: ='[1]Table-5'!H16 | J16: ='[1]Table-5'!I16 | ... V16: ='[1]Table-5'!U16
A17: ='[1]Table-5'!A17 | C17: ='[1]Table-5'!B17 | D17: ='[1]Table-5'!C17 | E17: ='[1]Table-5'!D17 | F17: ='[1]Table-5'!E17 | G17: ='[1]Table-5'!F17 | H17: ='[1]Table-5'!G17 | I17: ='[1]Table-5'!H17 | J17: ='[1]Table-5'!I17 | ... V17: ='[1]Table-5'!U17
A18: ='[1]Table-5'!A18 | C18: ='[1]Table-5'!B18 | D18: ='[1]Table-5'!C18 | E18: ='[1]Table-5'!D18 | F18: ='[1]Table-5'!E18 | G18: ='[1]Table-5'!F18 | H18: ='[1]Table-5'!G18 | I18: ='[1]Table-5'!H18 | J18: ='[1]Table-5'!I18 | ... V18: ='[1]Table-5'!U18
A19: ='[1]Table-5'!A19 | C19: ='[1]Table-5'!B19 | D19: ='[1]Table-5'!C19 | E19: ='[1]Table-5'!D19 | F19: ='[1]Table-5'!E19 | G19: ='[1]Table-5'!F19 | H19: ='[1]Table-5'!G19 | I19: ='[1]Table-5'!H19 | J19: ='[1]Table-5'!I19 | ... V19: ='[1]Table-5'!U19
A20: ='[1]Table-5'!A20 | C20: ='[1]Table-5'!B20 | D20: ='[1]Table-5'!C20 | E20: ='[1]Table-5'!D20 | F20: ='[1]Table-5'!E20 | G20: ='[1]Table-5'!F20 | H20: ='[1]Table-5'!G20 | I20: ='[1]Table-5'!H20 | J20: ='[1]Table-5'!I20 | ... V20: ='[1]Table-5'!U20
A21: ='[1]Table-5'!A21 | C21: ='[1]Table-5'!B21 | D21: ='[1]Table-5'!C21 | E21: ='[1]Table-5'!D21 | F21: ='[1]Table-5'!E21 | G21: ='[1]Table-5'!F21 | H21: ='[1]Table-5'!G21 | I21: ='[1]Table-5'!H21 | J21: ='[1]Table-5'!I21 | ... V21: ='[1]Table-5'!U21
A22: ='[1]Table-5'!A22 | C22: ='[1]Table-5'!B22 | D22: ='[1]Table-5'!C22 | E22: ='[1]Table-5'!D22 | F22: ='[1]Table-5'!E22 | G22: ='[1]Table-5'!F22 | H22: ='[1]Table-5'!G22 | I22: ='[1]Table-5'!H22 | J22: ='[1]Table-5'!I22 | ... V22: ='[1]Table-5'!U22
A23: ='[1]Table-5'!A23 | C23: ='[1]Table-5'!B23 | D23: ='[1]Table-5'!C23 | E23: ='[1]Table-5'!D23 | F23: ='[1]Table-5'!E23 | G23: ='[1]Table-5'!F23 | H23: ='[1]Table-5'!G23 | I23: ='[1]Table-5'!H23 | J23: ='[1]Table-5'!I23 | ... V23: ='[1]Table-5'!U23
... A100: ='[1]Table-5'!A100 -> TOTAL: | C100: ='[1]Table-5'!B100 -> 9 | D100: ='[1]Table-5'!C100 -> 9 | E100: ='[1]Table-5'!D100 -> 0 | F100: ='[1]Table-5'!E100 -> 0 | G100: ='[1]Table-5'!F100 -> 9 | H100: ='[1]Table-5'!G100 -> 0 | I100: ='[1]Table-5'!H100 -> 0 | J100: ='[1]Table-5'!I100 -> 0 | ... V100: ='[1]Table-5'!U100 -> 0
A101: %AGE TO COL.(19) | D101: ='[1]Table-5'!C101 -> 100 | E101: ='[1]Table-5'!D101 -> 0 | F101: ='[1]Table-5'!E101 -> 0 | G101: ='[1]Table-5'!F101 -> 100 | H101: ='[1]Table-5'!G101 -> 0 | I101: ='[1]Table-5'!H101 -> 0 | J101: ='[1]Table-5'!I101 -> 0 | K101: ='[1]Table-5'!J101 -> 0 | ... V101: ='[1]Table-5'!U101 -> 0
A102: % TO COL. 12 AND COL. 13 OR WITH RESPECT TO (COL. 6 + COL. 11) | M102: ='[1]Table-5'!L102 -> 100 | N102: ='[1]Table-5'!M102 -> 100
A103: NOTE: (I) COL.2= COL.19+COL.20+COL.21 (II) COL.2 OF TABLE A-2 SHOULD TALLY WITH COL.2 OF TABLE A-5
A104: REASON CODE: OCCUPIED WITH OTHER WORK = 1, TRS PROGRAMME WAS NOT INITIATED IN TIME= 2, OTHER REASON =3, REASON NOT AVAILABLE=4
A105: (THESE CODES CORRESPONDS TO PRE-TABULATION CODING I.E. 4,5,6, AND 7 FOR THE ITEM 10(D) OF SCH. AS 1.0)
A106: Developed by: Deepak Kumar Agrawal, Senior Statistical Officer, NSSO (FOD), Faridabad, Haryana
A108: TABLE A-5: DISTRICT-WISE DISTRIBUTION OF SELECTED VILLAGES ACCORDING TO COMPLETION OR OTHERWISE OF GIRDAWARI BY PATWARI AS PER THE PRESCRIBED TIME SCHEDULE.
A109: =A3 -> STATE:PUDUCHERRY(34) | H109: YEAR: | I109: ='[1]Table-5'!AD3 -> 2023-24 | M109: SEASON: | O109: ='[1]Table-5'!AJ3 -> RABI I(4)
A110: DISTRICT | B110: DISTRICT NAME | C110: NO. OF VILLAGE ANALYSED | D110: NUMBER OF VILLAGES WHERE GIRDAWARI HAS BEEN | M110: NO. OF VILLAGES IN WHICH | O110: NO. OF VILLAGES IN WHICH GIRDAWARI NOT YET STARTED DUE TO REASON (CODE)* | T110: TOTAL (COL. 6 +11+ 18) | U110: NO. OF VILLAGES FOR WHICH
D111: COMPLETED | H111: PARTIALLY COMPLETED DUE TO REASON (CODE)@ | U111: SYSTEM OF GIRDAWARI DOES NOT EXIST | V111: INFORMATION ABOUT COMPLETION OF GIRDAWARI NOT AVAILABLE
D112: IN TIME | E112: LATE | F112: BUT DATE OF COMPLETION IS NOT KNOWN | G112: SUB TOTAL (COL. 3+4+5) | H112: 1 | I112: 2 | J112: 3 | K112: 4 | L112: SUB TOTAL (COL. 7 + 8+9+ 10) | M112: LATEST FORM FOR GIRDAWARI USED | N112: RECORD OF GIRDAWARI KEPT IN REGULAR FORM | O112: 1 | P112: 2 | Q112: 3 | R112: 4 | S112: SUB TOTAL (COL. 14 + 15+ 16+ 17)
A113: 1 | B113: 2 | C113: 3 | D113: 4 | E113: 5 | F113: 6 | G113: 7 | H113: 8 | I113: 9 | J113: 10 | K113: 11 | L113: 12 | M113: 13 | N113: 14 | O113: 15 | P113: 16 | Q113: 17 | R113: 18 | S113: 19 | T113: 20 | U113: 21 | V113: 22
A114: ='[1]Table-5'!W8 | C114: ='[1]Table-5'!X8 | D114: ='[1]Table-5'!Y8 | E114: ='[1]Table-5'!Z8 | F114: ='[1]Table-5'!AA8 | G114: ='[1]Table-5'!AB8 | H114: ='[1]Table-5'!AC8 | I114: ='[1]Table-5'!AD8 | J114: ='[1]Table-5'!AE8 | ... T114: ='[1]Table-5'!AO8 | U114: ='RC1-A3'!F112 -> SAMPLE:STATE(2)
A115: ='[1]Table-5'!W9 -> 2 | B115: Puducherry | C115: ='[1]Table-5'!X9 -> 6 | D115: ='[1]Table-5'!Y9 -> 6 | E115: ='[1]Table-5'!Z9 -> 0 | F115: ='[1]Table-5'!AA9 -> 0 | G115: ='[1]Table-5'!AB9 -> 6 | H115: ='[1]Table-5'!AC9 -> 0 | I115: ='[1]Table-5'!AD9 -> 0 | J115: ='[1]Table-5'!AE9 -> 0 | ... V115: ='[1]Table-5'!AQ9 -> 0
A116: ='[1]Table-5'!W10 | C116: ='[1]Table-5'!X10 | D116: ='[1]Table-5'!Y10 | E116: ='[1]Table-5'!Z10 | F116: ='[1]Table-5'!AA10 | G116: ='[1]Table-5'!AB10 | H116: ='[1]Table-5'!AC10 | I116: ='[1]Table-5'!AD10 | J116: ='[1]Table-5'!AE10 | ... V116: ='[1]Table-5'!AQ10
A117: ='[1]Table-5'!W11 -> 4 | B117: Karaikal | C117: ='[1]Table-5'!X11 -> 3 | D117: ='[1]Table-5'!Y11 -> 3 | E117: ='[1]Table-5'!Z11 -> 0 | F117: ='[1]Table-5'!AA11 -> 0 | G117: ='[1]Table-5'!AB11 -> 3 | H117: ='[1]Table-5'!AC11 -> 0 | I117: ='[1]Table-5'!AD11 -> 0 | J117: ='[1]Table-5'!AE11 -> 0 | ... V117: ='[1]Table-5'!AQ11 -> 0
...

Sheet RC1-A6
A2: TABLE-A6: FREQUENCY DISTRIBUTION OF PATWARI OF THE SELECTED VILLAGE ACCORDING TO THE TOTAL NUMBER OF VILLAGES ALLOTED
A4: ='[1]Table-6'!A4 -> STATE: PUDUCHERRY(34) | C4: ='[1]Table-6'!C4 -> YEAR: 2023-24 | D4: ='[1]Table-6'!D4 -> SEASON: RABI I(4) | E4: ='RC1-A5'!U8 -> SAMPLE:CENTRAL(1)
A5: TOTAL | D5: TRS
A6: TOTAL NO OF VILLAGES ALLOTED FOR PATWARI | B6: FREQUENCY | C6: PERCENTAGE (0.0) | D6: TOTAL NO OF VILLAGES ALLOTED FOR PATWARI | E6: FREQUENCY | F6: PERCENTAGE (0.0)
A7: 1 | B7: 2 | C7: 3 | D7: 4 | E7: 5 | F7: 6
A8: 1 TO 5 | B8: ='[1]Table-6'!B8 -> 0 | C8: ='[1]Table-6'!C8 -> 0 | D8: 1 | E8: ='[1]Table-6'!E8 -> 0 | F8: ='[1]Table-6'!F8 -> 0
A9: 6 TO 10 | B9: ='[1]Table-6'!B9 -> 6 | C9: ='[1]Table-6'!C9 -> 66.67 | D9: 2 | E9: ='[1]Table-6'!E9 -> 9 | F9: ='[1]Table-6'!F9 -> 100
A10: 11 TO 15 | B10: ='[1]Table-6'!B10 -> 3 | C10: ='[1]Table-6'!C10 -> 33.33 | D10: 3 | E10: ='[1]Table-6'!E10 -> 0 | F10: ='[1]Table-6'!F10 -> 0
A11: ABOVE 15 | B11: ='[1]Table-6'!B11 -> 0 | C11: ='[1]Table-6'!C11 -> 0 | D11: GREATER THAN 3 | E11: ='[1]Table-6'!E11 -> 0 | F11: ='[1]Table-6'!F11 -> 0
A12: NOT REPORTED | B12: ='[1]Table-6'!B12 -> 0 | C12: ='[1]Table-6'!C12 -> 0 | D12: NO TRS / NOT IMPLEMENTED | E12: ='[1]Table-6'!E12 -> 0 | F12: ='[1]Table-6'!F12 -> 0
D13: NOT AVAILABLE | E13: ='[1]Table-6'!E13 -> 0 | F13: ='[1]Table-6'!F13 -> 0
A14: TOTAL | B14: ='[1]Table-6'!B14 -> 9 | C14: ='[1]Table-6'!C14 -> 100 | D14: TOTAL | E14: ='[1]Table-6'!E14 -> 9 | F14: ='[1]Table-6'!F14 -> 100
A21: TABLE-A6: FREQUENCY DISTRIBUTION OF PATWARI OF THE SELECTED VILLAGE ACCORDING TO THE TOTAL NUMBER OF VILLAGES ALLOTED
A23: ='[1]Table-6'!A23 -> STATE: PUDUCHERRY(34) | C23: ='[1]Table-6'!C23 -> YEAR: 2023-24 | D23: ='[1]Table-6'!D23 -> SEASON: RABI I(4) | E23: ='RC1-A5'!U114 -> SAMPLE:STATE(2)
A24: TOTAL | D24: TRS
A25: TOTAL NO OF VILLAGES ALLOTED FOR PATWARI | B25: FREQUENCY | C25: PERCENTAGE (0.0) | D25: TOTAL NO OF VILLAGES ALLOTED FOR PATWARI | E25: FREQUENCY | F25: PERCENTAGE (0.0)
A26: 1 | B26: 2 | C26: 3 | D26: 4 | E26: 5 | F26: 6
A27: 1 TO 5 | B27: ='[1]Table-6'!B27 -> 0 | C27: ='[1]Table-6'!C27 -> 0 | D27: 1 | E27: ='[1]Table-6'!E27 -> 4 | F27: ='[1]Table-6'!F27 -> 44.44
A28: 6 TO 10 | B28: ='[1]Table-6'!B28 -> 6 | C28: ='[1]Table-6'!C28 -> 66.67 | D28: 2 | E28: ='[1]Table-6'!E28 -> 5 | F28: ='[1]Table-6'!F28 -> 55.56
A29: 11 TO 15 | B29: ='[1]Table-6'!B29 -> 3 | C29: ='[1]Table-6'!C29 -> 33.33 | D29: 3 | E29: ='[1]Table-6'!E29 -> 0 | F29: ='[1]Table-6'!F29 -> 0
A30: ABOVE 15 | B30: ='[1]Table-6'!B30 -> 0 | C30: ='[1]Table-6'!C30 -> 0 | D30: GREATER THEN 3 | E30: ='[1]Table-6'!E30 -> 0 | F30: ='[1]Table-6'!F30 -> 0
A31: NOT REPORTED | B31: ='[1]Table-6'!B31 -> 0 | C31: ='[1]Table-6'!C31 -> 0 | D31: NO TRS / NOT IMPLEMENTED | E31: ='[1]Table-6'!E31 -> 0 | F31: ='[1]Table-6'!F31 -> 0
D32: NOT AVAILABLE | E32: ='[1]Table-6'!E32 -> 0 | F32: ='[1]Table-6'!F32 -> 0
A33: TOTAL | B33: ='[1]Table-6'!B33 -> 9 | C33: ='[1]Table-6'!C33 -> 100 | D33: TOTAL | E33: ='[1]Table-6'!E33 -> 9 | F33: ='[1]Table-6'!F33 -> 100
A34: NOTE: (I) THIS TABLE IS TO BE PREPARED ONLY FOR THE FIRST SEASON OF THE YEAR
A35: (II) COL. 4,5,6 ARE NOT APPLICABLE FOR EARAS STATE (I.E ORRISA, WEST BENGAL AND KERALA STATE)
A36: Developed by: Deepak Kumar Agrawal, Senior Statistical Officer, NSSO (FOD), Faridabad, Haryana

Sheet RC1-A7
K1: T-5
A2: TABLE A-7: DISTRICT-WISE DISTRIBUTION OF SELECTED VILLAGES ACCORDING TO THE SUBMISSION OF TRS STATEMENT.
A3: ='RC1-A6'!A4 -> STATE: PUDUCHERRY(34) | H3: YEAR: | I3: ='[1]Table-7'!H2 -> 2023-24 | M3: SEASON: | O3: ='[1]Table-7'!N2 -> RABI I(4)
A4: DISTRICT | B4: DISTRICT NAME | C4: NO. OF VILLAGES ANALYSED | D4: NUMBER OF VILLAGES FOR WHICH
D5: TRS STATEMENT SUBMITTED | N5: OUT OF COL. 12 | P5: TRS STATEMENT NOT SUBMITTED | T5: INFORMATION ABOUT SUBMISSION OR TRS STATEMENT NOT AVAILABLE | U5: TRS STATEMENT NOT TO BE SUBMITTED (A) BEING NON TRS VILLGES (B) AS PER STATE INSTRUCTION
D6: IN TIME | H6: LATE | L6: BUT DATE OF SUBMISSION NOT RECORDED | M6: TOTAL (COL. 6+ 10+ 11) | N6: TRS STATEMENT SUBMITTED IN STANDARD FORM | O6: DUPLICATE COPY OF STATEMENT KEPT | P6: THOUGH GIRDAWARI COMPLETED | R6: AS GIRDAWARI NOT COMPLETED | S6: SUB TOTAL (COL. 15+ 16 + 17)
D7: BEFORE GIRDAWARI | E7: AFTER GIRDAWARI | F7: BUT COULD NOT COMPARED WITH GIRDAWARI COMPLETION | G7: SUB TOTAL (COL. 3+ 4 +5) | H7: BEFORE GIRDAWARI | I7: AFTER GIRDAWARI | J7: BUT COULD NOT COMPARED WITH GIRDAWARI COMPLETION | K7: SUB TOTAL (COL.7 +8+9) | P7: AS DUE DATE NOT OVER | Q7: OTHER REASONS
A8: 1 | B8: 2 | C8: 3 | D8: 4 | E8: 5 | F8: 6 | G8: 7 | H8: 8 | I8: 9 | J8: 10 | K8: 11 | L8: 12 | M8: 13 | N8: 14 | O8: 15 | P8: 16 | Q8: 17 | R8: 18 | S8: 19 | T8: 20 | U8: 21
A9: ='[1]Table-7'!A8 | C9: ='[1]Table-7'!B8 | D9: ='[1]Table-7'!C8 | E9: ='[1]Table-7'!D8 | F9: ='[1]Table-7'!E8 | G9: ='[1]Table-7'!F8 | H9: ='[1]Table-7'!G8 | I9: ='[1]Table-7'!H8 | J9: ='[1]Table-7'!I8 | ... Q9: ='[1]Table-7'!P8 | R9: ='RC1-A6'!E4 -> SAMPLE:CENTRAL(1)
A10: ='[1]Table-7'!A9 -> 2 | B10: Puducherry | C10: ='[1]Table-7'!B9 -> 6 | D10: ='[1]Table-7'!C9 -> 0 | E10: ='[1]Table-7'!D9 -> 6 | F10: ='[1]Table-7'!E9 -> 0 | G10: ='[1]Table-7'!F9 -> 6 | H10: ='[1]Table-7'!G9 -> 0 | I10: ='[1]Table-7'!H9 -> 0 | J10: ='[1]Table-7'!I9 -> 0 | ... U10: ='[1]Table-7'!T9 -> 0
A11: ='[1]Table-7'!A10 | C11: ='[1]Table-7'!B10 | D11: ='[1]Table-7'!C10 | E11: ='[1]Table-7'!D10 | F11: ='[1]Table-7'!E10 | G11: ='[1]Table-7'!F10 | H11: ='[1]Table-7'!G10 | I11: ='[1]Table-7'!H10 | J11: ='[1]Table-7'!I10 | ... U11: ='[1]Table-7'!T10
A12: ='[1]Table-7'!A11 -> 4 | B12: Karaikal | C12: ='[1]Table-7'!B11 -> 3 | D12: ='[1]Table-7'!C11 -> 0 | E12: ='[1]Table-7'!D11 -> 3 | F12: ='[1]Table-7'!E11 -> 0 | G12: ='[1]Table-7'!F11 -> 3 | H12: ='[1]Table-7'!G11 -> 0 | I12: ='[1]Table-7'!H11 -> 0 | J12: ='[1]Table-7'!I11 -> 0 | ... U12: ='[1]Table-7'!T11 -> 0
A13: ='[1]Table-7'!A12 | C13: ='[1]Table-7'!B12 | D13: ='[1]Table-7'!C12 | E13: ='[1]Table-7'!D12 | F13: ='[1]Table-7'!E12 | G13: ='[1]Table-7'!F12 | H13: ='[1]Table-7'!G12 | I13: ='[1]Table-7'!H12 | J13: ='[1]Table-7'!I12 | ... U13: ='[1]Table-7'!T12
A14: ='[1]Table-7'!A13 | C14: ='[1]Table-7'!B13 | D14: ='[1]Table-7'!C13 | E14: ='[1]Table-7'!D13 | F14: ='[1]Table-7'!E13 | G14: ='[1]Table-7'!F13 | H14: ='[1]Table-7'!G13 | I14: ='[1]Table-7'!H13 | J14: ='[1]Table-7'!I13 | ... U14: ='[1]Table-7'!T13
A15: ='[1]Table-7'!A14 | C15: ='[1]Table-7'!B14 | D15: ='[1]Table-7'!C14 | E15: ='[1]Table-7'!D14 | F15: ='[1]Table-7'!E14 | G15: ='[1]Table-7'!F14 | H15: ='[1]Table-7'!G14 | I15: ='[1]Table-7'!H14 | J15: ='[1]Table-7'!I14 | ... U15: ='[1]Table-7'!T14
A16: ='[1]Table-7'!A15 | C16: ='[1]Table-7'!B15 | D16: ='[1]Table-7'!C15 | E16: ='[1]Table-7'!D15 | F16: ='[1]Table-7'!E15 | G16: ='[1]Table-7'!F15 | H16: ='[1]Table-7'!G15 | I16: ='[1]Table-7'!H15 | J16: ='[1]Table-7'!I15 | ... U16: ='[1]Table-7'!T15
A17: ='[1]Table-7'!A16 | C17: ='[1]Table-7'!B16 | D17: ='[1]Table-7'!C16 | E17: ='[1]Table-7'!D16 | F17: ='[1]Table-7'!E16 | G17: ='[1]Table-7'!F16 | H17: ='[1]Table-7'!G16 | I17: ='[1]Table-7'!H16 | J17: ='[1]Table-7'!I16 | ... U17: ='[1]Table-7'!T16
A18: ='[1]Table-7'!A17 | C18: ='[1]Table-7'!B17 | D18: ='[1]Table-7'!C17 | E18: ='[1]Table-7'!D17 | F18: ='[1]Table-7'!E17 | G18: ='[1]Table-7'!F17 | H18: ='[1]Table-7'!G17 | I18: ='[1]Table-7'!H17 | J18: ='[1]Table-7'!I17 | ... U18: ='[1]Table-7'!T17
A19: ='[1]Table-7'!A18 | C19: ='[1]Table-7'!B18 | D19: ='[1]Table-7'!C18 | E19: ='[1]Table-7'!D18 | F19: ='[1]Table-7'!E18 | G19: ='[1]Table-7'!F18 | H19: ='[1]Table-7'!G18 | I19: ='[1]Table-7'!H18 | J19: ='[1]Table-7'!I18 | ... U19: ='[1]Table-7'!T18
A20: ='[1]Table-7'!A19 | C20: ='[1]Table-7'!B19 | D20: ='[1]Table-7'!C19 | E20: ='[1]Table-7'!D19 | F20: ='[1]Table-7'!E19 | G20: ='[1]Table-7'!F19 | H20: ='[1]Table-7'!G19 | I20: ='[1]Table-7'!H19 | J20: ='[1]Table-7'!I19 | ... U20: ='[1]Table-7'!T19
A21: ='[1]Table-7'!A20 | C21: ='[1]Table-7'!B20 | D21: ='[1]Table-7'!C20 | E21: ='[1]Table-7'!D20 | F21: ='[1]Table-7'!E20 | G21: ='[1]Table-7'!F20 | H21: ='[1]Table-7'!G20 | I21: ='[1]Table-7'!H20 | J21: ='[1]Table-7'!I20 | ... U21: ='[1]Table-7'!T20
A22: ='[1]Table-7'!A21 | C22: ='[1]Table-7'!B21 | D22: ='[1]Table-7'!C21 | E22: ='[1]Table-7'!D21 | F22: ='[1]Table-7'!E21 | G22: ='[1]Table-7'!F21 | H22: ='[1]Table-7'!G21 | I22: ='[1]Table-7'!H21 | J22: ='[1]Table-7'!I21 | ... U22: ='[1]Table-7'!T21
A23: ='[1]Table-7'!A22 | C23: ='[1]Table-7'!B22 | D23: ='[1]Table-7'!C22 | E23: ='[1]Table-7'!D22 | F23: ='[1]Table-7'!E22 | G23: ='[1]Table-7'!F22 | H23: ='[1]Table-7'!G22 | I23: ='[1]Table-7'!H22 | J23: ='[1]Table-7'!I22 | ... U23: ='[1]Table-7'!T22
A24: ='[1]Table-7'!A23 | C24: ='[1]Table-7'!B23 | D24: ='[1]Table-7'!C23 | E24: ='[1]Table-7'!D23 | F24: ='[1]Table-7'!E23 | G24: ='[1]Table-7'!F23 | H24: ='[1]Table-7'!G23 | I24: ='[1]Table-7'!H23 | J24: ='[1]Table-7'!I23 | ... U24: ='[1]Table-7'!T23
... A100: ='[1]Table-7'!A99 -> TOTAL: | C100: ='[1]Table-7'!B99 -> 9 | D100: ='[1]Table-7'!C99 -> 0 | E100: ='[1]Table-7'!D99 -> 9 | F100: ='[1]Table-7'!E99 -> 0 | G100: ='[1]Table-7'!F99 -> 9 | H100: ='[1]Table-7'!G99 -> 0 | I100: ='[1]Table-7'!H99 -> 0 | J100: ='[1]Table-7'!I99 -> 0 | ... U100: ='[1]Table-7'!T99 -> 0
A101: %AGE TO COL.(2) | D101: ='[1]Table-7'!C100 -> 0 | E101: ='[1]Table-7'!D100 -> 100 | F101: ='[1]Table-7'!E100 -> 0 | G101: ='[1]Table-7'!F100 -> 100 | H101: ='[1]Table-7'!G100 -> 0 | I101: ='[1]Table-7'!H100 -> 0 | J101: ='[1]Table-7'!I100 -> 0 | K101: ='[1]Table-7'!J100 -> 0 | ... U101: ='[1]Table-7'!T100 -> 0
A102: NOTE- (I) PERCENTAGE OF ALL COLUMNS EXCEPT COL.13 AND COL.14 ARE WITH THE REFERENCE TO COL.2
A103: (II) PERCENTAGE OF COL.13 AND COL.14 ARE WITH REFERENCE TO COL.12
A104: Developed by: Deepak Kumar Agrawal, Senior Statistical Officer, NSSO (FOD), Faridabad, Haryana
A105: TABLE A-7: DISTRICT-WISE DISTRIBUTION OF SELECTED VILLAGES ACCORDING TO THE SUBMISSION OF TRS STATEMENT.
A106: =A3 -> STATE: PUDUCHERRY(34) | H106: YEAR: | I106: ='[1]Table-7'!AC2 -> 2023-24 | M106: SEASON: | O106: ='[1]Table-7'!AI2 -> RABI I(4)
A107: DISTRICT | B107: DISTRICT NAME | C107: NO. OF VILLAGES ANALYSED | D107: NUMBER OF VILLAGES FOR WHICH
D108: TRS STATEMENT SUBMITTED | N108: OUT OF COL. 12 | P108: TRS STATEMENT NOT SUBMITTED | T108: INFORMATION ABOUT SUBMISSION OR TRS STATEMENT NOT AVAILABLE | U108: TRS STATEMENT NOT TO BE SUBMITTED (A) BEING NON TRS VILLGES (B) AS PER STATE INSTRUCTION
D109: IN TIME | H109: LATE | L109: BUT DATE OF SUBMISSION NOT RECORDED | M109: TOTAL (COL. 6+ 10+ 11) | N109: TRS STATEMENT SUBMITTED IN STANDARD FORM | O109: DUPLICATE COPY OF STATEMENT KEPT | P109: THOUGH GIRDAWARI COMPLETED | R109: AS GIRDAWARI NOT COMPLETED | S109: SUB TOTAL (COL. 15+ 16 + 17)
D110: BEFORE GIRDAWARI | E110: AFTER GIRDAWARI | F110: BUT COULD NOT COMPARED WITH GIRDAWARI COMPLETION | G110: SUB TOTAL (COL. 3+ 4 +5) | H110: BEFORE GIRDAWARI | I110: AFTER GIRDAWARI | J110: BUT COULD NOT COMPARED WITH GIRDAWARI COMPLETION | K110: SUB TOTAL (COL.7 +8+9) | P110: AS DUE DATE NOT OVER | Q110: OTHER REASONS
A111: 1 | B111: 2 | C111: 3 | D111: 4 | E111: 5 | F111: 6 | G111: 7 | H111: 8 | I111: 9 | J111: 10 | K111: 11 | L111: 12 | M111: 13 | N111: 14 | O111: 15 | P111: 16 | Q111: 17 | R111: 18 | S111: 19 | T111: 20 | U111: 21
A112: ='[1]Table-7'!V8 | C112: ='[1]Table-7'!W8 | D112: ='[1]Table-7'!X8 | E112: ='[1]Table-7'!Y8 | F112: ='[1]Table-7'!Z8 | G112: ='[1]Table-7'!AA8 | H112: ='[1]Table-7'!AB8 | I112: ='[1]Table-7'!AC8 | J112: ='[1]Table-7'!AD8 | ... Q112: ='[1]Table-7'!AK8 | R112: ='RC1-A6'!E23 -> SAMPLE:STATE(2)
A113: ='[1]Table-7'!V9 -> 2 | B113: Puducherry | C113: ='[1]Table-7'!W9 -> 6 | D113: ='[1]Table-7'!X9 -> 0 | E113: ='[1]Table-7'!Y9 -> 6 | F113: ='[1]Table-7'!Z9 -> 0 | G113: ='[1]Table-7'!AA9 -> 6 | H113: ='[1]Table-7'!AB9 -> 0 | I113: ='[1]Table-7'!AC9 -> 0 | J113: ='[1]Table-7'!AD9 -> 0 | ... U113: ='[1]Table-7'!AO9 -> 0
A114: ='[1]Table-7'!V10 | C114: ='[1]Table-7'!W10 | D114: ='[1]Table-7'!X10 | E114: ='[1]Table-7'!Y10 | F114: ='[1]Table-7'!Z10 | G114: ='[1]Table-7'!AA10 | H114: ='[1]Table-7'!AB10 | I114: ='[1]Table-7'!AC10 | J114: ='[1]Table-7'!AD10 | ... U114: ='[1]Table-7'!AO10
A115: ='[1]Table-7'!V11 -> 4 | B115: Karaikal | C115: ='[1]Table-7'!W11 -> 3 | D115: ='[1]Table-7'!X11 -> 0 | E115: ='[1]Table-7'!Y11 -> 3 | F115: ='[1]Table-7'!Z11 -> 0 | G115: ='[1]Table-7'!AA11 -> 3 | H115: ='[1]Table-7'!AB11 -> 0 | I115: ='[1]Table-7'!AC11 -> 0 | J115: ='[1]Table-7'!AD11 -> 0 | ... U115: ='[1]Table-7'!AO11 -> 0
...

Sheet RC1-A14
L1: T-7
A2: TABLE A-14: DISTRICT-WISE DISTRIBUTION OF SAMPLE VILLAGES FOR WHICH THE AREAS UNDER CROPS ARE NOT AVAILABLE FOR PREVIOUS/CURRENT YEAR.
A3: ='RC1-A7'!A3:G3 -> STATE: PUDUCHERRY(34) | I3: YEAR: | K3: ='[1]Table-14'!J3 -> 2023-24 | O3: SEASON: | Q3: ='[1]Table-14'!P3 -> RABI I(4)
A4: DISTRICT | B4: DISTRICT NAME | C4: NO. OF VILLAGE ANALYSED | D4: NO.OF VILLAGES FOR WHICH AREA FIGURES FOR PREVIOUS YEAR ARE NOT AVAILABLE | R4: NO.OF VILLAGES FOR WHICH AREA FIGURES ARE NOT AVAILABLE FOR CURRENT YEAR FOR THE REASONS@
D6: FOR SELECTED CLUSTERS FOR THE REASONS@ | J6: FOR VILLAGES AS A WHOLE FOR THE REASONS@
D8: 0 | E8: 1 | F8: 2 | G8: 4 | H8: 6 | I8: 8 | J8: 0 | K8: 1 | L8: 2 | M8: 3 | N8: 4 | O8: 6 | P8: 7 | Q8: 8 | R8: 0 | S8: 1 | T8: 2 | U8: 3 | V8: 4 | W8: 6 | X8: 7 | Y8: 8
A9: 1 | B9: 2 | C9: 3 | D9: 4 | E9: 5 | F9: 6 | G9: 7 | H9: 8 | I9: 9 | J9: 10 | K9: 11 | L9: 12 | M9: 13 | N9: 14 | O9: 15 | P9: 16 | Q9: 17 | R9: 18 | S9: 19 | T9: 20 | U9: 21 | V9: 22 | W9: 23 | X9: 24 | Y9: 25
A10: ='[1]Table-14'!A10 | C10: ='[1]Table-14'!B10 | D10: ='[1]Table-14'!C10 | E10: ='[1]Table-14'!D10 | F10: ='[1]Table-14'!E10 | G10: ='[1]Table-14'!F10 | H10: ='[1]Table-14'!G10 | I10: ='[1]Table-14'!H10 | J10: ='[1]Table-14'!I10 | ... T10: ='[1]Table-14'!S10 | U10: ='RC1-A7'!R9 -> SAMPLE:CENTRAL(1)
A11: ='[1]Table-14'!A11 -> 2 | B11: Puducherry | C11: ='[1]Table-14'!B11 -> 6 | D11: ='[1]Table-14'!C11 -> 0 | E11: ='[1]Table-14'!D11 -> 0 | F11: ='[1]Table-14'!E11 -> 0 | G11: ='[1]Table-14'!F11 -> 1 | H11: ='[1]Table-14'!G11 -> 0 | I11: ='[1]Table-14'!H11 -> 0 | J11: ='[1]Table-14'!I11 -> 0 | ... Y11: ='[1]Table-14'!X11 -> 0
A12: ='[1]Table-14'!A12 | C12: ='[1]Table-14'!B12 | D12: ='[1]Table-14'!C12 | E12: ='[1]Table-14'!D12 | F12: ='[1]Table-14'!E12 | G12: ='[1]Table-14'!F12 | H12: ='[1]Table-14'!G12 | I12: ='[1]Table-14'!H12 | J12: ='[1]Table-14'!I12 | ... Y12: ='[1]Table-14'!X12
A13: ='[1]Table-14'!A13 -> 4 | B13: Karaikal | C13: ='[1]Table-14'!B13 -> 3 | D13: ='[1]Table-14'!C13 -> 0 | E13: ='[1]Table-14'!D13 -> 0 | F13: ='[1]Table-14'!E13 -> 0 | G13: ='[1]Table-14'!F13 -> 1 | H13: ='[1]Table-14'!G13 -> 0 | I13: ='[1]Table-14'!H13 -> 0 | J13: ='[1]Table-14'!I13 -> 0 | ... Y13: ='[1]Table-14'!X13 -> 0
A14: ='[1]Table-14'!A14 | C14: ='[1]Table-14'!B14 | D14: ='[1]Table-14'!C14 | E14: ='[1]Table-14'!D14 | F14: ='[1]Table-14'!E14 | G14: ='[1]Table-14'!F14 | H14: ='[1]Table-14'!G14 | I14: ='[1]Table-14'!H14 | J14: ='[1]Table-14'!I14 | ... Y14: ='[1]Table-14'!X14
A15: ='[1]Table-14'!A15 | C15: ='[1]Table-14'!B15 | D15: ='[1]Table-14'!C15 | E15: ='[1]Table-14'!D15 | F15: ='[1]Table-14'!E15 | G15: ='[1]Table-14'!F15 | H15: ='[1]Table-14'!G15 | I15: ='[1]Table-14'!H15 | J15: ='[1]Table-14'!I15 | ... Y15: ='[1]Table-14'!X15
A16: ='[1]Table-14'!A16 | C16: ='[1]Table-14'!B16 | D16: ='[1]Table-14'!C16 | E16: ='[1]Table-14'!D16 | F16: ='[1]Table-14'!E16 | G16: ='[1]Table-14'!F16 | H16: ='[1]Table-14'!G16 | I16: ='[1]Table-14'!H16 | J16: ='[1]Table-14'!I16 | ... Y16: ='[1]Table-14'!X16
A17: ='[1]Table-14'!A17 | C17: ='[1]Table-14'!B17 | D17: ='[1]Table-14'!C17 | E17: ='[1]Table-14'!D17 | F17: ='[1]Table-14'!E17 | G17: ='[1]Table-14'!F17 | H17: ='[1]Table-14'!G17 | I17: ='[1]Table-14'!H17 | J17: ='[1]Table-14'!I17 | ... Y17: ='[1]Table-14'!X17
A18: ='[1]Table-14'!A18 | C18: ='[1]Table-14'!B18 | D18: ='[1]Table-14'!C18 | E18: ='[1]Table-14'!D18 | F18: ='[1]Table-14'!E18 | G18: ='[1]Table-14'!F18 | H18: ='[1]Table-14'!G18 | I18: ='[1]Table-14'!H18 | J18: ='[1]Table-14'!I18 | ... Y18: ='[1]Table-14'!X18
A19: ='[1]Table-14'!A19 | C19: ='[1]Table-14'!B19 | D19: ='[1]Table-14'!C19 | E19: ='[1]Table-14'!D19 | F19: ='[1]Table-14'!E19 | G19: ='[1]Table-14'!F19 | H19: ='[1]Table-14'!G19 | I19: ='[1]Table-14'!H19 | J19: ='[1]Table-14'!I19 | ... Y19: ='[1]Table-14'!X19
A20: ='[1]Table-14'!A20 | C20: ='[1]Table-14'!B20 | D20: ='[1]Table-14'!C20 | E20: ='[1]Table-14'!D20 | F20: ='[1]Table-14'!E20 | G20: ='[1]Table-14'!F20 | H20: ='[1]Table-14'!G20 | I20: ='[1]Table-14'!H20 | J20: ='[1]Table-14'!I20 | ... Y20: ='[1]Table-14'!X20
A21: ='[1]Table-14'!A21 | C21: ='[1]Table-14'!B21 | D21: ='[1]Table-14'!C21 | E21: ='[1]Table-14'!D21 | F21: ='[1]Table-14'!E21 | G21: ='[1]Table-14'!F21 | H21: ='[1]Table-14'!G21 | I21: ='[1]Table-14'!H21 | J21: ='[1]Table-14'!I21 | ... Y21: ='[1]Table-14'!X21
A22: ='[1]Table-14'!A22 | C22: ='[1]Table-14'!B22 | D22: ='[1]Table-14'!C22 | E22: ='[1]Table-14'!D22 | F22: ='[1]Table-14'!E22 | G22: ='[1]Table-14'!F22 | H22: ='[1]Table-14'!G22 | I22: ='[1]Table-14'!H22 | J22: ='[1]Table-14'!I22 | ... Y22: ='[1]Table-14'!X22
A23: ='[1]Table-14'!A23 | C23: ='[1]Table-14'!B23 | D23: ='[1]Table-14'!C23 | E23: ='[1]Table-14'!D23 | F23: ='[1]Table-14'!E23 | G23: ='[1]Table-14'!F23 | H23: ='[1]Table-14'!G23 | I23: ='[1]Table-14'!H23 | J23: ='[1]Table-14'!I23 | ... Y23: ='[1]Table-14'!X23
A24: ='[1]Table-14'!A24 | C24: ='[1]Table-14'!B24 | D24: ='[1]Table-14'!C24 | E24: ='[1]Table-14'!D24 | F24: ='[1]Table-14'!E24 | G24: ='[1]Table-14'!F24 | H24: ='[1]Table-14'!G24 | I24: ='[1]Table-14'!H24 | J24: ='[1]Table-14'!I24 | ... Y24: ='[1]Table-14'!X24
A25: ='[1]Table-14'!A25 | C25: ='[1]Table-14'!B25 | D25: ='[1]Table-14'!C25 | E25: ='[1]Table-14'!D25 | F25: ='[1]Table-14'!E25 | G25: ='[1]Table-14'!F25 | H25: ='[1]Table-14'!G25 | I25: ='[1]Table-14'!H25 | J25: ='[1]Table-14'!I25 | ... Y25: ='[1]Table-14'!X25
... A100: ='[1]Table-14'!A100 -> TOTAL | C100: ='[1]Table-14'!B100 -> 9 | D100: ='[1]Table-14'!C100 -> 0 | E100: ='[1]Table-14'!D100 -> 0 | F100: ='[1]Table-14'!E100 -> 0 | G100: ='[1]Table-14'!F100 -> 2 | H100: ='[1]Table-14'!G100 -> 0 | I100: ='[1]Table-14'!H100 -> 0 | J100: ='[1]Table-14'!I100 -> 0 | ... Y100: ='[1]Table-14'!X100 -> 0
A101: %AGE TO COL. (2) | D101: ='[1]Table-14'!C101 -> 0 | E101: ='[1]Table-14'!D101 -> 0 | F101: ='[1]Table-14'!E101 -> 0 | G101: ='[1]Table-14'!F101 -> 22.22 | H101: ='[1]Table-14'!G101 -> 0 | I101: ='[1]Table-14'!H101 -> 0 | J101: ='[1]Table-14'!I101 -> 0 | K101: ='[1]Table-14'!J101 -> 0 | ... Y101: ='[1]Table-14'!X101 -> 0
A102: NOTE: SYSTEM OF GIRDAWARI DOES NOT EXIST | L102: 0 | M102: GIRDAWARI NOT DONE FOR PREVIOUS/CURRENT YEAR | Y102: 1
A103: KHASHRA REGISTER/OTHER RECORDS/STATEMENT(SPECIFY) NOT AVAILABLE | L103: 2 | M103: GIRDAWARI COMPLETED BUT TRS STATEMENT NOT REPORTED | Y103: 3
A104: REASON FOR NON AVAILBILITY OF INFORMATION NOT KNOWN | L104: 4 | M104: NOT APPLICABLE AS FOR KERALA, ORISSA AND HILLY DISTRICT OF UTTAR PRADESH | Y104: 6
A105: AGGREGATION FIGURES NOT AVAILABLE AT VILLAGE LEVEL FOR KERALA AND ORISSA | L105: 7 | M105: ANY OTHER REASON (SPECIFY) | Y105: 8
